Log file created at: 2019/11/04 15:37:37
Running on machine: SVMAC-C02T6AMCGTFL
Binary: Built with gc go1.13 for darwin/amd64
Log line format: [IWEF]mmdd hh:mm:ss.uuuuuu threadid file:line] msg
I1104 15:37:37.931903   63880 event_handlers.go:409] Add PodGroup(qj-1) into cache, spec(v1alpha1.PodGroupSpec{MinMember:2, Queue:"default", PriorityClassName:"", MinResources:(*v1.ResourceList)(nil)})
I1104 15:37:37.931940   63880 event_handlers.go:729] Add Queue(default) into cache, spec(v1alpha2.QueueSpec{Weight:1, Capability:v1.ResourceList(nil)})
I1104 15:37:37.931982   63880 event_handlers.go:709] Add Queue(default) into cache, spec(v1alpha1.QueueSpec{Weight:1, Capability:v1.ResourceList(nil)})
I1104 15:37:37.943819   63880 event_handlers.go:48] Pod kube-system/coredns-fb8b8dccf-cm54h will not not scheduled by jdos-batch, skip creating PodGroup and Job for it
I1104 15:37:37.943836   63880 event_handlers.go:189] Added pod <kube-system/coredns-fb8b8dccf-cm54h> into cache.
I1104 15:37:37.943846   63880 event_handlers.go:48] Pod kube-system/kube-scheduler-minikube will not not scheduled by jdos-batch, skip creating PodGroup and Job for it
I1104 15:37:37.943851   63880 event_handlers.go:189] Added pod <kube-system/kube-scheduler-minikube> into cache.
I1104 15:37:37.943858   63880 event_handlers.go:48] Pod kube-system/kubernetes-dashboard-d7c9687c7-tkc82 will not not scheduled by jdos-batch, skip creating PodGroup and Job for it
I1104 15:37:37.943876   63880 event_handlers.go:189] Added pod <kube-system/kubernetes-dashboard-d7c9687c7-tkc82> into cache.
I1104 15:37:37.943892   63880 event_handlers.go:48] Pod kube-system/registry-f4x5r will not not scheduled by jdos-batch, skip creating PodGroup and Job for it
I1104 15:37:37.943898   63880 event_handlers.go:189] Added pod <kube-system/registry-f4x5r> into cache.
I1104 15:37:37.943904   63880 event_handlers.go:48] Pod kube-system/kube-controller-manager-minikube will not not scheduled by jdos-batch, skip creating PodGroup and Job for it
I1104 15:37:37.943907   63880 event_handlers.go:189] Added pod <kube-system/kube-controller-manager-minikube> into cache.
I1104 15:37:37.943911   63880 event_handlers.go:48] Pod kube-system/kube-proxy-kc6f7 will not not scheduled by jdos-batch, skip creating PodGroup and Job for it
I1104 15:37:37.943914   63880 event_handlers.go:189] Added pod <kube-system/kube-proxy-kc6f7> into cache.
I1104 15:37:37.943925   63880 event_handlers.go:48] Pod kube-system/storage-provisioner will not not scheduled by jdos-batch, skip creating PodGroup and Job for it
I1104 15:37:37.943928   63880 event_handlers.go:189] Added pod <kube-system/storage-provisioner> into cache.
I1104 15:37:37.943941   63880 event_handlers.go:189] Added pod <default/qj-1-nfcct> into cache.
I1104 15:37:37.943945   63880 event_handlers.go:48] Pod kube-system/coredns-fb8b8dccf-xfpnf will not not scheduled by jdos-batch, skip creating PodGroup and Job for it
I1104 15:37:37.943947   63880 event_handlers.go:189] Added pod <kube-system/coredns-fb8b8dccf-xfpnf> into cache.
I1104 15:37:37.943951   63880 event_handlers.go:48] Pod kube-system/etcd-minikube will not not scheduled by jdos-batch, skip creating PodGroup and Job for it
I1104 15:37:37.943956   63880 event_handlers.go:189] Added pod <kube-system/etcd-minikube> into cache.
I1104 15:37:37.943974   63880 event_handlers.go:48] Pod kube-system/kube-addon-manager-minikube will not not scheduled by jdos-batch, skip creating PodGroup and Job for it
I1104 15:37:37.943980   63880 event_handlers.go:189] Added pod <kube-system/kube-addon-manager-minikube> into cache.
I1104 15:37:37.943992   63880 event_handlers.go:48] Pod kube-system/kube-apiserver-minikube will not not scheduled by jdos-batch, skip creating PodGroup and Job for it
I1104 15:37:37.943995   63880 event_handlers.go:189] Added pod <kube-system/kube-apiserver-minikube> into cache.
I1104 15:37:37.944002   63880 event_handlers.go:189] Added pod <default/qj-1-8g9hf> into cache.
I1104 15:37:38.022614   63880 scheduler.go:72] Start scheduling ...
I1104 15:37:38.023017   63880 cache.go:732] The priority of job <default/qj-1> is </0>
I1104 15:37:38.023051   63880 cache.go:771] There are <1> Jobs, <1> Queues and <1> Nodes in total for scheduling.
I1104 15:37:38.023073   63880 session.go:135] Open Session 15da8d2c-ff5c-11e9-bdbc-784f43775513 with <1> Job and <1> Queues
I1104 15:37:38.023704   63880 proportion.go:67] The total resource is <cpu 4000.00, memory 4959854592.00, hugepages-2Mi 0.00>
I1104 15:37:38.023747   63880 proportion.go:71] Considering Job <default/qj-1>.
I1104 15:37:38.023762   63880 proportion.go:85] Added Queue <default> attributes.
I1104 15:37:38.023776   63880 proportion.go:127] Considering Queue <default>: weight <1>, total weight <1>.
I1104 15:37:38.023793   63880 proportion.go:144] The attributes of queue <default> in proportion: deserved <cpu 4000.00, memory 4959854592.00, hugepages-2Mi 0.00>, allocate <cpu 0.00, memory 0.00>, request <cpu 2000.00, memory 1073741824.00>, share <0.00>
I1104 15:37:38.023832   63880 proportion.go:154] Exiting when remaining is empty:  <cpu 0.00, memory 0.00, hugepages-2Mi 0.00>
I1104 15:37:38.023864   63880 enqueue.go:43] Enter Enqueue ...
I1104 15:37:38.023871   63880 enqueue.go:58] Added Queue <default> for Job <default/qj-1>
I1104 15:37:38.023879   63880 enqueue.go:75] Try to enqueue PodGroup to 0 Queues
I1104 15:37:38.023890   63880 enqueue.go:122] Leaving Enqueue ...
I1104 15:37:38.023917   63880 allocate.go:43] Enter Allocate ...
I1104 15:37:38.023931   63880 allocate.go:90] Added Job <default/qj-1> into Queue <default>
I1104 15:37:38.023948   63880 allocate.go:94] Try to allocate resource to 1 Namespaces
I1104 15:37:38.023958   63880 proportion.go:207] Queue <default>: deserved <cpu 4000.00, memory 4959854592.00, hugepages-2Mi 0.00>, allocated <cpu 0.00, memory 0.00>, share <0>
I1104 15:37:38.023973   63880 allocate.go:138] Namespace <default> Queue <default> is overused, ignore it.
I1104 15:37:38.023995   63880 allocate.go:149] Namespace <default> have no queue, skip it
I1104 15:37:38.024017   63880 allocate.go:253] Leaving Allocate ...
I1104 15:37:38.024026   63880 backfill.go:42] Enter Backfill ...
I1104 15:37:38.024033   63880 backfill.go:91] Leaving Backfill ...
I1104 15:37:38.029971   63880 cache.go:634] task unscheduleable default/qj-1-8g9hf, message: 2/2 tasks in gang unschedulable: job is not ready, 2 Pending, 2 minAvailable., skip by no condition update
I1104 15:37:38.029979   63880 cache.go:634] task unscheduleable default/qj-1-nfcct, message: 2/2 tasks in gang unschedulable: job is not ready, 2 Pending, 2 minAvailable., skip by no condition update
I1104 15:37:38.029992   63880 session.go:154] Close Session 15da8d2c-ff5c-11e9-bdbc-784f43775513
I1104 15:37:38.029999   63880 scheduler.go:87] End scheduling ...
I1104 15:37:43.034885   63880 scheduler.go:72] Start scheduling ...
I1104 15:37:43.035033   63880 cache.go:732] The priority of job <default/qj-1> is </0>
I1104 15:37:43.035051   63880 cache.go:771] There are <1> Jobs, <1> Queues and <1> Nodes in total for scheduling.
I1104 15:37:43.035057   63880 session.go:135] Open Session 18d753c0-ff5c-11e9-bdbc-784f43775513 with <1> Job and <1> Queues
I1104 15:37:43.035095   63880 proportion.go:67] The total resource is <cpu 4000.00, memory 4959854592.00, hugepages-2Mi 0.00>
I1104 15:37:43.035106   63880 proportion.go:71] Considering Job <default/qj-1>.
I1104 15:37:43.035112   63880 proportion.go:85] Added Queue <default> attributes.
I1104 15:37:43.035119   63880 proportion.go:127] Considering Queue <default>: weight <1>, total weight <1>.
I1104 15:37:43.035126   63880 proportion.go:144] The attributes of queue <default> in proportion: deserved <cpu 4000.00, memory 4959854592.00, hugepages-2Mi 0.00>, allocate <cpu 0.00, memory 0.00>, request <cpu 2000.00, memory 1073741824.00>, share <0.00>
I1104 15:37:43.035152   63880 proportion.go:154] Exiting when remaining is empty:  <cpu 0.00, memory 0.00, hugepages-2Mi 0.00>
I1104 15:37:43.035171   63880 enqueue.go:43] Enter Enqueue ...
I1104 15:37:43.035174   63880 enqueue.go:58] Added Queue <default> for Job <default/qj-1>
I1104 15:37:43.035179   63880 enqueue.go:75] Try to enqueue PodGroup to 0 Queues
I1104 15:37:43.035185   63880 enqueue.go:122] Leaving Enqueue ...
I1104 15:37:43.035190   63880 allocate.go:43] Enter Allocate ...
I1104 15:37:43.035194   63880 allocate.go:90] Added Job <default/qj-1> into Queue <default>
I1104 15:37:43.035200   63880 allocate.go:94] Try to allocate resource to 1 Namespaces
I1104 15:37:43.035204   63880 proportion.go:207] Queue <default>: deserved <cpu 4000.00, memory 4959854592.00, hugepages-2Mi 0.00>, allocated <cpu 0.00, memory 0.00>, share <0>
I1104 15:37:43.035211   63880 allocate.go:138] Namespace <default> Queue <default> is overused, ignore it.
I1104 15:37:43.035222   63880 allocate.go:149] Namespace <default> have no queue, skip it
I1104 15:37:43.035231   63880 allocate.go:253] Leaving Allocate ...
I1104 15:37:43.035234   63880 backfill.go:42] Enter Backfill ...
I1104 15:37:43.035239   63880 backfill.go:91] Leaving Backfill ...
I1104 15:37:43.039686   63880 cache.go:634] task unscheduleable default/qj-1-nfcct, message: 2/2 tasks in gang unschedulable: job is not ready, 2 Pending, 2 minAvailable., skip by no condition update
I1104 15:37:43.039698   63880 cache.go:634] task unscheduleable default/qj-1-8g9hf, message: 2/2 tasks in gang unschedulable: job is not ready, 2 Pending, 2 minAvailable., skip by no condition update
I1104 15:37:43.039714   63880 session.go:154] Close Session 18d753c0-ff5c-11e9-bdbc-784f43775513
I1104 15:37:43.039722   63880 scheduler.go:87] End scheduling ...
I1104 15:37:48.041678   63880 scheduler.go:72] Start scheduling ...
I1104 15:37:48.041848   63880 cache.go:732] The priority of job <default/qj-1> is </0>
I1104 15:37:48.041882   63880 cache.go:771] There are <1> Jobs, <1> Queues and <1> Nodes in total for scheduling.
I1104 15:37:48.041891   63880 session.go:135] Open Session 1bd34e1c-ff5c-11e9-bdbc-784f43775513 with <1> Job and <1> Queues
I1104 15:37:48.041937   63880 proportion.go:67] The total resource is <cpu 4000.00, memory 4959854592.00, hugepages-2Mi 0.00>
I1104 15:37:48.041951   63880 proportion.go:71] Considering Job <default/qj-1>.
I1104 15:37:48.041956   63880 proportion.go:85] Added Queue <default> attributes.
I1104 15:37:48.041965   63880 proportion.go:127] Considering Queue <default>: weight <1>, total weight <1>.
I1104 15:37:48.041972   63880 proportion.go:144] The attributes of queue <default> in proportion: deserved <cpu 4000.00, memory 4959854592.00, hugepages-2Mi 0.00>, allocate <cpu 0.00, memory 0.00>, request <cpu 2000.00, memory 1073741824.00>, share <0.00>
I1104 15:37:48.041987   63880 proportion.go:154] Exiting when remaining is empty:  <cpu 0.00, memory 0.00, hugepages-2Mi 0.00>
I1104 15:37:48.042014   63880 enqueue.go:43] Enter Enqueue ...
I1104 15:37:48.042019   63880 enqueue.go:58] Added Queue <default> for Job <default/qj-1>
I1104 15:37:48.042025   63880 enqueue.go:75] Try to enqueue PodGroup to 0 Queues
I1104 15:37:48.042033   63880 enqueue.go:122] Leaving Enqueue ...
I1104 15:37:48.042040   63880 allocate.go:43] Enter Allocate ...
I1104 15:37:48.042046   63880 allocate.go:90] Added Job <default/qj-1> into Queue <default>
I1104 15:37:48.042052   63880 allocate.go:94] Try to allocate resource to 1 Namespaces
I1104 15:37:48.042057   63880 proportion.go:207] Queue <default>: deserved <cpu 4000.00, memory 4959854592.00, hugepages-2Mi 0.00>, allocated <cpu 0.00, memory 0.00>, share <0>
I1104 15:37:48.042068   63880 allocate.go:138] Namespace <default> Queue <default> is overused, ignore it.
I1104 15:37:48.042081   63880 allocate.go:149] Namespace <default> have no queue, skip it
I1104 15:37:48.042092   63880 allocate.go:253] Leaving Allocate ...
I1104 15:37:48.042097   63880 backfill.go:42] Enter Backfill ...
I1104 15:37:48.042103   63880 backfill.go:91] Leaving Backfill ...
I1104 15:37:48.047048   63880 cache.go:634] task unscheduleable default/qj-1-nfcct, message: 2/2 tasks in gang unschedulable: job is not ready, 2 Pending, 2 minAvailable., skip by no condition update
I1104 15:37:48.047057   63880 cache.go:634] task unscheduleable default/qj-1-8g9hf, message: 2/2 tasks in gang unschedulable: job is not ready, 2 Pending, 2 minAvailable., skip by no condition update
I1104 15:37:48.047072   63880 session.go:154] Close Session 1bd34e1c-ff5c-11e9-bdbc-784f43775513
I1104 15:37:48.047081   63880 scheduler.go:87] End scheduling ...
I1104 15:37:53.051304   63880 scheduler.go:72] Start scheduling ...
I1104 15:37:53.051531   63880 cache.go:732] The priority of job <default/qj-1> is </0>
I1104 15:37:53.051554   63880 cache.go:771] There are <1> Jobs, <1> Queues and <1> Nodes in total for scheduling.
I1104 15:37:53.051561   63880 session.go:135] Open Session 1ecfb862-ff5c-11e9-bdbc-784f43775513 with <1> Job and <1> Queues
I1104 15:37:53.051607   63880 proportion.go:67] The total resource is <cpu 4000.00, memory 4959854592.00, hugepages-2Mi 0.00>
I1104 15:37:53.051621   63880 proportion.go:71] Considering Job <default/qj-1>.
I1104 15:37:53.051627   63880 proportion.go:85] Added Queue <default> attributes.
I1104 15:37:53.051635   63880 proportion.go:127] Considering Queue <default>: weight <1>, total weight <1>.
I1104 15:37:53.051644   63880 proportion.go:144] The attributes of queue <default> in proportion: deserved <cpu 4000.00, memory 4959854592.00, hugepages-2Mi 0.00>, allocate <cpu 0.00, memory 0.00>, request <cpu 2000.00, memory 1073741824.00>, share <0.00>
I1104 15:37:53.051659   63880 proportion.go:154] Exiting when remaining is empty:  <cpu 0.00, memory 0.00, hugepages-2Mi 0.00>
I1104 15:37:53.051687   63880 enqueue.go:43] Enter Enqueue ...
I1104 15:37:53.051692   63880 enqueue.go:58] Added Queue <default> for Job <default/qj-1>
I1104 15:37:53.051709   63880 enqueue.go:75] Try to enqueue PodGroup to 0 Queues
I1104 15:37:53.051717   63880 enqueue.go:122] Leaving Enqueue ...
I1104 15:37:53.051723   63880 allocate.go:43] Enter Allocate ...
I1104 15:37:53.051729   63880 allocate.go:90] Added Job <default/qj-1> into Queue <default>
I1104 15:37:53.051736   63880 allocate.go:94] Try to allocate resource to 1 Namespaces
I1104 15:37:53.051740   63880 proportion.go:207] Queue <default>: deserved <cpu 4000.00, memory 4959854592.00, hugepages-2Mi 0.00>, allocated <cpu 0.00, memory 0.00>, share <0>
I1104 15:37:53.051750   63880 allocate.go:138] Namespace <default> Queue <default> is overused, ignore it.
I1104 15:37:53.051763   63880 allocate.go:149] Namespace <default> have no queue, skip it
I1104 15:37:53.051774   63880 allocate.go:253] Leaving Allocate ...
I1104 15:37:53.051778   63880 backfill.go:42] Enter Backfill ...
I1104 15:37:53.051783   63880 backfill.go:91] Leaving Backfill ...
I1104 15:37:53.055952   63880 cache.go:634] task unscheduleable default/qj-1-nfcct, message: 2/2 tasks in gang unschedulable: job is not ready, 2 Pending, 2 minAvailable., skip by no condition update
I1104 15:37:53.055962   63880 cache.go:634] task unscheduleable default/qj-1-8g9hf, message: 2/2 tasks in gang unschedulable: job is not ready, 2 Pending, 2 minAvailable., skip by no condition update
I1104 15:37:53.056024   63880 session.go:154] Close Session 1ecfb862-ff5c-11e9-bdbc-784f43775513
I1104 15:37:53.056033   63880 scheduler.go:87] End scheduling ...
I1104 15:37:58.058468   63880 scheduler.go:72] Start scheduling ...
I1104 15:37:58.058603   63880 cache.go:732] The priority of job <default/qj-1> is </0>
I1104 15:37:58.058619   63880 cache.go:771] There are <1> Jobs, <1> Queues and <1> Nodes in total for scheduling.
I1104 15:37:58.058624   63880 session.go:135] Open Session 21cbbe26-ff5c-11e9-bdbc-784f43775513 with <1> Job and <1> Queues
I1104 15:37:58.058659   63880 proportion.go:67] The total resource is <cpu 4000.00, memory 4959854592.00, hugepages-2Mi 0.00>
I1104 15:37:58.058670   63880 proportion.go:71] Considering Job <default/qj-1>.
I1104 15:37:58.058675   63880 proportion.go:85] Added Queue <default> attributes.
I1104 15:37:58.058682   63880 proportion.go:127] Considering Queue <default>: weight <1>, total weight <1>.
I1104 15:37:58.058689   63880 proportion.go:144] The attributes of queue <default> in proportion: deserved <cpu 4000.00, memory 4959854592.00, hugepages-2Mi 0.00>, allocate <cpu 0.00, memory 0.00>, request <cpu 2000.00, memory 1073741824.00>, share <0.00>
I1104 15:37:58.058706   63880 proportion.go:154] Exiting when remaining is empty:  <cpu 0.00, memory 0.00, hugepages-2Mi 0.00>
I1104 15:37:58.058737   63880 enqueue.go:43] Enter Enqueue ...
I1104 15:37:58.058741   63880 enqueue.go:58] Added Queue <default> for Job <default/qj-1>
I1104 15:37:58.058746   63880 enqueue.go:75] Try to enqueue PodGroup to 0 Queues
I1104 15:37:58.058752   63880 enqueue.go:122] Leaving Enqueue ...
I1104 15:37:58.058758   63880 allocate.go:43] Enter Allocate ...
I1104 15:37:58.058762   63880 allocate.go:90] Added Job <default/qj-1> into Queue <default>
I1104 15:37:58.058768   63880 allocate.go:94] Try to allocate resource to 1 Namespaces
I1104 15:37:58.058772   63880 proportion.go:207] Queue <default>: deserved <cpu 4000.00, memory 4959854592.00, hugepages-2Mi 0.00>, allocated <cpu 0.00, memory 0.00>, share <0>
I1104 15:37:58.058780   63880 allocate.go:138] Namespace <default> Queue <default> is overused, ignore it.
I1104 15:37:58.058791   63880 allocate.go:149] Namespace <default> have no queue, skip it
I1104 15:37:58.058800   63880 allocate.go:253] Leaving Allocate ...
I1104 15:37:58.058804   63880 backfill.go:42] Enter Backfill ...
I1104 15:37:58.058808   63880 backfill.go:91] Leaving Backfill ...
I1104 15:37:58.063347   63880 cache.go:634] task unscheduleable default/qj-1-nfcct, message: 2/2 tasks in gang unschedulable: job is not ready, 2 Pending, 2 minAvailable., skip by no condition update
I1104 15:37:58.063354   63880 cache.go:634] task unscheduleable default/qj-1-8g9hf, message: 2/2 tasks in gang unschedulable: job is not ready, 2 Pending, 2 minAvailable., skip by no condition update
I1104 15:37:58.063368   63880 session.go:154] Close Session 21cbbe26-ff5c-11e9-bdbc-784f43775513
I1104 15:37:58.063376   63880 scheduler.go:87] End scheduling ...
I1104 15:38:03.064047   63880 scheduler.go:72] Start scheduling ...
I1104 15:38:03.064212   63880 cache.go:732] The priority of job <default/qj-1> is </0>
I1104 15:38:03.064234   63880 cache.go:771] There are <1> Jobs, <1> Queues and <1> Nodes in total for scheduling.
I1104 15:38:03.064239   63880 session.go:135] Open Session 24c789b6-ff5c-11e9-bdbc-784f43775513 with <1> Job and <1> Queues
I1104 15:38:03.064251   63880 proportion.go:67] The total resource is <cpu 4000.00, memory 4959854592.00, hugepages-2Mi 0.00>
I1104 15:38:03.064262   63880 proportion.go:71] Considering Job <default/qj-1>.
I1104 15:38:03.064267   63880 proportion.go:85] Added Queue <default> attributes.
I1104 15:38:03.064273   63880 proportion.go:127] Considering Queue <default>: weight <1>, total weight <1>.
I1104 15:38:03.064281   63880 proportion.go:144] The attributes of queue <default> in proportion: deserved <cpu 4000.00, memory 4959854592.00, hugepages-2Mi 0.00>, allocate <cpu 0.00, memory 0.00>, request <cpu 2000.00, memory 1073741824.00>, share <0.00>
I1104 15:38:03.064296   63880 proportion.go:154] Exiting when remaining is empty:  <cpu 0.00, memory 0.00, hugepages-2Mi 0.00>
I1104 15:38:03.064344   63880 enqueue.go:43] Enter Enqueue ...
I1104 15:38:03.064349   63880 enqueue.go:58] Added Queue <default> for Job <default/qj-1>
I1104 15:38:03.064354   63880 enqueue.go:75] Try to enqueue PodGroup to 0 Queues
I1104 15:38:03.064360   63880 enqueue.go:122] Leaving Enqueue ...
I1104 15:38:03.064366   63880 allocate.go:43] Enter Allocate ...
I1104 15:38:03.064370   63880 allocate.go:90] Added Job <default/qj-1> into Queue <default>
I1104 15:38:03.064376   63880 allocate.go:94] Try to allocate resource to 1 Namespaces
I1104 15:38:03.064380   63880 proportion.go:207] Queue <default>: deserved <cpu 4000.00, memory 4959854592.00, hugepages-2Mi 0.00>, allocated <cpu 0.00, memory 0.00>, share <0>
I1104 15:38:03.064388   63880 allocate.go:138] Namespace <default> Queue <default> is overused, ignore it.
I1104 15:38:03.064399   63880 allocate.go:149] Namespace <default> have no queue, skip it
I1104 15:38:03.064408   63880 allocate.go:253] Leaving Allocate ...
I1104 15:38:03.064412   63880 backfill.go:42] Enter Backfill ...
I1104 15:38:03.064416   63880 backfill.go:91] Leaving Backfill ...
I1104 15:38:03.068753   63880 cache.go:634] task unscheduleable default/qj-1-nfcct, message: 2/2 tasks in gang unschedulable: job is not ready, 2 Pending, 2 minAvailable., skip by no condition update
I1104 15:38:03.068761   63880 cache.go:634] task unscheduleable default/qj-1-8g9hf, message: 2/2 tasks in gang unschedulable: job is not ready, 2 Pending, 2 minAvailable., skip by no condition update
I1104 15:38:03.068773   63880 session.go:154] Close Session 24c789b6-ff5c-11e9-bdbc-784f43775513
I1104 15:38:03.068781   63880 scheduler.go:87] End scheduling ...
I1104 15:38:08.069673   63880 scheduler.go:72] Start scheduling ...
I1104 15:38:08.069867   63880 cache.go:732] The priority of job <default/qj-1> is </0>
I1104 15:38:08.069897   63880 cache.go:771] There are <1> Jobs, <1> Queues and <1> Nodes in total for scheduling.
I1104 15:38:08.069907   63880 session.go:135] Open Session 27c355e6-ff5c-11e9-bdbc-784f43775513 with <1> Job and <1> Queues
I1104 15:38:08.069958   63880 proportion.go:67] The total resource is <cpu 4000.00, memory 4959854592.00, hugepages-2Mi 0.00>
I1104 15:38:08.069975   63880 proportion.go:71] Considering Job <default/qj-1>.
I1104 15:38:08.069981   63880 proportion.go:85] Added Queue <default> attributes.
I1104 15:38:08.069993   63880 proportion.go:127] Considering Queue <default>: weight <1>, total weight <1>.
I1104 15:38:08.070003   63880 proportion.go:144] The attributes of queue <default> in proportion: deserved <cpu 4000.00, memory 4959854592.00, hugepages-2Mi 0.00>, allocate <cpu 0.00, memory 0.00>, request <cpu 2000.00, memory 1073741824.00>, share <0.00>
I1104 15:38:08.070026   63880 proportion.go:154] Exiting when remaining is empty:  <cpu 0.00, memory 0.00, hugepages-2Mi 0.00>
I1104 15:38:08.070053   63880 enqueue.go:43] Enter Enqueue ...
I1104 15:38:08.070059   63880 enqueue.go:58] Added Queue <default> for Job <default/qj-1>
I1104 15:38:08.070066   63880 enqueue.go:75] Try to enqueue PodGroup to 0 Queues
I1104 15:38:08.070075   63880 enqueue.go:122] Leaving Enqueue ...
I1104 15:38:08.070083   63880 allocate.go:43] Enter Allocate ...
I1104 15:38:08.070089   63880 allocate.go:90] Added Job <default/qj-1> into Queue <default>
I1104 15:38:08.070097   63880 allocate.go:94] Try to allocate resource to 1 Namespaces
I1104 15:38:08.070103   63880 proportion.go:207] Queue <default>: deserved <cpu 4000.00, memory 4959854592.00, hugepages-2Mi 0.00>, allocated <cpu 0.00, memory 0.00>, share <0>
I1104 15:38:08.070114   63880 allocate.go:138] Namespace <default> Queue <default> is overused, ignore it.
I1104 15:38:08.070132   63880 allocate.go:149] Namespace <default> have no queue, skip it
I1104 15:38:08.070145   63880 allocate.go:253] Leaving Allocate ...
I1104 15:38:08.070150   63880 backfill.go:42] Enter Backfill ...
I1104 15:38:08.070156   63880 backfill.go:91] Leaving Backfill ...
I1104 15:38:08.079903   63880 cache.go:634] task unscheduleable default/qj-1-nfcct, message: 2/2 tasks in gang unschedulable: job is not ready, 2 Pending, 2 minAvailable., skip by no condition update
I1104 15:38:08.079915   63880 cache.go:634] task unscheduleable default/qj-1-8g9hf, message: 2/2 tasks in gang unschedulable: job is not ready, 2 Pending, 2 minAvailable., skip by no condition update
I1104 15:38:08.079934   63880 session.go:154] Close Session 27c355e6-ff5c-11e9-bdbc-784f43775513
I1104 15:38:08.079944   63880 scheduler.go:87] End scheduling ...
I1104 15:38:13.085123   63880 scheduler.go:72] Start scheduling ...
I1104 15:38:13.085312   63880 cache.go:732] The priority of job <default/qj-1> is </0>
I1104 15:38:13.085337   63880 cache.go:771] There are <1> Jobs, <1> Queues and <1> Nodes in total for scheduling.
I1104 15:38:13.085344   63880 session.go:135] Open Session 2ac0a23a-ff5c-11e9-bdbc-784f43775513 with <1> Job and <1> Queues
I1104 15:38:13.085402   63880 proportion.go:67] The total resource is <cpu 4000.00, memory 4959854592.00, hugepages-2Mi 0.00>
I1104 15:38:13.085419   63880 proportion.go:71] Considering Job <default/qj-1>.
I1104 15:38:13.085426   63880 proportion.go:85] Added Queue <default> attributes.
I1104 15:38:13.085436   63880 proportion.go:127] Considering Queue <default>: weight <1>, total weight <1>.
I1104 15:38:13.085446   63880 proportion.go:144] The attributes of queue <default> in proportion: deserved <cpu 4000.00, memory 4959854592.00, hugepages-2Mi 0.00>, allocate <cpu 0.00, memory 0.00>, request <cpu 2000.00, memory 1073741824.00>, share <0.00>
I1104 15:38:13.085466   63880 proportion.go:154] Exiting when remaining is empty:  <cpu 0.00, memory 0.00, hugepages-2Mi 0.00>
I1104 15:38:13.085506   63880 enqueue.go:43] Enter Enqueue ...
I1104 15:38:13.085512   63880 enqueue.go:58] Added Queue <default> for Job <default/qj-1>
I1104 15:38:13.085519   63880 enqueue.go:75] Try to enqueue PodGroup to 0 Queues
I1104 15:38:13.085529   63880 enqueue.go:122] Leaving Enqueue ...
I1104 15:38:13.085546   63880 allocate.go:43] Enter Allocate ...
I1104 15:38:13.085553   63880 allocate.go:90] Added Job <default/qj-1> into Queue <default>
I1104 15:38:13.085562   63880 allocate.go:94] Try to allocate resource to 1 Namespaces
I1104 15:38:13.085568   63880 proportion.go:207] Queue <default>: deserved <cpu 4000.00, memory 4959854592.00, hugepages-2Mi 0.00>, allocated <cpu 0.00, memory 0.00>, share <0>
I1104 15:38:13.085580   63880 allocate.go:138] Namespace <default> Queue <default> is overused, ignore it.
I1104 15:38:13.085598   63880 allocate.go:149] Namespace <default> have no queue, skip it
I1104 15:38:13.085611   63880 allocate.go:253] Leaving Allocate ...
I1104 15:38:13.085617   63880 backfill.go:42] Enter Backfill ...
I1104 15:38:13.085623   63880 backfill.go:91] Leaving Backfill ...
I1104 15:38:13.090803   63880 cache.go:634] task unscheduleable default/qj-1-nfcct, message: 2/2 tasks in gang unschedulable: job is not ready, 2 Pending, 2 minAvailable., skip by no condition update
I1104 15:38:13.090812   63880 cache.go:634] task unscheduleable default/qj-1-8g9hf, message: 2/2 tasks in gang unschedulable: job is not ready, 2 Pending, 2 minAvailable., skip by no condition update
I1104 15:38:13.090828   63880 session.go:154] Close Session 2ac0a23a-ff5c-11e9-bdbc-784f43775513
I1104 15:38:13.090838   63880 scheduler.go:87] End scheduling ...
I1104 15:38:18.096173   63880 scheduler.go:72] Start scheduling ...
I1104 15:38:18.096313   63880 cache.go:732] The priority of job <default/qj-1> is </0>
I1104 15:38:18.096330   63880 cache.go:771] There are <1> Jobs, <1> Queues and <1> Nodes in total for scheduling.
I1104 15:38:18.096338   63880 session.go:135] Open Session 2dbd4132-ff5c-11e9-bdbc-784f43775513 with <1> Job and <1> Queues
I1104 15:38:18.096368   63880 proportion.go:67] The total resource is <cpu 4000.00, memory 4959854592.00, hugepages-2Mi 0.00>
I1104 15:38:18.096380   63880 proportion.go:71] Considering Job <default/qj-1>.
I1104 15:38:18.096385   63880 proportion.go:85] Added Queue <default> attributes.
I1104 15:38:18.096392   63880 proportion.go:127] Considering Queue <default>: weight <1>, total weight <1>.
I1104 15:38:18.096398   63880 proportion.go:144] The attributes of queue <default> in proportion: deserved <cpu 4000.00, memory 4959854592.00, hugepages-2Mi 0.00>, allocate <cpu 0.00, memory 0.00>, request <cpu 2000.00, memory 1073741824.00>, share <0.00>
I1104 15:38:18.096413   63880 proportion.go:154] Exiting when remaining is empty:  <cpu 0.00, memory 0.00, hugepages-2Mi 0.00>
I1104 15:38:18.096442   63880 enqueue.go:43] Enter Enqueue ...
I1104 15:38:18.096446   63880 enqueue.go:58] Added Queue <default> for Job <default/qj-1>
I1104 15:38:18.096464   63880 enqueue.go:75] Try to enqueue PodGroup to 0 Queues
I1104 15:38:18.096471   63880 enqueue.go:122] Leaving Enqueue ...
I1104 15:38:18.096476   63880 allocate.go:43] Enter Allocate ...
I1104 15:38:18.096481   63880 allocate.go:90] Added Job <default/qj-1> into Queue <default>
I1104 15:38:18.096486   63880 allocate.go:94] Try to allocate resource to 1 Namespaces
I1104 15:38:18.096491   63880 proportion.go:207] Queue <default>: deserved <cpu 4000.00, memory 4959854592.00, hugepages-2Mi 0.00>, allocated <cpu 0.00, memory 0.00>, share <0>
I1104 15:38:18.096499   63880 allocate.go:138] Namespace <default> Queue <default> is overused, ignore it.
I1104 15:38:18.096511   63880 allocate.go:149] Namespace <default> have no queue, skip it
I1104 15:38:18.096520   63880 allocate.go:253] Leaving Allocate ...
I1104 15:38:18.096523   63880 backfill.go:42] Enter Backfill ...
I1104 15:38:18.096527   63880 backfill.go:91] Leaving Backfill ...
I1104 15:38:18.100528   63880 cache.go:634] task unscheduleable default/qj-1-8g9hf, message: 2/2 tasks in gang unschedulable: job is not ready, 2 Pending, 2 minAvailable., skip by no condition update
I1104 15:38:18.100536   63880 cache.go:634] task unscheduleable default/qj-1-nfcct, message: 2/2 tasks in gang unschedulable: job is not ready, 2 Pending, 2 minAvailable., skip by no condition update
I1104 15:38:18.100550   63880 session.go:154] Close Session 2dbd4132-ff5c-11e9-bdbc-784f43775513
I1104 15:38:18.100568   63880 scheduler.go:87] End scheduling ...
I1104 15:38:23.105510   63880 scheduler.go:72] Start scheduling ...
I1104 15:38:23.105746   63880 cache.go:732] The priority of job <default/qj-1> is </0>
I1104 15:38:23.105837   63880 cache.go:771] There are <1> Jobs, <1> Queues and <1> Nodes in total for scheduling.
I1104 15:38:23.105862   63880 session.go:135] Open Session 30b9a09c-ff5c-11e9-bdbc-784f43775513 with <1> Job and <1> Queues
I1104 15:38:23.105883   63880 proportion.go:67] The total resource is <cpu 4000.00, memory 4959854592.00, hugepages-2Mi 0.00>
I1104 15:38:23.105903   63880 proportion.go:71] Considering Job <default/qj-1>.
I1104 15:38:23.105912   63880 proportion.go:85] Added Queue <default> attributes.
I1104 15:38:23.105924   63880 proportion.go:127] Considering Queue <default>: weight <1>, total weight <1>.
I1104 15:38:23.105937   63880 proportion.go:144] The attributes of queue <default> in proportion: deserved <cpu 4000.00, memory 4959854592.00, hugepages-2Mi 0.00>, allocate <cpu 0.00, memory 0.00>, request <cpu 2000.00, memory 1073741824.00>, share <0.00>
I1104 15:38:23.105962   63880 proportion.go:154] Exiting when remaining is empty:  <cpu 0.00, memory 0.00, hugepages-2Mi 0.00>
I1104 15:38:23.106036   63880 enqueue.go:43] Enter Enqueue ...
I1104 15:38:23.106044   63880 enqueue.go:58] Added Queue <default> for Job <default/qj-1>
I1104 15:38:23.106064   63880 enqueue.go:75] Try to enqueue PodGroup to 0 Queues
I1104 15:38:23.106076   63880 enqueue.go:122] Leaving Enqueue ...
I1104 15:38:23.106086   63880 allocate.go:43] Enter Allocate ...
I1104 15:38:23.106094   63880 allocate.go:90] Added Job <default/qj-1> into Queue <default>
I1104 15:38:23.106105   63880 allocate.go:94] Try to allocate resource to 1 Namespaces
I1104 15:38:23.106113   63880 proportion.go:207] Queue <default>: deserved <cpu 4000.00, memory 4959854592.00, hugepages-2Mi 0.00>, allocated <cpu 0.00, memory 0.00>, share <0>
I1104 15:38:23.106128   63880 allocate.go:138] Namespace <default> Queue <default> is overused, ignore it.
I1104 15:38:23.106156   63880 allocate.go:149] Namespace <default> have no queue, skip it
I1104 15:38:23.106194   63880 allocate.go:253] Leaving Allocate ...
I1104 15:38:23.106199   63880 backfill.go:42] Enter Backfill ...
I1104 15:38:23.106206   63880 backfill.go:91] Leaving Backfill ...
I1104 15:38:23.110337   63880 cache.go:634] task unscheduleable default/qj-1-nfcct, message: 2/2 tasks in gang unschedulable: job is not ready, 2 Pending, 2 minAvailable., skip by no condition update
I1104 15:38:23.110343   63880 cache.go:634] task unscheduleable default/qj-1-8g9hf, message: 2/2 tasks in gang unschedulable: job is not ready, 2 Pending, 2 minAvailable., skip by no condition update
I1104 15:38:23.110354   63880 session.go:154] Close Session 30b9a09c-ff5c-11e9-bdbc-784f43775513
I1104 15:38:23.110360   63880 scheduler.go:87] End scheduling ...
I1104 15:38:28.114213   63880 scheduler.go:72] Start scheduling ...
I1104 15:38:28.114439   63880 cache.go:732] The priority of job <default/qj-1> is </0>
I1104 15:38:28.114465   63880 cache.go:771] There are <1> Jobs, <1> Queues and <1> Nodes in total for scheduling.
I1104 15:38:28.114472   63880 session.go:135] Open Session 33b5e56c-ff5c-11e9-bdbc-784f43775513 with <1> Job and <1> Queues
I1104 15:38:28.114550   63880 proportion.go:67] The total resource is <cpu 4000.00, memory 4959854592.00, hugepages-2Mi 0.00>
I1104 15:38:28.114566   63880 proportion.go:71] Considering Job <default/qj-1>.
I1104 15:38:28.114573   63880 proportion.go:85] Added Queue <default> attributes.
I1104 15:38:28.114584   63880 proportion.go:127] Considering Queue <default>: weight <1>, total weight <1>.
I1104 15:38:28.114593   63880 proportion.go:144] The attributes of queue <default> in proportion: deserved <cpu 4000.00, memory 4959854592.00, hugepages-2Mi 0.00>, allocate <cpu 0.00, memory 0.00>, request <cpu 2000.00, memory 1073741824.00>, share <0.00>
I1104 15:38:28.114621   63880 proportion.go:154] Exiting when remaining is empty:  <cpu 0.00, memory 0.00, hugepages-2Mi 0.00>
I1104 15:38:28.114655   63880 enqueue.go:43] Enter Enqueue ...
I1104 15:38:28.114661   63880 enqueue.go:58] Added Queue <default> for Job <default/qj-1>
I1104 15:38:28.114668   63880 enqueue.go:75] Try to enqueue PodGroup to 0 Queues
I1104 15:38:28.114677   63880 enqueue.go:122] Leaving Enqueue ...
I1104 15:38:28.114685   63880 allocate.go:43] Enter Allocate ...
I1104 15:38:28.114695   63880 allocate.go:90] Added Job <default/qj-1> into Queue <default>
I1104 15:38:28.114704   63880 allocate.go:94] Try to allocate resource to 1 Namespaces
I1104 15:38:28.114710   63880 proportion.go:207] Queue <default>: deserved <cpu 4000.00, memory 4959854592.00, hugepages-2Mi 0.00>, allocated <cpu 0.00, memory 0.00>, share <0>
I1104 15:38:28.114722   63880 allocate.go:138] Namespace <default> Queue <default> is overused, ignore it.
I1104 15:38:28.114740   63880 allocate.go:149] Namespace <default> have no queue, skip it
I1104 15:38:28.114753   63880 allocate.go:253] Leaving Allocate ...
I1104 15:38:28.114759   63880 backfill.go:42] Enter Backfill ...
I1104 15:38:28.114765   63880 backfill.go:91] Leaving Backfill ...
I1104 15:38:28.121135   63880 cache.go:634] task unscheduleable default/qj-1-nfcct, message: 2/2 tasks in gang unschedulable: job is not ready, 2 Pending, 2 minAvailable., skip by no condition update
I1104 15:38:28.121142   63880 cache.go:634] task unscheduleable default/qj-1-8g9hf, message: 2/2 tasks in gang unschedulable: job is not ready, 2 Pending, 2 minAvailable., skip by no condition update
I1104 15:38:28.121154   63880 session.go:154] Close Session 33b5e56c-ff5c-11e9-bdbc-784f43775513
I1104 15:38:28.121160   63880 scheduler.go:87] End scheduling ...
I1104 15:38:33.123690   63880 scheduler.go:72] Start scheduling ...
I1104 15:38:33.123857   63880 cache.go:732] The priority of job <default/qj-1> is </0>
I1104 15:38:33.123921   63880 cache.go:771] There are <1> Jobs, <1> Queues and <1> Nodes in total for scheduling.
I1104 15:38:33.123948   63880 session.go:135] Open Session 36b24616-ff5c-11e9-bdbc-784f43775513 with <1> Job and <1> Queues
I1104 15:38:33.123986   63880 proportion.go:67] The total resource is <cpu 4000.00, memory 4959854592.00, hugepages-2Mi 0.00>
I1104 15:38:33.124011   63880 proportion.go:71] Considering Job <default/qj-1>.
I1104 15:38:33.124016   63880 proportion.go:85] Added Queue <default> attributes.
I1104 15:38:33.124023   63880 proportion.go:127] Considering Queue <default>: weight <1>, total weight <1>.
I1104 15:38:33.124029   63880 proportion.go:144] The attributes of queue <default> in proportion: deserved <cpu 4000.00, memory 4959854592.00, hugepages-2Mi 0.00>, allocate <cpu 0.00, memory 0.00>, request <cpu 2000.00, memory 1073741824.00>, share <0.00>
I1104 15:38:33.124043   63880 proportion.go:154] Exiting when remaining is empty:  <cpu 0.00, memory 0.00, hugepages-2Mi 0.00>
I1104 15:38:33.124066   63880 enqueue.go:43] Enter Enqueue ...
I1104 15:38:33.124070   63880 enqueue.go:58] Added Queue <default> for Job <default/qj-1>
I1104 15:38:33.124075   63880 enqueue.go:75] Try to enqueue PodGroup to 0 Queues
I1104 15:38:33.124082   63880 enqueue.go:122] Leaving Enqueue ...
I1104 15:38:33.124087   63880 allocate.go:43] Enter Allocate ...
I1104 15:38:33.124091   63880 allocate.go:90] Added Job <default/qj-1> into Queue <default>
I1104 15:38:33.124097   63880 allocate.go:94] Try to allocate resource to 1 Namespaces
I1104 15:38:33.124101   63880 proportion.go:207] Queue <default>: deserved <cpu 4000.00, memory 4959854592.00, hugepages-2Mi 0.00>, allocated <cpu 0.00, memory 0.00>, share <0>
I1104 15:38:33.124109   63880 allocate.go:138] Namespace <default> Queue <default> is overused, ignore it.
I1104 15:38:33.124121   63880 allocate.go:149] Namespace <default> have no queue, skip it
I1104 15:38:33.124129   63880 allocate.go:253] Leaving Allocate ...
I1104 15:38:33.124133   63880 backfill.go:42] Enter Backfill ...
I1104 15:38:33.124143   63880 backfill.go:91] Leaving Backfill ...
I1104 15:38:33.129242   63880 cache.go:634] task unscheduleable default/qj-1-8g9hf, message: 2/2 tasks in gang unschedulable: job is not ready, 2 Pending, 2 minAvailable., skip by no condition update
I1104 15:38:33.129251   63880 cache.go:634] task unscheduleable default/qj-1-nfcct, message: 2/2 tasks in gang unschedulable: job is not ready, 2 Pending, 2 minAvailable., skip by no condition update
I1104 15:38:33.129269   63880 session.go:154] Close Session 36b24616-ff5c-11e9-bdbc-784f43775513
I1104 15:38:33.129279   63880 scheduler.go:87] End scheduling ...
I1104 15:38:38.132521   63880 scheduler.go:72] Start scheduling ...
I1104 15:38:38.132772   63880 cache.go:732] The priority of job <default/qj-1> is </0>
I1104 15:38:38.132803   63880 cache.go:771] There are <1> Jobs, <1> Queues and <1> Nodes in total for scheduling.
I1104 15:38:38.132810   63880 session.go:135] Open Session 39ae9216-ff5c-11e9-bdbc-784f43775513 with <1> Job and <1> Queues
I1104 15:38:38.132825   63880 proportion.go:67] The total resource is <cpu 4000.00, memory 4959854592.00, hugepages-2Mi 0.00>
I1104 15:38:38.132842   63880 proportion.go:71] Considering Job <default/qj-1>.
I1104 15:38:38.132849   63880 proportion.go:85] Added Queue <default> attributes.
I1104 15:38:38.132860   63880 proportion.go:127] Considering Queue <default>: weight <1>, total weight <1>.
I1104 15:38:38.132870   63880 proportion.go:144] The attributes of queue <default> in proportion: deserved <cpu 4000.00, memory 4959854592.00, hugepages-2Mi 0.00>, allocate <cpu 0.00, memory 0.00>, request <cpu 2000.00, memory 1073741824.00>, share <0.00>
I1104 15:38:38.132913   63880 proportion.go:154] Exiting when remaining is empty:  <cpu 0.00, memory 0.00, hugepages-2Mi 0.00>
I1104 15:38:38.132980   63880 enqueue.go:43] Enter Enqueue ...
I1104 15:38:38.132986   63880 enqueue.go:58] Added Queue <default> for Job <default/qj-1>
I1104 15:38:38.132993   63880 enqueue.go:75] Try to enqueue PodGroup to 0 Queues
I1104 15:38:38.133003   63880 enqueue.go:122] Leaving Enqueue ...
I1104 15:38:38.133010   63880 allocate.go:43] Enter Allocate ...
I1104 15:38:38.133017   63880 allocate.go:90] Added Job <default/qj-1> into Queue <default>
I1104 15:38:38.133025   63880 allocate.go:94] Try to allocate resource to 1 Namespaces
I1104 15:38:38.133031   63880 proportion.go:207] Queue <default>: deserved <cpu 4000.00, memory 4959854592.00, hugepages-2Mi 0.00>, allocated <cpu 0.00, memory 0.00>, share <0>
I1104 15:38:38.133043   63880 allocate.go:138] Namespace <default> Queue <default> is overused, ignore it.
I1104 15:38:38.133060   63880 allocate.go:149] Namespace <default> have no queue, skip it
I1104 15:38:38.133074   63880 allocate.go:253] Leaving Allocate ...
I1104 15:38:38.133085   63880 backfill.go:42] Enter Backfill ...
I1104 15:38:38.133092   63880 backfill.go:91] Leaving Backfill ...
I1104 15:38:38.140628   63880 cache.go:634] task unscheduleable default/qj-1-nfcct, message: 2/2 tasks in gang unschedulable: job is not ready, 2 Pending, 2 minAvailable., skip by no condition update
I1104 15:38:38.140637   63880 cache.go:634] task unscheduleable default/qj-1-8g9hf, message: 2/2 tasks in gang unschedulable: job is not ready, 2 Pending, 2 minAvailable., skip by no condition update
I1104 15:38:38.140651   63880 session.go:154] Close Session 39ae9216-ff5c-11e9-bdbc-784f43775513
I1104 15:38:38.140660   63880 scheduler.go:87] End scheduling ...
I1104 15:38:43.145354   63880 scheduler.go:72] Start scheduling ...
I1104 15:38:43.145523   63880 cache.go:732] The priority of job <default/qj-1> is </0>
I1104 15:38:43.145542   63880 cache.go:771] There are <1> Jobs, <1> Queues and <1> Nodes in total for scheduling.
I1104 15:38:43.145547   63880 session.go:135] Open Session 3cab7592-ff5c-11e9-bdbc-784f43775513 with <1> Job and <1> Queues
I1104 15:38:43.145596   63880 proportion.go:67] The total resource is <cpu 4000.00, memory 4959854592.00, hugepages-2Mi 0.00>
I1104 15:38:43.145608   63880 proportion.go:71] Considering Job <default/qj-1>.
I1104 15:38:43.145613   63880 proportion.go:85] Added Queue <default> attributes.
I1104 15:38:43.145622   63880 proportion.go:127] Considering Queue <default>: weight <1>, total weight <1>.
I1104 15:38:43.145630   63880 proportion.go:144] The attributes of queue <default> in proportion: deserved <cpu 4000.00, memory 4959854592.00, hugepages-2Mi 0.00>, allocate <cpu 0.00, memory 0.00>, request <cpu 2000.00, memory 1073741824.00>, share <0.00>
I1104 15:38:43.145645   63880 proportion.go:154] Exiting when remaining is empty:  <cpu 0.00, memory 0.00, hugepages-2Mi 0.00>
I1104 15:38:43.145665   63880 enqueue.go:43] Enter Enqueue ...
I1104 15:38:43.145670   63880 enqueue.go:58] Added Queue <default> for Job <default/qj-1>
I1104 15:38:43.145675   63880 enqueue.go:75] Try to enqueue PodGroup to 0 Queues
I1104 15:38:43.145683   63880 enqueue.go:122] Leaving Enqueue ...
I1104 15:38:43.145689   63880 allocate.go:43] Enter Allocate ...
I1104 15:38:43.145694   63880 allocate.go:90] Added Job <default/qj-1> into Queue <default>
I1104 15:38:43.145700   63880 allocate.go:94] Try to allocate resource to 1 Namespaces
I1104 15:38:43.145706   63880 proportion.go:207] Queue <default>: deserved <cpu 4000.00, memory 4959854592.00, hugepages-2Mi 0.00>, allocated <cpu 0.00, memory 0.00>, share <0>
I1104 15:38:43.145714   63880 allocate.go:138] Namespace <default> Queue <default> is overused, ignore it.
I1104 15:38:43.145742   63880 allocate.go:149] Namespace <default> have no queue, skip it
I1104 15:38:43.145753   63880 allocate.go:253] Leaving Allocate ...
I1104 15:38:43.145759   63880 backfill.go:42] Enter Backfill ...
I1104 15:38:43.145766   63880 backfill.go:91] Leaving Backfill ...
I1104 15:38:43.151164   63880 cache.go:634] task unscheduleable default/qj-1-nfcct, message: 2/2 tasks in gang unschedulable: job is not ready, 2 Pending, 2 minAvailable., skip by no condition update
I1104 15:38:43.151171   63880 cache.go:634] task unscheduleable default/qj-1-8g9hf, message: 2/2 tasks in gang unschedulable: job is not ready, 2 Pending, 2 minAvailable., skip by no condition update
I1104 15:38:43.151183   63880 session.go:154] Close Session 3cab7592-ff5c-11e9-bdbc-784f43775513
I1104 15:38:43.151189   63880 scheduler.go:87] End scheduling ...
I1104 15:38:48.153180   63880 scheduler.go:72] Start scheduling ...
I1104 15:38:48.153348   63880 cache.go:732] The priority of job <default/qj-1> is </0>
I1104 15:38:48.153372   63880 cache.go:771] There are <1> Jobs, <1> Queues and <1> Nodes in total for scheduling.
I1104 15:38:48.153378   63880 session.go:135] Open Session 3fa7976c-ff5c-11e9-bdbc-784f43775513 with <1> Job and <1> Queues
I1104 15:38:48.153410   63880 proportion.go:67] The total resource is <cpu 4000.00, memory 4959854592.00, hugepages-2Mi 0.00>
I1104 15:38:48.153423   63880 proportion.go:71] Considering Job <default/qj-1>.
I1104 15:38:48.153428   63880 proportion.go:85] Added Queue <default> attributes.
I1104 15:38:48.153436   63880 proportion.go:127] Considering Queue <default>: weight <1>, total weight <1>.
I1104 15:38:48.153444   63880 proportion.go:144] The attributes of queue <default> in proportion: deserved <cpu 4000.00, memory 4959854592.00, hugepages-2Mi 0.00>, allocate <cpu 0.00, memory 0.00>, request <cpu 2000.00, memory 1073741824.00>, share <0.00>
I1104 15:38:48.153459   63880 proportion.go:154] Exiting when remaining is empty:  <cpu 0.00, memory 0.00, hugepages-2Mi 0.00>
I1104 15:38:48.153495   63880 enqueue.go:43] Enter Enqueue ...
I1104 15:38:48.153499   63880 enqueue.go:58] Added Queue <default> for Job <default/qj-1>
I1104 15:38:48.153505   63880 enqueue.go:75] Try to enqueue PodGroup to 0 Queues
I1104 15:38:48.153512   63880 enqueue.go:122] Leaving Enqueue ...
I1104 15:38:48.153518   63880 allocate.go:43] Enter Allocate ...
I1104 15:38:48.153523   63880 allocate.go:90] Added Job <default/qj-1> into Queue <default>
I1104 15:38:48.153530   63880 allocate.go:94] Try to allocate resource to 1 Namespaces
I1104 15:38:48.153534   63880 proportion.go:207] Queue <default>: deserved <cpu 4000.00, memory 4959854592.00, hugepages-2Mi 0.00>, allocated <cpu 0.00, memory 0.00>, share <0>
I1104 15:38:48.153543   63880 allocate.go:138] Namespace <default> Queue <default> is overused, ignore it.
I1104 15:38:48.153557   63880 allocate.go:149] Namespace <default> have no queue, skip it
I1104 15:38:48.153567   63880 allocate.go:253] Leaving Allocate ...
I1104 15:38:48.153571   63880 backfill.go:42] Enter Backfill ...
I1104 15:38:48.153576   63880 backfill.go:91] Leaving Backfill ...
I1104 15:38:48.167511   63880 cache.go:634] task unscheduleable default/qj-1-nfcct, message: 2/2 tasks in gang unschedulable: job is not ready, 2 Pending, 2 minAvailable., skip by no condition update
I1104 15:38:48.167519   63880 cache.go:634] task unscheduleable default/qj-1-8g9hf, message: 2/2 tasks in gang unschedulable: job is not ready, 2 Pending, 2 minAvailable., skip by no condition update
I1104 15:38:48.167532   63880 session.go:154] Close Session 3fa7976c-ff5c-11e9-bdbc-784f43775513
I1104 15:38:48.167538   63880 scheduler.go:87] End scheduling ...
I1104 15:38:53.167929   63880 scheduler.go:72] Start scheduling ...
I1104 15:38:53.168128   63880 cache.go:732] The priority of job <default/qj-1> is </0>
I1104 15:38:53.168150   63880 cache.go:771] There are <1> Jobs, <1> Queues and <1> Nodes in total for scheduling.
I1104 15:38:53.168155   63880 session.go:135] Open Session 42a4c9ee-ff5c-11e9-bdbc-784f43775513 with <1> Job and <1> Queues
I1104 15:38:53.168197   63880 proportion.go:67] The total resource is <cpu 4000.00, memory 4959854592.00, hugepages-2Mi 0.00>
I1104 15:38:53.168208   63880 proportion.go:71] Considering Job <default/qj-1>.
I1104 15:38:53.168213   63880 proportion.go:85] Added Queue <default> attributes.
I1104 15:38:53.168221   63880 proportion.go:127] Considering Queue <default>: weight <1>, total weight <1>.
I1104 15:38:53.168245   63880 proportion.go:144] The attributes of queue <default> in proportion: deserved <cpu 4000.00, memory 4959854592.00, hugepages-2Mi 0.00>, allocate <cpu 0.00, memory 0.00>, request <cpu 2000.00, memory 1073741824.00>, share <0.00>
I1104 15:38:53.168264   63880 proportion.go:154] Exiting when remaining is empty:  <cpu 0.00, memory 0.00, hugepages-2Mi 0.00>
I1104 15:38:53.168306   63880 enqueue.go:43] Enter Enqueue ...
I1104 15:38:53.168313   63880 enqueue.go:58] Added Queue <default> for Job <default/qj-1>
I1104 15:38:53.168320   63880 enqueue.go:75] Try to enqueue PodGroup to 0 Queues
I1104 15:38:53.168330   63880 enqueue.go:122] Leaving Enqueue ...
I1104 15:38:53.168338   63880 allocate.go:43] Enter Allocate ...
I1104 15:38:53.168344   63880 allocate.go:90] Added Job <default/qj-1> into Queue <default>
I1104 15:38:53.168353   63880 allocate.go:94] Try to allocate resource to 1 Namespaces
I1104 15:38:53.168359   63880 proportion.go:207] Queue <default>: deserved <cpu 4000.00, memory 4959854592.00, hugepages-2Mi 0.00>, allocated <cpu 0.00, memory 0.00>, share <0>
I1104 15:38:53.168370   63880 allocate.go:138] Namespace <default> Queue <default> is overused, ignore it.
I1104 15:38:53.168388   63880 allocate.go:149] Namespace <default> have no queue, skip it
I1104 15:38:53.168401   63880 allocate.go:253] Leaving Allocate ...
I1104 15:38:53.168407   63880 backfill.go:42] Enter Backfill ...
I1104 15:38:53.168414   63880 backfill.go:91] Leaving Backfill ...
I1104 15:38:53.173029   63880 cache.go:634] task unscheduleable default/qj-1-nfcct, message: 2/2 tasks in gang unschedulable: job is not ready, 2 Pending, 2 minAvailable., skip by no condition update
I1104 15:38:53.173038   63880 cache.go:634] task unscheduleable default/qj-1-8g9hf, message: 2/2 tasks in gang unschedulable: job is not ready, 2 Pending, 2 minAvailable., skip by no condition update
I1104 15:38:53.173052   63880 session.go:154] Close Session 42a4c9ee-ff5c-11e9-bdbc-784f43775513
I1104 15:38:53.173058   63880 scheduler.go:87] End scheduling ...
I1104 15:38:58.175530   63880 scheduler.go:72] Start scheduling ...
I1104 15:38:58.175720   63880 cache.go:732] The priority of job <default/qj-1> is </0>
I1104 15:38:58.175743   63880 cache.go:771] There are <1> Jobs, <1> Queues and <1> Nodes in total for scheduling.
I1104 15:38:58.175750   63880 session.go:135] Open Session 45a0e27c-ff5c-11e9-bdbc-784f43775513 with <1> Job and <1> Queues
I1104 15:38:58.175803   63880 proportion.go:67] The total resource is <cpu 4000.00, memory 4959854592.00, hugepages-2Mi 0.00>
I1104 15:38:58.175817   63880 proportion.go:71] Considering Job <default/qj-1>.
I1104 15:38:58.175823   63880 proportion.go:85] Added Queue <default> attributes.
I1104 15:38:58.175831   63880 proportion.go:127] Considering Queue <default>: weight <1>, total weight <1>.
I1104 15:38:58.175838   63880 proportion.go:144] The attributes of queue <default> in proportion: deserved <cpu 4000.00, memory 4959854592.00, hugepages-2Mi 0.00>, allocate <cpu 0.00, memory 0.00>, request <cpu 2000.00, memory 1073741824.00>, share <0.00>
I1104 15:38:58.175853   63880 proportion.go:154] Exiting when remaining is empty:  <cpu 0.00, memory 0.00, hugepages-2Mi 0.00>
I1104 15:38:58.175877   63880 enqueue.go:43] Enter Enqueue ...
I1104 15:38:58.175881   63880 enqueue.go:58] Added Queue <default> for Job <default/qj-1>
I1104 15:38:58.175888   63880 enqueue.go:75] Try to enqueue PodGroup to 0 Queues
I1104 15:38:58.175895   63880 enqueue.go:122] Leaving Enqueue ...
I1104 15:38:58.175901   63880 allocate.go:43] Enter Allocate ...
I1104 15:38:58.175906   63880 allocate.go:90] Added Job <default/qj-1> into Queue <default>
I1104 15:38:58.175912   63880 allocate.go:94] Try to allocate resource to 1 Namespaces
I1104 15:38:58.175917   63880 proportion.go:207] Queue <default>: deserved <cpu 4000.00, memory 4959854592.00, hugepages-2Mi 0.00>, allocated <cpu 0.00, memory 0.00>, share <0>
I1104 15:38:58.175926   63880 allocate.go:138] Namespace <default> Queue <default> is overused, ignore it.
I1104 15:38:58.175946   63880 allocate.go:149] Namespace <default> have no queue, skip it
I1104 15:38:58.175957   63880 allocate.go:253] Leaving Allocate ...
I1104 15:38:58.175962   63880 backfill.go:42] Enter Backfill ...
I1104 15:38:58.175967   63880 backfill.go:91] Leaving Backfill ...
I1104 15:38:58.181812   63880 cache.go:634] task unscheduleable default/qj-1-nfcct, message: 2/2 tasks in gang unschedulable: job is not ready, 2 Pending, 2 minAvailable., skip by no condition update
I1104 15:38:58.181820   63880 cache.go:634] task unscheduleable default/qj-1-8g9hf, message: 2/2 tasks in gang unschedulable: job is not ready, 2 Pending, 2 minAvailable., skip by no condition update
I1104 15:38:58.181833   63880 session.go:154] Close Session 45a0e27c-ff5c-11e9-bdbc-784f43775513
I1104 15:38:58.181840   63880 scheduler.go:87] End scheduling ...
I1104 15:38:58.600279   63880 cache.go:641] Try to delete Job <default/qj-1:default/qj-1>
I1104 15:38:58.605398   63880 cache.go:641] Try to delete Job <default/qj-1:default/qj-1>
I1104 15:38:58.616103   63880 cache.go:641] Try to delete Job <default/qj-1:default/qj-1>
I1104 15:38:58.640857   63880 cache.go:641] Try to delete Job <default/qj-1:default/qj-1>
I1104 15:38:58.682832   63880 cache.go:641] Try to delete Job <default/qj-1:default/qj-1>
I1104 15:38:58.701965   63880 event_handlers.go:215] Updated pod <default/qj-1-8g9hf> in cache.
I1104 15:38:58.702401   63880 event_handlers.go:247] Deleted pod <default/qj-1-8g9hf> from cache.
I1104 15:38:58.709615   63880 cache.go:641] Try to delete Job <default/qj-1:default/qj-1>
I1104 15:38:58.709644   63880 event_handlers.go:215] Updated pod <default/qj-1-nfcct> in cache.
I1104 15:38:58.713693   63880 cache.go:641] Try to delete Job <default/qj-1:default/qj-1>
I1104 15:38:58.713714   63880 event_handlers.go:247] Deleted pod <default/qj-1-nfcct> from cache.
I1104 15:38:58.765911   63880 cache.go:665] Job <default/qj-1:default/qj-1> was deleted.
I1104 15:39:03.184856   63880 scheduler.go:72] Start scheduling ...
I1104 15:39:03.184976   63880 cache.go:771] There are <0> Jobs, <1> Queues and <1> Nodes in total for scheduling.
I1104 15:39:03.184982   63880 session.go:135] Open Session 489d3dae-ff5c-11e9-bdbc-784f43775513 with <0> Job and <1> Queues
I1104 15:39:03.185033   63880 proportion.go:67] The total resource is <cpu 4000.00, memory 4959854592.00, hugepages-2Mi 0.00>
I1104 15:39:03.185050   63880 proportion.go:117] Exiting when total weight is 0
I1104 15:39:03.185066   63880 enqueue.go:43] Enter Enqueue ...
I1104 15:39:03.185071   63880 enqueue.go:75] Try to enqueue PodGroup to 0 Queues
I1104 15:39:03.185077   63880 enqueue.go:122] Leaving Enqueue ...
I1104 15:39:03.185083   63880 allocate.go:43] Enter Allocate ...
I1104 15:39:03.185088   63880 allocate.go:94] Try to allocate resource to 0 Namespaces
I1104 15:39:03.185098   63880 allocate.go:253] Leaving Allocate ...
I1104 15:39:03.185102   63880 backfill.go:42] Enter Backfill ...
I1104 15:39:03.185105   63880 backfill.go:91] Leaving Backfill ...
I1104 15:39:03.185117   63880 session.go:154] Close Session 489d3dae-ff5c-11e9-bdbc-784f43775513
I1104 15:39:03.185120   63880 scheduler.go:87] End scheduling ...
I1104 15:39:08.186294   63880 scheduler.go:72] Start scheduling ...
I1104 15:39:08.186495   63880 cache.go:771] There are <0> Jobs, <1> Queues and <1> Nodes in total for scheduling.
I1104 15:39:08.202801   63880 session.go:135] Open Session 4b9868c6-ff5c-11e9-bdbc-784f43775513 with <0> Job and <1> Queues
I1104 15:39:08.202855   63880 proportion.go:67] The total resource is <cpu 4000.00, memory 4959854592.00, hugepages-2Mi 0.00>
I1104 15:39:08.202876   63880 proportion.go:117] Exiting when total weight is 0
I1104 15:39:08.202907   63880 enqueue.go:43] Enter Enqueue ...
I1104 15:39:08.202912   63880 enqueue.go:75] Try to enqueue PodGroup to 0 Queues
I1104 15:39:08.202920   63880 enqueue.go:122] Leaving Enqueue ...
I1104 15:39:08.202926   63880 allocate.go:43] Enter Allocate ...
I1104 15:39:08.202932   63880 allocate.go:94] Try to allocate resource to 0 Namespaces
I1104 15:39:08.202944   63880 allocate.go:253] Leaving Allocate ...
I1104 15:39:08.202948   63880 backfill.go:42] Enter Backfill ...
I1104 15:39:08.202952   63880 backfill.go:91] Leaving Backfill ...
I1104 15:39:08.202966   63880 session.go:154] Close Session 4b9868c6-ff5c-11e9-bdbc-784f43775513
I1104 15:39:08.202970   63880 scheduler.go:87] End scheduling ...
I1104 15:39:13.208058   63880 scheduler.go:72] Start scheduling ...
I1104 15:39:13.220879   63880 cache.go:771] There are <0> Jobs, <1> Queues and <1> Nodes in total for scheduling.
I1104 15:39:13.220888   63880 session.go:135] Open Session 4e989898-ff5c-11e9-bdbc-784f43775513 with <0> Job and <1> Queues
I1104 15:39:13.220921   63880 proportion.go:67] The total resource is <cpu 4000.00, memory 4959854592.00, hugepages-2Mi 0.00>
I1104 15:39:13.220939   63880 proportion.go:117] Exiting when total weight is 0
I1104 15:39:13.220968   63880 enqueue.go:43] Enter Enqueue ...
I1104 15:39:13.220974   63880 enqueue.go:75] Try to enqueue PodGroup to 0 Queues
I1104 15:39:13.220981   63880 enqueue.go:122] Leaving Enqueue ...
I1104 15:39:13.220987   63880 allocate.go:43] Enter Allocate ...
I1104 15:39:13.220993   63880 allocate.go:94] Try to allocate resource to 0 Namespaces
I1104 15:39:13.221005   63880 allocate.go:253] Leaving Allocate ...
I1104 15:39:13.221009   63880 backfill.go:42] Enter Backfill ...
I1104 15:39:13.221013   63880 backfill.go:91] Leaving Backfill ...
I1104 15:39:13.221026   63880 session.go:154] Close Session 4e989898-ff5c-11e9-bdbc-784f43775513
I1104 15:39:13.221030   63880 scheduler.go:87] End scheduling ...
I1104 15:39:18.221793   63880 scheduler.go:72] Start scheduling ...
I1104 15:39:18.238844   63880 cache.go:771] There are <0> Jobs, <1> Queues and <1> Nodes in total for scheduling.
I1104 15:39:18.238851   63880 session.go:135] Open Session 51964720-ff5c-11e9-bdbc-784f43775513 with <0> Job and <1> Queues
I1104 15:39:18.238898   63880 proportion.go:67] The total resource is <cpu 4000.00, memory 4959854592.00, hugepages-2Mi 0.00>
I1104 15:39:18.238916   63880 proportion.go:117] Exiting when total weight is 0
I1104 15:39:18.238933   63880 enqueue.go:43] Enter Enqueue ...
I1104 15:39:18.238937   63880 enqueue.go:75] Try to enqueue PodGroup to 0 Queues
I1104 15:39:18.238957   63880 enqueue.go:122] Leaving Enqueue ...
I1104 15:39:18.238962   63880 allocate.go:43] Enter Allocate ...
I1104 15:39:18.238967   63880 allocate.go:94] Try to allocate resource to 0 Namespaces
I1104 15:39:18.238979   63880 allocate.go:253] Leaving Allocate ...
I1104 15:39:18.238982   63880 backfill.go:42] Enter Backfill ...
I1104 15:39:18.238986   63880 backfill.go:91] Leaving Backfill ...
I1104 15:39:18.238996   63880 session.go:154] Close Session 51964720-ff5c-11e9-bdbc-784f43775513
I1104 15:39:18.239000   63880 scheduler.go:87] End scheduling ...
I1104 15:39:19.374649   63880 event_handlers.go:189] Added pod <default/qj-1-48k5h> into cache.
I1104 15:39:19.380123   63880 event_handlers.go:409] Add PodGroup(qj-1) into cache, spec(v1alpha1.PodGroupSpec{MinMember:2, Queue:"", PriorityClassName:"", MinResources:(*v1.ResourceList)(nil)})
I1104 15:39:19.383390   63880 event_handlers.go:189] Added pod <default/qj-1-gbshg> into cache.
I1104 15:39:23.241348   63880 scheduler.go:72] Start scheduling ...
I1104 15:39:23.256530   63880 cache.go:732] The priority of job <default/qj-1> is </0>
I1104 15:39:23.256560   63880 cache.go:771] There are <1> Jobs, <1> Queues and <1> Nodes in total for scheduling.
I1104 15:39:23.256567   63880 session.go:135] Open Session 5493e928-ff5c-11e9-bdbc-784f43775513 with <1> Job and <1> Queues
I1104 15:39:23.256620   63880 proportion.go:67] The total resource is <cpu 4000.00, memory 4959854592.00, hugepages-2Mi 0.00>
I1104 15:39:23.256637   63880 proportion.go:71] Considering Job <default/qj-1>.
I1104 15:39:23.256644   63880 proportion.go:85] Added Queue <default> attributes.
I1104 15:39:23.256655   63880 proportion.go:127] Considering Queue <default>: weight <1>, total weight <1>.
I1104 15:39:23.256665   63880 proportion.go:144] The attributes of queue <default> in proportion: deserved <cpu 4000.00, memory 4959854592.00, hugepages-2Mi 0.00>, allocate <cpu 0.00, memory 0.00>, request <cpu 2000.00, memory 0.00>, share <0.00>
I1104 15:39:23.256687   63880 proportion.go:154] Exiting when remaining is empty:  <cpu 0.00, memory 0.00, hugepages-2Mi 0.00>
I1104 15:39:23.256713   63880 enqueue.go:43] Enter Enqueue ...
I1104 15:39:23.256718   63880 enqueue.go:58] Added Queue <default> for Job <default/qj-1>
I1104 15:39:23.256726   63880 enqueue.go:75] Try to enqueue PodGroup to 0 Queues
I1104 15:39:23.256735   63880 enqueue.go:122] Leaving Enqueue ...
I1104 15:39:23.256742   63880 allocate.go:43] Enter Allocate ...
I1104 15:39:23.256749   63880 allocate.go:90] Added Job <default/qj-1> into Queue <default>
I1104 15:39:23.256757   63880 allocate.go:94] Try to allocate resource to 1 Namespaces
I1104 15:39:23.256763   63880 proportion.go:207] Queue <default>: deserved <cpu 4000.00, memory 4959854592.00, hugepages-2Mi 0.00>, allocated <cpu 0.00, memory 0.00>, share <0>
I1104 15:39:23.256774   63880 allocate.go:138] Namespace <default> Queue <default> is overused, ignore it.
I1104 15:39:23.256802   63880 allocate.go:149] Namespace <default> have no queue, skip it
I1104 15:39:23.256816   63880 allocate.go:253] Leaving Allocate ...
I1104 15:39:23.256821   63880 backfill.go:42] Enter Backfill ...
I1104 15:39:23.256828   63880 backfill.go:91] Leaving Backfill ...
I1104 15:39:23.262159   63880 cache.go:187] Updating pod condition for default/qj-1-gbshg to (PodScheduled==False)
I1104 15:39:23.268654   63880 event_handlers.go:215] Updated pod <default/qj-1-gbshg> in cache.
I1104 15:39:23.270005   63880 cache.go:187] Updating pod condition for default/qj-1-48k5h to (PodScheduled==False)
I1104 15:39:23.275044   63880 session.go:154] Close Session 5493e928-ff5c-11e9-bdbc-784f43775513
I1104 15:39:23.275059   63880 scheduler.go:87] End scheduling ...
I1104 15:39:23.275084   63880 event_handlers.go:215] Updated pod <default/qj-1-48k5h> in cache.
I1104 15:39:28.277369   63880 scheduler.go:72] Start scheduling ...
I1104 15:39:28.277583   63880 cache.go:732] The priority of job <default/qj-1> is </0>
I1104 15:39:28.277608   63880 cache.go:771] There are <1> Jobs, <1> Queues and <1> Nodes in total for scheduling.
I1104 15:39:28.277615   63880 session.go:135] Open Session 5792105a-ff5c-11e9-bdbc-784f43775513 with <1> Job and <1> Queues
I1104 15:39:28.277681   63880 proportion.go:67] The total resource is <cpu 4000.00, memory 4959854592.00, hugepages-2Mi 0.00>
I1104 15:39:28.277701   63880 proportion.go:71] Considering Job <default/qj-1>.
I1104 15:39:28.277708   63880 proportion.go:85] Added Queue <default> attributes.
I1104 15:39:28.277719   63880 proportion.go:127] Considering Queue <default>: weight <1>, total weight <1>.
I1104 15:39:28.277729   63880 proportion.go:144] The attributes of queue <default> in proportion: deserved <cpu 4000.00, memory 4959854592.00, hugepages-2Mi 0.00>, allocate <cpu 0.00, memory 0.00>, request <cpu 2000.00, memory 0.00>, share <0.00>
I1104 15:39:28.277748   63880 proportion.go:154] Exiting when remaining is empty:  <cpu 0.00, memory 0.00, hugepages-2Mi 0.00>
I1104 15:39:28.277760   63880 enqueue.go:43] Enter Enqueue ...
I1104 15:39:28.277766   63880 enqueue.go:58] Added Queue <default> for Job <default/qj-1>
I1104 15:39:28.277771   63880 enqueue.go:70] Added Job <default/qj-1> into Queue <default>
I1104 15:39:28.277778   63880 enqueue.go:75] Try to enqueue PodGroup to 1 Queues
I1104 15:39:28.277788   63880 enqueue.go:122] Leaving Enqueue ...
I1104 15:39:28.277796   63880 allocate.go:43] Enter Allocate ...
I1104 15:39:28.277802   63880 allocate.go:90] Added Job <default/qj-1> into Queue <default>
I1104 15:39:28.277810   63880 allocate.go:94] Try to allocate resource to 1 Namespaces
I1104 15:39:28.277816   63880 proportion.go:207] Queue <default>: deserved <cpu 4000.00, memory 4959854592.00, hugepages-2Mi 0.00>, allocated <cpu 0.00, memory 0.00>, share <0>
I1104 15:39:28.277827   63880 allocate.go:138] Namespace <default> Queue <default> is overused, ignore it.
I1104 15:39:28.277844   63880 allocate.go:149] Namespace <default> have no queue, skip it
I1104 15:39:28.277858   63880 allocate.go:253] Leaving Allocate ...
I1104 15:39:28.277863   63880 backfill.go:42] Enter Backfill ...
I1104 15:39:28.277870   63880 backfill.go:91] Leaving Backfill ...
I1104 15:39:28.300633   63880 cache.go:634] task unscheduleable default/qj-1-48k5h, message: 2/2 tasks in gang unschedulable: job is not ready, 2 Pending, 2 minAvailable., skip by no condition update
I1104 15:39:28.300640   63880 cache.go:634] task unscheduleable default/qj-1-gbshg, message: 2/2 tasks in gang unschedulable: job is not ready, 2 Pending, 2 minAvailable., skip by no condition update
I1104 15:39:28.300654   63880 session.go:154] Close Session 5792105a-ff5c-11e9-bdbc-784f43775513
I1104 15:39:28.300660   63880 scheduler.go:87] End scheduling ...
I1104 15:39:33.304827   63880 scheduler.go:72] Start scheduling ...
I1104 15:39:33.304982   63880 cache.go:732] The priority of job <default/qj-1> is </0>
I1104 15:39:33.305000   63880 cache.go:771] There are <1> Jobs, <1> Queues and <1> Nodes in total for scheduling.
I1104 15:39:33.305006   63880 session.go:135] Open Session 5a912f20-ff5c-11e9-bdbc-784f43775513 with <1> Job and <1> Queues
I1104 15:39:33.305035   63880 proportion.go:67] The total resource is <cpu 4000.00, memory 4959854592.00, hugepages-2Mi 0.00>
I1104 15:39:33.305047   63880 proportion.go:71] Considering Job <default/qj-1>.
I1104 15:39:33.305052   63880 proportion.go:85] Added Queue <default> attributes.
I1104 15:39:33.305059   63880 proportion.go:127] Considering Queue <default>: weight <1>, total weight <1>.
I1104 15:39:33.305065   63880 proportion.go:144] The attributes of queue <default> in proportion: deserved <cpu 4000.00, memory 4959854592.00, hugepages-2Mi 0.00>, allocate <cpu 0.00, memory 0.00>, request <cpu 2000.00, memory 0.00>, share <0.00>
I1104 15:39:33.305077   63880 proportion.go:154] Exiting when remaining is empty:  <cpu 0.00, memory 0.00, hugepages-2Mi 0.00>
I1104 15:39:33.305102   63880 enqueue.go:43] Enter Enqueue ...
I1104 15:39:33.305107   63880 enqueue.go:58] Added Queue <default> for Job <default/qj-1>
I1104 15:39:33.305112   63880 enqueue.go:75] Try to enqueue PodGroup to 0 Queues
I1104 15:39:33.305118   63880 enqueue.go:122] Leaving Enqueue ...
I1104 15:39:33.305123   63880 allocate.go:43] Enter Allocate ...
I1104 15:39:33.305128   63880 allocate.go:90] Added Job <default/qj-1> into Queue <default>
I1104 15:39:33.305134   63880 allocate.go:94] Try to allocate resource to 1 Namespaces
I1104 15:39:33.305138   63880 proportion.go:207] Queue <default>: deserved <cpu 4000.00, memory 4959854592.00, hugepages-2Mi 0.00>, allocated <cpu 0.00, memory 0.00>, share <0>
I1104 15:39:33.305145   63880 allocate.go:138] Namespace <default> Queue <default> is overused, ignore it.
I1104 15:39:33.305156   63880 allocate.go:149] Namespace <default> have no queue, skip it
I1104 15:39:33.305165   63880 allocate.go:253] Leaving Allocate ...
I1104 15:39:33.305168   63880 backfill.go:42] Enter Backfill ...
I1104 15:39:33.305173   63880 backfill.go:91] Leaving Backfill ...
I1104 15:39:33.311219   63880 cache.go:634] task unscheduleable default/qj-1-48k5h, message: 2/2 tasks in gang unschedulable: job is not ready, 2 Pending, 2 minAvailable., skip by no condition update
I1104 15:39:33.311227   63880 cache.go:634] task unscheduleable default/qj-1-gbshg, message: 2/2 tasks in gang unschedulable: job is not ready, 2 Pending, 2 minAvailable., skip by no condition update
I1104 15:39:33.311242   63880 session.go:154] Close Session 5a912f20-ff5c-11e9-bdbc-784f43775513
I1104 15:39:33.311250   63880 scheduler.go:87] End scheduling ...
I1104 15:39:38.311686   63880 scheduler.go:72] Start scheduling ...
I1104 15:39:38.311946   63880 cache.go:732] The priority of job <default/qj-1> is </0>
I1104 15:39:38.311974   63880 cache.go:771] There are <1> Jobs, <1> Queues and <1> Nodes in total for scheduling.
I1104 15:39:38.311981   63880 session.go:135] Open Session 5d8d2e18-ff5c-11e9-bdbc-784f43775513 with <1> Job and <1> Queues
I1104 15:39:38.311996   63880 proportion.go:67] The total resource is <cpu 4000.00, memory 4959854592.00, hugepages-2Mi 0.00>
I1104 15:39:38.312014   63880 proportion.go:71] Considering Job <default/qj-1>.
I1104 15:39:38.312021   63880 proportion.go:85] Added Queue <default> attributes.
I1104 15:39:38.312034   63880 proportion.go:127] Considering Queue <default>: weight <1>, total weight <1>.
I1104 15:39:38.312044   63880 proportion.go:144] The attributes of queue <default> in proportion: deserved <cpu 4000.00, memory 4959854592.00, hugepages-2Mi 0.00>, allocate <cpu 0.00, memory 0.00>, request <cpu 2000.00, memory 0.00>, share <0.00>
I1104 15:39:38.312062   63880 proportion.go:154] Exiting when remaining is empty:  <cpu 0.00, memory 0.00, hugepages-2Mi 0.00>
I1104 15:39:38.312108   63880 enqueue.go:43] Enter Enqueue ...
I1104 15:39:38.312112   63880 enqueue.go:58] Added Queue <default> for Job <default/qj-1>
I1104 15:39:38.312117   63880 enqueue.go:75] Try to enqueue PodGroup to 0 Queues
I1104 15:39:38.312123   63880 enqueue.go:122] Leaving Enqueue ...
I1104 15:39:38.312129   63880 allocate.go:43] Enter Allocate ...
I1104 15:39:38.312133   63880 allocate.go:90] Added Job <default/qj-1> into Queue <default>
I1104 15:39:38.312139   63880 allocate.go:94] Try to allocate resource to 1 Namespaces
I1104 15:39:38.312143   63880 proportion.go:207] Queue <default>: deserved <cpu 4000.00, memory 4959854592.00, hugepages-2Mi 0.00>, allocated <cpu 0.00, memory 0.00>, share <0>
I1104 15:39:38.312151   63880 allocate.go:138] Namespace <default> Queue <default> is overused, ignore it.
I1104 15:39:38.312163   63880 allocate.go:149] Namespace <default> have no queue, skip it
I1104 15:39:38.312172   63880 allocate.go:253] Leaving Allocate ...
I1104 15:39:38.312175   63880 backfill.go:42] Enter Backfill ...
I1104 15:39:38.312180   63880 backfill.go:91] Leaving Backfill ...
I1104 15:39:38.316494   63880 cache.go:634] task unscheduleable default/qj-1-48k5h, message: 2/2 tasks in gang unschedulable: job is not ready, 2 Pending, 2 minAvailable., skip by no condition update
I1104 15:39:38.316505   63880 cache.go:634] task unscheduleable default/qj-1-gbshg, message: 2/2 tasks in gang unschedulable: job is not ready, 2 Pending, 2 minAvailable., skip by no condition update
I1104 15:39:38.316515   63880 session.go:154] Close Session 5d8d2e18-ff5c-11e9-bdbc-784f43775513
I1104 15:39:38.316524   63880 scheduler.go:87] End scheduling ...
I1104 15:39:43.318902   63880 scheduler.go:72] Start scheduling ...
I1104 15:39:43.330068   63880 cache.go:732] The priority of job <default/qj-1> is </0>
I1104 15:39:43.330087   63880 cache.go:771] There are <1> Jobs, <1> Queues and <1> Nodes in total for scheduling.
I1104 15:39:43.330091   63880 session.go:135] Open Session 608ae498-ff5c-11e9-bdbc-784f43775513 with <1> Job and <1> Queues
I1104 15:39:43.330138   63880 proportion.go:67] The total resource is <cpu 4000.00, memory 4959854592.00, hugepages-2Mi 0.00>
I1104 15:39:43.330150   63880 proportion.go:71] Considering Job <default/qj-1>.
I1104 15:39:43.330154   63880 proportion.go:85] Added Queue <default> attributes.
I1104 15:39:43.330161   63880 proportion.go:127] Considering Queue <default>: weight <1>, total weight <1>.
I1104 15:39:43.330168   63880 proportion.go:144] The attributes of queue <default> in proportion: deserved <cpu 4000.00, memory 4959854592.00, hugepages-2Mi 0.00>, allocate <cpu 0.00, memory 0.00>, request <cpu 2000.00, memory 0.00>, share <0.00>
I1104 15:39:43.330180   63880 proportion.go:154] Exiting when remaining is empty:  <cpu 0.00, memory 0.00, hugepages-2Mi 0.00>
I1104 15:39:43.330187   63880 enqueue.go:43] Enter Enqueue ...
I1104 15:39:43.330191   63880 enqueue.go:58] Added Queue <default> for Job <default/qj-1>
I1104 15:39:43.330196   63880 enqueue.go:75] Try to enqueue PodGroup to 0 Queues
I1104 15:39:43.330202   63880 enqueue.go:122] Leaving Enqueue ...
I1104 15:39:43.330208   63880 allocate.go:43] Enter Allocate ...
I1104 15:39:43.330212   63880 allocate.go:90] Added Job <default/qj-1> into Queue <default>
I1104 15:39:43.330218   63880 allocate.go:94] Try to allocate resource to 1 Namespaces
I1104 15:39:43.330222   63880 proportion.go:207] Queue <default>: deserved <cpu 4000.00, memory 4959854592.00, hugepages-2Mi 0.00>, allocated <cpu 0.00, memory 0.00>, share <0>
I1104 15:39:43.330230   63880 allocate.go:138] Namespace <default> Queue <default> is overused, ignore it.
I1104 15:39:43.330242   63880 allocate.go:149] Namespace <default> have no queue, skip it
I1104 15:39:43.330252   63880 allocate.go:253] Leaving Allocate ...
I1104 15:39:43.330256   63880 backfill.go:42] Enter Backfill ...
I1104 15:39:43.330261   63880 backfill.go:91] Leaving Backfill ...
I1104 15:39:43.335161   63880 cache.go:634] task unscheduleable default/qj-1-48k5h, message: 2/2 tasks in gang unschedulable: job is not ready, 2 Pending, 2 minAvailable., skip by no condition update
I1104 15:39:43.335170   63880 cache.go:634] task unscheduleable default/qj-1-gbshg, message: 2/2 tasks in gang unschedulable: job is not ready, 2 Pending, 2 minAvailable., skip by no condition update
I1104 15:39:43.335182   63880 session.go:154] Close Session 608ae498-ff5c-11e9-bdbc-784f43775513
I1104 15:39:43.335188   63880 scheduler.go:87] End scheduling ...
I1104 15:39:48.339263   63880 scheduler.go:72] Start scheduling ...
I1104 15:39:48.344665   63880 cache.go:732] The priority of job <default/qj-1> is </0>
I1104 15:39:48.344689   63880 cache.go:771] There are <1> Jobs, <1> Queues and <1> Nodes in total for scheduling.
I1104 15:39:48.344695   63880 session.go:135] Open Session 63880e8c-ff5c-11e9-bdbc-784f43775513 with <1> Job and <1> Queues
I1104 15:39:48.344735   63880 proportion.go:67] The total resource is <cpu 4000.00, memory 4959854592.00, hugepages-2Mi 0.00>
I1104 15:39:48.344748   63880 proportion.go:71] Considering Job <default/qj-1>.
I1104 15:39:48.344753   63880 proportion.go:85] Added Queue <default> attributes.
I1104 15:39:48.344760   63880 proportion.go:127] Considering Queue <default>: weight <1>, total weight <1>.
I1104 15:39:48.344767   63880 proportion.go:144] The attributes of queue <default> in proportion: deserved <cpu 4000.00, memory 4959854592.00, hugepages-2Mi 0.00>, allocate <cpu 0.00, memory 0.00>, request <cpu 2000.00, memory 0.00>, share <0.00>
I1104 15:39:48.344781   63880 proportion.go:154] Exiting when remaining is empty:  <cpu 0.00, memory 0.00, hugepages-2Mi 0.00>
I1104 15:39:48.344801   63880 enqueue.go:43] Enter Enqueue ...
I1104 15:39:48.344806   63880 enqueue.go:58] Added Queue <default> for Job <default/qj-1>
I1104 15:39:48.344811   63880 enqueue.go:75] Try to enqueue PodGroup to 0 Queues
I1104 15:39:48.344818   63880 enqueue.go:122] Leaving Enqueue ...
I1104 15:39:48.344823   63880 allocate.go:43] Enter Allocate ...
I1104 15:39:48.344828   63880 allocate.go:90] Added Job <default/qj-1> into Queue <default>
I1104 15:39:48.344835   63880 allocate.go:94] Try to allocate resource to 1 Namespaces
I1104 15:39:48.344841   63880 proportion.go:207] Queue <default>: deserved <cpu 4000.00, memory 4959854592.00, hugepages-2Mi 0.00>, allocated <cpu 0.00, memory 0.00>, share <0>
I1104 15:39:48.344851   63880 allocate.go:138] Namespace <default> Queue <default> is overused, ignore it.
I1104 15:39:48.344864   63880 allocate.go:149] Namespace <default> have no queue, skip it
I1104 15:39:48.344874   63880 allocate.go:253] Leaving Allocate ...
I1104 15:39:48.344880   63880 backfill.go:42] Enter Backfill ...
I1104 15:39:48.344886   63880 backfill.go:91] Leaving Backfill ...
I1104 15:39:48.350676   63880 cache.go:634] task unscheduleable default/qj-1-48k5h, message: 2/2 tasks in gang unschedulable: job is not ready, 2 Pending, 2 minAvailable., skip by no condition update
I1104 15:39:48.350682   63880 cache.go:634] task unscheduleable default/qj-1-gbshg, message: 2/2 tasks in gang unschedulable: job is not ready, 2 Pending, 2 minAvailable., skip by no condition update
I1104 15:39:48.350694   63880 session.go:154] Close Session 63880e8c-ff5c-11e9-bdbc-784f43775513
I1104 15:39:48.350701   63880 scheduler.go:87] End scheduling ...
I1104 15:39:53.351603   63880 scheduler.go:72] Start scheduling ...
I1104 15:39:53.359872   63880 cache.go:732] The priority of job <default/qj-1> is </0>
I1104 15:39:53.359898   63880 cache.go:771] There are <1> Jobs, <1> Queues and <1> Nodes in total for scheduling.
I1104 15:39:53.359905   63880 session.go:135] Open Session 668550ae-ff5c-11e9-bdbc-784f43775513 with <1> Job and <1> Queues
I1104 15:39:53.359973   63880 proportion.go:67] The total resource is <cpu 4000.00, memory 4959854592.00, hugepages-2Mi 0.00>
I1104 15:39:53.359985   63880 proportion.go:71] Considering Job <default/qj-1>.
I1104 15:39:53.359990   63880 proportion.go:85] Added Queue <default> attributes.
I1104 15:39:53.359997   63880 proportion.go:127] Considering Queue <default>: weight <1>, total weight <1>.
I1104 15:39:53.360003   63880 proportion.go:144] The attributes of queue <default> in proportion: deserved <cpu 4000.00, memory 4959854592.00, hugepages-2Mi 0.00>, allocate <cpu 0.00, memory 0.00>, request <cpu 2000.00, memory 0.00>, share <0.00>
I1104 15:39:53.360014   63880 proportion.go:154] Exiting when remaining is empty:  <cpu 0.00, memory 0.00, hugepages-2Mi 0.00>
I1104 15:39:53.360032   63880 enqueue.go:43] Enter Enqueue ...
I1104 15:39:53.360036   63880 enqueue.go:58] Added Queue <default> for Job <default/qj-1>
I1104 15:39:53.360041   63880 enqueue.go:75] Try to enqueue PodGroup to 0 Queues
I1104 15:39:53.360047   63880 enqueue.go:122] Leaving Enqueue ...
I1104 15:39:53.360053   63880 allocate.go:43] Enter Allocate ...
I1104 15:39:53.360057   63880 allocate.go:90] Added Job <default/qj-1> into Queue <default>
I1104 15:39:53.360062   63880 allocate.go:94] Try to allocate resource to 1 Namespaces
I1104 15:39:53.360066   63880 proportion.go:207] Queue <default>: deserved <cpu 4000.00, memory 4959854592.00, hugepages-2Mi 0.00>, allocated <cpu 0.00, memory 0.00>, share <0>
I1104 15:39:53.360074   63880 allocate.go:138] Namespace <default> Queue <default> is overused, ignore it.
I1104 15:39:53.360085   63880 allocate.go:149] Namespace <default> have no queue, skip it
I1104 15:39:53.360093   63880 allocate.go:253] Leaving Allocate ...
I1104 15:39:53.360097   63880 backfill.go:42] Enter Backfill ...
I1104 15:39:53.360101   63880 backfill.go:91] Leaving Backfill ...
I1104 15:39:53.365454   63880 cache.go:634] task unscheduleable default/qj-1-48k5h, message: 2/2 tasks in gang unschedulable: job is not ready, 2 Pending, 2 minAvailable., skip by no condition update
I1104 15:39:53.365461   63880 cache.go:634] task unscheduleable default/qj-1-gbshg, message: 2/2 tasks in gang unschedulable: job is not ready, 2 Pending, 2 minAvailable., skip by no condition update
I1104 15:39:53.365476   63880 session.go:154] Close Session 668550ae-ff5c-11e9-bdbc-784f43775513
I1104 15:39:53.365484   63880 scheduler.go:87] End scheduling ...
I1104 15:39:58.368788   63880 scheduler.go:72] Start scheduling ...
I1104 15:39:58.376000   63880 cache.go:732] The priority of job <default/qj-1> is </0>
I1104 15:39:58.376031   63880 cache.go:771] There are <1> Jobs, <1> Queues and <1> Nodes in total for scheduling.
I1104 15:39:58.376039   63880 session.go:135] Open Session 6982b7ba-ff5c-11e9-bdbc-784f43775513 with <1> Job and <1> Queues
I1104 15:39:58.376078   63880 proportion.go:67] The total resource is <cpu 4000.00, memory 4959854592.00, hugepages-2Mi 0.00>
I1104 15:39:58.376094   63880 proportion.go:71] Considering Job <default/qj-1>.
I1104 15:39:58.376101   63880 proportion.go:85] Added Queue <default> attributes.
I1104 15:39:58.376111   63880 proportion.go:127] Considering Queue <default>: weight <1>, total weight <1>.
I1104 15:39:58.376121   63880 proportion.go:144] The attributes of queue <default> in proportion: deserved <cpu 4000.00, memory 4959854592.00, hugepages-2Mi 0.00>, allocate <cpu 0.00, memory 0.00>, request <cpu 2000.00, memory 0.00>, share <0.00>
I1104 15:39:58.376139   63880 proportion.go:154] Exiting when remaining is empty:  <cpu 0.00, memory 0.00, hugepages-2Mi 0.00>
I1104 15:39:58.376178   63880 enqueue.go:43] Enter Enqueue ...
I1104 15:39:58.376183   63880 enqueue.go:58] Added Queue <default> for Job <default/qj-1>
I1104 15:39:58.376191   63880 enqueue.go:75] Try to enqueue PodGroup to 0 Queues
I1104 15:39:58.376201   63880 enqueue.go:122] Leaving Enqueue ...
I1104 15:39:58.376208   63880 allocate.go:43] Enter Allocate ...
I1104 15:39:58.376214   63880 allocate.go:90] Added Job <default/qj-1> into Queue <default>
I1104 15:39:58.376223   63880 allocate.go:94] Try to allocate resource to 1 Namespaces
I1104 15:39:58.376228   63880 proportion.go:207] Queue <default>: deserved <cpu 4000.00, memory 4959854592.00, hugepages-2Mi 0.00>, allocated <cpu 0.00, memory 0.00>, share <0>
I1104 15:39:58.376240   63880 allocate.go:138] Namespace <default> Queue <default> is overused, ignore it.
I1104 15:39:58.376257   63880 allocate.go:149] Namespace <default> have no queue, skip it
I1104 15:39:58.376270   63880 allocate.go:253] Leaving Allocate ...
I1104 15:39:58.376276   63880 backfill.go:42] Enter Backfill ...
I1104 15:39:58.376282   63880 backfill.go:91] Leaving Backfill ...
I1104 15:39:58.380867   63880 cache.go:634] task unscheduleable default/qj-1-48k5h, message: 2/2 tasks in gang unschedulable: job is not ready, 2 Pending, 2 minAvailable., skip by no condition update
I1104 15:39:58.380877   63880 cache.go:634] task unscheduleable default/qj-1-gbshg, message: 2/2 tasks in gang unschedulable: job is not ready, 2 Pending, 2 minAvailable., skip by no condition update
I1104 15:39:58.380891   63880 session.go:154] Close Session 6982b7ba-ff5c-11e9-bdbc-784f43775513
I1104 15:39:58.380899   63880 scheduler.go:87] End scheduling ...
I1104 15:40:03.381308   63880 scheduler.go:72] Start scheduling ...
I1104 15:40:03.394702   63880 cache.go:732] The priority of job <default/qj-1> is </0>
I1104 15:40:03.394724   63880 cache.go:771] There are <1> Jobs, <1> Queues and <1> Nodes in total for scheduling.
I1104 15:40:03.394729   63880 session.go:135] Open Session 6c80833e-ff5c-11e9-bdbc-784f43775513 with <1> Job and <1> Queues
I1104 15:40:03.394774   63880 proportion.go:67] The total resource is <cpu 4000.00, memory 4959854592.00, hugepages-2Mi 0.00>
I1104 15:40:03.394787   63880 proportion.go:71] Considering Job <default/qj-1>.
I1104 15:40:03.394793   63880 proportion.go:85] Added Queue <default> attributes.
I1104 15:40:03.394802   63880 proportion.go:127] Considering Queue <default>: weight <1>, total weight <1>.
I1104 15:40:03.394809   63880 proportion.go:144] The attributes of queue <default> in proportion: deserved <cpu 4000.00, memory 4959854592.00, hugepages-2Mi 0.00>, allocate <cpu 0.00, memory 0.00>, request <cpu 2000.00, memory 0.00>, share <0.00>
I1104 15:40:03.394824   63880 proportion.go:154] Exiting when remaining is empty:  <cpu 0.00, memory 0.00, hugepages-2Mi 0.00>
I1104 15:40:03.394844   63880 enqueue.go:43] Enter Enqueue ...
I1104 15:40:03.394848   63880 enqueue.go:58] Added Queue <default> for Job <default/qj-1>
I1104 15:40:03.394854   63880 enqueue.go:75] Try to enqueue PodGroup to 0 Queues
I1104 15:40:03.394861   63880 enqueue.go:122] Leaving Enqueue ...
I1104 15:40:03.394867   63880 allocate.go:43] Enter Allocate ...
I1104 15:40:03.394872   63880 allocate.go:90] Added Job <default/qj-1> into Queue <default>
I1104 15:40:03.394879   63880 allocate.go:94] Try to allocate resource to 1 Namespaces
I1104 15:40:03.394884   63880 proportion.go:207] Queue <default>: deserved <cpu 4000.00, memory 4959854592.00, hugepages-2Mi 0.00>, allocated <cpu 0.00, memory 0.00>, share <0>
I1104 15:40:03.394893   63880 allocate.go:138] Namespace <default> Queue <default> is overused, ignore it.
I1104 15:40:03.394906   63880 allocate.go:149] Namespace <default> have no queue, skip it
I1104 15:40:03.394917   63880 allocate.go:253] Leaving Allocate ...
I1104 15:40:03.394921   63880 backfill.go:42] Enter Backfill ...
I1104 15:40:03.394926   63880 backfill.go:91] Leaving Backfill ...
I1104 15:40:03.402324   63880 cache.go:634] task unscheduleable default/qj-1-48k5h, message: 2/2 tasks in gang unschedulable: job is not ready, 2 Pending, 2 minAvailable., skip by no condition update
I1104 15:40:03.402331   63880 cache.go:634] task unscheduleable default/qj-1-gbshg, message: 2/2 tasks in gang unschedulable: job is not ready, 2 Pending, 2 minAvailable., skip by no condition update
I1104 15:40:03.402343   63880 session.go:154] Close Session 6c80833e-ff5c-11e9-bdbc-784f43775513
I1104 15:40:03.402350   63880 scheduler.go:87] End scheduling ...
I1104 15:40:08.407016   63880 scheduler.go:72] Start scheduling ...
I1104 15:40:08.408944   63880 cache.go:732] The priority of job <default/qj-1> is </0>
I1104 15:40:08.408970   63880 cache.go:771] There are <1> Jobs, <1> Queues and <1> Nodes in total for scheduling.
I1104 15:40:08.408977   63880 session.go:135] Open Session 6f7d9f86-ff5c-11e9-bdbc-784f43775513 with <1> Job and <1> Queues
I1104 15:40:08.409031   63880 proportion.go:67] The total resource is <cpu 4000.00, memory 4959854592.00, hugepages-2Mi 0.00>
I1104 15:40:08.409048   63880 proportion.go:71] Considering Job <default/qj-1>.
I1104 15:40:08.409055   63880 proportion.go:85] Added Queue <default> attributes.
I1104 15:40:08.409065   63880 proportion.go:127] Considering Queue <default>: weight <1>, total weight <1>.
I1104 15:40:08.409076   63880 proportion.go:144] The attributes of queue <default> in proportion: deserved <cpu 4000.00, memory 4959854592.00, hugepages-2Mi 0.00>, allocate <cpu 0.00, memory 0.00>, request <cpu 2000.00, memory 0.00>, share <0.00>
I1104 15:40:08.409094   63880 proportion.go:154] Exiting when remaining is empty:  <cpu 0.00, memory 0.00, hugepages-2Mi 0.00>
I1104 15:40:08.409123   63880 enqueue.go:43] Enter Enqueue ...
I1104 15:40:08.409128   63880 enqueue.go:58] Added Queue <default> for Job <default/qj-1>
I1104 15:40:08.409136   63880 enqueue.go:75] Try to enqueue PodGroup to 0 Queues
I1104 15:40:08.409146   63880 enqueue.go:122] Leaving Enqueue ...
I1104 15:40:08.409153   63880 allocate.go:43] Enter Allocate ...
I1104 15:40:08.409161   63880 allocate.go:90] Added Job <default/qj-1> into Queue <default>
I1104 15:40:08.409169   63880 allocate.go:94] Try to allocate resource to 1 Namespaces
I1104 15:40:08.409175   63880 proportion.go:207] Queue <default>: deserved <cpu 4000.00, memory 4959854592.00, hugepages-2Mi 0.00>, allocated <cpu 0.00, memory 0.00>, share <0>
I1104 15:40:08.409186   63880 allocate.go:138] Namespace <default> Queue <default> is overused, ignore it.
I1104 15:40:08.409203   63880 allocate.go:149] Namespace <default> have no queue, skip it
I1104 15:40:08.409217   63880 allocate.go:253] Leaving Allocate ...
I1104 15:40:08.409223   63880 backfill.go:42] Enter Backfill ...
I1104 15:40:08.409229   63880 backfill.go:91] Leaving Backfill ...
I1104 15:40:08.416924   63880 cache.go:634] task unscheduleable default/qj-1-48k5h, message: 2/2 tasks in gang unschedulable: job is not ready, 2 Pending, 2 minAvailable., skip by no condition update
I1104 15:40:08.416935   63880 cache.go:634] task unscheduleable default/qj-1-gbshg, message: 2/2 tasks in gang unschedulable: job is not ready, 2 Pending, 2 minAvailable., skip by no condition update
I1104 15:40:08.416949   63880 session.go:154] Close Session 6f7d9f86-ff5c-11e9-bdbc-784f43775513
I1104 15:40:08.416958   63880 scheduler.go:87] End scheduling ...
I1104 15:40:13.417275   63880 scheduler.go:72] Start scheduling ...
I1104 15:40:13.423710   63880 cache.go:732] The priority of job <default/qj-1> is </0>
I1104 15:40:13.423736   63880 cache.go:771] There are <1> Jobs, <1> Queues and <1> Nodes in total for scheduling.
I1104 15:40:13.423743   63880 session.go:135] Open Session 727ad0aa-ff5c-11e9-bdbc-784f43775513 with <1> Job and <1> Queues
I1104 15:40:13.423795   63880 proportion.go:67] The total resource is <cpu 4000.00, memory 4959854592.00, hugepages-2Mi 0.00>
I1104 15:40:13.423811   63880 proportion.go:71] Considering Job <default/qj-1>.
I1104 15:40:13.423817   63880 proportion.go:85] Added Queue <default> attributes.
I1104 15:40:13.423830   63880 proportion.go:127] Considering Queue <default>: weight <1>, total weight <1>.
I1104 15:40:13.423840   63880 proportion.go:144] The attributes of queue <default> in proportion: deserved <cpu 4000.00, memory 4959854592.00, hugepages-2Mi 0.00>, allocate <cpu 0.00, memory 0.00>, request <cpu 2000.00, memory 0.00>, share <0.00>
I1104 15:40:13.423858   63880 proportion.go:154] Exiting when remaining is empty:  <cpu 0.00, memory 0.00, hugepages-2Mi 0.00>
I1104 15:40:13.423884   63880 enqueue.go:43] Enter Enqueue ...
I1104 15:40:13.423890   63880 enqueue.go:58] Added Queue <default> for Job <default/qj-1>
I1104 15:40:13.423898   63880 enqueue.go:75] Try to enqueue PodGroup to 0 Queues
I1104 15:40:13.423907   63880 enqueue.go:122] Leaving Enqueue ...
I1104 15:40:13.423915   63880 allocate.go:43] Enter Allocate ...
I1104 15:40:13.423921   63880 allocate.go:90] Added Job <default/qj-1> into Queue <default>
I1104 15:40:13.423929   63880 allocate.go:94] Try to allocate resource to 1 Namespaces
I1104 15:40:13.423935   63880 proportion.go:207] Queue <default>: deserved <cpu 4000.00, memory 4959854592.00, hugepages-2Mi 0.00>, allocated <cpu 0.00, memory 0.00>, share <0>
I1104 15:40:13.423946   63880 allocate.go:138] Namespace <default> Queue <default> is overused, ignore it.
I1104 15:40:13.423963   63880 allocate.go:149] Namespace <default> have no queue, skip it
I1104 15:40:13.423977   63880 allocate.go:253] Leaving Allocate ...
I1104 15:40:13.423982   63880 backfill.go:42] Enter Backfill ...
I1104 15:40:13.423989   63880 backfill.go:91] Leaving Backfill ...
I1104 15:40:13.431417   63880 cache.go:634] task unscheduleable default/qj-1-48k5h, message: 2/2 tasks in gang unschedulable: job is not ready, 2 Pending, 2 minAvailable., skip by no condition update
I1104 15:40:13.431424   63880 cache.go:634] task unscheduleable default/qj-1-gbshg, message: 2/2 tasks in gang unschedulable: job is not ready, 2 Pending, 2 minAvailable., skip by no condition update
I1104 15:40:13.431437   63880 session.go:154] Close Session 727ad0aa-ff5c-11e9-bdbc-784f43775513
I1104 15:40:13.431443   63880 scheduler.go:87] End scheduling ...
I1104 15:40:18.431607   63880 scheduler.go:72] Start scheduling ...
I1104 15:40:18.441722   63880 cache.go:732] The priority of job <default/qj-1> is </0>
I1104 15:40:18.441745   63880 cache.go:771] There are <1> Jobs, <1> Queues and <1> Nodes in total for scheduling.
I1104 15:40:18.441750   63880 session.go:135] Open Session 7578818a-ff5c-11e9-bdbc-784f43775513 with <1> Job and <1> Queues
I1104 15:40:18.441789   63880 proportion.go:67] The total resource is <cpu 4000.00, memory 4959854592.00, hugepages-2Mi 0.00>
I1104 15:40:18.441803   63880 proportion.go:71] Considering Job <default/qj-1>.
I1104 15:40:18.441808   63880 proportion.go:85] Added Queue <default> attributes.
I1104 15:40:18.441816   63880 proportion.go:127] Considering Queue <default>: weight <1>, total weight <1>.
I1104 15:40:18.441824   63880 proportion.go:144] The attributes of queue <default> in proportion: deserved <cpu 4000.00, memory 4959854592.00, hugepages-2Mi 0.00>, allocate <cpu 0.00, memory 0.00>, request <cpu 2000.00, memory 0.00>, share <0.00>
I1104 15:40:18.441858   63880 proportion.go:154] Exiting when remaining is empty:  <cpu 0.00, memory 0.00, hugepages-2Mi 0.00>
I1104 15:40:18.441909   63880 enqueue.go:43] Enter Enqueue ...
I1104 15:40:18.441914   63880 enqueue.go:58] Added Queue <default> for Job <default/qj-1>
I1104 15:40:18.441922   63880 enqueue.go:75] Try to enqueue PodGroup to 0 Queues
I1104 15:40:18.441930   63880 enqueue.go:122] Leaving Enqueue ...
I1104 15:40:18.441937   63880 allocate.go:43] Enter Allocate ...
I1104 15:40:18.441941   63880 allocate.go:90] Added Job <default/qj-1> into Queue <default>
I1104 15:40:18.441950   63880 allocate.go:94] Try to allocate resource to 1 Namespaces
I1104 15:40:18.441956   63880 proportion.go:207] Queue <default>: deserved <cpu 4000.00, memory 4959854592.00, hugepages-2Mi 0.00>, allocated <cpu 0.00, memory 0.00>, share <0>
I1104 15:40:18.441968   63880 allocate.go:138] Namespace <default> Queue <default> is overused, ignore it.
I1104 15:40:18.441981   63880 allocate.go:149] Namespace <default> have no queue, skip it
I1104 15:40:18.441994   63880 allocate.go:253] Leaving Allocate ...
I1104 15:40:18.442000   63880 backfill.go:42] Enter Backfill ...
I1104 15:40:18.442006   63880 backfill.go:91] Leaving Backfill ...
I1104 15:40:18.446235   63880 cache.go:634] task unscheduleable default/qj-1-48k5h, message: 2/2 tasks in gang unschedulable: job is not ready, 2 Pending, 2 minAvailable., skip by no condition update
I1104 15:40:18.446243   63880 cache.go:634] task unscheduleable default/qj-1-gbshg, message: 2/2 tasks in gang unschedulable: job is not ready, 2 Pending, 2 minAvailable., skip by no condition update
I1104 15:40:18.446257   63880 session.go:154] Close Session 7578818a-ff5c-11e9-bdbc-784f43775513
I1104 15:40:18.446265   63880 scheduler.go:87] End scheduling ...
I1104 15:40:23.446783   63880 scheduler.go:72] Start scheduling ...
I1104 15:40:23.456272   63880 cache.go:732] The priority of job <default/qj-1> is </0>
I1104 15:40:23.456291   63880 cache.go:771] There are <1> Jobs, <1> Queues and <1> Nodes in total for scheduling.
I1104 15:40:23.456296   63880 session.go:135] Open Session 7875aa98-ff5c-11e9-bdbc-784f43775513 with <1> Job and <1> Queues
I1104 15:40:23.456330   63880 proportion.go:67] The total resource is <cpu 4000.00, memory 4959854592.00, hugepages-2Mi 0.00>
I1104 15:40:23.456341   63880 proportion.go:71] Considering Job <default/qj-1>.
I1104 15:40:23.456346   63880 proportion.go:85] Added Queue <default> attributes.
I1104 15:40:23.456353   63880 proportion.go:127] Considering Queue <default>: weight <1>, total weight <1>.
I1104 15:40:23.456359   63880 proportion.go:144] The attributes of queue <default> in proportion: deserved <cpu 4000.00, memory 4959854592.00, hugepages-2Mi 0.00>, allocate <cpu 0.00, memory 0.00>, request <cpu 2000.00, memory 0.00>, share <0.00>
I1104 15:40:23.456371   63880 proportion.go:154] Exiting when remaining is empty:  <cpu 0.00, memory 0.00, hugepages-2Mi 0.00>
I1104 15:40:23.456396   63880 enqueue.go:43] Enter Enqueue ...
I1104 15:40:23.456400   63880 enqueue.go:58] Added Queue <default> for Job <default/qj-1>
I1104 15:40:23.456405   63880 enqueue.go:75] Try to enqueue PodGroup to 0 Queues
I1104 15:40:23.456411   63880 enqueue.go:122] Leaving Enqueue ...
I1104 15:40:23.456416   63880 allocate.go:43] Enter Allocate ...
I1104 15:40:23.456421   63880 allocate.go:90] Added Job <default/qj-1> into Queue <default>
I1104 15:40:23.456426   63880 allocate.go:94] Try to allocate resource to 1 Namespaces
I1104 15:40:23.456430   63880 proportion.go:207] Queue <default>: deserved <cpu 4000.00, memory 4959854592.00, hugepages-2Mi 0.00>, allocated <cpu 0.00, memory 0.00>, share <0>
I1104 15:40:23.456438   63880 allocate.go:138] Namespace <default> Queue <default> is overused, ignore it.
I1104 15:40:23.456449   63880 allocate.go:149] Namespace <default> have no queue, skip it
I1104 15:40:23.456458   63880 allocate.go:253] Leaving Allocate ...
I1104 15:40:23.456462   63880 backfill.go:42] Enter Backfill ...
I1104 15:40:23.456466   63880 backfill.go:91] Leaving Backfill ...
I1104 15:40:23.461064   63880 cache.go:634] task unscheduleable default/qj-1-gbshg, message: 2/2 tasks in gang unschedulable: job is not ready, 2 Pending, 2 minAvailable., skip by no condition update
I1104 15:40:23.461071   63880 cache.go:634] task unscheduleable default/qj-1-48k5h, message: 2/2 tasks in gang unschedulable: job is not ready, 2 Pending, 2 minAvailable., skip by no condition update
I1104 15:40:23.461083   63880 session.go:154] Close Session 7875aa98-ff5c-11e9-bdbc-784f43775513
I1104 15:40:23.461091   63880 scheduler.go:87] End scheduling ...
I1104 15:40:28.464441   63880 scheduler.go:72] Start scheduling ...
I1104 15:40:28.473473   63880 cache.go:732] The priority of job <default/qj-1> is </0>
I1104 15:40:28.473493   63880 cache.go:771] There are <1> Jobs, <1> Queues and <1> Nodes in total for scheduling.
I1104 15:40:28.473499   63880 session.go:135] Open Session 7b733a4e-ff5c-11e9-bdbc-784f43775513 with <1> Job and <1> Queues
I1104 15:40:28.473533   63880 proportion.go:67] The total resource is <cpu 4000.00, memory 4959854592.00, hugepages-2Mi 0.00>
I1104 15:40:28.473546   63880 proportion.go:71] Considering Job <default/qj-1>.
I1104 15:40:28.473551   63880 proportion.go:85] Added Queue <default> attributes.
I1104 15:40:28.473559   63880 proportion.go:127] Considering Queue <default>: weight <1>, total weight <1>.
I1104 15:40:28.473567   63880 proportion.go:144] The attributes of queue <default> in proportion: deserved <cpu 4000.00, memory 4959854592.00, hugepages-2Mi 0.00>, allocate <cpu 0.00, memory 0.00>, request <cpu 2000.00, memory 0.00>, share <0.00>
I1104 15:40:28.473581   63880 proportion.go:154] Exiting when remaining is empty:  <cpu 0.00, memory 0.00, hugepages-2Mi 0.00>
I1104 15:40:28.473616   63880 enqueue.go:43] Enter Enqueue ...
I1104 15:40:28.473621   63880 enqueue.go:58] Added Queue <default> for Job <default/qj-1>
I1104 15:40:28.473627   63880 enqueue.go:75] Try to enqueue PodGroup to 0 Queues
I1104 15:40:28.473634   63880 enqueue.go:122] Leaving Enqueue ...
I1104 15:40:28.473640   63880 allocate.go:43] Enter Allocate ...
I1104 15:40:28.473645   63880 allocate.go:90] Added Job <default/qj-1> into Queue <default>
I1104 15:40:28.473651   63880 allocate.go:94] Try to allocate resource to 1 Namespaces
I1104 15:40:28.473656   63880 proportion.go:207] Queue <default>: deserved <cpu 4000.00, memory 4959854592.00, hugepages-2Mi 0.00>, allocated <cpu 0.00, memory 0.00>, share <0>
I1104 15:40:28.473665   63880 allocate.go:138] Namespace <default> Queue <default> is overused, ignore it.
I1104 15:40:28.473678   63880 allocate.go:149] Namespace <default> have no queue, skip it
I1104 15:40:28.473688   63880 allocate.go:253] Leaving Allocate ...
I1104 15:40:28.473693   63880 backfill.go:42] Enter Backfill ...
I1104 15:40:28.473698   63880 backfill.go:91] Leaving Backfill ...
I1104 15:40:28.478482   63880 cache.go:634] task unscheduleable default/qj-1-48k5h, message: 2/2 tasks in gang unschedulable: job is not ready, 2 Pending, 2 minAvailable., skip by no condition update
I1104 15:40:28.478489   63880 cache.go:634] task unscheduleable default/qj-1-gbshg, message: 2/2 tasks in gang unschedulable: job is not ready, 2 Pending, 2 minAvailable., skip by no condition update
I1104 15:40:28.478503   63880 session.go:154] Close Session 7b733a4e-ff5c-11e9-bdbc-784f43775513
I1104 15:40:28.478509   63880 scheduler.go:87] End scheduling ...
I1104 15:40:33.479155   63880 scheduler.go:72] Start scheduling ...
I1104 15:40:33.489778   63880 cache.go:732] The priority of job <default/qj-1> is </0>
I1104 15:40:33.489795   63880 cache.go:771] There are <1> Jobs, <1> Queues and <1> Nodes in total for scheduling.
I1104 15:40:33.489800   63880 session.go:135] Open Session 7e70a858-ff5c-11e9-bdbc-784f43775513 with <1> Job and <1> Queues
I1104 15:40:33.489854   63880 proportion.go:67] The total resource is <cpu 4000.00, memory 4959854592.00, hugepages-2Mi 0.00>
I1104 15:40:33.489866   63880 proportion.go:71] Considering Job <default/qj-1>.
I1104 15:40:33.489870   63880 proportion.go:85] Added Queue <default> attributes.
I1104 15:40:33.489877   63880 proportion.go:127] Considering Queue <default>: weight <1>, total weight <1>.
I1104 15:40:33.489883   63880 proportion.go:144] The attributes of queue <default> in proportion: deserved <cpu 4000.00, memory 4959854592.00, hugepages-2Mi 0.00>, allocate <cpu 0.00, memory 0.00>, request <cpu 2000.00, memory 0.00>, share <0.00>
I1104 15:40:33.489895   63880 proportion.go:154] Exiting when remaining is empty:  <cpu 0.00, memory 0.00, hugepages-2Mi 0.00>
I1104 15:40:33.489902   63880 enqueue.go:43] Enter Enqueue ...
I1104 15:40:33.489906   63880 enqueue.go:58] Added Queue <default> for Job <default/qj-1>
I1104 15:40:33.489911   63880 enqueue.go:75] Try to enqueue PodGroup to 0 Queues
I1104 15:40:33.489917   63880 enqueue.go:122] Leaving Enqueue ...
I1104 15:40:33.489927   63880 allocate.go:43] Enter Allocate ...
I1104 15:40:33.489932   63880 allocate.go:90] Added Job <default/qj-1> into Queue <default>
I1104 15:40:33.489937   63880 allocate.go:94] Try to allocate resource to 1 Namespaces
I1104 15:40:33.489941   63880 proportion.go:207] Queue <default>: deserved <cpu 4000.00, memory 4959854592.00, hugepages-2Mi 0.00>, allocated <cpu 0.00, memory 0.00>, share <0>
I1104 15:40:33.489949   63880 allocate.go:138] Namespace <default> Queue <default> is overused, ignore it.
I1104 15:40:33.489960   63880 allocate.go:149] Namespace <default> have no queue, skip it
I1104 15:40:33.489969   63880 allocate.go:253] Leaving Allocate ...
I1104 15:40:33.489972   63880 backfill.go:42] Enter Backfill ...
I1104 15:40:33.489977   63880 backfill.go:91] Leaving Backfill ...
I1104 15:40:33.495680   63880 cache.go:634] task unscheduleable default/qj-1-48k5h, message: 2/2 tasks in gang unschedulable: job is not ready, 2 Pending, 2 minAvailable., skip by no condition update
I1104 15:40:33.495687   63880 cache.go:634] task unscheduleable default/qj-1-gbshg, message: 2/2 tasks in gang unschedulable: job is not ready, 2 Pending, 2 minAvailable., skip by no condition update
I1104 15:40:33.495699   63880 session.go:154] Close Session 7e70a858-ff5c-11e9-bdbc-784f43775513
I1104 15:40:33.495706   63880 scheduler.go:87] End scheduling ...
I1104 15:40:38.497452   63880 scheduler.go:72] Start scheduling ...
I1104 15:40:38.504969   63880 cache.go:732] The priority of job <default/qj-1> is </0>
I1104 15:40:38.504995   63880 cache.go:771] There are <1> Jobs, <1> Queues and <1> Nodes in total for scheduling.
I1104 15:40:38.505003   63880 session.go:135] Open Session 816de8f4-ff5c-11e9-bdbc-784f43775513 with <1> Job and <1> Queues
I1104 15:40:38.505057   63880 proportion.go:67] The total resource is <cpu 4000.00, memory 4959854592.00, hugepages-2Mi 0.00>
I1104 15:40:38.505072   63880 proportion.go:71] Considering Job <default/qj-1>.
I1104 15:40:38.505079   63880 proportion.go:85] Added Queue <default> attributes.
I1104 15:40:38.505090   63880 proportion.go:127] Considering Queue <default>: weight <1>, total weight <1>.
I1104 15:40:38.505099   63880 proportion.go:144] The attributes of queue <default> in proportion: deserved <cpu 4000.00, memory 4959854592.00, hugepages-2Mi 0.00>, allocate <cpu 0.00, memory 0.00>, request <cpu 2000.00, memory 0.00>, share <0.00>
I1104 15:40:38.505118   63880 proportion.go:154] Exiting when remaining is empty:  <cpu 0.00, memory 0.00, hugepages-2Mi 0.00>
I1104 15:40:38.505152   63880 enqueue.go:43] Enter Enqueue ...
I1104 15:40:38.505158   63880 enqueue.go:58] Added Queue <default> for Job <default/qj-1>
I1104 15:40:38.505166   63880 enqueue.go:75] Try to enqueue PodGroup to 0 Queues
I1104 15:40:38.505175   63880 enqueue.go:122] Leaving Enqueue ...
I1104 15:40:38.505183   63880 allocate.go:43] Enter Allocate ...
I1104 15:40:38.505190   63880 allocate.go:90] Added Job <default/qj-1> into Queue <default>
I1104 15:40:38.505198   63880 allocate.go:94] Try to allocate resource to 1 Namespaces
I1104 15:40:38.505204   63880 proportion.go:207] Queue <default>: deserved <cpu 4000.00, memory 4959854592.00, hugepages-2Mi 0.00>, allocated <cpu 0.00, memory 0.00>, share <0>
I1104 15:40:38.505216   63880 allocate.go:138] Namespace <default> Queue <default> is overused, ignore it.
I1104 15:40:38.505248   63880 allocate.go:149] Namespace <default> have no queue, skip it
I1104 15:40:38.505263   63880 allocate.go:253] Leaving Allocate ...
I1104 15:40:38.505269   63880 backfill.go:42] Enter Backfill ...
I1104 15:40:38.505276   63880 backfill.go:91] Leaving Backfill ...
I1104 15:40:38.512362   63880 cache.go:634] task unscheduleable default/qj-1-48k5h, message: 2/2 tasks in gang unschedulable: job is not ready, 2 Pending, 2 minAvailable., skip by no condition update
I1104 15:40:38.512369   63880 cache.go:634] task unscheduleable default/qj-1-gbshg, message: 2/2 tasks in gang unschedulable: job is not ready, 2 Pending, 2 minAvailable., skip by no condition update
I1104 15:40:38.512382   63880 session.go:154] Close Session 816de8f4-ff5c-11e9-bdbc-784f43775513
I1104 15:40:38.512388   63880 scheduler.go:87] End scheduling ...
I1104 15:40:39.125790   63880 cache.go:641] Try to delete Job <default/qj-1:default/qj-1>
I1104 15:40:39.132012   63880 cache.go:641] Try to delete Job <default/qj-1:default/qj-1>
I1104 15:40:39.142127   63880 cache.go:641] Try to delete Job <default/qj-1:default/qj-1>
I1104 15:40:39.162801   63880 cache.go:641] Try to delete Job <default/qj-1:default/qj-1>
I1104 15:40:39.203859   63880 cache.go:641] Try to delete Job <default/qj-1:default/qj-1>
I1104 15:40:39.213832   63880 event_handlers.go:215] Updated pod <default/qj-1-48k5h> in cache.
I1104 15:40:39.217104   63880 event_handlers.go:247] Deleted pod <default/qj-1-48k5h> from cache.
I1104 15:40:39.224661   63880 cache.go:641] Try to delete Job <default/qj-1:default/qj-1>
I1104 15:40:39.224691   63880 event_handlers.go:215] Updated pod <default/qj-1-gbshg> in cache.
I1104 15:40:39.228048   63880 cache.go:641] Try to delete Job <default/qj-1:default/qj-1>
I1104 15:40:39.228072   63880 event_handlers.go:247] Deleted pod <default/qj-1-gbshg> from cache.
I1104 15:40:39.284281   63880 cache.go:665] Job <default/qj-1:default/qj-1> was deleted.
I1104 15:40:43.512724   63880 scheduler.go:72] Start scheduling ...
I1104 15:40:43.523631   63880 cache.go:771] There are <0> Jobs, <1> Queues and <1> Nodes in total for scheduling.
I1104 15:40:43.523638   63880 session.go:135] Open Session 846bb3e2-ff5c-11e9-bdbc-784f43775513 with <0> Job and <1> Queues
I1104 15:40:43.523677   63880 proportion.go:67] The total resource is <cpu 4000.00, memory 4959854592.00, hugepages-2Mi 0.00>
I1104 15:40:43.523695   63880 proportion.go:117] Exiting when total weight is 0
I1104 15:40:43.523712   63880 enqueue.go:43] Enter Enqueue ...
I1104 15:40:43.523716   63880 enqueue.go:75] Try to enqueue PodGroup to 0 Queues
I1104 15:40:43.523724   63880 enqueue.go:122] Leaving Enqueue ...
I1104 15:40:43.523729   63880 allocate.go:43] Enter Allocate ...
I1104 15:40:43.523734   63880 allocate.go:94] Try to allocate resource to 0 Namespaces
I1104 15:40:43.523745   63880 allocate.go:253] Leaving Allocate ...
I1104 15:40:43.523750   63880 backfill.go:42] Enter Backfill ...
I1104 15:40:43.523758   63880 backfill.go:91] Leaving Backfill ...
I1104 15:40:43.523770   63880 session.go:154] Close Session 846bb3e2-ff5c-11e9-bdbc-784f43775513
I1104 15:40:43.523774   63880 scheduler.go:87] End scheduling ...
I1104 15:40:48.523908   63880 scheduler.go:72] Start scheduling ...
I1104 15:40:48.541340   63880 cache.go:771] There are <0> Jobs, <1> Queues and <1> Nodes in total for scheduling.
I1104 15:40:48.541347   63880 session.go:135] Open Session 87695824-ff5c-11e9-bdbc-784f43775513 with <0> Job and <1> Queues
I1104 15:40:48.541376   63880 proportion.go:67] The total resource is <cpu 4000.00, memory 4959854592.00, hugepages-2Mi 0.00>
I1104 15:40:48.541394   63880 proportion.go:117] Exiting when total weight is 0
I1104 15:40:48.541414   63880 enqueue.go:43] Enter Enqueue ...
I1104 15:40:48.541419   63880 enqueue.go:75] Try to enqueue PodGroup to 0 Queues
I1104 15:40:48.541425   63880 enqueue.go:122] Leaving Enqueue ...
I1104 15:40:48.541430   63880 allocate.go:43] Enter Allocate ...
I1104 15:40:48.541435   63880 allocate.go:94] Try to allocate resource to 0 Namespaces
I1104 15:40:48.541445   63880 allocate.go:253] Leaving Allocate ...
I1104 15:40:48.541449   63880 backfill.go:42] Enter Backfill ...
I1104 15:40:48.541452   63880 backfill.go:91] Leaving Backfill ...
I1104 15:40:48.541464   63880 session.go:154] Close Session 87695824-ff5c-11e9-bdbc-784f43775513
I1104 15:40:48.541468   63880 scheduler.go:87] End scheduling ...
I1104 15:40:53.542367   63880 scheduler.go:72] Start scheduling ...
I1104 15:40:53.557303   63880 cache.go:771] There are <0> Jobs, <1> Queues and <1> Nodes in total for scheduling.
I1104 15:40:53.557313   63880 session.go:135] Open Session 8a66b7f6-ff5c-11e9-bdbc-784f43775513 with <0> Job and <1> Queues
I1104 15:40:53.557374   63880 proportion.go:67] The total resource is <cpu 4000.00, memory 4959854592.00, hugepages-2Mi 0.00>
I1104 15:40:53.557399   63880 proportion.go:117] Exiting when total weight is 0
I1104 15:40:53.557426   63880 enqueue.go:43] Enter Enqueue ...
I1104 15:40:53.557433   63880 enqueue.go:75] Try to enqueue PodGroup to 0 Queues
I1104 15:40:53.557442   63880 enqueue.go:122] Leaving Enqueue ...
I1104 15:40:53.557450   63880 allocate.go:43] Enter Allocate ...
I1104 15:40:53.557457   63880 allocate.go:94] Try to allocate resource to 0 Namespaces
I1104 15:40:53.557472   63880 allocate.go:253] Leaving Allocate ...
I1104 15:40:53.557478   63880 backfill.go:42] Enter Backfill ...
I1104 15:40:53.557483   63880 backfill.go:91] Leaving Backfill ...
I1104 15:40:53.557499   63880 session.go:154] Close Session 8a66b7f6-ff5c-11e9-bdbc-784f43775513
I1104 15:40:53.557504   63880 scheduler.go:87] End scheduling ...
I1104 15:40:58.562084   63880 scheduler.go:72] Start scheduling ...
I1104 15:40:58.577237   63880 cache.go:771] There are <0> Jobs, <1> Queues and <1> Nodes in total for scheduling.
I1104 15:40:58.577245   63880 session.go:135] Open Session 8d64b3ae-ff5c-11e9-bdbc-784f43775513 with <0> Job and <1> Queues
I1104 15:40:58.577282   63880 proportion.go:67] The total resource is <cpu 4000.00, memory 4959854592.00, hugepages-2Mi 0.00>
I1104 15:40:58.577300   63880 proportion.go:117] Exiting when total weight is 0
I1104 15:40:58.577315   63880 enqueue.go:43] Enter Enqueue ...
I1104 15:40:58.577319   63880 enqueue.go:75] Try to enqueue PodGroup to 0 Queues
I1104 15:40:58.577334   63880 enqueue.go:122] Leaving Enqueue ...
I1104 15:40:58.577340   63880 allocate.go:43] Enter Allocate ...
I1104 15:40:58.577344   63880 allocate.go:94] Try to allocate resource to 0 Namespaces
I1104 15:40:58.577355   63880 allocate.go:253] Leaving Allocate ...
I1104 15:40:58.577359   63880 backfill.go:42] Enter Backfill ...
I1104 15:40:58.577362   63880 backfill.go:91] Leaving Backfill ...
I1104 15:40:58.577373   63880 session.go:154] Close Session 8d64b3ae-ff5c-11e9-bdbc-784f43775513
I1104 15:40:58.577377   63880 scheduler.go:87] End scheduling ...
I1104 15:41:03.580018   63880 scheduler.go:72] Start scheduling ...
I1104 15:41:03.594502   63880 cache.go:771] There are <0> Jobs, <1> Queues and <1> Nodes in total for scheduling.
I1104 15:41:03.594512   63880 session.go:135] Open Session 906245b2-ff5c-11e9-bdbc-784f43775513 with <0> Job and <1> Queues
I1104 15:41:03.594572   63880 proportion.go:67] The total resource is <cpu 4000.00, memory 4959854592.00, hugepages-2Mi 0.00>
I1104 15:41:03.594589   63880 proportion.go:117] Exiting when total weight is 0
I1104 15:41:03.594605   63880 enqueue.go:43] Enter Enqueue ...
I1104 15:41:03.594609   63880 enqueue.go:75] Try to enqueue PodGroup to 0 Queues
I1104 15:41:03.594615   63880 enqueue.go:122] Leaving Enqueue ...
I1104 15:41:03.594620   63880 allocate.go:43] Enter Allocate ...
I1104 15:41:03.594625   63880 allocate.go:94] Try to allocate resource to 0 Namespaces
I1104 15:41:03.594636   63880 allocate.go:253] Leaving Allocate ...
I1104 15:41:03.594640   63880 backfill.go:42] Enter Backfill ...
I1104 15:41:03.594643   63880 backfill.go:91] Leaving Backfill ...
I1104 15:41:03.594654   63880 session.go:154] Close Session 906245b2-ff5c-11e9-bdbc-784f43775513
I1104 15:41:03.594663   63880 scheduler.go:87] End scheduling ...
I1104 15:41:08.599245   63880 scheduler.go:72] Start scheduling ...
I1104 15:41:08.599377   63880 cache.go:771] There are <0> Jobs, <1> Queues and <1> Nodes in total for scheduling.
I1104 15:41:08.614934   63880 session.go:135] Open Session 935df5b8-ff5c-11e9-bdbc-784f43775513 with <0> Job and <1> Queues
I1104 15:41:08.615000   63880 proportion.go:67] The total resource is <cpu 4000.00, memory 4959854592.00, hugepages-2Mi 0.00>
I1104 15:41:08.615020   63880 proportion.go:117] Exiting when total weight is 0
I1104 15:41:08.615028   63880 enqueue.go:43] Enter Enqueue ...
I1104 15:41:08.615033   63880 enqueue.go:75] Try to enqueue PodGroup to 0 Queues
I1104 15:41:08.615052   63880 enqueue.go:122] Leaving Enqueue ...
I1104 15:41:08.615059   63880 allocate.go:43] Enter Allocate ...
I1104 15:41:08.615064   63880 allocate.go:94] Try to allocate resource to 0 Namespaces
I1104 15:41:08.615077   63880 allocate.go:253] Leaving Allocate ...
I1104 15:41:08.615081   63880 backfill.go:42] Enter Backfill ...
I1104 15:41:08.615085   63880 backfill.go:91] Leaving Backfill ...
I1104 15:41:08.615099   63880 session.go:154] Close Session 935df5b8-ff5c-11e9-bdbc-784f43775513
I1104 15:41:08.615103   63880 scheduler.go:87] End scheduling ...
I1104 15:41:13.615251   63880 scheduler.go:72] Start scheduling ...
I1104 15:41:13.630026   63880 cache.go:771] There are <0> Jobs, <1> Queues and <1> Nodes in total for scheduling.
I1104 15:41:13.630034   63880 session.go:135] Open Session 965d9192-ff5c-11e9-bdbc-784f43775513 with <0> Job and <1> Queues
I1104 15:41:13.630070   63880 proportion.go:67] The total resource is <cpu 4000.00, memory 4959854592.00, hugepages-2Mi 0.00>
I1104 15:41:13.630102   63880 proportion.go:117] Exiting when total weight is 0
I1104 15:41:13.630133   63880 enqueue.go:43] Enter Enqueue ...
I1104 15:41:13.630137   63880 enqueue.go:75] Try to enqueue PodGroup to 0 Queues
I1104 15:41:13.630144   63880 enqueue.go:122] Leaving Enqueue ...
I1104 15:41:13.630149   63880 allocate.go:43] Enter Allocate ...
I1104 15:41:13.630154   63880 allocate.go:94] Try to allocate resource to 0 Namespaces
I1104 15:41:13.630164   63880 allocate.go:253] Leaving Allocate ...
I1104 15:41:13.630167   63880 backfill.go:42] Enter Backfill ...
I1104 15:41:13.630177   63880 backfill.go:91] Leaving Backfill ...
I1104 15:41:13.630188   63880 session.go:154] Close Session 965d9192-ff5c-11e9-bdbc-784f43775513
I1104 15:41:13.630191   63880 scheduler.go:87] End scheduling ...
I1104 15:41:18.632135   63880 scheduler.go:72] Start scheduling ...
I1104 15:41:18.632311   63880 cache.go:771] There are <0> Jobs, <1> Queues and <1> Nodes in total for scheduling.
I1104 15:41:18.648833   63880 session.go:135] Open Session 9958dc8a-ff5c-11e9-bdbc-784f43775513 with <0> Job and <1> Queues
I1104 15:41:18.648896   63880 proportion.go:67] The total resource is <cpu 4000.00, memory 4959854592.00, hugepages-2Mi 0.00>
I1104 15:41:18.648922   63880 proportion.go:117] Exiting when total weight is 0
I1104 15:41:18.648947   63880 enqueue.go:43] Enter Enqueue ...
I1104 15:41:18.648954   63880 enqueue.go:75] Try to enqueue PodGroup to 0 Queues
I1104 15:41:18.648963   63880 enqueue.go:122] Leaving Enqueue ...
I1104 15:41:18.648971   63880 allocate.go:43] Enter Allocate ...
I1104 15:41:18.648978   63880 allocate.go:94] Try to allocate resource to 0 Namespaces
I1104 15:41:18.648993   63880 allocate.go:253] Leaving Allocate ...
I1104 15:41:18.648999   63880 backfill.go:42] Enter Backfill ...
I1104 15:41:18.649004   63880 backfill.go:91] Leaving Backfill ...
I1104 15:41:18.649041   63880 session.go:154] Close Session 9958dc8a-ff5c-11e9-bdbc-784f43775513
I1104 15:41:18.649047   63880 scheduler.go:87] End scheduling ...
I1104 15:41:23.651529   63880 scheduler.go:72] Start scheduling ...
I1104 15:41:23.667564   63880 cache.go:771] There are <0> Jobs, <1> Queues and <1> Nodes in total for scheduling.
I1104 15:41:23.667571   63880 session.go:135] Open Session 9c592e80-ff5c-11e9-bdbc-784f43775513 with <0> Job and <1> Queues
I1104 15:41:23.667610   63880 proportion.go:67] The total resource is <cpu 4000.00, memory 4959854592.00, hugepages-2Mi 0.00>
I1104 15:41:23.667631   63880 proportion.go:117] Exiting when total weight is 0
I1104 15:41:23.667649   63880 enqueue.go:43] Enter Enqueue ...
I1104 15:41:23.667654   63880 enqueue.go:75] Try to enqueue PodGroup to 0 Queues
I1104 15:41:23.667661   63880 enqueue.go:122] Leaving Enqueue ...
I1104 15:41:23.667667   63880 allocate.go:43] Enter Allocate ...
I1104 15:41:23.667673   63880 allocate.go:94] Try to allocate resource to 0 Namespaces
I1104 15:41:23.667685   63880 allocate.go:253] Leaving Allocate ...
I1104 15:41:23.667689   63880 backfill.go:42] Enter Backfill ...
I1104 15:41:23.667693   63880 backfill.go:91] Leaving Backfill ...
I1104 15:41:23.667706   63880 session.go:154] Close Session 9c592e80-ff5c-11e9-bdbc-784f43775513
I1104 15:41:23.667709   63880 scheduler.go:87] End scheduling ...
I1104 15:41:28.669638   63880 scheduler.go:72] Start scheduling ...
I1104 15:41:28.684267   63880 cache.go:771] There are <0> Jobs, <1> Queues and <1> Nodes in total for scheduling.
I1104 15:41:28.684275   63880 session.go:135] Open Session 9f56ab80-ff5c-11e9-bdbc-784f43775513 with <0> Job and <1> Queues
I1104 15:41:28.684314   63880 proportion.go:67] The total resource is <cpu 4000.00, memory 4959854592.00, hugepages-2Mi 0.00>
I1104 15:41:28.684332   63880 proportion.go:117] Exiting when total weight is 0
I1104 15:41:28.684350   63880 enqueue.go:43] Enter Enqueue ...
I1104 15:41:28.684354   63880 enqueue.go:75] Try to enqueue PodGroup to 0 Queues
I1104 15:41:28.684360   63880 enqueue.go:122] Leaving Enqueue ...
I1104 15:41:28.684366   63880 allocate.go:43] Enter Allocate ...
I1104 15:41:28.684371   63880 allocate.go:94] Try to allocate resource to 0 Namespaces
I1104 15:41:28.684381   63880 allocate.go:253] Leaving Allocate ...
I1104 15:41:28.684384   63880 backfill.go:42] Enter Backfill ...
I1104 15:41:28.684388   63880 backfill.go:91] Leaving Backfill ...
I1104 15:41:28.684399   63880 session.go:154] Close Session 9f56ab80-ff5c-11e9-bdbc-784f43775513
I1104 15:41:28.684403   63880 scheduler.go:87] End scheduling ...
I1104 15:41:33.684552   63880 scheduler.go:72] Start scheduling ...
I1104 15:41:33.700252   63880 cache.go:771] There are <0> Jobs, <1> Queues and <1> Nodes in total for scheduling.
I1104 15:41:33.700259   63880 session.go:135] Open Session a2540c92-ff5c-11e9-bdbc-784f43775513 with <0> Job and <1> Queues
I1104 15:41:33.700270   63880 proportion.go:67] The total resource is <cpu 4000.00, memory 4959854592.00, hugepages-2Mi 0.00>
I1104 15:41:33.700285   63880 proportion.go:117] Exiting when total weight is 0
I1104 15:41:33.700321   63880 enqueue.go:43] Enter Enqueue ...
I1104 15:41:33.700325   63880 enqueue.go:75] Try to enqueue PodGroup to 0 Queues
I1104 15:41:33.700330   63880 enqueue.go:122] Leaving Enqueue ...
I1104 15:41:33.700335   63880 allocate.go:43] Enter Allocate ...
I1104 15:41:33.700339   63880 allocate.go:94] Try to allocate resource to 0 Namespaces
I1104 15:41:33.700347   63880 allocate.go:253] Leaving Allocate ...
I1104 15:41:33.700351   63880 backfill.go:42] Enter Backfill ...
I1104 15:41:33.700354   63880 backfill.go:91] Leaving Backfill ...
I1104 15:41:33.700364   63880 session.go:154] Close Session a2540c92-ff5c-11e9-bdbc-784f43775513
I1104 15:41:33.700367   63880 scheduler.go:87] End scheduling ...
I1104 15:41:38.701892   63880 scheduler.go:72] Start scheduling ...
I1104 15:41:38.702102   63880 cache.go:771] There are <0> Jobs, <1> Queues and <1> Nodes in total for scheduling.
I1104 15:41:38.702112   63880 session.go:135] Open Session a54f44ca-ff5c-11e9-bdbc-784f43775513 with <0> Job and <1> Queues
I1104 15:41:38.702163   63880 proportion.go:67] The total resource is <cpu 4000.00, memory 4959854592.00, hugepages-2Mi 0.00>
I1104 15:41:38.702187   63880 proportion.go:117] Exiting when total weight is 0
I1104 15:41:38.702209   63880 enqueue.go:43] Enter Enqueue ...
I1104 15:41:38.702216   63880 enqueue.go:75] Try to enqueue PodGroup to 0 Queues
I1104 15:41:38.702225   63880 enqueue.go:122] Leaving Enqueue ...
I1104 15:41:38.702233   63880 allocate.go:43] Enter Allocate ...
I1104 15:41:38.702240   63880 allocate.go:94] Try to allocate resource to 0 Namespaces
I1104 15:41:38.702256   63880 allocate.go:253] Leaving Allocate ...
I1104 15:41:38.702262   63880 backfill.go:42] Enter Backfill ...
I1104 15:41:38.702267   63880 backfill.go:91] Leaving Backfill ...
I1104 15:41:38.702283   63880 session.go:154] Close Session a54f44ca-ff5c-11e9-bdbc-784f43775513
I1104 15:41:38.702288   63880 scheduler.go:87] End scheduling ...
I1104 15:41:43.706609   63880 scheduler.go:72] Start scheduling ...
I1104 15:41:43.723774   63880 cache.go:771] There are <0> Jobs, <1> Queues and <1> Nodes in total for scheduling.
I1104 15:41:43.723782   63880 session.go:135] Open Session a84d8416-ff5c-11e9-bdbc-784f43775513 with <0> Job and <1> Queues
I1104 15:41:43.723840   63880 proportion.go:67] The total resource is <cpu 4000.00, memory 4959854592.00, hugepages-2Mi 0.00>
I1104 15:41:43.723862   63880 proportion.go:117] Exiting when total weight is 0
I1104 15:41:43.723870   63880 enqueue.go:43] Enter Enqueue ...
I1104 15:41:43.723876   63880 enqueue.go:75] Try to enqueue PodGroup to 0 Queues
I1104 15:41:43.723884   63880 enqueue.go:122] Leaving Enqueue ...
I1104 15:41:43.723892   63880 allocate.go:43] Enter Allocate ...
I1104 15:41:43.723898   63880 allocate.go:94] Try to allocate resource to 0 Namespaces
I1104 15:41:43.723912   63880 allocate.go:253] Leaving Allocate ...
I1104 15:41:43.723918   63880 backfill.go:42] Enter Backfill ...
I1104 15:41:43.723922   63880 backfill.go:91] Leaving Backfill ...
I1104 15:41:43.723936   63880 session.go:154] Close Session a84d8416-ff5c-11e9-bdbc-784f43775513
I1104 15:41:43.723941   63880 scheduler.go:87] End scheduling ...
I1104 15:41:48.725092   63880 scheduler.go:72] Start scheduling ...
I1104 15:41:48.738455   63880 cache.go:771] There are <0> Jobs, <1> Queues and <1> Nodes in total for scheduling.
I1104 15:41:48.738467   63880 session.go:135] Open Session ab4ab1b6-ff5c-11e9-bdbc-784f43775513 with <0> Job and <1> Queues
I1104 15:41:48.738506   63880 proportion.go:67] The total resource is <cpu 4000.00, memory 4959854592.00, hugepages-2Mi 0.00>
I1104 15:41:48.738532   63880 proportion.go:117] Exiting when total weight is 0
I1104 15:41:48.738565   63880 enqueue.go:43] Enter Enqueue ...
I1104 15:41:48.738571   63880 enqueue.go:75] Try to enqueue PodGroup to 0 Queues
I1104 15:41:48.738581   63880 enqueue.go:122] Leaving Enqueue ...
I1104 15:41:48.738589   63880 allocate.go:43] Enter Allocate ...
I1104 15:41:48.738597   63880 allocate.go:94] Try to allocate resource to 0 Namespaces
I1104 15:41:48.738613   63880 allocate.go:253] Leaving Allocate ...
I1104 15:41:48.738619   63880 backfill.go:42] Enter Backfill ...
I1104 15:41:48.738624   63880 backfill.go:91] Leaving Backfill ...
I1104 15:41:48.738642   63880 session.go:154] Close Session ab4ab1b6-ff5c-11e9-bdbc-784f43775513
I1104 15:41:48.738647   63880 scheduler.go:87] End scheduling ...
I1104 15:41:53.738823   63880 scheduler.go:72] Start scheduling ...
I1104 15:41:53.752312   63880 cache.go:771] There are <0> Jobs, <1> Queues and <1> Nodes in total for scheduling.
I1104 15:41:53.752320   63880 session.go:135] Open Session ae47bf94-ff5c-11e9-bdbc-784f43775513 with <0> Job and <1> Queues
I1104 15:41:53.752357   63880 proportion.go:67] The total resource is <cpu 4000.00, memory 4959854592.00, hugepages-2Mi 0.00>
I1104 15:41:53.752374   63880 proportion.go:117] Exiting when total weight is 0
I1104 15:41:53.752390   63880 enqueue.go:43] Enter Enqueue ...
I1104 15:41:53.752396   63880 enqueue.go:75] Try to enqueue PodGroup to 0 Queues
I1104 15:41:53.752402   63880 enqueue.go:122] Leaving Enqueue ...
I1104 15:41:53.752408   63880 allocate.go:43] Enter Allocate ...
I1104 15:41:53.752412   63880 allocate.go:94] Try to allocate resource to 0 Namespaces
I1104 15:41:53.752423   63880 allocate.go:253] Leaving Allocate ...
I1104 15:41:53.752426   63880 backfill.go:42] Enter Backfill ...
I1104 15:41:53.752430   63880 backfill.go:91] Leaving Backfill ...
I1104 15:41:53.752441   63880 session.go:154] Close Session ae47bf94-ff5c-11e9-bdbc-784f43775513
I1104 15:41:53.752445   63880 scheduler.go:87] End scheduling ...
I1104 15:41:58.756732   63880 scheduler.go:72] Start scheduling ...
I1104 15:41:58.770607   63880 cache.go:771] There are <0> Jobs, <1> Queues and <1> Nodes in total for scheduling.
I1104 15:41:58.770614   63880 session.go:135] Open Session b1457b3c-ff5c-11e9-bdbc-784f43775513 with <0> Job and <1> Queues
I1104 15:41:58.770647   63880 proportion.go:67] The total resource is <cpu 4000.00, memory 4959854592.00, hugepages-2Mi 0.00>
I1104 15:41:58.770665   63880 proportion.go:117] Exiting when total weight is 0
I1104 15:41:58.770683   63880 enqueue.go:43] Enter Enqueue ...
I1104 15:41:58.770687   63880 enqueue.go:75] Try to enqueue PodGroup to 0 Queues
I1104 15:41:58.770693   63880 enqueue.go:122] Leaving Enqueue ...
I1104 15:41:58.770698   63880 allocate.go:43] Enter Allocate ...
I1104 15:41:58.770703   63880 allocate.go:94] Try to allocate resource to 0 Namespaces
I1104 15:41:58.770713   63880 allocate.go:253] Leaving Allocate ...
I1104 15:41:58.770717   63880 backfill.go:42] Enter Backfill ...
I1104 15:41:58.770720   63880 backfill.go:91] Leaving Backfill ...
I1104 15:41:58.770731   63880 session.go:154] Close Session b1457b3c-ff5c-11e9-bdbc-784f43775513
I1104 15:41:58.770735   63880 scheduler.go:87] End scheduling ...
I1104 15:42:03.771526   63880 scheduler.go:72] Start scheduling ...
I1104 15:42:03.771659   63880 cache.go:771] There are <0> Jobs, <1> Queues and <1> Nodes in total for scheduling.
I1104 15:42:03.785224   63880 session.go:135] Open Session b4409498-ff5c-11e9-bdbc-784f43775513 with <0> Job and <1> Queues
I1104 15:42:03.785290   63880 proportion.go:67] The total resource is <cpu 4000.00, memory 4959854592.00, hugepages-2Mi 0.00>
I1104 15:42:03.785312   63880 proportion.go:117] Exiting when total weight is 0
I1104 15:42:03.785333   63880 enqueue.go:43] Enter Enqueue ...
I1104 15:42:03.785338   63880 enqueue.go:75] Try to enqueue PodGroup to 0 Queues
I1104 15:42:03.785346   63880 enqueue.go:122] Leaving Enqueue ...
I1104 15:42:03.785352   63880 allocate.go:43] Enter Allocate ...
I1104 15:42:03.785358   63880 allocate.go:94] Try to allocate resource to 0 Namespaces
I1104 15:42:03.785370   63880 allocate.go:253] Leaving Allocate ...
I1104 15:42:03.785374   63880 backfill.go:42] Enter Backfill ...
I1104 15:42:03.785378   63880 backfill.go:91] Leaving Backfill ...
I1104 15:42:03.785392   63880 session.go:154] Close Session b4409498-ff5c-11e9-bdbc-784f43775513
I1104 15:42:03.785396   63880 scheduler.go:87] End scheduling ...
I1104 15:42:08.790472   63880 scheduler.go:72] Start scheduling ...
I1104 15:42:08.802353   63880 cache.go:771] There are <0> Jobs, <1> Queues and <1> Nodes in total for scheduling.
I1104 15:42:08.802366   63880 session.go:135] Open Session b7403342-ff5c-11e9-bdbc-784f43775513 with <0> Job and <1> Queues
I1104 15:42:08.802428   63880 proportion.go:67] The total resource is <cpu 4000.00, memory 4959854592.00, hugepages-2Mi 0.00>
I1104 15:42:08.802458   63880 proportion.go:117] Exiting when total weight is 0
I1104 15:42:08.802492   63880 enqueue.go:43] Enter Enqueue ...
I1104 15:42:08.802501   63880 enqueue.go:75] Try to enqueue PodGroup to 0 Queues
I1104 15:42:08.802531   63880 enqueue.go:122] Leaving Enqueue ...
I1104 15:42:08.802542   63880 allocate.go:43] Enter Allocate ...
I1104 15:42:08.802551   63880 allocate.go:94] Try to allocate resource to 0 Namespaces
I1104 15:42:08.802593   63880 allocate.go:253] Leaving Allocate ...
I1104 15:42:08.802628   63880 backfill.go:42] Enter Backfill ...
I1104 15:42:08.802631   63880 backfill.go:91] Leaving Backfill ...
I1104 15:42:08.802643   63880 session.go:154] Close Session b7403342-ff5c-11e9-bdbc-784f43775513
I1104 15:42:08.802647   63880 scheduler.go:87] End scheduling ...
I1104 15:42:13.806738   63880 scheduler.go:72] Start scheduling ...
I1104 15:42:13.821061   63880 cache.go:771] There are <0> Jobs, <1> Queues and <1> Nodes in total for scheduling.
I1104 15:42:13.821069   63880 session.go:135] Open Session ba3dff8e-ff5c-11e9-bdbc-784f43775513 with <0> Job and <1> Queues
I1104 15:42:13.821116   63880 proportion.go:67] The total resource is <cpu 4000.00, memory 4959854592.00, hugepages-2Mi 0.00>
I1104 15:42:13.821139   63880 proportion.go:117] Exiting when total weight is 0
I1104 15:42:13.821174   63880 enqueue.go:43] Enter Enqueue ...
I1104 15:42:13.821181   63880 enqueue.go:75] Try to enqueue PodGroup to 0 Queues
I1104 15:42:13.821189   63880 enqueue.go:122] Leaving Enqueue ...
I1104 15:42:13.821197   63880 allocate.go:43] Enter Allocate ...
I1104 15:42:13.821205   63880 allocate.go:94] Try to allocate resource to 0 Namespaces
I1104 15:42:13.821220   63880 allocate.go:253] Leaving Allocate ...
I1104 15:42:13.821226   63880 backfill.go:42] Enter Backfill ...
I1104 15:42:13.821231   63880 backfill.go:91] Leaving Backfill ...
I1104 15:42:13.821247   63880 session.go:154] Close Session ba3dff8e-ff5c-11e9-bdbc-784f43775513
I1104 15:42:13.821252   63880 scheduler.go:87] End scheduling ...
I1104 15:42:18.821867   63880 scheduler.go:72] Start scheduling ...
I1104 15:42:18.835764   63880 cache.go:771] There are <0> Jobs, <1> Queues and <1> Nodes in total for scheduling.
I1104 15:42:18.835774   63880 session.go:135] Open Session bd3b2d74-ff5c-11e9-bdbc-784f43775513 with <0> Job and <1> Queues
I1104 15:42:18.835817   63880 proportion.go:67] The total resource is <cpu 4000.00, memory 4959854592.00, hugepages-2Mi 0.00>
I1104 15:42:18.835842   63880 proportion.go:117] Exiting when total weight is 0
I1104 15:42:18.835875   63880 enqueue.go:43] Enter Enqueue ...
I1104 15:42:18.835882   63880 enqueue.go:75] Try to enqueue PodGroup to 0 Queues
I1104 15:42:18.835892   63880 enqueue.go:122] Leaving Enqueue ...
I1104 15:42:18.835899   63880 allocate.go:43] Enter Allocate ...
I1104 15:42:18.835906   63880 allocate.go:94] Try to allocate resource to 0 Namespaces
I1104 15:42:18.835924   63880 allocate.go:253] Leaving Allocate ...
I1104 15:42:18.835930   63880 backfill.go:42] Enter Backfill ...
I1104 15:42:18.835935   63880 backfill.go:91] Leaving Backfill ...
I1104 15:42:18.835950   63880 session.go:154] Close Session bd3b2d74-ff5c-11e9-bdbc-784f43775513
I1104 15:42:18.835955   63880 scheduler.go:87] End scheduling ...
I1104 15:42:23.836219   63880 scheduler.go:72] Start scheduling ...
I1104 15:42:23.851782   63880 cache.go:771] There are <0> Jobs, <1> Queues and <1> Nodes in total for scheduling.
I1104 15:42:23.851789   63880 session.go:135] Open Session c03890a2-ff5c-11e9-bdbc-784f43775513 with <0> Job and <1> Queues
I1104 15:42:23.851804   63880 proportion.go:67] The total resource is <cpu 4000.00, memory 4959854592.00, hugepages-2Mi 0.00>
I1104 15:42:23.851820   63880 proportion.go:117] Exiting when total weight is 0
I1104 15:42:23.851858   63880 enqueue.go:43] Enter Enqueue ...
I1104 15:42:23.851862   63880 enqueue.go:75] Try to enqueue PodGroup to 0 Queues
I1104 15:42:23.851869   63880 enqueue.go:122] Leaving Enqueue ...
I1104 15:42:23.851874   63880 allocate.go:43] Enter Allocate ...
I1104 15:42:23.851879   63880 allocate.go:94] Try to allocate resource to 0 Namespaces
I1104 15:42:23.851889   63880 allocate.go:253] Leaving Allocate ...
I1104 15:42:23.851893   63880 backfill.go:42] Enter Backfill ...
I1104 15:42:23.851896   63880 backfill.go:91] Leaving Backfill ...
I1104 15:42:23.851907   63880 session.go:154] Close Session c03890a2-ff5c-11e9-bdbc-784f43775513
I1104 15:42:23.851911   63880 scheduler.go:87] End scheduling ...
I1104 15:42:28.852049   63880 scheduler.go:72] Start scheduling ...
I1104 15:42:28.866028   63880 cache.go:771] There are <0> Jobs, <1> Queues and <1> Nodes in total for scheduling.
I1104 15:42:28.866035   63880 session.go:135] Open Session c335ad94-ff5c-11e9-bdbc-784f43775513 with <0> Job and <1> Queues
I1104 15:42:28.866079   63880 proportion.go:67] The total resource is <cpu 4000.00, memory 4959854592.00, hugepages-2Mi 0.00>
I1104 15:42:28.866095   63880 proportion.go:117] Exiting when total weight is 0
I1104 15:42:28.866101   63880 enqueue.go:43] Enter Enqueue ...
I1104 15:42:28.866106   63880 enqueue.go:75] Try to enqueue PodGroup to 0 Queues
I1104 15:42:28.866111   63880 enqueue.go:122] Leaving Enqueue ...
I1104 15:42:28.866118   63880 allocate.go:43] Enter Allocate ...
I1104 15:42:28.866123   63880 allocate.go:94] Try to allocate resource to 0 Namespaces
I1104 15:42:28.866133   63880 allocate.go:253] Leaving Allocate ...
I1104 15:42:28.866137   63880 backfill.go:42] Enter Backfill ...
I1104 15:42:28.866140   63880 backfill.go:91] Leaving Backfill ...
I1104 15:42:28.866151   63880 session.go:154] Close Session c335ad94-ff5c-11e9-bdbc-784f43775513
I1104 15:42:28.866155   63880 scheduler.go:87] End scheduling ...
I1104 15:42:33.870583   63880 scheduler.go:72] Start scheduling ...
I1104 15:42:33.886856   63880 cache.go:771] There are <0> Jobs, <1> Queues and <1> Nodes in total for scheduling.
I1104 15:42:33.886863   63880 session.go:135] Open Session c633cba2-ff5c-11e9-bdbc-784f43775513 with <0> Job and <1> Queues
I1104 15:42:33.886900   63880 proportion.go:67] The total resource is <cpu 4000.00, memory 4959854592.00, hugepages-2Mi 0.00>
I1104 15:42:33.886917   63880 proportion.go:117] Exiting when total weight is 0
I1104 15:42:33.886937   63880 enqueue.go:43] Enter Enqueue ...
I1104 15:42:33.886941   63880 enqueue.go:75] Try to enqueue PodGroup to 0 Queues
I1104 15:42:33.886947   63880 enqueue.go:122] Leaving Enqueue ...
I1104 15:42:33.886953   63880 allocate.go:43] Enter Allocate ...
I1104 15:42:33.886957   63880 allocate.go:94] Try to allocate resource to 0 Namespaces
I1104 15:42:33.886968   63880 allocate.go:253] Leaving Allocate ...
I1104 15:42:33.886972   63880 backfill.go:42] Enter Backfill ...
I1104 15:42:33.886975   63880 backfill.go:91] Leaving Backfill ...
I1104 15:42:33.886987   63880 session.go:154] Close Session c633cba2-ff5c-11e9-bdbc-784f43775513
I1104 15:42:33.886992   63880 scheduler.go:87] End scheduling ...
I1104 15:42:38.890409   63880 scheduler.go:72] Start scheduling ...
I1104 15:42:38.904852   63880 cache.go:771] There are <0> Jobs, <1> Queues and <1> Nodes in total for scheduling.
I1104 15:42:38.904861   63880 session.go:135] Open Session c9317ad4-ff5c-11e9-bdbc-784f43775513 with <0> Job and <1> Queues
I1104 15:42:38.904893   63880 proportion.go:67] The total resource is <cpu 4000.00, memory 4959854592.00, hugepages-2Mi 0.00>
I1104 15:42:38.904910   63880 proportion.go:117] Exiting when total weight is 0
I1104 15:42:38.904936   63880 enqueue.go:43] Enter Enqueue ...
I1104 15:42:38.904940   63880 enqueue.go:75] Try to enqueue PodGroup to 0 Queues
I1104 15:42:38.904946   63880 enqueue.go:122] Leaving Enqueue ...
I1104 15:42:38.904952   63880 allocate.go:43] Enter Allocate ...
I1104 15:42:38.904957   63880 allocate.go:94] Try to allocate resource to 0 Namespaces
I1104 15:42:38.904967   63880 allocate.go:253] Leaving Allocate ...
I1104 15:42:38.904970   63880 backfill.go:42] Enter Backfill ...
I1104 15:42:38.904974   63880 backfill.go:91] Leaving Backfill ...
I1104 15:42:38.904984   63880 session.go:154] Close Session c9317ad4-ff5c-11e9-bdbc-784f43775513
I1104 15:42:38.904987   63880 scheduler.go:87] End scheduling ...
I1104 15:42:43.909319   63880 scheduler.go:72] Start scheduling ...
I1104 15:42:43.922647   63880 cache.go:771] There are <0> Jobs, <1> Queues and <1> Nodes in total for scheduling.
I1104 15:42:43.922655   63880 session.go:135] Open Session cc2f22ae-ff5c-11e9-bdbc-784f43775513 with <0> Job and <1> Queues
I1104 15:42:43.922687   63880 proportion.go:67] The total resource is <cpu 4000.00, memory 4959854592.00, hugepages-2Mi 0.00>
I1104 15:42:43.922705   63880 proportion.go:117] Exiting when total weight is 0
I1104 15:42:43.922732   63880 enqueue.go:43] Enter Enqueue ...
I1104 15:42:43.922738   63880 enqueue.go:75] Try to enqueue PodGroup to 0 Queues
I1104 15:42:43.922744   63880 enqueue.go:122] Leaving Enqueue ...
I1104 15:42:43.922750   63880 allocate.go:43] Enter Allocate ...
I1104 15:42:43.922755   63880 allocate.go:94] Try to allocate resource to 0 Namespaces
I1104 15:42:43.922766   63880 allocate.go:253] Leaving Allocate ...
I1104 15:42:43.922770   63880 backfill.go:42] Enter Backfill ...
I1104 15:42:43.922773   63880 backfill.go:91] Leaving Backfill ...
I1104 15:42:43.922785   63880 session.go:154] Close Session cc2f22ae-ff5c-11e9-bdbc-784f43775513
I1104 15:42:43.922789   63880 scheduler.go:87] End scheduling ...
I1104 15:42:48.924027   63880 scheduler.go:72] Start scheduling ...
I1104 15:42:48.939257   63880 cache.go:771] There are <0> Jobs, <1> Queues and <1> Nodes in total for scheduling.
I1104 15:42:48.939266   63880 session.go:135] Open Session cf2c9c16-ff5c-11e9-bdbc-784f43775513 with <0> Job and <1> Queues
I1104 15:42:48.939283   63880 proportion.go:67] The total resource is <cpu 4000.00, memory 4959854592.00, hugepages-2Mi 0.00>
I1104 15:42:48.939300   63880 proportion.go:117] Exiting when total weight is 0
I1104 15:42:48.939341   63880 enqueue.go:43] Enter Enqueue ...
I1104 15:42:48.939347   63880 enqueue.go:75] Try to enqueue PodGroup to 0 Queues
I1104 15:42:48.939354   63880 enqueue.go:122] Leaving Enqueue ...
I1104 15:42:48.939361   63880 allocate.go:43] Enter Allocate ...
I1104 15:42:48.939366   63880 allocate.go:94] Try to allocate resource to 0 Namespaces
I1104 15:42:48.939378   63880 allocate.go:253] Leaving Allocate ...
I1104 15:42:48.939386   63880 backfill.go:42] Enter Backfill ...
I1104 15:42:48.939393   63880 backfill.go:91] Leaving Backfill ...
I1104 15:42:48.939409   63880 session.go:154] Close Session cf2c9c16-ff5c-11e9-bdbc-784f43775513
I1104 15:42:48.939414   63880 scheduler.go:87] End scheduling ...
I1104 15:42:53.940676   63880 scheduler.go:72] Start scheduling ...
I1104 15:42:53.957598   63880 cache.go:771] There are <0> Jobs, <1> Queues and <1> Nodes in total for scheduling.
I1104 15:42:53.957609   63880 session.go:135] Open Session d22a585e-ff5c-11e9-bdbc-784f43775513 with <0> Job and <1> Queues
I1104 15:42:53.957652   63880 proportion.go:67] The total resource is <cpu 4000.00, memory 4959854592.00, hugepages-2Mi 0.00>
I1104 15:42:53.957678   63880 proportion.go:117] Exiting when total weight is 0
I1104 15:42:53.957714   63880 enqueue.go:43] Enter Enqueue ...
I1104 15:42:53.957721   63880 enqueue.go:75] Try to enqueue PodGroup to 0 Queues
I1104 15:42:53.957732   63880 enqueue.go:122] Leaving Enqueue ...
I1104 15:42:53.957741   63880 allocate.go:43] Enter Allocate ...
I1104 15:42:53.957749   63880 allocate.go:94] Try to allocate resource to 0 Namespaces
I1104 15:42:53.957766   63880 allocate.go:253] Leaving Allocate ...
I1104 15:42:53.957771   63880 backfill.go:42] Enter Backfill ...
I1104 15:42:53.957777   63880 backfill.go:91] Leaving Backfill ...
I1104 15:42:53.957793   63880 session.go:154] Close Session d22a585e-ff5c-11e9-bdbc-784f43775513
I1104 15:42:53.957799   63880 scheduler.go:87] End scheduling ...
I1104 15:42:58.958412   63880 scheduler.go:72] Start scheduling ...
I1104 15:42:58.958552   63880 cache.go:771] There are <0> Jobs, <1> Queues and <1> Nodes in total for scheduling.
I1104 15:42:58.958560   63880 session.go:135] Open Session d5256ec2-ff5c-11e9-bdbc-784f43775513 with <0> Job and <1> Queues
I1104 15:42:58.958595   63880 proportion.go:67] The total resource is <cpu 4000.00, memory 4959854592.00, hugepages-2Mi 0.00>
I1104 15:42:58.958619   63880 proportion.go:117] Exiting when total weight is 0
I1104 15:42:58.958644   63880 enqueue.go:43] Enter Enqueue ...
I1104 15:42:58.958649   63880 enqueue.go:75] Try to enqueue PodGroup to 0 Queues
I1104 15:42:58.958660   63880 enqueue.go:122] Leaving Enqueue ...
I1104 15:42:58.958667   63880 allocate.go:43] Enter Allocate ...
I1104 15:42:58.958673   63880 allocate.go:94] Try to allocate resource to 0 Namespaces
I1104 15:42:58.958685   63880 allocate.go:253] Leaving Allocate ...
I1104 15:42:58.958690   63880 backfill.go:42] Enter Backfill ...
I1104 15:42:58.958694   63880 backfill.go:91] Leaving Backfill ...
I1104 15:42:58.958708   63880 session.go:154] Close Session d5256ec2-ff5c-11e9-bdbc-784f43775513
I1104 15:42:58.958712   63880 scheduler.go:87] End scheduling ...
I1104 15:43:03.959850   63880 scheduler.go:72] Start scheduling ...
I1104 15:43:03.960012   63880 cache.go:771] There are <0> Jobs, <1> Queues and <1> Nodes in total for scheduling.
I1104 15:43:03.960021   63880 session.go:135] Open Session d82097be-ff5c-11e9-bdbc-784f43775513 with <0> Job and <1> Queues
I1104 15:43:03.960081   63880 proportion.go:67] The total resource is <cpu 4000.00, memory 4959854592.00, hugepages-2Mi 0.00>
I1104 15:43:03.960101   63880 proportion.go:117] Exiting when total weight is 0
I1104 15:43:03.960109   63880 enqueue.go:43] Enter Enqueue ...
I1104 15:43:03.960114   63880 enqueue.go:75] Try to enqueue PodGroup to 0 Queues
I1104 15:43:03.960122   63880 enqueue.go:122] Leaving Enqueue ...
I1104 15:43:03.960130   63880 allocate.go:43] Enter Allocate ...
I1104 15:43:03.960136   63880 allocate.go:94] Try to allocate resource to 0 Namespaces
I1104 15:43:03.960149   63880 allocate.go:253] Leaving Allocate ...
I1104 15:43:03.960154   63880 backfill.go:42] Enter Backfill ...
I1104 15:43:03.960159   63880 backfill.go:91] Leaving Backfill ...
I1104 15:43:03.960173   63880 session.go:154] Close Session d82097be-ff5c-11e9-bdbc-784f43775513
I1104 15:43:03.960181   63880 scheduler.go:87] End scheduling ...
I1104 15:43:08.963318   63880 scheduler.go:72] Start scheduling ...
I1104 15:43:08.963474   63880 cache.go:771] There are <0> Jobs, <1> Queues and <1> Nodes in total for scheduling.
I1104 15:43:08.963482   63880 session.go:135] Open Session db1c0f66-ff5c-11e9-bdbc-784f43775513 with <0> Job and <1> Queues
I1104 15:43:08.963513   63880 proportion.go:67] The total resource is <cpu 4000.00, memory 4959854592.00, hugepages-2Mi 0.00>
I1104 15:43:08.963533   63880 proportion.go:117] Exiting when total weight is 0
I1104 15:43:08.963556   63880 enqueue.go:43] Enter Enqueue ...
I1104 15:43:08.963561   63880 enqueue.go:75] Try to enqueue PodGroup to 0 Queues
I1104 15:43:08.963567   63880 enqueue.go:122] Leaving Enqueue ...
I1104 15:43:08.963573   63880 allocate.go:43] Enter Allocate ...
I1104 15:43:08.963578   63880 allocate.go:94] Try to allocate resource to 0 Namespaces
I1104 15:43:08.963588   63880 allocate.go:253] Leaving Allocate ...
I1104 15:43:08.963592   63880 backfill.go:42] Enter Backfill ...
I1104 15:43:08.963595   63880 backfill.go:91] Leaving Backfill ...
I1104 15:43:08.963607   63880 session.go:154] Close Session db1c0f66-ff5c-11e9-bdbc-784f43775513
I1104 15:43:08.963610   63880 scheduler.go:87] End scheduling ...
I1104 15:43:13.967999   63880 scheduler.go:72] Start scheduling ...
I1104 15:43:13.968135   63880 cache.go:771] There are <0> Jobs, <1> Queues and <1> Nodes in total for scheduling.
I1104 15:43:13.968142   63880 session.go:135] Open Session de17b6ac-ff5c-11e9-bdbc-784f43775513 with <0> Job and <1> Queues
I1104 15:43:13.968181   63880 proportion.go:67] The total resource is <cpu 4000.00, memory 4959854592.00, hugepages-2Mi 0.00>
I1104 15:43:13.968200   63880 proportion.go:117] Exiting when total weight is 0
I1104 15:43:13.968218   63880 enqueue.go:43] Enter Enqueue ...
I1104 15:43:13.968223   63880 enqueue.go:75] Try to enqueue PodGroup to 0 Queues
I1104 15:43:13.968233   63880 enqueue.go:122] Leaving Enqueue ...
I1104 15:43:13.968239   63880 allocate.go:43] Enter Allocate ...
I1104 15:43:13.968245   63880 allocate.go:94] Try to allocate resource to 0 Namespaces
I1104 15:43:13.968257   63880 allocate.go:253] Leaving Allocate ...
I1104 15:43:13.968261   63880 backfill.go:42] Enter Backfill ...
I1104 15:43:13.968265   63880 backfill.go:91] Leaving Backfill ...
I1104 15:43:13.968277   63880 session.go:154] Close Session de17b6ac-ff5c-11e9-bdbc-784f43775513
I1104 15:43:13.968281   63880 scheduler.go:87] End scheduling ...
I1104 15:43:18.968581   63880 scheduler.go:72] Start scheduling ...
I1104 15:43:18.968714   63880 cache.go:771] There are <0> Jobs, <1> Queues and <1> Nodes in total for scheduling.
I1104 15:43:18.968721   63880 session.go:135] Open Session e112bdb6-ff5c-11e9-bdbc-784f43775513 with <0> Job and <1> Queues
I1104 15:43:18.968734   63880 proportion.go:67] The total resource is <cpu 4000.00, memory 4959854592.00, hugepages-2Mi 0.00>
I1104 15:43:18.968754   63880 proportion.go:117] Exiting when total weight is 0
I1104 15:43:18.968805   63880 enqueue.go:43] Enter Enqueue ...
I1104 15:43:18.968811   63880 enqueue.go:75] Try to enqueue PodGroup to 0 Queues
I1104 15:43:18.968819   63880 enqueue.go:122] Leaving Enqueue ...
I1104 15:43:18.968826   63880 allocate.go:43] Enter Allocate ...
I1104 15:43:18.968832   63880 allocate.go:94] Try to allocate resource to 0 Namespaces
I1104 15:43:18.968845   63880 allocate.go:253] Leaving Allocate ...
I1104 15:43:18.968850   63880 backfill.go:42] Enter Backfill ...
I1104 15:43:18.968854   63880 backfill.go:91] Leaving Backfill ...
I1104 15:43:18.968870   63880 session.go:154] Close Session e112bdb6-ff5c-11e9-bdbc-784f43775513
I1104 15:43:18.968875   63880 scheduler.go:87] End scheduling ...
I1104 15:43:23.970882   63880 scheduler.go:72] Start scheduling ...
I1104 15:43:23.971042   63880 cache.go:771] There are <0> Jobs, <1> Queues and <1> Nodes in total for scheduling.
I1104 15:43:23.971048   63880 session.go:135] Open Session e40e0930-ff5c-11e9-bdbc-784f43775513 with <0> Job and <1> Queues
I1104 15:43:23.971089   63880 proportion.go:67] The total resource is <cpu 4000.00, memory 4959854592.00, hugepages-2Mi 0.00>
I1104 15:43:23.971107   63880 proportion.go:117] Exiting when total weight is 0
I1104 15:43:23.971123   63880 enqueue.go:43] Enter Enqueue ...
I1104 15:43:23.971127   63880 enqueue.go:75] Try to enqueue PodGroup to 0 Queues
I1104 15:43:23.971133   63880 enqueue.go:122] Leaving Enqueue ...
I1104 15:43:23.971139   63880 allocate.go:43] Enter Allocate ...
I1104 15:43:23.971144   63880 allocate.go:94] Try to allocate resource to 0 Namespaces
I1104 15:43:23.971154   63880 allocate.go:253] Leaving Allocate ...
I1104 15:43:23.971158   63880 backfill.go:42] Enter Backfill ...
I1104 15:43:23.971161   63880 backfill.go:91] Leaving Backfill ...
I1104 15:43:23.971172   63880 session.go:154] Close Session e40e0930-ff5c-11e9-bdbc-784f43775513
I1104 15:43:23.971176   63880 scheduler.go:87] End scheduling ...
I1104 15:43:28.974963   63880 scheduler.go:72] Start scheduling ...
I1104 15:43:28.975092   63880 cache.go:771] There are <0> Jobs, <1> Queues and <1> Nodes in total for scheduling.
I1104 15:43:28.975099   63880 session.go:135] Open Session e709980c-ff5c-11e9-bdbc-784f43775513 with <0> Job and <1> Queues
I1104 15:43:28.975143   63880 proportion.go:67] The total resource is <cpu 4000.00, memory 4959854592.00, hugepages-2Mi 0.00>
I1104 15:43:28.975160   63880 proportion.go:117] Exiting when total weight is 0
I1104 15:43:28.975166   63880 enqueue.go:43] Enter Enqueue ...
I1104 15:43:28.975170   63880 enqueue.go:75] Try to enqueue PodGroup to 0 Queues
I1104 15:43:28.975176   63880 enqueue.go:122] Leaving Enqueue ...
I1104 15:43:28.975181   63880 allocate.go:43] Enter Allocate ...
I1104 15:43:28.975186   63880 allocate.go:94] Try to allocate resource to 0 Namespaces
I1104 15:43:28.975196   63880 allocate.go:253] Leaving Allocate ...
I1104 15:43:28.975200   63880 backfill.go:42] Enter Backfill ...
I1104 15:43:28.975203   63880 backfill.go:91] Leaving Backfill ...
I1104 15:43:28.975213   63880 session.go:154] Close Session e709980c-ff5c-11e9-bdbc-784f43775513
I1104 15:43:28.975217   63880 scheduler.go:87] End scheduling ...
I1104 15:43:33.978337   63880 scheduler.go:72] Start scheduling ...
I1104 15:43:33.978516   63880 cache.go:771] There are <0> Jobs, <1> Queues and <1> Nodes in total for scheduling.
I1104 15:43:33.978525   63880 session.go:135] Open Session ea050dc0-ff5c-11e9-bdbc-784f43775513 with <0> Job and <1> Queues
I1104 15:43:33.978571   63880 proportion.go:67] The total resource is <cpu 4000.00, memory 4959854592.00, hugepages-2Mi 0.00>
I1104 15:43:33.978592   63880 proportion.go:117] Exiting when total weight is 0
I1104 15:43:33.978611   63880 enqueue.go:43] Enter Enqueue ...
I1104 15:43:33.978616   63880 enqueue.go:75] Try to enqueue PodGroup to 0 Queues
I1104 15:43:33.978622   63880 enqueue.go:122] Leaving Enqueue ...
I1104 15:43:33.978628   63880 allocate.go:43] Enter Allocate ...
I1104 15:43:33.978632   63880 allocate.go:94] Try to allocate resource to 0 Namespaces
I1104 15:43:33.978645   63880 allocate.go:253] Leaving Allocate ...
I1104 15:43:33.978650   63880 backfill.go:42] Enter Backfill ...
I1104 15:43:33.978653   63880 backfill.go:91] Leaving Backfill ...
I1104 15:43:33.978665   63880 session.go:154] Close Session ea050dc0-ff5c-11e9-bdbc-784f43775513
I1104 15:43:33.978670   63880 scheduler.go:87] End scheduling ...
I1104 15:43:38.981671   63880 scheduler.go:72] Start scheduling ...
I1104 15:43:38.981944   63880 cache.go:771] There are <0> Jobs, <1> Queues and <1> Nodes in total for scheduling.
I1104 15:43:38.981957   63880 session.go:135] Open Session ed0081a8-ff5c-11e9-bdbc-784f43775513 with <0> Job and <1> Queues
I1104 15:43:38.982092   63880 proportion.go:67] The total resource is <cpu 4000.00, memory 4959854592.00, hugepages-2Mi 0.00>
I1104 15:43:38.982117   63880 proportion.go:117] Exiting when total weight is 0
I1104 15:43:38.982147   63880 enqueue.go:43] Enter Enqueue ...
I1104 15:43:38.982152   63880 enqueue.go:75] Try to enqueue PodGroup to 0 Queues
I1104 15:43:38.982161   63880 enqueue.go:122] Leaving Enqueue ...
I1104 15:43:38.982168   63880 allocate.go:43] Enter Allocate ...
I1104 15:43:38.982173   63880 allocate.go:94] Try to allocate resource to 0 Namespaces
I1104 15:43:38.982185   63880 allocate.go:253] Leaving Allocate ...
I1104 15:43:38.982191   63880 backfill.go:42] Enter Backfill ...
I1104 15:43:38.982196   63880 backfill.go:91] Leaving Backfill ...
I1104 15:43:38.982209   63880 session.go:154] Close Session ed0081a8-ff5c-11e9-bdbc-784f43775513
I1104 15:43:38.982213   63880 scheduler.go:87] End scheduling ...
I1104 15:43:43.984803   63880 scheduler.go:72] Start scheduling ...
I1104 15:43:43.984981   63880 cache.go:771] There are <0> Jobs, <1> Queues and <1> Nodes in total for scheduling.
I1104 15:43:43.984988   63880 session.go:135] Open Session effbeb22-ff5c-11e9-bdbc-784f43775513 with <0> Job and <1> Queues
I1104 15:43:43.985050   63880 proportion.go:67] The total resource is <cpu 4000.00, memory 4959854592.00, hugepages-2Mi 0.00>
I1104 15:43:43.985074   63880 proportion.go:117] Exiting when total weight is 0
I1104 15:43:43.985106   63880 enqueue.go:43] Enter Enqueue ...
I1104 15:43:43.985111   63880 enqueue.go:75] Try to enqueue PodGroup to 0 Queues
I1104 15:43:43.985118   63880 enqueue.go:122] Leaving Enqueue ...
I1104 15:43:43.985124   63880 allocate.go:43] Enter Allocate ...
I1104 15:43:43.985129   63880 allocate.go:94] Try to allocate resource to 0 Namespaces
I1104 15:43:43.985140   63880 allocate.go:253] Leaving Allocate ...
I1104 15:43:43.985145   63880 backfill.go:42] Enter Backfill ...
I1104 15:43:43.985148   63880 backfill.go:91] Leaving Backfill ...
I1104 15:43:43.985160   63880 session.go:154] Close Session effbeb22-ff5c-11e9-bdbc-784f43775513
I1104 15:43:43.985164   63880 scheduler.go:87] End scheduling ...
I1104 15:43:48.985508   63880 scheduler.go:72] Start scheduling ...
I1104 15:43:48.985632   63880 cache.go:771] There are <0> Jobs, <1> Queues and <1> Nodes in total for scheduling.
I1104 15:43:48.985638   63880 session.go:135] Open Session f2f6f588-ff5c-11e9-bdbc-784f43775513 with <0> Job and <1> Queues
I1104 15:43:48.985673   63880 proportion.go:67] The total resource is <cpu 4000.00, memory 4959854592.00, hugepages-2Mi 0.00>
I1104 15:43:48.985689   63880 proportion.go:117] Exiting when total weight is 0
I1104 15:43:48.985705   63880 enqueue.go:43] Enter Enqueue ...
I1104 15:43:48.985709   63880 enqueue.go:75] Try to enqueue PodGroup to 0 Queues
I1104 15:43:48.985716   63880 enqueue.go:122] Leaving Enqueue ...
I1104 15:43:48.985721   63880 allocate.go:43] Enter Allocate ...
I1104 15:43:48.985726   63880 allocate.go:94] Try to allocate resource to 0 Namespaces
I1104 15:43:48.985737   63880 allocate.go:253] Leaving Allocate ...
I1104 15:43:48.985741   63880 backfill.go:42] Enter Backfill ...
I1104 15:43:48.985744   63880 backfill.go:91] Leaving Backfill ...
I1104 15:43:48.985755   63880 session.go:154] Close Session f2f6f588-ff5c-11e9-bdbc-784f43775513
I1104 15:43:48.985759   63880 scheduler.go:87] End scheduling ...
I1104 15:43:53.986076   63880 scheduler.go:72] Start scheduling ...
I1104 15:43:53.986218   63880 cache.go:771] There are <0> Jobs, <1> Queues and <1> Nodes in total for scheduling.
I1104 15:43:53.986224   63880 session.go:135] Open Session f5f1fd0a-ff5c-11e9-bdbc-784f43775513 with <0> Job and <1> Queues
I1104 15:43:53.986280   63880 proportion.go:67] The total resource is <cpu 4000.00, memory 4959854592.00, hugepages-2Mi 0.00>
I1104 15:43:53.986298   63880 proportion.go:117] Exiting when total weight is 0
I1104 15:43:53.986305   63880 enqueue.go:43] Enter Enqueue ...
I1104 15:43:53.986310   63880 enqueue.go:75] Try to enqueue PodGroup to 0 Queues
I1104 15:43:53.986318   63880 enqueue.go:122] Leaving Enqueue ...
I1104 15:43:53.986324   63880 allocate.go:43] Enter Allocate ...
I1104 15:43:53.986329   63880 allocate.go:94] Try to allocate resource to 0 Namespaces
I1104 15:43:53.986341   63880 allocate.go:253] Leaving Allocate ...
I1104 15:43:53.986345   63880 backfill.go:42] Enter Backfill ...
I1104 15:43:53.986349   63880 backfill.go:91] Leaving Backfill ...
I1104 15:43:53.986363   63880 session.go:154] Close Session f5f1fd0a-ff5c-11e9-bdbc-784f43775513
I1104 15:43:53.986367   63880 scheduler.go:87] End scheduling ...
I1104 15:43:58.990637   63880 scheduler.go:72] Start scheduling ...
I1104 15:43:58.990778   63880 cache.go:771] There are <0> Jobs, <1> Queues and <1> Nodes in total for scheduling.
I1104 15:43:58.990785   63880 session.go:135] Open Session f8ed9fb4-ff5c-11e9-bdbc-784f43775513 with <0> Job and <1> Queues
I1104 15:43:58.990821   63880 proportion.go:67] The total resource is <cpu 4000.00, memory 4959854592.00, hugepages-2Mi 0.00>
I1104 15:43:58.990842   63880 proportion.go:117] Exiting when total weight is 0
I1104 15:43:58.990863   63880 enqueue.go:43] Enter Enqueue ...
I1104 15:43:58.990868   63880 enqueue.go:75] Try to enqueue PodGroup to 0 Queues
I1104 15:43:58.990875   63880 enqueue.go:122] Leaving Enqueue ...
I1104 15:43:58.990881   63880 allocate.go:43] Enter Allocate ...
I1104 15:43:58.990886   63880 allocate.go:94] Try to allocate resource to 0 Namespaces
I1104 15:43:58.990898   63880 allocate.go:253] Leaving Allocate ...
I1104 15:43:58.990902   63880 backfill.go:42] Enter Backfill ...
I1104 15:43:58.990906   63880 backfill.go:91] Leaving Backfill ...
I1104 15:43:58.990918   63880 session.go:154] Close Session f8ed9fb4-ff5c-11e9-bdbc-784f43775513
I1104 15:43:58.990923   63880 scheduler.go:87] End scheduling ...
I1104 15:44:03.994893   63880 scheduler.go:72] Start scheduling ...
I1104 15:44:03.995036   63880 cache.go:771] There are <0> Jobs, <1> Queues and <1> Nodes in total for scheduling.
I1104 15:44:03.995042   63880 session.go:135] Open Session fbe93656-ff5c-11e9-bdbc-784f43775513 with <0> Job and <1> Queues
I1104 15:44:03.995082   63880 proportion.go:67] The total resource is <cpu 4000.00, memory 4959854592.00, hugepages-2Mi 0.00>
I1104 15:44:03.995104   63880 proportion.go:117] Exiting when total weight is 0
I1104 15:44:03.995125   63880 enqueue.go:43] Enter Enqueue ...
I1104 15:44:03.995131   63880 enqueue.go:75] Try to enqueue PodGroup to 0 Queues
I1104 15:44:03.995138   63880 enqueue.go:122] Leaving Enqueue ...
I1104 15:44:03.995144   63880 allocate.go:43] Enter Allocate ...
I1104 15:44:03.995151   63880 allocate.go:94] Try to allocate resource to 0 Namespaces
I1104 15:44:03.995164   63880 allocate.go:253] Leaving Allocate ...
I1104 15:44:03.995169   63880 backfill.go:42] Enter Backfill ...
I1104 15:44:03.995173   63880 backfill.go:91] Leaving Backfill ...
I1104 15:44:03.995187   63880 session.go:154] Close Session fbe93656-ff5c-11e9-bdbc-784f43775513
I1104 15:44:03.995191   63880 scheduler.go:87] End scheduling ...
I1104 15:44:08.999357   63880 scheduler.go:72] Start scheduling ...
I1104 15:44:08.999492   63880 cache.go:771] There are <0> Jobs, <1> Queues and <1> Nodes in total for scheduling.
I1104 15:44:08.999499   63880 session.go:135] Open Session fee4d4f0-ff5c-11e9-bdbc-784f43775513 with <0> Job and <1> Queues
I1104 15:44:08.999552   63880 proportion.go:67] The total resource is <cpu 4000.00, memory 4959854592.00, hugepages-2Mi 0.00>
I1104 15:44:08.999572   63880 proportion.go:117] Exiting when total weight is 0
I1104 15:44:08.999579   63880 enqueue.go:43] Enter Enqueue ...
I1104 15:44:08.999585   63880 enqueue.go:75] Try to enqueue PodGroup to 0 Queues
I1104 15:44:08.999593   63880 enqueue.go:122] Leaving Enqueue ...
I1104 15:44:08.999600   63880 allocate.go:43] Enter Allocate ...
I1104 15:44:08.999607   63880 allocate.go:94] Try to allocate resource to 0 Namespaces
I1104 15:44:08.999620   63880 allocate.go:253] Leaving Allocate ...
I1104 15:44:08.999625   63880 backfill.go:42] Enter Backfill ...
I1104 15:44:08.999629   63880 backfill.go:91] Leaving Backfill ...
I1104 15:44:08.999643   63880 session.go:154] Close Session fee4d4f0-ff5c-11e9-bdbc-784f43775513
I1104 15:44:08.999648   63880 scheduler.go:87] End scheduling ...
I1104 15:44:14.002052   63880 scheduler.go:72] Start scheduling ...
I1104 15:44:14.002196   63880 cache.go:771] There are <0> Jobs, <1> Queues and <1> Nodes in total for scheduling.
I1104 15:44:14.002202   63880 session.go:135] Open Session 01e02f06-ff5d-11e9-bdbc-784f43775513 with <0> Job and <1> Queues
I1104 15:44:14.002243   63880 proportion.go:67] The total resource is <cpu 4000.00, memory 4959854592.00, hugepages-2Mi 0.00>
I1104 15:44:14.002266   63880 proportion.go:117] Exiting when total weight is 0
I1104 15:44:14.002285   63880 enqueue.go:43] Enter Enqueue ...
I1104 15:44:14.002290   63880 enqueue.go:75] Try to enqueue PodGroup to 0 Queues
I1104 15:44:14.002299   63880 enqueue.go:122] Leaving Enqueue ...
I1104 15:44:14.002305   63880 allocate.go:43] Enter Allocate ...
I1104 15:44:14.002311   63880 allocate.go:94] Try to allocate resource to 0 Namespaces
I1104 15:44:14.002324   63880 allocate.go:253] Leaving Allocate ...
I1104 15:44:14.002327   63880 backfill.go:42] Enter Backfill ...
I1104 15:44:14.002331   63880 backfill.go:91] Leaving Backfill ...
I1104 15:44:14.002344   63880 session.go:154] Close Session 01e02f06-ff5d-11e9-bdbc-784f43775513
I1104 15:44:14.002349   63880 scheduler.go:87] End scheduling ...
I1104 15:44:19.007024   63880 scheduler.go:72] Start scheduling ...
I1104 15:44:19.007161   63880 cache.go:771] There are <0> Jobs, <1> Queues and <1> Nodes in total for scheduling.
I1104 15:44:19.007167   63880 session.go:135] Open Session 04dbe1b4-ff5d-11e9-bdbc-784f43775513 with <0> Job and <1> Queues
I1104 15:44:19.007178   63880 proportion.go:67] The total resource is <cpu 4000.00, memory 4959854592.00, hugepages-2Mi 0.00>
I1104 15:44:19.007193   63880 proportion.go:117] Exiting when total weight is 0
I1104 15:44:19.007230   63880 enqueue.go:43] Enter Enqueue ...
I1104 15:44:19.007235   63880 enqueue.go:75] Try to enqueue PodGroup to 0 Queues
I1104 15:44:19.007241   63880 enqueue.go:122] Leaving Enqueue ...
I1104 15:44:19.007246   63880 allocate.go:43] Enter Allocate ...
I1104 15:44:19.007250   63880 allocate.go:94] Try to allocate resource to 0 Namespaces
I1104 15:44:19.007261   63880 allocate.go:253] Leaving Allocate ...
I1104 15:44:19.007264   63880 backfill.go:42] Enter Backfill ...
I1104 15:44:19.007269   63880 backfill.go:91] Leaving Backfill ...
I1104 15:44:19.007280   63880 session.go:154] Close Session 04dbe1b4-ff5d-11e9-bdbc-784f43775513
I1104 15:44:19.007283   63880 scheduler.go:87] End scheduling ...
I1104 15:44:24.012282   63880 scheduler.go:72] Start scheduling ...
I1104 15:44:24.012458   63880 cache.go:771] There are <0> Jobs, <1> Queues and <1> Nodes in total for scheduling.
I1104 15:44:24.012465   63880 session.go:135] Open Session 07d7a0d8-ff5d-11e9-bdbc-784f43775513 with <0> Job and <1> Queues
I1104 15:44:24.012507   63880 proportion.go:67] The total resource is <cpu 4000.00, memory 4959854592.00, hugepages-2Mi 0.00>
I1104 15:44:24.012525   63880 proportion.go:117] Exiting when total weight is 0
I1104 15:44:24.012553   63880 enqueue.go:43] Enter Enqueue ...
I1104 15:44:24.012559   63880 enqueue.go:75] Try to enqueue PodGroup to 0 Queues
I1104 15:44:24.012566   63880 enqueue.go:122] Leaving Enqueue ...
I1104 15:44:24.012572   63880 allocate.go:43] Enter Allocate ...
I1104 15:44:24.012578   63880 allocate.go:94] Try to allocate resource to 0 Namespaces
I1104 15:44:24.012590   63880 allocate.go:253] Leaving Allocate ...
I1104 15:44:24.012594   63880 backfill.go:42] Enter Backfill ...
I1104 15:44:24.012598   63880 backfill.go:91] Leaving Backfill ...
I1104 15:44:24.012611   63880 session.go:154] Close Session 07d7a0d8-ff5d-11e9-bdbc-784f43775513
I1104 15:44:24.012615   63880 scheduler.go:87] End scheduling ...
I1104 15:44:29.013872   63880 scheduler.go:72] Start scheduling ...
I1104 15:44:29.014047   63880 cache.go:771] There are <0> Jobs, <1> Queues and <1> Nodes in total for scheduling.
I1104 15:44:29.014056   63880 session.go:135] Open Session 0ad2cf24-ff5d-11e9-bdbc-784f43775513 with <0> Job and <1> Queues
I1104 15:44:29.014072   63880 proportion.go:67] The total resource is <cpu 4000.00, memory 4959854592.00, hugepages-2Mi 0.00>
I1104 15:44:29.014094   63880 proportion.go:117] Exiting when total weight is 0
I1104 15:44:29.014168   63880 enqueue.go:43] Enter Enqueue ...
I1104 15:44:29.014177   63880 enqueue.go:75] Try to enqueue PodGroup to 0 Queues
I1104 15:44:29.014185   63880 enqueue.go:122] Leaving Enqueue ...
I1104 15:44:29.014192   63880 allocate.go:43] Enter Allocate ...
I1104 15:44:29.014198   63880 allocate.go:94] Try to allocate resource to 0 Namespaces
I1104 15:44:29.014208   63880 allocate.go:253] Leaving Allocate ...
I1104 15:44:29.014212   63880 backfill.go:42] Enter Backfill ...
I1104 15:44:29.014216   63880 backfill.go:91] Leaving Backfill ...
I1104 15:44:29.014229   63880 session.go:154] Close Session 0ad2cf24-ff5d-11e9-bdbc-784f43775513
I1104 15:44:29.014233   63880 scheduler.go:87] End scheduling ...
I1104 15:44:34.014748   63880 scheduler.go:72] Start scheduling ...
I1104 15:44:34.014884   63880 cache.go:771] There are <0> Jobs, <1> Queues and <1> Nodes in total for scheduling.
I1104 15:44:34.014892   63880 session.go:135] Open Session 0dcde09c-ff5d-11e9-bdbc-784f43775513 with <0> Job and <1> Queues
I1104 15:44:34.014944   63880 proportion.go:67] The total resource is <cpu 4000.00, memory 4959854592.00, hugepages-2Mi 0.00>
I1104 15:44:34.014961   63880 proportion.go:117] Exiting when total weight is 0
I1104 15:44:34.014967   63880 enqueue.go:43] Enter Enqueue ...
I1104 15:44:34.014970   63880 enqueue.go:75] Try to enqueue PodGroup to 0 Queues
I1104 15:44:34.014976   63880 enqueue.go:122] Leaving Enqueue ...
I1104 15:44:34.014981   63880 allocate.go:43] Enter Allocate ...
I1104 15:44:34.014985   63880 allocate.go:94] Try to allocate resource to 0 Namespaces
I1104 15:44:34.014995   63880 allocate.go:253] Leaving Allocate ...
I1104 15:44:34.014999   63880 backfill.go:42] Enter Backfill ...
I1104 15:44:34.015002   63880 backfill.go:91] Leaving Backfill ...
I1104 15:44:34.015012   63880 session.go:154] Close Session 0dcde09c-ff5d-11e9-bdbc-784f43775513
I1104 15:44:34.015015   63880 scheduler.go:87] End scheduling ...
I1104 15:44:39.015216   63880 scheduler.go:72] Start scheduling ...
I1104 15:44:39.015334   63880 cache.go:771] There are <0> Jobs, <1> Queues and <1> Nodes in total for scheduling.
I1104 15:44:39.015340   63880 session.go:135] Open Session 10c8e30a-ff5d-11e9-bdbc-784f43775513 with <0> Job and <1> Queues
I1104 15:44:39.015373   63880 proportion.go:67] The total resource is <cpu 4000.00, memory 4959854592.00, hugepages-2Mi 0.00>
I1104 15:44:39.015389   63880 proportion.go:117] Exiting when total weight is 0
I1104 15:44:39.015411   63880 enqueue.go:43] Enter Enqueue ...
I1104 15:44:39.015415   63880 enqueue.go:75] Try to enqueue PodGroup to 0 Queues
I1104 15:44:39.015421   63880 enqueue.go:122] Leaving Enqueue ...
I1104 15:44:39.015427   63880 allocate.go:43] Enter Allocate ...
I1104 15:44:39.015431   63880 allocate.go:94] Try to allocate resource to 0 Namespaces
I1104 15:44:39.015442   63880 allocate.go:253] Leaving Allocate ...
I1104 15:44:39.015446   63880 backfill.go:42] Enter Backfill ...
I1104 15:44:39.015449   63880 backfill.go:91] Leaving Backfill ...
I1104 15:44:39.015469   63880 session.go:154] Close Session 10c8e30a-ff5d-11e9-bdbc-784f43775513
I1104 15:44:39.015473   63880 scheduler.go:87] End scheduling ...
I1104 15:44:44.020455   63880 scheduler.go:72] Start scheduling ...
I1104 15:44:44.020620   63880 cache.go:771] There are <0> Jobs, <1> Queues and <1> Nodes in total for scheduling.
I1104 15:44:44.020628   63880 session.go:135] Open Session 13c4a170-ff5d-11e9-bdbc-784f43775513 with <0> Job and <1> Queues
I1104 15:44:44.020674   63880 proportion.go:67] The total resource is <cpu 4000.00, memory 4959854592.00, hugepages-2Mi 0.00>
I1104 15:44:44.020697   63880 proportion.go:117] Exiting when total weight is 0
I1104 15:44:44.020729   63880 enqueue.go:43] Enter Enqueue ...
I1104 15:44:44.020736   63880 enqueue.go:75] Try to enqueue PodGroup to 0 Queues
I1104 15:44:44.020746   63880 enqueue.go:122] Leaving Enqueue ...
I1104 15:44:44.020754   63880 allocate.go:43] Enter Allocate ...
I1104 15:44:44.020761   63880 allocate.go:94] Try to allocate resource to 0 Namespaces
I1104 15:44:44.020777   63880 allocate.go:253] Leaving Allocate ...
I1104 15:44:44.020783   63880 backfill.go:42] Enter Backfill ...
I1104 15:44:44.020789   63880 backfill.go:91] Leaving Backfill ...
I1104 15:44:44.020807   63880 session.go:154] Close Session 13c4a170-ff5d-11e9-bdbc-784f43775513
I1104 15:44:44.020815   63880 scheduler.go:87] End scheduling ...
I1104 15:44:49.021053   63880 scheduler.go:72] Start scheduling ...
I1104 15:44:49.021189   63880 cache.go:771] There are <0> Jobs, <1> Queues and <1> Nodes in total for scheduling.
I1104 15:44:49.021195   63880 session.go:135] Open Session 16bfa8b6-ff5d-11e9-bdbc-784f43775513 with <0> Job and <1> Queues
I1104 15:44:49.021231   63880 proportion.go:67] The total resource is <cpu 4000.00, memory 4959854592.00, hugepages-2Mi 0.00>
I1104 15:44:49.021248   63880 proportion.go:117] Exiting when total weight is 0
I1104 15:44:49.021264   63880 enqueue.go:43] Enter Enqueue ...
I1104 15:44:49.021268   63880 enqueue.go:75] Try to enqueue PodGroup to 0 Queues
I1104 15:44:49.021274   63880 enqueue.go:122] Leaving Enqueue ...
I1104 15:44:49.021279   63880 allocate.go:43] Enter Allocate ...
I1104 15:44:49.021284   63880 allocate.go:94] Try to allocate resource to 0 Namespaces
I1104 15:44:49.021294   63880 allocate.go:253] Leaving Allocate ...
I1104 15:44:49.021298   63880 backfill.go:42] Enter Backfill ...
I1104 15:44:49.021301   63880 backfill.go:91] Leaving Backfill ...
I1104 15:44:49.021313   63880 session.go:154] Close Session 16bfa8b6-ff5d-11e9-bdbc-784f43775513
I1104 15:44:49.021316   63880 scheduler.go:87] End scheduling ...
F1104 15:44:53.023199   63880 helpers.go:210] Stopped listening on 127.0.0.1:11251 due to error: http: Server closed
goroutine 70 [running]:
volcano.sh/volcano/vendor/github.com/golang/glog.stacks(0xc0000e8001, 0xc00074c000, 0x4b6, 0x2710)
	/Users/yuan.chen/GolandProjects/src/volcano.sh/volcano/vendor/github.com/golang/glog/glog.go:769 +0xb8
volcano.sh/volcano/vendor/github.com/golang/glog.(*loggingT).output(0x2efe3c0, 0xc000000003, 0xc00087ab60, 0x2e4a765, 0xa, 0xd2, 0x0)
	/Users/yuan.chen/GolandProjects/src/volcano.sh/volcano/vendor/github.com/golang/glog/glog.go:723 +0x1b7
volcano.sh/volcano/vendor/github.com/golang/glog.(*loggingT).printf(0x2efe3c0, 0x3, 0x21b0861, 0x13, 0xc000081f90, 0x2, 0x2)
	/Users/yuan.chen/GolandProjects/src/volcano.sh/volcano/vendor/github.com/golang/glog/glog.go:655 +0x14b
volcano.sh/volcano/vendor/github.com/golang/glog.Fatalf(...)
	/Users/yuan.chen/GolandProjects/src/volcano.sh/volcano/vendor/github.com/golang/glog/glog.go:1148
volcano.sh/volcano/pkg/apis/helpers.runServer.func2(0x23c27e0, 0xc000622040, 0xc0005dc000, 0xc000130060)
	/Users/yuan.chen/GolandProjects/src/volcano.sh/volcano/pkg/apis/helpers/helpers.go:210 +0x2fc
created by volcano.sh/volcano/pkg/apis/helpers.runServer
	/Users/yuan.chen/GolandProjects/src/volcano.sh/volcano/pkg/apis/helpers/helpers.go:198 +0x170

goroutine 1 [chan receive (nil chan), 7 minutes]:
volcano.sh/volcano/cmd/scheduler/app.Run.func2(0x23d2260, 0xc000118070)
	/Users/yuan.chen/GolandProjects/src/volcano.sh/volcano/cmd/scheduler/app/server.go:107 +0x73
volcano.sh/volcano/cmd/scheduler/app.Run(0xc0000b5380, 0x223db28, 0x223cab0)
	/Users/yuan.chen/GolandProjects/src/volcano.sh/volcano/cmd/scheduler/app/server.go:111 +0x79b
main.main()
	/Users/yuan.chen/GolandProjects/src/volcano.sh/volcano/cmd/scheduler/main.go:62 +0x1ae

goroutine 35 [chan receive]:
volcano.sh/volcano/vendor/k8s.io/klog.(*loggingT).flushDaemon(0x2efe560)
	/Users/yuan.chen/GolandProjects/src/volcano.sh/volcano/vendor/k8s.io/klog/klog.go:941 +0x8b
created by volcano.sh/volcano/vendor/k8s.io/klog.init.0
	/Users/yuan.chen/GolandProjects/src/volcano.sh/volcano/vendor/k8s.io/klog/klog.go:403 +0x6c

goroutine 20 [chan receive]:
volcano.sh/volcano/vendor/github.com/golang/glog.(*loggingT).flushDaemon(0x2efe3c0)
	/Users/yuan.chen/GolandProjects/src/volcano.sh/volcano/vendor/github.com/golang/glog/glog.go:882 +0x8b
created by volcano.sh/volcano/vendor/github.com/golang/glog.init.0
	/Users/yuan.chen/GolandProjects/src/volcano.sh/volcano/vendor/github.com/golang/glog/glog.go:410 +0x26f

goroutine 21 [syscall]:
os/signal.signal_recv(0x23a80a0)
	/usr/local/opt/go/libexec/src/runtime/sigqueue.go:144 +0x96
os/signal.loop()
	/usr/local/opt/go/libexec/src/os/signal/signal_unix.go:23 +0x22
created by os/signal.init.0
	/usr/local/opt/go/libexec/src/os/signal/signal_unix.go:29 +0x41

goroutine 64 [chan receive, 7 minutes]:
volcano.sh/volcano/vendor/k8s.io/client-go/tools/cache.(*processorListener).run.func1.1(0x0, 0x0, 0x0)
	/Users/yuan.chen/GolandProjects/src/volcano.sh/volcano/vendor/k8s.io/client-go/tools/cache/shared_informer.go:549 +0x54
volcano.sh/volcano/vendor/k8s.io/apimachinery/pkg/util/wait.ExponentialBackoff(0x989680, 0x3ff0000000000000, 0x3fb999999999999a, 0x5, 0xc000395dd8, 0x0, 0x0)
	/Users/yuan.chen/GolandProjects/src/volcano.sh/volcano/vendor/k8s.io/apimachinery/pkg/util/wait/wait.go:203 +0xde
volcano.sh/volcano/vendor/k8s.io/client-go/tools/cache.(*processorListener).run.func1()
	/Users/yuan.chen/GolandProjects/src/volcano.sh/volcano/vendor/k8s.io/client-go/tools/cache/shared_informer.go:548 +0x89
volcano.sh/volcano/vendor/k8s.io/apimachinery/pkg/util/wait.JitterUntil.func1(0xc00006d740)
	/Users/yuan.chen/GolandProjects/src/volcano.sh/volcano/vendor/k8s.io/apimachinery/pkg/util/wait/wait.go:133 +0x5e
volcano.sh/volcano/vendor/k8s.io/apimachinery/pkg/util/wait.JitterUntil(0xc000395f40, 0xdf8475800, 0x0, 0x1030501, 0xc000188180)
	/Users/yuan.chen/GolandProjects/src/volcano.sh/volcano/vendor/k8s.io/apimachinery/pkg/util/wait/wait.go:134 +0xf8
volcano.sh/volcano/vendor/k8s.io/apimachinery/pkg/util/wait.Until(...)
	/Users/yuan.chen/GolandProjects/src/volcano.sh/volcano/vendor/k8s.io/apimachinery/pkg/util/wait/wait.go:88
volcano.sh/volcano/vendor/k8s.io/client-go/tools/cache.(*processorListener).run(0xc0004dc380)
	/Users/yuan.chen/GolandProjects/src/volcano.sh/volcano/vendor/k8s.io/client-go/tools/cache/shared_informer.go:546 +0x9b
volcano.sh/volcano/vendor/k8s.io/apimachinery/pkg/util/wait.(*Group).Start.func1(0xc0001c6140, 0xc000084360)
	/Users/yuan.chen/GolandProjects/src/volcano.sh/volcano/vendor/k8s.io/apimachinery/pkg/util/wait/wait.go:71 +0x59
created by volcano.sh/volcano/vendor/k8s.io/apimachinery/pkg/util/wait.(*Group).Start
	/Users/yuan.chen/GolandProjects/src/volcano.sh/volcano/vendor/k8s.io/apimachinery/pkg/util/wait/wait.go:69 +0x62

goroutine 99 [select]:
volcano.sh/volcano/vendor/k8s.io/apimachinery/pkg/util/wait.JitterUntil(0x223cab0, 0x12a05f200, 0x0, 0x1, 0xc000188000)
	/Users/yuan.chen/GolandProjects/src/volcano.sh/volcano/vendor/k8s.io/apimachinery/pkg/util/wait/wait.go:145 +0x181
volcano.sh/volcano/vendor/k8s.io/apimachinery/pkg/util/wait.Until(0x223cab0, 0x12a05f200, 0xc000188000)
	/Users/yuan.chen/GolandProjects/src/volcano.sh/volcano/vendor/k8s.io/apimachinery/pkg/util/wait/wait.go:88 +0x4d
created by main.main
	/Users/yuan.chen/GolandProjects/src/volcano.sh/volcano/cmd/scheduler/main.go:59 +0x173

goroutine 114 [select]:
volcano.sh/volcano/vendor/k8s.io/client-go/util/workqueue.(*delayingType).waitingLoop(0xc0002faa50)
	/Users/yuan.chen/GolandProjects/src/volcano.sh/volcano/vendor/k8s.io/client-go/util/workqueue/delaying_queue.go:206 +0x344
created by volcano.sh/volcano/vendor/k8s.io/client-go/util/workqueue.newDelayingQueue
	/Users/yuan.chen/GolandProjects/src/volcano.sh/volcano/vendor/k8s.io/client-go/util/workqueue/delaying_queue.go:54 +0x1ae

goroutine 40 [IO wait]:
internal/poll.runtime_pollWait(0x6401130, 0x72, 0xffffffffffffffff)
	/usr/local/opt/go/libexec/src/runtime/netpoll.go:184 +0x55
internal/poll.(*pollDesc).wait(0xc0004d9718, 0x72, 0xd400, 0xd41a, 0xffffffffffffffff)
	/usr/local/opt/go/libexec/src/internal/poll/fd_poll_runtime.go:87 +0x45
internal/poll.(*pollDesc).waitRead(...)
	/usr/local/opt/go/libexec/src/internal/poll/fd_poll_runtime.go:92
internal/poll.(*FD).Read(0xc0004d9700, 0xc000724000, 0xd41a, 0xd41a, 0x0, 0x0, 0x0)
	/usr/local/opt/go/libexec/src/internal/poll/fd_unix.go:169 +0x22b
net.(*netFD).Read(0xc0004d9700, 0xc000724000, 0xd41a, 0xd41a, 0x203000, 0x100e256, 0xc0001c9900)
	/usr/local/opt/go/libexec/src/net/fd_unix.go:202 +0x4f
net.(*conn).Read(0xc0000e81d0, 0xc000724000, 0xd41a, 0xd41a, 0x0, 0x0, 0x0)
	/usr/local/opt/go/libexec/src/net/net.go:184 +0x68
crypto/tls.(*atLeastReader).Read(0xc000622c60, 0xc000724000, 0xd41a, 0xd41a, 0x50, 0xc0001c9900, 0xc0006b3970)
	/usr/local/opt/go/libexec/src/crypto/tls/conn.go:780 +0x60
bytes.(*Buffer).ReadFrom(0xc00043a258, 0x2397da0, 0xc000622c60, 0x100c165, 0x1ff03e0, 0x21438a0)
	/usr/local/opt/go/libexec/src/bytes/buffer.go:204 +0xb4
crypto/tls.(*Conn).readFromUntil(0xc00043a000, 0x6401200, 0xc0000e81d0, 0x5, 0xc0000e81d0, 0xc000a798d0)
	/usr/local/opt/go/libexec/src/crypto/tls/conn.go:802 +0xec
crypto/tls.(*Conn).readRecordOrCCS(0xc00043a000, 0x0, 0x0, 0x103a3de)
	/usr/local/opt/go/libexec/src/crypto/tls/conn.go:609 +0x124
crypto/tls.(*Conn).readRecord(...)
	/usr/local/opt/go/libexec/src/crypto/tls/conn.go:577
crypto/tls.(*Conn).Read(0xc00043a000, 0xc000644000, 0x1000, 0x1000, 0x0, 0x0, 0x0)
	/usr/local/opt/go/libexec/src/crypto/tls/conn.go:1255 +0x161
bufio.(*Reader).Read(0xc000305c20, 0xc0005dc118, 0x9, 0x9, 0xc0005007e0, 0xc0006b3dd8, 0xc0006b3cf0)
	/usr/local/opt/go/libexec/src/bufio/bufio.go:226 +0x26a
io.ReadAtLeast(0x2397c00, 0xc000305c20, 0xc0005dc118, 0x9, 0x9, 0x9, 0x1006d35, 0xc0000b10e0, 0xc0006b3dd8)
	/usr/local/opt/go/libexec/src/io/io.go:310 +0x87
io.ReadFull(...)
	/usr/local/opt/go/libexec/src/io/io.go:329
volcano.sh/volcano/vendor/golang.org/x/net/http2.readFrameHeader(0xc0005dc118, 0x9, 0x9, 0x2397c00, 0xc000305c20, 0x0, 0x0, 0xc00061a030, 0x0)
	/Users/yuan.chen/GolandProjects/src/volcano.sh/volcano/vendor/golang.org/x/net/http2/frame.go:237 +0x87
volcano.sh/volcano/vendor/golang.org/x/net/http2.(*Framer).ReadFrame(0xc0005dc0e0, 0xc00061a060, 0x0, 0x0, 0x0)
	/Users/yuan.chen/GolandProjects/src/volcano.sh/volcano/vendor/golang.org/x/net/http2/frame.go:492 +0xa1
volcano.sh/volcano/vendor/golang.org/x/net/http2.(*clientConnReadLoop).run(0xc0006b3fb8, 0x1000000010000, 0x0)
	/Users/yuan.chen/GolandProjects/src/volcano.sh/volcano/vendor/golang.org/x/net/http2/transport.go:1679 +0x8c
volcano.sh/volcano/vendor/golang.org/x/net/http2.(*ClientConn).readLoop(0xc000001200)
	/Users/yuan.chen/GolandProjects/src/volcano.sh/volcano/vendor/golang.org/x/net/http2/transport.go:1607 +0xa3
created by volcano.sh/volcano/vendor/golang.org/x/net/http2.(*Transport).newClientConn
	/Users/yuan.chen/GolandProjects/src/volcano.sh/volcano/vendor/golang.org/x/net/http2/transport.go:670 +0x62f

goroutine 33 [chan receive]:
volcano.sh/volcano/vendor/k8s.io/client-go/util/workqueue.(*Type).updateUnfinishedWorkLoop(0xc000156c00)
	/Users/yuan.chen/GolandProjects/src/volcano.sh/volcano/vendor/k8s.io/client-go/util/workqueue/queue.go:198 +0xe0
created by volcano.sh/volcano/vendor/k8s.io/client-go/util/workqueue.newQueue
	/Users/yuan.chen/GolandProjects/src/volcano.sh/volcano/vendor/k8s.io/client-go/util/workqueue/queue.go:58 +0x132

goroutine 115 [chan receive]:
volcano.sh/volcano/vendor/k8s.io/client-go/util/workqueue.(*Type).updateUnfinishedWorkLoop(0xc000156d20)
	/Users/yuan.chen/GolandProjects/src/volcano.sh/volcano/vendor/k8s.io/client-go/util/workqueue/queue.go:198 +0xe0
created by volcano.sh/volcano/vendor/k8s.io/client-go/util/workqueue.newQueue
	/Users/yuan.chen/GolandProjects/src/volcano.sh/volcano/vendor/k8s.io/client-go/util/workqueue/queue.go:58 +0x132

goroutine 116 [select]:
volcano.sh/volcano/vendor/k8s.io/client-go/util/workqueue.(*delayingType).waitingLoop(0xc0002fab40)
	/Users/yuan.chen/GolandProjects/src/volcano.sh/volcano/vendor/k8s.io/client-go/util/workqueue/delaying_queue.go:206 +0x344
created by volcano.sh/volcano/vendor/k8s.io/client-go/util/workqueue.newDelayingQueue
	/Users/yuan.chen/GolandProjects/src/volcano.sh/volcano/vendor/k8s.io/client-go/util/workqueue/delaying_queue.go:54 +0x1ae

goroutine 117 [chan receive, 5 minutes]:
volcano.sh/volcano/vendor/k8s.io/apimachinery/pkg/watch.(*Broadcaster).loop(0xc00004cb80)
	/Users/yuan.chen/GolandProjects/src/volcano.sh/volcano/vendor/k8s.io/apimachinery/pkg/watch/mux.go:207 +0x66
created by volcano.sh/volcano/vendor/k8s.io/apimachinery/pkg/watch.NewBroadcaster
	/Users/yuan.chen/GolandProjects/src/volcano.sh/volcano/vendor/k8s.io/apimachinery/pkg/watch/mux.go:75 +0xcc

goroutine 118 [chan receive, 5 minutes]:
volcano.sh/volcano/vendor/k8s.io/client-go/tools/record.(*eventBroadcasterImpl).StartEventWatcher.func1(0x23a38a0, 0xc0004b12c0, 0xc0004b1260)
	/Users/yuan.chen/GolandProjects/src/volcano.sh/volcano/vendor/k8s.io/client-go/tools/record/event.go:231 +0xc5
created by volcano.sh/volcano/vendor/k8s.io/client-go/tools/record.(*eventBroadcasterImpl).StartEventWatcher
	/Users/yuan.chen/GolandProjects/src/volcano.sh/volcano/vendor/k8s.io/client-go/tools/record/event.go:229 +0x6e

goroutine 8 [IO wait, 7 minutes]:
internal/poll.runtime_pollWait(0x6400f90, 0x72, 0x0)
	/usr/local/opt/go/libexec/src/runtime/netpoll.go:184 +0x55
internal/poll.(*pollDesc).wait(0xc00017a118, 0x72, 0x0, 0x0, 0x21a2933)
	/usr/local/opt/go/libexec/src/internal/poll/fd_poll_runtime.go:87 +0x45
internal/poll.(*pollDesc).waitRead(...)
	/usr/local/opt/go/libexec/src/internal/poll/fd_poll_runtime.go:92
internal/poll.(*FD).Accept(0xc00017a100, 0x0, 0x0, 0x0, 0x0, 0x0, 0x0, 0x0)
	/usr/local/opt/go/libexec/src/internal/poll/fd_unix.go:384 +0x1f8
net.(*netFD).accept(0xc00017a100, 0xc00007fd40, 0xc000072c00, 0x33916d0)
	/usr/local/opt/go/libexec/src/net/fd_unix.go:238 +0x42
net.(*TCPListener).accept(0xc00000e880, 0xc00007fd70, 0x100eac8, 0x30)
	/usr/local/opt/go/libexec/src/net/tcpsock_posix.go:139 +0x32
net.(*TCPListener).Accept(0xc00000e880, 0x20c6980, 0xc000538c30, 0x1fb6ee0, 0x2ee59d0)
	/usr/local/opt/go/libexec/src/net/tcpsock.go:261 +0x47
net/http.(*Server).Serve(0xc000282000, 0x23c27e0, 0xc00000e880, 0x0, 0x0)
	/usr/local/opt/go/libexec/src/net/http/server.go:2896 +0x286
net/http.(*Server).ListenAndServe(0xc000282000, 0xc000282000, 0x8)
	/usr/local/opt/go/libexec/src/net/http/server.go:2825 +0xb7
net/http.ListenAndServe(...)
	/usr/local/opt/go/libexec/src/net/http/server.go:3080
volcano.sh/volcano/cmd/scheduler/app.Run.func1(0xc0000b5380)
	/Users/yuan.chen/GolandProjects/src/volcano.sh/volcano/cmd/scheduler/app/server.go:98 +0xd1
created by volcano.sh/volcano/cmd/scheduler/app.Run
	/Users/yuan.chen/GolandProjects/src/volcano.sh/volcano/cmd/scheduler/app/server.go:96 +0x11e

goroutine 142 [chan receive, 7 minutes]:
volcano.sh/volcano/vendor/k8s.io/client-go/tools/cache.(*processorListener).run.func1.1(0x2f05740, 0x371ad80, 0xc000165598)
	/Users/yuan.chen/GolandProjects/src/volcano.sh/volcano/vendor/k8s.io/client-go/tools/cache/shared_informer.go:549 +0x54
volcano.sh/volcano/vendor/k8s.io/apimachinery/pkg/util/wait.ExponentialBackoff(0x989680, 0x3ff0000000000000, 0x3fb999999999999a, 0x5, 0xc00073ddd8, 0x1f67e20, 0x1)
	/Users/yuan.chen/GolandProjects/src/volcano.sh/volcano/vendor/k8s.io/apimachinery/pkg/util/wait/wait.go:203 +0xde
volcano.sh/volcano/vendor/k8s.io/client-go/tools/cache.(*processorListener).run.func1()
	/Users/yuan.chen/GolandProjects/src/volcano.sh/volcano/vendor/k8s.io/client-go/tools/cache/shared_informer.go:548 +0x89
volcano.sh/volcano/vendor/k8s.io/apimachinery/pkg/util/wait.JitterUntil.func1(0xc000165740)
	/Users/yuan.chen/GolandProjects/src/volcano.sh/volcano/vendor/k8s.io/apimachinery/pkg/util/wait/wait.go:133 +0x5e
volcano.sh/volcano/vendor/k8s.io/apimachinery/pkg/util/wait.JitterUntil(0xc00073df40, 0xdf8475800, 0x0, 0x1030501, 0xc0003ae1e0)
	/Users/yuan.chen/GolandProjects/src/volcano.sh/volcano/vendor/k8s.io/apimachinery/pkg/util/wait/wait.go:134 +0xf8
volcano.sh/volcano/vendor/k8s.io/apimachinery/pkg/util/wait.Until(...)
	/Users/yuan.chen/GolandProjects/src/volcano.sh/volcano/vendor/k8s.io/apimachinery/pkg/util/wait/wait.go:88
volcano.sh/volcano/vendor/k8s.io/client-go/tools/cache.(*processorListener).run(0xc0004dc280)
	/Users/yuan.chen/GolandProjects/src/volcano.sh/volcano/vendor/k8s.io/client-go/tools/cache/shared_informer.go:546 +0x9b
volcano.sh/volcano/vendor/k8s.io/apimachinery/pkg/util/wait.(*Group).Start.func1(0xc0001c6060, 0xc0000ea7a0)
	/Users/yuan.chen/GolandProjects/src/volcano.sh/volcano/vendor/k8s.io/apimachinery/pkg/util/wait/wait.go:71 +0x59
created by volcano.sh/volcano/vendor/k8s.io/apimachinery/pkg/util/wait.(*Group).Start
	/Users/yuan.chen/GolandProjects/src/volcano.sh/volcano/vendor/k8s.io/apimachinery/pkg/util/wait/wait.go:69 +0x62

goroutine 140 [chan receive, 7 minutes]:
volcano.sh/volcano/vendor/k8s.io/client-go/tools/cache.(*processorListener).run.func1.1(0x0, 0x0, 0x0)
	/Users/yuan.chen/GolandProjects/src/volcano.sh/volcano/vendor/k8s.io/client-go/tools/cache/shared_informer.go:549 +0x54
volcano.sh/volcano/vendor/k8s.io/apimachinery/pkg/util/wait.ExponentialBackoff(0x989680, 0x3ff0000000000000, 0x3fb999999999999a, 0x5, 0xc00007edd8, 0x101984e, 0x3715668)
	/Users/yuan.chen/GolandProjects/src/volcano.sh/volcano/vendor/k8s.io/apimachinery/pkg/util/wait/wait.go:203 +0xde
volcano.sh/volcano/vendor/k8s.io/client-go/tools/cache.(*processorListener).run.func1()
	/Users/yuan.chen/GolandProjects/src/volcano.sh/volcano/vendor/k8s.io/client-go/tools/cache/shared_informer.go:548 +0x89
volcano.sh/volcano/vendor/k8s.io/apimachinery/pkg/util/wait.JitterUntil.func1(0xc00035f740)
	/Users/yuan.chen/GolandProjects/src/volcano.sh/volcano/vendor/k8s.io/apimachinery/pkg/util/wait/wait.go:133 +0x5e
volcano.sh/volcano/vendor/k8s.io/apimachinery/pkg/util/wait.JitterUntil(0xc00007ef40, 0xdf8475800, 0x0, 0x1030501, 0xc00070e660)
	/Users/yuan.chen/GolandProjects/src/volcano.sh/volcano/vendor/k8s.io/apimachinery/pkg/util/wait/wait.go:134 +0xf8
volcano.sh/volcano/vendor/k8s.io/apimachinery/pkg/util/wait.Until(...)
	/Users/yuan.chen/GolandProjects/src/volcano.sh/volcano/vendor/k8s.io/apimachinery/pkg/util/wait/wait.go:88
volcano.sh/volcano/vendor/k8s.io/client-go/tools/cache.(*processorListener).run(0xc0004dc500)
	/Users/yuan.chen/GolandProjects/src/volcano.sh/volcano/vendor/k8s.io/client-go/tools/cache/shared_informer.go:546 +0x9b
volcano.sh/volcano/vendor/k8s.io/apimachinery/pkg/util/wait.(*Group).Start.func1(0xc0001c61b0, 0xc0000ea780)
	/Users/yuan.chen/GolandProjects/src/volcano.sh/volcano/vendor/k8s.io/apimachinery/pkg/util/wait/wait.go:71 +0x59
created by volcano.sh/volcano/vendor/k8s.io/apimachinery/pkg/util/wait.(*Group).Start
	/Users/yuan.chen/GolandProjects/src/volcano.sh/volcano/vendor/k8s.io/apimachinery/pkg/util/wait/wait.go:69 +0x62

goroutine 72 [select]:
volcano.sh/volcano/vendor/k8s.io/apimachinery/pkg/util/wait.poller.func1.1(0xc0000c20c0, 0x5f5e100, 0x0, 0x0)
	/Users/yuan.chen/GolandProjects/src/volcano.sh/volcano/vendor/k8s.io/apimachinery/pkg/util/wait/wait.go:374 +0x18e
created by volcano.sh/volcano/vendor/k8s.io/apimachinery/pkg/util/wait.poller.func1
	/Users/yuan.chen/GolandProjects/src/volcano.sh/volcano/vendor/k8s.io/apimachinery/pkg/util/wait/wait.go:357 +0x8c

goroutine 9 [sync.Cond.Wait, 7 minutes]:
runtime.goparkunlock(...)
	/usr/local/opt/go/libexec/src/runtime/proc.go:310
sync.runtime_notifyListWait(0xc0001d8188, 0x0)
	/usr/local/opt/go/libexec/src/runtime/sema.go:510 +0xf8
sync.(*Cond).Wait(0xc0001d8178)
	/usr/local/opt/go/libexec/src/sync/cond.go:56 +0x9d
volcano.sh/volcano/vendor/k8s.io/client-go/tools/cache.(*DeltaFIFO).Pop(0xc0001d8160, 0xc000582070, 0x0, 0x0, 0x0, 0x0)
	/Users/yuan.chen/GolandProjects/src/volcano.sh/volcano/vendor/k8s.io/client-go/tools/cache/delta_fifo.go:423 +0xa6
volcano.sh/volcano/vendor/k8s.io/client-go/tools/cache.(*controller).processLoop(0xc00017bc80)
	/Users/yuan.chen/GolandProjects/src/volcano.sh/volcano/vendor/k8s.io/client-go/tools/cache/controller.go:150 +0x40
volcano.sh/volcano/vendor/k8s.io/apimachinery/pkg/util/wait.JitterUntil.func1(0xc000083e00)
	/Users/yuan.chen/GolandProjects/src/volcano.sh/volcano/vendor/k8s.io/apimachinery/pkg/util/wait/wait.go:133 +0x5e
volcano.sh/volcano/vendor/k8s.io/apimachinery/pkg/util/wait.JitterUntil(0xc000083e00, 0x3b9aca00, 0x0, 0xc00019c301, 0x0)
	/Users/yuan.chen/GolandProjects/src/volcano.sh/volcano/vendor/k8s.io/apimachinery/pkg/util/wait/wait.go:134 +0xf8
volcano.sh/volcano/vendor/k8s.io/apimachinery/pkg/util/wait.Until(...)
	/Users/yuan.chen/GolandProjects/src/volcano.sh/volcano/vendor/k8s.io/apimachinery/pkg/util/wait/wait.go:88
volcano.sh/volcano/vendor/k8s.io/client-go/tools/cache.(*controller).Run(0xc00017bc80, 0x0)
	/Users/yuan.chen/GolandProjects/src/volcano.sh/volcano/vendor/k8s.io/client-go/tools/cache/controller.go:124 +0x2fd
volcano.sh/volcano/vendor/k8s.io/client-go/tools/cache.(*sharedIndexInformer).Run(0xc000708090, 0x0)
	/Users/yuan.chen/GolandProjects/src/volcano.sh/volcano/vendor/k8s.io/client-go/tools/cache/shared_informer.go:227 +0x47f
created by volcano.sh/volcano/pkg/scheduler/cache.(*SchedulerCache).Run
	/Users/yuan.chen/GolandProjects/src/volcano.sh/volcano/pkg/scheduler/cache/cache.go:434 +0x5e

goroutine 10 [sync.Cond.Wait, 5 minutes]:
runtime.goparkunlock(...)
	/usr/local/opt/go/libexec/src/runtime/proc.go:310
sync.runtime_notifyListWait(0xc000346188, 0xd)
	/usr/local/opt/go/libexec/src/runtime/sema.go:510 +0xf8
sync.(*Cond).Wait(0xc000346178)
	/usr/local/opt/go/libexec/src/sync/cond.go:56 +0x9d
volcano.sh/volcano/vendor/k8s.io/client-go/tools/cache.(*DeltaFIFO).Pop(0xc000346160, 0xc0000cccf0, 0x0, 0x0, 0x0, 0x0)
	/Users/yuan.chen/GolandProjects/src/volcano.sh/volcano/vendor/k8s.io/client-go/tools/cache/delta_fifo.go:423 +0xa6
volcano.sh/volcano/vendor/k8s.io/client-go/tools/cache.(*controller).processLoop(0xc0002db780)
	/Users/yuan.chen/GolandProjects/src/volcano.sh/volcano/vendor/k8s.io/client-go/tools/cache/controller.go:150 +0x40
volcano.sh/volcano/vendor/k8s.io/apimachinery/pkg/util/wait.JitterUntil.func1(0xc0005bae00)
	/Users/yuan.chen/GolandProjects/src/volcano.sh/volcano/vendor/k8s.io/apimachinery/pkg/util/wait/wait.go:133 +0x5e
volcano.sh/volcano/vendor/k8s.io/apimachinery/pkg/util/wait.JitterUntil(0xc0005bae00, 0x3b9aca00, 0x0, 0xc00043aa01, 0x0)
	/Users/yuan.chen/GolandProjects/src/volcano.sh/volcano/vendor/k8s.io/apimachinery/pkg/util/wait/wait.go:134 +0xf8
volcano.sh/volcano/vendor/k8s.io/apimachinery/pkg/util/wait.Until(...)
	/Users/yuan.chen/GolandProjects/src/volcano.sh/volcano/vendor/k8s.io/apimachinery/pkg/util/wait/wait.go:88
volcano.sh/volcano/vendor/k8s.io/client-go/tools/cache.(*controller).Run(0xc0002db780, 0x0)
	/Users/yuan.chen/GolandProjects/src/volcano.sh/volcano/vendor/k8s.io/client-go/tools/cache/controller.go:124 +0x2fd
volcano.sh/volcano/vendor/k8s.io/client-go/tools/cache.(*sharedIndexInformer).Run(0xc000708000, 0x0)
	/Users/yuan.chen/GolandProjects/src/volcano.sh/volcano/vendor/k8s.io/client-go/tools/cache/shared_informer.go:227 +0x47f
created by volcano.sh/volcano/pkg/scheduler/cache.(*SchedulerCache).Run
	/Users/yuan.chen/GolandProjects/src/volcano.sh/volcano/pkg/scheduler/cache/cache.go:435 +0x9b

goroutine 11 [sync.Cond.Wait]:
runtime.goparkunlock(...)
	/usr/local/opt/go/libexec/src/runtime/proc.go:310
sync.runtime_notifyListWait(0xc0001d8028, 0x8)
	/usr/local/opt/go/libexec/src/runtime/sema.go:510 +0xf8
sync.(*Cond).Wait(0xc0001d8018)
	/usr/local/opt/go/libexec/src/sync/cond.go:56 +0x9d
volcano.sh/volcano/vendor/k8s.io/client-go/tools/cache.(*DeltaFIFO).Pop(0xc0001d8000, 0xc0003be340, 0x0, 0x0, 0x0, 0x0)
	/Users/yuan.chen/GolandProjects/src/volcano.sh/volcano/vendor/k8s.io/client-go/tools/cache/delta_fifo.go:423 +0xa6
volcano.sh/volcano/vendor/k8s.io/client-go/tools/cache.(*controller).processLoop(0xc00017a700)
	/Users/yuan.chen/GolandProjects/src/volcano.sh/volcano/vendor/k8s.io/client-go/tools/cache/controller.go:150 +0x40
volcano.sh/volcano/vendor/k8s.io/apimachinery/pkg/util/wait.JitterUntil.func1(0xc000082e00)
	/Users/yuan.chen/GolandProjects/src/volcano.sh/volcano/vendor/k8s.io/apimachinery/pkg/util/wait/wait.go:133 +0x5e
volcano.sh/volcano/vendor/k8s.io/apimachinery/pkg/util/wait.JitterUntil(0xc000082e00, 0x3b9aca00, 0x0, 0xc0001ce201, 0x0)
	/Users/yuan.chen/GolandProjects/src/volcano.sh/volcano/vendor/k8s.io/apimachinery/pkg/util/wait/wait.go:134 +0xf8
volcano.sh/volcano/vendor/k8s.io/apimachinery/pkg/util/wait.Until(...)
	/Users/yuan.chen/GolandProjects/src/volcano.sh/volcano/vendor/k8s.io/apimachinery/pkg/util/wait/wait.go:88
volcano.sh/volcano/vendor/k8s.io/client-go/tools/cache.(*controller).Run(0xc00017a700, 0x0)
	/Users/yuan.chen/GolandProjects/src/volcano.sh/volcano/vendor/k8s.io/client-go/tools/cache/controller.go:124 +0x2fd
volcano.sh/volcano/vendor/k8s.io/client-go/tools/cache.(*sharedIndexInformer).Run(0xc0000fc510, 0x0)
	/Users/yuan.chen/GolandProjects/src/volcano.sh/volcano/vendor/k8s.io/client-go/tools/cache/shared_informer.go:227 +0x47f
created by volcano.sh/volcano/pkg/scheduler/cache.(*SchedulerCache).Run
	/Users/yuan.chen/GolandProjects/src/volcano.sh/volcano/pkg/scheduler/cache/cache.go:436 +0xd8

goroutine 12 [sync.Cond.Wait, 5 minutes]:
runtime.goparkunlock(...)
	/usr/local/opt/go/libexec/src/runtime/proc.go:310
sync.runtime_notifyListWait(0xc00018e398, 0x25)
	/usr/local/opt/go/libexec/src/runtime/sema.go:510 +0xf8
sync.(*Cond).Wait(0xc00018e388)
	/usr/local/opt/go/libexec/src/sync/cond.go:56 +0x9d
volcano.sh/volcano/vendor/k8s.io/client-go/tools/cache.(*DeltaFIFO).Pop(0xc00018e370, 0xc0000ff000, 0x0, 0x0, 0x0, 0x0)
	/Users/yuan.chen/GolandProjects/src/volcano.sh/volcano/vendor/k8s.io/client-go/tools/cache/delta_fifo.go:423 +0xa6
volcano.sh/volcano/vendor/k8s.io/client-go/tools/cache.(*controller).processLoop(0xc000641180)
	/Users/yuan.chen/GolandProjects/src/volcano.sh/volcano/vendor/k8s.io/client-go/tools/cache/controller.go:150 +0x40
volcano.sh/volcano/vendor/k8s.io/apimachinery/pkg/util/wait.JitterUntil.func1(0xc000398e00)
	/Users/yuan.chen/GolandProjects/src/volcano.sh/volcano/vendor/k8s.io/apimachinery/pkg/util/wait/wait.go:133 +0x5e
volcano.sh/volcano/vendor/k8s.io/apimachinery/pkg/util/wait.JitterUntil(0xc000398e00, 0x3b9aca00, 0x0, 0xc0004f4701, 0x0)
	/Users/yuan.chen/GolandProjects/src/volcano.sh/volcano/vendor/k8s.io/apimachinery/pkg/util/wait/wait.go:134 +0xf8
volcano.sh/volcano/vendor/k8s.io/apimachinery/pkg/util/wait.Until(...)
	/Users/yuan.chen/GolandProjects/src/volcano.sh/volcano/vendor/k8s.io/apimachinery/pkg/util/wait/wait.go:88
volcano.sh/volcano/vendor/k8s.io/client-go/tools/cache.(*controller).Run(0xc000641180, 0x0)
	/Users/yuan.chen/GolandProjects/src/volcano.sh/volcano/vendor/k8s.io/client-go/tools/cache/controller.go:124 +0x2fd
volcano.sh/volcano/vendor/k8s.io/client-go/tools/cache.(*sharedIndexInformer).Run(0xc000708240, 0x0)
	/Users/yuan.chen/GolandProjects/src/volcano.sh/volcano/vendor/k8s.io/client-go/tools/cache/shared_informer.go:227 +0x47f
created by volcano.sh/volcano/pkg/scheduler/cache.(*SchedulerCache).Run
	/Users/yuan.chen/GolandProjects/src/volcano.sh/volcano/pkg/scheduler/cache/cache.go:437 +0x118

goroutine 13 [sync.Cond.Wait, 7 minutes]:
runtime.goparkunlock(...)
	/usr/local/opt/go/libexec/src/runtime/proc.go:310
sync.runtime_notifyListWait(0xc000012188, 0x0)
	/usr/local/opt/go/libexec/src/runtime/sema.go:510 +0xf8
sync.(*Cond).Wait(0xc000012178)
	/usr/local/opt/go/libexec/src/sync/cond.go:56 +0x9d
volcano.sh/volcano/vendor/k8s.io/client-go/tools/cache.(*DeltaFIFO).Pop(0xc000012160, 0xc0000843d0, 0x0, 0x0, 0x0, 0x0)
	/Users/yuan.chen/GolandProjects/src/volcano.sh/volcano/vendor/k8s.io/client-go/tools/cache/delta_fifo.go:423 +0xa6
volcano.sh/volcano/vendor/k8s.io/client-go/tools/cache.(*controller).processLoop(0xc0004d8600)
	/Users/yuan.chen/GolandProjects/src/volcano.sh/volcano/vendor/k8s.io/client-go/tools/cache/controller.go:150 +0x40
volcano.sh/volcano/vendor/k8s.io/apimachinery/pkg/util/wait.JitterUntil.func1(0xc0005bbe00)
	/Users/yuan.chen/GolandProjects/src/volcano.sh/volcano/vendor/k8s.io/apimachinery/pkg/util/wait/wait.go:133 +0x5e
volcano.sh/volcano/vendor/k8s.io/apimachinery/pkg/util/wait.JitterUntil(0xc0005bbe00, 0x3b9aca00, 0x0, 0xc0004f4a01, 0x0)
	/Users/yuan.chen/GolandProjects/src/volcano.sh/volcano/vendor/k8s.io/apimachinery/pkg/util/wait/wait.go:134 +0xf8
volcano.sh/volcano/vendor/k8s.io/apimachinery/pkg/util/wait.Until(...)
	/Users/yuan.chen/GolandProjects/src/volcano.sh/volcano/vendor/k8s.io/apimachinery/pkg/util/wait/wait.go:88
volcano.sh/volcano/vendor/k8s.io/client-go/tools/cache.(*controller).Run(0xc0004d8600, 0x0)
	/Users/yuan.chen/GolandProjects/src/volcano.sh/volcano/vendor/k8s.io/client-go/tools/cache/controller.go:124 +0x2fd
volcano.sh/volcano/vendor/k8s.io/client-go/tools/cache.(*sharedIndexInformer).Run(0xc0007082d0, 0x0)
	/Users/yuan.chen/GolandProjects/src/volcano.sh/volcano/vendor/k8s.io/client-go/tools/cache/shared_informer.go:227 +0x47f
created by volcano.sh/volcano/pkg/scheduler/cache.(*SchedulerCache).Run
	/Users/yuan.chen/GolandProjects/src/volcano.sh/volcano/pkg/scheduler/cache/cache.go:438 +0x15b

goroutine 14 [sync.Cond.Wait, 7 minutes]:
runtime.goparkunlock(...)
	/usr/local/opt/go/libexec/src/runtime/proc.go:310
sync.runtime_notifyListWait(0xc00018e188, 0x0)
	/usr/local/opt/go/libexec/src/runtime/sema.go:510 +0xf8
sync.(*Cond).Wait(0xc00018e178)
	/usr/local/opt/go/libexec/src/sync/cond.go:56 +0x9d
volcano.sh/volcano/vendor/k8s.io/client-go/tools/cache.(*DeltaFIFO).Pop(0xc00018e160, 0xc0000fec20, 0x0, 0x0, 0x0, 0x0)
	/Users/yuan.chen/GolandProjects/src/volcano.sh/volcano/vendor/k8s.io/client-go/tools/cache/delta_fifo.go:423 +0xa6
volcano.sh/volcano/vendor/k8s.io/client-go/tools/cache.(*controller).processLoop(0xc000640780)
	/Users/yuan.chen/GolandProjects/src/volcano.sh/volcano/vendor/k8s.io/client-go/tools/cache/controller.go:150 +0x40
volcano.sh/volcano/vendor/k8s.io/apimachinery/pkg/util/wait.JitterUntil.func1(0xc000397e00)
	/Users/yuan.chen/GolandProjects/src/volcano.sh/volcano/vendor/k8s.io/apimachinery/pkg/util/wait/wait.go:133 +0x5e
volcano.sh/volcano/vendor/k8s.io/apimachinery/pkg/util/wait.JitterUntil(0xc000397e00, 0x3b9aca00, 0x0, 0xc0001cd901, 0x0)
	/Users/yuan.chen/GolandProjects/src/volcano.sh/volcano/vendor/k8s.io/apimachinery/pkg/util/wait/wait.go:134 +0xf8
volcano.sh/volcano/vendor/k8s.io/apimachinery/pkg/util/wait.Until(...)
	/Users/yuan.chen/GolandProjects/src/volcano.sh/volcano/vendor/k8s.io/apimachinery/pkg/util/wait/wait.go:88
volcano.sh/volcano/vendor/k8s.io/client-go/tools/cache.(*controller).Run(0xc000640780, 0x0)
	/Users/yuan.chen/GolandProjects/src/volcano.sh/volcano/vendor/k8s.io/client-go/tools/cache/controller.go:124 +0x2fd
volcano.sh/volcano/vendor/k8s.io/client-go/tools/cache.(*sharedIndexInformer).Run(0xc0000fc480, 0x0)
	/Users/yuan.chen/GolandProjects/src/volcano.sh/volcano/vendor/k8s.io/client-go/tools/cache/shared_informer.go:227 +0x47f
created by volcano.sh/volcano/pkg/scheduler/cache.(*SchedulerCache).Run
	/Users/yuan.chen/GolandProjects/src/volcano.sh/volcano/pkg/scheduler/cache/cache.go:439 +0x19e

goroutine 15 [sync.Cond.Wait, 7 minutes]:
runtime.goparkunlock(...)
	/usr/local/opt/go/libexec/src/runtime/proc.go:310
sync.runtime_notifyListWait(0xc000346028, 0x0)
	/usr/local/opt/go/libexec/src/runtime/sema.go:510 +0xf8
sync.(*Cond).Wait(0xc000346018)
	/usr/local/opt/go/libexec/src/sync/cond.go:56 +0x9d
volcano.sh/volcano/vendor/k8s.io/client-go/tools/cache.(*DeltaFIFO).Pop(0xc000346000, 0xc0000cca10, 0x0, 0x0, 0x0, 0x0)
	/Users/yuan.chen/GolandProjects/src/volcano.sh/volcano/vendor/k8s.io/client-go/tools/cache/delta_fifo.go:423 +0xa6
volcano.sh/volcano/vendor/k8s.io/client-go/tools/cache.(*controller).processLoop(0xc0002da000)
	/Users/yuan.chen/GolandProjects/src/volcano.sh/volcano/vendor/k8s.io/client-go/tools/cache/controller.go:150 +0x40
volcano.sh/volcano/vendor/k8s.io/apimachinery/pkg/util/wait.JitterUntil.func1(0xc00058be00)
	/Users/yuan.chen/GolandProjects/src/volcano.sh/volcano/vendor/k8s.io/apimachinery/pkg/util/wait/wait.go:133 +0x5e
volcano.sh/volcano/vendor/k8s.io/apimachinery/pkg/util/wait.JitterUntil(0xc00058be00, 0x3b9aca00, 0x0, 0xc0001d6801, 0x0)
	/Users/yuan.chen/GolandProjects/src/volcano.sh/volcano/vendor/k8s.io/apimachinery/pkg/util/wait/wait.go:134 +0xf8
volcano.sh/volcano/vendor/k8s.io/apimachinery/pkg/util/wait.Until(...)
	/Users/yuan.chen/GolandProjects/src/volcano.sh/volcano/vendor/k8s.io/apimachinery/pkg/util/wait/wait.go:88
volcano.sh/volcano/vendor/k8s.io/client-go/tools/cache.(*controller).Run(0xc0002da000, 0x0)
	/Users/yuan.chen/GolandProjects/src/volcano.sh/volcano/vendor/k8s.io/client-go/tools/cache/controller.go:124 +0x2fd
volcano.sh/volcano/vendor/k8s.io/client-go/tools/cache.(*sharedIndexInformer).Run(0xc0000fc3f0, 0x0)
	/Users/yuan.chen/GolandProjects/src/volcano.sh/volcano/vendor/k8s.io/client-go/tools/cache/shared_informer.go:227 +0x47f
created by volcano.sh/volcano/pkg/scheduler/cache.(*SchedulerCache).Run
	/Users/yuan.chen/GolandProjects/src/volcano.sh/volcano/pkg/scheduler/cache/cache.go:440 +0x1e1

goroutine 16 [sync.Cond.Wait, 7 minutes]:
runtime.goparkunlock(...)
	/usr/local/opt/go/libexec/src/runtime/proc.go:310
sync.runtime_notifyListWait(0xc000012028, 0x1)
	/usr/local/opt/go/libexec/src/runtime/sema.go:510 +0xf8
sync.(*Cond).Wait(0xc000012018)
	/usr/local/opt/go/libexec/src/sync/cond.go:56 +0x9d
volcano.sh/volcano/vendor/k8s.io/client-go/tools/cache.(*DeltaFIFO).Pop(0xc000012000, 0xc000084080, 0x0, 0x0, 0x0, 0x0)
	/Users/yuan.chen/GolandProjects/src/volcano.sh/volcano/vendor/k8s.io/client-go/tools/cache/delta_fifo.go:423 +0xa6
volcano.sh/volcano/vendor/k8s.io/client-go/tools/cache.(*controller).processLoop(0xc000422480)
	/Users/yuan.chen/GolandProjects/src/volcano.sh/volcano/vendor/k8s.io/client-go/tools/cache/controller.go:150 +0x40
volcano.sh/volcano/vendor/k8s.io/apimachinery/pkg/util/wait.JitterUntil.func1(0xc000393e00)
	/Users/yuan.chen/GolandProjects/src/volcano.sh/volcano/vendor/k8s.io/apimachinery/pkg/util/wait/wait.go:133 +0x5e
volcano.sh/volcano/vendor/k8s.io/apimachinery/pkg/util/wait.JitterUntil(0xc000393e00, 0x3b9aca00, 0x0, 0xc0002b4101, 0x0)
	/Users/yuan.chen/GolandProjects/src/volcano.sh/volcano/vendor/k8s.io/apimachinery/pkg/util/wait/wait.go:134 +0xf8
volcano.sh/volcano/vendor/k8s.io/apimachinery/pkg/util/wait.Until(...)
	/Users/yuan.chen/GolandProjects/src/volcano.sh/volcano/vendor/k8s.io/apimachinery/pkg/util/wait/wait.go:88
volcano.sh/volcano/vendor/k8s.io/client-go/tools/cache.(*controller).Run(0xc000422480, 0x0)
	/Users/yuan.chen/GolandProjects/src/volcano.sh/volcano/vendor/k8s.io/client-go/tools/cache/controller.go:124 +0x2fd
volcano.sh/volcano/vendor/k8s.io/client-go/tools/cache.(*sharedIndexInformer).Run(0xc0000fc360, 0x0)
	/Users/yuan.chen/GolandProjects/src/volcano.sh/volcano/vendor/k8s.io/client-go/tools/cache/shared_informer.go:227 +0x47f
created by volcano.sh/volcano/pkg/scheduler/cache.(*SchedulerCache).Run
	/Users/yuan.chen/GolandProjects/src/volcano.sh/volcano/pkg/scheduler/cache/cache.go:441 +0x224

goroutine 130 [sync.Cond.Wait, 7 minutes]:
runtime.goparkunlock(...)
	/usr/local/opt/go/libexec/src/runtime/proc.go:310
sync.runtime_notifyListWait(0xc0003a6028, 0x1)
	/usr/local/opt/go/libexec/src/runtime/sema.go:510 +0xf8
sync.(*Cond).Wait(0xc0003a6018)
	/usr/local/opt/go/libexec/src/sync/cond.go:56 +0x9d
volcano.sh/volcano/vendor/k8s.io/client-go/tools/cache.(*DeltaFIFO).Pop(0xc0003a6000, 0xc00054ff90, 0x0, 0x0, 0x0, 0x0)
	/Users/yuan.chen/GolandProjects/src/volcano.sh/volcano/vendor/k8s.io/client-go/tools/cache/delta_fifo.go:423 +0xa6
volcano.sh/volcano/vendor/k8s.io/client-go/tools/cache.(*controller).processLoop(0xc000504280)
	/Users/yuan.chen/GolandProjects/src/volcano.sh/volcano/vendor/k8s.io/client-go/tools/cache/controller.go:150 +0x40
volcano.sh/volcano/vendor/k8s.io/apimachinery/pkg/util/wait.JitterUntil.func1(0xc0005bfe00)
	/Users/yuan.chen/GolandProjects/src/volcano.sh/volcano/vendor/k8s.io/apimachinery/pkg/util/wait/wait.go:133 +0x5e
volcano.sh/volcano/vendor/k8s.io/apimachinery/pkg/util/wait.JitterUntil(0xc0005bfe00, 0x3b9aca00, 0x0, 0xc00019ca01, 0x0)
	/Users/yuan.chen/GolandProjects/src/volcano.sh/volcano/vendor/k8s.io/apimachinery/pkg/util/wait/wait.go:134 +0xf8
volcano.sh/volcano/vendor/k8s.io/apimachinery/pkg/util/wait.Until(...)
	/Users/yuan.chen/GolandProjects/src/volcano.sh/volcano/vendor/k8s.io/apimachinery/pkg/util/wait/wait.go:88
volcano.sh/volcano/vendor/k8s.io/client-go/tools/cache.(*controller).Run(0xc000504280, 0x0)
	/Users/yuan.chen/GolandProjects/src/volcano.sh/volcano/vendor/k8s.io/client-go/tools/cache/controller.go:124 +0x2fd
volcano.sh/volcano/vendor/k8s.io/client-go/tools/cache.(*sharedIndexInformer).Run(0xc000708360, 0x0)
	/Users/yuan.chen/GolandProjects/src/volcano.sh/volcano/vendor/k8s.io/client-go/tools/cache/shared_informer.go:227 +0x47f
created by volcano.sh/volcano/pkg/scheduler/cache.(*SchedulerCache).Run
	/Users/yuan.chen/GolandProjects/src/volcano.sh/volcano/pkg/scheduler/cache/cache.go:442 +0x267

goroutine 131 [sync.Cond.Wait, 7 minutes]:
runtime.goparkunlock(...)
	/usr/local/opt/go/libexec/src/runtime/proc.go:310
sync.runtime_notifyListWait(0xc000134398, 0x1)
	/usr/local/opt/go/libexec/src/runtime/sema.go:510 +0xf8
sync.(*Cond).Wait(0xc000134388)
	/usr/local/opt/go/libexec/src/sync/cond.go:56 +0x9d
volcano.sh/volcano/vendor/k8s.io/client-go/tools/cache.(*DeltaFIFO).Pop(0xc000134370, 0xc0004bc140, 0x0, 0x0, 0x0, 0x0)
	/Users/yuan.chen/GolandProjects/src/volcano.sh/volcano/vendor/k8s.io/client-go/tools/cache/delta_fifo.go:423 +0xa6
volcano.sh/volcano/vendor/k8s.io/client-go/tools/cache.(*controller).processLoop(0xc0004aa080)
	/Users/yuan.chen/GolandProjects/src/volcano.sh/volcano/vendor/k8s.io/client-go/tools/cache/controller.go:150 +0x40
volcano.sh/volcano/vendor/k8s.io/apimachinery/pkg/util/wait.JitterUntil.func1(0xc0006f9e00)
	/Users/yuan.chen/GolandProjects/src/volcano.sh/volcano/vendor/k8s.io/apimachinery/pkg/util/wait/wait.go:133 +0x5e
volcano.sh/volcano/vendor/k8s.io/apimachinery/pkg/util/wait.JitterUntil(0xc0006f9e00, 0x3b9aca00, 0x0, 0xc00019cc01, 0x0)
	/Users/yuan.chen/GolandProjects/src/volcano.sh/volcano/vendor/k8s.io/apimachinery/pkg/util/wait/wait.go:134 +0xf8
volcano.sh/volcano/vendor/k8s.io/apimachinery/pkg/util/wait.Until(...)
	/Users/yuan.chen/GolandProjects/src/volcano.sh/volcano/vendor/k8s.io/apimachinery/pkg/util/wait/wait.go:88
volcano.sh/volcano/vendor/k8s.io/client-go/tools/cache.(*controller).Run(0xc0004aa080, 0x0)
	/Users/yuan.chen/GolandProjects/src/volcano.sh/volcano/vendor/k8s.io/client-go/tools/cache/controller.go:124 +0x2fd
volcano.sh/volcano/vendor/k8s.io/client-go/tools/cache.(*sharedIndexInformer).Run(0xc0007083f0, 0x0)
	/Users/yuan.chen/GolandProjects/src/volcano.sh/volcano/vendor/k8s.io/client-go/tools/cache/shared_informer.go:227 +0x47f
created by volcano.sh/volcano/pkg/scheduler/cache.(*SchedulerCache).Run
	/Users/yuan.chen/GolandProjects/src/volcano.sh/volcano/pkg/scheduler/cache/cache.go:443 +0x2aa

goroutine 132 [sync.Cond.Wait, 7 minutes]:
runtime.goparkunlock(...)
	/usr/local/opt/go/libexec/src/runtime/proc.go:310
sync.runtime_notifyListWait(0xc0001b6028, 0x0)
	/usr/local/opt/go/libexec/src/runtime/sema.go:510 +0xf8
sync.(*Cond).Wait(0xc0001b6018)
	/usr/local/opt/go/libexec/src/sync/cond.go:56 +0x9d
volcano.sh/volcano/vendor/k8s.io/client-go/tools/cache.(*DeltaFIFO).Pop(0xc0001b6000, 0xc0000ea5a0, 0x0, 0x0, 0x0, 0x0)
	/Users/yuan.chen/GolandProjects/src/volcano.sh/volcano/vendor/k8s.io/client-go/tools/cache/delta_fifo.go:423 +0xa6
volcano.sh/volcano/vendor/k8s.io/client-go/tools/cache.(*controller).processLoop(0xc0004dcb80)
	/Users/yuan.chen/GolandProjects/src/volcano.sh/volcano/vendor/k8s.io/client-go/tools/cache/controller.go:150 +0x40
volcano.sh/volcano/vendor/k8s.io/apimachinery/pkg/util/wait.JitterUntil.func1(0xc00007ce00)
	/Users/yuan.chen/GolandProjects/src/volcano.sh/volcano/vendor/k8s.io/apimachinery/pkg/util/wait/wait.go:133 +0x5e
volcano.sh/volcano/vendor/k8s.io/apimachinery/pkg/util/wait.JitterUntil(0xc00007ce00, 0x3b9aca00, 0x0, 0xc00019c701, 0x0)
	/Users/yuan.chen/GolandProjects/src/volcano.sh/volcano/vendor/k8s.io/apimachinery/pkg/util/wait/wait.go:134 +0xf8
volcano.sh/volcano/vendor/k8s.io/apimachinery/pkg/util/wait.Until(...)
	/Users/yuan.chen/GolandProjects/src/volcano.sh/volcano/vendor/k8s.io/apimachinery/pkg/util/wait/wait.go:88
volcano.sh/volcano/vendor/k8s.io/client-go/tools/cache.(*controller).Run(0xc0004dcb80, 0x0)
	/Users/yuan.chen/GolandProjects/src/volcano.sh/volcano/vendor/k8s.io/client-go/tools/cache/controller.go:124 +0x2fd
volcano.sh/volcano/vendor/k8s.io/client-go/tools/cache.(*sharedIndexInformer).Run(0xc0007081b0, 0x0)
	/Users/yuan.chen/GolandProjects/src/volcano.sh/volcano/vendor/k8s.io/client-go/tools/cache/shared_informer.go:227 +0x47f
created by volcano.sh/volcano/pkg/scheduler/cache.(*SchedulerCache).Run
	/Users/yuan.chen/GolandProjects/src/volcano.sh/volcano/pkg/scheduler/cache/cache.go:444 +0x2ed

goroutine 133 [sync.Cond.Wait, 7 minutes]:
runtime.goparkunlock(...)
	/usr/local/opt/go/libexec/src/runtime/proc.go:310
sync.runtime_notifyListWait(0xc0003ac028, 0x1)
	/usr/local/opt/go/libexec/src/runtime/sema.go:510 +0xf8
sync.(*Cond).Wait(0xc0003ac018)
	/usr/local/opt/go/libexec/src/sync/cond.go:56 +0x9d
volcano.sh/volcano/vendor/k8s.io/client-go/tools/cache.(*DeltaFIFO).Pop(0xc0003ac000, 0xc000356020, 0x0, 0x0, 0x0, 0x0)
	/Users/yuan.chen/GolandProjects/src/volcano.sh/volcano/vendor/k8s.io/client-go/tools/cache/delta_fifo.go:423 +0xa6
volcano.sh/volcano/vendor/k8s.io/client-go/tools/cache.(*controller).processLoop(0xc00017c400)
	/Users/yuan.chen/GolandProjects/src/volcano.sh/volcano/vendor/k8s.io/client-go/tools/cache/controller.go:150 +0x40
volcano.sh/volcano/vendor/k8s.io/apimachinery/pkg/util/wait.JitterUntil.func1(0xc000588e00)
	/Users/yuan.chen/GolandProjects/src/volcano.sh/volcano/vendor/k8s.io/apimachinery/pkg/util/wait/wait.go:133 +0x5e
volcano.sh/volcano/vendor/k8s.io/apimachinery/pkg/util/wait.JitterUntil(0xc000588e00, 0x3b9aca00, 0x0, 0xc000108901, 0x0)
	/Users/yuan.chen/GolandProjects/src/volcano.sh/volcano/vendor/k8s.io/apimachinery/pkg/util/wait/wait.go:134 +0xf8
volcano.sh/volcano/vendor/k8s.io/apimachinery/pkg/util/wait.Until(...)
	/Users/yuan.chen/GolandProjects/src/volcano.sh/volcano/vendor/k8s.io/apimachinery/pkg/util/wait/wait.go:88
volcano.sh/volcano/vendor/k8s.io/client-go/tools/cache.(*controller).Run(0xc00017c400, 0x0)
	/Users/yuan.chen/GolandProjects/src/volcano.sh/volcano/vendor/k8s.io/client-go/tools/cache/controller.go:124 +0x2fd
volcano.sh/volcano/vendor/k8s.io/client-go/tools/cache.(*sharedIndexInformer).Run(0xc000708120, 0x0)
	/Users/yuan.chen/GolandProjects/src/volcano.sh/volcano/vendor/k8s.io/client-go/tools/cache/shared_informer.go:227 +0x47f
created by volcano.sh/volcano/pkg/scheduler/cache.(*SchedulerCache).Run
	/Users/yuan.chen/GolandProjects/src/volcano.sh/volcano/pkg/scheduler/cache/cache.go:447 +0x443

goroutine 134 [sync.Cond.Wait, 7 minutes]:
runtime.goparkunlock(...)
	/usr/local/opt/go/libexec/src/runtime/proc.go:310
sync.runtime_notifyListWait(0xc00004cb10, 0x0)
	/usr/local/opt/go/libexec/src/runtime/sema.go:510 +0xf8
sync.(*Cond).Wait(0xc00004cb00)
	/usr/local/opt/go/libexec/src/sync/cond.go:56 +0x9d
volcano.sh/volcano/vendor/k8s.io/client-go/util/workqueue.(*Type).Get(0xc000156c00, 0x0, 0x0, 0x0)
	/Users/yuan.chen/GolandProjects/src/volcano.sh/volcano/vendor/k8s.io/client-go/util/workqueue/queue.go:145 +0xa0
volcano.sh/volcano/pkg/scheduler/cache.(*SchedulerCache).processResyncTask(0xc0001d6540)
	/Users/yuan.chen/GolandProjects/src/volcano.sh/volcano/pkg/scheduler/cache/cache.go:677 +0x4f
volcano.sh/volcano/vendor/k8s.io/apimachinery/pkg/util/wait.JitterUntil.func1(0xc0000ea560)
	/Users/yuan.chen/GolandProjects/src/volcano.sh/volcano/vendor/k8s.io/apimachinery/pkg/util/wait/wait.go:133 +0x5e
volcano.sh/volcano/vendor/k8s.io/apimachinery/pkg/util/wait.JitterUntil(0xc0000ea560, 0x0, 0x0, 0x1, 0x0)
	/Users/yuan.chen/GolandProjects/src/volcano.sh/volcano/vendor/k8s.io/apimachinery/pkg/util/wait/wait.go:134 +0xf8
volcano.sh/volcano/vendor/k8s.io/apimachinery/pkg/util/wait.Until(0xc0000ea560, 0x0, 0x0)
	/Users/yuan.chen/GolandProjects/src/volcano.sh/volcano/vendor/k8s.io/apimachinery/pkg/util/wait/wait.go:88 +0x4d
created by volcano.sh/volcano/pkg/scheduler/cache.(*SchedulerCache).Run
	/Users/yuan.chen/GolandProjects/src/volcano.sh/volcano/pkg/scheduler/cache/cache.go:451 +0x366

goroutine 135 [sync.Cond.Wait, 5 minutes]:
runtime.goparkunlock(...)
	/usr/local/opt/go/libexec/src/runtime/proc.go:310
sync.runtime_notifyListWait(0xc00004cb50, 0xc00000000a)
	/usr/local/opt/go/libexec/src/runtime/sema.go:510 +0xf8
sync.(*Cond).Wait(0xc00004cb40)
	/usr/local/opt/go/libexec/src/sync/cond.go:56 +0x9d
volcano.sh/volcano/vendor/k8s.io/client-go/util/workqueue.(*Type).Get(0xc000156d20, 0x0, 0x0, 0x2137100)
	/Users/yuan.chen/GolandProjects/src/volcano.sh/volcano/vendor/k8s.io/client-go/util/workqueue/queue.go:145 +0xa0
volcano.sh/volcano/pkg/scheduler/cache.(*SchedulerCache).processCleanupJob(0xc0001d6540)
	/Users/yuan.chen/GolandProjects/src/volcano.sh/volcano/pkg/scheduler/cache/cache.go:647 +0x52
volcano.sh/volcano/vendor/k8s.io/apimachinery/pkg/util/wait.JitterUntil.func1(0xc0000ea580)
	/Users/yuan.chen/GolandProjects/src/volcano.sh/volcano/vendor/k8s.io/apimachinery/pkg/util/wait/wait.go:133 +0x5e
volcano.sh/volcano/vendor/k8s.io/apimachinery/pkg/util/wait.JitterUntil(0xc0000ea580, 0x0, 0x0, 0x1, 0x0)
	/Users/yuan.chen/GolandProjects/src/volcano.sh/volcano/vendor/k8s.io/apimachinery/pkg/util/wait/wait.go:134 +0xf8
volcano.sh/volcano/vendor/k8s.io/apimachinery/pkg/util/wait.Until(0xc0000ea580, 0x0, 0x0)
	/Users/yuan.chen/GolandProjects/src/volcano.sh/volcano/vendor/k8s.io/apimachinery/pkg/util/wait/wait.go:88 +0x4d
created by volcano.sh/volcano/pkg/scheduler/cache.(*SchedulerCache).Run
	/Users/yuan.chen/GolandProjects/src/volcano.sh/volcano/pkg/scheduler/cache/cache.go:454 +0x3c7

goroutine 122 [chan receive, 7 minutes]:
volcano.sh/volcano/vendor/k8s.io/client-go/tools/cache.(*sharedProcessor).run(0xc0002967e0, 0xc00070a0c0)
	/Users/yuan.chen/GolandProjects/src/volcano.sh/volcano/vendor/k8s.io/client-go/tools/cache/shared_informer.go:425 +0x49
volcano.sh/volcano/vendor/k8s.io/apimachinery/pkg/util/wait.(*Group).StartWithChannel.func1()
	/Users/yuan.chen/GolandProjects/src/volcano.sh/volcano/vendor/k8s.io/apimachinery/pkg/util/wait/wait.go:54 +0x2e
volcano.sh/volcano/vendor/k8s.io/apimachinery/pkg/util/wait.(*Group).Start.func1(0xc000118140, 0xc00000e9a0)
	/Users/yuan.chen/GolandProjects/src/volcano.sh/volcano/vendor/k8s.io/apimachinery/pkg/util/wait/wait.go:71 +0x59
created by volcano.sh/volcano/vendor/k8s.io/apimachinery/pkg/util/wait.(*Group).Start
	/Users/yuan.chen/GolandProjects/src/volcano.sh/volcano/vendor/k8s.io/apimachinery/pkg/util/wait/wait.go:69 +0x62

goroutine 109 [select]:
volcano.sh/volcano/vendor/k8s.io/client-go/tools/cache.(*processorListener).pop(0xc00062b200)
	/Users/yuan.chen/GolandProjects/src/volcano.sh/volcano/vendor/k8s.io/client-go/tools/cache/shared_informer.go:517 +0x18d
volcano.sh/volcano/vendor/k8s.io/apimachinery/pkg/util/wait.(*Group).Start.func1(0xc000296840, 0xc0000cccc0)
	/Users/yuan.chen/GolandProjects/src/volcano.sh/volcano/vendor/k8s.io/apimachinery/pkg/util/wait/wait.go:71 +0x59
created by volcano.sh/volcano/vendor/k8s.io/apimachinery/pkg/util/wait.(*Group).Start
	/Users/yuan.chen/GolandProjects/src/volcano.sh/volcano/vendor/k8s.io/apimachinery/pkg/util/wait/wait.go:69 +0x62

goroutine 123 [chan receive (nil chan), 7 minutes]:
volcano.sh/volcano/vendor/k8s.io/client-go/tools/cache.(*controller).Run.func1(0x0, 0xc00017a700)
	/Users/yuan.chen/GolandProjects/src/volcano.sh/volcano/vendor/k8s.io/client-go/tools/cache/controller.go:103 +0x34
created by volcano.sh/volcano/vendor/k8s.io/client-go/tools/cache.(*controller).Run
	/Users/yuan.chen/GolandProjects/src/volcano.sh/volcano/vendor/k8s.io/client-go/tools/cache/controller.go:102 +0xae

goroutine 89 [chan receive, 5 minutes]:
volcano.sh/volcano/vendor/k8s.io/client-go/tools/cache.(*processorListener).run.func1.1(0x0, 0x0, 0x0)
	/Users/yuan.chen/GolandProjects/src/volcano.sh/volcano/vendor/k8s.io/client-go/tools/cache/shared_informer.go:549 +0x54
volcano.sh/volcano/vendor/k8s.io/apimachinery/pkg/util/wait.ExponentialBackoff(0x989680, 0x3ff0000000000000, 0x3fb999999999999a, 0x5, 0xc000b2fdd8, 0x0, 0x0)
	/Users/yuan.chen/GolandProjects/src/volcano.sh/volcano/vendor/k8s.io/apimachinery/pkg/util/wait/wait.go:203 +0xde
volcano.sh/volcano/vendor/k8s.io/client-go/tools/cache.(*processorListener).run.func1()
	/Users/yuan.chen/GolandProjects/src/volcano.sh/volcano/vendor/k8s.io/client-go/tools/cache/shared_informer.go:548 +0x89
volcano.sh/volcano/vendor/k8s.io/apimachinery/pkg/util/wait.JitterUntil.func1(0xc000660f40)
	/Users/yuan.chen/GolandProjects/src/volcano.sh/volcano/vendor/k8s.io/apimachinery/pkg/util/wait/wait.go:133 +0x5e
volcano.sh/volcano/vendor/k8s.io/apimachinery/pkg/util/wait.JitterUntil(0xc000b2ff40, 0xdf8475800, 0x0, 0x1030501, 0xc0003ae120)
	/Users/yuan.chen/GolandProjects/src/volcano.sh/volcano/vendor/k8s.io/apimachinery/pkg/util/wait/wait.go:134 +0xf8
volcano.sh/volcano/vendor/k8s.io/apimachinery/pkg/util/wait.Until(...)
	/Users/yuan.chen/GolandProjects/src/volcano.sh/volcano/vendor/k8s.io/apimachinery/pkg/util/wait/wait.go:88
volcano.sh/volcano/vendor/k8s.io/client-go/tools/cache.(*processorListener).run(0xc0004dc700)
	/Users/yuan.chen/GolandProjects/src/volcano.sh/volcano/vendor/k8s.io/client-go/tools/cache/shared_informer.go:546 +0x9b
volcano.sh/volcano/vendor/k8s.io/apimachinery/pkg/util/wait.(*Group).Start.func1(0xc0001c6220, 0xc000356230)
	/Users/yuan.chen/GolandProjects/src/volcano.sh/volcano/vendor/k8s.io/apimachinery/pkg/util/wait/wait.go:71 +0x59
created by volcano.sh/volcano/vendor/k8s.io/apimachinery/pkg/util/wait.(*Group).Start
	/Users/yuan.chen/GolandProjects/src/volcano.sh/volcano/vendor/k8s.io/apimachinery/pkg/util/wait/wait.go:69 +0x62

goroutine 74 [chan receive, 7 minutes]:
volcano.sh/volcano/vendor/k8s.io/client-go/tools/cache.(*sharedProcessor).run(0xc0001c6310, 0xc0000c2120)
	/Users/yuan.chen/GolandProjects/src/volcano.sh/volcano/vendor/k8s.io/client-go/tools/cache/shared_informer.go:425 +0x49
volcano.sh/volcano/vendor/k8s.io/apimachinery/pkg/util/wait.(*Group).StartWithChannel.func1()
	/Users/yuan.chen/GolandProjects/src/volcano.sh/volcano/vendor/k8s.io/apimachinery/pkg/util/wait/wait.go:54 +0x2e
volcano.sh/volcano/vendor/k8s.io/apimachinery/pkg/util/wait.(*Group).Start.func1(0xc0000ee030, 0xc00044c260)
	/Users/yuan.chen/GolandProjects/src/volcano.sh/volcano/vendor/k8s.io/apimachinery/pkg/util/wait/wait.go:71 +0x59
created by volcano.sh/volcano/vendor/k8s.io/apimachinery/pkg/util/wait.(*Group).Start
	/Users/yuan.chen/GolandProjects/src/volcano.sh/volcano/vendor/k8s.io/apimachinery/pkg/util/wait/wait.go:69 +0x62

goroutine 75 [chan receive (nil chan), 7 minutes]:
volcano.sh/volcano/vendor/k8s.io/client-go/tools/cache.(*controller).Run.func1(0x0, 0xc0004aa080)
	/Users/yuan.chen/GolandProjects/src/volcano.sh/volcano/vendor/k8s.io/client-go/tools/cache/controller.go:103 +0x34
created by volcano.sh/volcano/vendor/k8s.io/client-go/tools/cache.(*controller).Run
	/Users/yuan.chen/GolandProjects/src/volcano.sh/volcano/vendor/k8s.io/client-go/tools/cache/controller.go:102 +0xae

goroutine 44 [chan receive, 7 minutes]:
volcano.sh/volcano/vendor/k8s.io/client-go/tools/cache.(*sharedProcessor).run(0xc000296770, 0xc000130240)
	/Users/yuan.chen/GolandProjects/src/volcano.sh/volcano/vendor/k8s.io/client-go/tools/cache/shared_informer.go:425 +0x49
volcano.sh/volcano/vendor/k8s.io/apimachinery/pkg/util/wait.(*Group).StartWithChannel.func1()
	/Users/yuan.chen/GolandProjects/src/volcano.sh/volcano/vendor/k8s.io/apimachinery/pkg/util/wait/wait.go:54 +0x2e
volcano.sh/volcano/vendor/k8s.io/apimachinery/pkg/util/wait.(*Group).Start.func1(0xc000594070, 0xc0006223a0)
	/Users/yuan.chen/GolandProjects/src/volcano.sh/volcano/vendor/k8s.io/apimachinery/pkg/util/wait/wait.go:71 +0x59
created by volcano.sh/volcano/vendor/k8s.io/apimachinery/pkg/util/wait.(*Group).Start
	/Users/yuan.chen/GolandProjects/src/volcano.sh/volcano/vendor/k8s.io/apimachinery/pkg/util/wait/wait.go:69 +0x62

goroutine 45 [chan receive (nil chan), 7 minutes]:
volcano.sh/volcano/vendor/k8s.io/client-go/tools/cache.(*controller).Run.func1(0x0, 0xc000640780)
	/Users/yuan.chen/GolandProjects/src/volcano.sh/volcano/vendor/k8s.io/client-go/tools/cache/controller.go:103 +0x34
created by volcano.sh/volcano/vendor/k8s.io/client-go/tools/cache.(*controller).Run
	/Users/yuan.chen/GolandProjects/src/volcano.sh/volcano/vendor/k8s.io/client-go/tools/cache/controller.go:102 +0xae

goroutine 61 [chan receive, 7 minutes]:
volcano.sh/volcano/vendor/k8s.io/client-go/tools/cache.(*sharedProcessor).run(0xc000296690, 0xc000188060)
	/Users/yuan.chen/GolandProjects/src/volcano.sh/volcano/vendor/k8s.io/client-go/tools/cache/shared_informer.go:425 +0x49
volcano.sh/volcano/vendor/k8s.io/apimachinery/pkg/util/wait.(*Group).StartWithChannel.func1()
	/Users/yuan.chen/GolandProjects/src/volcano.sh/volcano/vendor/k8s.io/apimachinery/pkg/util/wait/wait.go:54 +0x2e
volcano.sh/volcano/vendor/k8s.io/apimachinery/pkg/util/wait.(*Group).Start.func1(0xc000374070, 0xc00011e3c0)
	/Users/yuan.chen/GolandProjects/src/volcano.sh/volcano/vendor/k8s.io/apimachinery/pkg/util/wait/wait.go:71 +0x59
created by volcano.sh/volcano/vendor/k8s.io/apimachinery/pkg/util/wait.(*Group).Start
	/Users/yuan.chen/GolandProjects/src/volcano.sh/volcano/vendor/k8s.io/apimachinery/pkg/util/wait/wait.go:69 +0x62

goroutine 62 [chan receive (nil chan), 7 minutes]:
volcano.sh/volcano/vendor/k8s.io/client-go/tools/cache.(*controller).Run.func1(0x0, 0xc000422480)
	/Users/yuan.chen/GolandProjects/src/volcano.sh/volcano/vendor/k8s.io/client-go/tools/cache/controller.go:103 +0x34
created by volcano.sh/volcano/vendor/k8s.io/client-go/tools/cache.(*controller).Run
	/Users/yuan.chen/GolandProjects/src/volcano.sh/volcano/vendor/k8s.io/client-go/tools/cache/controller.go:102 +0xae

goroutine 137 [chan receive, 7 minutes]:
volcano.sh/volcano/vendor/k8s.io/client-go/tools/cache.(*sharedProcessor).run(0xc0001c6150, 0xc00070e600)
	/Users/yuan.chen/GolandProjects/src/volcano.sh/volcano/vendor/k8s.io/client-go/tools/cache/shared_informer.go:425 +0x49
volcano.sh/volcano/vendor/k8s.io/apimachinery/pkg/util/wait.(*Group).StartWithChannel.func1()
	/Users/yuan.chen/GolandProjects/src/volcano.sh/volcano/vendor/k8s.io/apimachinery/pkg/util/wait/wait.go:54 +0x2e
volcano.sh/volcano/vendor/k8s.io/apimachinery/pkg/util/wait.(*Group).Start.func1(0xc000610070, 0xc0003fe6e0)
	/Users/yuan.chen/GolandProjects/src/volcano.sh/volcano/vendor/k8s.io/apimachinery/pkg/util/wait/wait.go:71 +0x59
created by volcano.sh/volcano/vendor/k8s.io/apimachinery/pkg/util/wait.(*Group).Start
	/Users/yuan.chen/GolandProjects/src/volcano.sh/volcano/vendor/k8s.io/apimachinery/pkg/util/wait/wait.go:69 +0x62

goroutine 138 [chan receive (nil chan), 7 minutes]:
volcano.sh/volcano/vendor/k8s.io/client-go/tools/cache.(*controller).Run.func1(0x0, 0xc0004dcb80)
	/Users/yuan.chen/GolandProjects/src/volcano.sh/volcano/vendor/k8s.io/client-go/tools/cache/controller.go:103 +0x34
created by volcano.sh/volcano/vendor/k8s.io/client-go/tools/cache.(*controller).Run
	/Users/yuan.chen/GolandProjects/src/volcano.sh/volcano/vendor/k8s.io/client-go/tools/cache/controller.go:102 +0xae

goroutine 104 [chan receive, 7 minutes]:
volcano.sh/volcano/vendor/k8s.io/client-go/tools/cache.(*processorListener).run.func1.1(0x6d512b745748624e, 0x3265524771435548, 0x7868340a6c39796f)
	/Users/yuan.chen/GolandProjects/src/volcano.sh/volcano/vendor/k8s.io/client-go/tools/cache/shared_informer.go:549 +0x54
volcano.sh/volcano/vendor/k8s.io/apimachinery/pkg/util/wait.ExponentialBackoff(0x989680, 0x3ff0000000000000, 0x3fb999999999999a, 0x5, 0xc00058ddd8, 0x383835614c4a6c78, 0x3858584866635753)
	/Users/yuan.chen/GolandProjects/src/volcano.sh/volcano/vendor/k8s.io/apimachinery/pkg/util/wait/wait.go:203 +0xde
volcano.sh/volcano/vendor/k8s.io/client-go/tools/cache.(*processorListener).run.func1()
	/Users/yuan.chen/GolandProjects/src/volcano.sh/volcano/vendor/k8s.io/client-go/tools/cache/shared_informer.go:548 +0x89
volcano.sh/volcano/vendor/k8s.io/apimachinery/pkg/util/wait.JitterUntil.func1(0xc000524740)
	/Users/yuan.chen/GolandProjects/src/volcano.sh/volcano/vendor/k8s.io/apimachinery/pkg/util/wait/wait.go:133 +0x5e
volcano.sh/volcano/vendor/k8s.io/apimachinery/pkg/util/wait.JitterUntil(0xc00058df40, 0xdf8475800, 0x0, 0x1030501, 0xc000634120)
	/Users/yuan.chen/GolandProjects/src/volcano.sh/volcano/vendor/k8s.io/apimachinery/pkg/util/wait/wait.go:134 +0xf8
volcano.sh/volcano/vendor/k8s.io/apimachinery/pkg/util/wait.Until(...)
	/Users/yuan.chen/GolandProjects/src/volcano.sh/volcano/vendor/k8s.io/apimachinery/pkg/util/wait/wait.go:88
volcano.sh/volcano/vendor/k8s.io/client-go/tools/cache.(*processorListener).run(0xc00062b000)
	/Users/yuan.chen/GolandProjects/src/volcano.sh/volcano/vendor/k8s.io/client-go/tools/cache/shared_informer.go:546 +0x9b
volcano.sh/volcano/vendor/k8s.io/apimachinery/pkg/util/wait.(*Group).Start.func1(0xc000296760, 0xc0000ccc40)
	/Users/yuan.chen/GolandProjects/src/volcano.sh/volcano/vendor/k8s.io/apimachinery/pkg/util/wait/wait.go:71 +0x59
created by volcano.sh/volcano/vendor/k8s.io/apimachinery/pkg/util/wait.(*Group).Start
	/Users/yuan.chen/GolandProjects/src/volcano.sh/volcano/vendor/k8s.io/apimachinery/pkg/util/wait/wait.go:69 +0x62

goroutine 101 [chan receive, 7 minutes]:
volcano.sh/volcano/vendor/k8s.io/client-go/tools/cache.(*sharedProcessor).run(0xc000296700, 0xc000634000)
	/Users/yuan.chen/GolandProjects/src/volcano.sh/volcano/vendor/k8s.io/client-go/tools/cache/shared_informer.go:425 +0x49
volcano.sh/volcano/vendor/k8s.io/apimachinery/pkg/util/wait.(*Group).StartWithChannel.func1()
	/Users/yuan.chen/GolandProjects/src/volcano.sh/volcano/vendor/k8s.io/apimachinery/pkg/util/wait/wait.go:54 +0x2e
volcano.sh/volcano/vendor/k8s.io/apimachinery/pkg/util/wait.(*Group).Start.func1(0xc000044080, 0xc0000dc0e0)
	/Users/yuan.chen/GolandProjects/src/volcano.sh/volcano/vendor/k8s.io/apimachinery/pkg/util/wait/wait.go:71 +0x59
created by volcano.sh/volcano/vendor/k8s.io/apimachinery/pkg/util/wait.(*Group).Start
	/Users/yuan.chen/GolandProjects/src/volcano.sh/volcano/vendor/k8s.io/apimachinery/pkg/util/wait/wait.go:69 +0x62

goroutine 102 [chan receive (nil chan), 7 minutes]:
volcano.sh/volcano/vendor/k8s.io/client-go/tools/cache.(*controller).Run.func1(0x0, 0xc0002da000)
	/Users/yuan.chen/GolandProjects/src/volcano.sh/volcano/vendor/k8s.io/client-go/tools/cache/controller.go:103 +0x34
created by volcano.sh/volcano/vendor/k8s.io/client-go/tools/cache.(*controller).Run
	/Users/yuan.chen/GolandProjects/src/volcano.sh/volcano/vendor/k8s.io/client-go/tools/cache/controller.go:102 +0xae

goroutine 147 [chan receive, 7 minutes]:
volcano.sh/volcano/vendor/k8s.io/client-go/tools/cache.(*sharedProcessor).run(0xc0001c62a0, 0xc0003a8000)
	/Users/yuan.chen/GolandProjects/src/volcano.sh/volcano/vendor/k8s.io/client-go/tools/cache/shared_informer.go:425 +0x49
volcano.sh/volcano/vendor/k8s.io/apimachinery/pkg/util/wait.(*Group).StartWithChannel.func1()
	/Users/yuan.chen/GolandProjects/src/volcano.sh/volcano/vendor/k8s.io/apimachinery/pkg/util/wait/wait.go:54 +0x2e
volcano.sh/volcano/vendor/k8s.io/apimachinery/pkg/util/wait.(*Group).Start.func1(0xc000550060, 0xc00063ada0)
	/Users/yuan.chen/GolandProjects/src/volcano.sh/volcano/vendor/k8s.io/apimachinery/pkg/util/wait/wait.go:71 +0x59
created by volcano.sh/volcano/vendor/k8s.io/apimachinery/pkg/util/wait.(*Group).Start
	/Users/yuan.chen/GolandProjects/src/volcano.sh/volcano/vendor/k8s.io/apimachinery/pkg/util/wait/wait.go:69 +0x62

goroutine 148 [chan receive (nil chan), 7 minutes]:
volcano.sh/volcano/vendor/k8s.io/client-go/tools/cache.(*controller).Run.func1(0x0, 0xc000504280)
	/Users/yuan.chen/GolandProjects/src/volcano.sh/volcano/vendor/k8s.io/client-go/tools/cache/controller.go:103 +0x34
created by volcano.sh/volcano/vendor/k8s.io/client-go/tools/cache.(*controller).Run
	/Users/yuan.chen/GolandProjects/src/volcano.sh/volcano/vendor/k8s.io/client-go/tools/cache/controller.go:102 +0xae

goroutine 162 [chan receive, 7 minutes]:
volcano.sh/volcano/vendor/k8s.io/client-go/tools/cache.(*processorListener).run.func1.1(0x0, 0x0, 0x0)
	/Users/yuan.chen/GolandProjects/src/volcano.sh/volcano/vendor/k8s.io/client-go/tools/cache/shared_informer.go:549 +0x54
volcano.sh/volcano/vendor/k8s.io/apimachinery/pkg/util/wait.ExponentialBackoff(0x989680, 0x3ff0000000000000, 0x3fb999999999999a, 0x5, 0xc00073add8, 0x0, 0x0)
	/Users/yuan.chen/GolandProjects/src/volcano.sh/volcano/vendor/k8s.io/apimachinery/pkg/util/wait/wait.go:203 +0xde
volcano.sh/volcano/vendor/k8s.io/client-go/tools/cache.(*processorListener).run.func1()
	/Users/yuan.chen/GolandProjects/src/volcano.sh/volcano/vendor/k8s.io/client-go/tools/cache/shared_informer.go:548 +0x89
volcano.sh/volcano/vendor/k8s.io/apimachinery/pkg/util/wait.JitterUntil.func1(0xc00035cf40)
	/Users/yuan.chen/GolandProjects/src/volcano.sh/volcano/vendor/k8s.io/apimachinery/pkg/util/wait/wait.go:133 +0x5e
volcano.sh/volcano/vendor/k8s.io/apimachinery/pkg/util/wait.JitterUntil(0xc00073af40, 0xdf8475800, 0x0, 0x1030501, 0xc0006341e0)
	/Users/yuan.chen/GolandProjects/src/volcano.sh/volcano/vendor/k8s.io/apimachinery/pkg/util/wait/wait.go:134 +0xf8
volcano.sh/volcano/vendor/k8s.io/apimachinery/pkg/util/wait.Until(...)
	/Users/yuan.chen/GolandProjects/src/volcano.sh/volcano/vendor/k8s.io/apimachinery/pkg/util/wait/wait.go:88
volcano.sh/volcano/vendor/k8s.io/client-go/tools/cache.(*processorListener).run(0xc00062b180)
	/Users/yuan.chen/GolandProjects/src/volcano.sh/volcano/vendor/k8s.io/client-go/tools/cache/shared_informer.go:546 +0x9b
volcano.sh/volcano/vendor/k8s.io/apimachinery/pkg/util/wait.(*Group).Start.func1(0xc0002967d0, 0xc000084380)
	/Users/yuan.chen/GolandProjects/src/volcano.sh/volcano/vendor/k8s.io/apimachinery/pkg/util/wait/wait.go:71 +0x59
created by volcano.sh/volcano/vendor/k8s.io/apimachinery/pkg/util/wait.(*Group).Start
	/Users/yuan.chen/GolandProjects/src/volcano.sh/volcano/vendor/k8s.io/apimachinery/pkg/util/wait/wait.go:69 +0x62

goroutine 84 [chan receive, 7 minutes]:
volcano.sh/volcano/vendor/k8s.io/client-go/tools/cache.(*sharedProcessor).run(0xc0001c60e0, 0xc0003ae000)
	/Users/yuan.chen/GolandProjects/src/volcano.sh/volcano/vendor/k8s.io/client-go/tools/cache/shared_informer.go:425 +0x49
volcano.sh/volcano/vendor/k8s.io/apimachinery/pkg/util/wait.(*Group).StartWithChannel.func1()
	/Users/yuan.chen/GolandProjects/src/volcano.sh/volcano/vendor/k8s.io/apimachinery/pkg/util/wait/wait.go:54 +0x2e
volcano.sh/volcano/vendor/k8s.io/apimachinery/pkg/util/wait.(*Group).Start.func1(0xc0005ac020, 0xc0003061a0)
	/Users/yuan.chen/GolandProjects/src/volcano.sh/volcano/vendor/k8s.io/apimachinery/pkg/util/wait/wait.go:71 +0x59
created by volcano.sh/volcano/vendor/k8s.io/apimachinery/pkg/util/wait.(*Group).Start
	/Users/yuan.chen/GolandProjects/src/volcano.sh/volcano/vendor/k8s.io/apimachinery/pkg/util/wait/wait.go:69 +0x62

goroutine 85 [chan receive (nil chan), 7 minutes]:
volcano.sh/volcano/vendor/k8s.io/client-go/tools/cache.(*controller).Run.func1(0x0, 0xc00017c400)
	/Users/yuan.chen/GolandProjects/src/volcano.sh/volcano/vendor/k8s.io/client-go/tools/cache/controller.go:103 +0x34
created by volcano.sh/volcano/vendor/k8s.io/client-go/tools/cache.(*controller).Run
	/Users/yuan.chen/GolandProjects/src/volcano.sh/volcano/vendor/k8s.io/client-go/tools/cache/controller.go:102 +0xae

goroutine 46 [select]:
volcano.sh/volcano/vendor/k8s.io/client-go/tools/cache.(*Reflector).watchHandler(0xc0001c8a00, 0x23a3860, 0xc00076b140, 0xc0005d7be0, 0xc000703080, 0x0, 0x0, 0x0)
	/Users/yuan.chen/GolandProjects/src/volcano.sh/volcano/vendor/k8s.io/client-go/tools/cache/reflector.go:283 +0x1ec
volcano.sh/volcano/vendor/k8s.io/client-go/tools/cache.(*Reflector).ListAndWatch(0xc0001c8a00, 0x0, 0x0, 0x0)
	/Users/yuan.chen/GolandProjects/src/volcano.sh/volcano/vendor/k8s.io/client-go/tools/cache/reflector.go:254 +0xc73
volcano.sh/volcano/vendor/k8s.io/client-go/tools/cache.(*Reflector).Run.func1()
	/Users/yuan.chen/GolandProjects/src/volcano.sh/volcano/vendor/k8s.io/client-go/tools/cache/reflector.go:124 +0x33
volcano.sh/volcano/vendor/k8s.io/apimachinery/pkg/util/wait.JitterUntil.func1(0xc0000716f0)
	/Users/yuan.chen/GolandProjects/src/volcano.sh/volcano/vendor/k8s.io/apimachinery/pkg/util/wait/wait.go:133 +0x5e
volcano.sh/volcano/vendor/k8s.io/apimachinery/pkg/util/wait.JitterUntil(0xc0005d7ef0, 0x3b9aca00, 0x0, 0x1, 0x0)
	/Users/yuan.chen/GolandProjects/src/volcano.sh/volcano/vendor/k8s.io/apimachinery/pkg/util/wait/wait.go:134 +0xf8
volcano.sh/volcano/vendor/k8s.io/apimachinery/pkg/util/wait.Until(...)
	/Users/yuan.chen/GolandProjects/src/volcano.sh/volcano/vendor/k8s.io/apimachinery/pkg/util/wait/wait.go:88
volcano.sh/volcano/vendor/k8s.io/client-go/tools/cache.(*Reflector).Run(0xc0001c8a00, 0x0)
	/Users/yuan.chen/GolandProjects/src/volcano.sh/volcano/vendor/k8s.io/client-go/tools/cache/reflector.go:123 +0x169
volcano.sh/volcano/vendor/k8s.io/apimachinery/pkg/util/wait.(*Group).StartWithChannel.func1()
	/Users/yuan.chen/GolandProjects/src/volcano.sh/volcano/vendor/k8s.io/apimachinery/pkg/util/wait/wait.go:54 +0x2e
volcano.sh/volcano/vendor/k8s.io/apimachinery/pkg/util/wait.(*Group).Start.func1(0xc0005940b0, 0xc0006225e0)
	/Users/yuan.chen/GolandProjects/src/volcano.sh/volcano/vendor/k8s.io/apimachinery/pkg/util/wait/wait.go:71 +0x59
created by volcano.sh/volcano/vendor/k8s.io/apimachinery/pkg/util/wait.(*Group).Start
	/Users/yuan.chen/GolandProjects/src/volcano.sh/volcano/vendor/k8s.io/apimachinery/pkg/util/wait/wait.go:69 +0x62

goroutine 76 [select, 7 minutes]:
volcano.sh/volcano/vendor/k8s.io/client-go/tools/cache.(*Reflector).watchHandler(0xc00030c000, 0x23a3860, 0xc00095b020, 0xc00071fbe0, 0xc0007025a0, 0x0, 0x0, 0x0)
	/Users/yuan.chen/GolandProjects/src/volcano.sh/volcano/vendor/k8s.io/client-go/tools/cache/reflector.go:283 +0x1ec
volcano.sh/volcano/vendor/k8s.io/client-go/tools/cache.(*Reflector).ListAndWatch(0xc00030c000, 0x0, 0x0, 0x0)
	/Users/yuan.chen/GolandProjects/src/volcano.sh/volcano/vendor/k8s.io/client-go/tools/cache/reflector.go:254 +0xc73
volcano.sh/volcano/vendor/k8s.io/client-go/tools/cache.(*Reflector).Run.func1()
	/Users/yuan.chen/GolandProjects/src/volcano.sh/volcano/vendor/k8s.io/client-go/tools/cache/reflector.go:124 +0x33
volcano.sh/volcano/vendor/k8s.io/apimachinery/pkg/util/wait.JitterUntil.func1(0xc00035b6f0)
	/Users/yuan.chen/GolandProjects/src/volcano.sh/volcano/vendor/k8s.io/apimachinery/pkg/util/wait/wait.go:133 +0x5e
volcano.sh/volcano/vendor/k8s.io/apimachinery/pkg/util/wait.JitterUntil(0xc00071fef0, 0x3b9aca00, 0x0, 0x1, 0x0)
	/Users/yuan.chen/GolandProjects/src/volcano.sh/volcano/vendor/k8s.io/apimachinery/pkg/util/wait/wait.go:134 +0xf8
volcano.sh/volcano/vendor/k8s.io/apimachinery/pkg/util/wait.Until(...)
	/Users/yuan.chen/GolandProjects/src/volcano.sh/volcano/vendor/k8s.io/apimachinery/pkg/util/wait/wait.go:88
volcano.sh/volcano/vendor/k8s.io/client-go/tools/cache.(*Reflector).Run(0xc00030c000, 0x0)
	/Users/yuan.chen/GolandProjects/src/volcano.sh/volcano/vendor/k8s.io/client-go/tools/cache/reflector.go:123 +0x169
volcano.sh/volcano/vendor/k8s.io/apimachinery/pkg/util/wait.(*Group).StartWithChannel.func1()
	/Users/yuan.chen/GolandProjects/src/volcano.sh/volcano/vendor/k8s.io/apimachinery/pkg/util/wait/wait.go:54 +0x2e
volcano.sh/volcano/vendor/k8s.io/apimachinery/pkg/util/wait.(*Group).Start.func1(0xc0000ee0d0, 0xc00044c320)
	/Users/yuan.chen/GolandProjects/src/volcano.sh/volcano/vendor/k8s.io/apimachinery/pkg/util/wait/wait.go:71 +0x59
created by volcano.sh/volcano/vendor/k8s.io/apimachinery/pkg/util/wait.(*Group).Start
	/Users/yuan.chen/GolandProjects/src/volcano.sh/volcano/vendor/k8s.io/apimachinery/pkg/util/wait/wait.go:69 +0x62

goroutine 63 [select]:
volcano.sh/volcano/vendor/k8s.io/client-go/tools/cache.(*Reflector).watchHandler(0xc000332000, 0x23a3860, 0xc000798030, 0xc0005dbbe0, 0xc0000e6ba0, 0x0, 0x0, 0x0)
	/Users/yuan.chen/GolandProjects/src/volcano.sh/volcano/vendor/k8s.io/client-go/tools/cache/reflector.go:283 +0x1ec
volcano.sh/volcano/vendor/k8s.io/client-go/tools/cache.(*Reflector).ListAndWatch(0xc000332000, 0x0, 0x0, 0x0)
	/Users/yuan.chen/GolandProjects/src/volcano.sh/volcano/vendor/k8s.io/client-go/tools/cache/reflector.go:254 +0xc73
volcano.sh/volcano/vendor/k8s.io/client-go/tools/cache.(*Reflector).Run.func1()
	/Users/yuan.chen/GolandProjects/src/volcano.sh/volcano/vendor/k8s.io/client-go/tools/cache/reflector.go:124 +0x33
volcano.sh/volcano/vendor/k8s.io/apimachinery/pkg/util/wait.JitterUntil.func1(0xc00035a6f0)
	/Users/yuan.chen/GolandProjects/src/volcano.sh/volcano/vendor/k8s.io/apimachinery/pkg/util/wait/wait.go:133 +0x5e
volcano.sh/volcano/vendor/k8s.io/apimachinery/pkg/util/wait.JitterUntil(0xc0005dbef0, 0x3b9aca00, 0x0, 0x1, 0x0)
	/Users/yuan.chen/GolandProjects/src/volcano.sh/volcano/vendor/k8s.io/apimachinery/pkg/util/wait/wait.go:134 +0xf8
volcano.sh/volcano/vendor/k8s.io/apimachinery/pkg/util/wait.Until(...)
	/Users/yuan.chen/GolandProjects/src/volcano.sh/volcano/vendor/k8s.io/apimachinery/pkg/util/wait/wait.go:88
volcano.sh/volcano/vendor/k8s.io/client-go/tools/cache.(*Reflector).Run(0xc000332000, 0x0)
	/Users/yuan.chen/GolandProjects/src/volcano.sh/volcano/vendor/k8s.io/client-go/tools/cache/reflector.go:123 +0x169
volcano.sh/volcano/vendor/k8s.io/apimachinery/pkg/util/wait.(*Group).StartWithChannel.func1()
	/Users/yuan.chen/GolandProjects/src/volcano.sh/volcano/vendor/k8s.io/apimachinery/pkg/util/wait/wait.go:54 +0x2e
volcano.sh/volcano/vendor/k8s.io/apimachinery/pkg/util/wait.(*Group).Start.func1(0xc0003740f0, 0xc00011e6a0)
	/Users/yuan.chen/GolandProjects/src/volcano.sh/volcano/vendor/k8s.io/apimachinery/pkg/util/wait/wait.go:71 +0x59
created by volcano.sh/volcano/vendor/k8s.io/apimachinery/pkg/util/wait.(*Group).Start
	/Users/yuan.chen/GolandProjects/src/volcano.sh/volcano/vendor/k8s.io/apimachinery/pkg/util/wait/wait.go:69 +0x62

goroutine 103 [select, 3 minutes]:
volcano.sh/volcano/vendor/k8s.io/client-go/tools/cache.(*Reflector).watchHandler(0xc0003d6000, 0x23a3860, 0xc000779200, 0xc000af1be0, 0xc0000b0780, 0x0, 0x0, 0x0)
	/Users/yuan.chen/GolandProjects/src/volcano.sh/volcano/vendor/k8s.io/client-go/tools/cache/reflector.go:283 +0x1ec
volcano.sh/volcano/vendor/k8s.io/client-go/tools/cache.(*Reflector).ListAndWatch(0xc0003d6000, 0x0, 0x0, 0x0)
	/Users/yuan.chen/GolandProjects/src/volcano.sh/volcano/vendor/k8s.io/client-go/tools/cache/reflector.go:254 +0xc73
volcano.sh/volcano/vendor/k8s.io/client-go/tools/cache.(*Reflector).Run.func1()
	/Users/yuan.chen/GolandProjects/src/volcano.sh/volcano/vendor/k8s.io/client-go/tools/cache/reflector.go:124 +0x33
volcano.sh/volcano/vendor/k8s.io/apimachinery/pkg/util/wait.JitterUntil.func1(0xc000071ef0)
	/Users/yuan.chen/GolandProjects/src/volcano.sh/volcano/vendor/k8s.io/apimachinery/pkg/util/wait/wait.go:133 +0x5e
volcano.sh/volcano/vendor/k8s.io/apimachinery/pkg/util/wait.JitterUntil(0xc000af1ef0, 0x3b9aca00, 0x0, 0x1, 0x0)
	/Users/yuan.chen/GolandProjects/src/volcano.sh/volcano/vendor/k8s.io/apimachinery/pkg/util/wait/wait.go:134 +0xf8
volcano.sh/volcano/vendor/k8s.io/apimachinery/pkg/util/wait.Until(...)
	/Users/yuan.chen/GolandProjects/src/volcano.sh/volcano/vendor/k8s.io/apimachinery/pkg/util/wait/wait.go:88
volcano.sh/volcano/vendor/k8s.io/client-go/tools/cache.(*Reflector).Run(0xc0003d6000, 0x0)
	/Users/yuan.chen/GolandProjects/src/volcano.sh/volcano/vendor/k8s.io/client-go/tools/cache/reflector.go:123 +0x169
volcano.sh/volcano/vendor/k8s.io/apimachinery/pkg/util/wait.(*Group).StartWithChannel.func1()
	/Users/yuan.chen/GolandProjects/src/volcano.sh/volcano/vendor/k8s.io/apimachinery/pkg/util/wait/wait.go:54 +0x2e
volcano.sh/volcano/vendor/k8s.io/apimachinery/pkg/util/wait.(*Group).Start.func1(0xc000044920, 0xc0000dc340)
	/Users/yuan.chen/GolandProjects/src/volcano.sh/volcano/vendor/k8s.io/apimachinery/pkg/util/wait/wait.go:71 +0x59
created by volcano.sh/volcano/vendor/k8s.io/apimachinery/pkg/util/wait.(*Group).Start
	/Users/yuan.chen/GolandProjects/src/volcano.sh/volcano/vendor/k8s.io/apimachinery/pkg/util/wait/wait.go:69 +0x62

goroutine 86 [select, 7 minutes]:
volcano.sh/volcano/vendor/k8s.io/client-go/tools/cache.(*Reflector).watchHandler(0xc00051a000, 0x23a3860, 0xc000844840, 0xc0006afbe0, 0xc00070c840, 0x0, 0x0, 0x0)
	/Users/yuan.chen/GolandProjects/src/volcano.sh/volcano/vendor/k8s.io/client-go/tools/cache/reflector.go:283 +0x1ec
volcano.sh/volcano/vendor/k8s.io/client-go/tools/cache.(*Reflector).ListAndWatch(0xc00051a000, 0x0, 0x0, 0x0)
	/Users/yuan.chen/GolandProjects/src/volcano.sh/volcano/vendor/k8s.io/client-go/tools/cache/reflector.go:254 +0xc73
volcano.sh/volcano/vendor/k8s.io/client-go/tools/cache.(*Reflector).Run.func1()
	/Users/yuan.chen/GolandProjects/src/volcano.sh/volcano/vendor/k8s.io/client-go/tools/cache/reflector.go:124 +0x33
volcano.sh/volcano/vendor/k8s.io/apimachinery/pkg/util/wait.JitterUntil.func1(0xc00035c6f0)
	/Users/yuan.chen/GolandProjects/src/volcano.sh/volcano/vendor/k8s.io/apimachinery/pkg/util/wait/wait.go:133 +0x5e
volcano.sh/volcano/vendor/k8s.io/apimachinery/pkg/util/wait.JitterUntil(0xc0006afef0, 0x3b9aca00, 0x0, 0x1, 0x0)
	/Users/yuan.chen/GolandProjects/src/volcano.sh/volcano/vendor/k8s.io/apimachinery/pkg/util/wait/wait.go:134 +0xf8
volcano.sh/volcano/vendor/k8s.io/apimachinery/pkg/util/wait.Until(...)
	/Users/yuan.chen/GolandProjects/src/volcano.sh/volcano/vendor/k8s.io/apimachinery/pkg/util/wait/wait.go:88
volcano.sh/volcano/vendor/k8s.io/client-go/tools/cache.(*Reflector).Run(0xc00051a000, 0x0)
	/Users/yuan.chen/GolandProjects/src/volcano.sh/volcano/vendor/k8s.io/client-go/tools/cache/reflector.go:123 +0x169
volcano.sh/volcano/vendor/k8s.io/apimachinery/pkg/util/wait.(*Group).StartWithChannel.func1()
	/Users/yuan.chen/GolandProjects/src/volcano.sh/volcano/vendor/k8s.io/apimachinery/pkg/util/wait/wait.go:54 +0x2e
volcano.sh/volcano/vendor/k8s.io/apimachinery/pkg/util/wait.(*Group).Start.func1(0xc0005ac0a0, 0xc000306940)
	/Users/yuan.chen/GolandProjects/src/volcano.sh/volcano/vendor/k8s.io/apimachinery/pkg/util/wait/wait.go:71 +0x59
created by volcano.sh/volcano/vendor/k8s.io/apimachinery/pkg/util/wait.(*Group).Start
	/Users/yuan.chen/GolandProjects/src/volcano.sh/volcano/vendor/k8s.io/apimachinery/pkg/util/wait/wait.go:69 +0x62

goroutine 139 [select]:
volcano.sh/volcano/vendor/k8s.io/client-go/tools/cache.(*Reflector).watchHandler(0xc000410000, 0x23a3860, 0xc00061a120, 0xc0006d3be0, 0xc00070c960, 0x0, 0x0, 0x0)
	/Users/yuan.chen/GolandProjects/src/volcano.sh/volcano/vendor/k8s.io/client-go/tools/cache/reflector.go:283 +0x1ec
volcano.sh/volcano/vendor/k8s.io/client-go/tools/cache.(*Reflector).ListAndWatch(0xc000410000, 0x0, 0x0, 0x0)
	/Users/yuan.chen/GolandProjects/src/volcano.sh/volcano/vendor/k8s.io/client-go/tools/cache/reflector.go:254 +0xc73
volcano.sh/volcano/vendor/k8s.io/client-go/tools/cache.(*Reflector).Run.func1()
	/Users/yuan.chen/GolandProjects/src/volcano.sh/volcano/vendor/k8s.io/client-go/tools/cache/reflector.go:124 +0x33
volcano.sh/volcano/vendor/k8s.io/apimachinery/pkg/util/wait.JitterUntil.func1(0xc00035bef0)
	/Users/yuan.chen/GolandProjects/src/volcano.sh/volcano/vendor/k8s.io/apimachinery/pkg/util/wait/wait.go:133 +0x5e
volcano.sh/volcano/vendor/k8s.io/apimachinery/pkg/util/wait.JitterUntil(0xc0006d3ef0, 0x3b9aca00, 0x0, 0x1, 0x0)
	/Users/yuan.chen/GolandProjects/src/volcano.sh/volcano/vendor/k8s.io/apimachinery/pkg/util/wait/wait.go:134 +0xf8
volcano.sh/volcano/vendor/k8s.io/apimachinery/pkg/util/wait.Until(...)
	/Users/yuan.chen/GolandProjects/src/volcano.sh/volcano/vendor/k8s.io/apimachinery/pkg/util/wait/wait.go:88
volcano.sh/volcano/vendor/k8s.io/client-go/tools/cache.(*Reflector).Run(0xc000410000, 0x0)
	/Users/yuan.chen/GolandProjects/src/volcano.sh/volcano/vendor/k8s.io/client-go/tools/cache/reflector.go:123 +0x169
volcano.sh/volcano/vendor/k8s.io/apimachinery/pkg/util/wait.(*Group).StartWithChannel.func1()
	/Users/yuan.chen/GolandProjects/src/volcano.sh/volcano/vendor/k8s.io/apimachinery/pkg/util/wait/wait.go:54 +0x2e
volcano.sh/volcano/vendor/k8s.io/apimachinery/pkg/util/wait.(*Group).Start.func1(0xc0006100b0, 0xc0003fe7c0)
	/Users/yuan.chen/GolandProjects/src/volcano.sh/volcano/vendor/k8s.io/apimachinery/pkg/util/wait/wait.go:71 +0x59
created by volcano.sh/volcano/vendor/k8s.io/apimachinery/pkg/util/wait.(*Group).Start
	/Users/yuan.chen/GolandProjects/src/volcano.sh/volcano/vendor/k8s.io/apimachinery/pkg/util/wait/wait.go:69 +0x62

goroutine 65 [select, 7 minutes]:
volcano.sh/volcano/vendor/k8s.io/client-go/tools/cache.(*processorListener).pop(0xc0004dc380)
	/Users/yuan.chen/GolandProjects/src/volcano.sh/volcano/vendor/k8s.io/client-go/tools/cache/shared_informer.go:517 +0x18d
volcano.sh/volcano/vendor/k8s.io/apimachinery/pkg/util/wait.(*Group).Start.func1(0xc0001c6140, 0xc000084370)
	/Users/yuan.chen/GolandProjects/src/volcano.sh/volcano/vendor/k8s.io/apimachinery/pkg/util/wait/wait.go:71 +0x59
created by volcano.sh/volcano/vendor/k8s.io/apimachinery/pkg/util/wait.(*Group).Start
	/Users/yuan.chen/GolandProjects/src/volcano.sh/volcano/vendor/k8s.io/apimachinery/pkg/util/wait/wait.go:69 +0x62

goroutine 87 [chan receive, 7 minutes]:
volcano.sh/volcano/vendor/k8s.io/client-go/tools/cache.(*processorListener).run.func1.1(0x0, 0x10, 0x18)
	/Users/yuan.chen/GolandProjects/src/volcano.sh/volcano/vendor/k8s.io/client-go/tools/cache/shared_informer.go:549 +0x54
volcano.sh/volcano/vendor/k8s.io/apimachinery/pkg/util/wait.ExponentialBackoff(0x989680, 0x3ff0000000000000, 0x3fb999999999999a, 0x5, 0xc000a63dd8, 0x0, 0x0)
	/Users/yuan.chen/GolandProjects/src/volcano.sh/volcano/vendor/k8s.io/apimachinery/pkg/util/wait/wait.go:203 +0xde
volcano.sh/volcano/vendor/k8s.io/client-go/tools/cache.(*processorListener).run.func1()
	/Users/yuan.chen/GolandProjects/src/volcano.sh/volcano/vendor/k8s.io/client-go/tools/cache/shared_informer.go:548 +0x89
volcano.sh/volcano/vendor/k8s.io/apimachinery/pkg/util/wait.JitterUntil.func1(0xc000071740)
	/Users/yuan.chen/GolandProjects/src/volcano.sh/volcano/vendor/k8s.io/apimachinery/pkg/util/wait/wait.go:133 +0x5e
volcano.sh/volcano/vendor/k8s.io/apimachinery/pkg/util/wait.JitterUntil(0xc000a63f40, 0xdf8475800, 0x0, 0x1030501, 0xc0003ae0c0)
	/Users/yuan.chen/GolandProjects/src/volcano.sh/volcano/vendor/k8s.io/apimachinery/pkg/util/wait/wait.go:134 +0xf8
volcano.sh/volcano/vendor/k8s.io/apimachinery/pkg/util/wait.Until(...)
	/Users/yuan.chen/GolandProjects/src/volcano.sh/volcano/vendor/k8s.io/apimachinery/pkg/util/wait/wait.go:88
volcano.sh/volcano/vendor/k8s.io/client-go/tools/cache.(*processorListener).run(0xc0004dc980)
	/Users/yuan.chen/GolandProjects/src/volcano.sh/volcano/vendor/k8s.io/client-go/tools/cache/shared_informer.go:546 +0x9b
volcano.sh/volcano/vendor/k8s.io/apimachinery/pkg/util/wait.(*Group).Start.func1(0xc0001c6300, 0xc000356210)
	/Users/yuan.chen/GolandProjects/src/volcano.sh/volcano/vendor/k8s.io/apimachinery/pkg/util/wait/wait.go:71 +0x59
created by volcano.sh/volcano/vendor/k8s.io/apimachinery/pkg/util/wait.(*Group).Start
	/Users/yuan.chen/GolandProjects/src/volcano.sh/volcano/vendor/k8s.io/apimachinery/pkg/util/wait/wait.go:69 +0x62

goroutine 48 [chan receive, 7 minutes]:
volcano.sh/volcano/vendor/k8s.io/client-go/tools/cache.(*sharedProcessor).run(0xc0001c61c0, 0xc000130300)
	/Users/yuan.chen/GolandProjects/src/volcano.sh/volcano/vendor/k8s.io/client-go/tools/cache/shared_informer.go:425 +0x49
volcano.sh/volcano/vendor/k8s.io/apimachinery/pkg/util/wait.(*Group).StartWithChannel.func1()
	/Users/yuan.chen/GolandProjects/src/volcano.sh/volcano/vendor/k8s.io/apimachinery/pkg/util/wait/wait.go:54 +0x2e
volcano.sh/volcano/vendor/k8s.io/apimachinery/pkg/util/wait.(*Group).Start.func1(0xc0005941a0, 0xc0006229c0)
	/Users/yuan.chen/GolandProjects/src/volcano.sh/volcano/vendor/k8s.io/apimachinery/pkg/util/wait/wait.go:71 +0x59
created by volcano.sh/volcano/vendor/k8s.io/apimachinery/pkg/util/wait.(*Group).Start
	/Users/yuan.chen/GolandProjects/src/volcano.sh/volcano/vendor/k8s.io/apimachinery/pkg/util/wait/wait.go:69 +0x62

goroutine 49 [chan receive (nil chan), 7 minutes]:
volcano.sh/volcano/vendor/k8s.io/client-go/tools/cache.(*controller).Run.func1(0x0, 0xc000641180)
	/Users/yuan.chen/GolandProjects/src/volcano.sh/volcano/vendor/k8s.io/client-go/tools/cache/controller.go:103 +0x34
created by volcano.sh/volcano/vendor/k8s.io/client-go/tools/cache.(*controller).Run
	/Users/yuan.chen/GolandProjects/src/volcano.sh/volcano/vendor/k8s.io/client-go/tools/cache/controller.go:102 +0xae

goroutine 149 [select]:
volcano.sh/volcano/vendor/k8s.io/client-go/tools/cache.(*Reflector).watchHandler(0xc00018c140, 0x23a3860, 0xc000765260, 0xc0006d7be0, 0xc000549260, 0x0, 0x0, 0x0)
	/Users/yuan.chen/GolandProjects/src/volcano.sh/volcano/vendor/k8s.io/client-go/tools/cache/reflector.go:283 +0x1ec
volcano.sh/volcano/vendor/k8s.io/client-go/tools/cache.(*Reflector).ListAndWatch(0xc00018c140, 0x0, 0x0, 0x0)
	/Users/yuan.chen/GolandProjects/src/volcano.sh/volcano/vendor/k8s.io/client-go/tools/cache/reflector.go:254 +0xc73
volcano.sh/volcano/vendor/k8s.io/client-go/tools/cache.(*Reflector).Run.func1()
	/Users/yuan.chen/GolandProjects/src/volcano.sh/volcano/vendor/k8s.io/client-go/tools/cache/reflector.go:124 +0x33
volcano.sh/volcano/vendor/k8s.io/apimachinery/pkg/util/wait.JitterUntil.func1(0xc00035aef0)
	/Users/yuan.chen/GolandProjects/src/volcano.sh/volcano/vendor/k8s.io/apimachinery/pkg/util/wait/wait.go:133 +0x5e
volcano.sh/volcano/vendor/k8s.io/apimachinery/pkg/util/wait.JitterUntil(0xc0006d7ef0, 0x3b9aca00, 0x0, 0x1, 0x0)
	/Users/yuan.chen/GolandProjects/src/volcano.sh/volcano/vendor/k8s.io/apimachinery/pkg/util/wait/wait.go:134 +0xf8
volcano.sh/volcano/vendor/k8s.io/apimachinery/pkg/util/wait.Until(...)
	/Users/yuan.chen/GolandProjects/src/volcano.sh/volcano/vendor/k8s.io/apimachinery/pkg/util/wait/wait.go:88
volcano.sh/volcano/vendor/k8s.io/client-go/tools/cache.(*Reflector).Run(0xc00018c140, 0x0)
	/Users/yuan.chen/GolandProjects/src/volcano.sh/volcano/vendor/k8s.io/client-go/tools/cache/reflector.go:123 +0x169
volcano.sh/volcano/vendor/k8s.io/apimachinery/pkg/util/wait.(*Group).StartWithChannel.func1()
	/Users/yuan.chen/GolandProjects/src/volcano.sh/volcano/vendor/k8s.io/apimachinery/pkg/util/wait/wait.go:54 +0x2e
volcano.sh/volcano/vendor/k8s.io/apimachinery/pkg/util/wait.(*Group).Start.func1(0xc0005502e0, 0xc00063ae60)
	/Users/yuan.chen/GolandProjects/src/volcano.sh/volcano/vendor/k8s.io/apimachinery/pkg/util/wait/wait.go:71 +0x59
created by volcano.sh/volcano/vendor/k8s.io/apimachinery/pkg/util/wait.(*Group).Start
	/Users/yuan.chen/GolandProjects/src/volcano.sh/volcano/vendor/k8s.io/apimachinery/pkg/util/wait/wait.go:69 +0x62

goroutine 124 [select]:
volcano.sh/volcano/vendor/k8s.io/client-go/tools/cache.(*Reflector).watchHandler(0xc000104000, 0x23a3860, 0xc0004baae0, 0xc0005f3be0, 0xc000501560, 0x0, 0x0, 0x0)
	/Users/yuan.chen/GolandProjects/src/volcano.sh/volcano/vendor/k8s.io/client-go/tools/cache/reflector.go:283 +0x1ec
volcano.sh/volcano/vendor/k8s.io/client-go/tools/cache.(*Reflector).ListAndWatch(0xc000104000, 0x0, 0x0, 0x0)
	/Users/yuan.chen/GolandProjects/src/volcano.sh/volcano/vendor/k8s.io/client-go/tools/cache/reflector.go:254 +0xc73
volcano.sh/volcano/vendor/k8s.io/client-go/tools/cache.(*Reflector).Run.func1()
	/Users/yuan.chen/GolandProjects/src/volcano.sh/volcano/vendor/k8s.io/client-go/tools/cache/reflector.go:124 +0x33
volcano.sh/volcano/vendor/k8s.io/apimachinery/pkg/util/wait.JitterUntil.func1(0xc00006fef0)
	/Users/yuan.chen/GolandProjects/src/volcano.sh/volcano/vendor/k8s.io/apimachinery/pkg/util/wait/wait.go:133 +0x5e
volcano.sh/volcano/vendor/k8s.io/apimachinery/pkg/util/wait.JitterUntil(0xc0005f3ef0, 0x3b9aca00, 0x0, 0x1, 0x0)
	/Users/yuan.chen/GolandProjects/src/volcano.sh/volcano/vendor/k8s.io/apimachinery/pkg/util/wait/wait.go:134 +0xf8
volcano.sh/volcano/vendor/k8s.io/apimachinery/pkg/util/wait.Until(...)
	/Users/yuan.chen/GolandProjects/src/volcano.sh/volcano/vendor/k8s.io/apimachinery/pkg/util/wait/wait.go:88
volcano.sh/volcano/vendor/k8s.io/client-go/tools/cache.(*Reflector).Run(0xc000104000, 0x0)
	/Users/yuan.chen/GolandProjects/src/volcano.sh/volcano/vendor/k8s.io/client-go/tools/cache/reflector.go:123 +0x169
volcano.sh/volcano/vendor/k8s.io/apimachinery/pkg/util/wait.(*Group).StartWithChannel.func1()
	/Users/yuan.chen/GolandProjects/src/volcano.sh/volcano/vendor/k8s.io/apimachinery/pkg/util/wait/wait.go:54 +0x2e
volcano.sh/volcano/vendor/k8s.io/apimachinery/pkg/util/wait.(*Group).Start.func1(0xc000118300, 0xc00000eba0)
	/Users/yuan.chen/GolandProjects/src/volcano.sh/volcano/vendor/k8s.io/apimachinery/pkg/util/wait/wait.go:71 +0x59
created by volcano.sh/volcano/vendor/k8s.io/apimachinery/pkg/util/wait.(*Group).Start
	/Users/yuan.chen/GolandProjects/src/volcano.sh/volcano/vendor/k8s.io/apimachinery/pkg/util/wait/wait.go:69 +0x62

goroutine 105 [select, 7 minutes]:
volcano.sh/volcano/vendor/k8s.io/client-go/tools/cache.(*processorListener).pop(0xc00062b000)
	/Users/yuan.chen/GolandProjects/src/volcano.sh/volcano/vendor/k8s.io/client-go/tools/cache/shared_informer.go:517 +0x18d
volcano.sh/volcano/vendor/k8s.io/apimachinery/pkg/util/wait.(*Group).Start.func1(0xc000296760, 0xc0000ccc50)
	/Users/yuan.chen/GolandProjects/src/volcano.sh/volcano/vendor/k8s.io/apimachinery/pkg/util/wait/wait.go:71 +0x59
created by volcano.sh/volcano/vendor/k8s.io/apimachinery/pkg/util/wait.(*Group).Start
	/Users/yuan.chen/GolandProjects/src/volcano.sh/volcano/vendor/k8s.io/apimachinery/pkg/util/wait/wait.go:69 +0x62

goroutine 163 [select, 7 minutes]:
volcano.sh/volcano/vendor/k8s.io/client-go/tools/cache.(*processorListener).pop(0xc00062b180)
	/Users/yuan.chen/GolandProjects/src/volcano.sh/volcano/vendor/k8s.io/client-go/tools/cache/shared_informer.go:517 +0x18d
volcano.sh/volcano/vendor/k8s.io/apimachinery/pkg/util/wait.(*Group).Start.func1(0xc0002967d0, 0xc000084390)
	/Users/yuan.chen/GolandProjects/src/volcano.sh/volcano/vendor/k8s.io/apimachinery/pkg/util/wait/wait.go:71 +0x59
created by volcano.sh/volcano/vendor/k8s.io/apimachinery/pkg/util/wait.(*Group).Start
	/Users/yuan.chen/GolandProjects/src/volcano.sh/volcano/vendor/k8s.io/apimachinery/pkg/util/wait/wait.go:69 +0x62

goroutine 108 [chan receive]:
volcano.sh/volcano/vendor/k8s.io/client-go/tools/cache.(*processorListener).run.func1.1(0x0, 0x28, 0x5)
	/Users/yuan.chen/GolandProjects/src/volcano.sh/volcano/vendor/k8s.io/client-go/tools/cache/shared_informer.go:549 +0x54
volcano.sh/volcano/vendor/k8s.io/apimachinery/pkg/util/wait.ExponentialBackoff(0x989680, 0x3ff0000000000000, 0x3fb999999999999a, 0x5, 0xc0005c0dd8, 0x0, 0xc00016c8b8)
	/Users/yuan.chen/GolandProjects/src/volcano.sh/volcano/vendor/k8s.io/apimachinery/pkg/util/wait/wait.go:203 +0xde
volcano.sh/volcano/vendor/k8s.io/client-go/tools/cache.(*processorListener).run.func1()
	/Users/yuan.chen/GolandProjects/src/volcano.sh/volcano/vendor/k8s.io/client-go/tools/cache/shared_informer.go:548 +0x89
volcano.sh/volcano/vendor/k8s.io/apimachinery/pkg/util/wait.JitterUntil.func1(0xc00006d740)
	/Users/yuan.chen/GolandProjects/src/volcano.sh/volcano/vendor/k8s.io/apimachinery/pkg/util/wait/wait.go:133 +0x5e
volcano.sh/volcano/vendor/k8s.io/apimachinery/pkg/util/wait.JitterUntil(0xc0005c0f40, 0xdf8475800, 0x0, 0x1030501, 0xc0003a80c0)
	/Users/yuan.chen/GolandProjects/src/volcano.sh/volcano/vendor/k8s.io/apimachinery/pkg/util/wait/wait.go:134 +0xf8
volcano.sh/volcano/vendor/k8s.io/apimachinery/pkg/util/wait.Until(...)
	/Users/yuan.chen/GolandProjects/src/volcano.sh/volcano/vendor/k8s.io/apimachinery/pkg/util/wait/wait.go:88
volcano.sh/volcano/vendor/k8s.io/client-go/tools/cache.(*processorListener).run(0xc00062b200)
	/Users/yuan.chen/GolandProjects/src/volcano.sh/volcano/vendor/k8s.io/client-go/tools/cache/shared_informer.go:546 +0x9b
volcano.sh/volcano/vendor/k8s.io/apimachinery/pkg/util/wait.(*Group).Start.func1(0xc000296840, 0xc0000cccb0)
	/Users/yuan.chen/GolandProjects/src/volcano.sh/volcano/vendor/k8s.io/apimachinery/pkg/util/wait/wait.go:71 +0x59
created by volcano.sh/volcano/vendor/k8s.io/apimachinery/pkg/util/wait.(*Group).Start
	/Users/yuan.chen/GolandProjects/src/volcano.sh/volcano/vendor/k8s.io/apimachinery/pkg/util/wait/wait.go:69 +0x62

goroutine 165 [chan receive, 7 minutes]:
volcano.sh/volcano/vendor/k8s.io/client-go/tools/cache.(*sharedProcessor).run(0xc0001c6230, 0xc0001881e0)
	/Users/yuan.chen/GolandProjects/src/volcano.sh/volcano/vendor/k8s.io/client-go/tools/cache/shared_informer.go:425 +0x49
volcano.sh/volcano/vendor/k8s.io/apimachinery/pkg/util/wait.(*Group).StartWithChannel.func1()
	/Users/yuan.chen/GolandProjects/src/volcano.sh/volcano/vendor/k8s.io/apimachinery/pkg/util/wait/wait.go:54 +0x2e
volcano.sh/volcano/vendor/k8s.io/apimachinery/pkg/util/wait.(*Group).Start.func1(0xc000374470, 0xc00011ed40)
	/Users/yuan.chen/GolandProjects/src/volcano.sh/volcano/vendor/k8s.io/apimachinery/pkg/util/wait/wait.go:71 +0x59
created by volcano.sh/volcano/vendor/k8s.io/apimachinery/pkg/util/wait.(*Group).Start
	/Users/yuan.chen/GolandProjects/src/volcano.sh/volcano/vendor/k8s.io/apimachinery/pkg/util/wait/wait.go:69 +0x62

goroutine 166 [chan receive (nil chan), 7 minutes]:
volcano.sh/volcano/vendor/k8s.io/client-go/tools/cache.(*controller).Run.func1(0x0, 0xc0004d8600)
	/Users/yuan.chen/GolandProjects/src/volcano.sh/volcano/vendor/k8s.io/client-go/tools/cache/controller.go:103 +0x34
created by volcano.sh/volcano/vendor/k8s.io/client-go/tools/cache.(*controller).Run
	/Users/yuan.chen/GolandProjects/src/volcano.sh/volcano/vendor/k8s.io/client-go/tools/cache/controller.go:102 +0xae

goroutine 106 [chan receive, 7 minutes]:
volcano.sh/volcano/vendor/k8s.io/client-go/tools/cache.(*processorListener).run.func1.1(0x6d512b745748624e, 0x3265524771435548, 0x7868340a6c39796f)
	/Users/yuan.chen/GolandProjects/src/volcano.sh/volcano/vendor/k8s.io/client-go/tools/cache/shared_informer.go:549 +0x54
volcano.sh/volcano/vendor/k8s.io/apimachinery/pkg/util/wait.ExponentialBackoff(0x989680, 0x3ff0000000000000, 0x3fb999999999999a, 0x5, 0xc000a64dd8, 0x383835614c4a6c78, 0x3858584866635753)
	/Users/yuan.chen/GolandProjects/src/volcano.sh/volcano/vendor/k8s.io/apimachinery/pkg/util/wait/wait.go:203 +0xde
volcano.sh/volcano/vendor/k8s.io/client-go/tools/cache.(*processorListener).run.func1()
	/Users/yuan.chen/GolandProjects/src/volcano.sh/volcano/vendor/k8s.io/client-go/tools/cache/shared_informer.go:548 +0x89
volcano.sh/volcano/vendor/k8s.io/apimachinery/pkg/util/wait.JitterUntil.func1(0xc000524740)
	/Users/yuan.chen/GolandProjects/src/volcano.sh/volcano/vendor/k8s.io/apimachinery/pkg/util/wait/wait.go:133 +0x5e
volcano.sh/volcano/vendor/k8s.io/apimachinery/pkg/util/wait.JitterUntil(0xc000a64f40, 0xdf8475800, 0x0, 0x1030501, 0xc000634180)
	/Users/yuan.chen/GolandProjects/src/volcano.sh/volcano/vendor/k8s.io/apimachinery/pkg/util/wait/wait.go:134 +0xf8
volcano.sh/volcano/vendor/k8s.io/apimachinery/pkg/util/wait.Until(...)
	/Users/yuan.chen/GolandProjects/src/volcano.sh/volcano/vendor/k8s.io/apimachinery/pkg/util/wait/wait.go:88
volcano.sh/volcano/vendor/k8s.io/client-go/tools/cache.(*processorListener).run(0xc0004dca00)
	/Users/yuan.chen/GolandProjects/src/volcano.sh/volcano/vendor/k8s.io/client-go/tools/cache/shared_informer.go:546 +0x9b
volcano.sh/volcano/vendor/k8s.io/apimachinery/pkg/util/wait.(*Group).Start.func1(0xc0001c6370, 0xc0000ccc90)
	/Users/yuan.chen/GolandProjects/src/volcano.sh/volcano/vendor/k8s.io/apimachinery/pkg/util/wait/wait.go:71 +0x59
created by volcano.sh/volcano/vendor/k8s.io/apimachinery/pkg/util/wait.(*Group).Start
	/Users/yuan.chen/GolandProjects/src/volcano.sh/volcano/vendor/k8s.io/apimachinery/pkg/util/wait/wait.go:69 +0x62

goroutine 107 [select, 7 minutes]:
volcano.sh/volcano/vendor/k8s.io/client-go/tools/cache.(*processorListener).pop(0xc0004dca00)
	/Users/yuan.chen/GolandProjects/src/volcano.sh/volcano/vendor/k8s.io/client-go/tools/cache/shared_informer.go:517 +0x18d
volcano.sh/volcano/vendor/k8s.io/apimachinery/pkg/util/wait.(*Group).Start.func1(0xc0001c6370, 0xc0000ccca0)
	/Users/yuan.chen/GolandProjects/src/volcano.sh/volcano/vendor/k8s.io/apimachinery/pkg/util/wait/wait.go:71 +0x59
created by volcano.sh/volcano/vendor/k8s.io/apimachinery/pkg/util/wait.(*Group).Start
	/Users/yuan.chen/GolandProjects/src/volcano.sh/volcano/vendor/k8s.io/apimachinery/pkg/util/wait/wait.go:69 +0x62

goroutine 88 [select, 7 minutes]:
volcano.sh/volcano/vendor/k8s.io/client-go/tools/cache.(*processorListener).pop(0xc0004dc980)
	/Users/yuan.chen/GolandProjects/src/volcano.sh/volcano/vendor/k8s.io/client-go/tools/cache/shared_informer.go:517 +0x18d
volcano.sh/volcano/vendor/k8s.io/apimachinery/pkg/util/wait.(*Group).Start.func1(0xc0001c6300, 0xc000356220)
	/Users/yuan.chen/GolandProjects/src/volcano.sh/volcano/vendor/k8s.io/apimachinery/pkg/util/wait/wait.go:71 +0x59
created by volcano.sh/volcano/vendor/k8s.io/apimachinery/pkg/util/wait.(*Group).Start
	/Users/yuan.chen/GolandProjects/src/volcano.sh/volcano/vendor/k8s.io/apimachinery/pkg/util/wait/wait.go:69 +0x62

goroutine 141 [select, 7 minutes]:
volcano.sh/volcano/vendor/k8s.io/client-go/tools/cache.(*processorListener).pop(0xc0004dc500)
	/Users/yuan.chen/GolandProjects/src/volcano.sh/volcano/vendor/k8s.io/client-go/tools/cache/shared_informer.go:517 +0x18d
volcano.sh/volcano/vendor/k8s.io/apimachinery/pkg/util/wait.(*Group).Start.func1(0xc0001c61b0, 0xc0000ea790)
	/Users/yuan.chen/GolandProjects/src/volcano.sh/volcano/vendor/k8s.io/apimachinery/pkg/util/wait/wait.go:71 +0x59
created by volcano.sh/volcano/vendor/k8s.io/apimachinery/pkg/util/wait.(*Group).Start
	/Users/yuan.chen/GolandProjects/src/volcano.sh/volcano/vendor/k8s.io/apimachinery/pkg/util/wait/wait.go:69 +0x62

goroutine 143 [select, 7 minutes]:
volcano.sh/volcano/vendor/k8s.io/client-go/tools/cache.(*processorListener).pop(0xc0004dc280)
	/Users/yuan.chen/GolandProjects/src/volcano.sh/volcano/vendor/k8s.io/client-go/tools/cache/shared_informer.go:517 +0x18d
volcano.sh/volcano/vendor/k8s.io/apimachinery/pkg/util/wait.(*Group).Start.func1(0xc0001c6060, 0xc0000ea7b0)
	/Users/yuan.chen/GolandProjects/src/volcano.sh/volcano/vendor/k8s.io/apimachinery/pkg/util/wait/wait.go:71 +0x59
created by volcano.sh/volcano/vendor/k8s.io/apimachinery/pkg/util/wait.(*Group).Start
	/Users/yuan.chen/GolandProjects/src/volcano.sh/volcano/vendor/k8s.io/apimachinery/pkg/util/wait/wait.go:69 +0x62

goroutine 126 [chan receive, 7 minutes]:
volcano.sh/volcano/vendor/k8s.io/client-go/tools/cache.(*sharedProcessor).run(0xc0001c6000, 0xc00070a120)
	/Users/yuan.chen/GolandProjects/src/volcano.sh/volcano/vendor/k8s.io/client-go/tools/cache/shared_informer.go:425 +0x49
volcano.sh/volcano/vendor/k8s.io/apimachinery/pkg/util/wait.(*Group).StartWithChannel.func1()
	/Users/yuan.chen/GolandProjects/src/volcano.sh/volcano/vendor/k8s.io/apimachinery/pkg/util/wait/wait.go:54 +0x2e
volcano.sh/volcano/vendor/k8s.io/apimachinery/pkg/util/wait.(*Group).Start.func1(0xc0001184f0, 0xc00000f1c0)
	/Users/yuan.chen/GolandProjects/src/volcano.sh/volcano/vendor/k8s.io/apimachinery/pkg/util/wait/wait.go:71 +0x59
created by volcano.sh/volcano/vendor/k8s.io/apimachinery/pkg/util/wait.(*Group).Start
	/Users/yuan.chen/GolandProjects/src/volcano.sh/volcano/vendor/k8s.io/apimachinery/pkg/util/wait/wait.go:69 +0x62

goroutine 127 [chan receive (nil chan), 7 minutes]:
volcano.sh/volcano/vendor/k8s.io/client-go/tools/cache.(*controller).Run.func1(0x0, 0xc00017bc80)
	/Users/yuan.chen/GolandProjects/src/volcano.sh/volcano/vendor/k8s.io/client-go/tools/cache/controller.go:103 +0x34
created by volcano.sh/volcano/vendor/k8s.io/client-go/tools/cache.(*controller).Run
	/Users/yuan.chen/GolandProjects/src/volcano.sh/volcano/vendor/k8s.io/client-go/tools/cache/controller.go:102 +0xae

goroutine 90 [select, 5 minutes]:
volcano.sh/volcano/vendor/k8s.io/client-go/tools/cache.(*processorListener).pop(0xc0004dc700)
	/Users/yuan.chen/GolandProjects/src/volcano.sh/volcano/vendor/k8s.io/client-go/tools/cache/shared_informer.go:517 +0x18d
volcano.sh/volcano/vendor/k8s.io/apimachinery/pkg/util/wait.(*Group).Start.func1(0xc0001c6220, 0xc000356240)
	/Users/yuan.chen/GolandProjects/src/volcano.sh/volcano/vendor/k8s.io/apimachinery/pkg/util/wait/wait.go:71 +0x59
created by volcano.sh/volcano/vendor/k8s.io/apimachinery/pkg/util/wait.(*Group).Start
	/Users/yuan.chen/GolandProjects/src/volcano.sh/volcano/vendor/k8s.io/apimachinery/pkg/util/wait/wait.go:69 +0x62

goroutine 91 [chan receive, 7 minutes]:
volcano.sh/volcano/vendor/k8s.io/client-go/tools/cache.(*processorListener).run.func1.1(0x0, 0x0, 0x0)
	/Users/yuan.chen/GolandProjects/src/volcano.sh/volcano/vendor/k8s.io/client-go/tools/cache/shared_informer.go:549 +0x54
volcano.sh/volcano/vendor/k8s.io/apimachinery/pkg/util/wait.ExponentialBackoff(0x989680, 0x3ff0000000000000, 0x3fb999999999999a, 0x5, 0xc000738dd8, 0x0, 0x0)
	/Users/yuan.chen/GolandProjects/src/volcano.sh/volcano/vendor/k8s.io/apimachinery/pkg/util/wait/wait.go:203 +0xde
volcano.sh/volcano/vendor/k8s.io/client-go/tools/cache.(*processorListener).run.func1()
	/Users/yuan.chen/GolandProjects/src/volcano.sh/volcano/vendor/k8s.io/client-go/tools/cache/shared_informer.go:548 +0x89
volcano.sh/volcano/vendor/k8s.io/apimachinery/pkg/util/wait.JitterUntil.func1(0xc000660f40)
	/Users/yuan.chen/GolandProjects/src/volcano.sh/volcano/vendor/k8s.io/apimachinery/pkg/util/wait/wait.go:133 +0x5e
volcano.sh/volcano/vendor/k8s.io/apimachinery/pkg/util/wait.JitterUntil(0xc000738f40, 0xdf8475800, 0x0, 0x1030501, 0xc0003ae180)
	/Users/yuan.chen/GolandProjects/src/volcano.sh/volcano/vendor/k8s.io/apimachinery/pkg/util/wait/wait.go:134 +0xf8
volcano.sh/volcano/vendor/k8s.io/apimachinery/pkg/util/wait.Until(...)
	/Users/yuan.chen/GolandProjects/src/volcano.sh/volcano/vendor/k8s.io/apimachinery/pkg/util/wait/wait.go:88
volcano.sh/volcano/vendor/k8s.io/client-go/tools/cache.(*processorListener).run(0xc0004dc800)
	/Users/yuan.chen/GolandProjects/src/volcano.sh/volcano/vendor/k8s.io/client-go/tools/cache/shared_informer.go:546 +0x9b
volcano.sh/volcano/vendor/k8s.io/apimachinery/pkg/util/wait.(*Group).Start.func1(0xc0001c6290, 0xc000356250)
	/Users/yuan.chen/GolandProjects/src/volcano.sh/volcano/vendor/k8s.io/apimachinery/pkg/util/wait/wait.go:71 +0x59
created by volcano.sh/volcano/vendor/k8s.io/apimachinery/pkg/util/wait.(*Group).Start
	/Users/yuan.chen/GolandProjects/src/volcano.sh/volcano/vendor/k8s.io/apimachinery/pkg/util/wait/wait.go:69 +0x62

goroutine 92 [select, 7 minutes]:
volcano.sh/volcano/vendor/k8s.io/client-go/tools/cache.(*processorListener).pop(0xc0004dc800)
	/Users/yuan.chen/GolandProjects/src/volcano.sh/volcano/vendor/k8s.io/client-go/tools/cache/shared_informer.go:517 +0x18d
volcano.sh/volcano/vendor/k8s.io/apimachinery/pkg/util/wait.(*Group).Start.func1(0xc0001c6290, 0xc000356260)
	/Users/yuan.chen/GolandProjects/src/volcano.sh/volcano/vendor/k8s.io/apimachinery/pkg/util/wait/wait.go:71 +0x59
created by volcano.sh/volcano/vendor/k8s.io/apimachinery/pkg/util/wait.(*Group).Start
	/Users/yuan.chen/GolandProjects/src/volcano.sh/volcano/vendor/k8s.io/apimachinery/pkg/util/wait/wait.go:69 +0x62

goroutine 150 [chan receive, 5 minutes]:
volcano.sh/volcano/vendor/k8s.io/client-go/tools/cache.(*processorListener).run.func1.1(0x0, 0x28, 0x5)
	/Users/yuan.chen/GolandProjects/src/volcano.sh/volcano/vendor/k8s.io/client-go/tools/cache/shared_informer.go:549 +0x54
volcano.sh/volcano/vendor/k8s.io/apimachinery/pkg/util/wait.ExponentialBackoff(0x989680, 0x3ff0000000000000, 0x3fb999999999999a, 0x5, 0xc0006fadd8, 0x0, 0xc000099038)
	/Users/yuan.chen/GolandProjects/src/volcano.sh/volcano/vendor/k8s.io/apimachinery/pkg/util/wait/wait.go:203 +0xde
volcano.sh/volcano/vendor/k8s.io/client-go/tools/cache.(*processorListener).run.func1()
	/Users/yuan.chen/GolandProjects/src/volcano.sh/volcano/vendor/k8s.io/client-go/tools/cache/shared_informer.go:548 +0x89
volcano.sh/volcano/vendor/k8s.io/apimachinery/pkg/util/wait.JitterUntil.func1(0xc000663740)
	/Users/yuan.chen/GolandProjects/src/volcano.sh/volcano/vendor/k8s.io/apimachinery/pkg/util/wait/wait.go:133 +0x5e
volcano.sh/volcano/vendor/k8s.io/apimachinery/pkg/util/wait.JitterUntil(0xc0006faf40, 0xdf8475800, 0x0, 0x1030501, 0xc0003a8120)
	/Users/yuan.chen/GolandProjects/src/volcano.sh/volcano/vendor/k8s.io/apimachinery/pkg/util/wait/wait.go:134 +0xf8
volcano.sh/volcano/vendor/k8s.io/apimachinery/pkg/util/wait.Until(...)
	/Users/yuan.chen/GolandProjects/src/volcano.sh/volcano/vendor/k8s.io/apimachinery/pkg/util/wait/wait.go:88
volcano.sh/volcano/vendor/k8s.io/client-go/tools/cache.(*processorListener).run(0xc0004dc100)
	/Users/yuan.chen/GolandProjects/src/volcano.sh/volcano/vendor/k8s.io/client-go/tools/cache/shared_informer.go:546 +0x9b
volcano.sh/volcano/vendor/k8s.io/apimachinery/pkg/util/wait.(*Group).Start.func1(0xc0001c60d0, 0xc00055e160)
	/Users/yuan.chen/GolandProjects/src/volcano.sh/volcano/vendor/k8s.io/apimachinery/pkg/util/wait/wait.go:71 +0x59
created by volcano.sh/volcano/vendor/k8s.io/apimachinery/pkg/util/wait.(*Group).Start
	/Users/yuan.chen/GolandProjects/src/volcano.sh/volcano/vendor/k8s.io/apimachinery/pkg/util/wait/wait.go:69 +0x62

goroutine 111 [chan receive, 7 minutes]:
volcano.sh/volcano/vendor/k8s.io/client-go/tools/cache.(*sharedProcessor).run(0xc0001c6070, 0xc000634240)
	/Users/yuan.chen/GolandProjects/src/volcano.sh/volcano/vendor/k8s.io/client-go/tools/cache/shared_informer.go:425 +0x49
volcano.sh/volcano/vendor/k8s.io/apimachinery/pkg/util/wait.(*Group).StartWithChannel.func1()
	/Users/yuan.chen/GolandProjects/src/volcano.sh/volcano/vendor/k8s.io/apimachinery/pkg/util/wait/wait.go:54 +0x2e
volcano.sh/volcano/vendor/k8s.io/apimachinery/pkg/util/wait.(*Group).Start.func1(0xc000044a90, 0xc0000dc680)
	/Users/yuan.chen/GolandProjects/src/volcano.sh/volcano/vendor/k8s.io/apimachinery/pkg/util/wait/wait.go:71 +0x59
created by volcano.sh/volcano/vendor/k8s.io/apimachinery/pkg/util/wait.(*Group).Start
	/Users/yuan.chen/GolandProjects/src/volcano.sh/volcano/vendor/k8s.io/apimachinery/pkg/util/wait/wait.go:69 +0x62

goroutine 112 [chan receive (nil chan), 7 minutes]:
volcano.sh/volcano/vendor/k8s.io/client-go/tools/cache.(*controller).Run.func1(0x0, 0xc0002db780)
	/Users/yuan.chen/GolandProjects/src/volcano.sh/volcano/vendor/k8s.io/client-go/tools/cache/controller.go:103 +0x34
created by volcano.sh/volcano/vendor/k8s.io/client-go/tools/cache.(*controller).Run
	/Users/yuan.chen/GolandProjects/src/volcano.sh/volcano/vendor/k8s.io/client-go/tools/cache/controller.go:102 +0xae

goroutine 178 [select, 5 minutes]:
volcano.sh/volcano/vendor/k8s.io/client-go/tools/cache.(*Reflector).watchHandler(0xc0001c8c80, 0x23a3860, 0xc0004ba270, 0xc000a31be0, 0xc0000b0f00, 0x0, 0x0, 0x0)
	/Users/yuan.chen/GolandProjects/src/volcano.sh/volcano/vendor/k8s.io/client-go/tools/cache/reflector.go:283 +0x1ec
volcano.sh/volcano/vendor/k8s.io/client-go/tools/cache.(*Reflector).ListAndWatch(0xc0001c8c80, 0x0, 0x0, 0x0)
	/Users/yuan.chen/GolandProjects/src/volcano.sh/volcano/vendor/k8s.io/client-go/tools/cache/reflector.go:254 +0xc73
volcano.sh/volcano/vendor/k8s.io/client-go/tools/cache.(*Reflector).Run.func1()
	/Users/yuan.chen/GolandProjects/src/volcano.sh/volcano/vendor/k8s.io/client-go/tools/cache/reflector.go:124 +0x33
volcano.sh/volcano/vendor/k8s.io/apimachinery/pkg/util/wait.JitterUntil.func1(0xc0000706f0)
	/Users/yuan.chen/GolandProjects/src/volcano.sh/volcano/vendor/k8s.io/apimachinery/pkg/util/wait/wait.go:133 +0x5e
volcano.sh/volcano/vendor/k8s.io/apimachinery/pkg/util/wait.JitterUntil(0xc000a31ef0, 0x3b9aca00, 0x0, 0x1, 0x0)
	/Users/yuan.chen/GolandProjects/src/volcano.sh/volcano/vendor/k8s.io/apimachinery/pkg/util/wait/wait.go:134 +0xf8
volcano.sh/volcano/vendor/k8s.io/apimachinery/pkg/util/wait.Until(...)
	/Users/yuan.chen/GolandProjects/src/volcano.sh/volcano/vendor/k8s.io/apimachinery/pkg/util/wait/wait.go:88
volcano.sh/volcano/vendor/k8s.io/client-go/tools/cache.(*Reflector).Run(0xc0001c8c80, 0x0)
	/Users/yuan.chen/GolandProjects/src/volcano.sh/volcano/vendor/k8s.io/client-go/tools/cache/reflector.go:123 +0x169
volcano.sh/volcano/vendor/k8s.io/apimachinery/pkg/util/wait.(*Group).StartWithChannel.func1()
	/Users/yuan.chen/GolandProjects/src/volcano.sh/volcano/vendor/k8s.io/apimachinery/pkg/util/wait/wait.go:54 +0x2e
volcano.sh/volcano/vendor/k8s.io/apimachinery/pkg/util/wait.(*Group).Start.func1(0xc0005941e0, 0xc000622aa0)
	/Users/yuan.chen/GolandProjects/src/volcano.sh/volcano/vendor/k8s.io/apimachinery/pkg/util/wait/wait.go:71 +0x59
created by volcano.sh/volcano/vendor/k8s.io/apimachinery/pkg/util/wait.(*Group).Start
	/Users/yuan.chen/GolandProjects/src/volcano.sh/volcano/vendor/k8s.io/apimachinery/pkg/util/wait/wait.go:69 +0x62

goroutine 151 [select, 5 minutes]:
volcano.sh/volcano/vendor/k8s.io/client-go/tools/cache.(*processorListener).pop(0xc0004dc100)
	/Users/yuan.chen/GolandProjects/src/volcano.sh/volcano/vendor/k8s.io/client-go/tools/cache/shared_informer.go:517 +0x18d
volcano.sh/volcano/vendor/k8s.io/apimachinery/pkg/util/wait.(*Group).Start.func1(0xc0001c60d0, 0xc00055e170)
	/Users/yuan.chen/GolandProjects/src/volcano.sh/volcano/vendor/k8s.io/apimachinery/pkg/util/wait/wait.go:71 +0x59
created by volcano.sh/volcano/vendor/k8s.io/apimachinery/pkg/util/wait.(*Group).Start
	/Users/yuan.chen/GolandProjects/src/volcano.sh/volcano/vendor/k8s.io/apimachinery/pkg/util/wait/wait.go:69 +0x62

goroutine 167 [select, 7 minutes]:
volcano.sh/volcano/vendor/k8s.io/client-go/tools/cache.(*Reflector).watchHandler(0xc0003320a0, 0x23a3860, 0xc000a46030, 0xc0006b1be0, 0xc0005494a0, 0x0, 0x0, 0x0)
	/Users/yuan.chen/GolandProjects/src/volcano.sh/volcano/vendor/k8s.io/client-go/tools/cache/reflector.go:283 +0x1ec
volcano.sh/volcano/vendor/k8s.io/client-go/tools/cache.(*Reflector).ListAndWatch(0xc0003320a0, 0x0, 0x0, 0x0)
	/Users/yuan.chen/GolandProjects/src/volcano.sh/volcano/vendor/k8s.io/client-go/tools/cache/reflector.go:254 +0xc73
volcano.sh/volcano/vendor/k8s.io/client-go/tools/cache.(*Reflector).Run.func1()
	/Users/yuan.chen/GolandProjects/src/volcano.sh/volcano/vendor/k8s.io/client-go/tools/cache/reflector.go:124 +0x33
volcano.sh/volcano/vendor/k8s.io/apimachinery/pkg/util/wait.JitterUntil.func1(0xc000070ef0)
	/Users/yuan.chen/GolandProjects/src/volcano.sh/volcano/vendor/k8s.io/apimachinery/pkg/util/wait/wait.go:133 +0x5e
volcano.sh/volcano/vendor/k8s.io/apimachinery/pkg/util/wait.JitterUntil(0xc0006b1ef0, 0x3b9aca00, 0x0, 0x1, 0x0)
	/Users/yuan.chen/GolandProjects/src/volcano.sh/volcano/vendor/k8s.io/apimachinery/pkg/util/wait/wait.go:134 +0xf8
volcano.sh/volcano/vendor/k8s.io/apimachinery/pkg/util/wait.Until(...)
	/Users/yuan.chen/GolandProjects/src/volcano.sh/volcano/vendor/k8s.io/apimachinery/pkg/util/wait/wait.go:88
volcano.sh/volcano/vendor/k8s.io/client-go/tools/cache.(*Reflector).Run(0xc0003320a0, 0x0)
	/Users/yuan.chen/GolandProjects/src/volcano.sh/volcano/vendor/k8s.io/client-go/tools/cache/reflector.go:123 +0x169
volcano.sh/volcano/vendor/k8s.io/apimachinery/pkg/util/wait.(*Group).StartWithChannel.func1()
	/Users/yuan.chen/GolandProjects/src/volcano.sh/volcano/vendor/k8s.io/apimachinery/pkg/util/wait/wait.go:54 +0x2e
volcano.sh/volcano/vendor/k8s.io/apimachinery/pkg/util/wait.(*Group).Start.func1(0xc000374550, 0xc00011ee40)
	/Users/yuan.chen/GolandProjects/src/volcano.sh/volcano/vendor/k8s.io/apimachinery/pkg/util/wait/wait.go:71 +0x59
created by volcano.sh/volcano/vendor/k8s.io/apimachinery/pkg/util/wait.(*Group).Start
	/Users/yuan.chen/GolandProjects/src/volcano.sh/volcano/vendor/k8s.io/apimachinery/pkg/util/wait/wait.go:69 +0x62

goroutine 128 [select, 3 minutes]:
volcano.sh/volcano/vendor/k8s.io/client-go/tools/cache.(*Reflector).watchHandler(0xc000104960, 0x23a3860, 0xc000a0a420, 0xc000a4dbe0, 0xc0005499e0, 0x0, 0x0, 0x0)
	/Users/yuan.chen/GolandProjects/src/volcano.sh/volcano/vendor/k8s.io/client-go/tools/cache/reflector.go:283 +0x1ec
volcano.sh/volcano/vendor/k8s.io/client-go/tools/cache.(*Reflector).ListAndWatch(0xc000104960, 0x0, 0x0, 0x0)
	/Users/yuan.chen/GolandProjects/src/volcano.sh/volcano/vendor/k8s.io/client-go/tools/cache/reflector.go:254 +0xc73
volcano.sh/volcano/vendor/k8s.io/client-go/tools/cache.(*Reflector).Run.func1()
	/Users/yuan.chen/GolandProjects/src/volcano.sh/volcano/vendor/k8s.io/client-go/tools/cache/reflector.go:124 +0x33
volcano.sh/volcano/vendor/k8s.io/apimachinery/pkg/util/wait.JitterUntil.func1(0xc0001606f0)
	/Users/yuan.chen/GolandProjects/src/volcano.sh/volcano/vendor/k8s.io/apimachinery/pkg/util/wait/wait.go:133 +0x5e
volcano.sh/volcano/vendor/k8s.io/apimachinery/pkg/util/wait.JitterUntil(0xc000a4def0, 0x3b9aca00, 0x0, 0x1, 0x0)
	/Users/yuan.chen/GolandProjects/src/volcano.sh/volcano/vendor/k8s.io/apimachinery/pkg/util/wait/wait.go:134 +0xf8
volcano.sh/volcano/vendor/k8s.io/apimachinery/pkg/util/wait.Until(...)
	/Users/yuan.chen/GolandProjects/src/volcano.sh/volcano/vendor/k8s.io/apimachinery/pkg/util/wait/wait.go:88
volcano.sh/volcano/vendor/k8s.io/client-go/tools/cache.(*Reflector).Run(0xc000104960, 0x0)
	/Users/yuan.chen/GolandProjects/src/volcano.sh/volcano/vendor/k8s.io/client-go/tools/cache/reflector.go:123 +0x169
volcano.sh/volcano/vendor/k8s.io/apimachinery/pkg/util/wait.(*Group).StartWithChannel.func1()
	/Users/yuan.chen/GolandProjects/src/volcano.sh/volcano/vendor/k8s.io/apimachinery/pkg/util/wait/wait.go:54 +0x2e
volcano.sh/volcano/vendor/k8s.io/apimachinery/pkg/util/wait.(*Group).Start.func1(0xc000118550, 0xc00000f3e0)
	/Users/yuan.chen/GolandProjects/src/volcano.sh/volcano/vendor/k8s.io/apimachinery/pkg/util/wait/wait.go:71 +0x59
created by volcano.sh/volcano/vendor/k8s.io/apimachinery/pkg/util/wait.(*Group).Start
	/Users/yuan.chen/GolandProjects/src/volcano.sh/volcano/vendor/k8s.io/apimachinery/pkg/util/wait/wait.go:69 +0x62

goroutine 113 [select, 5 minutes]:
volcano.sh/volcano/vendor/k8s.io/client-go/tools/cache.(*Reflector).watchHandler(0xc0003d60a0, 0x23a3860, 0xc00095b0b0, 0xc000a4fbe0, 0xc00070dc20, 0x0, 0x0, 0x0)
	/Users/yuan.chen/GolandProjects/src/volcano.sh/volcano/vendor/k8s.io/client-go/tools/cache/reflector.go:283 +0x1ec
volcano.sh/volcano/vendor/k8s.io/client-go/tools/cache.(*Reflector).ListAndWatch(0xc0003d60a0, 0x0, 0x0, 0x0)
	/Users/yuan.chen/GolandProjects/src/volcano.sh/volcano/vendor/k8s.io/client-go/tools/cache/reflector.go:254 +0xc73
volcano.sh/volcano/vendor/k8s.io/client-go/tools/cache.(*Reflector).Run.func1()
	/Users/yuan.chen/GolandProjects/src/volcano.sh/volcano/vendor/k8s.io/client-go/tools/cache/reflector.go:124 +0x33
volcano.sh/volcano/vendor/k8s.io/apimachinery/pkg/util/wait.JitterUntil.func1(0xc00006f6f0)
	/Users/yuan.chen/GolandProjects/src/volcano.sh/volcano/vendor/k8s.io/apimachinery/pkg/util/wait/wait.go:133 +0x5e
volcano.sh/volcano/vendor/k8s.io/apimachinery/pkg/util/wait.JitterUntil(0xc000a4fef0, 0x3b9aca00, 0x0, 0x1, 0x0)
	/Users/yuan.chen/GolandProjects/src/volcano.sh/volcano/vendor/k8s.io/apimachinery/pkg/util/wait/wait.go:134 +0xf8
volcano.sh/volcano/vendor/k8s.io/apimachinery/pkg/util/wait.Until(...)
	/Users/yuan.chen/GolandProjects/src/volcano.sh/volcano/vendor/k8s.io/apimachinery/pkg/util/wait/wait.go:88
volcano.sh/volcano/vendor/k8s.io/client-go/tools/cache.(*Reflector).Run(0xc0003d60a0, 0x0)
	/Users/yuan.chen/GolandProjects/src/volcano.sh/volcano/vendor/k8s.io/client-go/tools/cache/reflector.go:123 +0x169
volcano.sh/volcano/vendor/k8s.io/apimachinery/pkg/util/wait.(*Group).StartWithChannel.func1()
	/Users/yuan.chen/GolandProjects/src/volcano.sh/volcano/vendor/k8s.io/apimachinery/pkg/util/wait/wait.go:54 +0x2e
volcano.sh/volcano/vendor/k8s.io/apimachinery/pkg/util/wait.(*Group).Start.func1(0xc000044b20, 0xc0000dc760)
	/Users/yuan.chen/GolandProjects/src/volcano.sh/volcano/vendor/k8s.io/apimachinery/pkg/util/wait/wait.go:71 +0x59
created by volcano.sh/volcano/vendor/k8s.io/apimachinery/pkg/util/wait.(*Group).Start
	/Users/yuan.chen/GolandProjects/src/volcano.sh/volcano/vendor/k8s.io/apimachinery/pkg/util/wait/wait.go:69 +0x62

goroutine 168 [select, 7 minutes]:
volcano.sh/volcano/vendor/k8s.io/client-go/tools/cache.(*Reflector).ListAndWatch.func1(0xc00051a000, 0x0, 0xc000188cc0, 0xc00070c840)
	/Users/yuan.chen/GolandProjects/src/volcano.sh/volcano/vendor/k8s.io/client-go/tools/cache/reflector.go:194 +0x178
created by volcano.sh/volcano/vendor/k8s.io/client-go/tools/cache.(*Reflector).ListAndWatch
	/Users/yuan.chen/GolandProjects/src/volcano.sh/volcano/vendor/k8s.io/client-go/tools/cache/reflector.go:188 +0x6fb

goroutine 318 [sync.Cond.Wait]:
runtime.goparkunlock(...)
	/usr/local/opt/go/libexec/src/runtime/proc.go:310
sync.runtime_notifyListWait(0xc000b0e2c0, 0x0)
	/usr/local/opt/go/libexec/src/runtime/sema.go:510 +0xf8
sync.(*Cond).Wait(0xc000b0e2b0)
	/usr/local/opt/go/libexec/src/sync/cond.go:56 +0x9d
volcano.sh/volcano/vendor/golang.org/x/net/http2.(*pipe).Read(0xc000b0e2a8, 0xc0004ae200, 0x200, 0x200, 0x0, 0x0, 0x0)
	/Users/yuan.chen/GolandProjects/src/volcano.sh/volcano/vendor/golang.org/x/net/http2/pipe.go:64 +0xa6
volcano.sh/volcano/vendor/golang.org/x/net/http2.transportResponseBody.Read(0xc000b0e280, 0xc0004ae200, 0x200, 0x200, 0x0, 0x0, 0x0)
	/Users/yuan.chen/GolandProjects/src/volcano.sh/volcano/vendor/golang.org/x/net/http2/transport.go:1952 +0xac
encoding/json.(*Decoder).refill(0xc000313760, 0xc0005522a0, 0x1d6a406)
	/usr/local/opt/go/libexec/src/encoding/json/stream.go:161 +0xeb
encoding/json.(*Decoder).readValue(0xc000313760, 0x0, 0x0, 0x1fbf8c0)
	/usr/local/opt/go/libexec/src/encoding/json/stream.go:136 +0x1dc
encoding/json.(*Decoder).Decode(0xc000313760, 0x1fd7a80, 0xc0005522a0, 0xc00052bce0, 0xc00003d7a0)
	/usr/local/opt/go/libexec/src/encoding/json/stream.go:63 +0x79
volcano.sh/volcano/vendor/k8s.io/apimachinery/pkg/util/framer.(*jsonFrameReader).Read(0xc000765230, 0xc000344400, 0x400, 0x400, 0x21a0dba, 0x4, 0x38)
	/Users/yuan.chen/GolandProjects/src/volcano.sh/volcano/vendor/k8s.io/apimachinery/pkg/util/framer/framer.go:150 +0x1a1
volcano.sh/volcano/vendor/k8s.io/apimachinery/pkg/runtime/serializer/streaming.(*decoder).Decode(0xc000180190, 0x0, 0x23a32e0, 0xc0004752c0, 0xc0001d6540, 0xc0008580c0, 0xc0000ee701, 0xc, 0x2f1cc80)
	/Users/yuan.chen/GolandProjects/src/volcano.sh/volcano/vendor/k8s.io/apimachinery/pkg/runtime/serializer/streaming/streaming.go:77 +0x89
volcano.sh/volcano/vendor/k8s.io/client-go/rest/watch.(*Decoder).Decode(0xc000552280, 0x2efe3c0, 0xc0006b6530, 0x0, 0x0, 0xc000b08507, 0x7)
	/Users/yuan.chen/GolandProjects/src/volcano.sh/volcano/vendor/k8s.io/client-go/rest/watch/decoder.go:49 +0x7c
volcano.sh/volcano/vendor/k8s.io/apimachinery/pkg/watch.(*StreamWatcher).receive(0xc000765260)
	/Users/yuan.chen/GolandProjects/src/volcano.sh/volcano/vendor/k8s.io/apimachinery/pkg/watch/streamwatcher.go:93 +0x175
created by volcano.sh/volcano/vendor/k8s.io/apimachinery/pkg/watch.NewStreamWatcher
	/Users/yuan.chen/GolandProjects/src/volcano.sh/volcano/vendor/k8s.io/apimachinery/pkg/watch/streamwatcher.go:60 +0x9f

goroutine 226 [sync.Cond.Wait, 5 minutes]:
runtime.goparkunlock(...)
	/usr/local/opt/go/libexec/src/runtime/proc.go:310
sync.runtime_notifyListWait(0xc0002b2400, 0xc000000024)
	/usr/local/opt/go/libexec/src/runtime/sema.go:510 +0xf8
sync.(*Cond).Wait(0xc0002b23f0)
	/usr/local/opt/go/libexec/src/sync/cond.go:56 +0x9d
volcano.sh/volcano/vendor/golang.org/x/net/http2.(*pipe).Read(0xc0002b23e8, 0xc000446001, 0x5ff, 0x5ff, 0x0, 0x0, 0x0)
	/Users/yuan.chen/GolandProjects/src/volcano.sh/volcano/vendor/golang.org/x/net/http2/pipe.go:64 +0xa6
volcano.sh/volcano/vendor/golang.org/x/net/http2.transportResponseBody.Read(0xc0002b23c0, 0xc000446001, 0x5ff, 0x5ff, 0x0, 0x0, 0x0)
	/Users/yuan.chen/GolandProjects/src/volcano.sh/volcano/vendor/golang.org/x/net/http2/transport.go:1952 +0xac
encoding/json.(*Decoder).refill(0xc00058e6e0, 0xc0007ea90a, 0x9)
	/usr/local/opt/go/libexec/src/encoding/json/stream.go:161 +0xeb
encoding/json.(*Decoder).readValue(0xc00058e6e0, 0x0, 0x0, 0x1fbf8c0)
	/usr/local/opt/go/libexec/src/encoding/json/stream.go:136 +0x1dc
encoding/json.(*Decoder).Decode(0xc00058e6e0, 0x1fd7a80, 0xc0007ea940, 0x0, 0x0)
	/usr/local/opt/go/libexec/src/encoding/json/stream.go:63 +0x79
volcano.sh/volcano/vendor/k8s.io/apimachinery/pkg/util/framer.(*jsonFrameReader).Read(0xc0004ba240, 0xc000344000, 0x400, 0x400, 0x239e6e0, 0x0, 0x38)
	/Users/yuan.chen/GolandProjects/src/volcano.sh/volcano/vendor/k8s.io/apimachinery/pkg/util/framer/framer.go:150 +0x1a1
volcano.sh/volcano/vendor/k8s.io/apimachinery/pkg/runtime/serializer/streaming.(*decoder).Decode(0xc0002fa410, 0x0, 0x23a32e0, 0xc0000afb40, 0x0, 0x0, 0x0, 0xc0000c2b38, 0x105aca0)
	/Users/yuan.chen/GolandProjects/src/volcano.sh/volcano/vendor/k8s.io/apimachinery/pkg/runtime/serializer/streaming/streaming.go:77 +0x89
volcano.sh/volcano/vendor/k8s.io/client-go/rest/watch.(*Decoder).Decode(0xc000923900, 0xc000721fa8, 0x7, 0x239e6e0, 0xc00085e900, 0x0, 0x0)
	/Users/yuan.chen/GolandProjects/src/volcano.sh/volcano/vendor/k8s.io/client-go/rest/watch/decoder.go:49 +0x7c
volcano.sh/volcano/vendor/k8s.io/apimachinery/pkg/watch.(*StreamWatcher).receive(0xc0004ba270)
	/Users/yuan.chen/GolandProjects/src/volcano.sh/volcano/vendor/k8s.io/apimachinery/pkg/watch/streamwatcher.go:93 +0x175
created by volcano.sh/volcano/vendor/k8s.io/apimachinery/pkg/watch.NewStreamWatcher
	/Users/yuan.chen/GolandProjects/src/volcano.sh/volcano/vendor/k8s.io/apimachinery/pkg/watch/streamwatcher.go:60 +0x9f

goroutine 144 [select, 7 minutes]:
volcano.sh/volcano/vendor/k8s.io/client-go/tools/cache.(*Reflector).ListAndWatch.func1(0xc00018c140, 0x0, 0xc00070e6c0, 0xc000549260)
	/Users/yuan.chen/GolandProjects/src/volcano.sh/volcano/vendor/k8s.io/client-go/tools/cache/reflector.go:194 +0x178
created by volcano.sh/volcano/vendor/k8s.io/client-go/tools/cache.(*Reflector).ListAndWatch
	/Users/yuan.chen/GolandProjects/src/volcano.sh/volcano/vendor/k8s.io/client-go/tools/cache/reflector.go:188 +0x6fb

goroutine 129 [select, 7 minutes]:
volcano.sh/volcano/vendor/k8s.io/client-go/tools/cache.(*Reflector).ListAndWatch.func1(0xc0003d6000, 0x0, 0xc0000c22a0, 0xc0000b0780)
	/Users/yuan.chen/GolandProjects/src/volcano.sh/volcano/vendor/k8s.io/client-go/tools/cache/reflector.go:194 +0x178
created by volcano.sh/volcano/vendor/k8s.io/client-go/tools/cache.(*Reflector).ListAndWatch
	/Users/yuan.chen/GolandProjects/src/volcano.sh/volcano/vendor/k8s.io/client-go/tools/cache/reflector.go:188 +0x6fb

goroutine 152 [select, 7 minutes]:
volcano.sh/volcano/vendor/k8s.io/client-go/tools/cache.(*Reflector).ListAndWatch.func1(0xc0001c8c80, 0x0, 0xc0003a8600, 0xc0000b0f00)
	/Users/yuan.chen/GolandProjects/src/volcano.sh/volcano/vendor/k8s.io/client-go/tools/cache/reflector.go:194 +0x178
created by volcano.sh/volcano/vendor/k8s.io/client-go/tools/cache.(*Reflector).ListAndWatch
	/Users/yuan.chen/GolandProjects/src/volcano.sh/volcano/vendor/k8s.io/client-go/tools/cache/reflector.go:188 +0x6fb

goroutine 78 [select, 7 minutes]:
volcano.sh/volcano/vendor/k8s.io/client-go/tools/cache.(*Reflector).ListAndWatch.func1(0xc00030c000, 0x0, 0xc0000c2540, 0xc0007025a0)
	/Users/yuan.chen/GolandProjects/src/volcano.sh/volcano/vendor/k8s.io/client-go/tools/cache/reflector.go:194 +0x178
created by volcano.sh/volcano/vendor/k8s.io/client-go/tools/cache.(*Reflector).ListAndWatch
	/Users/yuan.chen/GolandProjects/src/volcano.sh/volcano/vendor/k8s.io/client-go/tools/cache/reflector.go:188 +0x6fb

goroutine 169 [select, 7 minutes]:
volcano.sh/volcano/vendor/k8s.io/client-go/tools/cache.(*Reflector).ListAndWatch.func1(0xc000410000, 0x0, 0xc000188d20, 0xc00070c960)
	/Users/yuan.chen/GolandProjects/src/volcano.sh/volcano/vendor/k8s.io/client-go/tools/cache/reflector.go:194 +0x178
created by volcano.sh/volcano/vendor/k8s.io/client-go/tools/cache.(*Reflector).ListAndWatch
	/Users/yuan.chen/GolandProjects/src/volcano.sh/volcano/vendor/k8s.io/client-go/tools/cache/reflector.go:188 +0x6fb

goroutine 145 [select, 7 minutes]:
volcano.sh/volcano/vendor/k8s.io/client-go/tools/cache.(*Reflector).ListAndWatch.func1(0xc0003320a0, 0x0, 0xc00070e720, 0xc0005494a0)
	/Users/yuan.chen/GolandProjects/src/volcano.sh/volcano/vendor/k8s.io/client-go/tools/cache/reflector.go:194 +0x178
created by volcano.sh/volcano/vendor/k8s.io/client-go/tools/cache.(*Reflector).ListAndWatch
	/Users/yuan.chen/GolandProjects/src/volcano.sh/volcano/vendor/k8s.io/client-go/tools/cache/reflector.go:188 +0x6fb

goroutine 170 [select, 7 minutes]:
volcano.sh/volcano/vendor/k8s.io/client-go/tools/cache.(*Reflector).ListAndWatch.func1(0xc000332000, 0x0, 0xc0003a8180, 0xc0000e6ba0)
	/Users/yuan.chen/GolandProjects/src/volcano.sh/volcano/vendor/k8s.io/client-go/tools/cache/reflector.go:194 +0x178
created by volcano.sh/volcano/vendor/k8s.io/client-go/tools/cache.(*Reflector).ListAndWatch
	/Users/yuan.chen/GolandProjects/src/volcano.sh/volcano/vendor/k8s.io/client-go/tools/cache/reflector.go:188 +0x6fb

goroutine 210 [select, 7 minutes]:
volcano.sh/volcano/vendor/k8s.io/client-go/tools/cache.(*Reflector).ListAndWatch.func1(0xc000104960, 0x0, 0xc000635140, 0xc0005499e0)
	/Users/yuan.chen/GolandProjects/src/volcano.sh/volcano/vendor/k8s.io/client-go/tools/cache/reflector.go:194 +0x178
created by volcano.sh/volcano/vendor/k8s.io/client-go/tools/cache.(*Reflector).ListAndWatch
	/Users/yuan.chen/GolandProjects/src/volcano.sh/volcano/vendor/k8s.io/client-go/tools/cache/reflector.go:188 +0x6fb

goroutine 153 [select, 7 minutes]:
volcano.sh/volcano/vendor/k8s.io/client-go/tools/cache.(*Reflector).ListAndWatch.func1(0xc0001c8a00, 0x0, 0xc00070ea80, 0xc000703080)
	/Users/yuan.chen/GolandProjects/src/volcano.sh/volcano/vendor/k8s.io/client-go/tools/cache/reflector.go:194 +0x178
created by volcano.sh/volcano/vendor/k8s.io/client-go/tools/cache.(*Reflector).ListAndWatch
	/Users/yuan.chen/GolandProjects/src/volcano.sh/volcano/vendor/k8s.io/client-go/tools/cache/reflector.go:188 +0x6fb

goroutine 79 [select, 7 minutes]:
volcano.sh/volcano/vendor/k8s.io/client-go/tools/cache.(*Reflector).ListAndWatch.func1(0xc000104000, 0x0, 0xc000130de0, 0xc000501560)
	/Users/yuan.chen/GolandProjects/src/volcano.sh/volcano/vendor/k8s.io/client-go/tools/cache/reflector.go:194 +0x178
created by volcano.sh/volcano/vendor/k8s.io/client-go/tools/cache.(*Reflector).ListAndWatch
	/Users/yuan.chen/GolandProjects/src/volcano.sh/volcano/vendor/k8s.io/client-go/tools/cache/reflector.go:188 +0x6fb

goroutine 174 [select]:
volcano.sh/volcano/vendor/k8s.io/apimachinery/pkg/util/wait.JitterUntil(0xc000934fe0, 0x12a05f200, 0x0, 0x69433759354f0a01, 0x0)
	/Users/yuan.chen/GolandProjects/src/volcano.sh/volcano/vendor/k8s.io/apimachinery/pkg/util/wait/wait.go:145 +0x181
volcano.sh/volcano/vendor/k8s.io/apimachinery/pkg/util/wait.Until(0xc000934fe0, 0x12a05f200, 0x0)
	/Users/yuan.chen/GolandProjects/src/volcano.sh/volcano/vendor/k8s.io/apimachinery/pkg/util/wait/wait.go:88 +0x4d
created by volcano.sh/volcano/pkg/scheduler.(*Scheduler).Run
	/Users/yuan.chen/GolandProjects/src/volcano.sh/volcano/pkg/scheduler/scheduler.go:68 +0xd4

goroutine 172 [sync.Cond.Wait, 7 minutes]:
runtime.goparkunlock(...)
	/usr/local/opt/go/libexec/src/runtime/proc.go:310
sync.runtime_notifyListWait(0xc000328a40, 0x0)
	/usr/local/opt/go/libexec/src/runtime/sema.go:510 +0xf8
sync.(*Cond).Wait(0xc000328a30)
	/usr/local/opt/go/libexec/src/sync/cond.go:56 +0x9d
volcano.sh/volcano/vendor/golang.org/x/net/http2.(*pipe).Read(0xc000328a28, 0xc000788200, 0x200, 0x200, 0x0, 0x0, 0x0)
	/Users/yuan.chen/GolandProjects/src/volcano.sh/volcano/vendor/golang.org/x/net/http2/pipe.go:64 +0xa6
volcano.sh/volcano/vendor/golang.org/x/net/http2.transportResponseBody.Read(0xc000328a00, 0xc000788200, 0x200, 0x200, 0x0, 0x0, 0x0)
	/Users/yuan.chen/GolandProjects/src/volcano.sh/volcano/vendor/golang.org/x/net/http2/transport.go:1952 +0xac
encoding/json.(*Decoder).refill(0xc00078c160, 0xc00093f060, 0x4230773947696b68)
	/usr/local/opt/go/libexec/src/encoding/json/stream.go:161 +0xeb
encoding/json.(*Decoder).readValue(0xc00078c160, 0x0, 0x0, 0x1fbf8c0)
	/usr/local/opt/go/libexec/src/encoding/json/stream.go:136 +0x1dc
encoding/json.(*Decoder).Decode(0xc00078c160, 0x1fd7a80, 0xc00093f060, 0x750a50704b414245, 0x474c46786c754838)
	/usr/local/opt/go/libexec/src/encoding/json/stream.go:63 +0x79
volcano.sh/volcano/vendor/k8s.io/apimachinery/pkg/util/framer.(*jsonFrameReader).Read(0xc00095aff0, 0xc000a3e400, 0x400, 0x400, 0x7a30445832797953, 0x754f62714453, 0x38)
	/Users/yuan.chen/GolandProjects/src/volcano.sh/volcano/vendor/k8s.io/apimachinery/pkg/util/framer/framer.go:150 +0x1a1
volcano.sh/volcano/vendor/k8s.io/apimachinery/pkg/runtime/serializer/streaming.(*decoder).Decode(0xc000964190, 0x0, 0x23a32e0, 0xc0008ea840, 0x7035364f46534459, 0x62734c6532426455, 0x4e39307a634e7357, 0x47706474544d4154, 0x51354f6e0a6b6d53)
	/Users/yuan.chen/GolandProjects/src/volcano.sh/volcano/vendor/k8s.io/apimachinery/pkg/runtime/serializer/streaming/streaming.go:77 +0x89
volcano.sh/volcano/vendor/k8s.io/client-go/rest/watch.(*Decoder).Decode(0xc00093f040, 0x4e67425041544144, 0x386641424d524856, 0x4851414441544245, 0x7153434730414d2f, 0x51440a3362495347, 0x14eab96)
	/Users/yuan.chen/GolandProjects/src/volcano.sh/volcano/vendor/k8s.io/client-go/rest/watch/decoder.go:49 +0x7c
volcano.sh/volcano/vendor/k8s.io/apimachinery/pkg/watch.(*StreamWatcher).receive(0xc00095b020)
	/Users/yuan.chen/GolandProjects/src/volcano.sh/volcano/vendor/k8s.io/apimachinery/pkg/watch/streamwatcher.go:93 +0x175
created by volcano.sh/volcano/vendor/k8s.io/apimachinery/pkg/watch.NewStreamWatcher
	/Users/yuan.chen/GolandProjects/src/volcano.sh/volcano/vendor/k8s.io/apimachinery/pkg/watch/streamwatcher.go:60 +0x9f

goroutine 242 [sync.Cond.Wait, 7 minutes]:
runtime.goparkunlock(...)
	/usr/local/opt/go/libexec/src/runtime/proc.go:310
sync.runtime_notifyListWait(0xc000328680, 0x0)
	/usr/local/opt/go/libexec/src/runtime/sema.go:510 +0xf8
sync.(*Cond).Wait(0xc000328670)
	/usr/local/opt/go/libexec/src/sync/cond.go:56 +0x9d
volcano.sh/volcano/vendor/golang.org/x/net/http2.(*pipe).Read(0xc000328668, 0xc000786200, 0x200, 0x200, 0x0, 0x0, 0x0)
	/Users/yuan.chen/GolandProjects/src/volcano.sh/volcano/vendor/golang.org/x/net/http2/pipe.go:64 +0xa6
volcano.sh/volcano/vendor/golang.org/x/net/http2.transportResponseBody.Read(0xc000328640, 0xc000786200, 0x200, 0x200, 0x0, 0x0, 0x0)
	/Users/yuan.chen/GolandProjects/src/volcano.sh/volcano/vendor/golang.org/x/net/http2/transport.go:1952 +0xac
encoding/json.(*Decoder).refill(0xc0001c51e0, 0xc000846500, 0x40010000000000)
	/usr/local/opt/go/libexec/src/encoding/json/stream.go:161 +0xeb
encoding/json.(*Decoder).readValue(0xc0001c51e0, 0x0, 0x0, 0x1fbf8c0)
	/usr/local/opt/go/libexec/src/encoding/json/stream.go:136 +0x1dc
encoding/json.(*Decoder).Decode(0xc0001c51e0, 0x1fd7a80, 0xc000846500, 0x68a0f48, 0x0)
	/usr/local/opt/go/libexec/src/encoding/json/stream.go:63 +0x79
volcano.sh/volcano/vendor/k8s.io/apimachinery/pkg/util/framer.(*jsonFrameReader).Read(0xc000844810, 0xc00013cc00, 0x400, 0x400, 0x1, 0x1000000000000, 0x38)
	/Users/yuan.chen/GolandProjects/src/volcano.sh/volcano/vendor/k8s.io/apimachinery/pkg/util/framer/framer.go:150 +0x1a1
volcano.sh/volcano/vendor/k8s.io/apimachinery/pkg/runtime/serializer/streaming.(*decoder).Decode(0xc00012a3c0, 0x0, 0x23a32e0, 0xc000a1c000, 0x0, 0x0, 0x0, 0x0, 0x0)
	/Users/yuan.chen/GolandProjects/src/volcano.sh/volcano/vendor/k8s.io/apimachinery/pkg/runtime/serializer/streaming/streaming.go:77 +0x89
volcano.sh/volcano/vendor/k8s.io/client-go/rest/watch.(*Decoder).Decode(0xc0008464e0, 0x0, 0x0, 0x0, 0x0, 0x0, 0x0)
	/Users/yuan.chen/GolandProjects/src/volcano.sh/volcano/vendor/k8s.io/client-go/rest/watch/decoder.go:49 +0x7c
volcano.sh/volcano/vendor/k8s.io/apimachinery/pkg/watch.(*StreamWatcher).receive(0xc000844840)
	/Users/yuan.chen/GolandProjects/src/volcano.sh/volcano/vendor/k8s.io/apimachinery/pkg/watch/streamwatcher.go:93 +0x175
created by volcano.sh/volcano/vendor/k8s.io/apimachinery/pkg/watch.NewStreamWatcher
	/Users/yuan.chen/GolandProjects/src/volcano.sh/volcano/vendor/k8s.io/apimachinery/pkg/watch/streamwatcher.go:60 +0x9f

goroutine 236 [sync.Cond.Wait]:
runtime.goparkunlock(...)
	/usr/local/opt/go/libexec/src/runtime/proc.go:310
sync.runtime_notifyListWait(0xc000140040, 0xc000000007)
	/usr/local/opt/go/libexec/src/runtime/sema.go:510 +0xf8
sync.(*Cond).Wait(0xc000140030)
	/usr/local/opt/go/libexec/src/sync/cond.go:56 +0x9d
volcano.sh/volcano/vendor/golang.org/x/net/http2.(*pipe).Read(0xc000140028, 0xc0007ec001, 0x1dff, 0x1dff, 0x0, 0x0, 0x0)
	/Users/yuan.chen/GolandProjects/src/volcano.sh/volcano/vendor/golang.org/x/net/http2/pipe.go:64 +0xa6
volcano.sh/volcano/vendor/golang.org/x/net/http2.transportResponseBody.Read(0xc000140000, 0xc0007ec001, 0x1dff, 0x1dff, 0x0, 0x0, 0x0)
	/Users/yuan.chen/GolandProjects/src/volcano.sh/volcano/vendor/golang.org/x/net/http2/transport.go:1952 +0xac
encoding/json.(*Decoder).refill(0xc00058fce0, 0xc0004a590a, 0x9)
	/usr/local/opt/go/libexec/src/encoding/json/stream.go:161 +0xeb
encoding/json.(*Decoder).readValue(0xc00058fce0, 0x0, 0x0, 0x1fbf8c0)
	/usr/local/opt/go/libexec/src/encoding/json/stream.go:136 +0x1dc
encoding/json.(*Decoder).Decode(0xc00058fce0, 0x1fd7a80, 0xc0004a5960, 0x0, 0x0)
	/usr/local/opt/go/libexec/src/encoding/json/stream.go:63 +0x79
volcano.sh/volcano/vendor/k8s.io/apimachinery/pkg/util/framer.(*jsonFrameReader).Read(0xc0004baa80, 0xc00080a000, 0x2000, 0x2600, 0x23a16e0, 0x0, 0x38)
	/Users/yuan.chen/GolandProjects/src/volcano.sh/volcano/vendor/k8s.io/apimachinery/pkg/util/framer/framer.go:150 +0x1a1
volcano.sh/volcano/vendor/k8s.io/apimachinery/pkg/runtime/serializer/streaming.(*decoder).Decode(0xc0002fa780, 0x0, 0x23a32e0, 0xc000aa0a40, 0x0, 0x0, 0x0, 0xc0000c2b98, 0x105aca0)
	/Users/yuan.chen/GolandProjects/src/volcano.sh/volcano/vendor/k8s.io/apimachinery/pkg/runtime/serializer/streaming/streaming.go:77 +0x89
volcano.sh/volcano/vendor/k8s.io/client-go/rest/watch.(*Decoder).Decode(0xc000923960, 0xc0006b5fa8, 0x8, 0x23a16e0, 0xc0001102c0, 0x0, 0x0)
	/Users/yuan.chen/GolandProjects/src/volcano.sh/volcano/vendor/k8s.io/client-go/rest/watch/decoder.go:49 +0x7c
volcano.sh/volcano/vendor/k8s.io/apimachinery/pkg/watch.(*StreamWatcher).receive(0xc0004baae0)
	/Users/yuan.chen/GolandProjects/src/volcano.sh/volcano/vendor/k8s.io/apimachinery/pkg/watch/streamwatcher.go:93 +0x175
created by volcano.sh/volcano/vendor/k8s.io/apimachinery/pkg/watch.NewStreamWatcher
	/Users/yuan.chen/GolandProjects/src/volcano.sh/volcano/vendor/k8s.io/apimachinery/pkg/watch/streamwatcher.go:60 +0x9f

goroutine 93 [sync.Cond.Wait, 7 minutes]:
runtime.goparkunlock(...)
	/usr/local/opt/go/libexec/src/runtime/proc.go:310
sync.runtime_notifyListWait(0xc0001ca040, 0x0)
	/usr/local/opt/go/libexec/src/runtime/sema.go:510 +0xf8
sync.(*Cond).Wait(0xc0001ca030)
	/usr/local/opt/go/libexec/src/sync/cond.go:56 +0x9d
volcano.sh/volcano/vendor/golang.org/x/net/http2.(*pipe).Read(0xc0001ca028, 0xc000a68000, 0x200, 0x200, 0x0, 0x0, 0x0)
	/Users/yuan.chen/GolandProjects/src/volcano.sh/volcano/vendor/golang.org/x/net/http2/pipe.go:64 +0xa6
volcano.sh/volcano/vendor/golang.org/x/net/http2.transportResponseBody.Read(0xc0001ca000, 0xc000a68000, 0x200, 0x200, 0x0, 0x0, 0x0)
	/Users/yuan.chen/GolandProjects/src/volcano.sh/volcano/vendor/golang.org/x/net/http2/transport.go:1952 +0xac
encoding/json.(*Decoder).refill(0xc000580160, 0xc000a54020, 0x40010000000000)
	/usr/local/opt/go/libexec/src/encoding/json/stream.go:161 +0xeb
encoding/json.(*Decoder).readValue(0xc000580160, 0x0, 0x0, 0x1fbf8c0)
	/usr/local/opt/go/libexec/src/encoding/json/stream.go:136 +0x1dc
encoding/json.(*Decoder).Decode(0xc000580160, 0x1fd7a80, 0xc000a54020, 0x68a1b80, 0x0)
	/usr/local/opt/go/libexec/src/encoding/json/stream.go:63 +0x79
volcano.sh/volcano/vendor/k8s.io/apimachinery/pkg/util/framer.(*jsonFrameReader).Read(0xc000a46000, 0xc000a50000, 0x400, 0x400, 0x1, 0x1000000000000, 0x38)
	/Users/yuan.chen/GolandProjects/src/volcano.sh/volcano/vendor/k8s.io/apimachinery/pkg/util/framer/framer.go:150 +0x1a1
volcano.sh/volcano/vendor/k8s.io/apimachinery/pkg/runtime/serializer/streaming.(*decoder).Decode(0xc000180140, 0x0, 0x23a32e0, 0xc000a5c000, 0x0, 0x0, 0x0, 0x0, 0x0)
	/Users/yuan.chen/GolandProjects/src/volcano.sh/volcano/vendor/k8s.io/apimachinery/pkg/runtime/serializer/streaming/streaming.go:77 +0x89
volcano.sh/volcano/vendor/k8s.io/client-go/rest/watch.(*Decoder).Decode(0xc000a54000, 0x0, 0x0, 0x0, 0x0, 0x0, 0x0)
	/Users/yuan.chen/GolandProjects/src/volcano.sh/volcano/vendor/k8s.io/client-go/rest/watch/decoder.go:49 +0x7c
volcano.sh/volcano/vendor/k8s.io/apimachinery/pkg/watch.(*StreamWatcher).receive(0xc000a46030)
	/Users/yuan.chen/GolandProjects/src/volcano.sh/volcano/vendor/k8s.io/apimachinery/pkg/watch/streamwatcher.go:93 +0x175
created by volcano.sh/volcano/vendor/k8s.io/apimachinery/pkg/watch.NewStreamWatcher
	/Users/yuan.chen/GolandProjects/src/volcano.sh/volcano/vendor/k8s.io/apimachinery/pkg/watch/streamwatcher.go:60 +0x9f

goroutine 154 [select, 7 minutes]:
volcano.sh/volcano/vendor/k8s.io/client-go/tools/cache.(*Reflector).ListAndWatch.func1(0xc0003d60a0, 0x0, 0xc000aa90e0, 0xc00070dc20)
	/Users/yuan.chen/GolandProjects/src/volcano.sh/volcano/vendor/k8s.io/client-go/tools/cache/reflector.go:194 +0x178
created by volcano.sh/volcano/vendor/k8s.io/client-go/tools/cache.(*Reflector).ListAndWatch
	/Users/yuan.chen/GolandProjects/src/volcano.sh/volcano/vendor/k8s.io/client-go/tools/cache/reflector.go:188 +0x6fb

goroutine 173 [sync.Cond.Wait, 5 minutes]:
runtime.goparkunlock(...)
	/usr/local/opt/go/libexec/src/runtime/proc.go:310
sync.runtime_notifyListWait(0xc000b0e180, 0xc00000000c)
	/usr/local/opt/go/libexec/src/runtime/sema.go:510 +0xf8
sync.(*Cond).Wait(0xc000b0e170)
	/usr/local/opt/go/libexec/src/sync/cond.go:56 +0x9d
volcano.sh/volcano/vendor/golang.org/x/net/http2.(*pipe).Read(0xc000b0e168, 0xc00016e001, 0xdff, 0xdff, 0x0, 0x0, 0x0)
	/Users/yuan.chen/GolandProjects/src/volcano.sh/volcano/vendor/golang.org/x/net/http2/pipe.go:64 +0xa6
volcano.sh/volcano/vendor/golang.org/x/net/http2.transportResponseBody.Read(0xc000b0e140, 0xc00016e001, 0xdff, 0xdff, 0x0, 0x0, 0x0)
	/Users/yuan.chen/GolandProjects/src/volcano.sh/volcano/vendor/golang.org/x/net/http2/transport.go:1952 +0xac
encoding/json.(*Decoder).refill(0xc00078c2c0, 0xc0007eb10a, 0x9)
	/usr/local/opt/go/libexec/src/encoding/json/stream.go:161 +0xeb
encoding/json.(*Decoder).readValue(0xc00078c2c0, 0x0, 0x0, 0x1fbf8c0)
	/usr/local/opt/go/libexec/src/encoding/json/stream.go:136 +0x1dc
encoding/json.(*Decoder).Decode(0xc00078c2c0, 0x1fd7a80, 0xc0007eb1c0, 0x0, 0x0)
	/usr/local/opt/go/libexec/src/encoding/json/stream.go:63 +0x79
volcano.sh/volcano/vendor/k8s.io/apimachinery/pkg/util/framer.(*jsonFrameReader).Read(0xc00095b080, 0xc0007eea80, 0x800, 0xa80, 0x23a1920, 0x0, 0x38)
	/Users/yuan.chen/GolandProjects/src/volcano.sh/volcano/vendor/k8s.io/apimachinery/pkg/util/framer/framer.go:150 +0x1a1
volcano.sh/volcano/vendor/k8s.io/apimachinery/pkg/runtime/serializer/streaming.(*decoder).Decode(0xc0009641e0, 0x0, 0x23a32e0, 0xc0000aff80, 0x0, 0x0, 0x0, 0xc0003a82f8, 0x105aca0)
	/Users/yuan.chen/GolandProjects/src/volcano.sh/volcano/vendor/k8s.io/apimachinery/pkg/runtime/serializer/streaming/streaming.go:77 +0x89
volcano.sh/volcano/vendor/k8s.io/client-go/rest/watch.(*Decoder).Decode(0xc00093f7c0, 0xc000a2dfa8, 0x7, 0x23a1920, 0xc0008fc700, 0x0, 0x0)
	/Users/yuan.chen/GolandProjects/src/volcano.sh/volcano/vendor/k8s.io/client-go/rest/watch/decoder.go:49 +0x7c
volcano.sh/volcano/vendor/k8s.io/apimachinery/pkg/watch.(*StreamWatcher).receive(0xc00095b0b0)
	/Users/yuan.chen/GolandProjects/src/volcano.sh/volcano/vendor/k8s.io/apimachinery/pkg/watch/streamwatcher.go:93 +0x175
created by volcano.sh/volcano/vendor/k8s.io/apimachinery/pkg/watch.NewStreamWatcher
	/Users/yuan.chen/GolandProjects/src/volcano.sh/volcano/vendor/k8s.io/apimachinery/pkg/watch/streamwatcher.go:60 +0x9f

goroutine 377 [sync.Cond.Wait, 3 minutes]:
runtime.goparkunlock(...)
	/usr/local/opt/go/libexec/src/runtime/proc.go:310
sync.runtime_notifyListWait(0xc0002b27c0, 0xc000000000)
	/usr/local/opt/go/libexec/src/runtime/sema.go:510 +0xf8
sync.(*Cond).Wait(0xc0002b27b0)
	/usr/local/opt/go/libexec/src/sync/cond.go:56 +0x9d
volcano.sh/volcano/vendor/golang.org/x/net/http2.(*pipe).Read(0xc0002b27a8, 0xc000a53000, 0x200, 0x200, 0x0, 0x0, 0x0)
	/Users/yuan.chen/GolandProjects/src/volcano.sh/volcano/vendor/golang.org/x/net/http2/pipe.go:64 +0xa6
volcano.sh/volcano/vendor/golang.org/x/net/http2.transportResponseBody.Read(0xc0002b2780, 0xc000a53000, 0x200, 0x200, 0x0, 0x0, 0x0)
	/Users/yuan.chen/GolandProjects/src/volcano.sh/volcano/vendor/golang.org/x/net/http2/transport.go:1952 +0xac
encoding/json.(*Decoder).refill(0xc000312160, 0xc000a1ae00, 0x40010000000000)
	/usr/local/opt/go/libexec/src/encoding/json/stream.go:161 +0xeb
encoding/json.(*Decoder).readValue(0xc000312160, 0x0, 0x0, 0x1fbf8c0)
	/usr/local/opt/go/libexec/src/encoding/json/stream.go:136 +0x1dc
encoding/json.(*Decoder).Decode(0xc000312160, 0x1fd7a80, 0xc000a1ae00, 0x68a0f48, 0x0)
	/usr/local/opt/go/libexec/src/encoding/json/stream.go:63 +0x79
volcano.sh/volcano/vendor/k8s.io/apimachinery/pkg/util/framer.(*jsonFrameReader).Read(0xc000a0a330, 0xc00013dc00, 0x400, 0x400, 0x1, 0x0, 0x38)
	/Users/yuan.chen/GolandProjects/src/volcano.sh/volcano/vendor/k8s.io/apimachinery/pkg/util/framer/framer.go:150 +0x1a1
volcano.sh/volcano/vendor/k8s.io/apimachinery/pkg/runtime/serializer/streaming.(*decoder).Decode(0xc000964050, 0x0, 0x23a32e0, 0xc0000c1100, 0x0, 0x0, 0x0, 0x0, 0x0)
	/Users/yuan.chen/GolandProjects/src/volcano.sh/volcano/vendor/k8s.io/apimachinery/pkg/runtime/serializer/streaming/streaming.go:77 +0x89
volcano.sh/volcano/vendor/k8s.io/client-go/rest/watch.(*Decoder).Decode(0xc000a1ada0, 0x0, 0x0, 0x0, 0x0, 0x0, 0x0)
	/Users/yuan.chen/GolandProjects/src/volcano.sh/volcano/vendor/k8s.io/client-go/rest/watch/decoder.go:49 +0x7c
volcano.sh/volcano/vendor/k8s.io/apimachinery/pkg/watch.(*StreamWatcher).receive(0xc000a0a420)
	/Users/yuan.chen/GolandProjects/src/volcano.sh/volcano/vendor/k8s.io/apimachinery/pkg/watch/streamwatcher.go:93 +0x175
created by volcano.sh/volcano/vendor/k8s.io/apimachinery/pkg/watch.NewStreamWatcher
	/Users/yuan.chen/GolandProjects/src/volcano.sh/volcano/vendor/k8s.io/apimachinery/pkg/watch/streamwatcher.go:60 +0x9f

goroutine 341 [sync.Cond.Wait, 3 minutes]:
runtime.goparkunlock(...)
	/usr/local/opt/go/libexec/src/runtime/proc.go:310
sync.runtime_notifyListWait(0xc00019d800, 0x0)
	/usr/local/opt/go/libexec/src/runtime/sema.go:510 +0xf8
sync.(*Cond).Wait(0xc00019d7f0)
	/usr/local/opt/go/libexec/src/sync/cond.go:56 +0x9d
volcano.sh/volcano/vendor/golang.org/x/net/http2.(*pipe).Read(0xc00019d7e8, 0xc000788600, 0x200, 0x200, 0x0, 0x0, 0x0)
	/Users/yuan.chen/GolandProjects/src/volcano.sh/volcano/vendor/golang.org/x/net/http2/pipe.go:64 +0xa6
volcano.sh/volcano/vendor/golang.org/x/net/http2.transportResponseBody.Read(0xc00019d7c0, 0xc000788600, 0x200, 0x200, 0x0, 0x0, 0x0)
	/Users/yuan.chen/GolandProjects/src/volcano.sh/volcano/vendor/golang.org/x/net/http2/transport.go:1952 +0xac
encoding/json.(*Decoder).refill(0xc0002d8000, 0xc0009e8160, 0x0)
	/usr/local/opt/go/libexec/src/encoding/json/stream.go:161 +0xeb
encoding/json.(*Decoder).readValue(0xc0002d8000, 0x0, 0x0, 0x1fbf8c0)
	/usr/local/opt/go/libexec/src/encoding/json/stream.go:136 +0x1dc
encoding/json.(*Decoder).Decode(0xc0002d8000, 0x1fd7a80, 0xc0009e8160, 0x0, 0x0)
	/usr/local/opt/go/libexec/src/encoding/json/stream.go:63 +0x79
volcano.sh/volcano/vendor/k8s.io/apimachinery/pkg/util/framer.(*jsonFrameReader).Read(0xc0007791a0, 0xc000a40400, 0x400, 0x400, 0x0, 0x0, 0x38)
	/Users/yuan.chen/GolandProjects/src/volcano.sh/volcano/vendor/k8s.io/apimachinery/pkg/util/framer/framer.go:150 +0x1a1
volcano.sh/volcano/vendor/k8s.io/apimachinery/pkg/runtime/serializer/streaming.(*decoder).Decode(0xc0001861e0, 0x0, 0x23a32e0, 0xc0000aeb80, 0x4745422d2d2d2d2d, 0x5020415352204e49, 0x4b20455441564952, 0xa2d2d2d2d2d5945, 0x4249676f4549494d)
	/Users/yuan.chen/GolandProjects/src/volcano.sh/volcano/vendor/k8s.io/apimachinery/pkg/runtime/serializer/streaming/streaming.go:77 +0x89
volcano.sh/volcano/vendor/k8s.io/client-go/rest/watch.(*Decoder).Decode(0xc0009e8140, 0x685872565735564f, 0x746346794d4e7476, 0x6a656f6748325a77, 0x4c56556a6c773853, 0x5530336676540a44, 0x79595849372b4d6b)
	/Users/yuan.chen/GolandProjects/src/volcano.sh/volcano/vendor/k8s.io/client-go/rest/watch/decoder.go:49 +0x7c
volcano.sh/volcano/vendor/k8s.io/apimachinery/pkg/watch.(*StreamWatcher).receive(0xc000779200)
	/Users/yuan.chen/GolandProjects/src/volcano.sh/volcano/vendor/k8s.io/apimachinery/pkg/watch/streamwatcher.go:93 +0x175
created by volcano.sh/volcano/vendor/k8s.io/apimachinery/pkg/watch.NewStreamWatcher
	/Users/yuan.chen/GolandProjects/src/volcano.sh/volcano/vendor/k8s.io/apimachinery/pkg/watch/streamwatcher.go:60 +0x9f

goroutine 342 [sync.Cond.Wait]:
runtime.goparkunlock(...)
	/usr/local/opt/go/libexec/src/runtime/proc.go:310
sync.runtime_notifyListWait(0xc0002b2540, 0x0)
	/usr/local/opt/go/libexec/src/runtime/sema.go:510 +0xf8
sync.(*Cond).Wait(0xc0002b2530)
	/usr/local/opt/go/libexec/src/sync/cond.go:56 +0x9d
volcano.sh/volcano/vendor/golang.org/x/net/http2.(*pipe).Read(0xc0002b2528, 0xc000788000, 0x200, 0x200, 0x0, 0x0, 0x0)
	/Users/yuan.chen/GolandProjects/src/volcano.sh/volcano/vendor/golang.org/x/net/http2/pipe.go:64 +0xa6
volcano.sh/volcano/vendor/golang.org/x/net/http2.transportResponseBody.Read(0xc0002b2500, 0xc000788000, 0x200, 0x200, 0x0, 0x0, 0x0)
	/Users/yuan.chen/GolandProjects/src/volcano.sh/volcano/vendor/golang.org/x/net/http2/transport.go:1952 +0xac
encoding/json.(*Decoder).refill(0xc0001c4160, 0xc000790020, 0x0)
	/usr/local/opt/go/libexec/src/encoding/json/stream.go:161 +0xeb
encoding/json.(*Decoder).readValue(0xc0001c4160, 0x0, 0x0, 0x1fbf8c0)
	/usr/local/opt/go/libexec/src/encoding/json/stream.go:136 +0x1dc
encoding/json.(*Decoder).Decode(0xc0001c4160, 0x1fd7a80, 0xc000790020, 0x68a1058, 0x5)
	/usr/local/opt/go/libexec/src/encoding/json/stream.go:63 +0x79
volcano.sh/volcano/vendor/k8s.io/apimachinery/pkg/util/framer.(*jsonFrameReader).Read(0xc000798000, 0xc000a40800, 0x400, 0x400, 0x1, 0x1000000000000, 0x38)
	/Users/yuan.chen/GolandProjects/src/volcano.sh/volcano/vendor/k8s.io/apimachinery/pkg/util/framer/framer.go:150 +0x1a1
volcano.sh/volcano/vendor/k8s.io/apimachinery/pkg/runtime/serializer/streaming.(*decoder).Decode(0xc00012a230, 0x0, 0x23a32e0, 0xc000a20140, 0x0, 0x0, 0x18, 0xc000660df8, 0x13a6000)
	/Users/yuan.chen/GolandProjects/src/volcano.sh/volcano/vendor/k8s.io/apimachinery/pkg/runtime/serializer/streaming/streaming.go:77 +0x89
volcano.sh/volcano/vendor/k8s.io/client-go/rest/watch.(*Decoder).Decode(0xc000790000, 0x0, 0xc000097800, 0x3393f80, 0x0, 0xdf8475800, 0x14eab96)
	/Users/yuan.chen/GolandProjects/src/volcano.sh/volcano/vendor/k8s.io/client-go/rest/watch/decoder.go:49 +0x7c
volcano.sh/volcano/vendor/k8s.io/apimachinery/pkg/watch.(*StreamWatcher).receive(0xc000798030)
	/Users/yuan.chen/GolandProjects/src/volcano.sh/volcano/vendor/k8s.io/apimachinery/pkg/watch/streamwatcher.go:93 +0x175
created by volcano.sh/volcano/vendor/k8s.io/apimachinery/pkg/watch.NewStreamWatcher
	/Users/yuan.chen/GolandProjects/src/volcano.sh/volcano/vendor/k8s.io/apimachinery/pkg/watch/streamwatcher.go:60 +0x9f

goroutine 363 [sync.Cond.Wait]:
runtime.goparkunlock(...)
	/usr/local/opt/go/libexec/src/runtime/proc.go:310
sync.runtime_notifyListWait(0xc00019d940, 0x0)
	/usr/local/opt/go/libexec/src/runtime/sema.go:510 +0xf8
sync.(*Cond).Wait(0xc00019d930)
	/usr/local/opt/go/libexec/src/sync/cond.go:56 +0x9d
volcano.sh/volcano/vendor/golang.org/x/net/http2.(*pipe).Read(0xc00019d928, 0xc000786e00, 0x200, 0x200, 0x0, 0x0, 0x0)
	/Users/yuan.chen/GolandProjects/src/volcano.sh/volcano/vendor/golang.org/x/net/http2/pipe.go:64 +0xa6
volcano.sh/volcano/vendor/golang.org/x/net/http2.transportResponseBody.Read(0xc00019d900, 0xc000786e00, 0x200, 0x200, 0x0, 0x0, 0x0)
	/Users/yuan.chen/GolandProjects/src/volcano.sh/volcano/vendor/golang.org/x/net/http2/transport.go:1952 +0xac
encoding/json.(*Decoder).refill(0xc00078c000, 0xc0000dd920, 0x0)
	/usr/local/opt/go/libexec/src/encoding/json/stream.go:161 +0xeb
encoding/json.(*Decoder).readValue(0xc00078c000, 0x0, 0x0, 0x1fbf8c0)
	/usr/local/opt/go/libexec/src/encoding/json/stream.go:136 +0x1dc
encoding/json.(*Decoder).Decode(0xc00078c000, 0x1fd7a80, 0xc0000dd920, 0x0, 0x0)
	/usr/local/opt/go/libexec/src/encoding/json/stream.go:63 +0x79
volcano.sh/volcano/vendor/k8s.io/apimachinery/pkg/util/framer.(*jsonFrameReader).Read(0xc00076b0e0, 0xc000a50400, 0x400, 0x400, 0x0, 0x0, 0x38)
	/Users/yuan.chen/GolandProjects/src/volcano.sh/volcano/vendor/k8s.io/apimachinery/pkg/util/framer/framer.go:150 +0x1a1
volcano.sh/volcano/vendor/k8s.io/apimachinery/pkg/runtime/serializer/streaming.(*decoder).Decode(0xc00055a1e0, 0x0, 0x23a32e0, 0xc0000af3c0, 0x0, 0x0, 0x0, 0x0, 0x0)
	/Users/yuan.chen/GolandProjects/src/volcano.sh/volcano/vendor/k8s.io/apimachinery/pkg/runtime/serializer/streaming/streaming.go:77 +0x89
volcano.sh/volcano/vendor/k8s.io/client-go/rest/watch.(*Decoder).Decode(0xc0000dd900, 0x0, 0x0, 0x0, 0x0, 0x0, 0x14eab96)
	/Users/yuan.chen/GolandProjects/src/volcano.sh/volcano/vendor/k8s.io/client-go/rest/watch/decoder.go:49 +0x7c
volcano.sh/volcano/vendor/k8s.io/apimachinery/pkg/watch.(*StreamWatcher).receive(0xc00076b140)
	/Users/yuan.chen/GolandProjects/src/volcano.sh/volcano/vendor/k8s.io/apimachinery/pkg/watch/streamwatcher.go:93 +0x175
created by volcano.sh/volcano/vendor/k8s.io/apimachinery/pkg/watch.NewStreamWatcher
	/Users/yuan.chen/GolandProjects/src/volcano.sh/volcano/vendor/k8s.io/apimachinery/pkg/watch/streamwatcher.go:60 +0x9f

goroutine 408 [sync.Cond.Wait]:
runtime.goparkunlock(...)
	/usr/local/opt/go/libexec/src/runtime/proc.go:310
sync.runtime_notifyListWait(0xc000b0e400, 0x0)
	/usr/local/opt/go/libexec/src/runtime/sema.go:510 +0xf8
sync.(*Cond).Wait(0xc000b0e3f0)
	/usr/local/opt/go/libexec/src/sync/cond.go:56 +0x9d
volcano.sh/volcano/vendor/golang.org/x/net/http2.(*pipe).Read(0xc000b0e3e8, 0xc000a68600, 0x200, 0x200, 0x0, 0x0, 0x0)
	/Users/yuan.chen/GolandProjects/src/volcano.sh/volcano/vendor/golang.org/x/net/http2/pipe.go:64 +0xa6
volcano.sh/volcano/vendor/golang.org/x/net/http2.transportResponseBody.Read(0xc000b0e3c0, 0xc000a68600, 0x200, 0x200, 0x0, 0x0, 0x0)
	/Users/yuan.chen/GolandProjects/src/volcano.sh/volcano/vendor/golang.org/x/net/http2/transport.go:1952 +0xac
encoding/json.(*Decoder).refill(0xc00058e580, 0xc000622ca0, 0x350dc00)
	/usr/local/opt/go/libexec/src/encoding/json/stream.go:161 +0xeb
encoding/json.(*Decoder).readValue(0xc00058e580, 0x0, 0x0, 0x1fbf8c0)
	/usr/local/opt/go/libexec/src/encoding/json/stream.go:136 +0x1dc
encoding/json.(*Decoder).Decode(0xc00058e580, 0x1fd7a80, 0xc000622ca0, 0xc00004edf8, 0xc00004e000)
	/usr/local/opt/go/libexec/src/encoding/json/stream.go:63 +0x79
volcano.sh/volcano/vendor/k8s.io/apimachinery/pkg/util/framer.(*jsonFrameReader).Read(0xc00061a0f0, 0xc000a3e800, 0x400, 0x400, 0x0, 0x1, 0x38)
	/Users/yuan.chen/GolandProjects/src/volcano.sh/volcano/vendor/k8s.io/apimachinery/pkg/util/framer/framer.go:150 +0x1a1
volcano.sh/volcano/vendor/k8s.io/apimachinery/pkg/runtime/serializer/streaming.(*decoder).Decode(0xc000186460, 0x0, 0x23a32e0, 0xc0005551c0, 0x10, 0xc0000ea5e0, 0xc00035bf58, 0x1bc82cd, 0xc00035bf08)
	/Users/yuan.chen/GolandProjects/src/volcano.sh/volcano/vendor/k8s.io/apimachinery/pkg/runtime/serializer/streaming/streaming.go:77 +0x89
volcano.sh/volcano/vendor/k8s.io/client-go/rest/watch.(*Decoder).Decode(0xc000622c80, 0xc00035be90, 0xc00070e240, 0x18, 0xc00035be20, 0x1bc81ae, 0x223daf8)
	/Users/yuan.chen/GolandProjects/src/volcano.sh/volcano/vendor/k8s.io/client-go/rest/watch/decoder.go:49 +0x7c
volcano.sh/volcano/vendor/k8s.io/apimachinery/pkg/watch.(*StreamWatcher).receive(0xc00061a120)
	/Users/yuan.chen/GolandProjects/src/volcano.sh/volcano/vendor/k8s.io/apimachinery/pkg/watch/streamwatcher.go:93 +0x175
created by volcano.sh/volcano/vendor/k8s.io/apimachinery/pkg/watch.NewStreamWatcher
	/Users/yuan.chen/GolandProjects/src/volcano.sh/volcano/vendor/k8s.io/apimachinery/pkg/watch/streamwatcher.go:60 +0x9f
