Log file created at: 2019/11/04 15:48:25
Running on machine: SVMAC-C02T6AMCGTFL
Binary: Built with gc go1.13 for darwin/amd64
Log line format: [IWEF]mmdd hh:mm:ss.uuuuuu threadid file:line] msg
I1104 15:48:25.243658   66170 event_handlers.go:729] Add Queue(default) into cache, spec(v1alpha2.QueueSpec{Weight:1, Capability:v1.ResourceList(nil)})
I1104 15:48:25.243658   66170 event_handlers.go:709] Add Queue(default) into cache, spec(v1alpha1.QueueSpec{Weight:1, Capability:v1.ResourceList(nil)})
I1104 15:48:25.261215   66170 event_handlers.go:48] Pod kube-system/coredns-fb8b8dccf-cm54h will not not scheduled by jdos-batch, skip creating PodGroup and Job for it
I1104 15:48:25.261226   66170 event_handlers.go:189] Added pod <kube-system/coredns-fb8b8dccf-cm54h> into cache.
I1104 15:48:25.261234   66170 event_handlers.go:48] Pod kube-system/kube-scheduler-minikube will not not scheduled by jdos-batch, skip creating PodGroup and Job for it
I1104 15:48:25.261237   66170 event_handlers.go:189] Added pod <kube-system/kube-scheduler-minikube> into cache.
I1104 15:48:25.261242   66170 event_handlers.go:48] Pod kube-system/kubernetes-dashboard-d7c9687c7-tkc82 will not not scheduled by jdos-batch, skip creating PodGroup and Job for it
I1104 15:48:25.261245   66170 event_handlers.go:189] Added pod <kube-system/kubernetes-dashboard-d7c9687c7-tkc82> into cache.
I1104 15:48:25.261250   66170 event_handlers.go:48] Pod kube-system/registry-f4x5r will not not scheduled by jdos-batch, skip creating PodGroup and Job for it
I1104 15:48:25.261253   66170 event_handlers.go:189] Added pod <kube-system/registry-f4x5r> into cache.
I1104 15:48:25.261257   66170 event_handlers.go:48] Pod kube-system/kube-controller-manager-minikube will not not scheduled by jdos-batch, skip creating PodGroup and Job for it
I1104 15:48:25.261259   66170 event_handlers.go:189] Added pod <kube-system/kube-controller-manager-minikube> into cache.
I1104 15:48:25.261265   66170 event_handlers.go:48] Pod kube-system/kube-proxy-kc6f7 will not not scheduled by jdos-batch, skip creating PodGroup and Job for it
I1104 15:48:25.261268   66170 event_handlers.go:189] Added pod <kube-system/kube-proxy-kc6f7> into cache.
I1104 15:48:25.261270   66170 event_handlers.go:48] Pod kube-system/storage-provisioner will not not scheduled by jdos-batch, skip creating PodGroup and Job for it
I1104 15:48:25.261273   66170 event_handlers.go:189] Added pod <kube-system/storage-provisioner> into cache.
I1104 15:48:25.261279   66170 event_handlers.go:48] Pod kube-system/coredns-fb8b8dccf-xfpnf will not not scheduled by jdos-batch, skip creating PodGroup and Job for it
I1104 15:48:25.261282   66170 event_handlers.go:189] Added pod <kube-system/coredns-fb8b8dccf-xfpnf> into cache.
I1104 15:48:25.261285   66170 event_handlers.go:48] Pod kube-system/etcd-minikube will not not scheduled by jdos-batch, skip creating PodGroup and Job for it
I1104 15:48:25.261289   66170 event_handlers.go:189] Added pod <kube-system/etcd-minikube> into cache.
I1104 15:48:25.261294   66170 event_handlers.go:48] Pod kube-system/kube-addon-manager-minikube will not not scheduled by jdos-batch, skip creating PodGroup and Job for it
I1104 15:48:25.261297   66170 event_handlers.go:189] Added pod <kube-system/kube-addon-manager-minikube> into cache.
I1104 15:48:25.261300   66170 event_handlers.go:48] Pod kube-system/kube-apiserver-minikube will not not scheduled by jdos-batch, skip creating PodGroup and Job for it
I1104 15:48:25.261303   66170 event_handlers.go:189] Added pod <kube-system/kube-apiserver-minikube> into cache.
I1104 15:48:25.340063   66170 scheduler.go:72] Start scheduling ...
I1104 15:48:25.340360   66170 cache.go:771] There are <0> Jobs, <1> Queues and <1> Nodes in total for scheduling.
I1104 15:48:25.340371   66170 session.go:135] Open Session 97af582c-ff5d-11e9-bf19-784f43775513 with <0> Job and <1> Queues
I1104 15:48:25.340443   66170 proportion.go:67] The total resource is <cpu 4000.00, memory 4959854592.00, hugepages-2Mi 0.00>
I1104 15:48:25.340467   66170 proportion.go:117] Exiting when total weight is 0
I1104 15:48:25.340488   66170 enqueue.go:43] Enter Enqueue ...
I1104 15:48:25.340493   66170 enqueue.go:75] Try to enqueue PodGroup to 0 Queues
I1104 15:48:25.340499   66170 enqueue.go:122] Leaving Enqueue ...
I1104 15:48:25.340513   66170 allocate.go:43] Enter Allocate ...
I1104 15:48:25.340519   66170 allocate.go:94] Try to allocate resource to 0 Namespaces
I1104 15:48:25.340532   66170 allocate.go:253] Leaving Allocate ...
I1104 15:48:25.340536   66170 backfill.go:42] Enter Backfill ...
I1104 15:48:25.340540   66170 backfill.go:91] Leaving Backfill ...
I1104 15:48:25.340561   66170 session.go:154] Close Session 97af582c-ff5d-11e9-bf19-784f43775513
I1104 15:48:25.340565   66170 scheduler.go:87] End scheduling ...
I1104 15:48:30.345745   66170 scheduler.go:72] Start scheduling ...
I1104 15:48:30.345953   66170 cache.go:771] There are <0> Jobs, <1> Queues and <1> Nodes in total for scheduling.
I1104 15:48:30.345960   66170 session.go:135] Open Session 9aab2308-ff5d-11e9-bf19-784f43775513 with <0> Job and <1> Queues
I1104 15:48:30.345993   66170 proportion.go:67] The total resource is <cpu 4000.00, memory 4959854592.00, hugepages-2Mi 0.00>
I1104 15:48:30.346010   66170 proportion.go:117] Exiting when total weight is 0
I1104 15:48:30.346034   66170 enqueue.go:43] Enter Enqueue ...
I1104 15:48:30.346039   66170 enqueue.go:75] Try to enqueue PodGroup to 0 Queues
I1104 15:48:30.346045   66170 enqueue.go:122] Leaving Enqueue ...
I1104 15:48:30.346051   66170 allocate.go:43] Enter Allocate ...
I1104 15:48:30.346056   66170 allocate.go:94] Try to allocate resource to 0 Namespaces
I1104 15:48:30.346066   66170 allocate.go:253] Leaving Allocate ...
I1104 15:48:30.346070   66170 backfill.go:42] Enter Backfill ...
I1104 15:48:30.346074   66170 backfill.go:91] Leaving Backfill ...
I1104 15:48:30.346085   66170 session.go:154] Close Session 9aab2308-ff5d-11e9-bf19-784f43775513
I1104 15:48:30.346089   66170 scheduler.go:87] End scheduling ...
I1104 15:48:35.350985   66170 scheduler.go:72] Start scheduling ...
I1104 15:48:35.351124   66170 cache.go:771] There are <0> Jobs, <1> Queues and <1> Nodes in total for scheduling.
I1104 15:48:35.351131   66170 session.go:135] Open Session 9da6dd9a-ff5d-11e9-bf19-784f43775513 with <0> Job and <1> Queues
I1104 15:48:35.351144   66170 proportion.go:67] The total resource is <cpu 4000.00, memory 4959854592.00, hugepages-2Mi 0.00>
I1104 15:48:35.351162   66170 proportion.go:117] Exiting when total weight is 0
I1104 15:48:35.351207   66170 enqueue.go:43] Enter Enqueue ...
I1104 15:48:35.351213   66170 enqueue.go:75] Try to enqueue PodGroup to 0 Queues
I1104 15:48:35.351220   66170 enqueue.go:122] Leaving Enqueue ...
I1104 15:48:35.351226   66170 allocate.go:43] Enter Allocate ...
I1104 15:48:35.351232   66170 allocate.go:94] Try to allocate resource to 0 Namespaces
I1104 15:48:35.351244   66170 allocate.go:253] Leaving Allocate ...
I1104 15:48:35.351252   66170 backfill.go:42] Enter Backfill ...
I1104 15:48:35.351256   66170 backfill.go:91] Leaving Backfill ...
I1104 15:48:35.351270   66170 session.go:154] Close Session 9da6dd9a-ff5d-11e9-bf19-784f43775513
I1104 15:48:35.351274   66170 scheduler.go:87] End scheduling ...
I1104 15:48:40.351839   66170 scheduler.go:72] Start scheduling ...
I1104 15:48:40.351993   66170 cache.go:771] There are <0> Jobs, <1> Queues and <1> Nodes in total for scheduling.
I1104 15:48:40.352001   66170 session.go:135] Open Session a0a1efda-ff5d-11e9-bf19-784f43775513 with <0> Job and <1> Queues
I1104 15:48:40.352044   66170 proportion.go:67] The total resource is <cpu 4000.00, memory 4959854592.00, hugepages-2Mi 0.00>
I1104 15:48:40.352065   66170 proportion.go:117] Exiting when total weight is 0
I1104 15:48:40.352085   66170 enqueue.go:43] Enter Enqueue ...
I1104 15:48:40.352091   66170 enqueue.go:75] Try to enqueue PodGroup to 0 Queues
I1104 15:48:40.352103   66170 enqueue.go:122] Leaving Enqueue ...
I1104 15:48:40.352109   66170 allocate.go:43] Enter Allocate ...
I1104 15:48:40.352115   66170 allocate.go:94] Try to allocate resource to 0 Namespaces
I1104 15:48:40.352127   66170 allocate.go:253] Leaving Allocate ...
I1104 15:48:40.352132   66170 backfill.go:42] Enter Backfill ...
I1104 15:48:40.352136   66170 backfill.go:91] Leaving Backfill ...
I1104 15:48:40.352152   66170 session.go:154] Close Session a0a1efda-ff5d-11e9-bf19-784f43775513
I1104 15:48:40.352158   66170 scheduler.go:87] End scheduling ...
I1104 15:48:45.354689   66170 scheduler.go:72] Start scheduling ...
I1104 15:48:45.354959   66170 cache.go:771] There are <0> Jobs, <1> Queues and <1> Nodes in total for scheduling.
I1104 15:48:45.354970   66170 session.go:135] Open Session a39d53a0-ff5d-11e9-bf19-784f43775513 with <0> Job and <1> Queues
I1104 15:48:45.355022   66170 proportion.go:67] The total resource is <cpu 4000.00, memory 4959854592.00, hugepages-2Mi 0.00>
I1104 15:48:45.355048   66170 proportion.go:117] Exiting when total weight is 0
I1104 15:48:45.355079   66170 enqueue.go:43] Enter Enqueue ...
I1104 15:48:45.355086   66170 enqueue.go:75] Try to enqueue PodGroup to 0 Queues
I1104 15:48:45.355101   66170 enqueue.go:122] Leaving Enqueue ...
I1104 15:48:45.355109   66170 allocate.go:43] Enter Allocate ...
I1104 15:48:45.355116   66170 allocate.go:94] Try to allocate resource to 0 Namespaces
I1104 15:48:45.355134   66170 allocate.go:253] Leaving Allocate ...
I1104 15:48:45.355139   66170 backfill.go:42] Enter Backfill ...
I1104 15:48:45.355145   66170 backfill.go:91] Leaving Backfill ...
I1104 15:48:45.355164   66170 session.go:154] Close Session a39d53a0-ff5d-11e9-bf19-784f43775513
I1104 15:48:45.355170   66170 scheduler.go:87] End scheduling ...
I1104 15:48:50.355516   66170 scheduler.go:72] Start scheduling ...
I1104 15:48:50.355635   66170 cache.go:771] There are <0> Jobs, <1> Queues and <1> Nodes in total for scheduling.
I1104 15:48:50.355641   66170 session.go:135] Open Session a6985f96-ff5d-11e9-bf19-784f43775513 with <0> Job and <1> Queues
I1104 15:48:50.355678   66170 proportion.go:67] The total resource is <cpu 4000.00, memory 4959854592.00, hugepages-2Mi 0.00>
I1104 15:48:50.355693   66170 proportion.go:117] Exiting when total weight is 0
I1104 15:48:50.355713   66170 enqueue.go:43] Enter Enqueue ...
I1104 15:48:50.355718   66170 enqueue.go:75] Try to enqueue PodGroup to 0 Queues
I1104 15:48:50.355724   66170 enqueue.go:122] Leaving Enqueue ...
I1104 15:48:50.355729   66170 allocate.go:43] Enter Allocate ...
I1104 15:48:50.355736   66170 allocate.go:94] Try to allocate resource to 0 Namespaces
I1104 15:48:50.355747   66170 allocate.go:253] Leaving Allocate ...
I1104 15:48:50.355750   66170 backfill.go:42] Enter Backfill ...
I1104 15:48:50.355753   66170 backfill.go:91] Leaving Backfill ...
I1104 15:48:50.355766   66170 session.go:154] Close Session a6985f96-ff5d-11e9-bf19-784f43775513
I1104 15:48:50.355769   66170 scheduler.go:87] End scheduling ...
I1104 15:48:55.357327   66170 scheduler.go:72] Start scheduling ...
I1104 15:48:55.357447   66170 cache.go:771] There are <0> Jobs, <1> Queues and <1> Nodes in total for scheduling.
I1104 15:48:55.357453   66170 session.go:135] Open Session a99396b6-ff5d-11e9-bf19-784f43775513 with <0> Job and <1> Queues
I1104 15:48:55.357464   66170 proportion.go:67] The total resource is <cpu 4000.00, memory 4959854592.00, hugepages-2Mi 0.00>
I1104 15:48:55.357480   66170 proportion.go:117] Exiting when total weight is 0
I1104 15:48:55.357525   66170 enqueue.go:43] Enter Enqueue ...
I1104 15:48:55.357529   66170 enqueue.go:75] Try to enqueue PodGroup to 0 Queues
I1104 15:48:55.357535   66170 enqueue.go:122] Leaving Enqueue ...
I1104 15:48:55.357541   66170 allocate.go:43] Enter Allocate ...
I1104 15:48:55.357546   66170 allocate.go:94] Try to allocate resource to 0 Namespaces
I1104 15:48:55.357556   66170 allocate.go:253] Leaving Allocate ...
I1104 15:48:55.357560   66170 backfill.go:42] Enter Backfill ...
I1104 15:48:55.357563   66170 backfill.go:91] Leaving Backfill ...
I1104 15:48:55.357575   66170 session.go:154] Close Session a99396b6-ff5d-11e9-bf19-784f43775513
I1104 15:48:55.357578   66170 scheduler.go:87] End scheduling ...
I1104 15:49:00.361079   66170 scheduler.go:72] Start scheduling ...
I1104 15:49:00.361248   66170 cache.go:771] There are <0> Jobs, <1> Queues and <1> Nodes in total for scheduling.
I1104 15:49:00.361256   66170 session.go:135] Open Session ac8f1b10-ff5d-11e9-bf19-784f43775513 with <0> Job and <1> Queues
I1104 15:49:00.361327   66170 proportion.go:67] The total resource is <cpu 4000.00, memory 4959854592.00, hugepages-2Mi 0.00>
I1104 15:49:00.361352   66170 proportion.go:117] Exiting when total weight is 0
I1104 15:49:00.361361   66170 enqueue.go:43] Enter Enqueue ...
I1104 15:49:00.361368   66170 enqueue.go:75] Try to enqueue PodGroup to 0 Queues
I1104 15:49:00.361377   66170 enqueue.go:122] Leaving Enqueue ...
I1104 15:49:00.361386   66170 allocate.go:43] Enter Allocate ...
I1104 15:49:00.361393   66170 allocate.go:94] Try to allocate resource to 0 Namespaces
I1104 15:49:00.361409   66170 allocate.go:253] Leaving Allocate ...
I1104 15:49:00.361414   66170 backfill.go:42] Enter Backfill ...
I1104 15:49:00.361419   66170 backfill.go:91] Leaving Backfill ...
I1104 15:49:00.361435   66170 session.go:154] Close Session ac8f1b10-ff5d-11e9-bf19-784f43775513
I1104 15:49:00.361440   66170 scheduler.go:87] End scheduling ...
I1104 15:49:05.363723   66170 scheduler.go:72] Start scheduling ...
I1104 15:49:05.363862   66170 cache.go:771] There are <0> Jobs, <1> Queues and <1> Nodes in total for scheduling.
I1104 15:49:05.363870   66170 session.go:135] Open Session af8a7256-ff5d-11e9-bf19-784f43775513 with <0> Job and <1> Queues
I1104 15:49:05.363922   66170 proportion.go:67] The total resource is <cpu 4000.00, memory 4959854592.00, hugepages-2Mi 0.00>
I1104 15:49:05.363939   66170 proportion.go:117] Exiting when total weight is 0
I1104 15:49:05.363945   66170 enqueue.go:43] Enter Enqueue ...
I1104 15:49:05.363949   66170 enqueue.go:75] Try to enqueue PodGroup to 0 Queues
I1104 15:49:05.363955   66170 enqueue.go:122] Leaving Enqueue ...
I1104 15:49:05.363961   66170 allocate.go:43] Enter Allocate ...
I1104 15:49:05.363966   66170 allocate.go:94] Try to allocate resource to 0 Namespaces
I1104 15:49:05.363976   66170 allocate.go:253] Leaving Allocate ...
I1104 15:49:05.363979   66170 backfill.go:42] Enter Backfill ...
I1104 15:49:05.363983   66170 backfill.go:91] Leaving Backfill ...
I1104 15:49:05.363994   66170 session.go:154] Close Session af8a7256-ff5d-11e9-bf19-784f43775513
I1104 15:49:05.363997   66170 scheduler.go:87] End scheduling ...
I1104 15:49:10.366357   66170 scheduler.go:72] Start scheduling ...
I1104 15:49:10.366477   66170 cache.go:771] There are <0> Jobs, <1> Queues and <1> Nodes in total for scheduling.
I1104 15:49:10.366483   66170 session.go:135] Open Session b285c910-ff5d-11e9-bf19-784f43775513 with <0> Job and <1> Queues
I1104 15:49:10.366521   66170 proportion.go:67] The total resource is <cpu 4000.00, memory 4959854592.00, hugepages-2Mi 0.00>
I1104 15:49:10.366538   66170 proportion.go:117] Exiting when total weight is 0
I1104 15:49:10.366553   66170 enqueue.go:43] Enter Enqueue ...
I1104 15:49:10.366557   66170 enqueue.go:75] Try to enqueue PodGroup to 0 Queues
I1104 15:49:10.366564   66170 enqueue.go:122] Leaving Enqueue ...
I1104 15:49:10.366569   66170 allocate.go:43] Enter Allocate ...
I1104 15:49:10.366574   66170 allocate.go:94] Try to allocate resource to 0 Namespaces
I1104 15:49:10.366585   66170 allocate.go:253] Leaving Allocate ...
I1104 15:49:10.366588   66170 backfill.go:42] Enter Backfill ...
I1104 15:49:10.366592   66170 backfill.go:91] Leaving Backfill ...
I1104 15:49:10.366602   66170 session.go:154] Close Session b285c910-ff5d-11e9-bf19-784f43775513
I1104 15:49:10.366606   66170 scheduler.go:87] End scheduling ...
I1104 15:49:15.367891   66170 scheduler.go:72] Start scheduling ...
I1104 15:49:15.368057   66170 cache.go:771] There are <0> Jobs, <1> Queues and <1> Nodes in total for scheduling.
I1104 15:49:15.368065   66170 session.go:135] Open Session b580f6bc-ff5d-11e9-bf19-784f43775513 with <0> Job and <1> Queues
I1104 15:49:15.368134   66170 proportion.go:67] The total resource is <cpu 4000.00, memory 4959854592.00, hugepages-2Mi 0.00>
I1104 15:49:15.368158   66170 proportion.go:117] Exiting when total weight is 0
I1104 15:49:15.368166   66170 enqueue.go:43] Enter Enqueue ...
I1104 15:49:15.368173   66170 enqueue.go:75] Try to enqueue PodGroup to 0 Queues
I1104 15:49:15.368182   66170 enqueue.go:122] Leaving Enqueue ...
I1104 15:49:15.368190   66170 allocate.go:43] Enter Allocate ...
I1104 15:49:15.368197   66170 allocate.go:94] Try to allocate resource to 0 Namespaces
I1104 15:49:15.368213   66170 allocate.go:253] Leaving Allocate ...
I1104 15:49:15.368218   66170 backfill.go:42] Enter Backfill ...
I1104 15:49:15.368224   66170 backfill.go:91] Leaving Backfill ...
I1104 15:49:15.368239   66170 session.go:154] Close Session b580f6bc-ff5d-11e9-bf19-784f43775513
I1104 15:49:15.368245   66170 scheduler.go:87] End scheduling ...
I1104 15:49:20.372479   66170 scheduler.go:72] Start scheduling ...
I1104 15:49:20.387450   66170 cache.go:771] There are <0> Jobs, <1> Queues and <1> Nodes in total for scheduling.
I1104 15:49:20.387457   66170 session.go:135] Open Session b87edd34-ff5d-11e9-bf19-784f43775513 with <0> Job and <1> Queues
I1104 15:49:20.387469   66170 proportion.go:67] The total resource is <cpu 4000.00, memory 4959854592.00, hugepages-2Mi 0.00>
I1104 15:49:20.387485   66170 proportion.go:117] Exiting when total weight is 0
I1104 15:49:20.387526   66170 enqueue.go:43] Enter Enqueue ...
I1104 15:49:20.387530   66170 enqueue.go:75] Try to enqueue PodGroup to 0 Queues
I1104 15:49:20.387536   66170 enqueue.go:122] Leaving Enqueue ...
I1104 15:49:20.387542   66170 allocate.go:43] Enter Allocate ...
I1104 15:49:20.387546   66170 allocate.go:94] Try to allocate resource to 0 Namespaces
I1104 15:49:20.387557   66170 allocate.go:253] Leaving Allocate ...
I1104 15:49:20.387560   66170 backfill.go:42] Enter Backfill ...
I1104 15:49:20.387563   66170 backfill.go:91] Leaving Backfill ...
I1104 15:49:20.387576   66170 session.go:154] Close Session b87edd34-ff5d-11e9-bf19-784f43775513
I1104 15:49:20.387580   66170 scheduler.go:87] End scheduling ...
I1104 15:49:25.389092   66170 scheduler.go:72] Start scheduling ...
I1104 15:49:25.401990   66170 cache.go:771] There are <0> Jobs, <1> Queues and <1> Nodes in total for scheduling.
I1104 15:49:25.402000   66170 session.go:135] Open Session bb7c0516-ff5d-11e9-bf19-784f43775513 with <0> Job and <1> Queues
I1104 15:49:25.402075   66170 proportion.go:67] The total resource is <cpu 4000.00, memory 4959854592.00, hugepages-2Mi 0.00>
I1104 15:49:25.402103   66170 proportion.go:117] Exiting when total weight is 0
I1104 15:49:25.402125   66170 enqueue.go:43] Enter Enqueue ...
I1104 15:49:25.402134   66170 enqueue.go:75] Try to enqueue PodGroup to 0 Queues
I1104 15:49:25.402143   66170 enqueue.go:122] Leaving Enqueue ...
I1104 15:49:25.402151   66170 allocate.go:43] Enter Allocate ...
I1104 15:49:25.402160   66170 allocate.go:94] Try to allocate resource to 0 Namespaces
I1104 15:49:25.402176   66170 allocate.go:253] Leaving Allocate ...
I1104 15:49:25.402181   66170 backfill.go:42] Enter Backfill ...
I1104 15:49:25.402186   66170 backfill.go:91] Leaving Backfill ...
I1104 15:49:25.402203   66170 session.go:154] Close Session bb7c0516-ff5d-11e9-bf19-784f43775513
I1104 15:49:25.402208   66170 scheduler.go:87] End scheduling ...
I1104 15:49:30.406537   66170 scheduler.go:72] Start scheduling ...
I1104 15:49:30.420937   66170 cache.go:771] There are <0> Jobs, <1> Queues and <1> Nodes in total for scheduling.
I1104 15:49:30.420946   66170 session.go:135] Open Session be79da36-ff5d-11e9-bf19-784f43775513 with <0> Job and <1> Queues
I1104 15:49:30.420981   66170 proportion.go:67] The total resource is <cpu 4000.00, memory 4959854592.00, hugepages-2Mi 0.00>
I1104 15:49:30.420998   66170 proportion.go:117] Exiting when total weight is 0
I1104 15:49:30.421012   66170 enqueue.go:43] Enter Enqueue ...
I1104 15:49:30.421017   66170 enqueue.go:75] Try to enqueue PodGroup to 0 Queues
I1104 15:49:30.421023   66170 enqueue.go:122] Leaving Enqueue ...
I1104 15:49:30.421028   66170 allocate.go:43] Enter Allocate ...
I1104 15:49:30.421033   66170 allocate.go:94] Try to allocate resource to 0 Namespaces
I1104 15:49:30.421043   66170 allocate.go:253] Leaving Allocate ...
I1104 15:49:30.421046   66170 backfill.go:42] Enter Backfill ...
I1104 15:49:30.421050   66170 backfill.go:91] Leaving Backfill ...
I1104 15:49:30.421061   66170 session.go:154] Close Session be79da36-ff5d-11e9-bf19-784f43775513
I1104 15:49:30.421065   66170 scheduler.go:87] End scheduling ...
I1104 15:49:35.425214   66170 scheduler.go:72] Start scheduling ...
I1104 15:49:35.440967   66170 cache.go:771] There are <0> Jobs, <1> Queues and <1> Nodes in total for scheduling.
I1104 15:49:35.440974   66170 session.go:135] Open Session c177d90e-ff5d-11e9-bf19-784f43775513 with <0> Job and <1> Queues
I1104 15:49:35.441003   66170 proportion.go:67] The total resource is <cpu 4000.00, memory 4959854592.00, hugepages-2Mi 0.00>
I1104 15:49:35.441020   66170 proportion.go:117] Exiting when total weight is 0
I1104 15:49:35.441041   66170 enqueue.go:43] Enter Enqueue ...
I1104 15:49:35.441046   66170 enqueue.go:75] Try to enqueue PodGroup to 0 Queues
I1104 15:49:35.441052   66170 enqueue.go:122] Leaving Enqueue ...
I1104 15:49:35.441058   66170 allocate.go:43] Enter Allocate ...
I1104 15:49:35.441063   66170 allocate.go:94] Try to allocate resource to 0 Namespaces
I1104 15:49:35.441073   66170 allocate.go:253] Leaving Allocate ...
I1104 15:49:35.441077   66170 backfill.go:42] Enter Backfill ...
I1104 15:49:35.441080   66170 backfill.go:91] Leaving Backfill ...
I1104 15:49:35.441093   66170 session.go:154] Close Session c177d90e-ff5d-11e9-bf19-784f43775513
I1104 15:49:35.441096   66170 scheduler.go:87] End scheduling ...
I1104 15:49:40.445897   66170 scheduler.go:72] Start scheduling ...
I1104 15:49:40.460623   66170 cache.go:771] There are <0> Jobs, <1> Queues and <1> Nodes in total for scheduling.
I1104 15:49:40.460631   66170 session.go:135] Open Session c475c94a-ff5d-11e9-bf19-784f43775513 with <0> Job and <1> Queues
I1104 15:49:40.460663   66170 proportion.go:67] The total resource is <cpu 4000.00, memory 4959854592.00, hugepages-2Mi 0.00>
I1104 15:49:40.460680   66170 proportion.go:117] Exiting when total weight is 0
I1104 15:49:40.460704   66170 enqueue.go:43] Enter Enqueue ...
I1104 15:49:40.460709   66170 enqueue.go:75] Try to enqueue PodGroup to 0 Queues
I1104 15:49:40.460717   66170 enqueue.go:122] Leaving Enqueue ...
I1104 15:49:40.460724   66170 allocate.go:43] Enter Allocate ...
I1104 15:49:40.460728   66170 allocate.go:94] Try to allocate resource to 0 Namespaces
I1104 15:49:40.460739   66170 allocate.go:253] Leaving Allocate ...
I1104 15:49:40.460742   66170 backfill.go:42] Enter Backfill ...
I1104 15:49:40.460749   66170 backfill.go:91] Leaving Backfill ...
I1104 15:49:40.460761   66170 session.go:154] Close Session c475c94a-ff5d-11e9-bf19-784f43775513
I1104 15:49:40.460765   66170 scheduler.go:87] End scheduling ...
I1104 15:49:45.464728   66170 scheduler.go:72] Start scheduling ...
I1104 15:49:45.477822   66170 cache.go:771] There are <0> Jobs, <1> Queues and <1> Nodes in total for scheduling.
I1104 15:49:45.477829   66170 session.go:135] Open Session c77359e6-ff5d-11e9-bf19-784f43775513 with <0> Job and <1> Queues
I1104 15:49:45.477869   66170 proportion.go:67] The total resource is <cpu 4000.00, memory 4959854592.00, hugepages-2Mi 0.00>
I1104 15:49:45.477887   66170 proportion.go:117] Exiting when total weight is 0
I1104 15:49:45.477906   66170 enqueue.go:43] Enter Enqueue ...
I1104 15:49:45.477910   66170 enqueue.go:75] Try to enqueue PodGroup to 0 Queues
I1104 15:49:45.477926   66170 enqueue.go:122] Leaving Enqueue ...
I1104 15:49:45.477934   66170 allocate.go:43] Enter Allocate ...
I1104 15:49:45.477938   66170 allocate.go:94] Try to allocate resource to 0 Namespaces
I1104 15:49:45.477950   66170 allocate.go:253] Leaving Allocate ...
I1104 15:49:45.477953   66170 backfill.go:42] Enter Backfill ...
I1104 15:49:45.477957   66170 backfill.go:91] Leaving Backfill ...
I1104 15:49:45.477970   66170 session.go:154] Close Session c77359e6-ff5d-11e9-bf19-784f43775513
I1104 15:49:45.477974   66170 scheduler.go:87] End scheduling ...
I1104 15:49:50.480636   66170 scheduler.go:72] Start scheduling ...
I1104 15:49:50.495565   66170 cache.go:771] There are <0> Jobs, <1> Queues and <1> Nodes in total for scheduling.
I1104 15:49:50.495580   66170 session.go:135] Open Session ca70fe1e-ff5d-11e9-bf19-784f43775513 with <0> Job and <1> Queues
I1104 15:49:50.495693   66170 proportion.go:67] The total resource is <cpu 4000.00, memory 4959854592.00, hugepages-2Mi 0.00>
I1104 15:49:50.495716   66170 proportion.go:117] Exiting when total weight is 0
I1104 15:49:50.495723   66170 enqueue.go:43] Enter Enqueue ...
I1104 15:49:50.495728   66170 enqueue.go:75] Try to enqueue PodGroup to 0 Queues
I1104 15:49:50.495750   66170 enqueue.go:122] Leaving Enqueue ...
I1104 15:49:50.495757   66170 allocate.go:43] Enter Allocate ...
I1104 15:49:50.495762   66170 allocate.go:94] Try to allocate resource to 0 Namespaces
I1104 15:49:50.495774   66170 allocate.go:253] Leaving Allocate ...
I1104 15:49:50.495778   66170 backfill.go:42] Enter Backfill ...
I1104 15:49:50.495782   66170 backfill.go:91] Leaving Backfill ...
I1104 15:49:50.495795   66170 session.go:154] Close Session ca70fe1e-ff5d-11e9-bf19-784f43775513
I1104 15:49:50.495799   66170 scheduler.go:87] End scheduling ...
I1104 15:49:55.499177   66170 scheduler.go:72] Start scheduling ...
I1104 15:49:55.507924   66170 cache.go:771] There are <0> Jobs, <1> Queues and <1> Nodes in total for scheduling.
I1104 15:49:55.507932   66170 session.go:135] Open Session cd6dd2c2-ff5d-11e9-bf19-784f43775513 with <0> Job and <1> Queues
I1104 15:49:55.507963   66170 proportion.go:67] The total resource is <cpu 4000.00, memory 4959854592.00, hugepages-2Mi 0.00>
I1104 15:49:55.507979   66170 proportion.go:117] Exiting when total weight is 0
I1104 15:49:55.507998   66170 enqueue.go:43] Enter Enqueue ...
I1104 15:49:55.508002   66170 enqueue.go:75] Try to enqueue PodGroup to 0 Queues
I1104 15:49:55.508008   66170 enqueue.go:122] Leaving Enqueue ...
I1104 15:49:55.508013   66170 allocate.go:43] Enter Allocate ...
I1104 15:49:55.508017   66170 allocate.go:94] Try to allocate resource to 0 Namespaces
I1104 15:49:55.508027   66170 allocate.go:253] Leaving Allocate ...
I1104 15:49:55.508030   66170 backfill.go:42] Enter Backfill ...
I1104 15:49:55.508033   66170 backfill.go:91] Leaving Backfill ...
I1104 15:49:55.508044   66170 session.go:154] Close Session cd6dd2c2-ff5d-11e9-bf19-784f43775513
I1104 15:49:55.508048   66170 scheduler.go:87] End scheduling ...
I1104 15:50:00.509661   66170 scheduler.go:72] Start scheduling ...
I1104 15:50:00.509864   66170 cache.go:771] There are <0> Jobs, <1> Queues and <1> Nodes in total for scheduling.
I1104 15:50:00.525554   66170 session.go:135] Open Session d0690e88-ff5d-11e9-bf19-784f43775513 with <0> Job and <1> Queues
I1104 15:50:00.525610   66170 proportion.go:67] The total resource is <cpu 4000.00, memory 4959854592.00, hugepages-2Mi 0.00>
I1104 15:50:00.525634   66170 proportion.go:117] Exiting when total weight is 0
I1104 15:50:00.525668   66170 enqueue.go:43] Enter Enqueue ...
I1104 15:50:00.525674   66170 enqueue.go:75] Try to enqueue PodGroup to 0 Queues
I1104 15:50:00.525682   66170 enqueue.go:122] Leaving Enqueue ...
I1104 15:50:00.525688   66170 allocate.go:43] Enter Allocate ...
I1104 15:50:00.525695   66170 allocate.go:94] Try to allocate resource to 0 Namespaces
I1104 15:50:00.525708   66170 allocate.go:253] Leaving Allocate ...
I1104 15:50:00.525712   66170 backfill.go:42] Enter Backfill ...
I1104 15:50:00.525715   66170 backfill.go:91] Leaving Backfill ...
I1104 15:50:00.525729   66170 session.go:154] Close Session d0690e88-ff5d-11e9-bf19-784f43775513
I1104 15:50:00.525733   66170 scheduler.go:87] End scheduling ...
I1104 15:50:05.527713   66170 scheduler.go:72] Start scheduling ...
I1104 15:50:05.542769   66170 cache.go:771] There are <0> Jobs, <1> Queues and <1> Nodes in total for scheduling.
I1104 15:50:05.542779   66170 session.go:135] Open Session d369041c-ff5d-11e9-bf19-784f43775513 with <0> Job and <1> Queues
I1104 15:50:05.542827   66170 proportion.go:67] The total resource is <cpu 4000.00, memory 4959854592.00, hugepages-2Mi 0.00>
I1104 15:50:05.542851   66170 proportion.go:117] Exiting when total weight is 0
I1104 15:50:05.542878   66170 enqueue.go:43] Enter Enqueue ...
I1104 15:50:05.542885   66170 enqueue.go:75] Try to enqueue PodGroup to 0 Queues
I1104 15:50:05.542895   66170 enqueue.go:122] Leaving Enqueue ...
I1104 15:50:05.542903   66170 allocate.go:43] Enter Allocate ...
I1104 15:50:05.542910   66170 allocate.go:94] Try to allocate resource to 0 Namespaces
I1104 15:50:05.542929   66170 allocate.go:253] Leaving Allocate ...
I1104 15:50:05.542935   66170 backfill.go:42] Enter Backfill ...
I1104 15:50:05.542940   66170 backfill.go:91] Leaving Backfill ...
I1104 15:50:05.542957   66170 session.go:154] Close Session d369041c-ff5d-11e9-bf19-784f43775513
I1104 15:50:05.542962   66170 scheduler.go:87] End scheduling ...
I1104 15:50:10.545211   66170 scheduler.go:72] Start scheduling ...
I1104 15:50:10.557545   66170 cache.go:771] There are <0> Jobs, <1> Queues and <1> Nodes in total for scheduling.
I1104 15:50:10.557552   66170 session.go:135] Open Session d666368a-ff5d-11e9-bf19-784f43775513 with <0> Job and <1> Queues
I1104 15:50:10.557587   66170 proportion.go:67] The total resource is <cpu 4000.00, memory 4959854592.00, hugepages-2Mi 0.00>
I1104 15:50:10.557604   66170 proportion.go:117] Exiting when total weight is 0
I1104 15:50:10.557621   66170 enqueue.go:43] Enter Enqueue ...
I1104 15:50:10.557625   66170 enqueue.go:75] Try to enqueue PodGroup to 0 Queues
I1104 15:50:10.557632   66170 enqueue.go:122] Leaving Enqueue ...
I1104 15:50:10.557637   66170 allocate.go:43] Enter Allocate ...
I1104 15:50:10.557642   66170 allocate.go:94] Try to allocate resource to 0 Namespaces
I1104 15:50:10.557652   66170 allocate.go:253] Leaving Allocate ...
I1104 15:50:10.557655   66170 backfill.go:42] Enter Backfill ...
I1104 15:50:10.557659   66170 backfill.go:91] Leaving Backfill ...
I1104 15:50:10.557669   66170 session.go:154] Close Session d666368a-ff5d-11e9-bf19-784f43775513
I1104 15:50:10.557672   66170 scheduler.go:87] End scheduling ...
I1104 15:50:15.561483   66170 scheduler.go:72] Start scheduling ...
I1104 15:50:15.575669   66170 cache.go:771] There are <0> Jobs, <1> Queues and <1> Nodes in total for scheduling.
I1104 15:50:15.575676   66170 session.go:135] Open Session d963eb0c-ff5d-11e9-bf19-784f43775513 with <0> Job and <1> Queues
I1104 15:50:15.575720   66170 proportion.go:67] The total resource is <cpu 4000.00, memory 4959854592.00, hugepages-2Mi 0.00>
I1104 15:50:15.575735   66170 proportion.go:117] Exiting when total weight is 0
I1104 15:50:15.575741   66170 enqueue.go:43] Enter Enqueue ...
I1104 15:50:15.575750   66170 enqueue.go:75] Try to enqueue PodGroup to 0 Queues
I1104 15:50:15.575756   66170 enqueue.go:122] Leaving Enqueue ...
I1104 15:50:15.575762   66170 allocate.go:43] Enter Allocate ...
I1104 15:50:15.575767   66170 allocate.go:94] Try to allocate resource to 0 Namespaces
I1104 15:50:15.575776   66170 allocate.go:253] Leaving Allocate ...
I1104 15:50:15.575780   66170 backfill.go:42] Enter Backfill ...
I1104 15:50:15.575783   66170 backfill.go:91] Leaving Backfill ...
I1104 15:50:15.575793   66170 session.go:154] Close Session d963eb0c-ff5d-11e9-bf19-784f43775513
I1104 15:50:15.575797   66170 scheduler.go:87] End scheduling ...
I1104 15:50:20.577325   66170 scheduler.go:72] Start scheduling ...
I1104 15:50:20.577466   66170 cache.go:771] There are <0> Jobs, <1> Queues and <1> Nodes in total for scheduling.
I1104 15:50:20.594146   66170 session.go:135] Open Session dc5f21b4-ff5d-11e9-bf19-784f43775513 with <0> Job and <1> Queues
I1104 15:50:20.594208   66170 proportion.go:67] The total resource is <cpu 4000.00, memory 4959854592.00, hugepages-2Mi 0.00>
I1104 15:50:20.594234   66170 proportion.go:117] Exiting when total weight is 0
I1104 15:50:20.594260   66170 enqueue.go:43] Enter Enqueue ...
I1104 15:50:20.594267   66170 enqueue.go:75] Try to enqueue PodGroup to 0 Queues
I1104 15:50:20.594283   66170 enqueue.go:122] Leaving Enqueue ...
I1104 15:50:20.594291   66170 allocate.go:43] Enter Allocate ...
I1104 15:50:20.594298   66170 allocate.go:94] Try to allocate resource to 0 Namespaces
I1104 15:50:20.594314   66170 allocate.go:253] Leaving Allocate ...
I1104 15:50:20.594319   66170 backfill.go:42] Enter Backfill ...
I1104 15:50:20.594324   66170 backfill.go:91] Leaving Backfill ...
I1104 15:50:20.594340   66170 session.go:154] Close Session dc5f21b4-ff5d-11e9-bf19-784f43775513
I1104 15:50:20.594345   66170 scheduler.go:87] End scheduling ...
I1104 15:50:25.595229   66170 scheduler.go:72] Start scheduling ...
I1104 15:50:25.603322   66170 cache.go:771] There are <0> Jobs, <1> Queues and <1> Nodes in total for scheduling.
I1104 15:50:25.603330   66170 session.go:135] Open Session df5e042a-ff5d-11e9-bf19-784f43775513 with <0> Job and <1> Queues
I1104 15:50:25.603368   66170 proportion.go:67] The total resource is <cpu 4000.00, memory 4959854592.00, hugepages-2Mi 0.00>
I1104 15:50:25.603386   66170 proportion.go:117] Exiting when total weight is 0
I1104 15:50:25.603402   66170 enqueue.go:43] Enter Enqueue ...
I1104 15:50:25.603407   66170 enqueue.go:75] Try to enqueue PodGroup to 0 Queues
I1104 15:50:25.603413   66170 enqueue.go:122] Leaving Enqueue ...
I1104 15:50:25.603419   66170 allocate.go:43] Enter Allocate ...
I1104 15:50:25.603423   66170 allocate.go:94] Try to allocate resource to 0 Namespaces
I1104 15:50:25.603434   66170 allocate.go:253] Leaving Allocate ...
I1104 15:50:25.603437   66170 backfill.go:42] Enter Backfill ...
I1104 15:50:25.603441   66170 backfill.go:91] Leaving Backfill ...
I1104 15:50:25.603453   66170 session.go:154] Close Session df5e042a-ff5d-11e9-bf19-784f43775513
I1104 15:50:25.603457   66170 scheduler.go:87] End scheduling ...
I1104 15:50:30.608271   66170 scheduler.go:72] Start scheduling ...
I1104 15:50:30.624397   66170 cache.go:771] There are <0> Jobs, <1> Queues and <1> Nodes in total for scheduling.
I1104 15:50:30.624409   66170 session.go:135] Open Session e25c2a4e-ff5d-11e9-bf19-784f43775513 with <0> Job and <1> Queues
I1104 15:50:30.624427   66170 proportion.go:67] The total resource is <cpu 4000.00, memory 4959854592.00, hugepages-2Mi 0.00>
I1104 15:50:30.624453   66170 proportion.go:117] Exiting when total weight is 0
I1104 15:50:30.624516   66170 enqueue.go:43] Enter Enqueue ...
I1104 15:50:30.624525   66170 enqueue.go:75] Try to enqueue PodGroup to 0 Queues
I1104 15:50:30.624537   66170 enqueue.go:122] Leaving Enqueue ...
I1104 15:50:30.624547   66170 allocate.go:43] Enter Allocate ...
I1104 15:50:30.624557   66170 allocate.go:94] Try to allocate resource to 0 Namespaces
I1104 15:50:30.624576   66170 allocate.go:253] Leaving Allocate ...
I1104 15:50:30.624582   66170 backfill.go:42] Enter Backfill ...
I1104 15:50:30.624590   66170 backfill.go:91] Leaving Backfill ...
I1104 15:50:30.624607   66170 session.go:154] Close Session e25c2a4e-ff5d-11e9-bf19-784f43775513
I1104 15:50:30.624614   66170 scheduler.go:87] End scheduling ...
I1104 15:50:35.626149   66170 scheduler.go:72] Start scheduling ...
I1104 15:50:35.644249   66170 cache.go:771] There are <0> Jobs, <1> Queues and <1> Nodes in total for scheduling.
I1104 15:50:35.644260   66170 session.go:135] Open Session e55a2322-ff5d-11e9-bf19-784f43775513 with <0> Job and <1> Queues
I1104 15:50:35.644321   66170 proportion.go:67] The total resource is <cpu 4000.00, memory 4959854592.00, hugepages-2Mi 0.00>
I1104 15:50:35.644347   66170 proportion.go:117] Exiting when total weight is 0
I1104 15:50:35.644375   66170 enqueue.go:43] Enter Enqueue ...
I1104 15:50:35.644388   66170 enqueue.go:75] Try to enqueue PodGroup to 0 Queues
I1104 15:50:35.644403   66170 enqueue.go:122] Leaving Enqueue ...
I1104 15:50:35.644413   66170 allocate.go:43] Enter Allocate ...
I1104 15:50:35.644427   66170 allocate.go:94] Try to allocate resource to 0 Namespaces
I1104 15:50:35.644447   66170 allocate.go:253] Leaving Allocate ...
I1104 15:50:35.644456   66170 backfill.go:42] Enter Backfill ...
I1104 15:50:35.644465   66170 backfill.go:91] Leaving Backfill ...
I1104 15:50:35.644484   66170 session.go:154] Close Session e55a2322-ff5d-11e9-bf19-784f43775513
I1104 15:50:35.644492   66170 scheduler.go:87] End scheduling ...
I1104 15:50:40.647999   66170 scheduler.go:72] Start scheduling ...
I1104 15:50:40.663572   66170 cache.go:771] There are <0> Jobs, <1> Queues and <1> Nodes in total for scheduling.
I1104 15:50:40.663582   66170 session.go:135] Open Session e85806a2-ff5d-11e9-bf19-784f43775513 with <0> Job and <1> Queues
I1104 15:50:40.663631   66170 proportion.go:67] The total resource is <cpu 4000.00, memory 4959854592.00, hugepages-2Mi 0.00>
I1104 15:50:40.663657   66170 proportion.go:117] Exiting when total weight is 0
I1104 15:50:40.663679   66170 enqueue.go:43] Enter Enqueue ...
I1104 15:50:40.663686   66170 enqueue.go:75] Try to enqueue PodGroup to 0 Queues
I1104 15:50:40.663696   66170 enqueue.go:122] Leaving Enqueue ...
I1104 15:50:40.663704   66170 allocate.go:43] Enter Allocate ...
I1104 15:50:40.663711   66170 allocate.go:94] Try to allocate resource to 0 Namespaces
I1104 15:50:40.663727   66170 allocate.go:253] Leaving Allocate ...
I1104 15:50:40.663732   66170 backfill.go:42] Enter Backfill ...
I1104 15:50:40.663737   66170 backfill.go:91] Leaving Backfill ...
I1104 15:50:40.663755   66170 session.go:154] Close Session e85806a2-ff5d-11e9-bf19-784f43775513
I1104 15:50:40.663761   66170 scheduler.go:87] End scheduling ...
I1104 15:50:45.668322   66170 scheduler.go:72] Start scheduling ...
I1104 15:50:45.683681   66170 cache.go:771] There are <0> Jobs, <1> Queues and <1> Nodes in total for scheduling.
I1104 15:50:45.683693   66170 session.go:135] Open Session eb560854-ff5d-11e9-bf19-784f43775513 with <0> Job and <1> Queues
I1104 15:50:45.683711   66170 proportion.go:67] The total resource is <cpu 4000.00, memory 4959854592.00, hugepages-2Mi 0.00>
I1104 15:50:45.683737   66170 proportion.go:117] Exiting when total weight is 0
I1104 15:50:45.683799   66170 enqueue.go:43] Enter Enqueue ...
I1104 15:50:45.683806   66170 enqueue.go:75] Try to enqueue PodGroup to 0 Queues
I1104 15:50:45.683816   66170 enqueue.go:122] Leaving Enqueue ...
I1104 15:50:45.683825   66170 allocate.go:43] Enter Allocate ...
I1104 15:50:45.683833   66170 allocate.go:94] Try to allocate resource to 0 Namespaces
I1104 15:50:45.683856   66170 allocate.go:253] Leaving Allocate ...
I1104 15:50:45.683863   66170 backfill.go:42] Enter Backfill ...
I1104 15:50:45.683869   66170 backfill.go:91] Leaving Backfill ...
I1104 15:50:45.683890   66170 session.go:154] Close Session eb560854-ff5d-11e9-bf19-784f43775513
I1104 15:50:45.683897   66170 scheduler.go:87] End scheduling ...
I1104 15:50:50.684107   66170 scheduler.go:72] Start scheduling ...
I1104 15:50:50.698586   66170 cache.go:771] There are <0> Jobs, <1> Queues and <1> Nodes in total for scheduling.
I1104 15:50:50.698593   66170 session.go:135] Open Session ee533fea-ff5d-11e9-bf19-784f43775513 with <0> Job and <1> Queues
I1104 15:50:50.698630   66170 proportion.go:67] The total resource is <cpu 4000.00, memory 4959854592.00, hugepages-2Mi 0.00>
I1104 15:50:50.698647   66170 proportion.go:117] Exiting when total weight is 0
I1104 15:50:50.698663   66170 enqueue.go:43] Enter Enqueue ...
I1104 15:50:50.698668   66170 enqueue.go:75] Try to enqueue PodGroup to 0 Queues
I1104 15:50:50.698676   66170 enqueue.go:122] Leaving Enqueue ...
I1104 15:50:50.698682   66170 allocate.go:43] Enter Allocate ...
I1104 15:50:50.698687   66170 allocate.go:94] Try to allocate resource to 0 Namespaces
I1104 15:50:50.698698   66170 allocate.go:253] Leaving Allocate ...
I1104 15:50:50.698701   66170 backfill.go:42] Enter Backfill ...
I1104 15:50:50.698704   66170 backfill.go:91] Leaving Backfill ...
I1104 15:50:50.698717   66170 session.go:154] Close Session ee533fea-ff5d-11e9-bf19-784f43775513
I1104 15:50:50.698720   66170 scheduler.go:87] End scheduling ...
I1104 15:50:55.700157   66170 scheduler.go:72] Start scheduling ...
I1104 15:50:55.712264   66170 cache.go:771] There are <0> Jobs, <1> Queues and <1> Nodes in total for scheduling.
I1104 15:50:55.712272   66170 session.go:135] Open Session f150468e-ff5d-11e9-bf19-784f43775513 with <0> Job and <1> Queues
I1104 15:50:55.712308   66170 proportion.go:67] The total resource is <cpu 4000.00, memory 4959854592.00, hugepages-2Mi 0.00>
I1104 15:50:55.712325   66170 proportion.go:117] Exiting when total weight is 0
I1104 15:50:55.712341   66170 enqueue.go:43] Enter Enqueue ...
I1104 15:50:55.712345   66170 enqueue.go:75] Try to enqueue PodGroup to 0 Queues
I1104 15:50:55.712351   66170 enqueue.go:122] Leaving Enqueue ...
I1104 15:50:55.712357   66170 allocate.go:43] Enter Allocate ...
I1104 15:50:55.712364   66170 allocate.go:94] Try to allocate resource to 0 Namespaces
I1104 15:50:55.712374   66170 allocate.go:253] Leaving Allocate ...
I1104 15:50:55.712378   66170 backfill.go:42] Enter Backfill ...
I1104 15:50:55.712382   66170 backfill.go:91] Leaving Backfill ...
I1104 15:50:55.712394   66170 session.go:154] Close Session f150468e-ff5d-11e9-bf19-784f43775513
I1104 15:50:55.712399   66170 scheduler.go:87] End scheduling ...
I1104 15:51:00.717030   66170 scheduler.go:72] Start scheduling ...
I1104 15:51:00.732319   66170 cache.go:771] There are <0> Jobs, <1> Queues and <1> Nodes in total for scheduling.
I1104 15:51:00.732327   66170 session.go:135] Open Session f44e4692-ff5d-11e9-bf19-784f43775513 with <0> Job and <1> Queues
I1104 15:51:00.732339   66170 proportion.go:67] The total resource is <cpu 4000.00, memory 4959854592.00, hugepages-2Mi 0.00>
I1104 15:51:00.732355   66170 proportion.go:117] Exiting when total weight is 0
I1104 15:51:00.732401   66170 enqueue.go:43] Enter Enqueue ...
I1104 15:51:00.732405   66170 enqueue.go:75] Try to enqueue PodGroup to 0 Queues
I1104 15:51:00.732412   66170 enqueue.go:122] Leaving Enqueue ...
I1104 15:51:00.732417   66170 allocate.go:43] Enter Allocate ...
I1104 15:51:00.732422   66170 allocate.go:94] Try to allocate resource to 0 Namespaces
I1104 15:51:00.732432   66170 allocate.go:253] Leaving Allocate ...
I1104 15:51:00.732436   66170 backfill.go:42] Enter Backfill ...
I1104 15:51:00.732439   66170 backfill.go:91] Leaving Backfill ...
I1104 15:51:00.732451   66170 session.go:154] Close Session f44e4692-ff5d-11e9-bf19-784f43775513
I1104 15:51:00.732454   66170 scheduler.go:87] End scheduling ...
I1104 15:51:05.733431   66170 scheduler.go:72] Start scheduling ...
I1104 15:51:05.750031   66170 cache.go:771] There are <0> Jobs, <1> Queues and <1> Nodes in total for scheduling.
I1104 15:51:05.750039   66170 session.go:135] Open Session f74beade-ff5d-11e9-bf19-784f43775513 with <0> Job and <1> Queues
I1104 15:51:05.750093   66170 proportion.go:67] The total resource is <cpu 4000.00, memory 4959854592.00, hugepages-2Mi 0.00>
I1104 15:51:05.750109   66170 proportion.go:117] Exiting when total weight is 0
I1104 15:51:05.750114   66170 enqueue.go:43] Enter Enqueue ...
I1104 15:51:05.750119   66170 enqueue.go:75] Try to enqueue PodGroup to 0 Queues
I1104 15:51:05.750124   66170 enqueue.go:122] Leaving Enqueue ...
I1104 15:51:05.750130   66170 allocate.go:43] Enter Allocate ...
I1104 15:51:05.750134   66170 allocate.go:94] Try to allocate resource to 0 Namespaces
I1104 15:51:05.750144   66170 allocate.go:253] Leaving Allocate ...
I1104 15:51:05.750148   66170 backfill.go:42] Enter Backfill ...
I1104 15:51:05.750153   66170 backfill.go:91] Leaving Backfill ...
I1104 15:51:05.750168   66170 session.go:154] Close Session f74beade-ff5d-11e9-bf19-784f43775513
I1104 15:51:05.750172   66170 scheduler.go:87] End scheduling ...
F1104 15:51:10.268441   66170 helpers.go:210] Stopped listening on 127.0.0.1:11251 due to error: http: Server closed
goroutine 141 [running]:
volcano.sh/volcano/vendor/github.com/golang/glog.stacks(0xc0000e6001, 0xc0006a4000, 0x4b6, 0x2710)
	/Users/yuan.chen/GolandProjects/src/volcano.sh/volcano/vendor/github.com/golang/glog/glog.go:769 +0xb8
volcano.sh/volcano/vendor/github.com/golang/glog.(*loggingT).output(0x2efe3c0, 0xc000000003, 0xc0003260e0, 0x2e4a76d, 0xa, 0xd2, 0x0)
	/Users/yuan.chen/GolandProjects/src/volcano.sh/volcano/vendor/github.com/golang/glog/glog.go:723 +0x1b7
volcano.sh/volcano/vendor/github.com/golang/glog.(*loggingT).printf(0x2efe3c0, 0x3, 0x21b0861, 0x13, 0xc00007cf90, 0x2, 0x2)
	/Users/yuan.chen/GolandProjects/src/volcano.sh/volcano/vendor/github.com/golang/glog/glog.go:655 +0x14b
volcano.sh/volcano/vendor/github.com/golang/glog.Fatalf(...)
	/Users/yuan.chen/GolandProjects/src/volcano.sh/volcano/vendor/github.com/golang/glog/glog.go:1148
volcano.sh/volcano/pkg/apis/helpers.runServer.func2(0x23c27e0, 0xc00056ad40, 0xc0001680e0, 0xc0001d6d20)
	/Users/yuan.chen/GolandProjects/src/volcano.sh/volcano/pkg/apis/helpers/helpers.go:210 +0x2fc
created by volcano.sh/volcano/pkg/apis/helpers.runServer
	/Users/yuan.chen/GolandProjects/src/volcano.sh/volcano/pkg/apis/helpers/helpers.go:198 +0x170

goroutine 1 [chan receive (nil chan), 2 minutes]:
volcano.sh/volcano/cmd/scheduler/app.Run.func2(0x23d2260, 0xc000118070)
	/Users/yuan.chen/GolandProjects/src/volcano.sh/volcano/cmd/scheduler/app/server.go:107 +0x73
volcano.sh/volcano/cmd/scheduler/app.Run(0xc000588300, 0x223db28, 0x223cab0)
	/Users/yuan.chen/GolandProjects/src/volcano.sh/volcano/cmd/scheduler/app/server.go:111 +0x79b
main.main()
	/Users/yuan.chen/GolandProjects/src/volcano.sh/volcano/cmd/scheduler/main.go:62 +0x1ae

goroutine 19 [chan receive]:
volcano.sh/volcano/vendor/github.com/golang/glog.(*loggingT).flushDaemon(0x2efe3c0)
	/Users/yuan.chen/GolandProjects/src/volcano.sh/volcano/vendor/github.com/golang/glog/glog.go:882 +0x8b
created by volcano.sh/volcano/vendor/github.com/golang/glog.init.0
	/Users/yuan.chen/GolandProjects/src/volcano.sh/volcano/vendor/github.com/golang/glog/glog.go:410 +0x26f

goroutine 20 [chan receive]:
volcano.sh/volcano/vendor/k8s.io/klog.(*loggingT).flushDaemon(0x2efe560)
	/Users/yuan.chen/GolandProjects/src/volcano.sh/volcano/vendor/k8s.io/klog/klog.go:941 +0x8b
created by volcano.sh/volcano/vendor/k8s.io/klog.init.0
	/Users/yuan.chen/GolandProjects/src/volcano.sh/volcano/vendor/k8s.io/klog/klog.go:403 +0x6c

goroutine 36 [syscall]:
os/signal.signal_recv(0x23a80a0)
	/usr/local/opt/go/libexec/src/runtime/sigqueue.go:144 +0x96
os/signal.loop()
	/usr/local/opt/go/libexec/src/os/signal/signal_unix.go:23 +0x22
created by os/signal.init.0
	/usr/local/opt/go/libexec/src/os/signal/signal_unix.go:29 +0x41

goroutine 116 [chan receive, 2 minutes]:
volcano.sh/volcano/vendor/k8s.io/client-go/tools/cache.(*sharedProcessor).run(0xc0002962a0, 0xc0003e6000)
	/Users/yuan.chen/GolandProjects/src/volcano.sh/volcano/vendor/k8s.io/client-go/tools/cache/shared_informer.go:425 +0x49
volcano.sh/volcano/vendor/k8s.io/apimachinery/pkg/util/wait.(*Group).StartWithChannel.func1()
	/Users/yuan.chen/GolandProjects/src/volcano.sh/volcano/vendor/k8s.io/apimachinery/pkg/util/wait/wait.go:54 +0x2e
volcano.sh/volcano/vendor/k8s.io/apimachinery/pkg/util/wait.(*Group).Start.func1(0xc000496000, 0xc00000e0e0)
	/Users/yuan.chen/GolandProjects/src/volcano.sh/volcano/vendor/k8s.io/apimachinery/pkg/util/wait/wait.go:71 +0x59
created by volcano.sh/volcano/vendor/k8s.io/apimachinery/pkg/util/wait.(*Group).Start
	/Users/yuan.chen/GolandProjects/src/volcano.sh/volcano/vendor/k8s.io/apimachinery/pkg/util/wait/wait.go:69 +0x62

goroutine 64 [select]:
volcano.sh/volcano/vendor/k8s.io/apimachinery/pkg/util/wait.JitterUntil(0x223cab0, 0x12a05f200, 0x0, 0x1, 0xc0001300c0)
	/Users/yuan.chen/GolandProjects/src/volcano.sh/volcano/vendor/k8s.io/apimachinery/pkg/util/wait/wait.go:145 +0x181
volcano.sh/volcano/vendor/k8s.io/apimachinery/pkg/util/wait.Until(0x223cab0, 0x12a05f200, 0xc0001300c0)
	/Users/yuan.chen/GolandProjects/src/volcano.sh/volcano/vendor/k8s.io/apimachinery/pkg/util/wait/wait.go:88 +0x4d
created by main.main
	/Users/yuan.chen/GolandProjects/src/volcano.sh/volcano/cmd/scheduler/main.go:59 +0x173

goroutine 132 [chan receive]:
volcano.sh/volcano/vendor/k8s.io/client-go/util/workqueue.(*Type).updateUnfinishedWorkLoop(0xc000564c60)
	/Users/yuan.chen/GolandProjects/src/volcano.sh/volcano/vendor/k8s.io/client-go/util/workqueue/queue.go:198 +0xe0
created by volcano.sh/volcano/vendor/k8s.io/client-go/util/workqueue.newQueue
	/Users/yuan.chen/GolandProjects/src/volcano.sh/volcano/vendor/k8s.io/client-go/util/workqueue/queue.go:58 +0x132

goroutine 130 [IO wait]:
internal/poll.runtime_pollWait(0x65a30b8, 0x72, 0xffffffffffffffff)
	/usr/local/opt/go/libexec/src/runtime/netpoll.go:184 +0x55
internal/poll.(*pollDesc).wait(0xc00049d498, 0x72, 0xe500, 0xe5ce, 0xffffffffffffffff)
	/usr/local/opt/go/libexec/src/internal/poll/fd_poll_runtime.go:87 +0x45
internal/poll.(*pollDesc).waitRead(...)
	/usr/local/opt/go/libexec/src/internal/poll/fd_poll_runtime.go:92
internal/poll.(*FD).Read(0xc00049d480, 0xc00097a000, 0xe5ce, 0xe5ce, 0x0, 0x0, 0x0)
	/usr/local/opt/go/libexec/src/internal/poll/fd_unix.go:169 +0x22b
net.(*netFD).Read(0xc00049d480, 0xc00097a000, 0xe5ce, 0xe5ce, 0x203000, 0x50, 0xc0000838c8)
	/usr/local/opt/go/libexec/src/net/fd_unix.go:202 +0x4f
net.(*conn).Read(0xc0000102b0, 0xc00097a000, 0xe5ce, 0xe5ce, 0x0, 0x0, 0x0)
	/usr/local/opt/go/libexec/src/net/net.go:184 +0x68
crypto/tls.(*atLeastReader).Read(0xc000a0ae60, 0xc00097a000, 0xe5ce, 0xe5ce, 0x14e1165, 0x14e9a73, 0xc000083970)
	/usr/local/opt/go/libexec/src/crypto/tls/conn.go:780 +0x60
bytes.(*Buffer).ReadFrom(0xc00053fe58, 0x2397da0, 0xc000a0ae60, 0x100c165, 0x1ff03e0, 0x21438a0)
	/usr/local/opt/go/libexec/src/bytes/buffer.go:204 +0xb4
crypto/tls.(*Conn).readFromUntil(0xc00053fc00, 0x65a3188, 0xc0000102b0, 0x5, 0xc0000102b0, 0x203000)
	/usr/local/opt/go/libexec/src/crypto/tls/conn.go:802 +0xec
crypto/tls.(*Conn).readRecordOrCCS(0xc00053fc00, 0x0, 0x0, 0xc000a0ae40)
	/usr/local/opt/go/libexec/src/crypto/tls/conn.go:609 +0x124
crypto/tls.(*Conn).readRecord(...)
	/usr/local/opt/go/libexec/src/crypto/tls/conn.go:577
crypto/tls.(*Conn).Read(0xc00053fc00, 0xc000660000, 0x1000, 0x1000, 0x0, 0x0, 0x0)
	/usr/local/opt/go/libexec/src/crypto/tls/conn.go:1255 +0x161
bufio.(*Reader).Read(0xc0002f9200, 0xc0001681f8, 0x9, 0x9, 0x3d9e, 0x10cf, 0x0)
	/usr/local/opt/go/libexec/src/bufio/bufio.go:226 +0x26a
io.ReadAtLeast(0x2397c00, 0xc0002f9200, 0xc0001681f8, 0x9, 0x9, 0x9, 0x0, 0x0, 0xc000083f78)
	/usr/local/opt/go/libexec/src/io/io.go:310 +0x87
io.ReadFull(...)
	/usr/local/opt/go/libexec/src/io/io.go:329
volcano.sh/volcano/vendor/golang.org/x/net/http2.readFrameHeader(0xc0001681f8, 0x9, 0x9, 0x2397c00, 0xc0002f9200, 0x0, 0x0, 0xc000a72e70, 0x0)
	/Users/yuan.chen/GolandProjects/src/volcano.sh/volcano/vendor/golang.org/x/net/http2/frame.go:237 +0x87
volcano.sh/volcano/vendor/golang.org/x/net/http2.(*Framer).ReadFrame(0xc0001681c0, 0xc000a72e70, 0x0, 0x0, 0x0)
	/Users/yuan.chen/GolandProjects/src/volcano.sh/volcano/vendor/golang.org/x/net/http2/frame.go:492 +0xa1
volcano.sh/volcano/vendor/golang.org/x/net/http2.(*clientConnReadLoop).run(0xc000083fb8, 0x1000000000001, 0x0)
	/Users/yuan.chen/GolandProjects/src/volcano.sh/volcano/vendor/golang.org/x/net/http2/transport.go:1679 +0x8c
volcano.sh/volcano/vendor/golang.org/x/net/http2.(*ClientConn).readLoop(0xc000502780)
	/Users/yuan.chen/GolandProjects/src/volcano.sh/volcano/vendor/golang.org/x/net/http2/transport.go:1607 +0xa3
created by volcano.sh/volcano/vendor/golang.org/x/net/http2.(*Transport).newClientConn
	/Users/yuan.chen/GolandProjects/src/volcano.sh/volcano/vendor/golang.org/x/net/http2/transport.go:670 +0x62f

goroutine 133 [select]:
volcano.sh/volcano/vendor/k8s.io/client-go/util/workqueue.(*delayingType).waitingLoop(0xc00012a460)
	/Users/yuan.chen/GolandProjects/src/volcano.sh/volcano/vendor/k8s.io/client-go/util/workqueue/delaying_queue.go:206 +0x344
created by volcano.sh/volcano/vendor/k8s.io/client-go/util/workqueue.newDelayingQueue
	/Users/yuan.chen/GolandProjects/src/volcano.sh/volcano/vendor/k8s.io/client-go/util/workqueue/delaying_queue.go:54 +0x1ae

goroutine 27 [chan receive, 2 minutes]:
volcano.sh/volcano/vendor/k8s.io/client-go/tools/cache.(*processorListener).run.func1.1(0x60, 0x60, 0xc00006cf58)
	/Users/yuan.chen/GolandProjects/src/volcano.sh/volcano/vendor/k8s.io/client-go/tools/cache/shared_informer.go:549 +0x54
volcano.sh/volcano/vendor/k8s.io/apimachinery/pkg/util/wait.ExponentialBackoff(0x989680, 0x3ff0000000000000, 0x3fb999999999999a, 0x5, 0xc000a5edd8, 0xc00006ce20, 0x10589a7)
	/Users/yuan.chen/GolandProjects/src/volcano.sh/volcano/vendor/k8s.io/apimachinery/pkg/util/wait/wait.go:203 +0xde
volcano.sh/volcano/vendor/k8s.io/client-go/tools/cache.(*processorListener).run.func1()
	/Users/yuan.chen/GolandProjects/src/volcano.sh/volcano/vendor/k8s.io/client-go/tools/cache/shared_informer.go:548 +0x89
volcano.sh/volcano/vendor/k8s.io/apimachinery/pkg/util/wait.JitterUntil.func1(0xc00006cf40)
	/Users/yuan.chen/GolandProjects/src/volcano.sh/volcano/vendor/k8s.io/apimachinery/pkg/util/wait/wait.go:133 +0x5e
volcano.sh/volcano/vendor/k8s.io/apimachinery/pkg/util/wait.JitterUntil(0xc000a5ef40, 0xdf8475800, 0x0, 0x1030501, 0xc000330120)
	/Users/yuan.chen/GolandProjects/src/volcano.sh/volcano/vendor/k8s.io/apimachinery/pkg/util/wait/wait.go:134 +0xf8
volcano.sh/volcano/vendor/k8s.io/apimachinery/pkg/util/wait.Until(...)
	/Users/yuan.chen/GolandProjects/src/volcano.sh/volcano/vendor/k8s.io/apimachinery/pkg/util/wait/wait.go:88
volcano.sh/volcano/vendor/k8s.io/client-go/tools/cache.(*processorListener).run(0xc0005a5900)
	/Users/yuan.chen/GolandProjects/src/volcano.sh/volcano/vendor/k8s.io/client-go/tools/cache/shared_informer.go:546 +0x9b
volcano.sh/volcano/vendor/k8s.io/apimachinery/pkg/util/wait.(*Group).Start.func1(0xc0002968b0, 0xc00054c200)
	/Users/yuan.chen/GolandProjects/src/volcano.sh/volcano/vendor/k8s.io/apimachinery/pkg/util/wait/wait.go:71 +0x59
created by volcano.sh/volcano/vendor/k8s.io/apimachinery/pkg/util/wait.(*Group).Start
	/Users/yuan.chen/GolandProjects/src/volcano.sh/volcano/vendor/k8s.io/apimachinery/pkg/util/wait/wait.go:69 +0x62

goroutine 134 [chan receive]:
volcano.sh/volcano/vendor/k8s.io/client-go/util/workqueue.(*Type).updateUnfinishedWorkLoop(0xc000564d80)
	/Users/yuan.chen/GolandProjects/src/volcano.sh/volcano/vendor/k8s.io/client-go/util/workqueue/queue.go:198 +0xe0
created by volcano.sh/volcano/vendor/k8s.io/client-go/util/workqueue.newQueue
	/Users/yuan.chen/GolandProjects/src/volcano.sh/volcano/vendor/k8s.io/client-go/util/workqueue/queue.go:58 +0x132

goroutine 135 [select]:
volcano.sh/volcano/vendor/k8s.io/client-go/util/workqueue.(*delayingType).waitingLoop(0xc00012a550)
	/Users/yuan.chen/GolandProjects/src/volcano.sh/volcano/vendor/k8s.io/client-go/util/workqueue/delaying_queue.go:206 +0x344
created by volcano.sh/volcano/vendor/k8s.io/client-go/util/workqueue.newDelayingQueue
	/Users/yuan.chen/GolandProjects/src/volcano.sh/volcano/vendor/k8s.io/client-go/util/workqueue/delaying_queue.go:54 +0x1ae

goroutine 136 [chan receive, 2 minutes]:
volcano.sh/volcano/vendor/k8s.io/apimachinery/pkg/watch.(*Broadcaster).loop(0xc00016f200)
	/Users/yuan.chen/GolandProjects/src/volcano.sh/volcano/vendor/k8s.io/apimachinery/pkg/watch/mux.go:207 +0x66
created by volcano.sh/volcano/vendor/k8s.io/apimachinery/pkg/watch.NewBroadcaster
	/Users/yuan.chen/GolandProjects/src/volcano.sh/volcano/vendor/k8s.io/apimachinery/pkg/watch/mux.go:75 +0xcc

goroutine 137 [chan receive, 2 minutes]:
volcano.sh/volcano/vendor/k8s.io/client-go/tools/record.(*eventBroadcasterImpl).StartEventWatcher.func1(0x23a38a0, 0xc00053ae40, 0xc00053ae10)
	/Users/yuan.chen/GolandProjects/src/volcano.sh/volcano/vendor/k8s.io/client-go/tools/record/event.go:231 +0xc5
created by volcano.sh/volcano/vendor/k8s.io/client-go/tools/record.(*eventBroadcasterImpl).StartEventWatcher
	/Users/yuan.chen/GolandProjects/src/volcano.sh/volcano/vendor/k8s.io/client-go/tools/record/event.go:229 +0x6e

goroutine 138 [IO wait, 2 minutes]:
internal/poll.runtime_pollWait(0x65a2f18, 0x72, 0x0)
	/usr/local/opt/go/libexec/src/runtime/netpoll.go:184 +0x55
internal/poll.(*pollDesc).wait(0xc000480398, 0x72, 0x0, 0x0, 0x21a2933)
	/usr/local/opt/go/libexec/src/internal/poll/fd_poll_runtime.go:87 +0x45
internal/poll.(*pollDesc).waitRead(...)
	/usr/local/opt/go/libexec/src/internal/poll/fd_poll_runtime.go:92
internal/poll.(*FD).Accept(0xc000480380, 0x0, 0x0, 0x0, 0x0, 0x0, 0x0, 0x0)
	/usr/local/opt/go/libexec/src/internal/poll/fd_unix.go:384 +0x1f8
net.(*netFD).accept(0xc000480380, 0xc000081d40, 0xc00009e400, 0x3391008)
	/usr/local/opt/go/libexec/src/net/fd_unix.go:238 +0x42
net.(*TCPListener).accept(0xc0000da700, 0xc000081d70, 0x100eac8, 0x30)
	/usr/local/opt/go/libexec/src/net/tcpsock_posix.go:139 +0x32
net.(*TCPListener).Accept(0xc0000da700, 0x20c6980, 0xc0004b2c90, 0x1fb6ee0, 0x2ee59d0)
	/usr/local/opt/go/libexec/src/net/tcpsock.go:261 +0x47
net/http.(*Server).Serve(0xc0004ae000, 0x23c27e0, 0xc0000da700, 0x0, 0x0)
	/usr/local/opt/go/libexec/src/net/http/server.go:2896 +0x286
net/http.(*Server).ListenAndServe(0xc0004ae000, 0xc0004ae000, 0x8)
	/usr/local/opt/go/libexec/src/net/http/server.go:2825 +0xb7
net/http.ListenAndServe(...)
	/usr/local/opt/go/libexec/src/net/http/server.go:3080
volcano.sh/volcano/cmd/scheduler/app.Run.func1(0xc000588300)
	/Users/yuan.chen/GolandProjects/src/volcano.sh/volcano/cmd/scheduler/app/server.go:98 +0xd1
created by volcano.sh/volcano/cmd/scheduler/app.Run
	/Users/yuan.chen/GolandProjects/src/volcano.sh/volcano/cmd/scheduler/app/server.go:96 +0x11e

goroutine 89 [chan receive, 2 minutes]:
volcano.sh/volcano/vendor/k8s.io/client-go/tools/cache.(*processorListener).run.func1.1(0x2f05740, 0x6404cb8, 0xc000181d98)
	/Users/yuan.chen/GolandProjects/src/volcano.sh/volcano/vendor/k8s.io/client-go/tools/cache/shared_informer.go:549 +0x54
volcano.sh/volcano/vendor/k8s.io/apimachinery/pkg/util/wait.ExponentialBackoff(0x989680, 0x3ff0000000000000, 0x3fb999999999999a, 0x5, 0xc0006f9dd8, 0x1f67e20, 0x1)
	/Users/yuan.chen/GolandProjects/src/volcano.sh/volcano/vendor/k8s.io/apimachinery/pkg/util/wait/wait.go:203 +0xde
volcano.sh/volcano/vendor/k8s.io/client-go/tools/cache.(*processorListener).run.func1()
	/Users/yuan.chen/GolandProjects/src/volcano.sh/volcano/vendor/k8s.io/client-go/tools/cache/shared_informer.go:548 +0x89
volcano.sh/volcano/vendor/k8s.io/apimachinery/pkg/util/wait.JitterUntil.func1(0xc000181f40)
	/Users/yuan.chen/GolandProjects/src/volcano.sh/volcano/vendor/k8s.io/apimachinery/pkg/util/wait/wait.go:133 +0x5e
volcano.sh/volcano/vendor/k8s.io/apimachinery/pkg/util/wait.JitterUntil(0xc0006f9f40, 0xdf8475800, 0x0, 0x1030501, 0xc000340120)
	/Users/yuan.chen/GolandProjects/src/volcano.sh/volcano/vendor/k8s.io/apimachinery/pkg/util/wait/wait.go:134 +0xf8
volcano.sh/volcano/vendor/k8s.io/apimachinery/pkg/util/wait.Until(...)
	/Users/yuan.chen/GolandProjects/src/volcano.sh/volcano/vendor/k8s.io/apimachinery/pkg/util/wait/wait.go:88
volcano.sh/volcano/vendor/k8s.io/client-go/tools/cache.(*processorListener).run(0xc0005a4400)
	/Users/yuan.chen/GolandProjects/src/volcano.sh/volcano/vendor/k8s.io/client-go/tools/cache/shared_informer.go:546 +0x9b
volcano.sh/volcano/vendor/k8s.io/apimachinery/pkg/util/wait.(*Group).Start.func1(0xc000296300, 0xc0000ca560)
	/Users/yuan.chen/GolandProjects/src/volcano.sh/volcano/vendor/k8s.io/apimachinery/pkg/util/wait/wait.go:71 +0x59
created by volcano.sh/volcano/vendor/k8s.io/apimachinery/pkg/util/wait.(*Group).Start
	/Users/yuan.chen/GolandProjects/src/volcano.sh/volcano/vendor/k8s.io/apimachinery/pkg/util/wait/wait.go:69 +0x62

goroutine 97 [chan receive, 2 minutes]:
volcano.sh/volcano/vendor/k8s.io/client-go/tools/cache.(*processorListener).run.func1.1(0x0, 0x0, 0x0)
	/Users/yuan.chen/GolandProjects/src/volcano.sh/volcano/vendor/k8s.io/client-go/tools/cache/shared_informer.go:549 +0x54
volcano.sh/volcano/vendor/k8s.io/apimachinery/pkg/util/wait.ExponentialBackoff(0x989680, 0x3ff0000000000000, 0x3fb999999999999a, 0x5, 0xc00073edd8, 0x101984e, 0x3754b60)
	/Users/yuan.chen/GolandProjects/src/volcano.sh/volcano/vendor/k8s.io/apimachinery/pkg/util/wait/wait.go:203 +0xde
volcano.sh/volcano/vendor/k8s.io/client-go/tools/cache.(*processorListener).run.func1()
	/Users/yuan.chen/GolandProjects/src/volcano.sh/volcano/vendor/k8s.io/client-go/tools/cache/shared_informer.go:548 +0x89
volcano.sh/volcano/vendor/k8s.io/apimachinery/pkg/util/wait.JitterUntil.func1(0xc00038bf40)
	/Users/yuan.chen/GolandProjects/src/volcano.sh/volcano/vendor/k8s.io/apimachinery/pkg/util/wait/wait.go:133 +0x5e
volcano.sh/volcano/vendor/k8s.io/apimachinery/pkg/util/wait.JitterUntil(0xc00073ef40, 0xdf8475800, 0x0, 0x1030501, 0xc000340300)
	/Users/yuan.chen/GolandProjects/src/volcano.sh/volcano/vendor/k8s.io/apimachinery/pkg/util/wait/wait.go:134 +0xf8
volcano.sh/volcano/vendor/k8s.io/apimachinery/pkg/util/wait.Until(...)
	/Users/yuan.chen/GolandProjects/src/volcano.sh/volcano/vendor/k8s.io/apimachinery/pkg/util/wait/wait.go:88
volcano.sh/volcano/vendor/k8s.io/client-go/tools/cache.(*processorListener).run(0xc0005a5d00)
	/Users/yuan.chen/GolandProjects/src/volcano.sh/volcano/vendor/k8s.io/client-go/tools/cache/shared_informer.go:546 +0x9b
volcano.sh/volcano/vendor/k8s.io/apimachinery/pkg/util/wait.(*Group).Start.func1(0xc000296920, 0xc0000ca5e0)
	/Users/yuan.chen/GolandProjects/src/volcano.sh/volcano/vendor/k8s.io/apimachinery/pkg/util/wait/wait.go:71 +0x59
created by volcano.sh/volcano/vendor/k8s.io/apimachinery/pkg/util/wait.(*Group).Start
	/Users/yuan.chen/GolandProjects/src/volcano.sh/volcano/vendor/k8s.io/apimachinery/pkg/util/wait/wait.go:69 +0x62

goroutine 143 [select]:
volcano.sh/volcano/vendor/k8s.io/apimachinery/pkg/util/wait.poller.func1.1(0xc0001d6ea0, 0x5f5e100, 0x0, 0x0)
	/Users/yuan.chen/GolandProjects/src/volcano.sh/volcano/vendor/k8s.io/apimachinery/pkg/util/wait/wait.go:374 +0x18e
created by volcano.sh/volcano/vendor/k8s.io/apimachinery/pkg/util/wait.poller.func1
	/Users/yuan.chen/GolandProjects/src/volcano.sh/volcano/vendor/k8s.io/apimachinery/pkg/util/wait/wait.go:357 +0x8c

goroutine 144 [sync.Cond.Wait, 2 minutes]:
runtime.goparkunlock(...)
	/usr/local/opt/go/libexec/src/runtime/proc.go:310
sync.runtime_notifyListWait(0xc0001da028, 0x0)
	/usr/local/opt/go/libexec/src/runtime/sema.go:510 +0xf8
sync.(*Cond).Wait(0xc0001da018)
	/usr/local/opt/go/libexec/src/sync/cond.go:56 +0x9d
volcano.sh/volcano/vendor/k8s.io/client-go/tools/cache.(*DeltaFIFO).Pop(0xc0001da000, 0xc0000ca260, 0x0, 0x0, 0x0, 0x0)
	/Users/yuan.chen/GolandProjects/src/volcano.sh/volcano/vendor/k8s.io/client-go/tools/cache/delta_fifo.go:423 +0xa6
volcano.sh/volcano/vendor/k8s.io/client-go/tools/cache.(*controller).processLoop(0xc00003c300)
	/Users/yuan.chen/GolandProjects/src/volcano.sh/volcano/vendor/k8s.io/client-go/tools/cache/controller.go:150 +0x40
volcano.sh/volcano/vendor/k8s.io/apimachinery/pkg/util/wait.JitterUntil.func1(0xc000625e00)
	/Users/yuan.chen/GolandProjects/src/volcano.sh/volcano/vendor/k8s.io/apimachinery/pkg/util/wait/wait.go:133 +0x5e
volcano.sh/volcano/vendor/k8s.io/apimachinery/pkg/util/wait.JitterUntil(0xc000625e00, 0x3b9aca00, 0x0, 0xc000142601, 0x0)
	/Users/yuan.chen/GolandProjects/src/volcano.sh/volcano/vendor/k8s.io/apimachinery/pkg/util/wait/wait.go:134 +0xf8
volcano.sh/volcano/vendor/k8s.io/apimachinery/pkg/util/wait.Until(...)
	/Users/yuan.chen/GolandProjects/src/volcano.sh/volcano/vendor/k8s.io/apimachinery/pkg/util/wait/wait.go:88
volcano.sh/volcano/vendor/k8s.io/client-go/tools/cache.(*controller).Run(0xc00003c300, 0x0)
	/Users/yuan.chen/GolandProjects/src/volcano.sh/volcano/vendor/k8s.io/client-go/tools/cache/controller.go:124 +0x2fd
volcano.sh/volcano/vendor/k8s.io/client-go/tools/cache.(*sharedIndexInformer).Run(0xc0001de900, 0x0)
	/Users/yuan.chen/GolandProjects/src/volcano.sh/volcano/vendor/k8s.io/client-go/tools/cache/shared_informer.go:227 +0x47f
created by volcano.sh/volcano/pkg/scheduler/cache.(*SchedulerCache).Run
	/Users/yuan.chen/GolandProjects/src/volcano.sh/volcano/pkg/scheduler/cache/cache.go:434 +0x5e

goroutine 145 [sync.Cond.Wait, 2 minutes]:
runtime.goparkunlock(...)
	/usr/local/opt/go/libexec/src/runtime/proc.go:310
sync.runtime_notifyListWait(0xc0002d4028, 0x1)
	/usr/local/opt/go/libexec/src/runtime/sema.go:510 +0xf8
sync.(*Cond).Wait(0xc0002d4018)
	/usr/local/opt/go/libexec/src/sync/cond.go:56 +0x9d
volcano.sh/volcano/vendor/k8s.io/client-go/tools/cache.(*DeltaFIFO).Pop(0xc0002d4000, 0xc0005d4080, 0x0, 0x0, 0x0, 0x0)
	/Users/yuan.chen/GolandProjects/src/volcano.sh/volcano/vendor/k8s.io/client-go/tools/cache/delta_fifo.go:423 +0xa6
volcano.sh/volcano/vendor/k8s.io/client-go/tools/cache.(*controller).processLoop(0xc00043e080)
	/Users/yuan.chen/GolandProjects/src/volcano.sh/volcano/vendor/k8s.io/client-go/tools/cache/controller.go:150 +0x40
volcano.sh/volcano/vendor/k8s.io/apimachinery/pkg/util/wait.JitterUntil.func1(0xc00007de00)
	/Users/yuan.chen/GolandProjects/src/volcano.sh/volcano/vendor/k8s.io/apimachinery/pkg/util/wait/wait.go:133 +0x5e
volcano.sh/volcano/vendor/k8s.io/apimachinery/pkg/util/wait.JitterUntil(0xc00007de00, 0x3b9aca00, 0x0, 0xc00053f101, 0x0)
	/Users/yuan.chen/GolandProjects/src/volcano.sh/volcano/vendor/k8s.io/apimachinery/pkg/util/wait/wait.go:134 +0xf8
volcano.sh/volcano/vendor/k8s.io/apimachinery/pkg/util/wait.Until(...)
	/Users/yuan.chen/GolandProjects/src/volcano.sh/volcano/vendor/k8s.io/apimachinery/pkg/util/wait/wait.go:88
volcano.sh/volcano/vendor/k8s.io/client-go/tools/cache.(*controller).Run(0xc00043e080, 0x0)
	/Users/yuan.chen/GolandProjects/src/volcano.sh/volcano/vendor/k8s.io/client-go/tools/cache/controller.go:124 +0x2fd
volcano.sh/volcano/vendor/k8s.io/client-go/tools/cache.(*sharedIndexInformer).Run(0xc0001de870, 0x0)
	/Users/yuan.chen/GolandProjects/src/volcano.sh/volcano/vendor/k8s.io/client-go/tools/cache/shared_informer.go:227 +0x47f
created by volcano.sh/volcano/pkg/scheduler/cache.(*SchedulerCache).Run
	/Users/yuan.chen/GolandProjects/src/volcano.sh/volcano/pkg/scheduler/cache/cache.go:435 +0x9b

goroutine 146 [sync.Cond.Wait]:
runtime.goparkunlock(...)
	/usr/local/opt/go/libexec/src/runtime/proc.go:310
sync.runtime_notifyListWait(0xc00034a028, 0x4)
	/usr/local/opt/go/libexec/src/runtime/sema.go:510 +0xf8
sync.(*Cond).Wait(0xc00034a018)
	/usr/local/opt/go/libexec/src/sync/cond.go:56 +0x9d
volcano.sh/volcano/vendor/k8s.io/client-go/tools/cache.(*DeltaFIFO).Pop(0xc00034a000, 0xc000314230, 0x0, 0x0, 0x0, 0x0)
	/Users/yuan.chen/GolandProjects/src/volcano.sh/volcano/vendor/k8s.io/client-go/tools/cache/delta_fifo.go:423 +0xa6
volcano.sh/volcano/vendor/k8s.io/client-go/tools/cache.(*controller).processLoop(0xc000480680)
	/Users/yuan.chen/GolandProjects/src/volcano.sh/volcano/vendor/k8s.io/client-go/tools/cache/controller.go:150 +0x40
volcano.sh/volcano/vendor/k8s.io/apimachinery/pkg/util/wait.JitterUntil.func1(0xc000082e00)
	/Users/yuan.chen/GolandProjects/src/volcano.sh/volcano/vendor/k8s.io/apimachinery/pkg/util/wait/wait.go:133 +0x5e
volcano.sh/volcano/vendor/k8s.io/apimachinery/pkg/util/wait.JitterUntil(0xc000082e00, 0x3b9aca00, 0x0, 0xc000586501, 0x0)
	/Users/yuan.chen/GolandProjects/src/volcano.sh/volcano/vendor/k8s.io/apimachinery/pkg/util/wait/wait.go:134 +0xf8
volcano.sh/volcano/vendor/k8s.io/apimachinery/pkg/util/wait.Until(...)
	/Users/yuan.chen/GolandProjects/src/volcano.sh/volcano/vendor/k8s.io/apimachinery/pkg/util/wait/wait.go:88
volcano.sh/volcano/vendor/k8s.io/client-go/tools/cache.(*controller).Run(0xc000480680, 0x0)
	/Users/yuan.chen/GolandProjects/src/volcano.sh/volcano/vendor/k8s.io/client-go/tools/cache/controller.go:124 +0x2fd
volcano.sh/volcano/vendor/k8s.io/client-go/tools/cache.(*sharedIndexInformer).Run(0xc0001de7e0, 0x0)
	/Users/yuan.chen/GolandProjects/src/volcano.sh/volcano/vendor/k8s.io/client-go/tools/cache/shared_informer.go:227 +0x47f
created by volcano.sh/volcano/pkg/scheduler/cache.(*SchedulerCache).Run
	/Users/yuan.chen/GolandProjects/src/volcano.sh/volcano/pkg/scheduler/cache/cache.go:436 +0xd8

goroutine 147 [sync.Cond.Wait, 2 minutes]:
runtime.goparkunlock(...)
	/usr/local/opt/go/libexec/src/runtime/proc.go:310
sync.runtime_notifyListWait(0xc0001365a8, 0x0)
	/usr/local/opt/go/libexec/src/runtime/sema.go:510 +0xf8
sync.(*Cond).Wait(0xc000136598)
	/usr/local/opt/go/libexec/src/sync/cond.go:56 +0x9d
volcano.sh/volcano/vendor/k8s.io/client-go/tools/cache.(*DeltaFIFO).Pop(0xc000136580, 0xc000333750, 0x0, 0x0, 0x0, 0x0)
	/Users/yuan.chen/GolandProjects/src/volcano.sh/volcano/vendor/k8s.io/client-go/tools/cache/delta_fifo.go:423 +0xa6
volcano.sh/volcano/vendor/k8s.io/client-go/tools/cache.(*controller).processLoop(0xc0002d6080)
	/Users/yuan.chen/GolandProjects/src/volcano.sh/volcano/vendor/k8s.io/client-go/tools/cache/controller.go:150 +0x40
volcano.sh/volcano/vendor/k8s.io/apimachinery/pkg/util/wait.JitterUntil.func1(0xc00065be00)
	/Users/yuan.chen/GolandProjects/src/volcano.sh/volcano/vendor/k8s.io/apimachinery/pkg/util/wait/wait.go:133 +0x5e
volcano.sh/volcano/vendor/k8s.io/apimachinery/pkg/util/wait.JitterUntil(0xc00065be00, 0x3b9aca00, 0x0, 0xc0004f5001, 0x0)
	/Users/yuan.chen/GolandProjects/src/volcano.sh/volcano/vendor/k8s.io/apimachinery/pkg/util/wait/wait.go:134 +0xf8
volcano.sh/volcano/vendor/k8s.io/apimachinery/pkg/util/wait.Until(...)
	/Users/yuan.chen/GolandProjects/src/volcano.sh/volcano/vendor/k8s.io/apimachinery/pkg/util/wait/wait.go:88
volcano.sh/volcano/vendor/k8s.io/client-go/tools/cache.(*controller).Run(0xc0002d6080, 0x0)
	/Users/yuan.chen/GolandProjects/src/volcano.sh/volcano/vendor/k8s.io/client-go/tools/cache/controller.go:124 +0x2fd
volcano.sh/volcano/vendor/k8s.io/client-go/tools/cache.(*sharedIndexInformer).Run(0xc0001deb40, 0x0)
	/Users/yuan.chen/GolandProjects/src/volcano.sh/volcano/vendor/k8s.io/client-go/tools/cache/shared_informer.go:227 +0x47f
created by volcano.sh/volcano/pkg/scheduler/cache.(*SchedulerCache).Run
	/Users/yuan.chen/GolandProjects/src/volcano.sh/volcano/pkg/scheduler/cache/cache.go:437 +0x118

goroutine 148 [sync.Cond.Wait, 2 minutes]:
runtime.goparkunlock(...)
	/usr/local/opt/go/libexec/src/runtime/proc.go:310
sync.runtime_notifyListWait(0xc00034e188, 0x0)
	/usr/local/opt/go/libexec/src/runtime/sema.go:510 +0xf8
sync.(*Cond).Wait(0xc00034e178)
	/usr/local/opt/go/libexec/src/sync/cond.go:56 +0x9d
volcano.sh/volcano/vendor/k8s.io/client-go/tools/cache.(*DeltaFIFO).Pop(0xc00034e160, 0xc0003761f0, 0x0, 0x0, 0x0, 0x0)
	/Users/yuan.chen/GolandProjects/src/volcano.sh/volcano/vendor/k8s.io/client-go/tools/cache/delta_fifo.go:423 +0xa6
volcano.sh/volcano/vendor/k8s.io/client-go/tools/cache.(*controller).processLoop(0xc00041c700)
	/Users/yuan.chen/GolandProjects/src/volcano.sh/volcano/vendor/k8s.io/client-go/tools/cache/controller.go:150 +0x40
volcano.sh/volcano/vendor/k8s.io/apimachinery/pkg/util/wait.JitterUntil.func1(0xc00061ae00)
	/Users/yuan.chen/GolandProjects/src/volcano.sh/volcano/vendor/k8s.io/apimachinery/pkg/util/wait/wait.go:133 +0x5e
volcano.sh/volcano/vendor/k8s.io/apimachinery/pkg/util/wait.JitterUntil(0xc00061ae00, 0x3b9aca00, 0x0, 0xc0004f5301, 0x0)
	/Users/yuan.chen/GolandProjects/src/volcano.sh/volcano/vendor/k8s.io/apimachinery/pkg/util/wait/wait.go:134 +0xf8
volcano.sh/volcano/vendor/k8s.io/apimachinery/pkg/util/wait.Until(...)
	/Users/yuan.chen/GolandProjects/src/volcano.sh/volcano/vendor/k8s.io/apimachinery/pkg/util/wait/wait.go:88
volcano.sh/volcano/vendor/k8s.io/client-go/tools/cache.(*controller).Run(0xc00041c700, 0x0)
	/Users/yuan.chen/GolandProjects/src/volcano.sh/volcano/vendor/k8s.io/client-go/tools/cache/controller.go:124 +0x2fd
volcano.sh/volcano/vendor/k8s.io/client-go/tools/cache.(*sharedIndexInformer).Run(0xc0001debd0, 0x0)
	/Users/yuan.chen/GolandProjects/src/volcano.sh/volcano/vendor/k8s.io/client-go/tools/cache/shared_informer.go:227 +0x47f
created by volcano.sh/volcano/pkg/scheduler/cache.(*SchedulerCache).Run
	/Users/yuan.chen/GolandProjects/src/volcano.sh/volcano/pkg/scheduler/cache/cache.go:438 +0x15b

goroutine 149 [sync.Cond.Wait, 2 minutes]:
runtime.goparkunlock(...)
	/usr/local/opt/go/libexec/src/runtime/proc.go:310
sync.runtime_notifyListWait(0xc00034e028, 0x0)
	/usr/local/opt/go/libexec/src/runtime/sema.go:510 +0xf8
sync.(*Cond).Wait(0xc00034e018)
	/usr/local/opt/go/libexec/src/sync/cond.go:56 +0x9d
volcano.sh/volcano/vendor/k8s.io/client-go/tools/cache.(*DeltaFIFO).Pop(0xc00034e000, 0xc000376010, 0x0, 0x0, 0x0, 0x0)
	/Users/yuan.chen/GolandProjects/src/volcano.sh/volcano/vendor/k8s.io/client-go/tools/cache/delta_fifo.go:423 +0xa6
volcano.sh/volcano/vendor/k8s.io/client-go/tools/cache.(*controller).processLoop(0xc00041c080)
	/Users/yuan.chen/GolandProjects/src/volcano.sh/volcano/vendor/k8s.io/client-go/tools/cache/controller.go:150 +0x40
volcano.sh/volcano/vendor/k8s.io/apimachinery/pkg/util/wait.JitterUntil.func1(0xc000619e00)
	/Users/yuan.chen/GolandProjects/src/volcano.sh/volcano/vendor/k8s.io/apimachinery/pkg/util/wait/wait.go:133 +0x5e
volcano.sh/volcano/vendor/k8s.io/apimachinery/pkg/util/wait.JitterUntil(0xc000619e00, 0x3b9aca00, 0x0, 0xc0001cdb01, 0x0)
	/Users/yuan.chen/GolandProjects/src/volcano.sh/volcano/vendor/k8s.io/apimachinery/pkg/util/wait/wait.go:134 +0xf8
volcano.sh/volcano/vendor/k8s.io/apimachinery/pkg/util/wait.Until(...)
	/Users/yuan.chen/GolandProjects/src/volcano.sh/volcano/vendor/k8s.io/apimachinery/pkg/util/wait/wait.go:88
volcano.sh/volcano/vendor/k8s.io/client-go/tools/cache.(*controller).Run(0xc00041c080, 0x0)
	/Users/yuan.chen/GolandProjects/src/volcano.sh/volcano/vendor/k8s.io/client-go/tools/cache/controller.go:124 +0x2fd
volcano.sh/volcano/vendor/k8s.io/client-go/tools/cache.(*sharedIndexInformer).Run(0xc0001de750, 0x0)
	/Users/yuan.chen/GolandProjects/src/volcano.sh/volcano/vendor/k8s.io/client-go/tools/cache/shared_informer.go:227 +0x47f
created by volcano.sh/volcano/pkg/scheduler/cache.(*SchedulerCache).Run
	/Users/yuan.chen/GolandProjects/src/volcano.sh/volcano/pkg/scheduler/cache/cache.go:439 +0x19e

goroutine 150 [sync.Cond.Wait, 2 minutes]:
runtime.goparkunlock(...)
	/usr/local/opt/go/libexec/src/runtime/proc.go:310
sync.runtime_notifyListWait(0xc0003ac028, 0x0)
	/usr/local/opt/go/libexec/src/runtime/sema.go:510 +0xf8
sync.(*Cond).Wait(0xc0003ac018)
	/usr/local/opt/go/libexec/src/sync/cond.go:56 +0x9d
volcano.sh/volcano/vendor/k8s.io/client-go/tools/cache.(*DeltaFIFO).Pop(0xc0003ac000, 0xc0003c4010, 0x0, 0x0, 0x0, 0x0)
	/Users/yuan.chen/GolandProjects/src/volcano.sh/volcano/vendor/k8s.io/client-go/tools/cache/delta_fifo.go:423 +0xa6
volcano.sh/volcano/vendor/k8s.io/client-go/tools/cache.(*controller).processLoop(0xc000518000)
	/Users/yuan.chen/GolandProjects/src/volcano.sh/volcano/vendor/k8s.io/client-go/tools/cache/controller.go:150 +0x40
volcano.sh/volcano/vendor/k8s.io/apimachinery/pkg/util/wait.JitterUntil.func1(0xc000659e00)
	/Users/yuan.chen/GolandProjects/src/volcano.sh/volcano/vendor/k8s.io/apimachinery/pkg/util/wait/wait.go:133 +0x5e
volcano.sh/volcano/vendor/k8s.io/apimachinery/pkg/util/wait.JitterUntil(0xc000659e00, 0x3b9aca00, 0x0, 0xc0001d8801, 0x0)
	/Users/yuan.chen/GolandProjects/src/volcano.sh/volcano/vendor/k8s.io/apimachinery/pkg/util/wait/wait.go:134 +0xf8
volcano.sh/volcano/vendor/k8s.io/apimachinery/pkg/util/wait.Until(...)
	/Users/yuan.chen/GolandProjects/src/volcano.sh/volcano/vendor/k8s.io/apimachinery/pkg/util/wait/wait.go:88
volcano.sh/volcano/vendor/k8s.io/client-go/tools/cache.(*controller).Run(0xc000518000, 0x0)
	/Users/yuan.chen/GolandProjects/src/volcano.sh/volcano/vendor/k8s.io/client-go/tools/cache/controller.go:124 +0x2fd
volcano.sh/volcano/vendor/k8s.io/client-go/tools/cache.(*sharedIndexInformer).Run(0xc0001de6c0, 0x0)
	/Users/yuan.chen/GolandProjects/src/volcano.sh/volcano/vendor/k8s.io/client-go/tools/cache/shared_informer.go:227 +0x47f
created by volcano.sh/volcano/pkg/scheduler/cache.(*SchedulerCache).Run
	/Users/yuan.chen/GolandProjects/src/volcano.sh/volcano/pkg/scheduler/cache/cache.go:440 +0x1e1

goroutine 151 [sync.Cond.Wait, 2 minutes]:
runtime.goparkunlock(...)
	/usr/local/opt/go/libexec/src/runtime/proc.go:310
sync.runtime_notifyListWait(0xc000396028, 0x1)
	/usr/local/opt/go/libexec/src/runtime/sema.go:510 +0xf8
sync.(*Cond).Wait(0xc000396018)
	/usr/local/opt/go/libexec/src/sync/cond.go:56 +0x9d
volcano.sh/volcano/vendor/k8s.io/client-go/tools/cache.(*DeltaFIFO).Pop(0xc000396000, 0xc00039a010, 0x0, 0x0, 0x0, 0x0)
	/Users/yuan.chen/GolandProjects/src/volcano.sh/volcano/vendor/k8s.io/client-go/tools/cache/delta_fifo.go:423 +0xa6
volcano.sh/volcano/vendor/k8s.io/client-go/tools/cache.(*controller).processLoop(0xc00049c000)
	/Users/yuan.chen/GolandProjects/src/volcano.sh/volcano/vendor/k8s.io/client-go/tools/cache/controller.go:150 +0x40
volcano.sh/volcano/vendor/k8s.io/apimachinery/pkg/util/wait.JitterUntil.func1(0xc00061de00)
	/Users/yuan.chen/GolandProjects/src/volcano.sh/volcano/vendor/k8s.io/apimachinery/pkg/util/wait/wait.go:133 +0x5e
volcano.sh/volcano/vendor/k8s.io/apimachinery/pkg/util/wait.JitterUntil(0xc00061de00, 0x3b9aca00, 0x0, 0xc0004f4d01, 0x0)
	/Users/yuan.chen/GolandProjects/src/volcano.sh/volcano/vendor/k8s.io/apimachinery/pkg/util/wait/wait.go:134 +0xf8
volcano.sh/volcano/vendor/k8s.io/apimachinery/pkg/util/wait.Until(...)
	/Users/yuan.chen/GolandProjects/src/volcano.sh/volcano/vendor/k8s.io/apimachinery/pkg/util/wait/wait.go:88
volcano.sh/volcano/vendor/k8s.io/client-go/tools/cache.(*controller).Run(0xc00049c000, 0x0)
	/Users/yuan.chen/GolandProjects/src/volcano.sh/volcano/vendor/k8s.io/client-go/tools/cache/controller.go:124 +0x2fd
volcano.sh/volcano/vendor/k8s.io/client-go/tools/cache.(*sharedIndexInformer).Run(0xc0001de630, 0x0)
	/Users/yuan.chen/GolandProjects/src/volcano.sh/volcano/vendor/k8s.io/client-go/tools/cache/shared_informer.go:227 +0x47f
created by volcano.sh/volcano/pkg/scheduler/cache.(*SchedulerCache).Run
	/Users/yuan.chen/GolandProjects/src/volcano.sh/volcano/pkg/scheduler/cache/cache.go:441 +0x224

goroutine 152 [sync.Cond.Wait, 2 minutes]:
runtime.goparkunlock(...)
	/usr/local/opt/go/libexec/src/runtime/proc.go:310
sync.runtime_notifyListWait(0xc000328028, 0x1)
	/usr/local/opt/go/libexec/src/runtime/sema.go:510 +0xf8
sync.(*Cond).Wait(0xc000328018)
	/usr/local/opt/go/libexec/src/sync/cond.go:56 +0x9d
volcano.sh/volcano/vendor/k8s.io/client-go/tools/cache.(*DeltaFIFO).Pop(0xc000328000, 0xc00054c010, 0x0, 0x0, 0x0, 0x0)
	/Users/yuan.chen/GolandProjects/src/volcano.sh/volcano/vendor/k8s.io/client-go/tools/cache/delta_fifo.go:423 +0xa6
volcano.sh/volcano/vendor/k8s.io/client-go/tools/cache.(*controller).processLoop(0xc00016a180)
	/Users/yuan.chen/GolandProjects/src/volcano.sh/volcano/vendor/k8s.io/client-go/tools/cache/controller.go:150 +0x40
volcano.sh/volcano/vendor/k8s.io/apimachinery/pkg/util/wait.JitterUntil.func1(0xc000621e00)
	/Users/yuan.chen/GolandProjects/src/volcano.sh/volcano/vendor/k8s.io/apimachinery/pkg/util/wait/wait.go:133 +0x5e
volcano.sh/volcano/vendor/k8s.io/apimachinery/pkg/util/wait.JitterUntil(0xc000621e00, 0x3b9aca00, 0x0, 0xc000142d01, 0x0)
	/Users/yuan.chen/GolandProjects/src/volcano.sh/volcano/vendor/k8s.io/apimachinery/pkg/util/wait/wait.go:134 +0xf8
volcano.sh/volcano/vendor/k8s.io/apimachinery/pkg/util/wait.Until(...)
	/Users/yuan.chen/GolandProjects/src/volcano.sh/volcano/vendor/k8s.io/apimachinery/pkg/util/wait/wait.go:88
volcano.sh/volcano/vendor/k8s.io/client-go/tools/cache.(*controller).Run(0xc00016a180, 0x0)
	/Users/yuan.chen/GolandProjects/src/volcano.sh/volcano/vendor/k8s.io/client-go/tools/cache/controller.go:124 +0x2fd
volcano.sh/volcano/vendor/k8s.io/client-go/tools/cache.(*sharedIndexInformer).Run(0xc0001dec60, 0x0)
	/Users/yuan.chen/GolandProjects/src/volcano.sh/volcano/vendor/k8s.io/client-go/tools/cache/shared_informer.go:227 +0x47f
created by volcano.sh/volcano/pkg/scheduler/cache.(*SchedulerCache).Run
	/Users/yuan.chen/GolandProjects/src/volcano.sh/volcano/pkg/scheduler/cache/cache.go:442 +0x267

goroutine 153 [sync.Cond.Wait, 2 minutes]:
runtime.goparkunlock(...)
	/usr/local/opt/go/libexec/src/runtime/proc.go:310
sync.runtime_notifyListWait(0xc000136708, 0x1)
	/usr/local/opt/go/libexec/src/runtime/sema.go:510 +0xf8
sync.(*Cond).Wait(0xc0001366f8)
	/usr/local/opt/go/libexec/src/sync/cond.go:56 +0x9d
volcano.sh/volcano/vendor/k8s.io/client-go/tools/cache.(*DeltaFIFO).Pop(0xc0001366e0, 0xc000333940, 0x0, 0x0, 0x0, 0x0)
	/Users/yuan.chen/GolandProjects/src/volcano.sh/volcano/vendor/k8s.io/client-go/tools/cache/delta_fifo.go:423 +0xa6
volcano.sh/volcano/vendor/k8s.io/client-go/tools/cache.(*controller).processLoop(0xc0002d7980)
	/Users/yuan.chen/GolandProjects/src/volcano.sh/volcano/vendor/k8s.io/client-go/tools/cache/controller.go:150 +0x40
volcano.sh/volcano/vendor/k8s.io/apimachinery/pkg/util/wait.JitterUntil.func1(0xc00065ce00)
	/Users/yuan.chen/GolandProjects/src/volcano.sh/volcano/vendor/k8s.io/apimachinery/pkg/util/wait/wait.go:133 +0x5e
volcano.sh/volcano/vendor/k8s.io/apimachinery/pkg/util/wait.JitterUntil(0xc00065ce00, 0x3b9aca00, 0x0, 0xc000143001, 0x0)
	/Users/yuan.chen/GolandProjects/src/volcano.sh/volcano/vendor/k8s.io/apimachinery/pkg/util/wait/wait.go:134 +0xf8
volcano.sh/volcano/vendor/k8s.io/apimachinery/pkg/util/wait.Until(...)
	/Users/yuan.chen/GolandProjects/src/volcano.sh/volcano/vendor/k8s.io/apimachinery/pkg/util/wait/wait.go:88
volcano.sh/volcano/vendor/k8s.io/client-go/tools/cache.(*controller).Run(0xc0002d7980, 0x0)
	/Users/yuan.chen/GolandProjects/src/volcano.sh/volcano/vendor/k8s.io/client-go/tools/cache/controller.go:124 +0x2fd
volcano.sh/volcano/vendor/k8s.io/client-go/tools/cache.(*sharedIndexInformer).Run(0xc0001decf0, 0x0)
	/Users/yuan.chen/GolandProjects/src/volcano.sh/volcano/vendor/k8s.io/client-go/tools/cache/shared_informer.go:227 +0x47f
created by volcano.sh/volcano/pkg/scheduler/cache.(*SchedulerCache).Run
	/Users/yuan.chen/GolandProjects/src/volcano.sh/volcano/pkg/scheduler/cache/cache.go:443 +0x2aa

goroutine 154 [sync.Cond.Wait, 2 minutes]:
runtime.goparkunlock(...)
	/usr/local/opt/go/libexec/src/runtime/proc.go:310
sync.runtime_notifyListWait(0xc0002d4188, 0x0)
	/usr/local/opt/go/libexec/src/runtime/sema.go:510 +0xf8
sync.(*Cond).Wait(0xc0002d4178)
	/usr/local/opt/go/libexec/src/sync/cond.go:56 +0x9d
volcano.sh/volcano/vendor/k8s.io/client-go/tools/cache.(*DeltaFIFO).Pop(0xc0002d4160, 0xc0005d4260, 0x0, 0x0, 0x0, 0x0)
	/Users/yuan.chen/GolandProjects/src/volcano.sh/volcano/vendor/k8s.io/client-go/tools/cache/delta_fifo.go:423 +0xa6
volcano.sh/volcano/vendor/k8s.io/client-go/tools/cache.(*controller).processLoop(0xc00043ee80)
	/Users/yuan.chen/GolandProjects/src/volcano.sh/volcano/vendor/k8s.io/client-go/tools/cache/controller.go:150 +0x40
volcano.sh/volcano/vendor/k8s.io/apimachinery/pkg/util/wait.JitterUntil.func1(0xc00007ee00)
	/Users/yuan.chen/GolandProjects/src/volcano.sh/volcano/vendor/k8s.io/apimachinery/pkg/util/wait/wait.go:133 +0x5e
volcano.sh/volcano/vendor/k8s.io/apimachinery/pkg/util/wait.JitterUntil(0xc00007ee00, 0x3b9aca00, 0x0, 0xc000142b01, 0x0)
	/Users/yuan.chen/GolandProjects/src/volcano.sh/volcano/vendor/k8s.io/apimachinery/pkg/util/wait/wait.go:134 +0xf8
volcano.sh/volcano/vendor/k8s.io/apimachinery/pkg/util/wait.Until(...)
	/Users/yuan.chen/GolandProjects/src/volcano.sh/volcano/vendor/k8s.io/apimachinery/pkg/util/wait/wait.go:88
volcano.sh/volcano/vendor/k8s.io/client-go/tools/cache.(*controller).Run(0xc00043ee80, 0x0)
	/Users/yuan.chen/GolandProjects/src/volcano.sh/volcano/vendor/k8s.io/client-go/tools/cache/controller.go:124 +0x2fd
volcano.sh/volcano/vendor/k8s.io/client-go/tools/cache.(*sharedIndexInformer).Run(0xc0001deab0, 0x0)
	/Users/yuan.chen/GolandProjects/src/volcano.sh/volcano/vendor/k8s.io/client-go/tools/cache/shared_informer.go:227 +0x47f
created by volcano.sh/volcano/pkg/scheduler/cache.(*SchedulerCache).Run
	/Users/yuan.chen/GolandProjects/src/volcano.sh/volcano/pkg/scheduler/cache/cache.go:444 +0x2ed

goroutine 155 [sync.Cond.Wait, 2 minutes]:
runtime.goparkunlock(...)
	/usr/local/opt/go/libexec/src/runtime/proc.go:310
sync.runtime_notifyListWait(0xc000396188, 0x1)
	/usr/local/opt/go/libexec/src/runtime/sema.go:510 +0xf8
sync.(*Cond).Wait(0xc000396178)
	/usr/local/opt/go/libexec/src/sync/cond.go:56 +0x9d
volcano.sh/volcano/vendor/k8s.io/client-go/tools/cache.(*DeltaFIFO).Pop(0xc000396160, 0xc00039a210, 0x0, 0x0, 0x0, 0x0)
	/Users/yuan.chen/GolandProjects/src/volcano.sh/volcano/vendor/k8s.io/client-go/tools/cache/delta_fifo.go:423 +0xa6
volcano.sh/volcano/vendor/k8s.io/client-go/tools/cache.(*controller).processLoop(0xc00049ca80)
	/Users/yuan.chen/GolandProjects/src/volcano.sh/volcano/vendor/k8s.io/client-go/tools/cache/controller.go:150 +0x40
volcano.sh/volcano/vendor/k8s.io/apimachinery/pkg/util/wait.JitterUntil.func1(0xc00061fe00)
	/Users/yuan.chen/GolandProjects/src/volcano.sh/volcano/vendor/k8s.io/apimachinery/pkg/util/wait/wait.go:133 +0x5e
volcano.sh/volcano/vendor/k8s.io/apimachinery/pkg/util/wait.JitterUntil(0xc00061fe00, 0x3b9aca00, 0x0, 0xc00053c601, 0x0)
	/Users/yuan.chen/GolandProjects/src/volcano.sh/volcano/vendor/k8s.io/apimachinery/pkg/util/wait/wait.go:134 +0xf8
volcano.sh/volcano/vendor/k8s.io/apimachinery/pkg/util/wait.Until(...)
	/Users/yuan.chen/GolandProjects/src/volcano.sh/volcano/vendor/k8s.io/apimachinery/pkg/util/wait/wait.go:88
volcano.sh/volcano/vendor/k8s.io/client-go/tools/cache.(*controller).Run(0xc00049ca80, 0x0)
	/Users/yuan.chen/GolandProjects/src/volcano.sh/volcano/vendor/k8s.io/client-go/tools/cache/controller.go:124 +0x2fd
volcano.sh/volcano/vendor/k8s.io/client-go/tools/cache.(*sharedIndexInformer).Run(0xc0001dea20, 0x0)
	/Users/yuan.chen/GolandProjects/src/volcano.sh/volcano/vendor/k8s.io/client-go/tools/cache/shared_informer.go:227 +0x47f
created by volcano.sh/volcano/pkg/scheduler/cache.(*SchedulerCache).Run
	/Users/yuan.chen/GolandProjects/src/volcano.sh/volcano/pkg/scheduler/cache/cache.go:447 +0x443

goroutine 156 [sync.Cond.Wait, 2 minutes]:
runtime.goparkunlock(...)
	/usr/local/opt/go/libexec/src/runtime/proc.go:310
sync.runtime_notifyListWait(0xc00016f190, 0x0)
	/usr/local/opt/go/libexec/src/runtime/sema.go:510 +0xf8
sync.(*Cond).Wait(0xc00016f180)
	/usr/local/opt/go/libexec/src/sync/cond.go:56 +0x9d
volcano.sh/volcano/vendor/k8s.io/client-go/util/workqueue.(*Type).Get(0xc000564c60, 0x0, 0x0, 0x0)
	/Users/yuan.chen/GolandProjects/src/volcano.sh/volcano/vendor/k8s.io/client-go/util/workqueue/queue.go:145 +0xa0
volcano.sh/volcano/pkg/scheduler/cache.(*SchedulerCache).processResyncTask(0xc0001d8540)
	/Users/yuan.chen/GolandProjects/src/volcano.sh/volcano/pkg/scheduler/cache/cache.go:677 +0x4f
volcano.sh/volcano/vendor/k8s.io/apimachinery/pkg/util/wait.JitterUntil.func1(0xc000333720)
	/Users/yuan.chen/GolandProjects/src/volcano.sh/volcano/vendor/k8s.io/apimachinery/pkg/util/wait/wait.go:133 +0x5e
volcano.sh/volcano/vendor/k8s.io/apimachinery/pkg/util/wait.JitterUntil(0xc000333720, 0x0, 0x0, 0x79595849372b4d01, 0x0)
	/Users/yuan.chen/GolandProjects/src/volcano.sh/volcano/vendor/k8s.io/apimachinery/pkg/util/wait/wait.go:134 +0xf8
volcano.sh/volcano/vendor/k8s.io/apimachinery/pkg/util/wait.Until(0xc000333720, 0x0, 0x0)
	/Users/yuan.chen/GolandProjects/src/volcano.sh/volcano/vendor/k8s.io/apimachinery/pkg/util/wait/wait.go:88 +0x4d
created by volcano.sh/volcano/pkg/scheduler/cache.(*SchedulerCache).Run
	/Users/yuan.chen/GolandProjects/src/volcano.sh/volcano/pkg/scheduler/cache/cache.go:451 +0x366

goroutine 157 [sync.Cond.Wait, 2 minutes]:
runtime.goparkunlock(...)
	/usr/local/opt/go/libexec/src/runtime/proc.go:310
sync.runtime_notifyListWait(0xc00016f1d0, 0x56445a4e00000000)
	/usr/local/opt/go/libexec/src/runtime/sema.go:510 +0xf8
sync.(*Cond).Wait(0xc00016f1c0)
	/usr/local/opt/go/libexec/src/sync/cond.go:56 +0x9d
volcano.sh/volcano/vendor/k8s.io/client-go/util/workqueue.(*Type).Get(0xc000564d80, 0x0, 0x0, 0x63597244654d4b00)
	/Users/yuan.chen/GolandProjects/src/volcano.sh/volcano/vendor/k8s.io/client-go/util/workqueue/queue.go:145 +0xa0
volcano.sh/volcano/pkg/scheduler/cache.(*SchedulerCache).processCleanupJob(0xc0001d8540)
	/Users/yuan.chen/GolandProjects/src/volcano.sh/volcano/pkg/scheduler/cache/cache.go:647 +0x52
volcano.sh/volcano/vendor/k8s.io/apimachinery/pkg/util/wait.JitterUntil.func1(0xc000333730)
	/Users/yuan.chen/GolandProjects/src/volcano.sh/volcano/vendor/k8s.io/apimachinery/pkg/util/wait/wait.go:133 +0x5e
volcano.sh/volcano/vendor/k8s.io/apimachinery/pkg/util/wait.JitterUntil(0xc000333730, 0x0, 0x0, 0x367133446e356501, 0x0)
	/Users/yuan.chen/GolandProjects/src/volcano.sh/volcano/vendor/k8s.io/apimachinery/pkg/util/wait/wait.go:134 +0xf8
volcano.sh/volcano/vendor/k8s.io/apimachinery/pkg/util/wait.Until(0xc000333730, 0x0, 0x0)
	/Users/yuan.chen/GolandProjects/src/volcano.sh/volcano/vendor/k8s.io/apimachinery/pkg/util/wait/wait.go:88 +0x4d
created by volcano.sh/volcano/pkg/scheduler/cache.(*SchedulerCache).Run
	/Users/yuan.chen/GolandProjects/src/volcano.sh/volcano/pkg/scheduler/cache/cache.go:454 +0x3c7

goroutine 44 [chan receive, 2 minutes]:
volcano.sh/volcano/vendor/k8s.io/client-go/tools/cache.(*sharedProcessor).run(0xc000296460, 0xc0000c00c0)
	/Users/yuan.chen/GolandProjects/src/volcano.sh/volcano/vendor/k8s.io/client-go/tools/cache/shared_informer.go:425 +0x49
volcano.sh/volcano/vendor/k8s.io/apimachinery/pkg/util/wait.(*Group).StartWithChannel.func1()
	/Users/yuan.chen/GolandProjects/src/volcano.sh/volcano/vendor/k8s.io/apimachinery/pkg/util/wait/wait.go:54 +0x2e
volcano.sh/volcano/vendor/k8s.io/apimachinery/pkg/util/wait.(*Group).Start.func1(0xc000044090, 0xc0003021e0)
	/Users/yuan.chen/GolandProjects/src/volcano.sh/volcano/vendor/k8s.io/apimachinery/pkg/util/wait/wait.go:71 +0x59
created by volcano.sh/volcano/vendor/k8s.io/apimachinery/pkg/util/wait.(*Group).Start
	/Users/yuan.chen/GolandProjects/src/volcano.sh/volcano/vendor/k8s.io/apimachinery/pkg/util/wait/wait.go:69 +0x62

goroutine 24 [chan receive, 2 minutes]:
volcano.sh/volcano/vendor/k8s.io/client-go/tools/cache.(*sharedProcessor).run(0xc000296850, 0xc000330000)
	/Users/yuan.chen/GolandProjects/src/volcano.sh/volcano/vendor/k8s.io/client-go/tools/cache/shared_informer.go:425 +0x49
volcano.sh/volcano/vendor/k8s.io/apimachinery/pkg/util/wait.(*Group).StartWithChannel.func1()
	/Users/yuan.chen/GolandProjects/src/volcano.sh/volcano/vendor/k8s.io/apimachinery/pkg/util/wait/wait.go:54 +0x2e
volcano.sh/volcano/vendor/k8s.io/apimachinery/pkg/util/wait.(*Group).Start.func1(0xc000602020, 0xc0005a0140)
	/Users/yuan.chen/GolandProjects/src/volcano.sh/volcano/vendor/k8s.io/apimachinery/pkg/util/wait/wait.go:71 +0x59
created by volcano.sh/volcano/vendor/k8s.io/apimachinery/pkg/util/wait.(*Group).Start
	/Users/yuan.chen/GolandProjects/src/volcano.sh/volcano/vendor/k8s.io/apimachinery/pkg/util/wait/wait.go:69 +0x62

goroutine 45 [chan receive (nil chan), 2 minutes]:
volcano.sh/volcano/vendor/k8s.io/client-go/tools/cache.(*controller).Run.func1(0x0, 0xc00043e080)
	/Users/yuan.chen/GolandProjects/src/volcano.sh/volcano/vendor/k8s.io/client-go/tools/cache/controller.go:103 +0x34
created by volcano.sh/volcano/vendor/k8s.io/client-go/tools/cache.(*controller).Run
	/Users/yuan.chen/GolandProjects/src/volcano.sh/volcano/vendor/k8s.io/client-go/tools/cache/controller.go:102 +0xae

goroutine 25 [chan receive (nil chan), 2 minutes]:
volcano.sh/volcano/vendor/k8s.io/client-go/tools/cache.(*controller).Run.func1(0x0, 0xc00016a180)
	/Users/yuan.chen/GolandProjects/src/volcano.sh/volcano/vendor/k8s.io/client-go/tools/cache/controller.go:103 +0x34
created by volcano.sh/volcano/vendor/k8s.io/client-go/tools/cache.(*controller).Run
	/Users/yuan.chen/GolandProjects/src/volcano.sh/volcano/vendor/k8s.io/client-go/tools/cache/controller.go:102 +0xae

goroutine 159 [chan receive, 2 minutes]:
volcano.sh/volcano/vendor/k8s.io/client-go/tools/cache.(*sharedProcessor).run(0xc000296770, 0xc0001d6f00)
	/Users/yuan.chen/GolandProjects/src/volcano.sh/volcano/vendor/k8s.io/client-go/tools/cache/shared_informer.go:425 +0x49
volcano.sh/volcano/vendor/k8s.io/apimachinery/pkg/util/wait.(*Group).StartWithChannel.func1()
	/Users/yuan.chen/GolandProjects/src/volcano.sh/volcano/vendor/k8s.io/apimachinery/pkg/util/wait/wait.go:54 +0x2e
volcano.sh/volcano/vendor/k8s.io/apimachinery/pkg/util/wait.(*Group).Start.func1(0xc000118a10, 0xc00056b1c0)
	/Users/yuan.chen/GolandProjects/src/volcano.sh/volcano/vendor/k8s.io/apimachinery/pkg/util/wait/wait.go:71 +0x59
created by volcano.sh/volcano/vendor/k8s.io/apimachinery/pkg/util/wait.(*Group).Start
	/Users/yuan.chen/GolandProjects/src/volcano.sh/volcano/vendor/k8s.io/apimachinery/pkg/util/wait/wait.go:69 +0x62

goroutine 15 [chan receive, 2 minutes]:
volcano.sh/volcano/vendor/k8s.io/client-go/tools/cache.(*sharedProcessor).run(0xc0002963f0, 0xc0001301e0)
	/Users/yuan.chen/GolandProjects/src/volcano.sh/volcano/vendor/k8s.io/client-go/tools/cache/shared_informer.go:425 +0x49
volcano.sh/volcano/vendor/k8s.io/apimachinery/pkg/util/wait.(*Group).StartWithChannel.func1()
	/Users/yuan.chen/GolandProjects/src/volcano.sh/volcano/vendor/k8s.io/apimachinery/pkg/util/wait/wait.go:54 +0x2e
volcano.sh/volcano/vendor/k8s.io/apimachinery/pkg/util/wait.(*Group).Start.func1(0xc00057a030, 0xc0000da860)
	/Users/yuan.chen/GolandProjects/src/volcano.sh/volcano/vendor/k8s.io/apimachinery/pkg/util/wait/wait.go:71 +0x59
created by volcano.sh/volcano/vendor/k8s.io/apimachinery/pkg/util/wait.(*Group).Start
	/Users/yuan.chen/GolandProjects/src/volcano.sh/volcano/vendor/k8s.io/apimachinery/pkg/util/wait/wait.go:69 +0x62

goroutine 160 [chan receive (nil chan), 2 minutes]:
volcano.sh/volcano/vendor/k8s.io/client-go/tools/cache.(*controller).Run.func1(0x0, 0xc0002d6080)
	/Users/yuan.chen/GolandProjects/src/volcano.sh/volcano/vendor/k8s.io/client-go/tools/cache/controller.go:103 +0x34
created by volcano.sh/volcano/vendor/k8s.io/client-go/tools/cache.(*controller).Run
	/Users/yuan.chen/GolandProjects/src/volcano.sh/volcano/vendor/k8s.io/client-go/tools/cache/controller.go:102 +0xae

goroutine 91 [chan receive, 2 minutes]:
volcano.sh/volcano/vendor/k8s.io/client-go/tools/cache.(*processorListener).run.func1.1(0x0, 0x0, 0x0)
	/Users/yuan.chen/GolandProjects/src/volcano.sh/volcano/vendor/k8s.io/client-go/tools/cache/shared_informer.go:549 +0x54
volcano.sh/volcano/vendor/k8s.io/apimachinery/pkg/util/wait.ExponentialBackoff(0x989680, 0x3ff0000000000000, 0x3fb999999999999a, 0x5, 0xc000a61dd8, 0x0, 0x0)
	/Users/yuan.chen/GolandProjects/src/volcano.sh/volcano/vendor/k8s.io/apimachinery/pkg/util/wait/wait.go:203 +0xde
volcano.sh/volcano/vendor/k8s.io/client-go/tools/cache.(*processorListener).run.func1()
	/Users/yuan.chen/GolandProjects/src/volcano.sh/volcano/vendor/k8s.io/client-go/tools/cache/shared_informer.go:548 +0x89
volcano.sh/volcano/vendor/k8s.io/apimachinery/pkg/util/wait.JitterUntil.func1(0xc0005edf40)
	/Users/yuan.chen/GolandProjects/src/volcano.sh/volcano/vendor/k8s.io/apimachinery/pkg/util/wait/wait.go:133 +0x5e
volcano.sh/volcano/vendor/k8s.io/apimachinery/pkg/util/wait.JitterUntil(0xc000a61f40, 0xdf8475800, 0x0, 0x1030501, 0xc000340180)
	/Users/yuan.chen/GolandProjects/src/volcano.sh/volcano/vendor/k8s.io/apimachinery/pkg/util/wait/wait.go:134 +0xf8
volcano.sh/volcano/vendor/k8s.io/apimachinery/pkg/util/wait.Until(...)
	/Users/yuan.chen/GolandProjects/src/volcano.sh/volcano/vendor/k8s.io/apimachinery/pkg/util/wait/wait.go:88
volcano.sh/volcano/vendor/k8s.io/client-go/tools/cache.(*processorListener).run(0xc0005a4b80)
	/Users/yuan.chen/GolandProjects/src/volcano.sh/volcano/vendor/k8s.io/client-go/tools/cache/shared_informer.go:546 +0x9b
volcano.sh/volcano/vendor/k8s.io/apimachinery/pkg/util/wait.(*Group).Start.func1(0xc0002964c0, 0xc0000ca580)
	/Users/yuan.chen/GolandProjects/src/volcano.sh/volcano/vendor/k8s.io/apimachinery/pkg/util/wait/wait.go:71 +0x59
created by volcano.sh/volcano/vendor/k8s.io/apimachinery/pkg/util/wait.(*Group).Start
	/Users/yuan.chen/GolandProjects/src/volcano.sh/volcano/vendor/k8s.io/apimachinery/pkg/util/wait/wait.go:69 +0x62

goroutine 84 [chan receive, 2 minutes]:
volcano.sh/volcano/vendor/k8s.io/client-go/tools/cache.(*sharedProcessor).run(0xc0002964d0, 0xc000340000)
	/Users/yuan.chen/GolandProjects/src/volcano.sh/volcano/vendor/k8s.io/client-go/tools/cache/shared_informer.go:425 +0x49
volcano.sh/volcano/vendor/k8s.io/apimachinery/pkg/util/wait.(*Group).StartWithChannel.func1()
	/Users/yuan.chen/GolandProjects/src/volcano.sh/volcano/vendor/k8s.io/apimachinery/pkg/util/wait/wait.go:54 +0x2e
volcano.sh/volcano/vendor/k8s.io/apimachinery/pkg/util/wait.(*Group).Start.func1(0xc000456030, 0xc00042a060)
	/Users/yuan.chen/GolandProjects/src/volcano.sh/volcano/vendor/k8s.io/apimachinery/pkg/util/wait/wait.go:71 +0x59
created by volcano.sh/volcano/vendor/k8s.io/apimachinery/pkg/util/wait.(*Group).Start
	/Users/yuan.chen/GolandProjects/src/volcano.sh/volcano/vendor/k8s.io/apimachinery/pkg/util/wait/wait.go:69 +0x62

goroutine 16 [chan receive (nil chan), 2 minutes]:
volcano.sh/volcano/vendor/k8s.io/client-go/tools/cache.(*controller).Run.func1(0x0, 0xc000480680)
	/Users/yuan.chen/GolandProjects/src/volcano.sh/volcano/vendor/k8s.io/client-go/tools/cache/controller.go:103 +0x34
created by volcano.sh/volcano/vendor/k8s.io/client-go/tools/cache.(*controller).Run
	/Users/yuan.chen/GolandProjects/src/volcano.sh/volcano/vendor/k8s.io/client-go/tools/cache/controller.go:102 +0xae

goroutine 85 [chan receive (nil chan), 2 minutes]:
volcano.sh/volcano/vendor/k8s.io/client-go/tools/cache.(*controller).Run.func1(0x0, 0xc00003c300)
	/Users/yuan.chen/GolandProjects/src/volcano.sh/volcano/vendor/k8s.io/client-go/tools/cache/controller.go:103 +0x34
created by volcano.sh/volcano/vendor/k8s.io/client-go/tools/cache.(*controller).Run
	/Users/yuan.chen/GolandProjects/src/volcano.sh/volcano/vendor/k8s.io/client-go/tools/cache/controller.go:102 +0xae

goroutine 103 [chan receive, 2 minutes]:
volcano.sh/volcano/vendor/k8s.io/client-go/tools/cache.(*processorListener).run.func1.1(0x0, 0x0, 0x0)
	/Users/yuan.chen/GolandProjects/src/volcano.sh/volcano/vendor/k8s.io/client-go/tools/cache/shared_informer.go:549 +0x54
volcano.sh/volcano/vendor/k8s.io/apimachinery/pkg/util/wait.ExponentialBackoff(0x989680, 0x3ff0000000000000, 0x3fb999999999999a, 0x5, 0xc000712dd8, 0x0, 0x0)
	/Users/yuan.chen/GolandProjects/src/volcano.sh/volcano/vendor/k8s.io/apimachinery/pkg/util/wait/wait.go:203 +0xde
volcano.sh/volcano/vendor/k8s.io/client-go/tools/cache.(*processorListener).run.func1()
	/Users/yuan.chen/GolandProjects/src/volcano.sh/volcano/vendor/k8s.io/client-go/tools/cache/shared_informer.go:548 +0x89
volcano.sh/volcano/vendor/k8s.io/apimachinery/pkg/util/wait.JitterUntil.func1(0xc00060bf40)
	/Users/yuan.chen/GolandProjects/src/volcano.sh/volcano/vendor/k8s.io/apimachinery/pkg/util/wait/wait.go:133 +0x5e
volcano.sh/volcano/vendor/k8s.io/apimachinery/pkg/util/wait.JitterUntil(0xc000712f40, 0xdf8475800, 0x0, 0x1030501, 0xc000340240)
	/Users/yuan.chen/GolandProjects/src/volcano.sh/volcano/vendor/k8s.io/apimachinery/pkg/util/wait/wait.go:134 +0xf8
volcano.sh/volcano/vendor/k8s.io/apimachinery/pkg/util/wait.Until(...)
	/Users/yuan.chen/GolandProjects/src/volcano.sh/volcano/vendor/k8s.io/apimachinery/pkg/util/wait/wait.go:88
volcano.sh/volcano/vendor/k8s.io/client-go/tools/cache.(*processorListener).run(0xc0005a4600)
	/Users/yuan.chen/GolandProjects/src/volcano.sh/volcano/vendor/k8s.io/client-go/tools/cache/shared_informer.go:546 +0x9b
volcano.sh/volcano/vendor/k8s.io/apimachinery/pkg/util/wait.(*Group).Start.func1(0xc000296370, 0xc00039a1e0)
	/Users/yuan.chen/GolandProjects/src/volcano.sh/volcano/vendor/k8s.io/apimachinery/pkg/util/wait/wait.go:71 +0x59
created by volcano.sh/volcano/vendor/k8s.io/apimachinery/pkg/util/wait.(*Group).Start
	/Users/yuan.chen/GolandProjects/src/volcano.sh/volcano/vendor/k8s.io/apimachinery/pkg/util/wait/wait.go:69 +0x62

goroutine 68 [chan receive, 2 minutes]:
volcano.sh/volcano/vendor/k8s.io/client-go/tools/cache.(*sharedProcessor).run(0xc000296310, 0xc000384000)
	/Users/yuan.chen/GolandProjects/src/volcano.sh/volcano/vendor/k8s.io/client-go/tools/cache/shared_informer.go:425 +0x49
volcano.sh/volcano/vendor/k8s.io/apimachinery/pkg/util/wait.(*Group).StartWithChannel.func1()
	/Users/yuan.chen/GolandProjects/src/volcano.sh/volcano/vendor/k8s.io/apimachinery/pkg/util/wait/wait.go:54 +0x2e
volcano.sh/volcano/vendor/k8s.io/apimachinery/pkg/util/wait.(*Group).Start.func1(0xc0003be000, 0xc00016c0a0)
	/Users/yuan.chen/GolandProjects/src/volcano.sh/volcano/vendor/k8s.io/apimachinery/pkg/util/wait/wait.go:71 +0x59
created by volcano.sh/volcano/vendor/k8s.io/apimachinery/pkg/util/wait.(*Group).Start
	/Users/yuan.chen/GolandProjects/src/volcano.sh/volcano/vendor/k8s.io/apimachinery/pkg/util/wait/wait.go:69 +0x62

goroutine 69 [chan receive (nil chan), 2 minutes]:
volcano.sh/volcano/vendor/k8s.io/client-go/tools/cache.(*controller).Run.func1(0x0, 0xc00041c080)
	/Users/yuan.chen/GolandProjects/src/volcano.sh/volcano/vendor/k8s.io/client-go/tools/cache/controller.go:103 +0x34
created by volcano.sh/volcano/vendor/k8s.io/client-go/tools/cache.(*controller).Run
	/Users/yuan.chen/GolandProjects/src/volcano.sh/volcano/vendor/k8s.io/client-go/tools/cache/controller.go:102 +0xae

goroutine 104 [select, 2 minutes]:
volcano.sh/volcano/vendor/k8s.io/client-go/tools/cache.(*processorListener).pop(0xc0005a4600)
	/Users/yuan.chen/GolandProjects/src/volcano.sh/volcano/vendor/k8s.io/client-go/tools/cache/shared_informer.go:517 +0x18d
volcano.sh/volcano/vendor/k8s.io/apimachinery/pkg/util/wait.(*Group).Start.func1(0xc000296370, 0xc00039a1f0)
	/Users/yuan.chen/GolandProjects/src/volcano.sh/volcano/vendor/k8s.io/apimachinery/pkg/util/wait/wait.go:71 +0x59
created by volcano.sh/volcano/vendor/k8s.io/apimachinery/pkg/util/wait.(*Group).Start
	/Users/yuan.chen/GolandProjects/src/volcano.sh/volcano/vendor/k8s.io/apimachinery/pkg/util/wait/wait.go:69 +0x62

goroutine 100 [chan receive, 2 minutes]:
volcano.sh/volcano/vendor/k8s.io/client-go/tools/cache.(*sharedProcessor).run(0xc000296150, 0xc0003b8000)
	/Users/yuan.chen/GolandProjects/src/volcano.sh/volcano/vendor/k8s.io/client-go/tools/cache/shared_informer.go:425 +0x49
volcano.sh/volcano/vendor/k8s.io/apimachinery/pkg/util/wait.(*Group).StartWithChannel.func1()
	/Users/yuan.chen/GolandProjects/src/volcano.sh/volcano/vendor/k8s.io/apimachinery/pkg/util/wait/wait.go:54 +0x2e
volcano.sh/volcano/vendor/k8s.io/apimachinery/pkg/util/wait.(*Group).Start.func1(0xc000598000, 0xc00011e0c0)
	/Users/yuan.chen/GolandProjects/src/volcano.sh/volcano/vendor/k8s.io/apimachinery/pkg/util/wait/wait.go:71 +0x59
created by volcano.sh/volcano/vendor/k8s.io/apimachinery/pkg/util/wait.(*Group).Start
	/Users/yuan.chen/GolandProjects/src/volcano.sh/volcano/vendor/k8s.io/apimachinery/pkg/util/wait/wait.go:69 +0x62

goroutine 101 [chan receive (nil chan), 2 minutes]:
volcano.sh/volcano/vendor/k8s.io/client-go/tools/cache.(*controller).Run.func1(0x0, 0xc00049c000)
	/Users/yuan.chen/GolandProjects/src/volcano.sh/volcano/vendor/k8s.io/client-go/tools/cache/controller.go:103 +0x34
created by volcano.sh/volcano/vendor/k8s.io/client-go/tools/cache.(*controller).Run
	/Users/yuan.chen/GolandProjects/src/volcano.sh/volcano/vendor/k8s.io/client-go/tools/cache/controller.go:102 +0xae

goroutine 117 [chan receive (nil chan), 2 minutes]:
volcano.sh/volcano/vendor/k8s.io/client-go/tools/cache.(*controller).Run.func1(0x0, 0xc000518000)
	/Users/yuan.chen/GolandProjects/src/volcano.sh/volcano/vendor/k8s.io/client-go/tools/cache/controller.go:103 +0x34
created by volcano.sh/volcano/vendor/k8s.io/client-go/tools/cache.(*controller).Run
	/Users/yuan.chen/GolandProjects/src/volcano.sh/volcano/vendor/k8s.io/client-go/tools/cache/controller.go:102 +0xae

goroutine 26 [select, 2 minutes]:
volcano.sh/volcano/vendor/k8s.io/client-go/tools/cache.(*Reflector).watchHandler(0xc000350000, 0x23a3860, 0xc0008c4030, 0xc0008f1be0, 0xc0003b2600, 0x0, 0x0, 0x0)
	/Users/yuan.chen/GolandProjects/src/volcano.sh/volcano/vendor/k8s.io/client-go/tools/cache/reflector.go:283 +0x1ec
volcano.sh/volcano/vendor/k8s.io/client-go/tools/cache.(*Reflector).ListAndWatch(0xc000350000, 0x0, 0x0, 0x0)
	/Users/yuan.chen/GolandProjects/src/volcano.sh/volcano/vendor/k8s.io/client-go/tools/cache/reflector.go:254 +0xc73
volcano.sh/volcano/vendor/k8s.io/client-go/tools/cache.(*Reflector).Run.func1()
	/Users/yuan.chen/GolandProjects/src/volcano.sh/volcano/vendor/k8s.io/client-go/tools/cache/reflector.go:124 +0x33
volcano.sh/volcano/vendor/k8s.io/apimachinery/pkg/util/wait.JitterUntil.func1(0xc0003886f0)
	/Users/yuan.chen/GolandProjects/src/volcano.sh/volcano/vendor/k8s.io/apimachinery/pkg/util/wait/wait.go:133 +0x5e
volcano.sh/volcano/vendor/k8s.io/apimachinery/pkg/util/wait.JitterUntil(0xc0008f1ef0, 0x3b9aca00, 0x0, 0x1, 0x0)
	/Users/yuan.chen/GolandProjects/src/volcano.sh/volcano/vendor/k8s.io/apimachinery/pkg/util/wait/wait.go:134 +0xf8
volcano.sh/volcano/vendor/k8s.io/apimachinery/pkg/util/wait.Until(...)
	/Users/yuan.chen/GolandProjects/src/volcano.sh/volcano/vendor/k8s.io/apimachinery/pkg/util/wait/wait.go:88
volcano.sh/volcano/vendor/k8s.io/client-go/tools/cache.(*Reflector).Run(0xc000350000, 0x0)
	/Users/yuan.chen/GolandProjects/src/volcano.sh/volcano/vendor/k8s.io/client-go/tools/cache/reflector.go:123 +0x169
volcano.sh/volcano/vendor/k8s.io/apimachinery/pkg/util/wait.(*Group).StartWithChannel.func1()
	/Users/yuan.chen/GolandProjects/src/volcano.sh/volcano/vendor/k8s.io/apimachinery/pkg/util/wait/wait.go:54 +0x2e
volcano.sh/volcano/vendor/k8s.io/apimachinery/pkg/util/wait.(*Group).Start.func1(0xc000602060, 0xc0005a0380)
	/Users/yuan.chen/GolandProjects/src/volcano.sh/volcano/vendor/k8s.io/apimachinery/pkg/util/wait/wait.go:71 +0x59
created by volcano.sh/volcano/vendor/k8s.io/apimachinery/pkg/util/wait.(*Group).Start
	/Users/yuan.chen/GolandProjects/src/volcano.sh/volcano/vendor/k8s.io/apimachinery/pkg/util/wait/wait.go:69 +0x62

goroutine 161 [select, 2 minutes]:
volcano.sh/volcano/vendor/k8s.io/client-go/tools/cache.(*Reflector).watchHandler(0xc000321360, 0x23a3860, 0xc0008c4090, 0xc0006bfbe0, 0xc000158b40, 0x0, 0x0, 0x0)
	/Users/yuan.chen/GolandProjects/src/volcano.sh/volcano/vendor/k8s.io/client-go/tools/cache/reflector.go:283 +0x1ec
volcano.sh/volcano/vendor/k8s.io/client-go/tools/cache.(*Reflector).ListAndWatch(0xc000321360, 0x0, 0x0, 0x0)
	/Users/yuan.chen/GolandProjects/src/volcano.sh/volcano/vendor/k8s.io/client-go/tools/cache/reflector.go:254 +0xc73
volcano.sh/volcano/vendor/k8s.io/client-go/tools/cache.(*Reflector).Run.func1()
	/Users/yuan.chen/GolandProjects/src/volcano.sh/volcano/vendor/k8s.io/client-go/tools/cache/reflector.go:124 +0x33
volcano.sh/volcano/vendor/k8s.io/apimachinery/pkg/util/wait.JitterUntil.func1(0xc0005e9ef0)
	/Users/yuan.chen/GolandProjects/src/volcano.sh/volcano/vendor/k8s.io/apimachinery/pkg/util/wait/wait.go:133 +0x5e
volcano.sh/volcano/vendor/k8s.io/apimachinery/pkg/util/wait.JitterUntil(0xc0006bfef0, 0x3b9aca00, 0x0, 0x1, 0x0)
	/Users/yuan.chen/GolandProjects/src/volcano.sh/volcano/vendor/k8s.io/apimachinery/pkg/util/wait/wait.go:134 +0xf8
volcano.sh/volcano/vendor/k8s.io/apimachinery/pkg/util/wait.Until(...)
	/Users/yuan.chen/GolandProjects/src/volcano.sh/volcano/vendor/k8s.io/apimachinery/pkg/util/wait/wait.go:88
volcano.sh/volcano/vendor/k8s.io/client-go/tools/cache.(*Reflector).Run(0xc000321360, 0x0)
	/Users/yuan.chen/GolandProjects/src/volcano.sh/volcano/vendor/k8s.io/client-go/tools/cache/reflector.go:123 +0x169
volcano.sh/volcano/vendor/k8s.io/apimachinery/pkg/util/wait.(*Group).StartWithChannel.func1()
	/Users/yuan.chen/GolandProjects/src/volcano.sh/volcano/vendor/k8s.io/apimachinery/pkg/util/wait/wait.go:54 +0x2e
volcano.sh/volcano/vendor/k8s.io/apimachinery/pkg/util/wait.(*Group).Start.func1(0xc000118a80, 0xc00056b2c0)
	/Users/yuan.chen/GolandProjects/src/volcano.sh/volcano/vendor/k8s.io/apimachinery/pkg/util/wait/wait.go:71 +0x59
created by volcano.sh/volcano/vendor/k8s.io/apimachinery/pkg/util/wait.(*Group).Start
	/Users/yuan.chen/GolandProjects/src/volcano.sh/volcano/vendor/k8s.io/apimachinery/pkg/util/wait/wait.go:69 +0x62

goroutine 86 [select, 2 minutes]:
volcano.sh/volcano/vendor/k8s.io/client-go/tools/cache.(*Reflector).watchHandler(0xc0003f2000, 0x23a3860, 0xc000a12270, 0xc0006c3be0, 0xc0003a71a0, 0x0, 0x0, 0x0)
	/Users/yuan.chen/GolandProjects/src/volcano.sh/volcano/vendor/k8s.io/client-go/tools/cache/reflector.go:283 +0x1ec
volcano.sh/volcano/vendor/k8s.io/client-go/tools/cache.(*Reflector).ListAndWatch(0xc0003f2000, 0x0, 0x0, 0x0)
	/Users/yuan.chen/GolandProjects/src/volcano.sh/volcano/vendor/k8s.io/client-go/tools/cache/reflector.go:254 +0xc73
volcano.sh/volcano/vendor/k8s.io/client-go/tools/cache.(*Reflector).Run.func1()
	/Users/yuan.chen/GolandProjects/src/volcano.sh/volcano/vendor/k8s.io/client-go/tools/cache/reflector.go:124 +0x33
volcano.sh/volcano/vendor/k8s.io/apimachinery/pkg/util/wait.JitterUntil.func1(0xc00038d6f0)
	/Users/yuan.chen/GolandProjects/src/volcano.sh/volcano/vendor/k8s.io/apimachinery/pkg/util/wait/wait.go:133 +0x5e
volcano.sh/volcano/vendor/k8s.io/apimachinery/pkg/util/wait.JitterUntil(0xc0006c3ef0, 0x3b9aca00, 0x0, 0x1, 0x0)
	/Users/yuan.chen/GolandProjects/src/volcano.sh/volcano/vendor/k8s.io/apimachinery/pkg/util/wait/wait.go:134 +0xf8
volcano.sh/volcano/vendor/k8s.io/apimachinery/pkg/util/wait.Until(...)
	/Users/yuan.chen/GolandProjects/src/volcano.sh/volcano/vendor/k8s.io/apimachinery/pkg/util/wait/wait.go:88
volcano.sh/volcano/vendor/k8s.io/client-go/tools/cache.(*Reflector).Run(0xc0003f2000, 0x0)
	/Users/yuan.chen/GolandProjects/src/volcano.sh/volcano/vendor/k8s.io/client-go/tools/cache/reflector.go:123 +0x169
volcano.sh/volcano/vendor/k8s.io/apimachinery/pkg/util/wait.(*Group).StartWithChannel.func1()
	/Users/yuan.chen/GolandProjects/src/volcano.sh/volcano/vendor/k8s.io/apimachinery/pkg/util/wait/wait.go:54 +0x2e
volcano.sh/volcano/vendor/k8s.io/apimachinery/pkg/util/wait.(*Group).Start.func1(0xc000456070, 0xc00042a1c0)
	/Users/yuan.chen/GolandProjects/src/volcano.sh/volcano/vendor/k8s.io/apimachinery/pkg/util/wait/wait.go:71 +0x59
created by volcano.sh/volcano/vendor/k8s.io/apimachinery/pkg/util/wait.(*Group).Start
	/Users/yuan.chen/GolandProjects/src/volcano.sh/volcano/vendor/k8s.io/apimachinery/pkg/util/wait/wait.go:69 +0x62

goroutine 70 [select, 2 minutes]:
volcano.sh/volcano/vendor/k8s.io/client-go/tools/cache.(*Reflector).watchHandler(0xc000554000, 0x23a3860, 0xc0009b8150, 0xc00099dbe0, 0xc0002f9d40, 0x0, 0x0, 0x0)
	/Users/yuan.chen/GolandProjects/src/volcano.sh/volcano/vendor/k8s.io/client-go/tools/cache/reflector.go:283 +0x1ec
volcano.sh/volcano/vendor/k8s.io/client-go/tools/cache.(*Reflector).ListAndWatch(0xc000554000, 0x0, 0x0, 0x0)
	/Users/yuan.chen/GolandProjects/src/volcano.sh/volcano/vendor/k8s.io/client-go/tools/cache/reflector.go:254 +0xc73
volcano.sh/volcano/vendor/k8s.io/client-go/tools/cache.(*Reflector).Run.func1()
	/Users/yuan.chen/GolandProjects/src/volcano.sh/volcano/vendor/k8s.io/client-go/tools/cache/reflector.go:124 +0x33
volcano.sh/volcano/vendor/k8s.io/apimachinery/pkg/util/wait.JitterUntil.func1(0xc000386ef0)
	/Users/yuan.chen/GolandProjects/src/volcano.sh/volcano/vendor/k8s.io/apimachinery/pkg/util/wait/wait.go:133 +0x5e
volcano.sh/volcano/vendor/k8s.io/apimachinery/pkg/util/wait.JitterUntil(0xc00099def0, 0x3b9aca00, 0x0, 0x1, 0x0)
	/Users/yuan.chen/GolandProjects/src/volcano.sh/volcano/vendor/k8s.io/apimachinery/pkg/util/wait/wait.go:134 +0xf8
volcano.sh/volcano/vendor/k8s.io/apimachinery/pkg/util/wait.Until(...)
	/Users/yuan.chen/GolandProjects/src/volcano.sh/volcano/vendor/k8s.io/apimachinery/pkg/util/wait/wait.go:88
volcano.sh/volcano/vendor/k8s.io/client-go/tools/cache.(*Reflector).Run(0xc000554000, 0x0)
	/Users/yuan.chen/GolandProjects/src/volcano.sh/volcano/vendor/k8s.io/client-go/tools/cache/reflector.go:123 +0x169
volcano.sh/volcano/vendor/k8s.io/apimachinery/pkg/util/wait.(*Group).StartWithChannel.func1()
	/Users/yuan.chen/GolandProjects/src/volcano.sh/volcano/vendor/k8s.io/apimachinery/pkg/util/wait/wait.go:54 +0x2e
volcano.sh/volcano/vendor/k8s.io/apimachinery/pkg/util/wait.(*Group).Start.func1(0xc0003be070, 0xc00016c320)
	/Users/yuan.chen/GolandProjects/src/volcano.sh/volcano/vendor/k8s.io/apimachinery/pkg/util/wait/wait.go:71 +0x59
created by volcano.sh/volcano/vendor/k8s.io/apimachinery/pkg/util/wait.(*Group).Start
	/Users/yuan.chen/GolandProjects/src/volcano.sh/volcano/vendor/k8s.io/apimachinery/pkg/util/wait/wait.go:69 +0x62

goroutine 195 [chan receive, 2 minutes]:
volcano.sh/volcano/vendor/k8s.io/client-go/tools/cache.(*processorListener).run.func1.1(0x0, 0x10, 0x18)
	/Users/yuan.chen/GolandProjects/src/volcano.sh/volcano/vendor/k8s.io/client-go/tools/cache/shared_informer.go:549 +0x54
volcano.sh/volcano/vendor/k8s.io/apimachinery/pkg/util/wait.ExponentialBackoff(0x989680, 0x3ff0000000000000, 0x3fb999999999999a, 0x5, 0xc00073ddd8, 0x0, 0x0)
	/Users/yuan.chen/GolandProjects/src/volcano.sh/volcano/vendor/k8s.io/apimachinery/pkg/util/wait/wait.go:203 +0xde
volcano.sh/volcano/vendor/k8s.io/client-go/tools/cache.(*processorListener).run.func1()
	/Users/yuan.chen/GolandProjects/src/volcano.sh/volcano/vendor/k8s.io/client-go/tools/cache/shared_informer.go:548 +0x89
volcano.sh/volcano/vendor/k8s.io/apimachinery/pkg/util/wait.JitterUntil.func1(0xc0005e9f40)
	/Users/yuan.chen/GolandProjects/src/volcano.sh/volcano/vendor/k8s.io/apimachinery/pkg/util/wait/wait.go:133 +0x5e
volcano.sh/volcano/vendor/k8s.io/apimachinery/pkg/util/wait.JitterUntil(0xc00073df40, 0xdf8475800, 0x0, 0x1030501, 0xc000340360)
	/Users/yuan.chen/GolandProjects/src/volcano.sh/volcano/vendor/k8s.io/apimachinery/pkg/util/wait/wait.go:134 +0xf8
volcano.sh/volcano/vendor/k8s.io/apimachinery/pkg/util/wait.Until(...)
	/Users/yuan.chen/GolandProjects/src/volcano.sh/volcano/vendor/k8s.io/apimachinery/pkg/util/wait/wait.go:88
volcano.sh/volcano/vendor/k8s.io/client-go/tools/cache.(*processorListener).run(0xc0005a5100)
	/Users/yuan.chen/GolandProjects/src/volcano.sh/volcano/vendor/k8s.io/client-go/tools/cache/shared_informer.go:546 +0x9b
volcano.sh/volcano/vendor/k8s.io/apimachinery/pkg/util/wait.(*Group).Start.func1(0xc0002965a0, 0xc0000ca600)
	/Users/yuan.chen/GolandProjects/src/volcano.sh/volcano/vendor/k8s.io/apimachinery/pkg/util/wait/wait.go:71 +0x59
created by volcano.sh/volcano/vendor/k8s.io/apimachinery/pkg/util/wait.(*Group).Start
	/Users/yuan.chen/GolandProjects/src/volcano.sh/volcano/vendor/k8s.io/apimachinery/pkg/util/wait/wait.go:69 +0x62

goroutine 163 [chan receive, 2 minutes]:
volcano.sh/volcano/vendor/k8s.io/client-go/tools/cache.(*sharedProcessor).run(0xc0002968c0, 0xc0001d6f60)
	/Users/yuan.chen/GolandProjects/src/volcano.sh/volcano/vendor/k8s.io/client-go/tools/cache/shared_informer.go:425 +0x49
volcano.sh/volcano/vendor/k8s.io/apimachinery/pkg/util/wait.(*Group).StartWithChannel.func1()
	/Users/yuan.chen/GolandProjects/src/volcano.sh/volcano/vendor/k8s.io/apimachinery/pkg/util/wait/wait.go:54 +0x2e
volcano.sh/volcano/vendor/k8s.io/apimachinery/pkg/util/wait.(*Group).Start.func1(0xc000118bc0, 0xc00056b5c0)
	/Users/yuan.chen/GolandProjects/src/volcano.sh/volcano/vendor/k8s.io/apimachinery/pkg/util/wait/wait.go:71 +0x59
created by volcano.sh/volcano/vendor/k8s.io/apimachinery/pkg/util/wait.(*Group).Start
	/Users/yuan.chen/GolandProjects/src/volcano.sh/volcano/vendor/k8s.io/apimachinery/pkg/util/wait/wait.go:69 +0x62

goroutine 164 [chan receive (nil chan), 2 minutes]:
volcano.sh/volcano/vendor/k8s.io/client-go/tools/cache.(*controller).Run.func1(0x0, 0xc0002d7980)
	/Users/yuan.chen/GolandProjects/src/volcano.sh/volcano/vendor/k8s.io/client-go/tools/cache/controller.go:103 +0x34
created by volcano.sh/volcano/vendor/k8s.io/client-go/tools/cache.(*controller).Run
	/Users/yuan.chen/GolandProjects/src/volcano.sh/volcano/vendor/k8s.io/client-go/tools/cache/controller.go:102 +0xae

goroutine 118 [select, 2 minutes]:
volcano.sh/volcano/vendor/k8s.io/client-go/tools/cache.(*Reflector).watchHandler(0xc00030a0a0, 0x23a3860, 0xc0008d1200, 0xc0006c1be0, 0xc0003a6c60, 0x0, 0x0, 0x0)
	/Users/yuan.chen/GolandProjects/src/volcano.sh/volcano/vendor/k8s.io/client-go/tools/cache/reflector.go:283 +0x1ec
volcano.sh/volcano/vendor/k8s.io/client-go/tools/cache.(*Reflector).ListAndWatch(0xc00030a0a0, 0x0, 0x0, 0x0)
	/Users/yuan.chen/GolandProjects/src/volcano.sh/volcano/vendor/k8s.io/client-go/tools/cache/reflector.go:254 +0xc73
volcano.sh/volcano/vendor/k8s.io/client-go/tools/cache.(*Reflector).Run.func1()
	/Users/yuan.chen/GolandProjects/src/volcano.sh/volcano/vendor/k8s.io/client-go/tools/cache/reflector.go:124 +0x33
volcano.sh/volcano/vendor/k8s.io/apimachinery/pkg/util/wait.JitterUntil.func1(0xc0003876f0)
	/Users/yuan.chen/GolandProjects/src/volcano.sh/volcano/vendor/k8s.io/apimachinery/pkg/util/wait/wait.go:133 +0x5e
volcano.sh/volcano/vendor/k8s.io/apimachinery/pkg/util/wait.JitterUntil(0xc0006c1ef0, 0x3b9aca00, 0x0, 0x1, 0x0)
	/Users/yuan.chen/GolandProjects/src/volcano.sh/volcano/vendor/k8s.io/apimachinery/pkg/util/wait/wait.go:134 +0xf8
volcano.sh/volcano/vendor/k8s.io/apimachinery/pkg/util/wait.Until(...)
	/Users/yuan.chen/GolandProjects/src/volcano.sh/volcano/vendor/k8s.io/apimachinery/pkg/util/wait/wait.go:88
volcano.sh/volcano/vendor/k8s.io/client-go/tools/cache.(*Reflector).Run(0xc00030a0a0, 0x0)
	/Users/yuan.chen/GolandProjects/src/volcano.sh/volcano/vendor/k8s.io/client-go/tools/cache/reflector.go:123 +0x169
volcano.sh/volcano/vendor/k8s.io/apimachinery/pkg/util/wait.(*Group).StartWithChannel.func1()
	/Users/yuan.chen/GolandProjects/src/volcano.sh/volcano/vendor/k8s.io/apimachinery/pkg/util/wait/wait.go:54 +0x2e
volcano.sh/volcano/vendor/k8s.io/apimachinery/pkg/util/wait.(*Group).Start.func1(0xc000496120, 0xc00000e280)
	/Users/yuan.chen/GolandProjects/src/volcano.sh/volcano/vendor/k8s.io/apimachinery/pkg/util/wait/wait.go:71 +0x59
created by volcano.sh/volcano/vendor/k8s.io/apimachinery/pkg/util/wait.(*Group).Start
	/Users/yuan.chen/GolandProjects/src/volcano.sh/volcano/vendor/k8s.io/apimachinery/pkg/util/wait/wait.go:69 +0x62

goroutine 87 [chan receive, 2 minutes]:
volcano.sh/volcano/vendor/k8s.io/client-go/tools/cache.(*processorListener).run.func1.1(0x0, 0x10, 0x18)
	/Users/yuan.chen/GolandProjects/src/volcano.sh/volcano/vendor/k8s.io/client-go/tools/cache/shared_informer.go:549 +0x54
volcano.sh/volcano/vendor/k8s.io/apimachinery/pkg/util/wait.ExponentialBackoff(0x989680, 0x3ff0000000000000, 0x3fb999999999999a, 0x5, 0xc000627dd8, 0x0, 0x0)
	/Users/yuan.chen/GolandProjects/src/volcano.sh/volcano/vendor/k8s.io/apimachinery/pkg/util/wait/wait.go:203 +0xde
volcano.sh/volcano/vendor/k8s.io/client-go/tools/cache.(*processorListener).run.func1()
	/Users/yuan.chen/GolandProjects/src/volcano.sh/volcano/vendor/k8s.io/client-go/tools/cache/shared_informer.go:548 +0x89
volcano.sh/volcano/vendor/k8s.io/apimachinery/pkg/util/wait.JitterUntil.func1(0xc00038d740)
	/Users/yuan.chen/GolandProjects/src/volcano.sh/volcano/vendor/k8s.io/apimachinery/pkg/util/wait/wait.go:133 +0x5e
volcano.sh/volcano/vendor/k8s.io/apimachinery/pkg/util/wait.JitterUntil(0xc000627f40, 0xdf8475800, 0x0, 0xc0000ca301, 0xc0003400c0)
	/Users/yuan.chen/GolandProjects/src/volcano.sh/volcano/vendor/k8s.io/apimachinery/pkg/util/wait/wait.go:134 +0xf8
volcano.sh/volcano/vendor/k8s.io/apimachinery/pkg/util/wait.Until(...)
	/Users/yuan.chen/GolandProjects/src/volcano.sh/volcano/vendor/k8s.io/apimachinery/pkg/util/wait/wait.go:88
volcano.sh/volcano/vendor/k8s.io/client-go/tools/cache.(*processorListener).run(0xc0005a4e80)
	/Users/yuan.chen/GolandProjects/src/volcano.sh/volcano/vendor/k8s.io/client-go/tools/cache/shared_informer.go:546 +0x9b
volcano.sh/volcano/vendor/k8s.io/apimachinery/pkg/util/wait.(*Group).Start.func1(0xc000296530, 0xc0000ca540)
	/Users/yuan.chen/GolandProjects/src/volcano.sh/volcano/vendor/k8s.io/apimachinery/pkg/util/wait/wait.go:71 +0x59
created by volcano.sh/volcano/vendor/k8s.io/apimachinery/pkg/util/wait.(*Group).Start
	/Users/yuan.chen/GolandProjects/src/volcano.sh/volcano/vendor/k8s.io/apimachinery/pkg/util/wait/wait.go:69 +0x62

goroutine 88 [select, 2 minutes]:
volcano.sh/volcano/vendor/k8s.io/client-go/tools/cache.(*processorListener).pop(0xc0005a4e80)
	/Users/yuan.chen/GolandProjects/src/volcano.sh/volcano/vendor/k8s.io/client-go/tools/cache/shared_informer.go:517 +0x18d
volcano.sh/volcano/vendor/k8s.io/apimachinery/pkg/util/wait.(*Group).Start.func1(0xc000296530, 0xc0000ca550)
	/Users/yuan.chen/GolandProjects/src/volcano.sh/volcano/vendor/k8s.io/apimachinery/pkg/util/wait/wait.go:71 +0x59
created by volcano.sh/volcano/vendor/k8s.io/apimachinery/pkg/util/wait.(*Group).Start
	/Users/yuan.chen/GolandProjects/src/volcano.sh/volcano/vendor/k8s.io/apimachinery/pkg/util/wait/wait.go:69 +0x62

goroutine 102 [select, 2 minutes]:
volcano.sh/volcano/vendor/k8s.io/client-go/tools/cache.(*Reflector).watchHandler(0xc000464000, 0x23a3860, 0xc0009b8030, 0xc0008edbe0, 0xc0000aef60, 0x0, 0x0, 0x0)
	/Users/yuan.chen/GolandProjects/src/volcano.sh/volcano/vendor/k8s.io/client-go/tools/cache/reflector.go:283 +0x1ec
volcano.sh/volcano/vendor/k8s.io/client-go/tools/cache.(*Reflector).ListAndWatch(0xc000464000, 0x0, 0x0, 0x0)
	/Users/yuan.chen/GolandProjects/src/volcano.sh/volcano/vendor/k8s.io/client-go/tools/cache/reflector.go:254 +0xc73
volcano.sh/volcano/vendor/k8s.io/client-go/tools/cache.(*Reflector).Run.func1()
	/Users/yuan.chen/GolandProjects/src/volcano.sh/volcano/vendor/k8s.io/client-go/tools/cache/reflector.go:124 +0x33
volcano.sh/volcano/vendor/k8s.io/apimachinery/pkg/util/wait.JitterUntil.func1(0xc000387ef0)
	/Users/yuan.chen/GolandProjects/src/volcano.sh/volcano/vendor/k8s.io/apimachinery/pkg/util/wait/wait.go:133 +0x5e
volcano.sh/volcano/vendor/k8s.io/apimachinery/pkg/util/wait.JitterUntil(0xc0008edef0, 0x3b9aca00, 0x0, 0x1, 0x0)
	/Users/yuan.chen/GolandProjects/src/volcano.sh/volcano/vendor/k8s.io/apimachinery/pkg/util/wait/wait.go:134 +0xf8
volcano.sh/volcano/vendor/k8s.io/apimachinery/pkg/util/wait.Until(...)
	/Users/yuan.chen/GolandProjects/src/volcano.sh/volcano/vendor/k8s.io/apimachinery/pkg/util/wait/wait.go:88
volcano.sh/volcano/vendor/k8s.io/client-go/tools/cache.(*Reflector).Run(0xc000464000, 0x0)
	/Users/yuan.chen/GolandProjects/src/volcano.sh/volcano/vendor/k8s.io/client-go/tools/cache/reflector.go:123 +0x169
volcano.sh/volcano/vendor/k8s.io/apimachinery/pkg/util/wait.(*Group).StartWithChannel.func1()
	/Users/yuan.chen/GolandProjects/src/volcano.sh/volcano/vendor/k8s.io/apimachinery/pkg/util/wait/wait.go:54 +0x2e
volcano.sh/volcano/vendor/k8s.io/apimachinery/pkg/util/wait.(*Group).Start.func1(0xc000598060, 0xc00011e3c0)
	/Users/yuan.chen/GolandProjects/src/volcano.sh/volcano/vendor/k8s.io/apimachinery/pkg/util/wait/wait.go:71 +0x59
created by volcano.sh/volcano/vendor/k8s.io/apimachinery/pkg/util/wait.(*Group).Start
	/Users/yuan.chen/GolandProjects/src/volcano.sh/volcano/vendor/k8s.io/apimachinery/pkg/util/wait/wait.go:69 +0x62

goroutine 46 [select, 2 minutes]:
volcano.sh/volcano/vendor/k8s.io/client-go/tools/cache.(*Reflector).watchHandler(0xc0005fe000, 0x23a3860, 0xc0009b8300, 0xc000777be0, 0xc0002f9b60, 0x0, 0x0, 0x0)
	/Users/yuan.chen/GolandProjects/src/volcano.sh/volcano/vendor/k8s.io/client-go/tools/cache/reflector.go:283 +0x1ec
volcano.sh/volcano/vendor/k8s.io/client-go/tools/cache.(*Reflector).ListAndWatch(0xc0005fe000, 0x0, 0x0, 0x0)
	/Users/yuan.chen/GolandProjects/src/volcano.sh/volcano/vendor/k8s.io/client-go/tools/cache/reflector.go:254 +0xc73
volcano.sh/volcano/vendor/k8s.io/client-go/tools/cache.(*Reflector).Run.func1()
	/Users/yuan.chen/GolandProjects/src/volcano.sh/volcano/vendor/k8s.io/client-go/tools/cache/reflector.go:124 +0x33
volcano.sh/volcano/vendor/k8s.io/apimachinery/pkg/util/wait.JitterUntil.func1(0xc000071ef0)
	/Users/yuan.chen/GolandProjects/src/volcano.sh/volcano/vendor/k8s.io/apimachinery/pkg/util/wait/wait.go:133 +0x5e
volcano.sh/volcano/vendor/k8s.io/apimachinery/pkg/util/wait.JitterUntil(0xc000777ef0, 0x3b9aca00, 0x0, 0x1, 0x0)
	/Users/yuan.chen/GolandProjects/src/volcano.sh/volcano/vendor/k8s.io/apimachinery/pkg/util/wait/wait.go:134 +0xf8
volcano.sh/volcano/vendor/k8s.io/apimachinery/pkg/util/wait.Until(...)
	/Users/yuan.chen/GolandProjects/src/volcano.sh/volcano/vendor/k8s.io/apimachinery/pkg/util/wait/wait.go:88
volcano.sh/volcano/vendor/k8s.io/client-go/tools/cache.(*Reflector).Run(0xc0005fe000, 0x0)
	/Users/yuan.chen/GolandProjects/src/volcano.sh/volcano/vendor/k8s.io/client-go/tools/cache/reflector.go:123 +0x169
volcano.sh/volcano/vendor/k8s.io/apimachinery/pkg/util/wait.(*Group).StartWithChannel.func1()
	/Users/yuan.chen/GolandProjects/src/volcano.sh/volcano/vendor/k8s.io/apimachinery/pkg/util/wait/wait.go:54 +0x2e
volcano.sh/volcano/vendor/k8s.io/apimachinery/pkg/util/wait.(*Group).Start.func1(0xc0000440f0, 0xc000302360)
	/Users/yuan.chen/GolandProjects/src/volcano.sh/volcano/vendor/k8s.io/apimachinery/pkg/util/wait/wait.go:71 +0x59
created by volcano.sh/volcano/vendor/k8s.io/apimachinery/pkg/util/wait.(*Group).Start
	/Users/yuan.chen/GolandProjects/src/volcano.sh/volcano/vendor/k8s.io/apimachinery/pkg/util/wait/wait.go:69 +0x62

goroutine 178 [select]:
volcano.sh/volcano/vendor/k8s.io/client-go/tools/cache.(*Reflector).watchHandler(0xc000628000, 0x23a3860, 0xc000a12390, 0xc00090dbe0, 0xc0003b2f00, 0x0, 0x0, 0x0)
	/Users/yuan.chen/GolandProjects/src/volcano.sh/volcano/vendor/k8s.io/client-go/tools/cache/reflector.go:283 +0x1ec
volcano.sh/volcano/vendor/k8s.io/client-go/tools/cache.(*Reflector).ListAndWatch(0xc000628000, 0x0, 0x0, 0x0)
	/Users/yuan.chen/GolandProjects/src/volcano.sh/volcano/vendor/k8s.io/client-go/tools/cache/reflector.go:254 +0xc73
volcano.sh/volcano/vendor/k8s.io/client-go/tools/cache.(*Reflector).Run.func1()
	/Users/yuan.chen/GolandProjects/src/volcano.sh/volcano/vendor/k8s.io/client-go/tools/cache/reflector.go:124 +0x33
volcano.sh/volcano/vendor/k8s.io/apimachinery/pkg/util/wait.JitterUntil.func1(0xc00006c6f0)
	/Users/yuan.chen/GolandProjects/src/volcano.sh/volcano/vendor/k8s.io/apimachinery/pkg/util/wait/wait.go:133 +0x5e
volcano.sh/volcano/vendor/k8s.io/apimachinery/pkg/util/wait.JitterUntil(0xc00090def0, 0x3b9aca00, 0x0, 0x1, 0x0)
	/Users/yuan.chen/GolandProjects/src/volcano.sh/volcano/vendor/k8s.io/apimachinery/pkg/util/wait/wait.go:134 +0xf8
volcano.sh/volcano/vendor/k8s.io/apimachinery/pkg/util/wait.Until(...)
	/Users/yuan.chen/GolandProjects/src/volcano.sh/volcano/vendor/k8s.io/apimachinery/pkg/util/wait/wait.go:88
volcano.sh/volcano/vendor/k8s.io/client-go/tools/cache.(*Reflector).Run(0xc000628000, 0x0)
	/Users/yuan.chen/GolandProjects/src/volcano.sh/volcano/vendor/k8s.io/client-go/tools/cache/reflector.go:123 +0x169
volcano.sh/volcano/vendor/k8s.io/apimachinery/pkg/util/wait.(*Group).StartWithChannel.func1()
	/Users/yuan.chen/GolandProjects/src/volcano.sh/volcano/vendor/k8s.io/apimachinery/pkg/util/wait/wait.go:54 +0x2e
volcano.sh/volcano/vendor/k8s.io/apimachinery/pkg/util/wait.(*Group).Start.func1(0xc00057a200, 0xc0000daac0)
	/Users/yuan.chen/GolandProjects/src/volcano.sh/volcano/vendor/k8s.io/apimachinery/pkg/util/wait/wait.go:71 +0x59
created by volcano.sh/volcano/vendor/k8s.io/apimachinery/pkg/util/wait.(*Group).Start
	/Users/yuan.chen/GolandProjects/src/volcano.sh/volcano/vendor/k8s.io/apimachinery/pkg/util/wait/wait.go:69 +0x62

goroutine 90 [select, 2 minutes]:
volcano.sh/volcano/vendor/k8s.io/client-go/tools/cache.(*processorListener).pop(0xc0005a4400)
	/Users/yuan.chen/GolandProjects/src/volcano.sh/volcano/vendor/k8s.io/client-go/tools/cache/shared_informer.go:517 +0x18d
volcano.sh/volcano/vendor/k8s.io/apimachinery/pkg/util/wait.(*Group).Start.func1(0xc000296300, 0xc0000ca570)
	/Users/yuan.chen/GolandProjects/src/volcano.sh/volcano/vendor/k8s.io/apimachinery/pkg/util/wait/wait.go:71 +0x59
created by volcano.sh/volcano/vendor/k8s.io/apimachinery/pkg/util/wait.(*Group).Start
	/Users/yuan.chen/GolandProjects/src/volcano.sh/volcano/vendor/k8s.io/apimachinery/pkg/util/wait/wait.go:69 +0x62

goroutine 106 [chan receive, 2 minutes]:
volcano.sh/volcano/vendor/k8s.io/client-go/tools/cache.(*sharedProcessor).run(0xc000296540, 0xc0003b80c0)
	/Users/yuan.chen/GolandProjects/src/volcano.sh/volcano/vendor/k8s.io/client-go/tools/cache/shared_informer.go:425 +0x49
volcano.sh/volcano/vendor/k8s.io/apimachinery/pkg/util/wait.(*Group).StartWithChannel.func1()
	/Users/yuan.chen/GolandProjects/src/volcano.sh/volcano/vendor/k8s.io/apimachinery/pkg/util/wait/wait.go:54 +0x2e
volcano.sh/volcano/vendor/k8s.io/apimachinery/pkg/util/wait.(*Group).Start.func1(0xc000598170, 0xc00011e760)
	/Users/yuan.chen/GolandProjects/src/volcano.sh/volcano/vendor/k8s.io/apimachinery/pkg/util/wait/wait.go:71 +0x59
created by volcano.sh/volcano/vendor/k8s.io/apimachinery/pkg/util/wait.(*Group).Start
	/Users/yuan.chen/GolandProjects/src/volcano.sh/volcano/vendor/k8s.io/apimachinery/pkg/util/wait/wait.go:69 +0x62

goroutine 72 [chan receive, 2 minutes]:
volcano.sh/volcano/vendor/k8s.io/client-go/tools/cache.(*sharedProcessor).run(0xc0002967e0, 0xc0003840c0)
	/Users/yuan.chen/GolandProjects/src/volcano.sh/volcano/vendor/k8s.io/client-go/tools/cache/shared_informer.go:425 +0x49
volcano.sh/volcano/vendor/k8s.io/apimachinery/pkg/util/wait.(*Group).StartWithChannel.func1()
	/Users/yuan.chen/GolandProjects/src/volcano.sh/volcano/vendor/k8s.io/apimachinery/pkg/util/wait/wait.go:54 +0x2e
volcano.sh/volcano/vendor/k8s.io/apimachinery/pkg/util/wait.(*Group).Start.func1(0xc0003be180, 0xc00016cbe0)
	/Users/yuan.chen/GolandProjects/src/volcano.sh/volcano/vendor/k8s.io/apimachinery/pkg/util/wait/wait.go:71 +0x59
created by volcano.sh/volcano/vendor/k8s.io/apimachinery/pkg/util/wait.(*Group).Start
	/Users/yuan.chen/GolandProjects/src/volcano.sh/volcano/vendor/k8s.io/apimachinery/pkg/util/wait/wait.go:69 +0x62

goroutine 73 [chan receive (nil chan), 2 minutes]:
volcano.sh/volcano/vendor/k8s.io/client-go/tools/cache.(*controller).Run.func1(0x0, 0xc00041c700)
	/Users/yuan.chen/GolandProjects/src/volcano.sh/volcano/vendor/k8s.io/client-go/tools/cache/controller.go:103 +0x34
created by volcano.sh/volcano/vendor/k8s.io/client-go/tools/cache.(*controller).Run
	/Users/yuan.chen/GolandProjects/src/volcano.sh/volcano/vendor/k8s.io/client-go/tools/cache/controller.go:102 +0xae

goroutine 165 [select, 2 minutes]:
volcano.sh/volcano/vendor/k8s.io/client-go/tools/cache.(*Reflector).watchHandler(0xc000321400, 0x23a3860, 0xc0000ccde0, 0xc000909be0, 0xc000565860, 0x0, 0x0, 0x0)
	/Users/yuan.chen/GolandProjects/src/volcano.sh/volcano/vendor/k8s.io/client-go/tools/cache/reflector.go:283 +0x1ec
volcano.sh/volcano/vendor/k8s.io/client-go/tools/cache.(*Reflector).ListAndWatch(0xc000321400, 0x0, 0x0, 0x0)
	/Users/yuan.chen/GolandProjects/src/volcano.sh/volcano/vendor/k8s.io/client-go/tools/cache/reflector.go:254 +0xc73
volcano.sh/volcano/vendor/k8s.io/client-go/tools/cache.(*Reflector).Run.func1()
	/Users/yuan.chen/GolandProjects/src/volcano.sh/volcano/vendor/k8s.io/client-go/tools/cache/reflector.go:124 +0x33
volcano.sh/volcano/vendor/k8s.io/apimachinery/pkg/util/wait.JitterUntil.func1(0xc000388ef0)
	/Users/yuan.chen/GolandProjects/src/volcano.sh/volcano/vendor/k8s.io/apimachinery/pkg/util/wait/wait.go:133 +0x5e
volcano.sh/volcano/vendor/k8s.io/apimachinery/pkg/util/wait.JitterUntil(0xc000909ef0, 0x3b9aca00, 0x0, 0x1, 0x0)
	/Users/yuan.chen/GolandProjects/src/volcano.sh/volcano/vendor/k8s.io/apimachinery/pkg/util/wait/wait.go:134 +0xf8
volcano.sh/volcano/vendor/k8s.io/apimachinery/pkg/util/wait.Until(...)
	/Users/yuan.chen/GolandProjects/src/volcano.sh/volcano/vendor/k8s.io/apimachinery/pkg/util/wait/wait.go:88
volcano.sh/volcano/vendor/k8s.io/client-go/tools/cache.(*Reflector).Run(0xc000321400, 0x0)
	/Users/yuan.chen/GolandProjects/src/volcano.sh/volcano/vendor/k8s.io/client-go/tools/cache/reflector.go:123 +0x169
volcano.sh/volcano/vendor/k8s.io/apimachinery/pkg/util/wait.(*Group).StartWithChannel.func1()
	/Users/yuan.chen/GolandProjects/src/volcano.sh/volcano/vendor/k8s.io/apimachinery/pkg/util/wait/wait.go:54 +0x2e
volcano.sh/volcano/vendor/k8s.io/apimachinery/pkg/util/wait.(*Group).Start.func1(0xc000118c10, 0xc00056b6c0)
	/Users/yuan.chen/GolandProjects/src/volcano.sh/volcano/vendor/k8s.io/apimachinery/pkg/util/wait/wait.go:71 +0x59
created by volcano.sh/volcano/vendor/k8s.io/apimachinery/pkg/util/wait.(*Group).Start
	/Users/yuan.chen/GolandProjects/src/volcano.sh/volcano/vendor/k8s.io/apimachinery/pkg/util/wait/wait.go:69 +0x62

goroutine 92 [select, 2 minutes]:
volcano.sh/volcano/vendor/k8s.io/client-go/tools/cache.(*processorListener).pop(0xc0005a4b80)
	/Users/yuan.chen/GolandProjects/src/volcano.sh/volcano/vendor/k8s.io/client-go/tools/cache/shared_informer.go:517 +0x18d
volcano.sh/volcano/vendor/k8s.io/apimachinery/pkg/util/wait.(*Group).Start.func1(0xc0002964c0, 0xc0000ca590)
	/Users/yuan.chen/GolandProjects/src/volcano.sh/volcano/vendor/k8s.io/apimachinery/pkg/util/wait/wait.go:71 +0x59
created by volcano.sh/volcano/vendor/k8s.io/apimachinery/pkg/util/wait.(*Group).Start
	/Users/yuan.chen/GolandProjects/src/volcano.sh/volcano/vendor/k8s.io/apimachinery/pkg/util/wait/wait.go:69 +0x62

goroutine 28 [select, 2 minutes]:
volcano.sh/volcano/vendor/k8s.io/client-go/tools/cache.(*processorListener).pop(0xc0005a5900)
	/Users/yuan.chen/GolandProjects/src/volcano.sh/volcano/vendor/k8s.io/client-go/tools/cache/shared_informer.go:517 +0x18d
volcano.sh/volcano/vendor/k8s.io/apimachinery/pkg/util/wait.(*Group).Start.func1(0xc0002968b0, 0xc00054c210)
	/Users/yuan.chen/GolandProjects/src/volcano.sh/volcano/vendor/k8s.io/apimachinery/pkg/util/wait/wait.go:71 +0x59
created by volcano.sh/volcano/vendor/k8s.io/apimachinery/pkg/util/wait.(*Group).Start
	/Users/yuan.chen/GolandProjects/src/volcano.sh/volcano/vendor/k8s.io/apimachinery/pkg/util/wait/wait.go:69 +0x62

goroutine 93 [chan receive]:
volcano.sh/volcano/vendor/k8s.io/client-go/tools/cache.(*processorListener).run.func1.1(0x0, 0x0, 0x0)
	/Users/yuan.chen/GolandProjects/src/volcano.sh/volcano/vendor/k8s.io/client-go/tools/cache/shared_informer.go:549 +0x54
volcano.sh/volcano/vendor/k8s.io/apimachinery/pkg/util/wait.ExponentialBackoff(0x989680, 0x3ff0000000000000, 0x3fb999999999999a, 0x5, 0xc000711dd8, 0x0, 0x0)
	/Users/yuan.chen/GolandProjects/src/volcano.sh/volcano/vendor/k8s.io/apimachinery/pkg/util/wait/wait.go:203 +0xde
volcano.sh/volcano/vendor/k8s.io/client-go/tools/cache.(*processorListener).run.func1()
	/Users/yuan.chen/GolandProjects/src/volcano.sh/volcano/vendor/k8s.io/client-go/tools/cache/shared_informer.go:548 +0x89
volcano.sh/volcano/vendor/k8s.io/apimachinery/pkg/util/wait.JitterUntil.func1(0xc0005edf40)
	/Users/yuan.chen/GolandProjects/src/volcano.sh/volcano/vendor/k8s.io/apimachinery/pkg/util/wait/wait.go:133 +0x5e
volcano.sh/volcano/vendor/k8s.io/apimachinery/pkg/util/wait.JitterUntil(0xc000711f40, 0xdf8475800, 0x0, 0x1030501, 0xc0003401e0)
	/Users/yuan.chen/GolandProjects/src/volcano.sh/volcano/vendor/k8s.io/apimachinery/pkg/util/wait/wait.go:134 +0xf8
volcano.sh/volcano/vendor/k8s.io/apimachinery/pkg/util/wait.Until(...)
	/Users/yuan.chen/GolandProjects/src/volcano.sh/volcano/vendor/k8s.io/apimachinery/pkg/util/wait/wait.go:88
volcano.sh/volcano/vendor/k8s.io/client-go/tools/cache.(*processorListener).run(0xc0005a4900)
	/Users/yuan.chen/GolandProjects/src/volcano.sh/volcano/vendor/k8s.io/client-go/tools/cache/shared_informer.go:546 +0x9b
volcano.sh/volcano/vendor/k8s.io/apimachinery/pkg/util/wait.(*Group).Start.func1(0xc000296450, 0xc0000ca5a0)
	/Users/yuan.chen/GolandProjects/src/volcano.sh/volcano/vendor/k8s.io/apimachinery/pkg/util/wait/wait.go:71 +0x59
created by volcano.sh/volcano/vendor/k8s.io/apimachinery/pkg/util/wait.(*Group).Start
	/Users/yuan.chen/GolandProjects/src/volcano.sh/volcano/vendor/k8s.io/apimachinery/pkg/util/wait/wait.go:69 +0x62

goroutine 94 [select]:
volcano.sh/volcano/vendor/k8s.io/client-go/tools/cache.(*processorListener).pop(0xc0005a4900)
	/Users/yuan.chen/GolandProjects/src/volcano.sh/volcano/vendor/k8s.io/client-go/tools/cache/shared_informer.go:517 +0x18d
volcano.sh/volcano/vendor/k8s.io/apimachinery/pkg/util/wait.(*Group).Start.func1(0xc000296450, 0xc0000ca5b0)
	/Users/yuan.chen/GolandProjects/src/volcano.sh/volcano/vendor/k8s.io/apimachinery/pkg/util/wait/wait.go:71 +0x59
created by volcano.sh/volcano/vendor/k8s.io/apimachinery/pkg/util/wait.(*Group).Start
	/Users/yuan.chen/GolandProjects/src/volcano.sh/volcano/vendor/k8s.io/apimachinery/pkg/util/wait/wait.go:69 +0x62

goroutine 95 [chan receive, 2 minutes]:
volcano.sh/volcano/vendor/k8s.io/client-go/tools/cache.(*processorListener).run.func1.1(0x0, 0x0, 0x0)
	/Users/yuan.chen/GolandProjects/src/volcano.sh/volcano/vendor/k8s.io/client-go/tools/cache/shared_informer.go:549 +0x54
volcano.sh/volcano/vendor/k8s.io/apimachinery/pkg/util/wait.ExponentialBackoff(0x989680, 0x3ff0000000000000, 0x3fb999999999999a, 0x5, 0xc00070ddd8, 0x0, 0x0)
	/Users/yuan.chen/GolandProjects/src/volcano.sh/volcano/vendor/k8s.io/apimachinery/pkg/util/wait/wait.go:203 +0xde
volcano.sh/volcano/vendor/k8s.io/client-go/tools/cache.(*processorListener).run.func1()
	/Users/yuan.chen/GolandProjects/src/volcano.sh/volcano/vendor/k8s.io/client-go/tools/cache/shared_informer.go:548 +0x89
volcano.sh/volcano/vendor/k8s.io/apimachinery/pkg/util/wait.JitterUntil.func1(0xc00060bf40)
	/Users/yuan.chen/GolandProjects/src/volcano.sh/volcano/vendor/k8s.io/apimachinery/pkg/util/wait/wait.go:133 +0x5e
volcano.sh/volcano/vendor/k8s.io/apimachinery/pkg/util/wait.JitterUntil(0xc00070df40, 0xdf8475800, 0x0, 0x1030501, 0xc0003402a0)
	/Users/yuan.chen/GolandProjects/src/volcano.sh/volcano/vendor/k8s.io/apimachinery/pkg/util/wait/wait.go:134 +0xf8
volcano.sh/volcano/vendor/k8s.io/apimachinery/pkg/util/wait.Until(...)
	/Users/yuan.chen/GolandProjects/src/volcano.sh/volcano/vendor/k8s.io/apimachinery/pkg/util/wait/wait.go:88
volcano.sh/volcano/vendor/k8s.io/client-go/tools/cache.(*processorListener).run(0xc0005a5480)
	/Users/yuan.chen/GolandProjects/src/volcano.sh/volcano/vendor/k8s.io/client-go/tools/cache/shared_informer.go:546 +0x9b
volcano.sh/volcano/vendor/k8s.io/apimachinery/pkg/util/wait.(*Group).Start.func1(0xc0002967d0, 0xc0000ca5c0)
	/Users/yuan.chen/GolandProjects/src/volcano.sh/volcano/vendor/k8s.io/apimachinery/pkg/util/wait/wait.go:71 +0x59
created by volcano.sh/volcano/vendor/k8s.io/apimachinery/pkg/util/wait.(*Group).Start
	/Users/yuan.chen/GolandProjects/src/volcano.sh/volcano/vendor/k8s.io/apimachinery/pkg/util/wait/wait.go:69 +0x62

goroutine 96 [select, 2 minutes]:
volcano.sh/volcano/vendor/k8s.io/client-go/tools/cache.(*processorListener).pop(0xc0005a5480)
	/Users/yuan.chen/GolandProjects/src/volcano.sh/volcano/vendor/k8s.io/client-go/tools/cache/shared_informer.go:517 +0x18d
volcano.sh/volcano/vendor/k8s.io/apimachinery/pkg/util/wait.(*Group).Start.func1(0xc0002967d0, 0xc0000ca5d0)
	/Users/yuan.chen/GolandProjects/src/volcano.sh/volcano/vendor/k8s.io/apimachinery/pkg/util/wait/wait.go:71 +0x59
created by volcano.sh/volcano/vendor/k8s.io/apimachinery/pkg/util/wait.(*Group).Start
	/Users/yuan.chen/GolandProjects/src/volcano.sh/volcano/vendor/k8s.io/apimachinery/pkg/util/wait/wait.go:69 +0x62

goroutine 107 [chan receive (nil chan), 2 minutes]:
volcano.sh/volcano/vendor/k8s.io/client-go/tools/cache.(*controller).Run.func1(0x0, 0xc00049ca80)
	/Users/yuan.chen/GolandProjects/src/volcano.sh/volcano/vendor/k8s.io/client-go/tools/cache/controller.go:103 +0x34
created by volcano.sh/volcano/vendor/k8s.io/client-go/tools/cache.(*controller).Run
	/Users/yuan.chen/GolandProjects/src/volcano.sh/volcano/vendor/k8s.io/client-go/tools/cache/controller.go:102 +0xae

goroutine 194 [select, 2 minutes]:
volcano.sh/volcano/vendor/k8s.io/client-go/tools/cache.(*processorListener).pop(0xc0005a5d00)
	/Users/yuan.chen/GolandProjects/src/volcano.sh/volcano/vendor/k8s.io/client-go/tools/cache/shared_informer.go:517 +0x18d
volcano.sh/volcano/vendor/k8s.io/apimachinery/pkg/util/wait.(*Group).Start.func1(0xc000296920, 0xc0000ca5f0)
	/Users/yuan.chen/GolandProjects/src/volcano.sh/volcano/vendor/k8s.io/apimachinery/pkg/util/wait/wait.go:71 +0x59
created by volcano.sh/volcano/vendor/k8s.io/apimachinery/pkg/util/wait.(*Group).Start
	/Users/yuan.chen/GolandProjects/src/volcano.sh/volcano/vendor/k8s.io/apimachinery/pkg/util/wait/wait.go:69 +0x62

goroutine 48 [chan receive, 2 minutes]:
volcano.sh/volcano/vendor/k8s.io/client-go/tools/cache.(*sharedProcessor).run(0xc000296700, 0xc0000c0300)
	/Users/yuan.chen/GolandProjects/src/volcano.sh/volcano/vendor/k8s.io/client-go/tools/cache/shared_informer.go:425 +0x49
volcano.sh/volcano/vendor/k8s.io/apimachinery/pkg/util/wait.(*Group).StartWithChannel.func1()
	/Users/yuan.chen/GolandProjects/src/volcano.sh/volcano/vendor/k8s.io/apimachinery/pkg/util/wait/wait.go:54 +0x2e
volcano.sh/volcano/vendor/k8s.io/apimachinery/pkg/util/wait.(*Group).Start.func1(0xc0000442b0, 0xc000302740)
	/Users/yuan.chen/GolandProjects/src/volcano.sh/volcano/vendor/k8s.io/apimachinery/pkg/util/wait/wait.go:71 +0x59
created by volcano.sh/volcano/vendor/k8s.io/apimachinery/pkg/util/wait.(*Group).Start
	/Users/yuan.chen/GolandProjects/src/volcano.sh/volcano/vendor/k8s.io/apimachinery/pkg/util/wait/wait.go:69 +0x62

goroutine 74 [select, 2 minutes]:
volcano.sh/volcano/vendor/k8s.io/client-go/tools/cache.(*Reflector).watchHandler(0xc0005540a0, 0x23a3860, 0xc0000cccc0, 0xc00095fbe0, 0xc0000aec60, 0x0, 0x0, 0x0)
	/Users/yuan.chen/GolandProjects/src/volcano.sh/volcano/vendor/k8s.io/client-go/tools/cache/reflector.go:283 +0x1ec
volcano.sh/volcano/vendor/k8s.io/client-go/tools/cache.(*Reflector).ListAndWatch(0xc0005540a0, 0x0, 0x0, 0x0)
	/Users/yuan.chen/GolandProjects/src/volcano.sh/volcano/vendor/k8s.io/client-go/tools/cache/reflector.go:254 +0xc73
volcano.sh/volcano/vendor/k8s.io/client-go/tools/cache.(*Reflector).Run.func1()
	/Users/yuan.chen/GolandProjects/src/volcano.sh/volcano/vendor/k8s.io/client-go/tools/cache/reflector.go:124 +0x33
volcano.sh/volcano/vendor/k8s.io/apimachinery/pkg/util/wait.JitterUntil.func1(0xc0003866f0)
	/Users/yuan.chen/GolandProjects/src/volcano.sh/volcano/vendor/k8s.io/apimachinery/pkg/util/wait/wait.go:133 +0x5e
volcano.sh/volcano/vendor/k8s.io/apimachinery/pkg/util/wait.JitterUntil(0xc00095fef0, 0x3b9aca00, 0x0, 0x1, 0x0)
	/Users/yuan.chen/GolandProjects/src/volcano.sh/volcano/vendor/k8s.io/apimachinery/pkg/util/wait/wait.go:134 +0xf8
volcano.sh/volcano/vendor/k8s.io/apimachinery/pkg/util/wait.Until(...)
	/Users/yuan.chen/GolandProjects/src/volcano.sh/volcano/vendor/k8s.io/apimachinery/pkg/util/wait/wait.go:88
volcano.sh/volcano/vendor/k8s.io/client-go/tools/cache.(*Reflector).Run(0xc0005540a0, 0x0)
	/Users/yuan.chen/GolandProjects/src/volcano.sh/volcano/vendor/k8s.io/client-go/tools/cache/reflector.go:123 +0x169
volcano.sh/volcano/vendor/k8s.io/apimachinery/pkg/util/wait.(*Group).StartWithChannel.func1()
	/Users/yuan.chen/GolandProjects/src/volcano.sh/volcano/vendor/k8s.io/apimachinery/pkg/util/wait/wait.go:54 +0x2e
volcano.sh/volcano/vendor/k8s.io/apimachinery/pkg/util/wait.(*Group).Start.func1(0xc0003be1e0, 0xc00016cd00)
	/Users/yuan.chen/GolandProjects/src/volcano.sh/volcano/vendor/k8s.io/apimachinery/pkg/util/wait/wait.go:71 +0x59
created by volcano.sh/volcano/vendor/k8s.io/apimachinery/pkg/util/wait.(*Group).Start
	/Users/yuan.chen/GolandProjects/src/volcano.sh/volcano/vendor/k8s.io/apimachinery/pkg/util/wait/wait.go:69 +0x62

goroutine 196 [select, 2 minutes]:
volcano.sh/volcano/vendor/k8s.io/client-go/tools/cache.(*processorListener).pop(0xc0005a5100)
	/Users/yuan.chen/GolandProjects/src/volcano.sh/volcano/vendor/k8s.io/client-go/tools/cache/shared_informer.go:517 +0x18d
volcano.sh/volcano/vendor/k8s.io/apimachinery/pkg/util/wait.(*Group).Start.func1(0xc0002965a0, 0xc0000ca610)
	/Users/yuan.chen/GolandProjects/src/volcano.sh/volcano/vendor/k8s.io/apimachinery/pkg/util/wait/wait.go:71 +0x59
created by volcano.sh/volcano/vendor/k8s.io/apimachinery/pkg/util/wait.(*Group).Start
	/Users/yuan.chen/GolandProjects/src/volcano.sh/volcano/vendor/k8s.io/apimachinery/pkg/util/wait/wait.go:69 +0x62

goroutine 49 [chan receive (nil chan), 2 minutes]:
volcano.sh/volcano/vendor/k8s.io/client-go/tools/cache.(*controller).Run.func1(0x0, 0xc00043ee80)
	/Users/yuan.chen/GolandProjects/src/volcano.sh/volcano/vendor/k8s.io/client-go/tools/cache/controller.go:103 +0x34
created by volcano.sh/volcano/vendor/k8s.io/client-go/tools/cache.(*controller).Run
	/Users/yuan.chen/GolandProjects/src/volcano.sh/volcano/vendor/k8s.io/client-go/tools/cache/controller.go:102 +0xae

goroutine 119 [chan receive, 2 minutes]:
volcano.sh/volcano/vendor/k8s.io/client-go/tools/cache.(*processorListener).run.func1.1(0x0, 0x10, 0x18)
	/Users/yuan.chen/GolandProjects/src/volcano.sh/volcano/vendor/k8s.io/client-go/tools/cache/shared_informer.go:549 +0x54
volcano.sh/volcano/vendor/k8s.io/apimachinery/pkg/util/wait.ExponentialBackoff(0x989680, 0x3ff0000000000000, 0x3fb999999999999a, 0x5, 0xc00065fdd8, 0x0, 0x0)
	/Users/yuan.chen/GolandProjects/src/volcano.sh/volcano/vendor/k8s.io/apimachinery/pkg/util/wait/wait.go:203 +0xde
volcano.sh/volcano/vendor/k8s.io/client-go/tools/cache.(*processorListener).run.func1()
	/Users/yuan.chen/GolandProjects/src/volcano.sh/volcano/vendor/k8s.io/client-go/tools/cache/shared_informer.go:548 +0x89
volcano.sh/volcano/vendor/k8s.io/apimachinery/pkg/util/wait.JitterUntil.func1(0xc000387740)
	/Users/yuan.chen/GolandProjects/src/volcano.sh/volcano/vendor/k8s.io/apimachinery/pkg/util/wait/wait.go:133 +0x5e
volcano.sh/volcano/vendor/k8s.io/apimachinery/pkg/util/wait.JitterUntil(0xc00065ff40, 0xdf8475800, 0x0, 0xc0003c4001, 0xc0003e60c0)
	/Users/yuan.chen/GolandProjects/src/volcano.sh/volcano/vendor/k8s.io/apimachinery/pkg/util/wait/wait.go:134 +0xf8
volcano.sh/volcano/vendor/k8s.io/apimachinery/pkg/util/wait.Until(...)
	/Users/yuan.chen/GolandProjects/src/volcano.sh/volcano/vendor/k8s.io/apimachinery/pkg/util/wait/wait.go:88
volcano.sh/volcano/vendor/k8s.io/client-go/tools/cache.(*processorListener).run(0xc0005a5280)
	/Users/yuan.chen/GolandProjects/src/volcano.sh/volcano/vendor/k8s.io/client-go/tools/cache/shared_informer.go:546 +0x9b
volcano.sh/volcano/vendor/k8s.io/apimachinery/pkg/util/wait.(*Group).Start.func1(0xc000296760, 0xc0003c41d0)
	/Users/yuan.chen/GolandProjects/src/volcano.sh/volcano/vendor/k8s.io/apimachinery/pkg/util/wait/wait.go:71 +0x59
created by volcano.sh/volcano/vendor/k8s.io/apimachinery/pkg/util/wait.(*Group).Start
	/Users/yuan.chen/GolandProjects/src/volcano.sh/volcano/vendor/k8s.io/apimachinery/pkg/util/wait/wait.go:69 +0x62

goroutine 120 [select, 2 minutes]:
volcano.sh/volcano/vendor/k8s.io/client-go/tools/cache.(*processorListener).pop(0xc0005a5280)
	/Users/yuan.chen/GolandProjects/src/volcano.sh/volcano/vendor/k8s.io/client-go/tools/cache/shared_informer.go:517 +0x18d
volcano.sh/volcano/vendor/k8s.io/apimachinery/pkg/util/wait.(*Group).Start.func1(0xc000296760, 0xc0003c41e0)
	/Users/yuan.chen/GolandProjects/src/volcano.sh/volcano/vendor/k8s.io/apimachinery/pkg/util/wait/wait.go:71 +0x59
created by volcano.sh/volcano/vendor/k8s.io/apimachinery/pkg/util/wait.(*Group).Start
	/Users/yuan.chen/GolandProjects/src/volcano.sh/volcano/vendor/k8s.io/apimachinery/pkg/util/wait/wait.go:69 +0x62

goroutine 121 [chan receive, 2 minutes]:
volcano.sh/volcano/vendor/k8s.io/client-go/tools/cache.(*processorListener).run.func1.1(0x0, 0x10, 0x18)
	/Users/yuan.chen/GolandProjects/src/volcano.sh/volcano/vendor/k8s.io/client-go/tools/cache/shared_informer.go:549 +0x54
volcano.sh/volcano/vendor/k8s.io/apimachinery/pkg/util/wait.ExponentialBackoff(0x989680, 0x3ff0000000000000, 0x3fb999999999999a, 0x5, 0xc000739dd8, 0x0, 0x0)
	/Users/yuan.chen/GolandProjects/src/volcano.sh/volcano/vendor/k8s.io/apimachinery/pkg/util/wait/wait.go:203 +0xde
volcano.sh/volcano/vendor/k8s.io/client-go/tools/cache.(*processorListener).run.func1()
	/Users/yuan.chen/GolandProjects/src/volcano.sh/volcano/vendor/k8s.io/client-go/tools/cache/shared_informer.go:548 +0x89
volcano.sh/volcano/vendor/k8s.io/apimachinery/pkg/util/wait.JitterUntil.func1(0xc000387740)
	/Users/yuan.chen/GolandProjects/src/volcano.sh/volcano/vendor/k8s.io/apimachinery/pkg/util/wait/wait.go:133 +0x5e
volcano.sh/volcano/vendor/k8s.io/apimachinery/pkg/util/wait.JitterUntil(0xc000739f40, 0xdf8475800, 0x0, 0xc0003c4001, 0xc0003e6120)
	/Users/yuan.chen/GolandProjects/src/volcano.sh/volcano/vendor/k8s.io/apimachinery/pkg/util/wait/wait.go:134 +0xf8
volcano.sh/volcano/vendor/k8s.io/apimachinery/pkg/util/wait.Until(...)
	/Users/yuan.chen/GolandProjects/src/volcano.sh/volcano/vendor/k8s.io/apimachinery/pkg/util/wait/wait.go:88
volcano.sh/volcano/vendor/k8s.io/client-go/tools/cache.(*processorListener).run(0xc0005a5600)
	/Users/yuan.chen/GolandProjects/src/volcano.sh/volcano/vendor/k8s.io/client-go/tools/cache/shared_informer.go:546 +0x9b
volcano.sh/volcano/vendor/k8s.io/apimachinery/pkg/util/wait.(*Group).Start.func1(0xc000296840, 0xc0003c41f0)
	/Users/yuan.chen/GolandProjects/src/volcano.sh/volcano/vendor/k8s.io/apimachinery/pkg/util/wait/wait.go:71 +0x59
created by volcano.sh/volcano/vendor/k8s.io/apimachinery/pkg/util/wait.(*Group).Start
	/Users/yuan.chen/GolandProjects/src/volcano.sh/volcano/vendor/k8s.io/apimachinery/pkg/util/wait/wait.go:69 +0x62

goroutine 122 [select, 2 minutes]:
volcano.sh/volcano/vendor/k8s.io/client-go/tools/cache.(*processorListener).pop(0xc0005a5600)
	/Users/yuan.chen/GolandProjects/src/volcano.sh/volcano/vendor/k8s.io/client-go/tools/cache/shared_informer.go:517 +0x18d
volcano.sh/volcano/vendor/k8s.io/apimachinery/pkg/util/wait.(*Group).Start.func1(0xc000296840, 0xc0003c4200)
	/Users/yuan.chen/GolandProjects/src/volcano.sh/volcano/vendor/k8s.io/apimachinery/pkg/util/wait/wait.go:71 +0x59
created by volcano.sh/volcano/vendor/k8s.io/apimachinery/pkg/util/wait.(*Group).Start
	/Users/yuan.chen/GolandProjects/src/volcano.sh/volcano/vendor/k8s.io/apimachinery/pkg/util/wait/wait.go:69 +0x62

goroutine 108 [select, 2 minutes]:
volcano.sh/volcano/vendor/k8s.io/client-go/tools/cache.(*Reflector).watchHandler(0xc0004640a0, 0x23a3860, 0xc000a18030, 0xc00095bbe0, 0xc0003a76e0, 0x0, 0x0, 0x0)
	/Users/yuan.chen/GolandProjects/src/volcano.sh/volcano/vendor/k8s.io/client-go/tools/cache/reflector.go:283 +0x1ec
volcano.sh/volcano/vendor/k8s.io/client-go/tools/cache.(*Reflector).ListAndWatch(0xc0004640a0, 0x0, 0x0, 0x0)
	/Users/yuan.chen/GolandProjects/src/volcano.sh/volcano/vendor/k8s.io/client-go/tools/cache/reflector.go:254 +0xc73
volcano.sh/volcano/vendor/k8s.io/client-go/tools/cache.(*Reflector).Run.func1()
	/Users/yuan.chen/GolandProjects/src/volcano.sh/volcano/vendor/k8s.io/client-go/tools/cache/reflector.go:124 +0x33
volcano.sh/volcano/vendor/k8s.io/apimachinery/pkg/util/wait.JitterUntil.func1(0xc0005e5ef0)
	/Users/yuan.chen/GolandProjects/src/volcano.sh/volcano/vendor/k8s.io/apimachinery/pkg/util/wait/wait.go:133 +0x5e
volcano.sh/volcano/vendor/k8s.io/apimachinery/pkg/util/wait.JitterUntil(0xc00095bef0, 0x3b9aca00, 0x0, 0x1, 0x0)
	/Users/yuan.chen/GolandProjects/src/volcano.sh/volcano/vendor/k8s.io/apimachinery/pkg/util/wait/wait.go:134 +0xf8
volcano.sh/volcano/vendor/k8s.io/apimachinery/pkg/util/wait.Until(...)
	/Users/yuan.chen/GolandProjects/src/volcano.sh/volcano/vendor/k8s.io/apimachinery/pkg/util/wait/wait.go:88
volcano.sh/volcano/vendor/k8s.io/client-go/tools/cache.(*Reflector).Run(0xc0004640a0, 0x0)
	/Users/yuan.chen/GolandProjects/src/volcano.sh/volcano/vendor/k8s.io/client-go/tools/cache/reflector.go:123 +0x169
volcano.sh/volcano/vendor/k8s.io/apimachinery/pkg/util/wait.(*Group).StartWithChannel.func1()
	/Users/yuan.chen/GolandProjects/src/volcano.sh/volcano/vendor/k8s.io/apimachinery/pkg/util/wait/wait.go:54 +0x2e
volcano.sh/volcano/vendor/k8s.io/apimachinery/pkg/util/wait.(*Group).Start.func1(0xc0005981f0, 0xc00011e820)
	/Users/yuan.chen/GolandProjects/src/volcano.sh/volcano/vendor/k8s.io/apimachinery/pkg/util/wait/wait.go:71 +0x59
created by volcano.sh/volcano/vendor/k8s.io/apimachinery/pkg/util/wait.(*Group).Start
	/Users/yuan.chen/GolandProjects/src/volcano.sh/volcano/vendor/k8s.io/apimachinery/pkg/util/wait/wait.go:69 +0x62

goroutine 210 [select, 2 minutes]:
volcano.sh/volcano/vendor/k8s.io/client-go/tools/cache.(*Reflector).watchHandler(0xc0005fe0a0, 0x23a3860, 0xc0009b82a0, 0xc0008efbe0, 0xc0001594a0, 0x0, 0x0, 0x0)
	/Users/yuan.chen/GolandProjects/src/volcano.sh/volcano/vendor/k8s.io/client-go/tools/cache/reflector.go:283 +0x1ec
volcano.sh/volcano/vendor/k8s.io/client-go/tools/cache.(*Reflector).ListAndWatch(0xc0005fe0a0, 0x0, 0x0, 0x0)
	/Users/yuan.chen/GolandProjects/src/volcano.sh/volcano/vendor/k8s.io/client-go/tools/cache/reflector.go:254 +0xc73
volcano.sh/volcano/vendor/k8s.io/client-go/tools/cache.(*Reflector).Run.func1()
	/Users/yuan.chen/GolandProjects/src/volcano.sh/volcano/vendor/k8s.io/client-go/tools/cache/reflector.go:124 +0x33
volcano.sh/volcano/vendor/k8s.io/apimachinery/pkg/util/wait.JitterUntil.func1(0xc0003896f0)
	/Users/yuan.chen/GolandProjects/src/volcano.sh/volcano/vendor/k8s.io/apimachinery/pkg/util/wait/wait.go:133 +0x5e
volcano.sh/volcano/vendor/k8s.io/apimachinery/pkg/util/wait.JitterUntil(0xc0008efef0, 0x3b9aca00, 0x0, 0x1, 0x0)
	/Users/yuan.chen/GolandProjects/src/volcano.sh/volcano/vendor/k8s.io/apimachinery/pkg/util/wait/wait.go:134 +0xf8
volcano.sh/volcano/vendor/k8s.io/apimachinery/pkg/util/wait.Until(...)
	/Users/yuan.chen/GolandProjects/src/volcano.sh/volcano/vendor/k8s.io/apimachinery/pkg/util/wait/wait.go:88
volcano.sh/volcano/vendor/k8s.io/client-go/tools/cache.(*Reflector).Run(0xc0005fe0a0, 0x0)
	/Users/yuan.chen/GolandProjects/src/volcano.sh/volcano/vendor/k8s.io/client-go/tools/cache/reflector.go:123 +0x169
volcano.sh/volcano/vendor/k8s.io/apimachinery/pkg/util/wait.(*Group).StartWithChannel.func1()
	/Users/yuan.chen/GolandProjects/src/volcano.sh/volcano/vendor/k8s.io/apimachinery/pkg/util/wait/wait.go:54 +0x2e
volcano.sh/volcano/vendor/k8s.io/apimachinery/pkg/util/wait.(*Group).Start.func1(0xc000044560, 0xc0003028a0)
	/Users/yuan.chen/GolandProjects/src/volcano.sh/volcano/vendor/k8s.io/apimachinery/pkg/util/wait/wait.go:71 +0x59
created by volcano.sh/volcano/vendor/k8s.io/apimachinery/pkg/util/wait.(*Group).Start
	/Users/yuan.chen/GolandProjects/src/volcano.sh/volcano/vendor/k8s.io/apimachinery/pkg/util/wait/wait.go:69 +0x62

goroutine 110 [select, 2 minutes]:
volcano.sh/volcano/vendor/k8s.io/client-go/tools/cache.(*Reflector).ListAndWatch.func1(0xc0005fe0a0, 0x0, 0xc0001d7980, 0xc0001594a0)
	/Users/yuan.chen/GolandProjects/src/volcano.sh/volcano/vendor/k8s.io/client-go/tools/cache/reflector.go:194 +0x178
created by volcano.sh/volcano/vendor/k8s.io/client-go/tools/cache.(*Reflector).ListAndWatch
	/Users/yuan.chen/GolandProjects/src/volcano.sh/volcano/vendor/k8s.io/client-go/tools/cache/reflector.go:188 +0x6fb

goroutine 179 [select, 2 minutes]:
volcano.sh/volcano/vendor/k8s.io/client-go/tools/cache.(*Reflector).ListAndWatch.func1(0xc000321360, 0x0, 0xc000130240, 0xc000158b40)
	/Users/yuan.chen/GolandProjects/src/volcano.sh/volcano/vendor/k8s.io/client-go/tools/cache/reflector.go:194 +0x178
created by volcano.sh/volcano/vendor/k8s.io/client-go/tools/cache.(*Reflector).ListAndWatch
	/Users/yuan.chen/GolandProjects/src/volcano.sh/volcano/vendor/k8s.io/client-go/tools/cache/reflector.go:188 +0x6fb

goroutine 128 [sync.Cond.Wait, 2 minutes]:
runtime.goparkunlock(...)
	/usr/local/opt/go/libexec/src/runtime/proc.go:310
sync.runtime_notifyListWait(0xc0003fa400, 0x0)
	/usr/local/opt/go/libexec/src/runtime/sema.go:510 +0xf8
sync.(*Cond).Wait(0xc0003fa3f0)
	/usr/local/opt/go/libexec/src/sync/cond.go:56 +0x9d
volcano.sh/volcano/vendor/golang.org/x/net/http2.(*pipe).Read(0xc0003fa3e8, 0xc0009d4200, 0x200, 0x200, 0x0, 0x0, 0x0)
	/Users/yuan.chen/GolandProjects/src/volcano.sh/volcano/vendor/golang.org/x/net/http2/pipe.go:64 +0xa6
volcano.sh/volcano/vendor/golang.org/x/net/http2.transportResponseBody.Read(0xc0003fa3c0, 0xc0009d4200, 0x200, 0x200, 0x0, 0x0, 0x0)
	/Users/yuan.chen/GolandProjects/src/volcano.sh/volcano/vendor/golang.org/x/net/http2/transport.go:1952 +0xac
encoding/json.(*Decoder).refill(0xc000754420, 0xc0009be080, 0x100ef32)
	/usr/local/opt/go/libexec/src/encoding/json/stream.go:161 +0xeb
encoding/json.(*Decoder).readValue(0xc000754420, 0x0, 0x0, 0x1fbf8c0)
	/usr/local/opt/go/libexec/src/encoding/json/stream.go:136 +0x1dc
encoding/json.(*Decoder).Decode(0xc000754420, 0x1fd7a80, 0xc0009be080, 0xc0001d68a0, 0xc0005e9d30)
	/usr/local/opt/go/libexec/src/encoding/json/stream.go:63 +0x79
volcano.sh/volcano/vendor/k8s.io/apimachinery/pkg/util/framer.(*jsonFrameReader).Read(0xc0009b8120, 0xc0009bc400, 0x400, 0x400, 0x0, 0x0, 0x38)
	/Users/yuan.chen/GolandProjects/src/volcano.sh/volcano/vendor/k8s.io/apimachinery/pkg/util/framer/framer.go:150 +0x1a1
volcano.sh/volcano/vendor/k8s.io/apimachinery/pkg/runtime/serializer/streaming.(*decoder).Decode(0xc000188320, 0x0, 0x23a32e0, 0xc0009c40c0, 0x10, 0xc000333790, 0x18, 0xc0005e9df8, 0x13a6000)
	/Users/yuan.chen/GolandProjects/src/volcano.sh/volcano/vendor/k8s.io/apimachinery/pkg/runtime/serializer/streaming/streaming.go:77 +0x89
volcano.sh/volcano/vendor/k8s.io/client-go/rest/watch.(*Decoder).Decode(0xc0009be060, 0xc000333790, 0xc00009e400, 0x33931f0, 0x0, 0xdf8475800, 0x14eab96)
	/Users/yuan.chen/GolandProjects/src/volcano.sh/volcano/vendor/k8s.io/client-go/rest/watch/decoder.go:49 +0x7c
volcano.sh/volcano/vendor/k8s.io/apimachinery/pkg/watch.(*StreamWatcher).receive(0xc0009b8150)
	/Users/yuan.chen/GolandProjects/src/volcano.sh/volcano/vendor/k8s.io/apimachinery/pkg/watch/streamwatcher.go:93 +0x175
created by volcano.sh/volcano/vendor/k8s.io/apimachinery/pkg/watch.NewStreamWatcher
	/Users/yuan.chen/GolandProjects/src/volcano.sh/volcano/vendor/k8s.io/apimachinery/pkg/watch/streamwatcher.go:60 +0x9f

goroutine 75 [select, 2 minutes]:
volcano.sh/volcano/vendor/k8s.io/client-go/tools/cache.(*Reflector).ListAndWatch.func1(0xc000350000, 0x0, 0xc0003845a0, 0xc0003b2600)
	/Users/yuan.chen/GolandProjects/src/volcano.sh/volcano/vendor/k8s.io/client-go/tools/cache/reflector.go:194 +0x178
created by volcano.sh/volcano/vendor/k8s.io/client-go/tools/cache.(*Reflector).ListAndWatch
	/Users/yuan.chen/GolandProjects/src/volcano.sh/volcano/vendor/k8s.io/client-go/tools/cache/reflector.go:188 +0x6fb

goroutine 168 [select, 2 minutes]:
volcano.sh/volcano/vendor/k8s.io/client-go/tools/cache.(*Reflector).ListAndWatch.func1(0xc000321400, 0x0, 0xc0001d7680, 0xc000565860)
	/Users/yuan.chen/GolandProjects/src/volcano.sh/volcano/vendor/k8s.io/client-go/tools/cache/reflector.go:194 +0x178
created by volcano.sh/volcano/vendor/k8s.io/client-go/tools/cache.(*Reflector).ListAndWatch
	/Users/yuan.chen/GolandProjects/src/volcano.sh/volcano/vendor/k8s.io/client-go/tools/cache/reflector.go:188 +0x6fb

goroutine 198 [select, 2 minutes]:
volcano.sh/volcano/vendor/k8s.io/client-go/tools/cache.(*Reflector).ListAndWatch.func1(0xc0005540a0, 0x0, 0xc0003403c0, 0xc0000aec60)
	/Users/yuan.chen/GolandProjects/src/volcano.sh/volcano/vendor/k8s.io/client-go/tools/cache/reflector.go:194 +0x178
created by volcano.sh/volcano/vendor/k8s.io/client-go/tools/cache.(*Reflector).ListAndWatch
	/Users/yuan.chen/GolandProjects/src/volcano.sh/volcano/vendor/k8s.io/client-go/tools/cache/reflector.go:188 +0x6fb

goroutine 212 [sync.Cond.Wait, 2 minutes]:
runtime.goparkunlock(...)
	/usr/local/opt/go/libexec/src/runtime/proc.go:310
sync.runtime_notifyListWait(0xc0003fa7c0, 0x0)
	/usr/local/opt/go/libexec/src/runtime/sema.go:510 +0xf8
sync.(*Cond).Wait(0xc0003fa7b0)
	/usr/local/opt/go/libexec/src/sync/cond.go:56 +0x9d
volcano.sh/volcano/vendor/golang.org/x/net/http2.(*pipe).Read(0xc0003fa7a8, 0xc000780400, 0x200, 0x200, 0x0, 0x0, 0x0)
	/Users/yuan.chen/GolandProjects/src/volcano.sh/volcano/vendor/golang.org/x/net/http2/pipe.go:64 +0xa6
volcano.sh/volcano/vendor/golang.org/x/net/http2.transportResponseBody.Read(0xc0003fa780, 0xc000780400, 0x200, 0x200, 0x0, 0x0, 0x0)
	/Users/yuan.chen/GolandProjects/src/volcano.sh/volcano/vendor/golang.org/x/net/http2/transport.go:1952 +0xac
encoding/json.(*Decoder).refill(0xc00010e160, 0xc0003d21c0, 0x0)
	/usr/local/opt/go/libexec/src/encoding/json/stream.go:161 +0xeb
encoding/json.(*Decoder).readValue(0xc00010e160, 0x0, 0x0, 0x1fbf8c0)
	/usr/local/opt/go/libexec/src/encoding/json/stream.go:136 +0x1dc
encoding/json.(*Decoder).Decode(0xc00010e160, 0x1fd7a80, 0xc0003d21c0, 0x339a998, 0xc)
	/usr/local/opt/go/libexec/src/encoding/json/stream.go:63 +0x79
volcano.sh/volcano/vendor/k8s.io/apimachinery/pkg/util/framer.(*jsonFrameReader).Read(0xc0000cc870, 0xc00013f400, 0x400, 0x400, 0x2d2d2d0a3d3d5101, 0x120444e452d2d, 0x38)
	/Users/yuan.chen/GolandProjects/src/volcano.sh/volcano/vendor/k8s.io/apimachinery/pkg/util/framer/framer.go:150 +0x1a1
volcano.sh/volcano/vendor/k8s.io/apimachinery/pkg/runtime/serializer/streaming.(*decoder).Decode(0xc000842050, 0x0, 0x23a32e0, 0xc00004c300, 0x0, 0x0, 0x0, 0x0, 0x0)
	/Users/yuan.chen/GolandProjects/src/volcano.sh/volcano/vendor/k8s.io/apimachinery/pkg/runtime/serializer/streaming/streaming.go:77 +0x89
volcano.sh/volcano/vendor/k8s.io/client-go/rest/watch.(*Decoder).Decode(0xc0003d2180, 0x0, 0x0, 0x0, 0x0, 0x0, 0x14eab96)
	/Users/yuan.chen/GolandProjects/src/volcano.sh/volcano/vendor/k8s.io/client-go/rest/watch/decoder.go:49 +0x7c
volcano.sh/volcano/vendor/k8s.io/apimachinery/pkg/watch.(*StreamWatcher).receive(0xc0000cccc0)
	/Users/yuan.chen/GolandProjects/src/volcano.sh/volcano/vendor/k8s.io/apimachinery/pkg/watch/streamwatcher.go:93 +0x175
created by volcano.sh/volcano/vendor/k8s.io/apimachinery/pkg/watch.NewStreamWatcher
	/Users/yuan.chen/GolandProjects/src/volcano.sh/volcano/vendor/k8s.io/apimachinery/pkg/watch/streamwatcher.go:60 +0x9f

goroutine 170 [select, 2 minutes]:
volcano.sh/volcano/vendor/k8s.io/client-go/tools/cache.(*Reflector).ListAndWatch.func1(0xc00030a0a0, 0x0, 0xc0003b8ae0, 0xc0003a6c60)
	/Users/yuan.chen/GolandProjects/src/volcano.sh/volcano/vendor/k8s.io/client-go/tools/cache/reflector.go:194 +0x178
created by volcano.sh/volcano/vendor/k8s.io/client-go/tools/cache.(*Reflector).ListAndWatch
	/Users/yuan.chen/GolandProjects/src/volcano.sh/volcano/vendor/k8s.io/client-go/tools/cache/reflector.go:188 +0x6fb

goroutine 76 [select, 2 minutes]:
volcano.sh/volcano/vendor/k8s.io/client-go/tools/cache.(*Reflector).ListAndWatch.func1(0xc000464000, 0x0, 0xc000340c60, 0xc0000aef60)
	/Users/yuan.chen/GolandProjects/src/volcano.sh/volcano/vendor/k8s.io/client-go/tools/cache/reflector.go:194 +0x178
created by volcano.sh/volcano/vendor/k8s.io/client-go/tools/cache.(*Reflector).ListAndWatch
	/Users/yuan.chen/GolandProjects/src/volcano.sh/volcano/vendor/k8s.io/client-go/tools/cache/reflector.go:188 +0x6fb

goroutine 29 [sync.Cond.Wait, 2 minutes]:
runtime.goparkunlock(...)
	/usr/local/opt/go/libexec/src/runtime/proc.go:310
sync.runtime_notifyListWait(0xc0001cae00, 0x0)
	/usr/local/opt/go/libexec/src/runtime/sema.go:510 +0xf8
sync.(*Cond).Wait(0xc0001cadf0)
	/usr/local/opt/go/libexec/src/sync/cond.go:56 +0x9d
volcano.sh/volcano/vendor/golang.org/x/net/http2.(*pipe).Read(0xc0001cade8, 0xc00077e000, 0x200, 0x200, 0x0, 0x0, 0x0)
	/Users/yuan.chen/GolandProjects/src/volcano.sh/volcano/vendor/golang.org/x/net/http2/pipe.go:64 +0xa6
volcano.sh/volcano/vendor/golang.org/x/net/http2.transportResponseBody.Read(0xc0001cadc0, 0xc00077e000, 0x200, 0x200, 0x0, 0x0, 0x0)
	/Users/yuan.chen/GolandProjects/src/volcano.sh/volcano/vendor/golang.org/x/net/http2/transport.go:1952 +0xac
encoding/json.(*Decoder).refill(0xc0002da420, 0xc00011e320, 0x0)
	/usr/local/opt/go/libexec/src/encoding/json/stream.go:161 +0xeb
encoding/json.(*Decoder).readValue(0xc0002da420, 0x0, 0x0, 0x1fbf8c0)
	/usr/local/opt/go/libexec/src/encoding/json/stream.go:136 +0x1dc
encoding/json.(*Decoder).Decode(0xc0002da420, 0x1fd7a80, 0xc00011e320, 0x339c538, 0x4)
	/usr/local/opt/go/libexec/src/encoding/json/stream.go:63 +0x79
volcano.sh/volcano/vendor/k8s.io/apimachinery/pkg/util/framer.(*jsonFrameReader).Read(0xc0008c4000, 0xc000382400, 0x400, 0x400, 0x4e5466656e396401, 0x16c614b7a352b, 0x38)
	/Users/yuan.chen/GolandProjects/src/volcano.sh/volcano/vendor/k8s.io/apimachinery/pkg/util/framer/framer.go:150 +0x1a1
volcano.sh/volcano/vendor/k8s.io/apimachinery/pkg/runtime/serializer/streaming.(*decoder).Decode(0xc00081e0a0, 0x0, 0x23a32e0, 0xc000106100, 0x45623174327a7537, 0x57575774616e6472, 0x59496c4c662b4c61, 0x2f344e576b747572, 0x56674e427367676a)
	/Users/yuan.chen/GolandProjects/src/volcano.sh/volcano/vendor/k8s.io/apimachinery/pkg/runtime/serializer/streaming/streaming.go:77 +0x89
volcano.sh/volcano/vendor/k8s.io/client-go/rest/watch.(*Decoder).Decode(0xc00011e2e0, 0x682f766676555044, 0x77764e4439354c77, 0x6c6a61384e6b6349, 0x6239774a6a7a7576, 0x455967434d664f36, 0x14eab96)
	/Users/yuan.chen/GolandProjects/src/volcano.sh/volcano/vendor/k8s.io/client-go/rest/watch/decoder.go:49 +0x7c
volcano.sh/volcano/vendor/k8s.io/apimachinery/pkg/watch.(*StreamWatcher).receive(0xc0008c4030)
	/Users/yuan.chen/GolandProjects/src/volcano.sh/volcano/vendor/k8s.io/apimachinery/pkg/watch/streamwatcher.go:93 +0x175
created by volcano.sh/volcano/vendor/k8s.io/apimachinery/pkg/watch.NewStreamWatcher
	/Users/yuan.chen/GolandProjects/src/volcano.sh/volcano/vendor/k8s.io/apimachinery/pkg/watch/streamwatcher.go:60 +0x9f

goroutine 171 [select, 2 minutes]:
volcano.sh/volcano/vendor/k8s.io/client-go/tools/cache.(*Reflector).ListAndWatch.func1(0xc0003f2000, 0x0, 0xc0003b90e0, 0xc0003a71a0)
	/Users/yuan.chen/GolandProjects/src/volcano.sh/volcano/vendor/k8s.io/client-go/tools/cache/reflector.go:194 +0x178
created by volcano.sh/volcano/vendor/k8s.io/client-go/tools/cache.(*Reflector).ListAndWatch
	/Users/yuan.chen/GolandProjects/src/volcano.sh/volcano/vendor/k8s.io/client-go/tools/cache/reflector.go:188 +0x6fb

goroutine 213 [sync.Cond.Wait, 2 minutes]:
runtime.goparkunlock(...)
	/usr/local/opt/go/libexec/src/runtime/proc.go:310
sync.runtime_notifyListWait(0xc00077c180, 0x0)
	/usr/local/opt/go/libexec/src/runtime/sema.go:510 +0xf8
sync.(*Cond).Wait(0xc00077c170)
	/usr/local/opt/go/libexec/src/sync/cond.go:56 +0x9d
volcano.sh/volcano/vendor/golang.org/x/net/http2.(*pipe).Read(0xc00077c168, 0xc000780600, 0x200, 0x200, 0x0, 0x0, 0x0)
	/Users/yuan.chen/GolandProjects/src/volcano.sh/volcano/vendor/golang.org/x/net/http2/pipe.go:64 +0xa6
volcano.sh/volcano/vendor/golang.org/x/net/http2.transportResponseBody.Read(0xc00077c140, 0xc000780600, 0x200, 0x200, 0x0, 0x0, 0x0)
	/Users/yuan.chen/GolandProjects/src/volcano.sh/volcano/vendor/golang.org/x/net/http2/transport.go:1952 +0xac
encoding/json.(*Decoder).refill(0xc00010e420, 0xc0003d2240, 0x0)
	/usr/local/opt/go/libexec/src/encoding/json/stream.go:161 +0xeb
encoding/json.(*Decoder).readValue(0xc00010e420, 0x0, 0x0, 0x1fbf8c0)
	/usr/local/opt/go/libexec/src/encoding/json/stream.go:136 +0x1dc
encoding/json.(*Decoder).Decode(0xc00010e420, 0x1fd7a80, 0xc0003d2240, 0x0, 0x0)
	/usr/local/opt/go/libexec/src/encoding/json/stream.go:63 +0x79
volcano.sh/volcano/vendor/k8s.io/apimachinery/pkg/util/framer.(*jsonFrameReader).Read(0xc0000cccf0, 0xc00013f800, 0x400, 0x400, 0x0, 0x0, 0x38)
	/Users/yuan.chen/GolandProjects/src/volcano.sh/volcano/vendor/k8s.io/apimachinery/pkg/util/framer/framer.go:150 +0x1a1
volcano.sh/volcano/vendor/k8s.io/apimachinery/pkg/runtime/serializer/streaming.(*decoder).Decode(0xc0008420a0, 0x0, 0x23a32e0, 0xc00004c340, 0x4745422d2d2d2d2d, 0x5020415352204e49, 0x4b20455441564952, 0xa2d2d2d2d2d5945, 0x4249676f4549494d)
	/Users/yuan.chen/GolandProjects/src/volcano.sh/volcano/vendor/k8s.io/apimachinery/pkg/runtime/serializer/streaming/streaming.go:77 +0x89
volcano.sh/volcano/vendor/k8s.io/client-go/rest/watch.(*Decoder).Decode(0xc0003d2200, 0x685872565735564f, 0x746346794d4e7476, 0x6a656f6748325a77, 0x4c56556a6c773853, 0x5530336676540a44, 0x14eab96)
	/Users/yuan.chen/GolandProjects/src/volcano.sh/volcano/vendor/k8s.io/client-go/rest/watch/decoder.go:49 +0x7c
volcano.sh/volcano/vendor/k8s.io/apimachinery/pkg/watch.(*StreamWatcher).receive(0xc0000ccde0)
	/Users/yuan.chen/GolandProjects/src/volcano.sh/volcano/vendor/k8s.io/apimachinery/pkg/watch/streamwatcher.go:93 +0x175
created by volcano.sh/volcano/vendor/k8s.io/apimachinery/pkg/watch.NewStreamWatcher
	/Users/yuan.chen/GolandProjects/src/volcano.sh/volcano/vendor/k8s.io/apimachinery/pkg/watch/streamwatcher.go:60 +0x9f

goroutine 30 [sync.Cond.Wait, 2 minutes]:
runtime.goparkunlock(...)
	/usr/local/opt/go/libexec/src/runtime/proc.go:310
sync.runtime_notifyListWait(0xc00085c040, 0xa70795500000000)
	/usr/local/opt/go/libexec/src/runtime/sema.go:510 +0xf8
sync.(*Cond).Wait(0xc00085c030)
	/usr/local/opt/go/libexec/src/sync/cond.go:56 +0x9d
volcano.sh/volcano/vendor/golang.org/x/net/http2.(*pipe).Read(0xc00085c028, 0xc00077e200, 0x200, 0x200, 0x0, 0x0, 0x0)
	/Users/yuan.chen/GolandProjects/src/volcano.sh/volcano/vendor/golang.org/x/net/http2/pipe.go:64 +0xa6
volcano.sh/volcano/vendor/golang.org/x/net/http2.transportResponseBody.Read(0xc00085c000, 0xc00077e200, 0x200, 0x200, 0x0, 0x0, 0x0)
	/Users/yuan.chen/GolandProjects/src/volcano.sh/volcano/vendor/golang.org/x/net/http2/transport.go:1952 +0xac
encoding/json.(*Decoder).refill(0xc0002da6e0, 0xc00011e360, 0x0)
	/usr/local/opt/go/libexec/src/encoding/json/stream.go:161 +0xeb
encoding/json.(*Decoder).readValue(0xc0002da6e0, 0x0, 0x0, 0x1fbf8c0)
	/usr/local/opt/go/libexec/src/encoding/json/stream.go:136 +0x1dc
encoding/json.(*Decoder).Decode(0xc0002da6e0, 0x1fd7a80, 0xc00011e360, 0x339c538, 0x4)
	/usr/local/opt/go/libexec/src/encoding/json/stream.go:63 +0x79
volcano.sh/volcano/vendor/k8s.io/apimachinery/pkg/util/framer.(*jsonFrameReader).Read(0xc0008c4060, 0xc000382800, 0x400, 0x400, 0x4e5466656e396401, 0x6c614b7a352b, 0x38)
	/Users/yuan.chen/GolandProjects/src/volcano.sh/volcano/vendor/k8s.io/apimachinery/pkg/util/framer/framer.go:150 +0x1a1
volcano.sh/volcano/vendor/k8s.io/apimachinery/pkg/runtime/serializer/streaming.(*decoder).Decode(0xc00081e0f0, 0x0, 0x23a32e0, 0xc0001061c0, 0x45623174327a7537, 0x57575774616e6472, 0x59496c4c662b4c61, 0x2f344e576b747572, 0x56674e427367676a)
	/Users/yuan.chen/GolandProjects/src/volcano.sh/volcano/vendor/k8s.io/apimachinery/pkg/runtime/serializer/streaming/streaming.go:77 +0x89
volcano.sh/volcano/vendor/k8s.io/client-go/rest/watch.(*Decoder).Decode(0xc00011e340, 0x682f766676555044, 0x77764e4439354c77, 0x6c6a61384e6b6349, 0x6239774a6a7a7576, 0x455967434d664f36, 0x14eab96)
	/Users/yuan.chen/GolandProjects/src/volcano.sh/volcano/vendor/k8s.io/client-go/rest/watch/decoder.go:49 +0x7c
volcano.sh/volcano/vendor/k8s.io/apimachinery/pkg/watch.(*StreamWatcher).receive(0xc0008c4090)
	/Users/yuan.chen/GolandProjects/src/volcano.sh/volcano/vendor/k8s.io/apimachinery/pkg/watch/streamwatcher.go:93 +0x175
created by volcano.sh/volcano/vendor/k8s.io/apimachinery/pkg/watch.NewStreamWatcher
	/Users/yuan.chen/GolandProjects/src/volcano.sh/volcano/vendor/k8s.io/apimachinery/pkg/watch/streamwatcher.go:60 +0x9f

goroutine 182 [select, 2 minutes]:
volcano.sh/volcano/vendor/k8s.io/client-go/tools/cache.(*Reflector).ListAndWatch.func1(0xc0005fe000, 0x0, 0xc0003e6a80, 0xc0002f9b60)
	/Users/yuan.chen/GolandProjects/src/volcano.sh/volcano/vendor/k8s.io/client-go/tools/cache/reflector.go:194 +0x178
created by volcano.sh/volcano/vendor/k8s.io/client-go/tools/cache.(*Reflector).ListAndWatch
	/Users/yuan.chen/GolandProjects/src/volcano.sh/volcano/vendor/k8s.io/client-go/tools/cache/reflector.go:188 +0x6fb

goroutine 31 [select, 2 minutes]:
volcano.sh/volcano/vendor/k8s.io/client-go/tools/cache.(*Reflector).ListAndWatch.func1(0xc000628000, 0x0, 0xc000384cc0, 0xc0003b2f00)
	/Users/yuan.chen/GolandProjects/src/volcano.sh/volcano/vendor/k8s.io/client-go/tools/cache/reflector.go:194 +0x178
created by volcano.sh/volcano/vendor/k8s.io/client-go/tools/cache.(*Reflector).ListAndWatch
	/Users/yuan.chen/GolandProjects/src/volcano.sh/volcano/vendor/k8s.io/client-go/tools/cache/reflector.go:188 +0x6fb

goroutine 180 [select, 2 minutes]:
volcano.sh/volcano/vendor/k8s.io/client-go/tools/cache.(*Reflector).ListAndWatch.func1(0xc000554000, 0x0, 0xc0003e6cc0, 0xc0002f9d40)
	/Users/yuan.chen/GolandProjects/src/volcano.sh/volcano/vendor/k8s.io/client-go/tools/cache/reflector.go:194 +0x178
created by volcano.sh/volcano/vendor/k8s.io/client-go/tools/cache.(*Reflector).ListAndWatch
	/Users/yuan.chen/GolandProjects/src/volcano.sh/volcano/vendor/k8s.io/client-go/tools/cache/reflector.go:188 +0x6fb

goroutine 172 [select, 2 minutes]:
volcano.sh/volcano/vendor/k8s.io/client-go/tools/cache.(*Reflector).ListAndWatch.func1(0xc0004640a0, 0x0, 0xc0003b9680, 0xc0003a76e0)
	/Users/yuan.chen/GolandProjects/src/volcano.sh/volcano/vendor/k8s.io/client-go/tools/cache/reflector.go:194 +0x178
created by volcano.sh/volcano/vendor/k8s.io/client-go/tools/cache.(*Reflector).ListAndWatch
	/Users/yuan.chen/GolandProjects/src/volcano.sh/volcano/vendor/k8s.io/client-go/tools/cache/reflector.go:188 +0x6fb

goroutine 181 [sync.Cond.Wait, 2 minutes]:
runtime.goparkunlock(...)
	/usr/local/opt/go/libexec/src/runtime/proc.go:310
sync.runtime_notifyListWait(0xc000142540, 0x0)
	/usr/local/opt/go/libexec/src/runtime/sema.go:510 +0xf8
sync.(*Cond).Wait(0xc000142530)
	/usr/local/opt/go/libexec/src/sync/cond.go:56 +0x9d
volcano.sh/volcano/vendor/golang.org/x/net/http2.(*pipe).Read(0xc000142528, 0xc000784200, 0x200, 0x200, 0x0, 0x0, 0x0)
	/Users/yuan.chen/GolandProjects/src/volcano.sh/volcano/vendor/golang.org/x/net/http2/pipe.go:64 +0xa6
volcano.sh/volcano/vendor/golang.org/x/net/http2.transportResponseBody.Read(0xc000142500, 0xc000784200, 0x200, 0x200, 0x0, 0x0, 0x0)
	/Users/yuan.chen/GolandProjects/src/volcano.sh/volcano/vendor/golang.org/x/net/http2/transport.go:1952 +0xac
encoding/json.(*Decoder).refill(0xc000631340, 0xc0008c7e80, 0x0)
	/usr/local/opt/go/libexec/src/encoding/json/stream.go:161 +0xeb
encoding/json.(*Decoder).readValue(0xc000631340, 0x0, 0x0, 0x1fbf8c0)
	/usr/local/opt/go/libexec/src/encoding/json/stream.go:136 +0x1dc
encoding/json.(*Decoder).Decode(0xc000631340, 0x1fd7a80, 0xc0008c7e80, 0x339c538, 0x4)
	/usr/local/opt/go/libexec/src/encoding/json/stream.go:63 +0x79
volcano.sh/volcano/vendor/k8s.io/apimachinery/pkg/util/framer.(*jsonFrameReader).Read(0xc0008d11d0, 0xc00094e400, 0x400, 0x400, 0x4e5466656e396401, 0x6c614b7a352b, 0x38)
	/Users/yuan.chen/GolandProjects/src/volcano.sh/volcano/vendor/k8s.io/apimachinery/pkg/util/framer/framer.go:150 +0x1a1
volcano.sh/volcano/vendor/k8s.io/apimachinery/pkg/runtime/serializer/streaming.(*decoder).Decode(0xc0007984b0, 0x0, 0x23a32e0, 0xc0000bf100, 0x45623174327a7537, 0x57575774616e6472, 0x59496c4c662b4c61, 0x2f344e576b747572, 0x56674e427367676a)
	/Users/yuan.chen/GolandProjects/src/volcano.sh/volcano/vendor/k8s.io/apimachinery/pkg/runtime/serializer/streaming/streaming.go:77 +0x89
volcano.sh/volcano/vendor/k8s.io/client-go/rest/watch.(*Decoder).Decode(0xc0008c7e60, 0x682f766676555044, 0x77764e4439354c77, 0x6c6a61384e6b6349, 0x6239774a6a7a7576, 0x455967434d664f36, 0x14eab96)
	/Users/yuan.chen/GolandProjects/src/volcano.sh/volcano/vendor/k8s.io/client-go/rest/watch/decoder.go:49 +0x7c
volcano.sh/volcano/vendor/k8s.io/apimachinery/pkg/watch.(*StreamWatcher).receive(0xc0008d1200)
	/Users/yuan.chen/GolandProjects/src/volcano.sh/volcano/vendor/k8s.io/apimachinery/pkg/watch/streamwatcher.go:93 +0x175
created by volcano.sh/volcano/vendor/k8s.io/apimachinery/pkg/watch.NewStreamWatcher
	/Users/yuan.chen/GolandProjects/src/volcano.sh/volcano/vendor/k8s.io/apimachinery/pkg/watch/streamwatcher.go:60 +0x9f

goroutine 126 [sync.Cond.Wait, 2 minutes]:
runtime.goparkunlock(...)
	/usr/local/opt/go/libexec/src/runtime/proc.go:310
sync.runtime_notifyListWait(0xc00077c040, 0x0)
	/usr/local/opt/go/libexec/src/runtime/sema.go:510 +0xf8
sync.(*Cond).Wait(0xc00077c030)
	/usr/local/opt/go/libexec/src/sync/cond.go:56 +0x9d
volcano.sh/volcano/vendor/golang.org/x/net/http2.(*pipe).Read(0xc00077c028, 0xc0009d4000, 0x200, 0x200, 0x0, 0x0, 0x0)
	/Users/yuan.chen/GolandProjects/src/volcano.sh/volcano/vendor/golang.org/x/net/http2/pipe.go:64 +0xa6
volcano.sh/volcano/vendor/golang.org/x/net/http2.transportResponseBody.Read(0xc00077c000, 0xc0009d4000, 0x200, 0x200, 0x0, 0x0, 0x0)
	/Users/yuan.chen/GolandProjects/src/volcano.sh/volcano/vendor/golang.org/x/net/http2/transport.go:1952 +0xac
encoding/json.(*Decoder).refill(0xc000754000, 0xc0009be020, 0x40010000000000)
	/usr/local/opt/go/libexec/src/encoding/json/stream.go:161 +0xeb
encoding/json.(*Decoder).readValue(0xc000754000, 0x0, 0x0, 0x1fbf8c0)
	/usr/local/opt/go/libexec/src/encoding/json/stream.go:136 +0x1dc
encoding/json.(*Decoder).Decode(0xc000754000, 0x1fd7a80, 0xc0009be020, 0x65a69f0, 0x0)
	/usr/local/opt/go/libexec/src/encoding/json/stream.go:63 +0x79
volcano.sh/volcano/vendor/k8s.io/apimachinery/pkg/util/framer.(*jsonFrameReader).Read(0xc0009b8000, 0xc0009bc000, 0x400, 0x400, 0xc0000b0801, 0x1000000000001, 0x38)
	/Users/yuan.chen/GolandProjects/src/volcano.sh/volcano/vendor/k8s.io/apimachinery/pkg/util/framer/framer.go:150 +0x1a1
volcano.sh/volcano/vendor/k8s.io/apimachinery/pkg/runtime/serializer/streaming.(*decoder).Decode(0xc000188190, 0x0, 0x23a32e0, 0xc0009c4000, 0x0, 0xc0001d63c0, 0x0, 0x1bc82cd, 0xc00060bf08)
	/Users/yuan.chen/GolandProjects/src/volcano.sh/volcano/vendor/k8s.io/apimachinery/pkg/runtime/serializer/streaming/streaming.go:77 +0x89
volcano.sh/volcano/vendor/k8s.io/client-go/rest/watch.(*Decoder).Decode(0xc0009be000, 0x1bcc7a8, 0xc00060bf38, 0xc00060bec4, 0x3, 0x1bc81ae, 0x14eab96)
	/Users/yuan.chen/GolandProjects/src/volcano.sh/volcano/vendor/k8s.io/client-go/rest/watch/decoder.go:49 +0x7c
volcano.sh/volcano/vendor/k8s.io/apimachinery/pkg/watch.(*StreamWatcher).receive(0xc0009b8030)
	/Users/yuan.chen/GolandProjects/src/volcano.sh/volcano/vendor/k8s.io/apimachinery/pkg/watch/streamwatcher.go:93 +0x175
created by volcano.sh/volcano/vendor/k8s.io/apimachinery/pkg/watch.NewStreamWatcher
	/Users/yuan.chen/GolandProjects/src/volcano.sh/volcano/vendor/k8s.io/apimachinery/pkg/watch/streamwatcher.go:60 +0x9f

goroutine 112 [sync.Cond.Wait, 2 minutes]:
runtime.goparkunlock(...)
	/usr/local/opt/go/libexec/src/runtime/proc.go:310
sync.runtime_notifyListWait(0xc0001427c0, 0x0)
	/usr/local/opt/go/libexec/src/runtime/sema.go:510 +0xf8
sync.(*Cond).Wait(0xc0001427b0)
	/usr/local/opt/go/libexec/src/sync/cond.go:56 +0x9d
volcano.sh/volcano/vendor/golang.org/x/net/http2.(*pipe).Read(0xc0001427a8, 0xc000a24000, 0x200, 0x200, 0x0, 0x0, 0x0)
	/Users/yuan.chen/GolandProjects/src/volcano.sh/volcano/vendor/golang.org/x/net/http2/pipe.go:64 +0xa6
volcano.sh/volcano/vendor/golang.org/x/net/http2.transportResponseBody.Read(0xc000142780, 0xc000a24000, 0x200, 0x200, 0x0, 0x0, 0x0)
	/Users/yuan.chen/GolandProjects/src/volcano.sh/volcano/vendor/golang.org/x/net/http2/transport.go:1952 +0xac
encoding/json.(*Decoder).refill(0xc0006574a0, 0xc000a0a900, 0xc00009e748)
	/usr/local/opt/go/libexec/src/encoding/json/stream.go:161 +0xeb
encoding/json.(*Decoder).readValue(0xc0006574a0, 0x0, 0x0, 0x1fbf8c0)
	/usr/local/opt/go/libexec/src/encoding/json/stream.go:136 +0x1dc
encoding/json.(*Decoder).Decode(0xc0006574a0, 0x1fd7a80, 0xc000a0a900, 0x207efa0, 0x21419a0)
	/usr/local/opt/go/libexec/src/encoding/json/stream.go:63 +0x79
volcano.sh/volcano/vendor/k8s.io/apimachinery/pkg/util/framer.(*jsonFrameReader).Read(0xc000a12240, 0xc000a20000, 0x400, 0x400, 0xc00034a000, 0x1bc438a, 0x38)
	/Users/yuan.chen/GolandProjects/src/volcano.sh/volcano/vendor/k8s.io/apimachinery/pkg/util/framer/framer.go:150 +0x1a1
volcano.sh/volcano/vendor/k8s.io/apimachinery/pkg/runtime/serializer/streaming.(*decoder).Decode(0xc00012a7d0, 0x0, 0x23a32e0, 0xc0009d2ac0, 0x10, 0xc000314280, 0xc00006c7c0, 0xc00006c688, 0x3b9aca00)
	/Users/yuan.chen/GolandProjects/src/volcano.sh/volcano/vendor/k8s.io/apimachinery/pkg/runtime/serializer/streaming/streaming.go:77 +0x89
volcano.sh/volcano/vendor/k8s.io/client-go/rest/watch.(*Decoder).Decode(0xc000a0a8e0, 0xc000314280, 0xc00006c738, 0x1bc3249, 0xc00006c6f0, 0x3b9aca00, 0x0)
	/Users/yuan.chen/GolandProjects/src/volcano.sh/volcano/vendor/k8s.io/client-go/rest/watch/decoder.go:49 +0x7c
volcano.sh/volcano/vendor/k8s.io/apimachinery/pkg/watch.(*StreamWatcher).receive(0xc000a12270)
	/Users/yuan.chen/GolandProjects/src/volcano.sh/volcano/vendor/k8s.io/apimachinery/pkg/watch/streamwatcher.go:93 +0x175
created by volcano.sh/volcano/vendor/k8s.io/apimachinery/pkg/watch.NewStreamWatcher
	/Users/yuan.chen/GolandProjects/src/volcano.sh/volcano/vendor/k8s.io/apimachinery/pkg/watch/streamwatcher.go:60 +0x9f

goroutine 242 [sync.Cond.Wait]:
runtime.goparkunlock(...)
	/usr/local/opt/go/libexec/src/runtime/proc.go:310
sync.runtime_notifyListWait(0xc00083a2c0, 0xc000000003)
	/usr/local/opt/go/libexec/src/runtime/sema.go:510 +0xf8
sync.(*Cond).Wait(0xc00083a2b0)
	/usr/local/opt/go/libexec/src/sync/cond.go:56 +0x9d
volcano.sh/volcano/vendor/golang.org/x/net/http2.(*pipe).Read(0xc00083a2a8, 0xc000538001, 0x1dff, 0x1dff, 0x0, 0x0, 0x0)
	/Users/yuan.chen/GolandProjects/src/volcano.sh/volcano/vendor/golang.org/x/net/http2/pipe.go:64 +0xa6
volcano.sh/volcano/vendor/golang.org/x/net/http2.transportResponseBody.Read(0xc00083a280, 0xc000538001, 0x1dff, 0x1dff, 0x0, 0x0, 0x0)
	/Users/yuan.chen/GolandProjects/src/volcano.sh/volcano/vendor/golang.org/x/net/http2/transport.go:1952 +0xac
encoding/json.(*Decoder).refill(0xc000657760, 0xc000a1030a, 0x9)
	/usr/local/opt/go/libexec/src/encoding/json/stream.go:161 +0xeb
encoding/json.(*Decoder).readValue(0xc000657760, 0x0, 0x0, 0x1fbf8c0)
	/usr/local/opt/go/libexec/src/encoding/json/stream.go:136 +0x1dc
encoding/json.(*Decoder).Decode(0xc000657760, 0x1fd7a80, 0xc000a10300, 0x0, 0x0)
	/usr/local/opt/go/libexec/src/encoding/json/stream.go:63 +0x79
volcano.sh/volcano/vendor/k8s.io/apimachinery/pkg/util/framer.(*jsonFrameReader).Read(0xc000a12360, 0xc0006ca000, 0x2000, 0x2600, 0x23a16e0, 0x0, 0x38)
	/Users/yuan.chen/GolandProjects/src/volcano.sh/volcano/vendor/k8s.io/apimachinery/pkg/util/framer/framer.go:150 +0x1a1
volcano.sh/volcano/vendor/k8s.io/apimachinery/pkg/runtime/serializer/streaming.(*decoder).Decode(0xc00012a9b0, 0x0, 0x23a32e0, 0xc00056d4c0, 0x0, 0x0, 0x0, 0xc0001d7bb8, 0x105aca0)
	/Users/yuan.chen/GolandProjects/src/volcano.sh/volcano/vendor/k8s.io/apimachinery/pkg/runtime/serializer/streaming/streaming.go:77 +0x89
volcano.sh/volcano/vendor/k8s.io/client-go/rest/watch.(*Decoder).Decode(0xc000a0a940, 0xc000999fa8, 0x8, 0x23a16e0, 0xc0001ce580, 0x0, 0x0)
	/Users/yuan.chen/GolandProjects/src/volcano.sh/volcano/vendor/k8s.io/client-go/rest/watch/decoder.go:49 +0x7c
volcano.sh/volcano/vendor/k8s.io/apimachinery/pkg/watch.(*StreamWatcher).receive(0xc000a12390)
	/Users/yuan.chen/GolandProjects/src/volcano.sh/volcano/vendor/k8s.io/apimachinery/pkg/watch/streamwatcher.go:93 +0x175
created by volcano.sh/volcano/vendor/k8s.io/apimachinery/pkg/watch.NewStreamWatcher
	/Users/yuan.chen/GolandProjects/src/volcano.sh/volcano/vendor/k8s.io/apimachinery/pkg/watch/streamwatcher.go:60 +0x9f

goroutine 228 [sync.Cond.Wait, 2 minutes]:
runtime.goparkunlock(...)
	/usr/local/opt/go/libexec/src/runtime/proc.go:310
sync.runtime_notifyListWait(0xc000142cc0, 0x0)
	/usr/local/opt/go/libexec/src/runtime/sema.go:510 +0xf8
sync.(*Cond).Wait(0xc000142cb0)
	/usr/local/opt/go/libexec/src/sync/cond.go:56 +0x9d
volcano.sh/volcano/vendor/golang.org/x/net/http2.(*pipe).Read(0xc000142ca8, 0xc000a24400, 0x200, 0x200, 0x0, 0x0, 0x0)
	/Users/yuan.chen/GolandProjects/src/volcano.sh/volcano/vendor/golang.org/x/net/http2/pipe.go:64 +0xa6
volcano.sh/volcano/vendor/golang.org/x/net/http2.transportResponseBody.Read(0xc000142c80, 0xc000a24400, 0x200, 0x200, 0x0, 0x0, 0x0)
	/Users/yuan.chen/GolandProjects/src/volcano.sh/volcano/vendor/golang.org/x/net/http2/transport.go:1952 +0xac
encoding/json.(*Decoder).refill(0xc0007542c0, 0xc000a10020, 0x0)
	/usr/local/opt/go/libexec/src/encoding/json/stream.go:161 +0xeb
encoding/json.(*Decoder).readValue(0xc0007542c0, 0x0, 0x0, 0x1fbf8c0)
	/usr/local/opt/go/libexec/src/encoding/json/stream.go:136 +0x1dc
encoding/json.(*Decoder).Decode(0xc0007542c0, 0x1fd7a80, 0xc000a10020, 0x7045740, 0x10)
	/usr/local/opt/go/libexec/src/encoding/json/stream.go:63 +0x79
volcano.sh/volcano/vendor/k8s.io/apimachinery/pkg/util/framer.(*jsonFrameReader).Read(0xc000a18000, 0xc000a20800, 0x400, 0x400, 0x566a455563526c01, 0x1504254476553, 0x38)
	/Users/yuan.chen/GolandProjects/src/volcano.sh/volcano/vendor/k8s.io/apimachinery/pkg/util/framer/framer.go:150 +0x1a1
volcano.sh/volcano/vendor/k8s.io/apimachinery/pkg/runtime/serializer/streaming.(*decoder).Decode(0xc0001882d0, 0x0, 0x23a32e0, 0xc000a74400, 0x5666436e4c784539, 0x4264394667424b51, 0x5465486b314f4559, 0x56445a4e6e635976, 0x756f6a4f426a4139)
	/Users/yuan.chen/GolandProjects/src/volcano.sh/volcano/vendor/k8s.io/apimachinery/pkg/runtime/serializer/streaming/streaming.go:77 +0x89
volcano.sh/volcano/vendor/k8s.io/client-go/rest/watch.(*Decoder).Decode(0xc000a10000, 0x50374c5255696c4c, 0x41764d6c42587353, 0x4f37716656527870, 0x6564346c5a387269, 0x476668654f4f7750, 0x757030657751454c)
	/Users/yuan.chen/GolandProjects/src/volcano.sh/volcano/vendor/k8s.io/client-go/rest/watch/decoder.go:49 +0x7c
volcano.sh/volcano/vendor/k8s.io/apimachinery/pkg/watch.(*StreamWatcher).receive(0xc000a18030)
	/Users/yuan.chen/GolandProjects/src/volcano.sh/volcano/vendor/k8s.io/apimachinery/pkg/watch/streamwatcher.go:93 +0x175
created by volcano.sh/volcano/vendor/k8s.io/apimachinery/pkg/watch.NewStreamWatcher
	/Users/yuan.chen/GolandProjects/src/volcano.sh/volcano/vendor/k8s.io/apimachinery/pkg/watch/streamwatcher.go:60 +0x9f

goroutine 260 [sync.Cond.Wait, 2 minutes]:
runtime.goparkunlock(...)
	/usr/local/opt/go/libexec/src/runtime/proc.go:310
sync.runtime_notifyListWait(0xc0001ca180, 0x0)
	/usr/local/opt/go/libexec/src/runtime/sema.go:510 +0xf8
sync.(*Cond).Wait(0xc0001ca170)
	/usr/local/opt/go/libexec/src/sync/cond.go:56 +0x9d
volcano.sh/volcano/vendor/golang.org/x/net/http2.(*pipe).Read(0xc0001ca168, 0xc0009d4400, 0x200, 0x200, 0x0, 0x0, 0x0)
	/Users/yuan.chen/GolandProjects/src/volcano.sh/volcano/vendor/golang.org/x/net/http2/pipe.go:64 +0xa6
volcano.sh/volcano/vendor/golang.org/x/net/http2.transportResponseBody.Read(0xc0001ca140, 0xc0009d4400, 0x200, 0x200, 0x0, 0x0, 0x0)
	/Users/yuan.chen/GolandProjects/src/volcano.sh/volcano/vendor/golang.org/x/net/http2/transport.go:1952 +0xac
encoding/json.(*Decoder).refill(0xc0006562c0, 0xc0009be0c0, 0x6845504254476553)
	/usr/local/opt/go/libexec/src/encoding/json/stream.go:161 +0xeb
encoding/json.(*Decoder).readValue(0xc0006562c0, 0x0, 0x0, 0x1fbf8c0)
	/usr/local/opt/go/libexec/src/encoding/json/stream.go:136 +0x1dc
encoding/json.(*Decoder).Decode(0xc0006562c0, 0x1fd7a80, 0xc0009be0c0, 0x594d366b68786448, 0x5338785368453462)
	/usr/local/opt/go/libexec/src/encoding/json/stream.go:63 +0x79
volcano.sh/volcano/vendor/k8s.io/apimachinery/pkg/util/framer.(*jsonFrameReader).Read(0xc0009b8270, 0xc0009bc800, 0x400, 0x400, 0x72354c580a364469, 0x2b416e664736, 0x38)
	/Users/yuan.chen/GolandProjects/src/volcano.sh/volcano/vendor/k8s.io/apimachinery/pkg/util/framer/framer.go:150 +0x1a1
volcano.sh/volcano/vendor/k8s.io/apimachinery/pkg/runtime/serializer/streaming.(*decoder).Decode(0xc00012a960, 0x0, 0x23a32e0, 0xc0009d2280, 0x75762b4950482b6b, 0x734946656f7a3455, 0x7851545872624539, 0x5238786f41364a67, 0x6a552b71726d4750)
	/Users/yuan.chen/GolandProjects/src/volcano.sh/volcano/vendor/k8s.io/apimachinery/pkg/runtime/serializer/streaming/streaming.go:77 +0x89
volcano.sh/volcano/vendor/k8s.io/client-go/rest/watch.(*Decoder).Decode(0xc0009be0a0, 0x2d2d2d59454b2045, 0xa2d2d, 0x0, 0x0, 0x0, 0x0)
	/Users/yuan.chen/GolandProjects/src/volcano.sh/volcano/vendor/k8s.io/client-go/rest/watch/decoder.go:49 +0x7c
volcano.sh/volcano/vendor/k8s.io/apimachinery/pkg/watch.(*StreamWatcher).receive(0xc0009b82a0)
	/Users/yuan.chen/GolandProjects/src/volcano.sh/volcano/vendor/k8s.io/apimachinery/pkg/watch/streamwatcher.go:93 +0x175
created by volcano.sh/volcano/vendor/k8s.io/apimachinery/pkg/watch.NewStreamWatcher
	/Users/yuan.chen/GolandProjects/src/volcano.sh/volcano/vendor/k8s.io/apimachinery/pkg/watch/streamwatcher.go:60 +0x9f

goroutine 261 [sync.Cond.Wait, 2 minutes]:
runtime.goparkunlock(...)
	/usr/local/opt/go/libexec/src/runtime/proc.go:310
sync.runtime_notifyListWait(0xc00077c2c0, 0x0)
	/usr/local/opt/go/libexec/src/runtime/sema.go:510 +0xf8
sync.(*Cond).Wait(0xc00077c2b0)
	/usr/local/opt/go/libexec/src/sync/cond.go:56 +0x9d
volcano.sh/volcano/vendor/golang.org/x/net/http2.(*pipe).Read(0xc00077c2a8, 0xc0009d4600, 0x200, 0x200, 0x0, 0x0, 0x0)
	/Users/yuan.chen/GolandProjects/src/volcano.sh/volcano/vendor/golang.org/x/net/http2/pipe.go:64 +0xa6
volcano.sh/volcano/vendor/golang.org/x/net/http2.transportResponseBody.Read(0xc00077c280, 0xc0009d4600, 0x200, 0x200, 0x0, 0x0, 0x0)
	/Users/yuan.chen/GolandProjects/src/volcano.sh/volcano/vendor/golang.org/x/net/http2/transport.go:1952 +0xac
encoding/json.(*Decoder).refill(0xc000656420, 0xc0009be100, 0x454320444e452d2d)
	/usr/local/opt/go/libexec/src/encoding/json/stream.go:161 +0xeb
encoding/json.(*Decoder).readValue(0xc000656420, 0x0, 0x0, 0x1fbf8c0)
	/usr/local/opt/go/libexec/src/encoding/json/stream.go:136 +0x1dc
encoding/json.(*Decoder).Decode(0xc000656420, 0x1fd7a80, 0xc0009be100, 0x239e400, 0xc0005e6550)
	/usr/local/opt/go/libexec/src/encoding/json/stream.go:63 +0x79
volcano.sh/volcano/vendor/k8s.io/apimachinery/pkg/util/framer.(*jsonFrameReader).Read(0xc0009b82d0, 0xc0009bcc00, 0x400, 0x400, 0xc0004be000, 0xc0005e6568, 0x38)
	/Users/yuan.chen/GolandProjects/src/volcano.sh/volcano/vendor/k8s.io/apimachinery/pkg/util/framer/framer.go:150 +0x1a1
volcano.sh/volcano/vendor/k8s.io/apimachinery/pkg/runtime/serializer/streaming.(*decoder).Decode(0xc00012aa00, 0x0, 0x23a32e0, 0xc0009d2300, 0x0, 0xc0003e6a80, 0x0, 0x0, 0x0)
	/Users/yuan.chen/GolandProjects/src/volcano.sh/volcano/vendor/k8s.io/apimachinery/pkg/runtime/serializer/streaming/streaming.go:77 +0x89
volcano.sh/volcano/vendor/k8s.io/client-go/rest/watch.(*Decoder).Decode(0xc0009be0e0, 0x1bcc7a8, 0xc0005e6738, 0xc0005e66c4, 0x3, 0x223daf8, 0x14eab96)
	/Users/yuan.chen/GolandProjects/src/volcano.sh/volcano/vendor/k8s.io/client-go/rest/watch/decoder.go:49 +0x7c
volcano.sh/volcano/vendor/k8s.io/apimachinery/pkg/watch.(*StreamWatcher).receive(0xc0009b8300)
	/Users/yuan.chen/GolandProjects/src/volcano.sh/volcano/vendor/k8s.io/apimachinery/pkg/watch/streamwatcher.go:93 +0x175
created by volcano.sh/volcano/vendor/k8s.io/apimachinery/pkg/watch.NewStreamWatcher
	/Users/yuan.chen/GolandProjects/src/volcano.sh/volcano/vendor/k8s.io/apimachinery/pkg/watch/streamwatcher.go:60 +0x9f

goroutine 262 [select]:
volcano.sh/volcano/vendor/k8s.io/apimachinery/pkg/util/wait.JitterUntil(0xc0009ea080, 0x12a05f200, 0x0, 0x1, 0x0)
	/Users/yuan.chen/GolandProjects/src/volcano.sh/volcano/vendor/k8s.io/apimachinery/pkg/util/wait/wait.go:145 +0x181
volcano.sh/volcano/vendor/k8s.io/apimachinery/pkg/util/wait.Until(0xc0009ea080, 0x12a05f200, 0x0)
	/Users/yuan.chen/GolandProjects/src/volcano.sh/volcano/vendor/k8s.io/apimachinery/pkg/util/wait/wait.go:88 +0x4d
created by volcano.sh/volcano/pkg/scheduler.(*Scheduler).Run
	/Users/yuan.chen/GolandProjects/src/volcano.sh/volcano/pkg/scheduler/scheduler.go:68 +0xd4
