Log file created at: 2019/11/04 15:47:23
Running on machine: SVMAC-C02T6AMCGTFL
Binary: Built with gc go1.13 for darwin/amd64
Log line format: [IWEF]mmdd hh:mm:ss.uuuuuu threadid file:line] msg
I1104 15:47:23.934450   65962 event_handlers.go:709] Add Queue(default) into cache, spec(v1alpha1.QueueSpec{Weight:1, Capability:v1.ResourceList(nil)})
I1104 15:47:23.938683   65962 event_handlers.go:729] Add Queue(default) into cache, spec(v1alpha2.QueueSpec{Weight:1, Capability:v1.ResourceList(nil)})
I1104 15:47:23.944904   65962 event_handlers.go:48] Pod kube-system/registry-f4x5r will not not scheduled by jdos-batch, skip creating PodGroup and Job for it
I1104 15:47:23.944917   65962 event_handlers.go:189] Added pod <kube-system/registry-f4x5r> into cache.
I1104 15:47:23.944925   65962 event_handlers.go:48] Pod kube-system/coredns-fb8b8dccf-cm54h will not not scheduled by jdos-batch, skip creating PodGroup and Job for it
I1104 15:47:23.944929   65962 event_handlers.go:189] Added pod <kube-system/coredns-fb8b8dccf-cm54h> into cache.
I1104 15:47:23.944934   65962 event_handlers.go:48] Pod kube-system/kube-scheduler-minikube will not not scheduled by jdos-batch, skip creating PodGroup and Job for it
I1104 15:47:23.944937   65962 event_handlers.go:189] Added pod <kube-system/kube-scheduler-minikube> into cache.
I1104 15:47:23.944939   65962 event_handlers.go:48] Pod kube-system/kubernetes-dashboard-d7c9687c7-tkc82 will not not scheduled by jdos-batch, skip creating PodGroup and Job for it
I1104 15:47:23.944942   65962 event_handlers.go:189] Added pod <kube-system/kubernetes-dashboard-d7c9687c7-tkc82> into cache.
I1104 15:47:23.944945   65962 event_handlers.go:48] Pod kube-system/kube-apiserver-minikube will not not scheduled by jdos-batch, skip creating PodGroup and Job for it
I1104 15:47:23.944948   65962 event_handlers.go:189] Added pod <kube-system/kube-apiserver-minikube> into cache.
I1104 15:47:23.944951   65962 event_handlers.go:48] Pod kube-system/kube-controller-manager-minikube will not not scheduled by jdos-batch, skip creating PodGroup and Job for it
I1104 15:47:23.944953   65962 event_handlers.go:189] Added pod <kube-system/kube-controller-manager-minikube> into cache.
I1104 15:47:23.944956   65962 event_handlers.go:48] Pod kube-system/kube-proxy-kc6f7 will not not scheduled by jdos-batch, skip creating PodGroup and Job for it
I1104 15:47:23.944959   65962 event_handlers.go:189] Added pod <kube-system/kube-proxy-kc6f7> into cache.
I1104 15:47:23.944963   65962 event_handlers.go:48] Pod kube-system/storage-provisioner will not not scheduled by jdos-batch, skip creating PodGroup and Job for it
I1104 15:47:23.944966   65962 event_handlers.go:189] Added pod <kube-system/storage-provisioner> into cache.
I1104 15:47:23.944972   65962 event_handlers.go:48] Pod kube-system/coredns-fb8b8dccf-xfpnf will not not scheduled by jdos-batch, skip creating PodGroup and Job for it
I1104 15:47:23.944977   65962 event_handlers.go:189] Added pod <kube-system/coredns-fb8b8dccf-xfpnf> into cache.
I1104 15:47:23.944981   65962 event_handlers.go:48] Pod kube-system/etcd-minikube will not not scheduled by jdos-batch, skip creating PodGroup and Job for it
I1104 15:47:23.944984   65962 event_handlers.go:189] Added pod <kube-system/etcd-minikube> into cache.
I1104 15:47:23.944987   65962 event_handlers.go:48] Pod kube-system/kube-addon-manager-minikube will not not scheduled by jdos-batch, skip creating PodGroup and Job for it
I1104 15:47:23.944990   65962 event_handlers.go:189] Added pod <kube-system/kube-addon-manager-minikube> into cache.
I1104 15:47:24.033430   65962 scheduler.go:72] Start scheduling ...
I1104 15:47:24.033768   65962 cache.go:771] There are <0> Jobs, <1> Queues and <1> Nodes in total for scheduling.
I1104 15:47:24.033779   65962 session.go:135] Open Session 7324b344-ff5d-11e9-a079-784f43775513 with <0> Job and <1> Queues
I1104 15:47:24.033855   65962 proportion.go:67] The total resource is <cpu 4000.00, memory 4959854592.00, hugepages-2Mi 0.00>
I1104 15:47:24.033883   65962 proportion.go:117] Exiting when total weight is 0
I1104 15:47:24.033915   65962 enqueue.go:43] Enter Enqueue ...
I1104 15:47:24.033921   65962 enqueue.go:75] Try to enqueue PodGroup to 0 Queues
I1104 15:47:24.033930   65962 enqueue.go:122] Leaving Enqueue ...
I1104 15:47:24.033946   65962 allocate.go:43] Enter Allocate ...
I1104 15:47:24.033955   65962 allocate.go:94] Try to allocate resource to 0 Namespaces
I1104 15:47:24.033971   65962 allocate.go:253] Leaving Allocate ...
I1104 15:47:24.033976   65962 backfill.go:42] Enter Backfill ...
I1104 15:47:24.033980   65962 backfill.go:91] Leaving Backfill ...
I1104 15:47:24.034021   65962 session.go:154] Close Session 7324b344-ff5d-11e9-a079-784f43775513
I1104 15:47:24.034025   65962 scheduler.go:87] End scheduling ...
I1104 15:47:29.034218   65962 scheduler.go:72] Start scheduling ...
I1104 15:47:29.034367   65962 cache.go:771] There are <0> Jobs, <1> Queues and <1> Nodes in total for scheduling.
I1104 15:47:29.034372   65962 session.go:135] Open Session 761fbb2a-ff5d-11e9-a079-784f43775513 with <0> Job and <1> Queues
I1104 15:47:29.034412   65962 proportion.go:67] The total resource is <cpu 4000.00, memory 4959854592.00, hugepages-2Mi 0.00>
I1104 15:47:29.034429   65962 proportion.go:117] Exiting when total weight is 0
I1104 15:47:29.034445   65962 enqueue.go:43] Enter Enqueue ...
I1104 15:47:29.034449   65962 enqueue.go:75] Try to enqueue PodGroup to 0 Queues
I1104 15:47:29.034455   65962 enqueue.go:122] Leaving Enqueue ...
I1104 15:47:29.034460   65962 allocate.go:43] Enter Allocate ...
I1104 15:47:29.034465   65962 allocate.go:94] Try to allocate resource to 0 Namespaces
I1104 15:47:29.034475   65962 allocate.go:253] Leaving Allocate ...
I1104 15:47:29.034479   65962 backfill.go:42] Enter Backfill ...
I1104 15:47:29.034482   65962 backfill.go:91] Leaving Backfill ...
I1104 15:47:29.034492   65962 session.go:154] Close Session 761fbb2a-ff5d-11e9-a079-784f43775513
I1104 15:47:29.034496   65962 scheduler.go:87] End scheduling ...
I1104 15:47:34.034707   65962 scheduler.go:72] Start scheduling ...
I1104 15:47:34.034853   65962 cache.go:771] There are <0> Jobs, <1> Queues and <1> Nodes in total for scheduling.
I1104 15:47:34.034862   65962 session.go:135] Open Session 791abeba-ff5d-11e9-a079-784f43775513 with <0> Job and <1> Queues
I1104 15:47:34.034940   65962 proportion.go:67] The total resource is <cpu 4000.00, memory 4959854592.00, hugepages-2Mi 0.00>
I1104 15:47:34.034962   65962 proportion.go:117] Exiting when total weight is 0
I1104 15:47:34.034990   65962 enqueue.go:43] Enter Enqueue ...
I1104 15:47:34.034997   65962 enqueue.go:75] Try to enqueue PodGroup to 0 Queues
I1104 15:47:34.035006   65962 enqueue.go:122] Leaving Enqueue ...
I1104 15:47:34.035013   65962 allocate.go:43] Enter Allocate ...
I1104 15:47:34.035020   65962 allocate.go:94] Try to allocate resource to 0 Namespaces
I1104 15:47:34.035030   65962 allocate.go:253] Leaving Allocate ...
I1104 15:47:34.035033   65962 backfill.go:42] Enter Backfill ...
I1104 15:47:34.035036   65962 backfill.go:91] Leaving Backfill ...
I1104 15:47:34.035048   65962 session.go:154] Close Session 791abeba-ff5d-11e9-a079-784f43775513
I1104 15:47:34.035052   65962 scheduler.go:87] End scheduling ...
I1104 15:47:38.701898   65962 event_handlers.go:189] Added pod <default/qj-1-vfl4v> into cache.
I1104 15:47:38.702001   65962 event_handlers.go:189] Added pod <default/qj-1-mvb6j> into cache.
I1104 15:47:38.707979   65962 event_handlers.go:409] Add PodGroup(qj-1) into cache, spec(v1alpha1.PodGroupSpec{MinMember:2, Queue:"default", PriorityClassName:"", MinResources:(*v1.ResourceList)(nil)})
I1104 15:47:39.037284   65962 scheduler.go:72] Start scheduling ...
I1104 15:47:39.037443   65962 cache.go:732] The priority of job <default/qj-1> is </0>
I1104 15:47:39.037462   65962 cache.go:771] There are <1> Jobs, <1> Queues and <1> Nodes in total for scheduling.
I1104 15:47:39.037470   65962 session.go:135] Open Session 7c1613a8-ff5d-11e9-a079-784f43775513 with <1> Job and <1> Queues
I1104 15:47:39.037508   65962 proportion.go:67] The total resource is <cpu 4000.00, memory 4959854592.00, hugepages-2Mi 0.00>
I1104 15:47:39.037520   65962 proportion.go:71] Considering Job <default/qj-1>.
I1104 15:47:39.037524   65962 proportion.go:85] Added Queue <default> attributes.
I1104 15:47:39.037532   65962 proportion.go:127] Considering Queue <default>: weight <1>, total weight <1>.
I1104 15:47:39.037548   65962 proportion.go:144] The attributes of queue <default> in proportion: deserved <cpu 4000.00, memory 4959854592.00, hugepages-2Mi 0.00>, allocate <cpu 0.00, memory 0.00>, request <cpu 2000.00, memory 1073741824.00>, share <0.00>
I1104 15:47:39.037567   65962 proportion.go:154] Exiting when remaining is empty:  <cpu 0.00, memory 0.00, hugepages-2Mi 0.00>
I1104 15:47:39.037596   65962 enqueue.go:43] Enter Enqueue ...
I1104 15:47:39.037599   65962 enqueue.go:58] Added Queue <default> for Job <default/qj-1>
I1104 15:47:39.037604   65962 enqueue.go:75] Try to enqueue PodGroup to 0 Queues
I1104 15:47:39.037610   65962 enqueue.go:122] Leaving Enqueue ...
I1104 15:47:39.037615   65962 allocate.go:43] Enter Allocate ...
I1104 15:47:39.037618   65962 allocate.go:90] Added Job <default/qj-1> into Queue <default>
I1104 15:47:39.037623   65962 allocate.go:94] Try to allocate resource to 1 Namespaces
I1104 15:47:39.037630   65962 allocate.go:153] Try to allocate resource to Jobs in Namespace <default> Queue <default>
I1104 15:47:39.037637   65962 priority.go:47] Priority TaskOrder: <default/qj-1-mvb6j> priority is 0, <default/qj-1-vfl4v> priority is 0
I1104 15:47:39.037644   65962 allocate.go:178] Try to allocate resource to 2 tasks of Job <default/qj-1>
I1104 15:47:39.037650   65962 allocate.go:186] There are <1> nodes for Job <default/qj-1>
I1104 15:47:39.037674   65962 scheduler_helper.go:84] Considering Task <default/qj-1-vfl4v> on node <minikube>: <cpu 1000.00, memory 536870912.00> vs. <cpu 3245.00, memory 4760625152.00, hugepages-2Mi 0.00>
I1104 15:47:39.037736   65962 predicates.go:177] CheckNodeCondition predicates Task <default/qj-1-vfl4v> on Node <minikube>: fit true, err <nil>
I1104 15:47:39.037743   65962 predicates.go:190] CheckNodeUnschedulable Predicate Task <default/qj-1-vfl4v> on Node <minikube>: fit true, err <nil>
I1104 15:47:39.037751   65962 predicates.go:203] NodeSelect predicates Task <default/qj-1-vfl4v> on Node <minikube>: fit true, err <nil>
I1104 15:47:39.037758   65962 predicates.go:216] HostPorts predicates Task <default/qj-1-vfl4v> on Node <minikube>: fit true, err <nil>
I1104 15:47:39.037765   65962 predicates.go:229] Toleration/Taint predicates Task <default/qj-1-vfl4v> on Node <minikube>: fit true, err <nil>
I1104 15:47:39.037774   65962 predicate_extension.go:36] Pod qj-1-vfl4v is not batch task
I1104 15:47:39.037778   65962 scheduler_helper.go:89] Predicates failed for task <default/qj-1-vfl4v> on node <minikube>: task default/qj-1-vfl4v on node minikube fit failed: Pod is not a batch task
I1104 15:47:39.037794   65962 statement.go:310] Discarding operations ...
I1104 15:47:39.037803   65962 allocate.go:153] Try to allocate resource to Jobs in Namespace <default> Queue <default>
I1104 15:47:39.037808   65962 allocate.go:157] Can not find jobs for queue default.
I1104 15:47:39.037817   65962 allocate.go:253] Leaving Allocate ...
I1104 15:47:39.037820   65962 backfill.go:42] Enter Backfill ...
I1104 15:47:39.037825   65962 backfill.go:91] Leaving Backfill ...
I1104 15:47:39.042882   65962 cache.go:187] Updating pod condition for default/qj-1-vfl4v to (PodScheduled==False)
I1104 15:47:39.049580   65962 event_handlers.go:215] Updated pod <default/qj-1-vfl4v> in cache.
I1104 15:47:39.050028   65962 cache.go:187] Updating pod condition for default/qj-1-mvb6j to (PodScheduled==False)
I1104 15:47:39.054967   65962 event_handlers.go:215] Updated pod <default/qj-1-mvb6j> in cache.
I1104 15:47:39.062463   65962 session.go:154] Close Session 7c1613a8-ff5d-11e9-a079-784f43775513
I1104 15:47:39.062473   65962 scheduler.go:87] End scheduling ...
I1104 15:47:44.067699   65962 scheduler.go:72] Start scheduling ...
I1104 15:47:44.067836   65962 cache.go:732] The priority of job <default/qj-1> is </0>
I1104 15:47:44.067854   65962 cache.go:771] There are <1> Jobs, <1> Queues and <1> Nodes in total for scheduling.
I1104 15:47:44.067860   65962 session.go:135] Open Session 7f15a7d0-ff5d-11e9-a079-784f43775513 with <1> Job and <1> Queues
I1104 15:47:44.067899   65962 proportion.go:67] The total resource is <cpu 4000.00, memory 4959854592.00, hugepages-2Mi 0.00>
I1104 15:47:44.067913   65962 proportion.go:71] Considering Job <default/qj-1>.
I1104 15:47:44.067918   65962 proportion.go:85] Added Queue <default> attributes.
I1104 15:47:44.067926   65962 proportion.go:127] Considering Queue <default>: weight <1>, total weight <1>.
I1104 15:47:44.067934   65962 proportion.go:144] The attributes of queue <default> in proportion: deserved <cpu 4000.00, memory 4959854592.00, hugepages-2Mi 0.00>, allocate <cpu 0.00, memory 0.00>, request <cpu 2000.00, memory 1073741824.00>, share <0.00>
I1104 15:47:44.067953   65962 proportion.go:154] Exiting when remaining is empty:  <cpu 0.00, memory 0.00, hugepages-2Mi 0.00>
I1104 15:47:44.067977   65962 enqueue.go:43] Enter Enqueue ...
I1104 15:47:44.067981   65962 enqueue.go:58] Added Queue <default> for Job <default/qj-1>
I1104 15:47:44.067985   65962 enqueue.go:70] Added Job <default/qj-1> into Queue <default>
I1104 15:47:44.067990   65962 enqueue.go:75] Try to enqueue PodGroup to 1 Queues
I1104 15:47:44.067997   65962 enqueue.go:122] Leaving Enqueue ...
I1104 15:47:44.068003   65962 allocate.go:43] Enter Allocate ...
I1104 15:47:44.068008   65962 allocate.go:90] Added Job <default/qj-1> into Queue <default>
I1104 15:47:44.068013   65962 allocate.go:94] Try to allocate resource to 1 Namespaces
I1104 15:47:44.068020   65962 allocate.go:153] Try to allocate resource to Jobs in Namespace <default> Queue <default>
I1104 15:47:44.068025   65962 priority.go:47] Priority TaskOrder: <default/qj-1-mvb6j> priority is 0, <default/qj-1-vfl4v> priority is 0
I1104 15:47:44.068033   65962 allocate.go:178] Try to allocate resource to 2 tasks of Job <default/qj-1>
I1104 15:47:44.068040   65962 allocate.go:186] There are <1> nodes for Job <default/qj-1>
I1104 15:47:44.068071   65962 scheduler_helper.go:84] Considering Task <default/qj-1-vfl4v> on node <minikube>: <cpu 1000.00, memory 536870912.00> vs. <cpu 3245.00, memory 4760625152.00, hugepages-2Mi 0.00>
I1104 15:47:44.068116   65962 predicates.go:177] CheckNodeCondition predicates Task <default/qj-1-vfl4v> on Node <minikube>: fit true, err <nil>
I1104 15:47:44.068122   65962 predicates.go:190] CheckNodeUnschedulable Predicate Task <default/qj-1-vfl4v> on Node <minikube>: fit true, err <nil>
I1104 15:47:44.068128   65962 predicates.go:203] NodeSelect predicates Task <default/qj-1-vfl4v> on Node <minikube>: fit true, err <nil>
I1104 15:47:44.068133   65962 predicates.go:216] HostPorts predicates Task <default/qj-1-vfl4v> on Node <minikube>: fit true, err <nil>
I1104 15:47:44.068138   65962 predicates.go:229] Toleration/Taint predicates Task <default/qj-1-vfl4v> on Node <minikube>: fit true, err <nil>
I1104 15:47:44.068143   65962 predicate_extension.go:36] Pod qj-1-vfl4v is not batch task
I1104 15:47:44.068147   65962 scheduler_helper.go:89] Predicates failed for task <default/qj-1-vfl4v> on node <minikube>: task default/qj-1-vfl4v on node minikube fit failed: Pod is not a batch task
I1104 15:47:44.068160   65962 statement.go:310] Discarding operations ...
I1104 15:47:44.068168   65962 allocate.go:153] Try to allocate resource to Jobs in Namespace <default> Queue <default>
I1104 15:47:44.068173   65962 allocate.go:157] Can not find jobs for queue default.
I1104 15:47:44.068182   65962 allocate.go:253] Leaving Allocate ...
I1104 15:47:44.068186   65962 backfill.go:42] Enter Backfill ...
I1104 15:47:44.068192   65962 backfill.go:91] Leaving Backfill ...
I1104 15:47:44.073111   65962 cache.go:634] task unscheduleable default/qj-1-vfl4v, message: all nodes are unavailable: 1 Pod is not a batch task., skip by no condition update
I1104 15:47:44.073118   65962 cache.go:634] task unscheduleable default/qj-1-mvb6j, message: 2/2 tasks in gang unschedulable: job is not ready, 2 Pending, 2 minAvailable., skip by no condition update
I1104 15:47:44.073130   65962 session.go:154] Close Session 7f15a7d0-ff5d-11e9-a079-784f43775513
I1104 15:47:44.073136   65962 scheduler.go:87] End scheduling ...
I1104 15:47:49.076035   65962 scheduler.go:72] Start scheduling ...
I1104 15:47:49.076175   65962 cache.go:732] The priority of job <default/qj-1> is </0>
I1104 15:47:49.076210   65962 cache.go:771] There are <1> Jobs, <1> Queues and <1> Nodes in total for scheduling.
I1104 15:47:49.076219   65962 session.go:135] Open Session 8211ddf0-ff5d-11e9-a079-784f43775513 with <1> Job and <1> Queues
I1104 15:47:49.076260   65962 proportion.go:67] The total resource is <cpu 4000.00, memory 4959854592.00, hugepages-2Mi 0.00>
I1104 15:47:49.076271   65962 proportion.go:71] Considering Job <default/qj-1>.
I1104 15:47:49.076276   65962 proportion.go:85] Added Queue <default> attributes.
I1104 15:47:49.076283   65962 proportion.go:127] Considering Queue <default>: weight <1>, total weight <1>.
I1104 15:47:49.076291   65962 proportion.go:144] The attributes of queue <default> in proportion: deserved <cpu 4000.00, memory 4959854592.00, hugepages-2Mi 0.00>, allocate <cpu 0.00, memory 0.00>, request <cpu 2000.00, memory 1073741824.00>, share <0.00>
I1104 15:47:49.076303   65962 proportion.go:154] Exiting when remaining is empty:  <cpu 0.00, memory 0.00, hugepages-2Mi 0.00>
I1104 15:47:49.076322   65962 enqueue.go:43] Enter Enqueue ...
I1104 15:47:49.076326   65962 enqueue.go:58] Added Queue <default> for Job <default/qj-1>
I1104 15:47:49.076331   65962 enqueue.go:75] Try to enqueue PodGroup to 0 Queues
I1104 15:47:49.076337   65962 enqueue.go:122] Leaving Enqueue ...
I1104 15:47:49.076342   65962 allocate.go:43] Enter Allocate ...
I1104 15:47:49.076347   65962 allocate.go:90] Added Job <default/qj-1> into Queue <default>
I1104 15:47:49.076352   65962 allocate.go:94] Try to allocate resource to 1 Namespaces
I1104 15:47:49.076359   65962 allocate.go:153] Try to allocate resource to Jobs in Namespace <default> Queue <default>
I1104 15:47:49.076364   65962 priority.go:47] Priority TaskOrder: <default/qj-1-mvb6j> priority is 0, <default/qj-1-vfl4v> priority is 0
I1104 15:47:49.076371   65962 allocate.go:178] Try to allocate resource to 2 tasks of Job <default/qj-1>
I1104 15:47:49.076377   65962 allocate.go:186] There are <1> nodes for Job <default/qj-1>
I1104 15:47:49.076400   65962 scheduler_helper.go:84] Considering Task <default/qj-1-vfl4v> on node <minikube>: <cpu 1000.00, memory 536870912.00> vs. <cpu 3245.00, memory 4760625152.00, hugepages-2Mi 0.00>
I1104 15:47:49.076436   65962 predicates.go:177] CheckNodeCondition predicates Task <default/qj-1-vfl4v> on Node <minikube>: fit true, err <nil>
I1104 15:47:49.076442   65962 predicates.go:190] CheckNodeUnschedulable Predicate Task <default/qj-1-vfl4v> on Node <minikube>: fit true, err <nil>
I1104 15:47:49.076447   65962 predicates.go:203] NodeSelect predicates Task <default/qj-1-vfl4v> on Node <minikube>: fit true, err <nil>
I1104 15:47:49.076453   65962 predicates.go:216] HostPorts predicates Task <default/qj-1-vfl4v> on Node <minikube>: fit true, err <nil>
I1104 15:47:49.076458   65962 predicates.go:229] Toleration/Taint predicates Task <default/qj-1-vfl4v> on Node <minikube>: fit true, err <nil>
I1104 15:47:49.076462   65962 predicate_extension.go:36] Pod qj-1-vfl4v is not batch task
I1104 15:47:49.076466   65962 scheduler_helper.go:89] Predicates failed for task <default/qj-1-vfl4v> on node <minikube>: task default/qj-1-vfl4v on node minikube fit failed: Pod is not a batch task
I1104 15:47:49.076478   65962 statement.go:310] Discarding operations ...
I1104 15:47:49.076485   65962 allocate.go:153] Try to allocate resource to Jobs in Namespace <default> Queue <default>
I1104 15:47:49.076490   65962 allocate.go:157] Can not find jobs for queue default.
I1104 15:47:49.076499   65962 allocate.go:253] Leaving Allocate ...
I1104 15:47:49.076503   65962 backfill.go:42] Enter Backfill ...
I1104 15:47:49.076507   65962 backfill.go:91] Leaving Backfill ...
I1104 15:47:49.080553   65962 cache.go:634] task unscheduleable default/qj-1-vfl4v, message: all nodes are unavailable: 1 Pod is not a batch task., skip by no condition update
I1104 15:47:49.080560   65962 cache.go:634] task unscheduleable default/qj-1-mvb6j, message: 2/2 tasks in gang unschedulable: job is not ready, 2 Pending, 2 minAvailable., skip by no condition update
I1104 15:47:49.080571   65962 session.go:154] Close Session 8211ddf0-ff5d-11e9-a079-784f43775513
I1104 15:47:49.080577   65962 scheduler.go:87] End scheduling ...
I1104 15:47:54.081541   65962 scheduler.go:72] Start scheduling ...
I1104 15:47:54.081677   65962 cache.go:732] The priority of job <default/qj-1> is </0>
I1104 15:47:54.081699   65962 cache.go:771] There are <1> Jobs, <1> Queues and <1> Nodes in total for scheduling.
I1104 15:47:54.081705   65962 session.go:135] Open Session 850da57a-ff5d-11e9-a079-784f43775513 with <1> Job and <1> Queues
I1104 15:47:54.081742   65962 proportion.go:67] The total resource is <cpu 4000.00, memory 4959854592.00, hugepages-2Mi 0.00>
I1104 15:47:54.081754   65962 proportion.go:71] Considering Job <default/qj-1>.
I1104 15:47:54.081759   65962 proportion.go:85] Added Queue <default> attributes.
I1104 15:47:54.081766   65962 proportion.go:127] Considering Queue <default>: weight <1>, total weight <1>.
I1104 15:47:54.081773   65962 proportion.go:144] The attributes of queue <default> in proportion: deserved <cpu 4000.00, memory 4959854592.00, hugepages-2Mi 0.00>, allocate <cpu 0.00, memory 0.00>, request <cpu 2000.00, memory 1073741824.00>, share <0.00>
I1104 15:47:54.081786   65962 proportion.go:154] Exiting when remaining is empty:  <cpu 0.00, memory 0.00, hugepages-2Mi 0.00>
I1104 15:47:54.081820   65962 enqueue.go:43] Enter Enqueue ...
I1104 15:47:54.081837   65962 enqueue.go:58] Added Queue <default> for Job <default/qj-1>
I1104 15:47:54.081843   65962 enqueue.go:75] Try to enqueue PodGroup to 0 Queues
I1104 15:47:54.081850   65962 enqueue.go:122] Leaving Enqueue ...
I1104 15:47:54.081856   65962 allocate.go:43] Enter Allocate ...
I1104 15:47:54.081860   65962 allocate.go:90] Added Job <default/qj-1> into Queue <default>
I1104 15:47:54.081866   65962 allocate.go:94] Try to allocate resource to 1 Namespaces
I1104 15:47:54.081873   65962 allocate.go:153] Try to allocate resource to Jobs in Namespace <default> Queue <default>
I1104 15:47:54.081878   65962 priority.go:47] Priority TaskOrder: <default/qj-1-mvb6j> priority is 0, <default/qj-1-vfl4v> priority is 0
I1104 15:47:54.081913   65962 allocate.go:178] Try to allocate resource to 2 tasks of Job <default/qj-1>
I1104 15:47:54.081930   65962 allocate.go:186] There are <1> nodes for Job <default/qj-1>
I1104 15:47:54.081982   65962 scheduler_helper.go:84] Considering Task <default/qj-1-vfl4v> on node <minikube>: <cpu 1000.00, memory 536870912.00> vs. <cpu 3245.00, memory 4760625152.00, hugepages-2Mi 0.00>
I1104 15:47:54.082019   65962 predicates.go:177] CheckNodeCondition predicates Task <default/qj-1-vfl4v> on Node <minikube>: fit true, err <nil>
I1104 15:47:54.082028   65962 predicates.go:190] CheckNodeUnschedulable Predicate Task <default/qj-1-vfl4v> on Node <minikube>: fit true, err <nil>
I1104 15:47:54.082034   65962 predicates.go:203] NodeSelect predicates Task <default/qj-1-vfl4v> on Node <minikube>: fit true, err <nil>
I1104 15:47:54.082040   65962 predicates.go:216] HostPorts predicates Task <default/qj-1-vfl4v> on Node <minikube>: fit true, err <nil>
I1104 15:47:54.082045   65962 predicates.go:229] Toleration/Taint predicates Task <default/qj-1-vfl4v> on Node <minikube>: fit true, err <nil>
I1104 15:47:54.082049   65962 predicate_extension.go:36] Pod qj-1-vfl4v is not batch task
I1104 15:47:54.082053   65962 scheduler_helper.go:89] Predicates failed for task <default/qj-1-vfl4v> on node <minikube>: task default/qj-1-vfl4v on node minikube fit failed: Pod is not a batch task
I1104 15:47:54.082067   65962 statement.go:310] Discarding operations ...
I1104 15:47:54.082075   65962 allocate.go:153] Try to allocate resource to Jobs in Namespace <default> Queue <default>
I1104 15:47:54.082082   65962 allocate.go:157] Can not find jobs for queue default.
I1104 15:47:54.082094   65962 allocate.go:253] Leaving Allocate ...
I1104 15:47:54.082101   65962 backfill.go:42] Enter Backfill ...
I1104 15:47:54.082106   65962 backfill.go:91] Leaving Backfill ...
I1104 15:47:54.089859   65962 cache.go:634] task unscheduleable default/qj-1-vfl4v, message: all nodes are unavailable: 1 Pod is not a batch task., skip by no condition update
I1104 15:47:54.089865   65962 cache.go:634] task unscheduleable default/qj-1-mvb6j, message: 2/2 tasks in gang unschedulable: job is not ready, 2 Pending, 2 minAvailable., skip by no condition update
I1104 15:47:54.089877   65962 session.go:154] Close Session 850da57a-ff5d-11e9-a079-784f43775513
I1104 15:47:54.089883   65962 scheduler.go:87] End scheduling ...
I1104 15:47:56.191242   65962 cache.go:641] Try to delete Job <default/qj-1:default/qj-1>
I1104 15:47:56.197000   65962 cache.go:641] Try to delete Job <default/qj-1:default/qj-1>
I1104 15:47:56.209634   65962 cache.go:641] Try to delete Job <default/qj-1:default/qj-1>
I1104 15:47:56.234213   65962 cache.go:641] Try to delete Job <default/qj-1:default/qj-1>
I1104 15:47:56.274720   65962 cache.go:641] Try to delete Job <default/qj-1:default/qj-1>
I1104 15:47:56.279904   65962 event_handlers.go:215] Updated pod <default/qj-1-mvb6j> in cache.
I1104 15:47:56.283150   65962 event_handlers.go:247] Deleted pod <default/qj-1-mvb6j> from cache.
I1104 15:47:56.293055   65962 cache.go:641] Try to delete Job <default/qj-1:default/qj-1>
I1104 15:47:56.293079   65962 event_handlers.go:215] Updated pod <default/qj-1-vfl4v> in cache.
I1104 15:47:56.295892   65962 cache.go:641] Try to delete Job <default/qj-1:default/qj-1>
I1104 15:47:56.295917   65962 event_handlers.go:247] Deleted pod <default/qj-1-vfl4v> from cache.
I1104 15:47:56.356969   65962 cache.go:665] Job <default/qj-1:default/qj-1> was deleted.
I1104 15:47:59.091812   65962 scheduler.go:72] Start scheduling ...
I1104 15:47:59.091974   65962 cache.go:771] There are <0> Jobs, <1> Queues and <1> Nodes in total for scheduling.
I1104 15:47:59.091982   65962 session.go:135] Open Session 880a283e-ff5d-11e9-a079-784f43775513 with <0> Job and <1> Queues
I1104 15:47:59.092028   65962 proportion.go:67] The total resource is <cpu 4000.00, memory 4959854592.00, hugepages-2Mi 0.00>
I1104 15:47:59.092051   65962 proportion.go:117] Exiting when total weight is 0
I1104 15:47:59.092077   65962 enqueue.go:43] Enter Enqueue ...
I1104 15:47:59.092084   65962 enqueue.go:75] Try to enqueue PodGroup to 0 Queues
I1104 15:47:59.092099   65962 enqueue.go:122] Leaving Enqueue ...
I1104 15:47:59.092107   65962 allocate.go:43] Enter Allocate ...
I1104 15:47:59.092114   65962 allocate.go:94] Try to allocate resource to 0 Namespaces
I1104 15:47:59.092130   65962 allocate.go:253] Leaving Allocate ...
I1104 15:47:59.092135   65962 backfill.go:42] Enter Backfill ...
I1104 15:47:59.092140   65962 backfill.go:91] Leaving Backfill ...
I1104 15:47:59.092156   65962 session.go:154] Close Session 880a283e-ff5d-11e9-a079-784f43775513
I1104 15:47:59.092161   65962 scheduler.go:87] End scheduling ...
I1104 15:48:04.096035   65962 scheduler.go:72] Start scheduling ...
I1104 15:48:04.096155   65962 cache.go:771] There are <0> Jobs, <1> Queues and <1> Nodes in total for scheduling.
I1104 15:48:04.096161   65962 session.go:135] Open Session 8b05bc9c-ff5d-11e9-a079-784f43775513 with <0> Job and <1> Queues
I1104 15:48:04.096199   65962 proportion.go:67] The total resource is <cpu 4000.00, memory 4959854592.00, hugepages-2Mi 0.00>
I1104 15:48:04.096216   65962 proportion.go:117] Exiting when total weight is 0
I1104 15:48:04.096240   65962 enqueue.go:43] Enter Enqueue ...
I1104 15:48:04.096246   65962 enqueue.go:75] Try to enqueue PodGroup to 0 Queues
I1104 15:48:04.096254   65962 enqueue.go:122] Leaving Enqueue ...
I1104 15:48:04.096260   65962 allocate.go:43] Enter Allocate ...
I1104 15:48:04.096265   65962 allocate.go:94] Try to allocate resource to 0 Namespaces
I1104 15:48:04.096276   65962 allocate.go:253] Leaving Allocate ...
I1104 15:48:04.096280   65962 backfill.go:42] Enter Backfill ...
I1104 15:48:04.096283   65962 backfill.go:91] Leaving Backfill ...
I1104 15:48:04.096295   65962 session.go:154] Close Session 8b05bc9c-ff5d-11e9-a079-784f43775513
I1104 15:48:04.096299   65962 scheduler.go:87] End scheduling ...
I1104 15:48:09.098639   65962 scheduler.go:72] Start scheduling ...
I1104 15:48:09.098767   65962 cache.go:771] There are <0> Jobs, <1> Queues and <1> Nodes in total for scheduling.
I1104 15:48:09.098773   65962 session.go:135] Open Session 8e01131a-ff5d-11e9-a079-784f43775513 with <0> Job and <1> Queues
I1104 15:48:09.098803   65962 proportion.go:67] The total resource is <cpu 4000.00, memory 4959854592.00, hugepages-2Mi 0.00>
I1104 15:48:09.098819   65962 proportion.go:117] Exiting when total weight is 0
I1104 15:48:09.098840   65962 enqueue.go:43] Enter Enqueue ...
I1104 15:48:09.098845   65962 enqueue.go:75] Try to enqueue PodGroup to 0 Queues
I1104 15:48:09.098853   65962 enqueue.go:122] Leaving Enqueue ...
I1104 15:48:09.098858   65962 allocate.go:43] Enter Allocate ...
I1104 15:48:09.098863   65962 allocate.go:94] Try to allocate resource to 0 Namespaces
I1104 15:48:09.098874   65962 allocate.go:253] Leaving Allocate ...
I1104 15:48:09.098877   65962 backfill.go:42] Enter Backfill ...
I1104 15:48:09.098880   65962 backfill.go:91] Leaving Backfill ...
I1104 15:48:09.098892   65962 session.go:154] Close Session 8e01131a-ff5d-11e9-a079-784f43775513
I1104 15:48:09.098895   65962 scheduler.go:87] End scheduling ...
I1104 15:48:14.102920   65962 scheduler.go:72] Start scheduling ...
I1104 15:48:14.103088   65962 cache.go:771] There are <0> Jobs, <1> Queues and <1> Nodes in total for scheduling.
I1104 15:48:14.103096   65962 session.go:135] Open Session 90fcabd8-ff5d-11e9-a079-784f43775513 with <0> Job and <1> Queues
I1104 15:48:14.103136   65962 proportion.go:67] The total resource is <cpu 4000.00, memory 4959854592.00, hugepages-2Mi 0.00>
I1104 15:48:14.103159   65962 proportion.go:117] Exiting when total weight is 0
I1104 15:48:14.103194   65962 enqueue.go:43] Enter Enqueue ...
I1104 15:48:14.103201   65962 enqueue.go:75] Try to enqueue PodGroup to 0 Queues
I1104 15:48:14.103210   65962 enqueue.go:122] Leaving Enqueue ...
I1104 15:48:14.103218   65962 allocate.go:43] Enter Allocate ...
I1104 15:48:14.103225   65962 allocate.go:94] Try to allocate resource to 0 Namespaces
I1104 15:48:14.103240   65962 allocate.go:253] Leaving Allocate ...
I1104 15:48:14.103245   65962 backfill.go:42] Enter Backfill ...
I1104 15:48:14.103250   65962 backfill.go:91] Leaving Backfill ...
I1104 15:48:14.103266   65962 session.go:154] Close Session 90fcabd8-ff5d-11e9-a079-784f43775513
I1104 15:48:14.103271   65962 scheduler.go:87] End scheduling ...
I1104 15:48:19.105494   65962 scheduler.go:72] Start scheduling ...
I1104 15:48:19.105618   65962 cache.go:771] There are <0> Jobs, <1> Queues and <1> Nodes in total for scheduling.
I1104 15:48:19.105624   65962 session.go:135] Open Session 93f7ff90-ff5d-11e9-a079-784f43775513 with <0> Job and <1> Queues
I1104 15:48:19.105658   65962 proportion.go:67] The total resource is <cpu 4000.00, memory 4959854592.00, hugepages-2Mi 0.00>
I1104 15:48:19.105674   65962 proportion.go:117] Exiting when total weight is 0
I1104 15:48:19.105689   65962 enqueue.go:43] Enter Enqueue ...
I1104 15:48:19.105693   65962 enqueue.go:75] Try to enqueue PodGroup to 0 Queues
I1104 15:48:19.105699   65962 enqueue.go:122] Leaving Enqueue ...
I1104 15:48:19.105706   65962 allocate.go:43] Enter Allocate ...
I1104 15:48:19.105711   65962 allocate.go:94] Try to allocate resource to 0 Namespaces
I1104 15:48:19.105721   65962 allocate.go:253] Leaving Allocate ...
I1104 15:48:19.105725   65962 backfill.go:42] Enter Backfill ...
I1104 15:48:19.105728   65962 backfill.go:91] Leaving Backfill ...
I1104 15:48:19.105739   65962 session.go:154] Close Session 93f7ff90-ff5d-11e9-a079-784f43775513
I1104 15:48:19.105742   65962 scheduler.go:87] End scheduling ...
F1104 15:48:21.178150   65962 helpers.go:210] Stopped listening on 127.0.0.1:11251 due to error: http: Server closed
goroutine 31 [running]:
volcano.sh/volcano/vendor/github.com/golang/glog.stacks(0xc000010001, 0xc000844000, 0x4b6, 0x2710)
	/Users/yuan.chen/GolandProjects/src/volcano.sh/volcano/vendor/github.com/golang/glog/glog.go:769 +0xb8
volcano.sh/volcano/vendor/github.com/golang/glog.(*loggingT).output(0x2efe3c0, 0xc000000003, 0xc00032e310, 0x2e4a76d, 0xa, 0xd2, 0x0)
	/Users/yuan.chen/GolandProjects/src/volcano.sh/volcano/vendor/github.com/golang/glog/glog.go:723 +0x1b7
volcano.sh/volcano/vendor/github.com/golang/glog.(*loggingT).printf(0x2efe3c0, 0x3, 0x21b0861, 0x13, 0xc00040bf90, 0x2, 0x2)
	/Users/yuan.chen/GolandProjects/src/volcano.sh/volcano/vendor/github.com/golang/glog/glog.go:655 +0x14b
volcano.sh/volcano/vendor/github.com/golang/glog.Fatalf(...)
	/Users/yuan.chen/GolandProjects/src/volcano.sh/volcano/vendor/github.com/golang/glog/glog.go:1148
volcano.sh/volcano/pkg/apis/helpers.runServer.func2(0x23c27e0, 0xc00000ea60, 0xc000288000, 0xc000114a80)
	/Users/yuan.chen/GolandProjects/src/volcano.sh/volcano/pkg/apis/helpers/helpers.go:210 +0x2fc
created by volcano.sh/volcano/pkg/apis/helpers.runServer
	/Users/yuan.chen/GolandProjects/src/volcano.sh/volcano/pkg/apis/helpers/helpers.go:198 +0x170

goroutine 1 [chan receive (nil chan)]:
volcano.sh/volcano/cmd/scheduler/app.Run.func2(0x23d2260, 0xc0000440f8)
	/Users/yuan.chen/GolandProjects/src/volcano.sh/volcano/cmd/scheduler/app/server.go:107 +0x73
volcano.sh/volcano/cmd/scheduler/app.Run(0xc0004f2780, 0x223db28, 0x223cab0)
	/Users/yuan.chen/GolandProjects/src/volcano.sh/volcano/cmd/scheduler/app/server.go:111 +0x79b
main.main()
	/Users/yuan.chen/GolandProjects/src/volcano.sh/volcano/cmd/scheduler/main.go:62 +0x1ae

goroutine 35 [chan receive]:
volcano.sh/volcano/vendor/github.com/golang/glog.(*loggingT).flushDaemon(0x2efe3c0)
	/Users/yuan.chen/GolandProjects/src/volcano.sh/volcano/vendor/github.com/golang/glog/glog.go:882 +0x8b
created by volcano.sh/volcano/vendor/github.com/golang/glog.init.0
	/Users/yuan.chen/GolandProjects/src/volcano.sh/volcano/vendor/github.com/golang/glog/glog.go:410 +0x26f

goroutine 37 [chan receive]:
volcano.sh/volcano/vendor/k8s.io/klog.(*loggingT).flushDaemon(0x2efe560)
	/Users/yuan.chen/GolandProjects/src/volcano.sh/volcano/vendor/k8s.io/klog/klog.go:941 +0x8b
created by volcano.sh/volcano/vendor/k8s.io/klog.init.0
	/Users/yuan.chen/GolandProjects/src/volcano.sh/volcano/vendor/k8s.io/klog/klog.go:403 +0x6c

goroutine 50 [syscall]:
os/signal.signal_recv(0x23a80a0)
	/usr/local/opt/go/libexec/src/runtime/sigqueue.go:144 +0x96
os/signal.loop()
	/usr/local/opt/go/libexec/src/os/signal/signal_unix.go:23 +0x22
created by os/signal.init.0
	/usr/local/opt/go/libexec/src/os/signal/signal_unix.go:29 +0x41

goroutine 45 [sync.Cond.Wait]:
runtime.goparkunlock(...)
	/usr/local/opt/go/libexec/src/runtime/proc.go:310
sync.runtime_notifyListWait(0xc000316028, 0x0)
	/usr/local/opt/go/libexec/src/runtime/sema.go:510 +0xf8
sync.(*Cond).Wait(0xc000316018)
	/usr/local/opt/go/libexec/src/sync/cond.go:56 +0x9d
volcano.sh/volcano/vendor/k8s.io/client-go/tools/cache.(*DeltaFIFO).Pop(0xc000316000, 0xc0000d01f0, 0x0, 0x0, 0x0, 0x0)
	/Users/yuan.chen/GolandProjects/src/volcano.sh/volcano/vendor/k8s.io/client-go/tools/cache/delta_fifo.go:423 +0xa6
volcano.sh/volcano/vendor/k8s.io/client-go/tools/cache.(*controller).processLoop(0xc0003f2000)
	/Users/yuan.chen/GolandProjects/src/volcano.sh/volcano/vendor/k8s.io/client-go/tools/cache/controller.go:150 +0x40
volcano.sh/volcano/vendor/k8s.io/apimachinery/pkg/util/wait.JitterUntil.func1(0xc0005e9e00)
	/Users/yuan.chen/GolandProjects/src/volcano.sh/volcano/vendor/k8s.io/apimachinery/pkg/util/wait/wait.go:133 +0x5e
volcano.sh/volcano/vendor/k8s.io/apimachinery/pkg/util/wait.JitterUntil(0xc0005e9e00, 0x3b9aca00, 0x0, 0xc0001cc101, 0x0)
	/Users/yuan.chen/GolandProjects/src/volcano.sh/volcano/vendor/k8s.io/apimachinery/pkg/util/wait/wait.go:134 +0xf8
volcano.sh/volcano/vendor/k8s.io/apimachinery/pkg/util/wait.Until(...)
	/Users/yuan.chen/GolandProjects/src/volcano.sh/volcano/vendor/k8s.io/apimachinery/pkg/util/wait/wait.go:88
volcano.sh/volcano/vendor/k8s.io/client-go/tools/cache.(*controller).Run(0xc0003f2000, 0x0)
	/Users/yuan.chen/GolandProjects/src/volcano.sh/volcano/vendor/k8s.io/client-go/tools/cache/controller.go:124 +0x2fd
volcano.sh/volcano/vendor/k8s.io/client-go/tools/cache.(*sharedIndexInformer).Run(0xc00003c6c0, 0x0)
	/Users/yuan.chen/GolandProjects/src/volcano.sh/volcano/vendor/k8s.io/client-go/tools/cache/shared_informer.go:227 +0x47f
created by volcano.sh/volcano/pkg/scheduler/cache.(*SchedulerCache).Run
	/Users/yuan.chen/GolandProjects/src/volcano.sh/volcano/pkg/scheduler/cache/cache.go:434 +0x5e

goroutine 5 [select]:
volcano.sh/volcano/vendor/k8s.io/apimachinery/pkg/util/wait.JitterUntil(0x223cab0, 0x12a05f200, 0x0, 0x1, 0xc00016a000)
	/Users/yuan.chen/GolandProjects/src/volcano.sh/volcano/vendor/k8s.io/apimachinery/pkg/util/wait/wait.go:145 +0x181
volcano.sh/volcano/vendor/k8s.io/apimachinery/pkg/util/wait.Until(0x223cab0, 0x12a05f200, 0xc00016a000)
	/Users/yuan.chen/GolandProjects/src/volcano.sh/volcano/vendor/k8s.io/apimachinery/pkg/util/wait/wait.go:88 +0x4d
created by main.main
	/Users/yuan.chen/GolandProjects/src/volcano.sh/volcano/cmd/scheduler/main.go:59 +0x173

goroutine 27 [IO wait]:
internal/poll.runtime_pollWait(0x6900f10, 0x72, 0xffffffffffffffff)
	/usr/local/opt/go/libexec/src/runtime/netpoll.go:184 +0x55
internal/poll.(*pollDesc).wait(0xc000593898, 0x72, 0xc300, 0xc322, 0xffffffffffffffff)
	/usr/local/opt/go/libexec/src/internal/poll/fd_poll_runtime.go:87 +0x45
internal/poll.(*pollDesc).waitRead(...)
	/usr/local/opt/go/libexec/src/internal/poll/fd_poll_runtime.go:92
internal/poll.(*FD).Read(0xc000593880, 0xc000898000, 0xc322, 0xc322, 0x0, 0x0, 0x0)
	/usr/local/opt/go/libexec/src/internal/poll/fd_unix.go:169 +0x22b
net.(*netFD).Read(0xc000593880, 0xc000898000, 0xc322, 0xc322, 0x203000, 0x0, 0xc315)
	/usr/local/opt/go/libexec/src/net/fd_unix.go:202 +0x4f
net.(*conn).Read(0xc00018a258, 0xc000898000, 0xc322, 0xc322, 0x0, 0x0, 0x0)
	/usr/local/opt/go/libexec/src/net/net.go:184 +0x68
crypto/tls.(*atLeastReader).Read(0xc0009abe40, 0xc000898000, 0xc322, 0xc322, 0x7c4, 0x2397f40, 0xc00070d970)
	/usr/local/opt/go/libexec/src/crypto/tls/conn.go:780 +0x60
bytes.(*Buffer).ReadFrom(0xc0005ba5d8, 0x2397da0, 0xc0009abe40, 0x100c165, 0x1ff03e0, 0x21438a0)
	/usr/local/opt/go/libexec/src/bytes/buffer.go:204 +0xb4
crypto/tls.(*Conn).readFromUntil(0xc0005ba380, 0x6900fe0, 0xc00018a258, 0x5, 0xc00018a258, 0x7a7)
	/usr/local/opt/go/libexec/src/crypto/tls/conn.go:802 +0xec
crypto/tls.(*Conn).readRecordOrCCS(0xc0005ba380, 0x0, 0x0, 0xc0009ab920)
	/usr/local/opt/go/libexec/src/crypto/tls/conn.go:609 +0x124
crypto/tls.(*Conn).readRecord(...)
	/usr/local/opt/go/libexec/src/crypto/tls/conn.go:577
crypto/tls.(*Conn).Read(0xc0005ba380, 0xc000655000, 0x1000, 0x1000, 0x0, 0x0, 0x0)
	/usr/local/opt/go/libexec/src/crypto/tls/conn.go:1255 +0x161
bufio.(*Reader).Read(0xc000628360, 0xc0006221f8, 0x9, 0x9, 0x3eca, 0x79e, 0x0)
	/usr/local/opt/go/libexec/src/bufio/bufio.go:226 +0x26a
io.ReadAtLeast(0x2397c00, 0xc000628360, 0xc0006221f8, 0x9, 0x9, 0x9, 0x0, 0x0, 0xc00070df78)
	/usr/local/opt/go/libexec/src/io/io.go:310 +0x87
io.ReadFull(...)
	/usr/local/opt/go/libexec/src/io/io.go:329
volcano.sh/volcano/vendor/golang.org/x/net/http2.readFrameHeader(0xc0006221f8, 0x9, 0x9, 0x2397c00, 0xc000628360, 0x0, 0x0, 0xc0009b78c0, 0x0)
	/Users/yuan.chen/GolandProjects/src/volcano.sh/volcano/vendor/golang.org/x/net/http2/frame.go:237 +0x87
volcano.sh/volcano/vendor/golang.org/x/net/http2.(*Framer).ReadFrame(0xc0006221c0, 0xc0009b78c0, 0x0, 0x0, 0x0)
	/Users/yuan.chen/GolandProjects/src/volcano.sh/volcano/vendor/golang.org/x/net/http2/frame.go:492 +0xa1
volcano.sh/volcano/vendor/golang.org/x/net/http2.(*clientConnReadLoop).run(0xc00070dfb8, 0x14e004d, 0xc0000ea660)
	/Users/yuan.chen/GolandProjects/src/volcano.sh/volcano/vendor/golang.org/x/net/http2/transport.go:1679 +0x8c
volcano.sh/volcano/vendor/golang.org/x/net/http2.(*ClientConn).readLoop(0xc00050f500)
	/Users/yuan.chen/GolandProjects/src/volcano.sh/volcano/vendor/golang.org/x/net/http2/transport.go:1607 +0xa3
created by volcano.sh/volcano/vendor/golang.org/x/net/http2.(*Transport).newClientConn
	/Users/yuan.chen/GolandProjects/src/volcano.sh/volcano/vendor/golang.org/x/net/http2/transport.go:670 +0x62f

goroutine 143 [chan receive]:
volcano.sh/volcano/vendor/k8s.io/client-go/tools/cache.(*processorListener).run.func1.1(0x0, 0x0, 0x0)
	/Users/yuan.chen/GolandProjects/src/volcano.sh/volcano/vendor/k8s.io/client-go/tools/cache/shared_informer.go:549 +0x54
volcano.sh/volcano/vendor/k8s.io/apimachinery/pkg/util/wait.ExponentialBackoff(0x989680, 0x3ff0000000000000, 0x3fb999999999999a, 0x5, 0xc0006e9dd8, 0x0, 0x0)
	/Users/yuan.chen/GolandProjects/src/volcano.sh/volcano/vendor/k8s.io/apimachinery/pkg/util/wait/wait.go:203 +0xde
volcano.sh/volcano/vendor/k8s.io/client-go/tools/cache.(*processorListener).run.func1()
	/Users/yuan.chen/GolandProjects/src/volcano.sh/volcano/vendor/k8s.io/client-go/tools/cache/shared_informer.go:548 +0x89
volcano.sh/volcano/vendor/k8s.io/apimachinery/pkg/util/wait.JitterUntil.func1(0xc00056f740)
	/Users/yuan.chen/GolandProjects/src/volcano.sh/volcano/vendor/k8s.io/apimachinery/pkg/util/wait/wait.go:133 +0x5e
volcano.sh/volcano/vendor/k8s.io/apimachinery/pkg/util/wait.JitterUntil(0xc0006e9f40, 0xdf8475800, 0x0, 0x1030501, 0xc000114d80)
	/Users/yuan.chen/GolandProjects/src/volcano.sh/volcano/vendor/k8s.io/apimachinery/pkg/util/wait/wait.go:134 +0xf8
volcano.sh/volcano/vendor/k8s.io/apimachinery/pkg/util/wait.Until(...)
	/Users/yuan.chen/GolandProjects/src/volcano.sh/volcano/vendor/k8s.io/apimachinery/pkg/util/wait/wait.go:88
volcano.sh/volcano/vendor/k8s.io/client-go/tools/cache.(*processorListener).run(0xc00014c400)
	/Users/yuan.chen/GolandProjects/src/volcano.sh/volcano/vendor/k8s.io/client-go/tools/cache/shared_informer.go:546 +0x9b
volcano.sh/volcano/vendor/k8s.io/apimachinery/pkg/util/wait.(*Group).Start.func1(0xc00036a5a0, 0xc0006a3230)
	/Users/yuan.chen/GolandProjects/src/volcano.sh/volcano/vendor/k8s.io/apimachinery/pkg/util/wait/wait.go:71 +0x59
created by volcano.sh/volcano/vendor/k8s.io/apimachinery/pkg/util/wait.(*Group).Start
	/Users/yuan.chen/GolandProjects/src/volcano.sh/volcano/vendor/k8s.io/apimachinery/pkg/util/wait/wait.go:69 +0x62

goroutine 104 [chan receive]:
volcano.sh/volcano/vendor/k8s.io/client-go/tools/cache.(*sharedProcessor).run(0xc00036a310, 0xc0003b6060)
	/Users/yuan.chen/GolandProjects/src/volcano.sh/volcano/vendor/k8s.io/client-go/tools/cache/shared_informer.go:425 +0x49
volcano.sh/volcano/vendor/k8s.io/apimachinery/pkg/util/wait.(*Group).StartWithChannel.func1()
	/Users/yuan.chen/GolandProjects/src/volcano.sh/volcano/vendor/k8s.io/apimachinery/pkg/util/wait/wait.go:54 +0x2e
volcano.sh/volcano/vendor/k8s.io/apimachinery/pkg/util/wait.(*Group).Start.func1(0xc000384430, 0xc00063e580)
	/Users/yuan.chen/GolandProjects/src/volcano.sh/volcano/vendor/k8s.io/apimachinery/pkg/util/wait/wait.go:71 +0x59
created by volcano.sh/volcano/vendor/k8s.io/apimachinery/pkg/util/wait.(*Group).Start
	/Users/yuan.chen/GolandProjects/src/volcano.sh/volcano/vendor/k8s.io/apimachinery/pkg/util/wait/wait.go:69 +0x62

goroutine 61 [chan receive]:
volcano.sh/volcano/vendor/k8s.io/client-go/util/workqueue.(*Type).updateUnfinishedWorkLoop(0xc0003c0180)
	/Users/yuan.chen/GolandProjects/src/volcano.sh/volcano/vendor/k8s.io/client-go/util/workqueue/queue.go:198 +0xe0
created by volcano.sh/volcano/vendor/k8s.io/client-go/util/workqueue.newQueue
	/Users/yuan.chen/GolandProjects/src/volcano.sh/volcano/vendor/k8s.io/client-go/util/workqueue/queue.go:58 +0x132

goroutine 62 [select]:
volcano.sh/volcano/vendor/k8s.io/client-go/util/workqueue.(*delayingType).waitingLoop(0xc0001642d0)
	/Users/yuan.chen/GolandProjects/src/volcano.sh/volcano/vendor/k8s.io/client-go/util/workqueue/delaying_queue.go:206 +0x344
created by volcano.sh/volcano/vendor/k8s.io/client-go/util/workqueue.newDelayingQueue
	/Users/yuan.chen/GolandProjects/src/volcano.sh/volcano/vendor/k8s.io/client-go/util/workqueue/delaying_queue.go:54 +0x1ae

goroutine 63 [chan receive]:
volcano.sh/volcano/vendor/k8s.io/client-go/util/workqueue.(*Type).updateUnfinishedWorkLoop(0xc0003c0360)
	/Users/yuan.chen/GolandProjects/src/volcano.sh/volcano/vendor/k8s.io/client-go/util/workqueue/queue.go:198 +0xe0
created by volcano.sh/volcano/vendor/k8s.io/client-go/util/workqueue.newQueue
	/Users/yuan.chen/GolandProjects/src/volcano.sh/volcano/vendor/k8s.io/client-go/util/workqueue/queue.go:58 +0x132

goroutine 64 [select]:
volcano.sh/volcano/vendor/k8s.io/client-go/util/workqueue.(*delayingType).waitingLoop(0xc0001643c0)
	/Users/yuan.chen/GolandProjects/src/volcano.sh/volcano/vendor/k8s.io/client-go/util/workqueue/delaying_queue.go:206 +0x344
created by volcano.sh/volcano/vendor/k8s.io/client-go/util/workqueue.newDelayingQueue
	/Users/yuan.chen/GolandProjects/src/volcano.sh/volcano/vendor/k8s.io/client-go/util/workqueue/delaying_queue.go:54 +0x1ae

goroutine 65 [chan receive]:
volcano.sh/volcano/vendor/k8s.io/apimachinery/pkg/watch.(*Broadcaster).loop(0xc0000bc500)
	/Users/yuan.chen/GolandProjects/src/volcano.sh/volcano/vendor/k8s.io/apimachinery/pkg/watch/mux.go:207 +0x66
created by volcano.sh/volcano/vendor/k8s.io/apimachinery/pkg/watch.NewBroadcaster
	/Users/yuan.chen/GolandProjects/src/volcano.sh/volcano/vendor/k8s.io/apimachinery/pkg/watch/mux.go:75 +0xcc

goroutine 130 [chan receive]:
volcano.sh/volcano/vendor/k8s.io/client-go/tools/record.(*eventBroadcasterImpl).StartEventWatcher.func1(0x23a38a0, 0xc000400cc0, 0xc000400c90)
	/Users/yuan.chen/GolandProjects/src/volcano.sh/volcano/vendor/k8s.io/client-go/tools/record/event.go:231 +0xc5
created by volcano.sh/volcano/vendor/k8s.io/client-go/tools/record.(*eventBroadcasterImpl).StartEventWatcher
	/Users/yuan.chen/GolandProjects/src/volcano.sh/volcano/vendor/k8s.io/client-go/tools/record/event.go:229 +0x6e

goroutine 131 [IO wait]:
internal/poll.runtime_pollWait(0x6900d70, 0x72, 0x0)
	/usr/local/opt/go/libexec/src/runtime/netpoll.go:184 +0x55
internal/poll.(*pollDesc).wait(0xc00019a018, 0x72, 0x0, 0x0, 0x21a2933)
	/usr/local/opt/go/libexec/src/internal/poll/fd_poll_runtime.go:87 +0x45
internal/poll.(*pollDesc).waitRead(...)
	/usr/local/opt/go/libexec/src/internal/poll/fd_poll_runtime.go:92
internal/poll.(*FD).Accept(0xc00019a000, 0x0, 0x0, 0x0, 0x0, 0x0, 0x0, 0x0)
	/usr/local/opt/go/libexec/src/internal/poll/fd_unix.go:384 +0x1f8
net.(*netFD).accept(0xc00019a000, 0xc000083d40, 0xc00009e800, 0x3391d98)
	/usr/local/opt/go/libexec/src/net/fd_unix.go:238 +0x42
net.(*TCPListener).accept(0xc0004b04c0, 0xc000083d70, 0x100eac8, 0x30)
	/usr/local/opt/go/libexec/src/net/tcpsock_posix.go:139 +0x32
net.(*TCPListener).Accept(0xc0004b04c0, 0x20c6980, 0xc0005c45a0, 0x1fb6ee0, 0x2ee59d0)
	/usr/local/opt/go/libexec/src/net/tcpsock.go:261 +0x47
net/http.(*Server).Serve(0xc000622000, 0x23c27e0, 0xc0004b04c0, 0x0, 0x0)
	/usr/local/opt/go/libexec/src/net/http/server.go:2896 +0x286
net/http.(*Server).ListenAndServe(0xc000622000, 0xc000622000, 0x8)
	/usr/local/opt/go/libexec/src/net/http/server.go:2825 +0xb7
net/http.ListenAndServe(...)
	/usr/local/opt/go/libexec/src/net/http/server.go:3080
volcano.sh/volcano/cmd/scheduler/app.Run.func1(0xc0004f2780)
	/Users/yuan.chen/GolandProjects/src/volcano.sh/volcano/cmd/scheduler/app/server.go:98 +0xd1
created by volcano.sh/volcano/cmd/scheduler/app.Run
	/Users/yuan.chen/GolandProjects/src/volcano.sh/volcano/cmd/scheduler/app/server.go:96 +0x11e

goroutine 12 [chan receive]:
volcano.sh/volcano/vendor/k8s.io/client-go/tools/cache.(*processorListener).run.func1.1(0x1c0, 0x400, 0x400)
	/Users/yuan.chen/GolandProjects/src/volcano.sh/volcano/vendor/k8s.io/client-go/tools/cache/shared_informer.go:549 +0x54
volcano.sh/volcano/vendor/k8s.io/apimachinery/pkg/util/wait.ExponentialBackoff(0x989680, 0x3ff0000000000000, 0x3fb999999999999a, 0x5, 0xc000409dd8, 0x101984e, 0x6402d30)
	/Users/yuan.chen/GolandProjects/src/volcano.sh/volcano/vendor/k8s.io/apimachinery/pkg/util/wait/wait.go:203 +0xde
volcano.sh/volcano/vendor/k8s.io/client-go/tools/cache.(*processorListener).run.func1()
	/Users/yuan.chen/GolandProjects/src/volcano.sh/volcano/vendor/k8s.io/client-go/tools/cache/shared_informer.go:548 +0x89
volcano.sh/volcano/vendor/k8s.io/apimachinery/pkg/util/wait.JitterUntil.func1(0xc00038ef40)
	/Users/yuan.chen/GolandProjects/src/volcano.sh/volcano/vendor/k8s.io/apimachinery/pkg/util/wait/wait.go:133 +0x5e
volcano.sh/volcano/vendor/k8s.io/apimachinery/pkg/util/wait.JitterUntil(0xc000409f40, 0xdf8475800, 0x0, 0x1030501, 0xc00016a300)
	/Users/yuan.chen/GolandProjects/src/volcano.sh/volcano/vendor/k8s.io/apimachinery/pkg/util/wait/wait.go:134 +0xf8
volcano.sh/volcano/vendor/k8s.io/apimachinery/pkg/util/wait.Until(...)
	/Users/yuan.chen/GolandProjects/src/volcano.sh/volcano/vendor/k8s.io/apimachinery/pkg/util/wait/wait.go:88
volcano.sh/volcano/vendor/k8s.io/client-go/tools/cache.(*processorListener).run(0xc000507b00)
	/Users/yuan.chen/GolandProjects/src/volcano.sh/volcano/vendor/k8s.io/client-go/tools/cache/shared_informer.go:546 +0x9b
volcano.sh/volcano/vendor/k8s.io/apimachinery/pkg/util/wait.(*Group).Start.func1(0xc00036a3e0, 0xc000364560)
	/Users/yuan.chen/GolandProjects/src/volcano.sh/volcano/vendor/k8s.io/apimachinery/pkg/util/wait/wait.go:71 +0x59
created by volcano.sh/volcano/vendor/k8s.io/apimachinery/pkg/util/wait.(*Group).Start
	/Users/yuan.chen/GolandProjects/src/volcano.sh/volcano/vendor/k8s.io/apimachinery/pkg/util/wait/wait.go:69 +0x62

goroutine 33 [select]:
volcano.sh/volcano/vendor/k8s.io/apimachinery/pkg/util/wait.poller.func1.1(0xc0000c0180, 0x5f5e100, 0x0, 0x0)
	/Users/yuan.chen/GolandProjects/src/volcano.sh/volcano/vendor/k8s.io/apimachinery/pkg/util/wait/wait.go:374 +0x18e
created by volcano.sh/volcano/vendor/k8s.io/apimachinery/pkg/util/wait.poller.func1
	/Users/yuan.chen/GolandProjects/src/volcano.sh/volcano/vendor/k8s.io/apimachinery/pkg/util/wait/wait.go:357 +0x8c

goroutine 46 [sync.Cond.Wait]:
runtime.goparkunlock(...)
	/usr/local/opt/go/libexec/src/runtime/proc.go:310
sync.runtime_notifyListWait(0xc0001182e8, 0x9)
	/usr/local/opt/go/libexec/src/runtime/sema.go:510 +0xf8
sync.(*Cond).Wait(0xc0001182d8)
	/usr/local/opt/go/libexec/src/sync/cond.go:56 +0x9d
volcano.sh/volcano/vendor/k8s.io/client-go/tools/cache.(*DeltaFIFO).Pop(0xc0001182c0, 0xc000364040, 0x0, 0x0, 0x0, 0x0)
	/Users/yuan.chen/GolandProjects/src/volcano.sh/volcano/vendor/k8s.io/client-go/tools/cache/delta_fifo.go:423 +0xa6
volcano.sh/volcano/vendor/k8s.io/client-go/tools/cache.(*controller).processLoop(0xc000470000)
	/Users/yuan.chen/GolandProjects/src/volcano.sh/volcano/vendor/k8s.io/client-go/tools/cache/controller.go:150 +0x40
volcano.sh/volcano/vendor/k8s.io/apimachinery/pkg/util/wait.JitterUntil.func1(0xc000407e00)
	/Users/yuan.chen/GolandProjects/src/volcano.sh/volcano/vendor/k8s.io/apimachinery/pkg/util/wait/wait.go:133 +0x5e
volcano.sh/volcano/vendor/k8s.io/apimachinery/pkg/util/wait.JitterUntil(0xc000407e00, 0x3b9aca00, 0x0, 0xc0005baa01, 0x0)
	/Users/yuan.chen/GolandProjects/src/volcano.sh/volcano/vendor/k8s.io/apimachinery/pkg/util/wait/wait.go:134 +0xf8
volcano.sh/volcano/vendor/k8s.io/apimachinery/pkg/util/wait.Until(...)
	/Users/yuan.chen/GolandProjects/src/volcano.sh/volcano/vendor/k8s.io/apimachinery/pkg/util/wait/wait.go:88
volcano.sh/volcano/vendor/k8s.io/client-go/tools/cache.(*controller).Run(0xc000470000, 0x0)
	/Users/yuan.chen/GolandProjects/src/volcano.sh/volcano/vendor/k8s.io/client-go/tools/cache/controller.go:124 +0x2fd
volcano.sh/volcano/vendor/k8s.io/client-go/tools/cache.(*sharedIndexInformer).Run(0xc00003c630, 0x0)
	/Users/yuan.chen/GolandProjects/src/volcano.sh/volcano/vendor/k8s.io/client-go/tools/cache/shared_informer.go:227 +0x47f
created by volcano.sh/volcano/pkg/scheduler/cache.(*SchedulerCache).Run
	/Users/yuan.chen/GolandProjects/src/volcano.sh/volcano/pkg/scheduler/cache/cache.go:435 +0x9b

goroutine 47 [sync.Cond.Wait]:
runtime.goparkunlock(...)
	/usr/local/opt/go/libexec/src/runtime/proc.go:310
sync.runtime_notifyListWait(0xc0001184f8, 0x2)
	/usr/local/opt/go/libexec/src/runtime/sema.go:510 +0xf8
sync.(*Cond).Wait(0xc0001184e8)
	/usr/local/opt/go/libexec/src/sync/cond.go:56 +0x9d
volcano.sh/volcano/vendor/k8s.io/client-go/tools/cache.(*DeltaFIFO).Pop(0xc0001184d0, 0xc0003645a0, 0x0, 0x0, 0x0, 0x0)
	/Users/yuan.chen/GolandProjects/src/volcano.sh/volcano/vendor/k8s.io/client-go/tools/cache/delta_fifo.go:423 +0xa6
volcano.sh/volcano/vendor/k8s.io/client-go/tools/cache.(*controller).processLoop(0xc000470700)
	/Users/yuan.chen/GolandProjects/src/volcano.sh/volcano/vendor/k8s.io/client-go/tools/cache/controller.go:150 +0x40
volcano.sh/volcano/vendor/k8s.io/apimachinery/pkg/util/wait.JitterUntil.func1(0xc00040ae00)
	/Users/yuan.chen/GolandProjects/src/volcano.sh/volcano/vendor/k8s.io/apimachinery/pkg/util/wait/wait.go:133 +0x5e
volcano.sh/volcano/vendor/k8s.io/apimachinery/pkg/util/wait.JitterUntil(0xc00040ae00, 0x3b9aca00, 0x0, 0xc0001d0501, 0x0)
	/Users/yuan.chen/GolandProjects/src/volcano.sh/volcano/vendor/k8s.io/apimachinery/pkg/util/wait/wait.go:134 +0xf8
volcano.sh/volcano/vendor/k8s.io/apimachinery/pkg/util/wait.Until(...)
	/Users/yuan.chen/GolandProjects/src/volcano.sh/volcano/vendor/k8s.io/apimachinery/pkg/util/wait/wait.go:88
volcano.sh/volcano/vendor/k8s.io/client-go/tools/cache.(*controller).Run(0xc000470700, 0x0)
	/Users/yuan.chen/GolandProjects/src/volcano.sh/volcano/vendor/k8s.io/client-go/tools/cache/controller.go:124 +0x2fd
volcano.sh/volcano/vendor/k8s.io/client-go/tools/cache.(*sharedIndexInformer).Run(0xc00003c5a0, 0x0)
	/Users/yuan.chen/GolandProjects/src/volcano.sh/volcano/vendor/k8s.io/client-go/tools/cache/shared_informer.go:227 +0x47f
created by volcano.sh/volcano/pkg/scheduler/cache.(*SchedulerCache).Run
	/Users/yuan.chen/GolandProjects/src/volcano.sh/volcano/pkg/scheduler/cache/cache.go:436 +0xd8

goroutine 48 [sync.Cond.Wait]:
runtime.goparkunlock(...)
	/usr/local/opt/go/libexec/src/runtime/proc.go:310
sync.runtime_notifyListWait(0xc000316188, 0x6)
	/usr/local/opt/go/libexec/src/runtime/sema.go:510 +0xf8
sync.(*Cond).Wait(0xc000316178)
	/usr/local/opt/go/libexec/src/sync/cond.go:56 +0x9d
volcano.sh/volcano/vendor/k8s.io/client-go/tools/cache.(*DeltaFIFO).Pop(0xc000316160, 0xc0000d0ab0, 0x0, 0x0, 0x0, 0x0)
	/Users/yuan.chen/GolandProjects/src/volcano.sh/volcano/vendor/k8s.io/client-go/tools/cache/delta_fifo.go:423 +0xa6
volcano.sh/volcano/vendor/k8s.io/client-go/tools/cache.(*controller).processLoop(0xc0003f2b80)
	/Users/yuan.chen/GolandProjects/src/volcano.sh/volcano/vendor/k8s.io/client-go/tools/cache/controller.go:150 +0x40
volcano.sh/volcano/vendor/k8s.io/apimachinery/pkg/util/wait.JitterUntil.func1(0xc0006efe00)
	/Users/yuan.chen/GolandProjects/src/volcano.sh/volcano/vendor/k8s.io/apimachinery/pkg/util/wait/wait.go:133 +0x5e
volcano.sh/volcano/vendor/k8s.io/apimachinery/pkg/util/wait.JitterUntil(0xc0006efe00, 0x3b9aca00, 0x0, 0xc0000a1c01, 0x0)
	/Users/yuan.chen/GolandProjects/src/volcano.sh/volcano/vendor/k8s.io/apimachinery/pkg/util/wait/wait.go:134 +0xf8
volcano.sh/volcano/vendor/k8s.io/apimachinery/pkg/util/wait.Until(...)
	/Users/yuan.chen/GolandProjects/src/volcano.sh/volcano/vendor/k8s.io/apimachinery/pkg/util/wait/wait.go:88
volcano.sh/volcano/vendor/k8s.io/client-go/tools/cache.(*controller).Run(0xc0003f2b80, 0x0)
	/Users/yuan.chen/GolandProjects/src/volcano.sh/volcano/vendor/k8s.io/client-go/tools/cache/controller.go:124 +0x2fd
volcano.sh/volcano/vendor/k8s.io/client-go/tools/cache.(*sharedIndexInformer).Run(0xc00003c870, 0x0)
	/Users/yuan.chen/GolandProjects/src/volcano.sh/volcano/vendor/k8s.io/client-go/tools/cache/shared_informer.go:227 +0x47f
created by volcano.sh/volcano/pkg/scheduler/cache.(*SchedulerCache).Run
	/Users/yuan.chen/GolandProjects/src/volcano.sh/volcano/pkg/scheduler/cache/cache.go:437 +0x118

goroutine 49 [sync.Cond.Wait]:
runtime.goparkunlock(...)
	/usr/local/opt/go/libexec/src/runtime/proc.go:310
sync.runtime_notifyListWait(0xc0001da188, 0x0)
	/usr/local/opt/go/libexec/src/runtime/sema.go:510 +0xf8
sync.(*Cond).Wait(0xc0001da178)
	/usr/local/opt/go/libexec/src/sync/cond.go:56 +0x9d
volcano.sh/volcano/vendor/k8s.io/client-go/tools/cache.(*DeltaFIFO).Pop(0xc0001da160, 0xc0006a3260, 0x0, 0x0, 0x0, 0x0)
	/Users/yuan.chen/GolandProjects/src/volcano.sh/volcano/vendor/k8s.io/client-go/tools/cache/delta_fifo.go:423 +0xa6
volcano.sh/volcano/vendor/k8s.io/client-go/tools/cache.(*controller).processLoop(0xc00014dd00)
	/Users/yuan.chen/GolandProjects/src/volcano.sh/volcano/vendor/k8s.io/client-go/tools/cache/controller.go:150 +0x40
volcano.sh/volcano/vendor/k8s.io/apimachinery/pkg/util/wait.JitterUntil.func1(0xc0005e3e00)
	/Users/yuan.chen/GolandProjects/src/volcano.sh/volcano/vendor/k8s.io/apimachinery/pkg/util/wait/wait.go:133 +0x5e
volcano.sh/volcano/vendor/k8s.io/apimachinery/pkg/util/wait.JitterUntil(0xc0005e3e00, 0x3b9aca00, 0x0, 0xc00050f801, 0x0)
	/Users/yuan.chen/GolandProjects/src/volcano.sh/volcano/vendor/k8s.io/apimachinery/pkg/util/wait/wait.go:134 +0xf8
volcano.sh/volcano/vendor/k8s.io/apimachinery/pkg/util/wait.Until(...)
	/Users/yuan.chen/GolandProjects/src/volcano.sh/volcano/vendor/k8s.io/apimachinery/pkg/util/wait/wait.go:88
volcano.sh/volcano/vendor/k8s.io/client-go/tools/cache.(*controller).Run(0xc00014dd00, 0x0)
	/Users/yuan.chen/GolandProjects/src/volcano.sh/volcano/vendor/k8s.io/client-go/tools/cache/controller.go:124 +0x2fd
volcano.sh/volcano/vendor/k8s.io/client-go/tools/cache.(*sharedIndexInformer).Run(0xc00003c900, 0x0)
	/Users/yuan.chen/GolandProjects/src/volcano.sh/volcano/vendor/k8s.io/client-go/tools/cache/shared_informer.go:227 +0x47f
created by volcano.sh/volcano/pkg/scheduler/cache.(*SchedulerCache).Run
	/Users/yuan.chen/GolandProjects/src/volcano.sh/volcano/pkg/scheduler/cache/cache.go:438 +0x15b

goroutine 146 [sync.Cond.Wait]:
runtime.goparkunlock(...)
	/usr/local/opt/go/libexec/src/runtime/proc.go:310
sync.runtime_notifyListWait(0xc0001702e8, 0x0)
	/usr/local/opt/go/libexec/src/runtime/sema.go:510 +0xf8
sync.(*Cond).Wait(0xc0001702d8)
	/usr/local/opt/go/libexec/src/sync/cond.go:56 +0x9d
volcano.sh/volcano/vendor/k8s.io/client-go/tools/cache.(*DeltaFIFO).Pop(0xc0001702c0, 0xc000084e50, 0x0, 0x0, 0x0, 0x0)
	/Users/yuan.chen/GolandProjects/src/volcano.sh/volcano/vendor/k8s.io/client-go/tools/cache/delta_fifo.go:423 +0xa6
volcano.sh/volcano/vendor/k8s.io/client-go/tools/cache.(*controller).processLoop(0xc00019a780)
	/Users/yuan.chen/GolandProjects/src/volcano.sh/volcano/vendor/k8s.io/client-go/tools/cache/controller.go:150 +0x40
volcano.sh/volcano/vendor/k8s.io/apimachinery/pkg/util/wait.JitterUntil.func1(0xc00007ce00)
	/Users/yuan.chen/GolandProjects/src/volcano.sh/volcano/vendor/k8s.io/apimachinery/pkg/util/wait/wait.go:133 +0x5e
volcano.sh/volcano/vendor/k8s.io/apimachinery/pkg/util/wait.JitterUntil(0xc00007ce00, 0x3b9aca00, 0x0, 0xc0001cf901, 0x0)
	/Users/yuan.chen/GolandProjects/src/volcano.sh/volcano/vendor/k8s.io/apimachinery/pkg/util/wait/wait.go:134 +0xf8
volcano.sh/volcano/vendor/k8s.io/apimachinery/pkg/util/wait.Until(...)
	/Users/yuan.chen/GolandProjects/src/volcano.sh/volcano/vendor/k8s.io/apimachinery/pkg/util/wait/wait.go:88
volcano.sh/volcano/vendor/k8s.io/client-go/tools/cache.(*controller).Run(0xc00019a780, 0x0)
	/Users/yuan.chen/GolandProjects/src/volcano.sh/volcano/vendor/k8s.io/client-go/tools/cache/controller.go:124 +0x2fd
volcano.sh/volcano/vendor/k8s.io/client-go/tools/cache.(*sharedIndexInformer).Run(0xc00003c510, 0x0)
	/Users/yuan.chen/GolandProjects/src/volcano.sh/volcano/vendor/k8s.io/client-go/tools/cache/shared_informer.go:227 +0x47f
created by volcano.sh/volcano/pkg/scheduler/cache.(*SchedulerCache).Run
	/Users/yuan.chen/GolandProjects/src/volcano.sh/volcano/pkg/scheduler/cache/cache.go:439 +0x19e

goroutine 147 [sync.Cond.Wait]:
runtime.goparkunlock(...)
	/usr/local/opt/go/libexec/src/runtime/proc.go:310
sync.runtime_notifyListWait(0xc0003e4028, 0x0)
	/usr/local/opt/go/libexec/src/runtime/sema.go:510 +0xf8
sync.(*Cond).Wait(0xc0003e4018)
	/usr/local/opt/go/libexec/src/sync/cond.go:56 +0x9d
volcano.sh/volcano/vendor/k8s.io/client-go/tools/cache.(*DeltaFIFO).Pop(0xc0003e4000, 0xc00063a010, 0x0, 0x0, 0x0, 0x0)
	/Users/yuan.chen/GolandProjects/src/volcano.sh/volcano/vendor/k8s.io/client-go/tools/cache/delta_fifo.go:423 +0xa6
volcano.sh/volcano/vendor/k8s.io/client-go/tools/cache.(*controller).processLoop(0xc0004d4000)
	/Users/yuan.chen/GolandProjects/src/volcano.sh/volcano/vendor/k8s.io/client-go/tools/cache/controller.go:150 +0x40
volcano.sh/volcano/vendor/k8s.io/apimachinery/pkg/util/wait.JitterUntil.func1(0xc000573e00)
	/Users/yuan.chen/GolandProjects/src/volcano.sh/volcano/vendor/k8s.io/apimachinery/pkg/util/wait/wait.go:133 +0x5e
volcano.sh/volcano/vendor/k8s.io/apimachinery/pkg/util/wait.JitterUntil(0xc000573e00, 0x3b9aca00, 0x0, 0xc000192701, 0x0)
	/Users/yuan.chen/GolandProjects/src/volcano.sh/volcano/vendor/k8s.io/apimachinery/pkg/util/wait/wait.go:134 +0xf8
volcano.sh/volcano/vendor/k8s.io/apimachinery/pkg/util/wait.Until(...)
	/Users/yuan.chen/GolandProjects/src/volcano.sh/volcano/vendor/k8s.io/apimachinery/pkg/util/wait/wait.go:88
volcano.sh/volcano/vendor/k8s.io/client-go/tools/cache.(*controller).Run(0xc0004d4000, 0x0)
	/Users/yuan.chen/GolandProjects/src/volcano.sh/volcano/vendor/k8s.io/client-go/tools/cache/controller.go:124 +0x2fd
volcano.sh/volcano/vendor/k8s.io/client-go/tools/cache.(*sharedIndexInformer).Run(0xc00003c480, 0x0)
	/Users/yuan.chen/GolandProjects/src/volcano.sh/volcano/vendor/k8s.io/client-go/tools/cache/shared_informer.go:227 +0x47f
created by volcano.sh/volcano/pkg/scheduler/cache.(*SchedulerCache).Run
	/Users/yuan.chen/GolandProjects/src/volcano.sh/volcano/pkg/scheduler/cache/cache.go:440 +0x1e1

goroutine 148 [sync.Cond.Wait]:
runtime.goparkunlock(...)
	/usr/local/opt/go/libexec/src/runtime/proc.go:310
sync.runtime_notifyListWait(0xc0003ae028, 0x1)
	/usr/local/opt/go/libexec/src/runtime/sema.go:510 +0xf8
sync.(*Cond).Wait(0xc0003ae018)
	/usr/local/opt/go/libexec/src/sync/cond.go:56 +0x9d
volcano.sh/volcano/vendor/k8s.io/client-go/tools/cache.(*DeltaFIFO).Pop(0xc0003ae000, 0xc000166100, 0x0, 0x0, 0x0, 0x0)
	/Users/yuan.chen/GolandProjects/src/volcano.sh/volcano/vendor/k8s.io/client-go/tools/cache/delta_fifo.go:423 +0xa6
volcano.sh/volcano/vendor/k8s.io/client-go/tools/cache.(*controller).processLoop(0xc000532080)
	/Users/yuan.chen/GolandProjects/src/volcano.sh/volcano/vendor/k8s.io/client-go/tools/cache/controller.go:150 +0x40
volcano.sh/volcano/vendor/k8s.io/apimachinery/pkg/util/wait.JitterUntil.func1(0xc0005d9e00)
	/Users/yuan.chen/GolandProjects/src/volcano.sh/volcano/vendor/k8s.io/apimachinery/pkg/util/wait/wait.go:133 +0x5e
volcano.sh/volcano/vendor/k8s.io/apimachinery/pkg/util/wait.JitterUntil(0xc0005d9e00, 0x3b9aca00, 0x0, 0xc0000a1901, 0x0)
	/Users/yuan.chen/GolandProjects/src/volcano.sh/volcano/vendor/k8s.io/apimachinery/pkg/util/wait/wait.go:134 +0xf8
volcano.sh/volcano/vendor/k8s.io/apimachinery/pkg/util/wait.Until(...)
	/Users/yuan.chen/GolandProjects/src/volcano.sh/volcano/vendor/k8s.io/apimachinery/pkg/util/wait/wait.go:88
volcano.sh/volcano/vendor/k8s.io/client-go/tools/cache.(*controller).Run(0xc000532080, 0x0)
	/Users/yuan.chen/GolandProjects/src/volcano.sh/volcano/vendor/k8s.io/client-go/tools/cache/controller.go:124 +0x2fd
volcano.sh/volcano/vendor/k8s.io/client-go/tools/cache.(*sharedIndexInformer).Run(0xc00003c3f0, 0x0)
	/Users/yuan.chen/GolandProjects/src/volcano.sh/volcano/vendor/k8s.io/client-go/tools/cache/shared_informer.go:227 +0x47f
created by volcano.sh/volcano/pkg/scheduler/cache.(*SchedulerCache).Run
	/Users/yuan.chen/GolandProjects/src/volcano.sh/volcano/pkg/scheduler/cache/cache.go:441 +0x224

goroutine 149 [sync.Cond.Wait]:
runtime.goparkunlock(...)
	/usr/local/opt/go/libexec/src/runtime/proc.go:310
sync.runtime_notifyListWait(0xc0001da028, 0x1)
	/usr/local/opt/go/libexec/src/runtime/sema.go:510 +0xf8
sync.(*Cond).Wait(0xc0001da018)
	/usr/local/opt/go/libexec/src/sync/cond.go:56 +0x9d
volcano.sh/volcano/vendor/k8s.io/client-go/tools/cache.(*DeltaFIFO).Pop(0xc0001da000, 0xc0006a3000, 0x0, 0x0, 0x0, 0x0)
	/Users/yuan.chen/GolandProjects/src/volcano.sh/volcano/vendor/k8s.io/client-go/tools/cache/delta_fifo.go:423 +0xa6
volcano.sh/volcano/vendor/k8s.io/client-go/tools/cache.(*controller).processLoop(0xc00014c600)
	/Users/yuan.chen/GolandProjects/src/volcano.sh/volcano/vendor/k8s.io/client-go/tools/cache/controller.go:150 +0x40
volcano.sh/volcano/vendor/k8s.io/apimachinery/pkg/util/wait.JitterUntil.func1(0xc00007ee00)
	/Users/yuan.chen/GolandProjects/src/volcano.sh/volcano/vendor/k8s.io/apimachinery/pkg/util/wait/wait.go:133 +0x5e
volcano.sh/volcano/vendor/k8s.io/apimachinery/pkg/util/wait.JitterUntil(0xc00007ee00, 0x3b9aca00, 0x0, 0xc0001ccd01, 0x0)
	/Users/yuan.chen/GolandProjects/src/volcano.sh/volcano/vendor/k8s.io/apimachinery/pkg/util/wait/wait.go:134 +0xf8
volcano.sh/volcano/vendor/k8s.io/apimachinery/pkg/util/wait.Until(...)
	/Users/yuan.chen/GolandProjects/src/volcano.sh/volcano/vendor/k8s.io/apimachinery/pkg/util/wait/wait.go:88
volcano.sh/volcano/vendor/k8s.io/client-go/tools/cache.(*controller).Run(0xc00014c600, 0x0)
	/Users/yuan.chen/GolandProjects/src/volcano.sh/volcano/vendor/k8s.io/client-go/tools/cache/controller.go:124 +0x2fd
volcano.sh/volcano/vendor/k8s.io/client-go/tools/cache.(*sharedIndexInformer).Run(0xc00003c990, 0x0)
	/Users/yuan.chen/GolandProjects/src/volcano.sh/volcano/vendor/k8s.io/client-go/tools/cache/shared_informer.go:227 +0x47f
created by volcano.sh/volcano/pkg/scheduler/cache.(*SchedulerCache).Run
	/Users/yuan.chen/GolandProjects/src/volcano.sh/volcano/pkg/scheduler/cache/cache.go:442 +0x267

goroutine 150 [sync.Cond.Wait]:
runtime.goparkunlock(...)
	/usr/local/opt/go/libexec/src/runtime/proc.go:310
sync.runtime_notifyListWait(0xc000366028, 0x1)
	/usr/local/opt/go/libexec/src/runtime/sema.go:510 +0xf8
sync.(*Cond).Wait(0xc000366018)
	/usr/local/opt/go/libexec/src/sync/cond.go:56 +0x9d
volcano.sh/volcano/vendor/k8s.io/client-go/tools/cache.(*DeltaFIFO).Pop(0xc000366000, 0xc000500880, 0x0, 0x0, 0x0, 0x0)
	/Users/yuan.chen/GolandProjects/src/volcano.sh/volcano/vendor/k8s.io/client-go/tools/cache/delta_fifo.go:423 +0xa6
volcano.sh/volcano/vendor/k8s.io/client-go/tools/cache.(*controller).processLoop(0xc000152300)
	/Users/yuan.chen/GolandProjects/src/volcano.sh/volcano/vendor/k8s.io/client-go/tools/cache/controller.go:150 +0x40
volcano.sh/volcano/vendor/k8s.io/apimachinery/pkg/util/wait.JitterUntil.func1(0xc0005dde00)
	/Users/yuan.chen/GolandProjects/src/volcano.sh/volcano/vendor/k8s.io/apimachinery/pkg/util/wait/wait.go:133 +0x5e
volcano.sh/volcano/vendor/k8s.io/apimachinery/pkg/util/wait.JitterUntil(0xc0005dde00, 0x3b9aca00, 0x0, 0xc0001cd101, 0x0)
	/Users/yuan.chen/GolandProjects/src/volcano.sh/volcano/vendor/k8s.io/apimachinery/pkg/util/wait/wait.go:134 +0xf8
volcano.sh/volcano/vendor/k8s.io/apimachinery/pkg/util/wait.Until(...)
	/Users/yuan.chen/GolandProjects/src/volcano.sh/volcano/vendor/k8s.io/apimachinery/pkg/util/wait/wait.go:88
volcano.sh/volcano/vendor/k8s.io/client-go/tools/cache.(*controller).Run(0xc000152300, 0x0)
	/Users/yuan.chen/GolandProjects/src/volcano.sh/volcano/vendor/k8s.io/client-go/tools/cache/controller.go:124 +0x2fd
volcano.sh/volcano/vendor/k8s.io/client-go/tools/cache.(*sharedIndexInformer).Run(0xc00003ca20, 0x0)
	/Users/yuan.chen/GolandProjects/src/volcano.sh/volcano/vendor/k8s.io/client-go/tools/cache/shared_informer.go:227 +0x47f
created by volcano.sh/volcano/pkg/scheduler/cache.(*SchedulerCache).Run
	/Users/yuan.chen/GolandProjects/src/volcano.sh/volcano/pkg/scheduler/cache/cache.go:443 +0x2aa

goroutine 151 [sync.Cond.Wait]:
runtime.goparkunlock(...)
	/usr/local/opt/go/libexec/src/runtime/proc.go:310
sync.runtime_notifyListWait(0xc0003fc028, 0x0)
	/usr/local/opt/go/libexec/src/runtime/sema.go:510 +0xf8
sync.(*Cond).Wait(0xc0003fc018)
	/usr/local/opt/go/libexec/src/sync/cond.go:56 +0x9d
volcano.sh/volcano/vendor/k8s.io/client-go/tools/cache.(*DeltaFIFO).Pop(0xc0003fc000, 0xc000502030, 0x0, 0x0, 0x0, 0x0)
	/Users/yuan.chen/GolandProjects/src/volcano.sh/volcano/vendor/k8s.io/client-go/tools/cache/delta_fifo.go:423 +0xa6
volcano.sh/volcano/vendor/k8s.io/client-go/tools/cache.(*controller).processLoop(0xc000486180)
	/Users/yuan.chen/GolandProjects/src/volcano.sh/volcano/vendor/k8s.io/client-go/tools/cache/controller.go:150 +0x40
volcano.sh/volcano/vendor/k8s.io/apimachinery/pkg/util/wait.JitterUntil.func1(0xc000404e00)
	/Users/yuan.chen/GolandProjects/src/volcano.sh/volcano/vendor/k8s.io/apimachinery/pkg/util/wait/wait.go:133 +0x5e
volcano.sh/volcano/vendor/k8s.io/apimachinery/pkg/util/wait.JitterUntil(0xc000404e00, 0x3b9aca00, 0x0, 0xc0001cc301, 0x0)
	/Users/yuan.chen/GolandProjects/src/volcano.sh/volcano/vendor/k8s.io/apimachinery/pkg/util/wait/wait.go:134 +0xf8
volcano.sh/volcano/vendor/k8s.io/apimachinery/pkg/util/wait.Until(...)
	/Users/yuan.chen/GolandProjects/src/volcano.sh/volcano/vendor/k8s.io/apimachinery/pkg/util/wait/wait.go:88
volcano.sh/volcano/vendor/k8s.io/client-go/tools/cache.(*controller).Run(0xc000486180, 0x0)
	/Users/yuan.chen/GolandProjects/src/volcano.sh/volcano/vendor/k8s.io/client-go/tools/cache/controller.go:124 +0x2fd
volcano.sh/volcano/vendor/k8s.io/client-go/tools/cache.(*sharedIndexInformer).Run(0xc00003c7e0, 0x0)
	/Users/yuan.chen/GolandProjects/src/volcano.sh/volcano/vendor/k8s.io/client-go/tools/cache/shared_informer.go:227 +0x47f
created by volcano.sh/volcano/pkg/scheduler/cache.(*SchedulerCache).Run
	/Users/yuan.chen/GolandProjects/src/volcano.sh/volcano/pkg/scheduler/cache/cache.go:444 +0x2ed

goroutine 152 [sync.Cond.Wait]:
runtime.goparkunlock(...)
	/usr/local/opt/go/libexec/src/runtime/proc.go:310
sync.runtime_notifyListWait(0xc0003ae188, 0x1)
	/usr/local/opt/go/libexec/src/runtime/sema.go:510 +0xf8
sync.(*Cond).Wait(0xc0003ae178)
	/usr/local/opt/go/libexec/src/sync/cond.go:56 +0x9d
volcano.sh/volcano/vendor/k8s.io/client-go/tools/cache.(*DeltaFIFO).Pop(0xc0003ae160, 0xc0001666e0, 0x0, 0x0, 0x0, 0x0)
	/Users/yuan.chen/GolandProjects/src/volcano.sh/volcano/vendor/k8s.io/client-go/tools/cache/delta_fifo.go:423 +0xa6
volcano.sh/volcano/vendor/k8s.io/client-go/tools/cache.(*controller).processLoop(0xc000532b80)
	/Users/yuan.chen/GolandProjects/src/volcano.sh/volcano/vendor/k8s.io/client-go/tools/cache/controller.go:150 +0x40
volcano.sh/volcano/vendor/k8s.io/apimachinery/pkg/util/wait.JitterUntil.func1(0xc0005dae00)
	/Users/yuan.chen/GolandProjects/src/volcano.sh/volcano/vendor/k8s.io/apimachinery/pkg/util/wait/wait.go:133 +0x5e
volcano.sh/volcano/vendor/k8s.io/apimachinery/pkg/util/wait.JitterUntil(0xc0005dae00, 0x3b9aca00, 0x0, 0xc0000fca01, 0x0)
	/Users/yuan.chen/GolandProjects/src/volcano.sh/volcano/vendor/k8s.io/apimachinery/pkg/util/wait/wait.go:134 +0xf8
volcano.sh/volcano/vendor/k8s.io/apimachinery/pkg/util/wait.Until(...)
	/Users/yuan.chen/GolandProjects/src/volcano.sh/volcano/vendor/k8s.io/apimachinery/pkg/util/wait/wait.go:88
volcano.sh/volcano/vendor/k8s.io/client-go/tools/cache.(*controller).Run(0xc000532b80, 0x0)
	/Users/yuan.chen/GolandProjects/src/volcano.sh/volcano/vendor/k8s.io/client-go/tools/cache/controller.go:124 +0x2fd
volcano.sh/volcano/vendor/k8s.io/client-go/tools/cache.(*sharedIndexInformer).Run(0xc00003c750, 0x0)
	/Users/yuan.chen/GolandProjects/src/volcano.sh/volcano/vendor/k8s.io/client-go/tools/cache/shared_informer.go:227 +0x47f
created by volcano.sh/volcano/pkg/scheduler/cache.(*SchedulerCache).Run
	/Users/yuan.chen/GolandProjects/src/volcano.sh/volcano/pkg/scheduler/cache/cache.go:447 +0x443

goroutine 123 [chan receive]:
volcano.sh/volcano/vendor/k8s.io/client-go/tools/cache.(*processorListener).run.func1.1(0x0, 0x0, 0x0)
	/Users/yuan.chen/GolandProjects/src/volcano.sh/volcano/vendor/k8s.io/client-go/tools/cache/shared_informer.go:549 +0x54
volcano.sh/volcano/vendor/k8s.io/apimachinery/pkg/util/wait.ExponentialBackoff(0x989680, 0x3ff0000000000000, 0x3fb999999999999a, 0x5, 0xc0006ebdd8, 0x0, 0x0)
	/Users/yuan.chen/GolandProjects/src/volcano.sh/volcano/vendor/k8s.io/apimachinery/pkg/util/wait/wait.go:203 +0xde
volcano.sh/volcano/vendor/k8s.io/client-go/tools/cache.(*processorListener).run.func1()
	/Users/yuan.chen/GolandProjects/src/volcano.sh/volcano/vendor/k8s.io/client-go/tools/cache/shared_informer.go:548 +0x89
volcano.sh/volcano/vendor/k8s.io/apimachinery/pkg/util/wait.JitterUntil.func1(0xc00038ff40)
	/Users/yuan.chen/GolandProjects/src/volcano.sh/volcano/vendor/k8s.io/apimachinery/pkg/util/wait/wait.go:133 +0x5e
volcano.sh/volcano/vendor/k8s.io/apimachinery/pkg/util/wait.JitterUntil(0xc0006ebf40, 0xdf8475800, 0x0, 0x1030501, 0xc00042e2a0)
	/Users/yuan.chen/GolandProjects/src/volcano.sh/volcano/vendor/k8s.io/apimachinery/pkg/util/wait/wait.go:134 +0xf8
volcano.sh/volcano/vendor/k8s.io/apimachinery/pkg/util/wait.Until(...)
	/Users/yuan.chen/GolandProjects/src/volcano.sh/volcano/vendor/k8s.io/apimachinery/pkg/util/wait/wait.go:88
volcano.sh/volcano/vendor/k8s.io/client-go/tools/cache.(*processorListener).run(0xc000507200)
	/Users/yuan.chen/GolandProjects/src/volcano.sh/volcano/vendor/k8s.io/client-go/tools/cache/shared_informer.go:546 +0x9b
volcano.sh/volcano/vendor/k8s.io/apimachinery/pkg/util/wait.(*Group).Start.func1(0xc00036a220, 0xc0005023a0)
	/Users/yuan.chen/GolandProjects/src/volcano.sh/volcano/vendor/k8s.io/apimachinery/pkg/util/wait/wait.go:71 +0x59
created by volcano.sh/volcano/vendor/k8s.io/apimachinery/pkg/util/wait.(*Group).Start
	/Users/yuan.chen/GolandProjects/src/volcano.sh/volcano/vendor/k8s.io/apimachinery/pkg/util/wait/wait.go:69 +0x62

goroutine 137 [chan receive]:
volcano.sh/volcano/vendor/k8s.io/client-go/tools/cache.(*processorListener).run.func1.1(0xc00015b6c0, 0x13350ad, 0xc000288000)
	/Users/yuan.chen/GolandProjects/src/volcano.sh/volcano/vendor/k8s.io/client-go/tools/cache/shared_informer.go:549 +0x54
volcano.sh/volcano/vendor/k8s.io/apimachinery/pkg/util/wait.ExponentialBackoff(0x989680, 0x3ff0000000000000, 0x3fb999999999999a, 0x5, 0xc000707dd8, 0x0, 0x18)
	/Users/yuan.chen/GolandProjects/src/volcano.sh/volcano/vendor/k8s.io/apimachinery/pkg/util/wait/wait.go:203 +0xde
volcano.sh/volcano/vendor/k8s.io/client-go/tools/cache.(*processorListener).run.func1()
	/Users/yuan.chen/GolandProjects/src/volcano.sh/volcano/vendor/k8s.io/client-go/tools/cache/shared_informer.go:548 +0x89
volcano.sh/volcano/vendor/k8s.io/apimachinery/pkg/util/wait.JitterUntil.func1(0xc00015b740)
	/Users/yuan.chen/GolandProjects/src/volcano.sh/volcano/vendor/k8s.io/apimachinery/pkg/util/wait/wait.go:133 +0x5e
volcano.sh/volcano/vendor/k8s.io/apimachinery/pkg/util/wait.JitterUntil(0xc000707f40, 0xdf8475800, 0x0, 0x1030501, 0xc000114c60)
	/Users/yuan.chen/GolandProjects/src/volcano.sh/volcano/vendor/k8s.io/apimachinery/pkg/util/wait/wait.go:134 +0xf8
volcano.sh/volcano/vendor/k8s.io/apimachinery/pkg/util/wait.Until(...)
	/Users/yuan.chen/GolandProjects/src/volcano.sh/volcano/vendor/k8s.io/apimachinery/pkg/util/wait/wait.go:88
volcano.sh/volcano/vendor/k8s.io/client-go/tools/cache.(*processorListener).run(0xc00014c100)
	/Users/yuan.chen/GolandProjects/src/volcano.sh/volcano/vendor/k8s.io/client-go/tools/cache/shared_informer.go:546 +0x9b
volcano.sh/volcano/vendor/k8s.io/apimachinery/pkg/util/wait.(*Group).Start.func1(0xc00036a530, 0xc0006a31d0)
	/Users/yuan.chen/GolandProjects/src/volcano.sh/volcano/vendor/k8s.io/apimachinery/pkg/util/wait/wait.go:71 +0x59
created by volcano.sh/volcano/vendor/k8s.io/apimachinery/pkg/util/wait.(*Group).Start
	/Users/yuan.chen/GolandProjects/src/volcano.sh/volcano/vendor/k8s.io/apimachinery/pkg/util/wait/wait.go:69 +0x62

goroutine 163 [chan receive]:
volcano.sh/volcano/vendor/k8s.io/client-go/tools/cache.(*sharedProcessor).run(0xc00036a150, 0xc0000c0300)
	/Users/yuan.chen/GolandProjects/src/volcano.sh/volcano/vendor/k8s.io/client-go/tools/cache/shared_informer.go:425 +0x49
volcano.sh/volcano/vendor/k8s.io/apimachinery/pkg/util/wait.(*Group).StartWithChannel.func1()
	/Users/yuan.chen/GolandProjects/src/volcano.sh/volcano/vendor/k8s.io/apimachinery/pkg/util/wait/wait.go:54 +0x2e
volcano.sh/volcano/vendor/k8s.io/apimachinery/pkg/util/wait.(*Group).Start.func1(0xc0005880d0, 0xc0004b07c0)
	/Users/yuan.chen/GolandProjects/src/volcano.sh/volcano/vendor/k8s.io/apimachinery/pkg/util/wait/wait.go:71 +0x59
created by volcano.sh/volcano/vendor/k8s.io/apimachinery/pkg/util/wait.(*Group).Start
	/Users/yuan.chen/GolandProjects/src/volcano.sh/volcano/vendor/k8s.io/apimachinery/pkg/util/wait/wait.go:69 +0x62

goroutine 153 [sync.Cond.Wait]:
runtime.goparkunlock(...)
	/usr/local/opt/go/libexec/src/runtime/proc.go:310
sync.runtime_notifyListWait(0xc0000bc490, 0x0)
	/usr/local/opt/go/libexec/src/runtime/sema.go:510 +0xf8
sync.(*Cond).Wait(0xc0000bc480)
	/usr/local/opt/go/libexec/src/sync/cond.go:56 +0x9d
volcano.sh/volcano/vendor/k8s.io/client-go/util/workqueue.(*Type).Get(0xc0003c0180, 0x0, 0x0, 0x0)
	/Users/yuan.chen/GolandProjects/src/volcano.sh/volcano/vendor/k8s.io/client-go/util/workqueue/queue.go:145 +0xa0
volcano.sh/volcano/pkg/scheduler/cache.(*SchedulerCache).processResyncTask(0xc000192380)
	/Users/yuan.chen/GolandProjects/src/volcano.sh/volcano/pkg/scheduler/cache/cache.go:677 +0x4f
volcano.sh/volcano/vendor/k8s.io/apimachinery/pkg/util/wait.JitterUntil.func1(0xc000500770)
	/Users/yuan.chen/GolandProjects/src/volcano.sh/volcano/vendor/k8s.io/apimachinery/pkg/util/wait/wait.go:133 +0x5e
volcano.sh/volcano/vendor/k8s.io/apimachinery/pkg/util/wait.JitterUntil(0xc000500770, 0x0, 0x0, 0x1, 0x0)
	/Users/yuan.chen/GolandProjects/src/volcano.sh/volcano/vendor/k8s.io/apimachinery/pkg/util/wait/wait.go:134 +0xf8
volcano.sh/volcano/vendor/k8s.io/apimachinery/pkg/util/wait.Until(0xc000500770, 0x0, 0x0)
	/Users/yuan.chen/GolandProjects/src/volcano.sh/volcano/vendor/k8s.io/apimachinery/pkg/util/wait/wait.go:88 +0x4d
created by volcano.sh/volcano/pkg/scheduler/cache.(*SchedulerCache).Run
	/Users/yuan.chen/GolandProjects/src/volcano.sh/volcano/pkg/scheduler/cache/cache.go:451 +0x366

goroutine 134 [chan receive]:
volcano.sh/volcano/vendor/k8s.io/client-go/tools/cache.(*sharedProcessor).run(0xc00036a4d0, 0xc000114c00)
	/Users/yuan.chen/GolandProjects/src/volcano.sh/volcano/vendor/k8s.io/client-go/tools/cache/shared_informer.go:425 +0x49
volcano.sh/volcano/vendor/k8s.io/apimachinery/pkg/util/wait.(*Group).StartWithChannel.func1()
	/Users/yuan.chen/GolandProjects/src/volcano.sh/volcano/vendor/k8s.io/apimachinery/pkg/util/wait/wait.go:54 +0x2e
volcano.sh/volcano/vendor/k8s.io/apimachinery/pkg/util/wait.(*Group).Start.func1(0xc000540920, 0xc00000ee20)
	/Users/yuan.chen/GolandProjects/src/volcano.sh/volcano/vendor/k8s.io/apimachinery/pkg/util/wait/wait.go:71 +0x59
created by volcano.sh/volcano/vendor/k8s.io/apimachinery/pkg/util/wait.(*Group).Start
	/Users/yuan.chen/GolandProjects/src/volcano.sh/volcano/vendor/k8s.io/apimachinery/pkg/util/wait/wait.go:69 +0x62

goroutine 154 [sync.Cond.Wait]:
runtime.goparkunlock(...)
	/usr/local/opt/go/libexec/src/runtime/proc.go:310
sync.runtime_notifyListWait(0xc0000bc4d0, 0xc000000005)
	/usr/local/opt/go/libexec/src/runtime/sema.go:510 +0xf8
sync.(*Cond).Wait(0xc0000bc4c0)
	/usr/local/opt/go/libexec/src/sync/cond.go:56 +0x9d
volcano.sh/volcano/vendor/k8s.io/client-go/util/workqueue.(*Type).Get(0xc0003c0360, 0x0, 0x0, 0x2137100)
	/Users/yuan.chen/GolandProjects/src/volcano.sh/volcano/vendor/k8s.io/client-go/util/workqueue/queue.go:145 +0xa0
volcano.sh/volcano/pkg/scheduler/cache.(*SchedulerCache).processCleanupJob(0xc000192380)
	/Users/yuan.chen/GolandProjects/src/volcano.sh/volcano/pkg/scheduler/cache/cache.go:647 +0x52
volcano.sh/volcano/vendor/k8s.io/apimachinery/pkg/util/wait.JitterUntil.func1(0xc0005007c0)
	/Users/yuan.chen/GolandProjects/src/volcano.sh/volcano/vendor/k8s.io/apimachinery/pkg/util/wait/wait.go:133 +0x5e
volcano.sh/volcano/vendor/k8s.io/apimachinery/pkg/util/wait.JitterUntil(0xc0005007c0, 0x0, 0x0, 0x1, 0x0)
	/Users/yuan.chen/GolandProjects/src/volcano.sh/volcano/vendor/k8s.io/apimachinery/pkg/util/wait/wait.go:134 +0xf8
volcano.sh/volcano/vendor/k8s.io/apimachinery/pkg/util/wait.Until(0xc0005007c0, 0x0, 0x0)
	/Users/yuan.chen/GolandProjects/src/volcano.sh/volcano/vendor/k8s.io/apimachinery/pkg/util/wait/wait.go:88 +0x4d
created by volcano.sh/volcano/pkg/scheduler/cache.(*SchedulerCache).Run
	/Users/yuan.chen/GolandProjects/src/volcano.sh/volcano/pkg/scheduler/cache/cache.go:454 +0x3c7

goroutine 135 [chan receive (nil chan)]:
volcano.sh/volcano/vendor/k8s.io/client-go/tools/cache.(*controller).Run.func1(0x0, 0xc00014c600)
	/Users/yuan.chen/GolandProjects/src/volcano.sh/volcano/vendor/k8s.io/client-go/tools/cache/controller.go:103 +0x34
created by volcano.sh/volcano/vendor/k8s.io/client-go/tools/cache.(*controller).Run
	/Users/yuan.chen/GolandProjects/src/volcano.sh/volcano/vendor/k8s.io/client-go/tools/cache/controller.go:102 +0xae

goroutine 141 [chan receive]:
volcano.sh/volcano/vendor/k8s.io/client-go/tools/cache.(*processorListener).run.func1.1(0x0, 0x0, 0x0)
	/Users/yuan.chen/GolandProjects/src/volcano.sh/volcano/vendor/k8s.io/client-go/tools/cache/shared_informer.go:549 +0x54
volcano.sh/volcano/vendor/k8s.io/apimachinery/pkg/util/wait.ExponentialBackoff(0x989680, 0x3ff0000000000000, 0x3fb999999999999a, 0x5, 0xc0005e8dd8, 0x0, 0x0)
	/Users/yuan.chen/GolandProjects/src/volcano.sh/volcano/vendor/k8s.io/apimachinery/pkg/util/wait/wait.go:203 +0xde
volcano.sh/volcano/vendor/k8s.io/client-go/tools/cache.(*processorListener).run.func1()
	/Users/yuan.chen/GolandProjects/src/volcano.sh/volcano/vendor/k8s.io/client-go/tools/cache/shared_informer.go:548 +0x89
volcano.sh/volcano/vendor/k8s.io/apimachinery/pkg/util/wait.JitterUntil.func1(0xc00055b740)
	/Users/yuan.chen/GolandProjects/src/volcano.sh/volcano/vendor/k8s.io/apimachinery/pkg/util/wait/wait.go:133 +0x5e
volcano.sh/volcano/vendor/k8s.io/apimachinery/pkg/util/wait.JitterUntil(0xc0005e8f40, 0xdf8475800, 0x0, 0x1030501, 0xc000114d20)
	/Users/yuan.chen/GolandProjects/src/volcano.sh/volcano/vendor/k8s.io/apimachinery/pkg/util/wait/wait.go:134 +0xf8
volcano.sh/volcano/vendor/k8s.io/apimachinery/pkg/util/wait.Until(...)
	/Users/yuan.chen/GolandProjects/src/volcano.sh/volcano/vendor/k8s.io/apimachinery/pkg/util/wait/wait.go:88
volcano.sh/volcano/vendor/k8s.io/client-go/tools/cache.(*processorListener).run(0xc000507680)
	/Users/yuan.chen/GolandProjects/src/volcano.sh/volcano/vendor/k8s.io/client-go/tools/cache/shared_informer.go:546 +0x9b
volcano.sh/volcano/vendor/k8s.io/apimachinery/pkg/util/wait.(*Group).Start.func1(0xc00036a300, 0xc0006a3210)
	/Users/yuan.chen/GolandProjects/src/volcano.sh/volcano/vendor/k8s.io/apimachinery/pkg/util/wait/wait.go:71 +0x59
created by volcano.sh/volcano/vendor/k8s.io/apimachinery/pkg/util/wait.(*Group).Start
	/Users/yuan.chen/GolandProjects/src/volcano.sh/volcano/vendor/k8s.io/apimachinery/pkg/util/wait/wait.go:69 +0x62

goroutine 9 [chan receive]:
volcano.sh/volcano/vendor/k8s.io/client-go/tools/cache.(*sharedProcessor).run(0xc00036a230, 0xc00016a060)
	/Users/yuan.chen/GolandProjects/src/volcano.sh/volcano/vendor/k8s.io/client-go/tools/cache/shared_informer.go:425 +0x49
volcano.sh/volcano/vendor/k8s.io/apimachinery/pkg/util/wait.(*Group).StartWithChannel.func1()
	/Users/yuan.chen/GolandProjects/src/volcano.sh/volcano/vendor/k8s.io/apimachinery/pkg/util/wait/wait.go:54 +0x2e
volcano.sh/volcano/vendor/k8s.io/apimachinery/pkg/util/wait.(*Group).Start.func1(0xc00018c000, 0xc0000e0280)
	/Users/yuan.chen/GolandProjects/src/volcano.sh/volcano/vendor/k8s.io/apimachinery/pkg/util/wait/wait.go:71 +0x59
created by volcano.sh/volcano/vendor/k8s.io/apimachinery/pkg/util/wait.(*Group).Start
	/Users/yuan.chen/GolandProjects/src/volcano.sh/volcano/vendor/k8s.io/apimachinery/pkg/util/wait/wait.go:69 +0x62

goroutine 10 [chan receive (nil chan)]:
volcano.sh/volcano/vendor/k8s.io/client-go/tools/cache.(*controller).Run.func1(0x0, 0xc000470000)
	/Users/yuan.chen/GolandProjects/src/volcano.sh/volcano/vendor/k8s.io/client-go/tools/cache/controller.go:103 +0x34
created by volcano.sh/volcano/vendor/k8s.io/client-go/tools/cache.(*controller).Run
	/Users/yuan.chen/GolandProjects/src/volcano.sh/volcano/vendor/k8s.io/client-go/tools/cache/controller.go:102 +0xae

goroutine 164 [chan receive (nil chan)]:
volcano.sh/volcano/vendor/k8s.io/client-go/tools/cache.(*controller).Run.func1(0x0, 0xc00019a780)
	/Users/yuan.chen/GolandProjects/src/volcano.sh/volcano/vendor/k8s.io/client-go/tools/cache/controller.go:103 +0x34
created by volcano.sh/volcano/vendor/k8s.io/client-go/tools/cache.(*controller).Run
	/Users/yuan.chen/GolandProjects/src/volcano.sh/volcano/vendor/k8s.io/client-go/tools/cache/controller.go:102 +0xae

goroutine 156 [chan receive]:
volcano.sh/volcano/vendor/k8s.io/client-go/tools/cache.(*sharedProcessor).run(0xc00036a540, 0xc00039e000)
	/Users/yuan.chen/GolandProjects/src/volcano.sh/volcano/vendor/k8s.io/client-go/tools/cache/shared_informer.go:425 +0x49
volcano.sh/volcano/vendor/k8s.io/apimachinery/pkg/util/wait.(*Group).StartWithChannel.func1()
	/Users/yuan.chen/GolandProjects/src/volcano.sh/volcano/vendor/k8s.io/apimachinery/pkg/util/wait/wait.go:54 +0x2e
volcano.sh/volcano/vendor/k8s.io/apimachinery/pkg/util/wait.(*Group).Start.func1(0xc000438010, 0xc00030a060)
	/Users/yuan.chen/GolandProjects/src/volcano.sh/volcano/vendor/k8s.io/apimachinery/pkg/util/wait/wait.go:71 +0x59
created by volcano.sh/volcano/vendor/k8s.io/apimachinery/pkg/util/wait.(*Group).Start
	/Users/yuan.chen/GolandProjects/src/volcano.sh/volcano/vendor/k8s.io/apimachinery/pkg/util/wait/wait.go:69 +0x62

goroutine 72 [chan receive]:
volcano.sh/volcano/vendor/k8s.io/client-go/tools/cache.(*sharedProcessor).run(0xc00036a2a0, 0xc00038a000)
	/Users/yuan.chen/GolandProjects/src/volcano.sh/volcano/vendor/k8s.io/client-go/tools/cache/shared_informer.go:425 +0x49
volcano.sh/volcano/vendor/k8s.io/apimachinery/pkg/util/wait.(*Group).StartWithChannel.func1()
	/Users/yuan.chen/GolandProjects/src/volcano.sh/volcano/vendor/k8s.io/apimachinery/pkg/util/wait/wait.go:54 +0x2e
volcano.sh/volcano/vendor/k8s.io/apimachinery/pkg/util/wait.(*Group).Start.func1(0xc000638000, 0xc000520040)
	/Users/yuan.chen/GolandProjects/src/volcano.sh/volcano/vendor/k8s.io/apimachinery/pkg/util/wait/wait.go:71 +0x59
created by volcano.sh/volcano/vendor/k8s.io/apimachinery/pkg/util/wait.(*Group).Start
	/Users/yuan.chen/GolandProjects/src/volcano.sh/volcano/vendor/k8s.io/apimachinery/pkg/util/wait/wait.go:69 +0x62

goroutine 157 [chan receive (nil chan)]:
volcano.sh/volcano/vendor/k8s.io/client-go/tools/cache.(*controller).Run.func1(0x0, 0xc000152300)
	/Users/yuan.chen/GolandProjects/src/volcano.sh/volcano/vendor/k8s.io/client-go/tools/cache/controller.go:103 +0x34
created by volcano.sh/volcano/vendor/k8s.io/client-go/tools/cache.(*controller).Run
	/Users/yuan.chen/GolandProjects/src/volcano.sh/volcano/vendor/k8s.io/client-go/tools/cache/controller.go:102 +0xae

goroutine 73 [chan receive (nil chan)]:
volcano.sh/volcano/vendor/k8s.io/client-go/tools/cache.(*controller).Run.func1(0x0, 0xc0003f2000)
	/Users/yuan.chen/GolandProjects/src/volcano.sh/volcano/vendor/k8s.io/client-go/tools/cache/controller.go:103 +0x34
created by volcano.sh/volcano/vendor/k8s.io/client-go/tools/cache.(*controller).Run
	/Users/yuan.chen/GolandProjects/src/volcano.sh/volcano/vendor/k8s.io/client-go/tools/cache/controller.go:102 +0xae

goroutine 100 [chan receive]:
volcano.sh/volcano/vendor/k8s.io/client-go/tools/cache.(*sharedProcessor).run(0xc00036a070, 0xc0003b6000)
	/Users/yuan.chen/GolandProjects/src/volcano.sh/volcano/vendor/k8s.io/client-go/tools/cache/shared_informer.go:425 +0x49
volcano.sh/volcano/vendor/k8s.io/apimachinery/pkg/util/wait.(*Group).StartWithChannel.func1()
	/Users/yuan.chen/GolandProjects/src/volcano.sh/volcano/vendor/k8s.io/apimachinery/pkg/util/wait/wait.go:54 +0x2e
volcano.sh/volcano/vendor/k8s.io/apimachinery/pkg/util/wait.(*Group).Start.func1(0xc000384010, 0xc00063e060)
	/Users/yuan.chen/GolandProjects/src/volcano.sh/volcano/vendor/k8s.io/apimachinery/pkg/util/wait/wait.go:71 +0x59
created by volcano.sh/volcano/vendor/k8s.io/apimachinery/pkg/util/wait.(*Group).Start
	/Users/yuan.chen/GolandProjects/src/volcano.sh/volcano/vendor/k8s.io/apimachinery/pkg/util/wait/wait.go:69 +0x62

goroutine 101 [chan receive (nil chan)]:
volcano.sh/volcano/vendor/k8s.io/client-go/tools/cache.(*controller).Run.func1(0x0, 0xc000532080)
	/Users/yuan.chen/GolandProjects/src/volcano.sh/volcano/vendor/k8s.io/client-go/tools/cache/controller.go:103 +0x34
created by volcano.sh/volcano/vendor/k8s.io/client-go/tools/cache.(*controller).Run
	/Users/yuan.chen/GolandProjects/src/volcano.sh/volcano/vendor/k8s.io/client-go/tools/cache/controller.go:102 +0xae

goroutine 122 [select]:
volcano.sh/volcano/vendor/k8s.io/client-go/tools/cache.(*processorListener).pop(0xc000507d00)
	/Users/yuan.chen/GolandProjects/src/volcano.sh/volcano/vendor/k8s.io/client-go/tools/cache/shared_informer.go:517 +0x18d
volcano.sh/volcano/vendor/k8s.io/apimachinery/pkg/util/wait.(*Group).Start.func1(0xc00036a450, 0xc000502370)
	/Users/yuan.chen/GolandProjects/src/volcano.sh/volcano/vendor/k8s.io/apimachinery/pkg/util/wait/wait.go:71 +0x59
created by volcano.sh/volcano/vendor/k8s.io/apimachinery/pkg/util/wait.(*Group).Start
	/Users/yuan.chen/GolandProjects/src/volcano.sh/volcano/vendor/k8s.io/apimachinery/pkg/util/wait/wait.go:69 +0x62

goroutine 84 [chan receive]:
volcano.sh/volcano/vendor/k8s.io/client-go/tools/cache.(*sharedProcessor).run(0xc00036a0e0, 0xc0003e6000)
	/Users/yuan.chen/GolandProjects/src/volcano.sh/volcano/vendor/k8s.io/client-go/tools/cache/shared_informer.go:425 +0x49
volcano.sh/volcano/vendor/k8s.io/apimachinery/pkg/util/wait.(*Group).StartWithChannel.func1()
	/Users/yuan.chen/GolandProjects/src/volcano.sh/volcano/vendor/k8s.io/apimachinery/pkg/util/wait/wait.go:54 +0x2e
volcano.sh/volcano/vendor/k8s.io/apimachinery/pkg/util/wait.(*Group).Start.func1(0xc0004a6000, 0xc000456080)
	/Users/yuan.chen/GolandProjects/src/volcano.sh/volcano/vendor/k8s.io/apimachinery/pkg/util/wait/wait.go:71 +0x59
created by volcano.sh/volcano/vendor/k8s.io/apimachinery/pkg/util/wait.(*Group).Start
	/Users/yuan.chen/GolandProjects/src/volcano.sh/volcano/vendor/k8s.io/apimachinery/pkg/util/wait/wait.go:69 +0x62

goroutine 85 [chan receive (nil chan)]:
volcano.sh/volcano/vendor/k8s.io/client-go/tools/cache.(*controller).Run.func1(0x0, 0xc0004d4000)
	/Users/yuan.chen/GolandProjects/src/volcano.sh/volcano/vendor/k8s.io/client-go/tools/cache/controller.go:103 +0x34
created by volcano.sh/volcano/vendor/k8s.io/client-go/tools/cache.(*controller).Run
	/Users/yuan.chen/GolandProjects/src/volcano.sh/volcano/vendor/k8s.io/client-go/tools/cache/controller.go:102 +0xae

goroutine 15 [chan receive]:
volcano.sh/volcano/vendor/k8s.io/client-go/tools/cache.(*sharedProcessor).run(0xc00036a1c0, 0xc00016a3c0)
	/Users/yuan.chen/GolandProjects/src/volcano.sh/volcano/vendor/k8s.io/client-go/tools/cache/shared_informer.go:425 +0x49
volcano.sh/volcano/vendor/k8s.io/apimachinery/pkg/util/wait.(*Group).StartWithChannel.func1()
	/Users/yuan.chen/GolandProjects/src/volcano.sh/volcano/vendor/k8s.io/apimachinery/pkg/util/wait/wait.go:54 +0x2e
volcano.sh/volcano/vendor/k8s.io/apimachinery/pkg/util/wait.(*Group).Start.func1(0xc00018d200, 0xc0000e0700)
	/Users/yuan.chen/GolandProjects/src/volcano.sh/volcano/vendor/k8s.io/apimachinery/pkg/util/wait/wait.go:71 +0x59
created by volcano.sh/volcano/vendor/k8s.io/apimachinery/pkg/util/wait.(*Group).Start
	/Users/yuan.chen/GolandProjects/src/volcano.sh/volcano/vendor/k8s.io/apimachinery/pkg/util/wait/wait.go:69 +0x62

goroutine 116 [chan receive]:
volcano.sh/volcano/vendor/k8s.io/client-go/tools/cache.(*sharedProcessor).run(0xc00036a380, 0xc00042e000)
	/Users/yuan.chen/GolandProjects/src/volcano.sh/volcano/vendor/k8s.io/client-go/tools/cache/shared_informer.go:425 +0x49
volcano.sh/volcano/vendor/k8s.io/apimachinery/pkg/util/wait.(*Group).StartWithChannel.func1()
	/Users/yuan.chen/GolandProjects/src/volcano.sh/volcano/vendor/k8s.io/apimachinery/pkg/util/wait/wait.go:54 +0x2e
volcano.sh/volcano/vendor/k8s.io/apimachinery/pkg/util/wait.(*Group).Start.func1(0xc0001b62a0, 0xc000412040)
	/Users/yuan.chen/GolandProjects/src/volcano.sh/volcano/vendor/k8s.io/apimachinery/pkg/util/wait/wait.go:71 +0x59
created by volcano.sh/volcano/vendor/k8s.io/apimachinery/pkg/util/wait.(*Group).Start
	/Users/yuan.chen/GolandProjects/src/volcano.sh/volcano/vendor/k8s.io/apimachinery/pkg/util/wait/wait.go:69 +0x62

goroutine 117 [chan receive (nil chan)]:
volcano.sh/volcano/vendor/k8s.io/client-go/tools/cache.(*controller).Run.func1(0x0, 0xc000486180)
	/Users/yuan.chen/GolandProjects/src/volcano.sh/volcano/vendor/k8s.io/client-go/tools/cache/controller.go:103 +0x34
created by volcano.sh/volcano/vendor/k8s.io/client-go/tools/cache.(*controller).Run
	/Users/yuan.chen/GolandProjects/src/volcano.sh/volcano/vendor/k8s.io/client-go/tools/cache/controller.go:102 +0xae

goroutine 136 [select]:
volcano.sh/volcano/vendor/k8s.io/client-go/tools/cache.(*Reflector).watchHandler(0xc000334aa0, 0x23a3860, 0xc00032c510, 0xc000621be0, 0xc0003095c0, 0x0, 0x0, 0x0)
	/Users/yuan.chen/GolandProjects/src/volcano.sh/volcano/vendor/k8s.io/client-go/tools/cache/reflector.go:283 +0x1ec
volcano.sh/volcano/vendor/k8s.io/client-go/tools/cache.(*Reflector).ListAndWatch(0xc000334aa0, 0x0, 0x0, 0x0)
	/Users/yuan.chen/GolandProjects/src/volcano.sh/volcano/vendor/k8s.io/client-go/tools/cache/reflector.go:254 +0xc73
volcano.sh/volcano/vendor/k8s.io/client-go/tools/cache.(*Reflector).Run.func1()
	/Users/yuan.chen/GolandProjects/src/volcano.sh/volcano/vendor/k8s.io/client-go/tools/cache/reflector.go:124 +0x33
volcano.sh/volcano/vendor/k8s.io/apimachinery/pkg/util/wait.JitterUntil.func1(0xc00038e6f0)
	/Users/yuan.chen/GolandProjects/src/volcano.sh/volcano/vendor/k8s.io/apimachinery/pkg/util/wait/wait.go:133 +0x5e
volcano.sh/volcano/vendor/k8s.io/apimachinery/pkg/util/wait.JitterUntil(0xc000621ef0, 0x3b9aca00, 0x0, 0x1, 0x0)
	/Users/yuan.chen/GolandProjects/src/volcano.sh/volcano/vendor/k8s.io/apimachinery/pkg/util/wait/wait.go:134 +0xf8
volcano.sh/volcano/vendor/k8s.io/apimachinery/pkg/util/wait.Until(...)
	/Users/yuan.chen/GolandProjects/src/volcano.sh/volcano/vendor/k8s.io/apimachinery/pkg/util/wait/wait.go:88
volcano.sh/volcano/vendor/k8s.io/client-go/tools/cache.(*Reflector).Run(0xc000334aa0, 0x0)
	/Users/yuan.chen/GolandProjects/src/volcano.sh/volcano/vendor/k8s.io/client-go/tools/cache/reflector.go:123 +0x169
volcano.sh/volcano/vendor/k8s.io/apimachinery/pkg/util/wait.(*Group).StartWithChannel.func1()
	/Users/yuan.chen/GolandProjects/src/volcano.sh/volcano/vendor/k8s.io/apimachinery/pkg/util/wait/wait.go:54 +0x2e
volcano.sh/volcano/vendor/k8s.io/apimachinery/pkg/util/wait.(*Group).Start.func1(0xc000540990, 0xc00000f060)
	/Users/yuan.chen/GolandProjects/src/volcano.sh/volcano/vendor/k8s.io/apimachinery/pkg/util/wait/wait.go:71 +0x59
created by volcano.sh/volcano/vendor/k8s.io/apimachinery/pkg/util/wait.(*Group).Start
	/Users/yuan.chen/GolandProjects/src/volcano.sh/volcano/vendor/k8s.io/apimachinery/pkg/util/wait/wait.go:69 +0x62

goroutine 118 [select]:
volcano.sh/volcano/vendor/k8s.io/client-go/tools/cache.(*Reflector).watchHandler(0xc0001caa00, 0x23a3860, 0xc0007d55c0, 0xc00065dbe0, 0xc000446300, 0x0, 0x0, 0x0)
	/Users/yuan.chen/GolandProjects/src/volcano.sh/volcano/vendor/k8s.io/client-go/tools/cache/reflector.go:283 +0x1ec
volcano.sh/volcano/vendor/k8s.io/client-go/tools/cache.(*Reflector).ListAndWatch(0xc0001caa00, 0x0, 0x0, 0x0)
	/Users/yuan.chen/GolandProjects/src/volcano.sh/volcano/vendor/k8s.io/client-go/tools/cache/reflector.go:254 +0xc73
volcano.sh/volcano/vendor/k8s.io/client-go/tools/cache.(*Reflector).Run.func1()
	/Users/yuan.chen/GolandProjects/src/volcano.sh/volcano/vendor/k8s.io/client-go/tools/cache/reflector.go:124 +0x33
volcano.sh/volcano/vendor/k8s.io/apimachinery/pkg/util/wait.JitterUntil.func1(0xc000693ef0)
	/Users/yuan.chen/GolandProjects/src/volcano.sh/volcano/vendor/k8s.io/apimachinery/pkg/util/wait/wait.go:133 +0x5e
volcano.sh/volcano/vendor/k8s.io/apimachinery/pkg/util/wait.JitterUntil(0xc00065def0, 0x3b9aca00, 0x0, 0x1, 0x0)
	/Users/yuan.chen/GolandProjects/src/volcano.sh/volcano/vendor/k8s.io/apimachinery/pkg/util/wait/wait.go:134 +0xf8
volcano.sh/volcano/vendor/k8s.io/apimachinery/pkg/util/wait.Until(...)
	/Users/yuan.chen/GolandProjects/src/volcano.sh/volcano/vendor/k8s.io/apimachinery/pkg/util/wait/wait.go:88
volcano.sh/volcano/vendor/k8s.io/client-go/tools/cache.(*Reflector).Run(0xc0001caa00, 0x0)
	/Users/yuan.chen/GolandProjects/src/volcano.sh/volcano/vendor/k8s.io/client-go/tools/cache/reflector.go:123 +0x169
volcano.sh/volcano/vendor/k8s.io/apimachinery/pkg/util/wait.(*Group).StartWithChannel.func1()
	/Users/yuan.chen/GolandProjects/src/volcano.sh/volcano/vendor/k8s.io/apimachinery/pkg/util/wait/wait.go:54 +0x2e
volcano.sh/volcano/vendor/k8s.io/apimachinery/pkg/util/wait.(*Group).Start.func1(0xc0001b62f0, 0xc0004121a0)
	/Users/yuan.chen/GolandProjects/src/volcano.sh/volcano/vendor/k8s.io/apimachinery/pkg/util/wait/wait.go:71 +0x59
created by volcano.sh/volcano/vendor/k8s.io/apimachinery/pkg/util/wait.(*Group).Start
	/Users/yuan.chen/GolandProjects/src/volcano.sh/volcano/vendor/k8s.io/apimachinery/pkg/util/wait/wait.go:69 +0x62

goroutine 102 [select]:
volcano.sh/volcano/vendor/k8s.io/client-go/tools/cache.(*Reflector).watchHandler(0xc0003e8000, 0x23a3860, 0xc000931cb0, 0xc000a15be0, 0xc0000eb1a0, 0x0, 0x0, 0x0)
	/Users/yuan.chen/GolandProjects/src/volcano.sh/volcano/vendor/k8s.io/client-go/tools/cache/reflector.go:283 +0x1ec
volcano.sh/volcano/vendor/k8s.io/client-go/tools/cache.(*Reflector).ListAndWatch(0xc0003e8000, 0x0, 0x0, 0x0)
	/Users/yuan.chen/GolandProjects/src/volcano.sh/volcano/vendor/k8s.io/client-go/tools/cache/reflector.go:254 +0xc73
volcano.sh/volcano/vendor/k8s.io/client-go/tools/cache.(*Reflector).Run.func1()
	/Users/yuan.chen/GolandProjects/src/volcano.sh/volcano/vendor/k8s.io/client-go/tools/cache/reflector.go:124 +0x33
volcano.sh/volcano/vendor/k8s.io/apimachinery/pkg/util/wait.JitterUntil.func1(0xc000395ef0)
	/Users/yuan.chen/GolandProjects/src/volcano.sh/volcano/vendor/k8s.io/apimachinery/pkg/util/wait/wait.go:133 +0x5e
volcano.sh/volcano/vendor/k8s.io/apimachinery/pkg/util/wait.JitterUntil(0xc000a15ef0, 0x3b9aca00, 0x0, 0x1, 0x0)
	/Users/yuan.chen/GolandProjects/src/volcano.sh/volcano/vendor/k8s.io/apimachinery/pkg/util/wait/wait.go:134 +0xf8
volcano.sh/volcano/vendor/k8s.io/apimachinery/pkg/util/wait.Until(...)
	/Users/yuan.chen/GolandProjects/src/volcano.sh/volcano/vendor/k8s.io/apimachinery/pkg/util/wait/wait.go:88
volcano.sh/volcano/vendor/k8s.io/client-go/tools/cache.(*Reflector).Run(0xc0003e8000, 0x0)
	/Users/yuan.chen/GolandProjects/src/volcano.sh/volcano/vendor/k8s.io/client-go/tools/cache/reflector.go:123 +0x169
volcano.sh/volcano/vendor/k8s.io/apimachinery/pkg/util/wait.(*Group).StartWithChannel.func1()
	/Users/yuan.chen/GolandProjects/src/volcano.sh/volcano/vendor/k8s.io/apimachinery/pkg/util/wait/wait.go:54 +0x2e
volcano.sh/volcano/vendor/k8s.io/apimachinery/pkg/util/wait.(*Group).Start.func1(0xc0003840d0, 0xc00063e140)
	/Users/yuan.chen/GolandProjects/src/volcano.sh/volcano/vendor/k8s.io/apimachinery/pkg/util/wait/wait.go:71 +0x59
created by volcano.sh/volcano/vendor/k8s.io/apimachinery/pkg/util/wait.(*Group).Start
	/Users/yuan.chen/GolandProjects/src/volcano.sh/volcano/vendor/k8s.io/apimachinery/pkg/util/wait/wait.go:69 +0x62

goroutine 11 [select]:
volcano.sh/volcano/vendor/k8s.io/client-go/tools/cache.(*Reflector).watchHandler(0xc000310000, 0x23a3860, 0xc0005a1b30, 0xc000a23be0, 0xc0006a75c0, 0x0, 0x0, 0x0)
	/Users/yuan.chen/GolandProjects/src/volcano.sh/volcano/vendor/k8s.io/client-go/tools/cache/reflector.go:283 +0x1ec
volcano.sh/volcano/vendor/k8s.io/client-go/tools/cache.(*Reflector).ListAndWatch(0xc000310000, 0x0, 0x0, 0x0)
	/Users/yuan.chen/GolandProjects/src/volcano.sh/volcano/vendor/k8s.io/client-go/tools/cache/reflector.go:254 +0xc73
volcano.sh/volcano/vendor/k8s.io/client-go/tools/cache.(*Reflector).Run.func1()
	/Users/yuan.chen/GolandProjects/src/volcano.sh/volcano/vendor/k8s.io/client-go/tools/cache/reflector.go:124 +0x33
volcano.sh/volcano/vendor/k8s.io/apimachinery/pkg/util/wait.JitterUntil.func1(0xc0006976f0)
	/Users/yuan.chen/GolandProjects/src/volcano.sh/volcano/vendor/k8s.io/apimachinery/pkg/util/wait/wait.go:133 +0x5e
volcano.sh/volcano/vendor/k8s.io/apimachinery/pkg/util/wait.JitterUntil(0xc000a23ef0, 0x3b9aca00, 0x0, 0x1, 0x0)
	/Users/yuan.chen/GolandProjects/src/volcano.sh/volcano/vendor/k8s.io/apimachinery/pkg/util/wait/wait.go:134 +0xf8
volcano.sh/volcano/vendor/k8s.io/apimachinery/pkg/util/wait.Until(...)
	/Users/yuan.chen/GolandProjects/src/volcano.sh/volcano/vendor/k8s.io/apimachinery/pkg/util/wait/wait.go:88
volcano.sh/volcano/vendor/k8s.io/client-go/tools/cache.(*Reflector).Run(0xc000310000, 0x0)
	/Users/yuan.chen/GolandProjects/src/volcano.sh/volcano/vendor/k8s.io/client-go/tools/cache/reflector.go:123 +0x169
volcano.sh/volcano/vendor/k8s.io/apimachinery/pkg/util/wait.(*Group).StartWithChannel.func1()
	/Users/yuan.chen/GolandProjects/src/volcano.sh/volcano/vendor/k8s.io/apimachinery/pkg/util/wait/wait.go:54 +0x2e
volcano.sh/volcano/vendor/k8s.io/apimachinery/pkg/util/wait.(*Group).Start.func1(0xc00018c050, 0xc0000e0380)
	/Users/yuan.chen/GolandProjects/src/volcano.sh/volcano/vendor/k8s.io/apimachinery/pkg/util/wait/wait.go:71 +0x59
created by volcano.sh/volcano/vendor/k8s.io/apimachinery/pkg/util/wait.(*Group).Start
	/Users/yuan.chen/GolandProjects/src/volcano.sh/volcano/vendor/k8s.io/apimachinery/pkg/util/wait/wait.go:69 +0x62

goroutine 138 [select]:
volcano.sh/volcano/vendor/k8s.io/client-go/tools/cache.(*processorListener).pop(0xc00014c100)
	/Users/yuan.chen/GolandProjects/src/volcano.sh/volcano/vendor/k8s.io/client-go/tools/cache/shared_informer.go:517 +0x18d
volcano.sh/volcano/vendor/k8s.io/apimachinery/pkg/util/wait.(*Group).Start.func1(0xc00036a530, 0xc0006a31e0)
	/Users/yuan.chen/GolandProjects/src/volcano.sh/volcano/vendor/k8s.io/apimachinery/pkg/util/wait/wait.go:71 +0x59
created by volcano.sh/volcano/vendor/k8s.io/apimachinery/pkg/util/wait.(*Group).Start
	/Users/yuan.chen/GolandProjects/src/volcano.sh/volcano/vendor/k8s.io/apimachinery/pkg/util/wait/wait.go:69 +0x62

goroutine 105 [chan receive (nil chan)]:
volcano.sh/volcano/vendor/k8s.io/client-go/tools/cache.(*controller).Run.func1(0x0, 0xc000532b80)
	/Users/yuan.chen/GolandProjects/src/volcano.sh/volcano/vendor/k8s.io/client-go/tools/cache/controller.go:103 +0x34
created by volcano.sh/volcano/vendor/k8s.io/client-go/tools/cache.(*controller).Run
	/Users/yuan.chen/GolandProjects/src/volcano.sh/volcano/vendor/k8s.io/client-go/tools/cache/controller.go:102 +0xae

goroutine 74 [select]:
volcano.sh/volcano/vendor/k8s.io/client-go/tools/cache.(*Reflector).watchHandler(0xc000416000, 0x23a3860, 0xc000214ae0, 0xc000ac1be0, 0xc0006a6e40, 0x0, 0x0, 0x0)
	/Users/yuan.chen/GolandProjects/src/volcano.sh/volcano/vendor/k8s.io/client-go/tools/cache/reflector.go:283 +0x1ec
volcano.sh/volcano/vendor/k8s.io/client-go/tools/cache.(*Reflector).ListAndWatch(0xc000416000, 0x0, 0x0, 0x0)
	/Users/yuan.chen/GolandProjects/src/volcano.sh/volcano/vendor/k8s.io/client-go/tools/cache/reflector.go:254 +0xc73
volcano.sh/volcano/vendor/k8s.io/client-go/tools/cache.(*Reflector).Run.func1()
	/Users/yuan.chen/GolandProjects/src/volcano.sh/volcano/vendor/k8s.io/client-go/tools/cache/reflector.go:124 +0x33
volcano.sh/volcano/vendor/k8s.io/apimachinery/pkg/util/wait.JitterUntil.func1(0xc00006cef0)
	/Users/yuan.chen/GolandProjects/src/volcano.sh/volcano/vendor/k8s.io/apimachinery/pkg/util/wait/wait.go:133 +0x5e
volcano.sh/volcano/vendor/k8s.io/apimachinery/pkg/util/wait.JitterUntil(0xc000ac1ef0, 0x3b9aca00, 0x0, 0x1, 0x0)
	/Users/yuan.chen/GolandProjects/src/volcano.sh/volcano/vendor/k8s.io/apimachinery/pkg/util/wait/wait.go:134 +0xf8
volcano.sh/volcano/vendor/k8s.io/apimachinery/pkg/util/wait.Until(...)
	/Users/yuan.chen/GolandProjects/src/volcano.sh/volcano/vendor/k8s.io/apimachinery/pkg/util/wait/wait.go:88
volcano.sh/volcano/vendor/k8s.io/client-go/tools/cache.(*Reflector).Run(0xc000416000, 0x0)
	/Users/yuan.chen/GolandProjects/src/volcano.sh/volcano/vendor/k8s.io/client-go/tools/cache/reflector.go:123 +0x169
volcano.sh/volcano/vendor/k8s.io/apimachinery/pkg/util/wait.(*Group).StartWithChannel.func1()
	/Users/yuan.chen/GolandProjects/src/volcano.sh/volcano/vendor/k8s.io/apimachinery/pkg/util/wait/wait.go:54 +0x2e
volcano.sh/volcano/vendor/k8s.io/apimachinery/pkg/util/wait.(*Group).Start.func1(0xc000638040, 0xc000520120)
	/Users/yuan.chen/GolandProjects/src/volcano.sh/volcano/vendor/k8s.io/apimachinery/pkg/util/wait/wait.go:71 +0x59
created by volcano.sh/volcano/vendor/k8s.io/apimachinery/pkg/util/wait.(*Group).Start
	/Users/yuan.chen/GolandProjects/src/volcano.sh/volcano/vendor/k8s.io/apimachinery/pkg/util/wait/wait.go:69 +0x62

goroutine 139 [chan receive]:
volcano.sh/volcano/vendor/k8s.io/client-go/tools/cache.(*processorListener).run.func1.1(0xc00015b6c0, 0x13350ad, 0xc000288000)
	/Users/yuan.chen/GolandProjects/src/volcano.sh/volcano/vendor/k8s.io/client-go/tools/cache/shared_informer.go:549 +0x54
volcano.sh/volcano/vendor/k8s.io/apimachinery/pkg/util/wait.ExponentialBackoff(0x989680, 0x3ff0000000000000, 0x3fb999999999999a, 0x5, 0xc000ac7dd8, 0x0, 0x18)
	/Users/yuan.chen/GolandProjects/src/volcano.sh/volcano/vendor/k8s.io/apimachinery/pkg/util/wait/wait.go:203 +0xde
volcano.sh/volcano/vendor/k8s.io/client-go/tools/cache.(*processorListener).run.func1()
	/Users/yuan.chen/GolandProjects/src/volcano.sh/volcano/vendor/k8s.io/client-go/tools/cache/shared_informer.go:548 +0x89
volcano.sh/volcano/vendor/k8s.io/apimachinery/pkg/util/wait.JitterUntil.func1(0xc00015b740)
	/Users/yuan.chen/GolandProjects/src/volcano.sh/volcano/vendor/k8s.io/apimachinery/pkg/util/wait/wait.go:133 +0x5e
volcano.sh/volcano/vendor/k8s.io/apimachinery/pkg/util/wait.JitterUntil(0xc000ac7f40, 0xdf8475800, 0x0, 0x1030501, 0xc000114cc0)
	/Users/yuan.chen/GolandProjects/src/volcano.sh/volcano/vendor/k8s.io/apimachinery/pkg/util/wait/wait.go:134 +0xf8
volcano.sh/volcano/vendor/k8s.io/apimachinery/pkg/util/wait.Until(...)
	/Users/yuan.chen/GolandProjects/src/volcano.sh/volcano/vendor/k8s.io/apimachinery/pkg/util/wait/wait.go:88
volcano.sh/volcano/vendor/k8s.io/client-go/tools/cache.(*processorListener).run(0xc000507400)
	/Users/yuan.chen/GolandProjects/src/volcano.sh/volcano/vendor/k8s.io/client-go/tools/cache/shared_informer.go:546 +0x9b
volcano.sh/volcano/vendor/k8s.io/apimachinery/pkg/util/wait.(*Group).Start.func1(0xc00036a290, 0xc0006a31f0)
	/Users/yuan.chen/GolandProjects/src/volcano.sh/volcano/vendor/k8s.io/apimachinery/pkg/util/wait/wait.go:71 +0x59
created by volcano.sh/volcano/vendor/k8s.io/apimachinery/pkg/util/wait.(*Group).Start
	/Users/yuan.chen/GolandProjects/src/volcano.sh/volcano/vendor/k8s.io/apimachinery/pkg/util/wait/wait.go:69 +0x62

goroutine 140 [select]:
volcano.sh/volcano/vendor/k8s.io/client-go/tools/cache.(*processorListener).pop(0xc000507400)
	/Users/yuan.chen/GolandProjects/src/volcano.sh/volcano/vendor/k8s.io/client-go/tools/cache/shared_informer.go:517 +0x18d
volcano.sh/volcano/vendor/k8s.io/apimachinery/pkg/util/wait.(*Group).Start.func1(0xc00036a290, 0xc0006a3200)
	/Users/yuan.chen/GolandProjects/src/volcano.sh/volcano/vendor/k8s.io/apimachinery/pkg/util/wait/wait.go:71 +0x59
created by volcano.sh/volcano/vendor/k8s.io/apimachinery/pkg/util/wait.(*Group).Start
	/Users/yuan.chen/GolandProjects/src/volcano.sh/volcano/vendor/k8s.io/apimachinery/pkg/util/wait/wait.go:69 +0x62

goroutine 142 [select]:
volcano.sh/volcano/vendor/k8s.io/client-go/tools/cache.(*processorListener).pop(0xc000507680)
	/Users/yuan.chen/GolandProjects/src/volcano.sh/volcano/vendor/k8s.io/client-go/tools/cache/shared_informer.go:517 +0x18d
volcano.sh/volcano/vendor/k8s.io/apimachinery/pkg/util/wait.(*Group).Start.func1(0xc00036a300, 0xc0006a3220)
	/Users/yuan.chen/GolandProjects/src/volcano.sh/volcano/vendor/k8s.io/apimachinery/pkg/util/wait/wait.go:71 +0x59
created by volcano.sh/volcano/vendor/k8s.io/apimachinery/pkg/util/wait.(*Group).Start
	/Users/yuan.chen/GolandProjects/src/volcano.sh/volcano/vendor/k8s.io/apimachinery/pkg/util/wait/wait.go:69 +0x62

goroutine 158 [select]:
volcano.sh/volcano/vendor/k8s.io/client-go/tools/cache.(*Reflector).watchHandler(0xc0000fa000, 0x23a3860, 0xc0009b6ba0, 0xc00061fbe0, 0xc000446900, 0x0, 0x0, 0x0)
	/Users/yuan.chen/GolandProjects/src/volcano.sh/volcano/vendor/k8s.io/client-go/tools/cache/reflector.go:283 +0x1ec
volcano.sh/volcano/vendor/k8s.io/client-go/tools/cache.(*Reflector).ListAndWatch(0xc0000fa000, 0x0, 0x0, 0x0)
	/Users/yuan.chen/GolandProjects/src/volcano.sh/volcano/vendor/k8s.io/client-go/tools/cache/reflector.go:254 +0xc73
volcano.sh/volcano/vendor/k8s.io/client-go/tools/cache.(*Reflector).Run.func1()
	/Users/yuan.chen/GolandProjects/src/volcano.sh/volcano/vendor/k8s.io/client-go/tools/cache/reflector.go:124 +0x33
volcano.sh/volcano/vendor/k8s.io/apimachinery/pkg/util/wait.JitterUntil.func1(0xc0006936f0)
	/Users/yuan.chen/GolandProjects/src/volcano.sh/volcano/vendor/k8s.io/apimachinery/pkg/util/wait/wait.go:133 +0x5e
volcano.sh/volcano/vendor/k8s.io/apimachinery/pkg/util/wait.JitterUntil(0xc00061fef0, 0x3b9aca00, 0x0, 0x1, 0x0)
	/Users/yuan.chen/GolandProjects/src/volcano.sh/volcano/vendor/k8s.io/apimachinery/pkg/util/wait/wait.go:134 +0xf8
volcano.sh/volcano/vendor/k8s.io/apimachinery/pkg/util/wait.Until(...)
	/Users/yuan.chen/GolandProjects/src/volcano.sh/volcano/vendor/k8s.io/apimachinery/pkg/util/wait/wait.go:88
volcano.sh/volcano/vendor/k8s.io/client-go/tools/cache.(*Reflector).Run(0xc0000fa000, 0x0)
	/Users/yuan.chen/GolandProjects/src/volcano.sh/volcano/vendor/k8s.io/client-go/tools/cache/reflector.go:123 +0x169
volcano.sh/volcano/vendor/k8s.io/apimachinery/pkg/util/wait.(*Group).StartWithChannel.func1()
	/Users/yuan.chen/GolandProjects/src/volcano.sh/volcano/vendor/k8s.io/apimachinery/pkg/util/wait/wait.go:54 +0x2e
volcano.sh/volcano/vendor/k8s.io/apimachinery/pkg/util/wait.(*Group).Start.func1(0xc000438070, 0xc00030a1a0)
	/Users/yuan.chen/GolandProjects/src/volcano.sh/volcano/vendor/k8s.io/apimachinery/pkg/util/wait/wait.go:71 +0x59
created by volcano.sh/volcano/vendor/k8s.io/apimachinery/pkg/util/wait.(*Group).Start
	/Users/yuan.chen/GolandProjects/src/volcano.sh/volcano/vendor/k8s.io/apimachinery/pkg/util/wait/wait.go:69 +0x62

goroutine 144 [select]:
volcano.sh/volcano/vendor/k8s.io/client-go/tools/cache.(*processorListener).pop(0xc00014c400)
	/Users/yuan.chen/GolandProjects/src/volcano.sh/volcano/vendor/k8s.io/client-go/tools/cache/shared_informer.go:517 +0x18d
volcano.sh/volcano/vendor/k8s.io/apimachinery/pkg/util/wait.(*Group).Start.func1(0xc00036a5a0, 0xc0006a3240)
	/Users/yuan.chen/GolandProjects/src/volcano.sh/volcano/vendor/k8s.io/apimachinery/pkg/util/wait/wait.go:71 +0x59
created by volcano.sh/volcano/vendor/k8s.io/apimachinery/pkg/util/wait.(*Group).Start
	/Users/yuan.chen/GolandProjects/src/volcano.sh/volcano/vendor/k8s.io/apimachinery/pkg/util/wait/wait.go:69 +0x62

goroutine 13 [select]:
volcano.sh/volcano/vendor/k8s.io/client-go/tools/cache.(*processorListener).pop(0xc000507b00)
	/Users/yuan.chen/GolandProjects/src/volcano.sh/volcano/vendor/k8s.io/client-go/tools/cache/shared_informer.go:517 +0x18d
volcano.sh/volcano/vendor/k8s.io/apimachinery/pkg/util/wait.(*Group).Start.func1(0xc00036a3e0, 0xc000364580)
	/Users/yuan.chen/GolandProjects/src/volcano.sh/volcano/vendor/k8s.io/apimachinery/pkg/util/wait/wait.go:71 +0x59
created by volcano.sh/volcano/vendor/k8s.io/apimachinery/pkg/util/wait.(*Group).Start
	/Users/yuan.chen/GolandProjects/src/volcano.sh/volcano/vendor/k8s.io/apimachinery/pkg/util/wait/wait.go:69 +0x62

goroutine 106 [select]:
volcano.sh/volcano/vendor/k8s.io/client-go/tools/cache.(*Reflector).watchHandler(0xc0003e80a0, 0x23a3860, 0xc000a3b7d0, 0xc000a11be0, 0xc0000ecf60, 0x0, 0x0, 0x0)
	/Users/yuan.chen/GolandProjects/src/volcano.sh/volcano/vendor/k8s.io/client-go/tools/cache/reflector.go:283 +0x1ec
volcano.sh/volcano/vendor/k8s.io/client-go/tools/cache.(*Reflector).ListAndWatch(0xc0003e80a0, 0x0, 0x0, 0x0)
	/Users/yuan.chen/GolandProjects/src/volcano.sh/volcano/vendor/k8s.io/client-go/tools/cache/reflector.go:254 +0xc73
volcano.sh/volcano/vendor/k8s.io/client-go/tools/cache.(*Reflector).Run.func1()
	/Users/yuan.chen/GolandProjects/src/volcano.sh/volcano/vendor/k8s.io/client-go/tools/cache/reflector.go:124 +0x33
volcano.sh/volcano/vendor/k8s.io/apimachinery/pkg/util/wait.JitterUntil.func1(0xc0006946f0)
	/Users/yuan.chen/GolandProjects/src/volcano.sh/volcano/vendor/k8s.io/apimachinery/pkg/util/wait/wait.go:133 +0x5e
volcano.sh/volcano/vendor/k8s.io/apimachinery/pkg/util/wait.JitterUntil(0xc000a11ef0, 0x3b9aca00, 0x0, 0x1, 0x0)
	/Users/yuan.chen/GolandProjects/src/volcano.sh/volcano/vendor/k8s.io/apimachinery/pkg/util/wait/wait.go:134 +0xf8
volcano.sh/volcano/vendor/k8s.io/apimachinery/pkg/util/wait.Until(...)
	/Users/yuan.chen/GolandProjects/src/volcano.sh/volcano/vendor/k8s.io/apimachinery/pkg/util/wait/wait.go:88
volcano.sh/volcano/vendor/k8s.io/client-go/tools/cache.(*Reflector).Run(0xc0003e80a0, 0x0)
	/Users/yuan.chen/GolandProjects/src/volcano.sh/volcano/vendor/k8s.io/client-go/tools/cache/reflector.go:123 +0x169
volcano.sh/volcano/vendor/k8s.io/apimachinery/pkg/util/wait.(*Group).StartWithChannel.func1()
	/Users/yuan.chen/GolandProjects/src/volcano.sh/volcano/vendor/k8s.io/apimachinery/pkg/util/wait/wait.go:54 +0x2e
volcano.sh/volcano/vendor/k8s.io/apimachinery/pkg/util/wait.(*Group).Start.func1(0xc000384500, 0xc00063e6a0)
	/Users/yuan.chen/GolandProjects/src/volcano.sh/volcano/vendor/k8s.io/apimachinery/pkg/util/wait/wait.go:71 +0x59
created by volcano.sh/volcano/vendor/k8s.io/apimachinery/pkg/util/wait.(*Group).Start
	/Users/yuan.chen/GolandProjects/src/volcano.sh/volcano/vendor/k8s.io/apimachinery/pkg/util/wait/wait.go:69 +0x62

goroutine 75 [chan receive]:
volcano.sh/volcano/vendor/k8s.io/client-go/tools/cache.(*processorListener).run.func1.1(0x0, 0x339b7f0, 0x8)
	/Users/yuan.chen/GolandProjects/src/volcano.sh/volcano/vendor/k8s.io/client-go/tools/cache/shared_informer.go:549 +0x54
volcano.sh/volcano/vendor/k8s.io/apimachinery/pkg/util/wait.ExponentialBackoff(0x989680, 0x3ff0000000000000, 0x3fb999999999999a, 0x5, 0xc0005d7dd8, 0x0, 0x0)
	/Users/yuan.chen/GolandProjects/src/volcano.sh/volcano/vendor/k8s.io/apimachinery/pkg/util/wait/wait.go:203 +0xde
volcano.sh/volcano/vendor/k8s.io/client-go/tools/cache.(*processorListener).run.func1()
	/Users/yuan.chen/GolandProjects/src/volcano.sh/volcano/vendor/k8s.io/client-go/tools/cache/shared_informer.go:548 +0x89
volcano.sh/volcano/vendor/k8s.io/apimachinery/pkg/util/wait.JitterUntil.func1(0xc00006cf40)
	/Users/yuan.chen/GolandProjects/src/volcano.sh/volcano/vendor/k8s.io/apimachinery/pkg/util/wait/wait.go:133 +0x5e
volcano.sh/volcano/vendor/k8s.io/apimachinery/pkg/util/wait.JitterUntil(0xc0005d7f40, 0xdf8475800, 0x0, 0xc0000d0401, 0xc00038a0c0)
	/Users/yuan.chen/GolandProjects/src/volcano.sh/volcano/vendor/k8s.io/apimachinery/pkg/util/wait/wait.go:134 +0xf8
volcano.sh/volcano/vendor/k8s.io/apimachinery/pkg/util/wait.Until(...)
	/Users/yuan.chen/GolandProjects/src/volcano.sh/volcano/vendor/k8s.io/apimachinery/pkg/util/wait/wait.go:88
volcano.sh/volcano/vendor/k8s.io/client-go/tools/cache.(*processorListener).run(0xc000507880)
	/Users/yuan.chen/GolandProjects/src/volcano.sh/volcano/vendor/k8s.io/client-go/tools/cache/shared_informer.go:546 +0x9b
volcano.sh/volcano/vendor/k8s.io/apimachinery/pkg/util/wait.(*Group).Start.func1(0xc00036a370, 0xc0000d0a10)
	/Users/yuan.chen/GolandProjects/src/volcano.sh/volcano/vendor/k8s.io/apimachinery/pkg/util/wait/wait.go:71 +0x59
created by volcano.sh/volcano/vendor/k8s.io/apimachinery/pkg/util/wait.(*Group).Start
	/Users/yuan.chen/GolandProjects/src/volcano.sh/volcano/vendor/k8s.io/apimachinery/pkg/util/wait/wait.go:69 +0x62

goroutine 76 [select]:
volcano.sh/volcano/vendor/k8s.io/client-go/tools/cache.(*processorListener).pop(0xc000507880)
	/Users/yuan.chen/GolandProjects/src/volcano.sh/volcano/vendor/k8s.io/client-go/tools/cache/shared_informer.go:517 +0x18d
volcano.sh/volcano/vendor/k8s.io/apimachinery/pkg/util/wait.(*Group).Start.func1(0xc00036a370, 0xc0000d0a70)
	/Users/yuan.chen/GolandProjects/src/volcano.sh/volcano/vendor/k8s.io/apimachinery/pkg/util/wait/wait.go:71 +0x59
created by volcano.sh/volcano/vendor/k8s.io/apimachinery/pkg/util/wait.(*Group).Start
	/Users/yuan.chen/GolandProjects/src/volcano.sh/volcano/vendor/k8s.io/apimachinery/pkg/util/wait/wait.go:69 +0x62

goroutine 121 [chan receive]:
volcano.sh/volcano/vendor/k8s.io/client-go/tools/cache.(*processorListener).run.func1.1(0x0, 0x0, 0x0)
	/Users/yuan.chen/GolandProjects/src/volcano.sh/volcano/vendor/k8s.io/client-go/tools/cache/shared_informer.go:549 +0x54
volcano.sh/volcano/vendor/k8s.io/apimachinery/pkg/util/wait.ExponentialBackoff(0x989680, 0x3ff0000000000000, 0x3fb999999999999a, 0x5, 0xc000ab6dd8, 0x0, 0x0)
	/Users/yuan.chen/GolandProjects/src/volcano.sh/volcano/vendor/k8s.io/apimachinery/pkg/util/wait/wait.go:203 +0xde
volcano.sh/volcano/vendor/k8s.io/client-go/tools/cache.(*processorListener).run.func1()
	/Users/yuan.chen/GolandProjects/src/volcano.sh/volcano/vendor/k8s.io/client-go/tools/cache/shared_informer.go:548 +0x89
volcano.sh/volcano/vendor/k8s.io/apimachinery/pkg/util/wait.JitterUntil.func1(0xc00056f740)
	/Users/yuan.chen/GolandProjects/src/volcano.sh/volcano/vendor/k8s.io/apimachinery/pkg/util/wait/wait.go:133 +0x5e
volcano.sh/volcano/vendor/k8s.io/apimachinery/pkg/util/wait.JitterUntil(0xc000ab6f40, 0xdf8475800, 0x0, 0x1030501, 0xc00042e240)
	/Users/yuan.chen/GolandProjects/src/volcano.sh/volcano/vendor/k8s.io/apimachinery/pkg/util/wait/wait.go:134 +0xf8
volcano.sh/volcano/vendor/k8s.io/apimachinery/pkg/util/wait.Until(...)
	/Users/yuan.chen/GolandProjects/src/volcano.sh/volcano/vendor/k8s.io/apimachinery/pkg/util/wait/wait.go:88
volcano.sh/volcano/vendor/k8s.io/client-go/tools/cache.(*processorListener).run(0xc000507d00)
	/Users/yuan.chen/GolandProjects/src/volcano.sh/volcano/vendor/k8s.io/client-go/tools/cache/shared_informer.go:546 +0x9b
volcano.sh/volcano/vendor/k8s.io/apimachinery/pkg/util/wait.(*Group).Start.func1(0xc00036a450, 0xc000502360)
	/Users/yuan.chen/GolandProjects/src/volcano.sh/volcano/vendor/k8s.io/apimachinery/pkg/util/wait/wait.go:71 +0x59
created by volcano.sh/volcano/vendor/k8s.io/apimachinery/pkg/util/wait.(*Group).Start
	/Users/yuan.chen/GolandProjects/src/volcano.sh/volcano/vendor/k8s.io/apimachinery/pkg/util/wait/wait.go:69 +0x62

goroutine 16 [chan receive (nil chan)]:
volcano.sh/volcano/vendor/k8s.io/client-go/tools/cache.(*controller).Run.func1(0x0, 0xc000470700)
	/Users/yuan.chen/GolandProjects/src/volcano.sh/volcano/vendor/k8s.io/client-go/tools/cache/controller.go:103 +0x34
created by volcano.sh/volcano/vendor/k8s.io/client-go/tools/cache.(*controller).Run
	/Users/yuan.chen/GolandProjects/src/volcano.sh/volcano/vendor/k8s.io/client-go/tools/cache/controller.go:102 +0xae

goroutine 178 [chan receive]:
volcano.sh/volcano/vendor/k8s.io/client-go/tools/cache.(*sharedProcessor).run(0xc00036a460, 0xc000114de0)
	/Users/yuan.chen/GolandProjects/src/volcano.sh/volcano/vendor/k8s.io/client-go/tools/cache/shared_informer.go:425 +0x49
volcano.sh/volcano/vendor/k8s.io/apimachinery/pkg/util/wait.(*Group).StartWithChannel.func1()
	/Users/yuan.chen/GolandProjects/src/volcano.sh/volcano/vendor/k8s.io/apimachinery/pkg/util/wait/wait.go:54 +0x2e
volcano.sh/volcano/vendor/k8s.io/apimachinery/pkg/util/wait.(*Group).Start.func1(0xc000540ac0, 0xc00000f660)
	/Users/yuan.chen/GolandProjects/src/volcano.sh/volcano/vendor/k8s.io/apimachinery/pkg/util/wait/wait.go:71 +0x59
created by volcano.sh/volcano/vendor/k8s.io/apimachinery/pkg/util/wait.(*Group).Start
	/Users/yuan.chen/GolandProjects/src/volcano.sh/volcano/vendor/k8s.io/apimachinery/pkg/util/wait/wait.go:69 +0x62

goroutine 179 [chan receive (nil chan)]:
volcano.sh/volcano/vendor/k8s.io/client-go/tools/cache.(*controller).Run.func1(0x0, 0xc00014dd00)
	/Users/yuan.chen/GolandProjects/src/volcano.sh/volcano/vendor/k8s.io/client-go/tools/cache/controller.go:103 +0x34
created by volcano.sh/volcano/vendor/k8s.io/client-go/tools/cache.(*controller).Run
	/Users/yuan.chen/GolandProjects/src/volcano.sh/volcano/vendor/k8s.io/client-go/tools/cache/controller.go:102 +0xae

goroutine 119 [chan receive]:
volcano.sh/volcano/vendor/k8s.io/client-go/tools/cache.(*processorListener).run.func1.1(0x0, 0x10, 0x18)
	/Users/yuan.chen/GolandProjects/src/volcano.sh/volcano/vendor/k8s.io/client-go/tools/cache/shared_informer.go:549 +0x54
volcano.sh/volcano/vendor/k8s.io/apimachinery/pkg/util/wait.ExponentialBackoff(0x989680, 0x3ff0000000000000, 0x3fb999999999999a, 0x5, 0xc000406dd8, 0x0, 0x0)
	/Users/yuan.chen/GolandProjects/src/volcano.sh/volcano/vendor/k8s.io/apimachinery/pkg/util/wait/wait.go:203 +0xde
volcano.sh/volcano/vendor/k8s.io/client-go/tools/cache.(*processorListener).run.func1()
	/Users/yuan.chen/GolandProjects/src/volcano.sh/volcano/vendor/k8s.io/client-go/tools/cache/shared_informer.go:548 +0x89
volcano.sh/volcano/vendor/k8s.io/apimachinery/pkg/util/wait.JitterUntil.func1(0xc000693f40)
	/Users/yuan.chen/GolandProjects/src/volcano.sh/volcano/vendor/k8s.io/apimachinery/pkg/util/wait/wait.go:133 +0x5e
volcano.sh/volcano/vendor/k8s.io/apimachinery/pkg/util/wait.JitterUntil(0xc000406f40, 0xdf8475800, 0x0, 0xc000502001, 0xc00042e180)
	/Users/yuan.chen/GolandProjects/src/volcano.sh/volcano/vendor/k8s.io/apimachinery/pkg/util/wait/wait.go:134 +0xf8
volcano.sh/volcano/vendor/k8s.io/apimachinery/pkg/util/wait.Until(...)
	/Users/yuan.chen/GolandProjects/src/volcano.sh/volcano/vendor/k8s.io/apimachinery/pkg/util/wait/wait.go:88
volcano.sh/volcano/vendor/k8s.io/client-go/tools/cache.(*processorListener).run(0xc000506e00)
	/Users/yuan.chen/GolandProjects/src/volcano.sh/volcano/vendor/k8s.io/client-go/tools/cache/shared_informer.go:546 +0x9b
volcano.sh/volcano/vendor/k8s.io/apimachinery/pkg/util/wait.(*Group).Start.func1(0xc00036a140, 0xc000502330)
	/Users/yuan.chen/GolandProjects/src/volcano.sh/volcano/vendor/k8s.io/apimachinery/pkg/util/wait/wait.go:71 +0x59
created by volcano.sh/volcano/vendor/k8s.io/apimachinery/pkg/util/wait.(*Group).Start
	/Users/yuan.chen/GolandProjects/src/volcano.sh/volcano/vendor/k8s.io/apimachinery/pkg/util/wait/wait.go:69 +0x62

goroutine 120 [select]:
volcano.sh/volcano/vendor/k8s.io/client-go/tools/cache.(*processorListener).pop(0xc000506e00)
	/Users/yuan.chen/GolandProjects/src/volcano.sh/volcano/vendor/k8s.io/client-go/tools/cache/shared_informer.go:517 +0x18d
volcano.sh/volcano/vendor/k8s.io/apimachinery/pkg/util/wait.(*Group).Start.func1(0xc00036a140, 0xc000502340)
	/Users/yuan.chen/GolandProjects/src/volcano.sh/volcano/vendor/k8s.io/apimachinery/pkg/util/wait/wait.go:71 +0x59
created by volcano.sh/volcano/vendor/k8s.io/apimachinery/pkg/util/wait.(*Group).Start
	/Users/yuan.chen/GolandProjects/src/volcano.sh/volcano/vendor/k8s.io/apimachinery/pkg/util/wait/wait.go:69 +0x62

goroutine 165 [select]:
volcano.sh/volcano/vendor/k8s.io/client-go/tools/cache.(*Reflector).watchHandler(0xc0005c0000, 0x23a3860, 0xc0007d55f0, 0xc000733be0, 0xc0000ecba0, 0x0, 0x0, 0x0)
	/Users/yuan.chen/GolandProjects/src/volcano.sh/volcano/vendor/k8s.io/client-go/tools/cache/reflector.go:283 +0x1ec
volcano.sh/volcano/vendor/k8s.io/client-go/tools/cache.(*Reflector).ListAndWatch(0xc0005c0000, 0x0, 0x0, 0x0)
	/Users/yuan.chen/GolandProjects/src/volcano.sh/volcano/vendor/k8s.io/client-go/tools/cache/reflector.go:254 +0xc73
volcano.sh/volcano/vendor/k8s.io/client-go/tools/cache.(*Reflector).Run.func1()
	/Users/yuan.chen/GolandProjects/src/volcano.sh/volcano/vendor/k8s.io/client-go/tools/cache/reflector.go:124 +0x33
volcano.sh/volcano/vendor/k8s.io/apimachinery/pkg/util/wait.JitterUntil.func1(0xc000393ef0)
	/Users/yuan.chen/GolandProjects/src/volcano.sh/volcano/vendor/k8s.io/apimachinery/pkg/util/wait/wait.go:133 +0x5e
volcano.sh/volcano/vendor/k8s.io/apimachinery/pkg/util/wait.JitterUntil(0xc000733ef0, 0x3b9aca00, 0x0, 0x1, 0x0)
	/Users/yuan.chen/GolandProjects/src/volcano.sh/volcano/vendor/k8s.io/apimachinery/pkg/util/wait/wait.go:134 +0xf8
volcano.sh/volcano/vendor/k8s.io/apimachinery/pkg/util/wait.Until(...)
	/Users/yuan.chen/GolandProjects/src/volcano.sh/volcano/vendor/k8s.io/apimachinery/pkg/util/wait/wait.go:88
volcano.sh/volcano/vendor/k8s.io/client-go/tools/cache.(*Reflector).Run(0xc0005c0000, 0x0)
	/Users/yuan.chen/GolandProjects/src/volcano.sh/volcano/vendor/k8s.io/client-go/tools/cache/reflector.go:123 +0x169
volcano.sh/volcano/vendor/k8s.io/apimachinery/pkg/util/wait.(*Group).StartWithChannel.func1()
	/Users/yuan.chen/GolandProjects/src/volcano.sh/volcano/vendor/k8s.io/apimachinery/pkg/util/wait/wait.go:54 +0x2e
volcano.sh/volcano/vendor/k8s.io/apimachinery/pkg/util/wait.(*Group).Start.func1(0xc000588130, 0xc0004b09a0)
	/Users/yuan.chen/GolandProjects/src/volcano.sh/volcano/vendor/k8s.io/apimachinery/pkg/util/wait/wait.go:71 +0x59
created by volcano.sh/volcano/vendor/k8s.io/apimachinery/pkg/util/wait.(*Group).Start
	/Users/yuan.chen/GolandProjects/src/volcano.sh/volcano/vendor/k8s.io/apimachinery/pkg/util/wait/wait.go:69 +0x62

goroutine 77 [chan receive]:
volcano.sh/volcano/vendor/k8s.io/client-go/tools/cache.(*processorListener).run.func1.1(0x0, 0x339b7f0, 0x8)
	/Users/yuan.chen/GolandProjects/src/volcano.sh/volcano/vendor/k8s.io/client-go/tools/cache/shared_informer.go:549 +0x54
volcano.sh/volcano/vendor/k8s.io/apimachinery/pkg/util/wait.ExponentialBackoff(0x989680, 0x3ff0000000000000, 0x3fb999999999999a, 0x5, 0xc0006d3dd8, 0x0, 0x0)
	/Users/yuan.chen/GolandProjects/src/volcano.sh/volcano/vendor/k8s.io/apimachinery/pkg/util/wait/wait.go:203 +0xde
volcano.sh/volcano/vendor/k8s.io/client-go/tools/cache.(*processorListener).run.func1()
	/Users/yuan.chen/GolandProjects/src/volcano.sh/volcano/vendor/k8s.io/client-go/tools/cache/shared_informer.go:548 +0x89
volcano.sh/volcano/vendor/k8s.io/apimachinery/pkg/util/wait.JitterUntil.func1(0xc00006cf40)
	/Users/yuan.chen/GolandProjects/src/volcano.sh/volcano/vendor/k8s.io/apimachinery/pkg/util/wait/wait.go:133 +0x5e
volcano.sh/volcano/vendor/k8s.io/apimachinery/pkg/util/wait.JitterUntil(0xc0006d3f40, 0xdf8475800, 0x0, 0xc0000d0401, 0xc00042e1e0)
	/Users/yuan.chen/GolandProjects/src/volcano.sh/volcano/vendor/k8s.io/apimachinery/pkg/util/wait/wait.go:134 +0xf8
volcano.sh/volcano/vendor/k8s.io/apimachinery/pkg/util/wait.Until(...)
	/Users/yuan.chen/GolandProjects/src/volcano.sh/volcano/vendor/k8s.io/apimachinery/pkg/util/wait/wait.go:88
volcano.sh/volcano/vendor/k8s.io/client-go/tools/cache.(*processorListener).run(0xc000506f80)
	/Users/yuan.chen/GolandProjects/src/volcano.sh/volcano/vendor/k8s.io/client-go/tools/cache/shared_informer.go:546 +0x9b
volcano.sh/volcano/vendor/k8s.io/apimachinery/pkg/util/wait.(*Group).Start.func1(0xc00036a1b0, 0xc0000d0a80)
	/Users/yuan.chen/GolandProjects/src/volcano.sh/volcano/vendor/k8s.io/apimachinery/pkg/util/wait/wait.go:71 +0x59
created by volcano.sh/volcano/vendor/k8s.io/apimachinery/pkg/util/wait.(*Group).Start
	/Users/yuan.chen/GolandProjects/src/volcano.sh/volcano/vendor/k8s.io/apimachinery/pkg/util/wait/wait.go:69 +0x62

goroutine 78 [select]:
volcano.sh/volcano/vendor/k8s.io/client-go/tools/cache.(*processorListener).pop(0xc000506f80)
	/Users/yuan.chen/GolandProjects/src/volcano.sh/volcano/vendor/k8s.io/client-go/tools/cache/shared_informer.go:517 +0x18d
volcano.sh/volcano/vendor/k8s.io/apimachinery/pkg/util/wait.(*Group).Start.func1(0xc00036a1b0, 0xc0000d0a90)
	/Users/yuan.chen/GolandProjects/src/volcano.sh/volcano/vendor/k8s.io/apimachinery/pkg/util/wait/wait.go:71 +0x59
created by volcano.sh/volcano/vendor/k8s.io/apimachinery/pkg/util/wait.(*Group).Start
	/Users/yuan.chen/GolandProjects/src/volcano.sh/volcano/vendor/k8s.io/apimachinery/pkg/util/wait/wait.go:69 +0x62

goroutine 86 [select]:
volcano.sh/volcano/vendor/k8s.io/client-go/tools/cache.(*Reflector).watchHandler(0xc0005c6000, 0x23a3860, 0xc00032c990, 0xc000a13be0, 0xc0000bea20, 0x0, 0x0, 0x0)
	/Users/yuan.chen/GolandProjects/src/volcano.sh/volcano/vendor/k8s.io/client-go/tools/cache/reflector.go:283 +0x1ec
volcano.sh/volcano/vendor/k8s.io/client-go/tools/cache.(*Reflector).ListAndWatch(0xc0005c6000, 0x0, 0x0, 0x0)
	/Users/yuan.chen/GolandProjects/src/volcano.sh/volcano/vendor/k8s.io/client-go/tools/cache/reflector.go:254 +0xc73
volcano.sh/volcano/vendor/k8s.io/client-go/tools/cache.(*Reflector).Run.func1()
	/Users/yuan.chen/GolandProjects/src/volcano.sh/volcano/vendor/k8s.io/client-go/tools/cache/reflector.go:124 +0x33
volcano.sh/volcano/vendor/k8s.io/apimachinery/pkg/util/wait.JitterUntil.func1(0xc000394ef0)
	/Users/yuan.chen/GolandProjects/src/volcano.sh/volcano/vendor/k8s.io/apimachinery/pkg/util/wait/wait.go:133 +0x5e
volcano.sh/volcano/vendor/k8s.io/apimachinery/pkg/util/wait.JitterUntil(0xc000a13ef0, 0x3b9aca00, 0x0, 0x1, 0x0)
	/Users/yuan.chen/GolandProjects/src/volcano.sh/volcano/vendor/k8s.io/apimachinery/pkg/util/wait/wait.go:134 +0xf8
volcano.sh/volcano/vendor/k8s.io/apimachinery/pkg/util/wait.Until(...)
	/Users/yuan.chen/GolandProjects/src/volcano.sh/volcano/vendor/k8s.io/apimachinery/pkg/util/wait/wait.go:88
volcano.sh/volcano/vendor/k8s.io/client-go/tools/cache.(*Reflector).Run(0xc0005c6000, 0x0)
	/Users/yuan.chen/GolandProjects/src/volcano.sh/volcano/vendor/k8s.io/client-go/tools/cache/reflector.go:123 +0x169
volcano.sh/volcano/vendor/k8s.io/apimachinery/pkg/util/wait.(*Group).StartWithChannel.func1()
	/Users/yuan.chen/GolandProjects/src/volcano.sh/volcano/vendor/k8s.io/apimachinery/pkg/util/wait/wait.go:54 +0x2e
volcano.sh/volcano/vendor/k8s.io/apimachinery/pkg/util/wait.(*Group).Start.func1(0xc0004a6070, 0xc000456180)
	/Users/yuan.chen/GolandProjects/src/volcano.sh/volcano/vendor/k8s.io/apimachinery/pkg/util/wait/wait.go:71 +0x59
created by volcano.sh/volcano/vendor/k8s.io/apimachinery/pkg/util/wait.(*Group).Start
	/Users/yuan.chen/GolandProjects/src/volcano.sh/volcano/vendor/k8s.io/apimachinery/pkg/util/wait/wait.go:69 +0x62

goroutine 80 [chan receive]:
volcano.sh/volcano/vendor/k8s.io/client-go/tools/cache.(*sharedProcessor).run(0xc00036a3f0, 0xc00038a120)
	/Users/yuan.chen/GolandProjects/src/volcano.sh/volcano/vendor/k8s.io/client-go/tools/cache/shared_informer.go:425 +0x49
volcano.sh/volcano/vendor/k8s.io/apimachinery/pkg/util/wait.(*Group).StartWithChannel.func1()
	/Users/yuan.chen/GolandProjects/src/volcano.sh/volcano/vendor/k8s.io/apimachinery/pkg/util/wait/wait.go:54 +0x2e
volcano.sh/volcano/vendor/k8s.io/apimachinery/pkg/util/wait.(*Group).Start.func1(0xc000638140, 0xc000520420)
	/Users/yuan.chen/GolandProjects/src/volcano.sh/volcano/vendor/k8s.io/apimachinery/pkg/util/wait/wait.go:71 +0x59
created by volcano.sh/volcano/vendor/k8s.io/apimachinery/pkg/util/wait.(*Group).Start
	/Users/yuan.chen/GolandProjects/src/volcano.sh/volcano/vendor/k8s.io/apimachinery/pkg/util/wait/wait.go:69 +0x62

goroutine 81 [chan receive (nil chan)]:
volcano.sh/volcano/vendor/k8s.io/client-go/tools/cache.(*controller).Run.func1(0x0, 0xc0003f2b80)
	/Users/yuan.chen/GolandProjects/src/volcano.sh/volcano/vendor/k8s.io/client-go/tools/cache/controller.go:103 +0x34
created by volcano.sh/volcano/vendor/k8s.io/client-go/tools/cache.(*controller).Run
	/Users/yuan.chen/GolandProjects/src/volcano.sh/volcano/vendor/k8s.io/client-go/tools/cache/controller.go:102 +0xae

goroutine 124 [select]:
volcano.sh/volcano/vendor/k8s.io/client-go/tools/cache.(*processorListener).pop(0xc000507200)
	/Users/yuan.chen/GolandProjects/src/volcano.sh/volcano/vendor/k8s.io/client-go/tools/cache/shared_informer.go:517 +0x18d
volcano.sh/volcano/vendor/k8s.io/apimachinery/pkg/util/wait.(*Group).Start.func1(0xc00036a220, 0xc0005023b0)
	/Users/yuan.chen/GolandProjects/src/volcano.sh/volcano/vendor/k8s.io/apimachinery/pkg/util/wait/wait.go:71 +0x59
created by volcano.sh/volcano/vendor/k8s.io/apimachinery/pkg/util/wait.(*Group).Start
	/Users/yuan.chen/GolandProjects/src/volcano.sh/volcano/vendor/k8s.io/apimachinery/pkg/util/wait/wait.go:69 +0x62

goroutine 107 [chan receive]:
volcano.sh/volcano/vendor/k8s.io/client-go/tools/cache.(*processorListener).run.func1.1(0x0, 0x10, 0x18)
	/Users/yuan.chen/GolandProjects/src/volcano.sh/volcano/vendor/k8s.io/client-go/tools/cache/shared_informer.go:549 +0x54
volcano.sh/volcano/vendor/k8s.io/apimachinery/pkg/util/wait.ExponentialBackoff(0x989680, 0x3ff0000000000000, 0x3fb999999999999a, 0x5, 0xc0005dcdd8, 0x0, 0x0)
	/Users/yuan.chen/GolandProjects/src/volcano.sh/volcano/vendor/k8s.io/apimachinery/pkg/util/wait/wait.go:203 +0xde
volcano.sh/volcano/vendor/k8s.io/client-go/tools/cache.(*processorListener).run.func1()
	/Users/yuan.chen/GolandProjects/src/volcano.sh/volcano/vendor/k8s.io/client-go/tools/cache/shared_informer.go:548 +0x89
volcano.sh/volcano/vendor/k8s.io/apimachinery/pkg/util/wait.JitterUntil.func1(0xc000694740)
	/Users/yuan.chen/GolandProjects/src/volcano.sh/volcano/vendor/k8s.io/apimachinery/pkg/util/wait/wait.go:133 +0x5e
volcano.sh/volcano/vendor/k8s.io/apimachinery/pkg/util/wait.JitterUntil(0xc0005dcf40, 0xdf8475800, 0x0, 0xc000166701, 0xc0003b60c0)
	/Users/yuan.chen/GolandProjects/src/volcano.sh/volcano/vendor/k8s.io/apimachinery/pkg/util/wait/wait.go:134 +0xf8
volcano.sh/volcano/vendor/k8s.io/apimachinery/pkg/util/wait.Until(...)
	/Users/yuan.chen/GolandProjects/src/volcano.sh/volcano/vendor/k8s.io/apimachinery/pkg/util/wait/wait.go:88
volcano.sh/volcano/vendor/k8s.io/client-go/tools/cache.(*processorListener).run(0xc000507f80)
	/Users/yuan.chen/GolandProjects/src/volcano.sh/volcano/vendor/k8s.io/client-go/tools/cache/shared_informer.go:546 +0x9b
volcano.sh/volcano/vendor/k8s.io/apimachinery/pkg/util/wait.(*Group).Start.func1(0xc00036a4c0, 0xc00066eb90)
	/Users/yuan.chen/GolandProjects/src/volcano.sh/volcano/vendor/k8s.io/apimachinery/pkg/util/wait/wait.go:71 +0x59
created by volcano.sh/volcano/vendor/k8s.io/apimachinery/pkg/util/wait.(*Group).Start
	/Users/yuan.chen/GolandProjects/src/volcano.sh/volcano/vendor/k8s.io/apimachinery/pkg/util/wait/wait.go:69 +0x62

goroutine 108 [select]:
volcano.sh/volcano/vendor/k8s.io/client-go/tools/cache.(*processorListener).pop(0xc000507f80)
	/Users/yuan.chen/GolandProjects/src/volcano.sh/volcano/vendor/k8s.io/client-go/tools/cache/shared_informer.go:517 +0x18d
volcano.sh/volcano/vendor/k8s.io/apimachinery/pkg/util/wait.(*Group).Start.func1(0xc00036a4c0, 0xc00066eba0)
	/Users/yuan.chen/GolandProjects/src/volcano.sh/volcano/vendor/k8s.io/apimachinery/pkg/util/wait/wait.go:71 +0x59
created by volcano.sh/volcano/vendor/k8s.io/apimachinery/pkg/util/wait.(*Group).Start
	/Users/yuan.chen/GolandProjects/src/volcano.sh/volcano/vendor/k8s.io/apimachinery/pkg/util/wait/wait.go:69 +0x62

goroutine 194 [select]:
volcano.sh/volcano/vendor/k8s.io/client-go/tools/cache.(*Reflector).watchHandler(0xc000310140, 0x23a3860, 0xc0008ea030, 0xc000abdbe0, 0xc0003098c0, 0x0, 0x0, 0x0)
	/Users/yuan.chen/GolandProjects/src/volcano.sh/volcano/vendor/k8s.io/client-go/tools/cache/reflector.go:283 +0x1ec
volcano.sh/volcano/vendor/k8s.io/client-go/tools/cache.(*Reflector).ListAndWatch(0xc000310140, 0x0, 0x0, 0x0)
	/Users/yuan.chen/GolandProjects/src/volcano.sh/volcano/vendor/k8s.io/client-go/tools/cache/reflector.go:254 +0xc73
volcano.sh/volcano/vendor/k8s.io/client-go/tools/cache.(*Reflector).Run.func1()
	/Users/yuan.chen/GolandProjects/src/volcano.sh/volcano/vendor/k8s.io/client-go/tools/cache/reflector.go:124 +0x33
volcano.sh/volcano/vendor/k8s.io/apimachinery/pkg/util/wait.JitterUntil.func1(0xc000391ef0)
	/Users/yuan.chen/GolandProjects/src/volcano.sh/volcano/vendor/k8s.io/apimachinery/pkg/util/wait/wait.go:133 +0x5e
volcano.sh/volcano/vendor/k8s.io/apimachinery/pkg/util/wait.JitterUntil(0xc000abdef0, 0x3b9aca00, 0x0, 0x1, 0x0)
	/Users/yuan.chen/GolandProjects/src/volcano.sh/volcano/vendor/k8s.io/apimachinery/pkg/util/wait/wait.go:134 +0xf8
volcano.sh/volcano/vendor/k8s.io/apimachinery/pkg/util/wait.Until(...)
	/Users/yuan.chen/GolandProjects/src/volcano.sh/volcano/vendor/k8s.io/apimachinery/pkg/util/wait/wait.go:88
volcano.sh/volcano/vendor/k8s.io/client-go/tools/cache.(*Reflector).Run(0xc000310140, 0x0)
	/Users/yuan.chen/GolandProjects/src/volcano.sh/volcano/vendor/k8s.io/client-go/tools/cache/reflector.go:123 +0x169
volcano.sh/volcano/vendor/k8s.io/apimachinery/pkg/util/wait.(*Group).StartWithChannel.func1()
	/Users/yuan.chen/GolandProjects/src/volcano.sh/volcano/vendor/k8s.io/apimachinery/pkg/util/wait/wait.go:54 +0x2e
volcano.sh/volcano/vendor/k8s.io/apimachinery/pkg/util/wait.(*Group).Start.func1(0xc00018d440, 0xc0000e0840)
	/Users/yuan.chen/GolandProjects/src/volcano.sh/volcano/vendor/k8s.io/apimachinery/pkg/util/wait/wait.go:71 +0x59
created by volcano.sh/volcano/vendor/k8s.io/apimachinery/pkg/util/wait.(*Group).Start
	/Users/yuan.chen/GolandProjects/src/volcano.sh/volcano/vendor/k8s.io/apimachinery/pkg/util/wait/wait.go:69 +0x62

goroutine 180 [select]:
volcano.sh/volcano/vendor/k8s.io/client-go/tools/cache.(*Reflector).watchHandler(0xc000334b40, 0x23a3860, 0xc0009d6b40, 0xc000a17be0, 0xc000186cc0, 0x0, 0x0, 0x0)
	/Users/yuan.chen/GolandProjects/src/volcano.sh/volcano/vendor/k8s.io/client-go/tools/cache/reflector.go:283 +0x1ec
volcano.sh/volcano/vendor/k8s.io/client-go/tools/cache.(*Reflector).ListAndWatch(0xc000334b40, 0x0, 0x0, 0x0)
	/Users/yuan.chen/GolandProjects/src/volcano.sh/volcano/vendor/k8s.io/client-go/tools/cache/reflector.go:254 +0xc73
volcano.sh/volcano/vendor/k8s.io/client-go/tools/cache.(*Reflector).Run.func1()
	/Users/yuan.chen/GolandProjects/src/volcano.sh/volcano/vendor/k8s.io/client-go/tools/cache/reflector.go:124 +0x33
volcano.sh/volcano/vendor/k8s.io/apimachinery/pkg/util/wait.JitterUntil.func1(0xc0003936f0)
	/Users/yuan.chen/GolandProjects/src/volcano.sh/volcano/vendor/k8s.io/apimachinery/pkg/util/wait/wait.go:133 +0x5e
volcano.sh/volcano/vendor/k8s.io/apimachinery/pkg/util/wait.JitterUntil(0xc000a17ef0, 0x3b9aca00, 0x0, 0x1, 0x0)
	/Users/yuan.chen/GolandProjects/src/volcano.sh/volcano/vendor/k8s.io/apimachinery/pkg/util/wait/wait.go:134 +0xf8
volcano.sh/volcano/vendor/k8s.io/apimachinery/pkg/util/wait.Until(...)
	/Users/yuan.chen/GolandProjects/src/volcano.sh/volcano/vendor/k8s.io/apimachinery/pkg/util/wait/wait.go:88
volcano.sh/volcano/vendor/k8s.io/client-go/tools/cache.(*Reflector).Run(0xc000334b40, 0x0)
	/Users/yuan.chen/GolandProjects/src/volcano.sh/volcano/vendor/k8s.io/client-go/tools/cache/reflector.go:123 +0x169
volcano.sh/volcano/vendor/k8s.io/apimachinery/pkg/util/wait.(*Group).StartWithChannel.func1()
	/Users/yuan.chen/GolandProjects/src/volcano.sh/volcano/vendor/k8s.io/apimachinery/pkg/util/wait/wait.go:54 +0x2e
volcano.sh/volcano/vendor/k8s.io/apimachinery/pkg/util/wait.(*Group).Start.func1(0xc000540b00, 0xc00000f900)
	/Users/yuan.chen/GolandProjects/src/volcano.sh/volcano/vendor/k8s.io/apimachinery/pkg/util/wait/wait.go:71 +0x59
created by volcano.sh/volcano/vendor/k8s.io/apimachinery/pkg/util/wait.(*Group).Start
	/Users/yuan.chen/GolandProjects/src/volcano.sh/volcano/vendor/k8s.io/apimachinery/pkg/util/wait/wait.go:69 +0x62

goroutine 210 [select]:
volcano.sh/volcano/vendor/k8s.io/client-go/tools/cache.(*Reflector).watchHandler(0xc0004160a0, 0x23a3860, 0xc0005c4360, 0xc000ab9be0, 0xc0000ecc00, 0x0, 0x0, 0x0)
	/Users/yuan.chen/GolandProjects/src/volcano.sh/volcano/vendor/k8s.io/client-go/tools/cache/reflector.go:283 +0x1ec
volcano.sh/volcano/vendor/k8s.io/client-go/tools/cache.(*Reflector).ListAndWatch(0xc0004160a0, 0x0, 0x0, 0x0)
	/Users/yuan.chen/GolandProjects/src/volcano.sh/volcano/vendor/k8s.io/client-go/tools/cache/reflector.go:254 +0xc73
volcano.sh/volcano/vendor/k8s.io/client-go/tools/cache.(*Reflector).Run.func1()
	/Users/yuan.chen/GolandProjects/src/volcano.sh/volcano/vendor/k8s.io/client-go/tools/cache/reflector.go:124 +0x33
volcano.sh/volcano/vendor/k8s.io/apimachinery/pkg/util/wait.JitterUntil.func1(0xc0003926f0)
	/Users/yuan.chen/GolandProjects/src/volcano.sh/volcano/vendor/k8s.io/apimachinery/pkg/util/wait/wait.go:133 +0x5e
volcano.sh/volcano/vendor/k8s.io/apimachinery/pkg/util/wait.JitterUntil(0xc000ab9ef0, 0x3b9aca00, 0x0, 0x1, 0x0)
	/Users/yuan.chen/GolandProjects/src/volcano.sh/volcano/vendor/k8s.io/apimachinery/pkg/util/wait/wait.go:134 +0xf8
volcano.sh/volcano/vendor/k8s.io/apimachinery/pkg/util/wait.Until(...)
	/Users/yuan.chen/GolandProjects/src/volcano.sh/volcano/vendor/k8s.io/apimachinery/pkg/util/wait/wait.go:88
volcano.sh/volcano/vendor/k8s.io/client-go/tools/cache.(*Reflector).Run(0xc0004160a0, 0x0)
	/Users/yuan.chen/GolandProjects/src/volcano.sh/volcano/vendor/k8s.io/client-go/tools/cache/reflector.go:123 +0x169
volcano.sh/volcano/vendor/k8s.io/apimachinery/pkg/util/wait.(*Group).StartWithChannel.func1()
	/Users/yuan.chen/GolandProjects/src/volcano.sh/volcano/vendor/k8s.io/apimachinery/pkg/util/wait/wait.go:54 +0x2e
volcano.sh/volcano/vendor/k8s.io/apimachinery/pkg/util/wait.(*Group).Start.func1(0xc000638190, 0xc000520520)
	/Users/yuan.chen/GolandProjects/src/volcano.sh/volcano/vendor/k8s.io/apimachinery/pkg/util/wait/wait.go:71 +0x59
created by volcano.sh/volcano/vendor/k8s.io/apimachinery/pkg/util/wait.(*Group).Start
	/Users/yuan.chen/GolandProjects/src/volcano.sh/volcano/vendor/k8s.io/apimachinery/pkg/util/wait/wait.go:69 +0x62

goroutine 202 [sync.Cond.Wait]:
runtime.goparkunlock(...)
	/usr/local/opt/go/libexec/src/runtime/proc.go:310
sync.runtime_notifyListWait(0xc0008202c0, 0x0)
	/usr/local/opt/go/libexec/src/runtime/sema.go:510 +0xf8
sync.(*Cond).Wait(0xc0008202b0)
	/usr/local/opt/go/libexec/src/sync/cond.go:56 +0x9d
volcano.sh/volcano/vendor/golang.org/x/net/http2.(*pipe).Read(0xc0008202a8, 0xc00073c800, 0x200, 0x200, 0x0, 0x0, 0x0)
	/Users/yuan.chen/GolandProjects/src/volcano.sh/volcano/vendor/golang.org/x/net/http2/pipe.go:64 +0xa6
volcano.sh/volcano/vendor/golang.org/x/net/http2.transportResponseBody.Read(0xc000820280, 0xc00073c800, 0x200, 0x200, 0x0, 0x0, 0x0)
	/Users/yuan.chen/GolandProjects/src/volcano.sh/volcano/vendor/golang.org/x/net/http2/transport.go:1952 +0xac
encoding/json.(*Decoder).refill(0xc0005c9340, 0xc000a35240, 0x1019f4e)
	/usr/local/opt/go/libexec/src/encoding/json/stream.go:161 +0xeb
encoding/json.(*Decoder).readValue(0xc0005c9340, 0x0, 0x0, 0x1fbf8c0)
	/usr/local/opt/go/libexec/src/encoding/json/stream.go:136 +0x1dc
encoding/json.(*Decoder).Decode(0xc0005c9340, 0x1fd7a80, 0xc000a35240, 0x10233e5, 0xc0002b9dc0)
	/usr/local/opt/go/libexec/src/encoding/json/stream.go:63 +0x79
volcano.sh/volcano/vendor/k8s.io/apimachinery/pkg/util/framer.(*jsonFrameReader).Read(0xc000a3b7a0, 0xc000914400, 0x400, 0x400, 0xc0003e4000, 0x1bc438a, 0x38)
	/Users/yuan.chen/GolandProjects/src/volcano.sh/volcano/vendor/k8s.io/apimachinery/pkg/util/framer/framer.go:150 +0x1a1
volcano.sh/volcano/vendor/k8s.io/apimachinery/pkg/runtime/serializer/streaming.(*decoder).Decode(0xc0006f6410, 0x0, 0x23a32e0, 0xc0002b9dc0, 0x10, 0xc00063a050, 0xc000394fc0, 0xc000394e88, 0x3b9aca00)
	/Users/yuan.chen/GolandProjects/src/volcano.sh/volcano/vendor/k8s.io/apimachinery/pkg/runtime/serializer/streaming/streaming.go:77 +0x89
volcano.sh/volcano/vendor/k8s.io/client-go/rest/watch.(*Decoder).Decode(0xc000a35220, 0xc00063a050, 0xc000394f38, 0x1bc3249, 0xc000394ef0, 0x3b9aca00, 0x14eab96)
	/Users/yuan.chen/GolandProjects/src/volcano.sh/volcano/vendor/k8s.io/client-go/rest/watch/decoder.go:49 +0x7c
volcano.sh/volcano/vendor/k8s.io/apimachinery/pkg/watch.(*StreamWatcher).receive(0xc000a3b7d0)
	/Users/yuan.chen/GolandProjects/src/volcano.sh/volcano/vendor/k8s.io/apimachinery/pkg/watch/streamwatcher.go:93 +0x175
created by volcano.sh/volcano/vendor/k8s.io/apimachinery/pkg/watch.NewStreamWatcher
	/Users/yuan.chen/GolandProjects/src/volcano.sh/volcano/vendor/k8s.io/apimachinery/pkg/watch/streamwatcher.go:60 +0x9f

goroutine 215 [select]:
volcano.sh/volcano/vendor/k8s.io/client-go/tools/cache.(*Reflector).ListAndWatch.func1(0xc000416000, 0x0, 0xc00016aa20, 0xc0006a6e40)
	/Users/yuan.chen/GolandProjects/src/volcano.sh/volcano/vendor/k8s.io/client-go/tools/cache/reflector.go:194 +0x178
created by volcano.sh/volcano/vendor/k8s.io/client-go/tools/cache.(*Reflector).ListAndWatch
	/Users/yuan.chen/GolandProjects/src/volcano.sh/volcano/vendor/k8s.io/client-go/tools/cache/reflector.go:188 +0x6fb

goroutine 161 [select]:
volcano.sh/volcano/vendor/k8s.io/client-go/tools/cache.(*Reflector).ListAndWatch.func1(0xc000334b40, 0x0, 0xc00039ec60, 0xc000186cc0)
	/Users/yuan.chen/GolandProjects/src/volcano.sh/volcano/vendor/k8s.io/client-go/tools/cache/reflector.go:194 +0x178
created by volcano.sh/volcano/vendor/k8s.io/client-go/tools/cache.(*Reflector).ListAndWatch
	/Users/yuan.chen/GolandProjects/src/volcano.sh/volcano/vendor/k8s.io/client-go/tools/cache/reflector.go:188 +0x6fb

goroutine 196 [select]:
volcano.sh/volcano/vendor/k8s.io/client-go/tools/cache.(*Reflector).ListAndWatch.func1(0xc0004160a0, 0x0, 0xc0003b6120, 0xc0000ecc00)
	/Users/yuan.chen/GolandProjects/src/volcano.sh/volcano/vendor/k8s.io/client-go/tools/cache/reflector.go:194 +0x178
created by volcano.sh/volcano/vendor/k8s.io/client-go/tools/cache.(*Reflector).ListAndWatch
	/Users/yuan.chen/GolandProjects/src/volcano.sh/volcano/vendor/k8s.io/client-go/tools/cache/reflector.go:188 +0x6fb

goroutine 182 [select]:
volcano.sh/volcano/vendor/k8s.io/client-go/tools/cache.(*Reflector).ListAndWatch.func1(0xc0005c6000, 0x0, 0xc00038a780, 0xc0000bea20)
	/Users/yuan.chen/GolandProjects/src/volcano.sh/volcano/vendor/k8s.io/client-go/tools/cache/reflector.go:194 +0x178
created by volcano.sh/volcano/vendor/k8s.io/client-go/tools/cache.(*Reflector).ListAndWatch
	/Users/yuan.chen/GolandProjects/src/volcano.sh/volcano/vendor/k8s.io/client-go/tools/cache/reflector.go:188 +0x6fb

goroutine 166 [select]:
volcano.sh/volcano/vendor/k8s.io/client-go/tools/cache.(*Reflector).ListAndWatch.func1(0xc000334aa0, 0x0, 0xc0000c0a20, 0xc0003095c0)
	/Users/yuan.chen/GolandProjects/src/volcano.sh/volcano/vendor/k8s.io/client-go/tools/cache/reflector.go:194 +0x178
created by volcano.sh/volcano/vendor/k8s.io/client-go/tools/cache.(*Reflector).ListAndWatch
	/Users/yuan.chen/GolandProjects/src/volcano.sh/volcano/vendor/k8s.io/client-go/tools/cache/reflector.go:188 +0x6fb

goroutine 167 [select]:
volcano.sh/volcano/vendor/k8s.io/client-go/tools/cache.(*Reflector).ListAndWatch.func1(0xc0001caa00, 0x0, 0xc0003e6540, 0xc000446300)
	/Users/yuan.chen/GolandProjects/src/volcano.sh/volcano/vendor/k8s.io/client-go/tools/cache/reflector.go:194 +0x178
created by volcano.sh/volcano/vendor/k8s.io/client-go/tools/cache.(*Reflector).ListAndWatch
	/Users/yuan.chen/GolandProjects/src/volcano.sh/volcano/vendor/k8s.io/client-go/tools/cache/reflector.go:188 +0x6fb

goroutine 197 [sync.Cond.Wait]:
runtime.goparkunlock(...)
	/usr/local/opt/go/libexec/src/runtime/proc.go:310
sync.runtime_notifyListWait(0xc000656400, 0x0)
	/usr/local/opt/go/libexec/src/runtime/sema.go:510 +0xf8
sync.(*Cond).Wait(0xc0006563f0)
	/usr/local/opt/go/libexec/src/sync/cond.go:56 +0x9d
volcano.sh/volcano/vendor/golang.org/x/net/http2.(*pipe).Read(0xc0006563e8, 0xc00073c400, 0x200, 0x200, 0x0, 0x0, 0x0)
	/Users/yuan.chen/GolandProjects/src/volcano.sh/volcano/vendor/golang.org/x/net/http2/pipe.go:64 +0xa6
volcano.sh/volcano/vendor/golang.org/x/net/http2.transportResponseBody.Read(0xc0006563c0, 0xc00073c400, 0x200, 0x200, 0x0, 0x0, 0x0)
	/Users/yuan.chen/GolandProjects/src/volcano.sh/volcano/vendor/golang.org/x/net/http2/transport.go:1952 +0xac
encoding/json.(*Decoder).refill(0xc0002dde40, 0xc00080dac0, 0x0)
	/usr/local/opt/go/libexec/src/encoding/json/stream.go:161 +0xeb
encoding/json.(*Decoder).readValue(0xc0002dde40, 0x0, 0x0, 0x1fbf8c0)
	/usr/local/opt/go/libexec/src/encoding/json/stream.go:136 +0x1dc
encoding/json.(*Decoder).Decode(0xc0002dde40, 0x1fd7a80, 0xc00080dac0, 0x0, 0x0)
	/usr/local/opt/go/libexec/src/encoding/json/stream.go:63 +0x79
volcano.sh/volcano/vendor/k8s.io/apimachinery/pkg/util/framer.(*jsonFrameReader).Read(0xc00032c4e0, 0xc000120c00, 0x400, 0x400, 0x0, 0x0, 0x38)
	/Users/yuan.chen/GolandProjects/src/volcano.sh/volcano/vendor/k8s.io/apimachinery/pkg/util/framer/framer.go:150 +0x1a1
volcano.sh/volcano/vendor/k8s.io/apimachinery/pkg/runtime/serializer/streaming.(*decoder).Decode(0xc0006f6050, 0x0, 0x23a32e0, 0xc0002b8940, 0x0, 0x0, 0x0, 0x0, 0x0)
	/Users/yuan.chen/GolandProjects/src/volcano.sh/volcano/vendor/k8s.io/apimachinery/pkg/runtime/serializer/streaming/streaming.go:77 +0x89
volcano.sh/volcano/vendor/k8s.io/client-go/rest/watch.(*Decoder).Decode(0xc00080daa0, 0x0, 0x0, 0x0, 0x0, 0x0, 0x14eab96)
	/Users/yuan.chen/GolandProjects/src/volcano.sh/volcano/vendor/k8s.io/client-go/rest/watch/decoder.go:49 +0x7c
volcano.sh/volcano/vendor/k8s.io/apimachinery/pkg/watch.(*StreamWatcher).receive(0xc00032c510)
	/Users/yuan.chen/GolandProjects/src/volcano.sh/volcano/vendor/k8s.io/apimachinery/pkg/watch/streamwatcher.go:93 +0x175
created by volcano.sh/volcano/vendor/k8s.io/apimachinery/pkg/watch.NewStreamWatcher
	/Users/yuan.chen/GolandProjects/src/volcano.sh/volcano/vendor/k8s.io/apimachinery/pkg/watch/streamwatcher.go:60 +0x9f

goroutine 159 [select]:
volcano.sh/volcano/vendor/k8s.io/client-go/tools/cache.(*Reflector).ListAndWatch.func1(0xc000310140, 0x0, 0xc00039e6c0, 0xc0003098c0)
	/Users/yuan.chen/GolandProjects/src/volcano.sh/volcano/vendor/k8s.io/client-go/tools/cache/reflector.go:194 +0x178
created by volcano.sh/volcano/vendor/k8s.io/client-go/tools/cache.(*Reflector).ListAndWatch
	/Users/yuan.chen/GolandProjects/src/volcano.sh/volcano/vendor/k8s.io/client-go/tools/cache/reflector.go:188 +0x6fb

goroutine 199 [sync.Cond.Wait]:
runtime.goparkunlock(...)
	/usr/local/opt/go/libexec/src/runtime/proc.go:310
sync.runtime_notifyListWait(0xc000656040, 0x0)
	/usr/local/opt/go/libexec/src/runtime/sema.go:510 +0xf8
sync.(*Cond).Wait(0xc000656030)
	/usr/local/opt/go/libexec/src/sync/cond.go:56 +0x9d
volcano.sh/volcano/vendor/golang.org/x/net/http2.(*pipe).Read(0xc000656028, 0xc00073c600, 0x200, 0x200, 0x0, 0x0, 0x0)
	/Users/yuan.chen/GolandProjects/src/volcano.sh/volcano/vendor/golang.org/x/net/http2/pipe.go:64 +0xa6
volcano.sh/volcano/vendor/golang.org/x/net/http2.transportResponseBody.Read(0xc000656000, 0xc00073c600, 0x200, 0x200, 0x0, 0x0, 0x0)
	/Users/yuan.chen/GolandProjects/src/volcano.sh/volcano/vendor/golang.org/x/net/http2/transport.go:1952 +0xac
encoding/json.(*Decoder).refill(0xc0005c86e0, 0xc00080dc80, 0x0)
	/usr/local/opt/go/libexec/src/encoding/json/stream.go:161 +0xeb
encoding/json.(*Decoder).readValue(0xc0005c86e0, 0x0, 0x0, 0x1fbf8c0)
	/usr/local/opt/go/libexec/src/encoding/json/stream.go:136 +0x1dc
encoding/json.(*Decoder).Decode(0xc0005c86e0, 0x1fd7a80, 0xc00080dc80, 0xc00005f2f8, 0xc00005e500)
	/usr/local/opt/go/libexec/src/encoding/json/stream.go:63 +0x79
volcano.sh/volcano/vendor/k8s.io/apimachinery/pkg/util/framer.(*jsonFrameReader).Read(0xc00032c900, 0xc000121400, 0x400, 0x400, 0x0, 0x1, 0x38)
	/Users/yuan.chen/GolandProjects/src/volcano.sh/volcano/vendor/k8s.io/apimachinery/pkg/util/framer/framer.go:150 +0x1a1
volcano.sh/volcano/vendor/k8s.io/apimachinery/pkg/runtime/serializer/streaming.(*decoder).Decode(0xc0006f6190, 0x0, 0x23a32e0, 0xc0002b8a40, 0x0, 0x0, 0xc00056f758, 0x1bc82cd, 0xc00056f708)
	/Users/yuan.chen/GolandProjects/src/volcano.sh/volcano/vendor/k8s.io/apimachinery/pkg/runtime/serializer/streaming/streaming.go:77 +0x89
volcano.sh/volcano/vendor/k8s.io/client-go/rest/watch.(*Decoder).Decode(0xc00080dc60, 0xc00056f690, 0xc0001143c0, 0x18, 0xc00056f620, 0x1bc81ae, 0x14eab96)
	/Users/yuan.chen/GolandProjects/src/volcano.sh/volcano/vendor/k8s.io/client-go/rest/watch/decoder.go:49 +0x7c
volcano.sh/volcano/vendor/k8s.io/apimachinery/pkg/watch.(*StreamWatcher).receive(0xc00032c990)
	/Users/yuan.chen/GolandProjects/src/volcano.sh/volcano/vendor/k8s.io/apimachinery/pkg/watch/streamwatcher.go:93 +0x175
created by volcano.sh/volcano/vendor/k8s.io/apimachinery/pkg/watch.NewStreamWatcher
	/Users/yuan.chen/GolandProjects/src/volcano.sh/volcano/vendor/k8s.io/apimachinery/pkg/watch/streamwatcher.go:60 +0x9f

goroutine 126 [sync.Cond.Wait]:
runtime.goparkunlock(...)
	/usr/local/opt/go/libexec/src/runtime/proc.go:310
sync.runtime_notifyListWait(0xc0001cc040, 0x0)
	/usr/local/opt/go/libexec/src/runtime/sema.go:510 +0xf8
sync.(*Cond).Wait(0xc0001cc030)
	/usr/local/opt/go/libexec/src/sync/cond.go:56 +0x9d
volcano.sh/volcano/vendor/golang.org/x/net/http2.(*pipe).Read(0xc0001cc028, 0xc000468000, 0x200, 0x200, 0x0, 0x0, 0x0)
	/Users/yuan.chen/GolandProjects/src/volcano.sh/volcano/vendor/golang.org/x/net/http2/pipe.go:64 +0xa6
volcano.sh/volcano/vendor/golang.org/x/net/http2.transportResponseBody.Read(0xc0001cc000, 0xc000468000, 0x200, 0x200, 0x0, 0x0, 0x0)
	/Users/yuan.chen/GolandProjects/src/volcano.sh/volcano/vendor/golang.org/x/net/http2/transport.go:1952 +0xac
encoding/json.(*Decoder).refill(0xc0006486e0, 0xc0007ecbe0, 0x6845504254476553)
	/usr/local/opt/go/libexec/src/encoding/json/stream.go:161 +0xeb
encoding/json.(*Decoder).readValue(0xc0006486e0, 0x0, 0x0, 0x1fbf8c0)
	/usr/local/opt/go/libexec/src/encoding/json/stream.go:136 +0x1dc
encoding/json.(*Decoder).Decode(0xc0006486e0, 0x1fd7a80, 0xc0007ecbe0, 0x64003c0, 0x52)
	/usr/local/opt/go/libexec/src/encoding/json/stream.go:63 +0x79
volcano.sh/volcano/vendor/k8s.io/apimachinery/pkg/util/framer.(*jsonFrameReader).Read(0xc0007d5590, 0xc000460000, 0x400, 0x400, 0x0, 0x1, 0x38)
	/Users/yuan.chen/GolandProjects/src/volcano.sh/volcano/vendor/k8s.io/apimachinery/pkg/util/framer/framer.go:150 +0x1a1
volcano.sh/volcano/vendor/k8s.io/apimachinery/pkg/runtime/serializer/streaming.(*decoder).Decode(0xc00015e140, 0x0, 0x23a32e0, 0xc000195480, 0x75762b4950482b6b, 0x734946656f7a3455, 0xc00056c758, 0x1bc82cd, 0xc00056c708)
	/Users/yuan.chen/GolandProjects/src/volcano.sh/volcano/vendor/k8s.io/apimachinery/pkg/runtime/serializer/streaming/streaming.go:77 +0x89
volcano.sh/volcano/vendor/k8s.io/client-go/rest/watch.(*Decoder).Decode(0xc0007ecbc0, 0xc00056c690, 0xc000114840, 0x18, 0xc00056c620, 0x1bc81ae, 0x223daf8)
	/Users/yuan.chen/GolandProjects/src/volcano.sh/volcano/vendor/k8s.io/client-go/rest/watch/decoder.go:49 +0x7c
volcano.sh/volcano/vendor/k8s.io/apimachinery/pkg/watch.(*StreamWatcher).receive(0xc0007d55c0)
	/Users/yuan.chen/GolandProjects/src/volcano.sh/volcano/vendor/k8s.io/apimachinery/pkg/watch/streamwatcher.go:93 +0x175
created by volcano.sh/volcano/vendor/k8s.io/apimachinery/pkg/watch.NewStreamWatcher
	/Users/yuan.chen/GolandProjects/src/volcano.sh/volcano/vendor/k8s.io/apimachinery/pkg/watch/streamwatcher.go:60 +0x9f

goroutine 213 [sync.Cond.Wait]:
runtime.goparkunlock(...)
	/usr/local/opt/go/libexec/src/runtime/proc.go:310
sync.runtime_notifyListWait(0xc000820180, 0xc000000006)
	/usr/local/opt/go/libexec/src/runtime/sema.go:510 +0xf8
sync.(*Cond).Wait(0xc000820170)
	/usr/local/opt/go/libexec/src/sync/cond.go:56 +0x9d
volcano.sh/volcano/vendor/golang.org/x/net/http2.(*pipe).Read(0xc000820168, 0xc00051f201, 0x5ff, 0x5ff, 0x0, 0x0, 0x0)
	/Users/yuan.chen/GolandProjects/src/volcano.sh/volcano/vendor/golang.org/x/net/http2/pipe.go:64 +0xa6
volcano.sh/volcano/vendor/golang.org/x/net/http2.transportResponseBody.Read(0xc000820140, 0xc00051f201, 0x5ff, 0x5ff, 0x0, 0x0, 0x0)
	/Users/yuan.chen/GolandProjects/src/volcano.sh/volcano/vendor/golang.org/x/net/http2/transport.go:1952 +0xac
encoding/json.(*Decoder).refill(0xc000178160, 0xc0008c9f0a, 0x9)
	/usr/local/opt/go/libexec/src/encoding/json/stream.go:161 +0xeb
encoding/json.(*Decoder).readValue(0xc000178160, 0x0, 0x0, 0x1fbf8c0)
	/usr/local/opt/go/libexec/src/encoding/json/stream.go:136 +0x1dc
encoding/json.(*Decoder).Decode(0xc000178160, 0x1fd7a80, 0xc0008c9f00, 0x0, 0x0)
	/usr/local/opt/go/libexec/src/encoding/json/stream.go:63 +0x79
volcano.sh/volcano/vendor/k8s.io/apimachinery/pkg/util/framer.(*jsonFrameReader).Read(0xc0005c42a0, 0xc0008c6000, 0x400, 0x400, 0x239e6e0, 0x0, 0x38)
	/Users/yuan.chen/GolandProjects/src/volcano.sh/volcano/vendor/k8s.io/apimachinery/pkg/util/framer/framer.go:150 +0x1a1
volcano.sh/volcano/vendor/k8s.io/apimachinery/pkg/runtime/serializer/streaming.(*decoder).Decode(0xc0001645f0, 0x0, 0x23a32e0, 0xc000907b80, 0x0, 0x0, 0x0, 0xc00016a538, 0x105aca0)
	/Users/yuan.chen/GolandProjects/src/volcano.sh/volcano/vendor/k8s.io/apimachinery/pkg/runtime/serializer/streaming/streaming.go:77 +0x89
volcano.sh/volcano/vendor/k8s.io/client-go/rest/watch.(*Decoder).Decode(0xc00030a040, 0xc000661fa8, 0x7, 0x239e6e0, 0xc0003b4480, 0x0, 0x0)
	/Users/yuan.chen/GolandProjects/src/volcano.sh/volcano/vendor/k8s.io/client-go/rest/watch/decoder.go:49 +0x7c
volcano.sh/volcano/vendor/k8s.io/apimachinery/pkg/watch.(*StreamWatcher).receive(0xc0005c4360)
	/Users/yuan.chen/GolandProjects/src/volcano.sh/volcano/vendor/k8s.io/apimachinery/pkg/watch/streamwatcher.go:93 +0x175
created by volcano.sh/volcano/vendor/k8s.io/apimachinery/pkg/watch.NewStreamWatcher
	/Users/yuan.chen/GolandProjects/src/volcano.sh/volcano/vendor/k8s.io/apimachinery/pkg/watch/streamwatcher.go:60 +0x9f

goroutine 90 [sync.Cond.Wait]:
runtime.goparkunlock(...)
	/usr/local/opt/go/libexec/src/runtime/proc.go:310
sync.runtime_notifyListWait(0xc000124040, 0xc000000001)
	/usr/local/opt/go/libexec/src/runtime/sema.go:510 +0xf8
sync.(*Cond).Wait(0xc000124030)
	/usr/local/opt/go/libexec/src/sync/cond.go:56 +0x9d
volcano.sh/volcano/vendor/golang.org/x/net/http2.(*pipe).Read(0xc000124028, 0xc0004ea001, 0x1dff, 0x1dff, 0x0, 0x0, 0x0)
	/Users/yuan.chen/GolandProjects/src/volcano.sh/volcano/vendor/golang.org/x/net/http2/pipe.go:64 +0xa6
volcano.sh/volcano/vendor/golang.org/x/net/http2.transportResponseBody.Read(0xc000124000, 0xc0004ea001, 0x1dff, 0x1dff, 0x0, 0x0, 0x0)
	/Users/yuan.chen/GolandProjects/src/volcano.sh/volcano/vendor/golang.org/x/net/http2/transport.go:1952 +0xac
encoding/json.(*Decoder).refill(0xc0001c6160, 0xc00094c40a, 0x9)
	/usr/local/opt/go/libexec/src/encoding/json/stream.go:161 +0xeb
encoding/json.(*Decoder).readValue(0xc0001c6160, 0x0, 0x0, 0x1fbf8c0)
	/usr/local/opt/go/libexec/src/encoding/json/stream.go:136 +0x1dc
encoding/json.(*Decoder).Decode(0xc0001c6160, 0x1fd7a80, 0xc00094c400, 0x0, 0x0)
	/usr/local/opt/go/libexec/src/encoding/json/stream.go:63 +0x79
volcano.sh/volcano/vendor/k8s.io/apimachinery/pkg/util/framer.(*jsonFrameReader).Read(0xc0008ea000, 0xc00073e000, 0x2000, 0x2600, 0x23a16e0, 0x0, 0x38)
	/Users/yuan.chen/GolandProjects/src/volcano.sh/volcano/vendor/k8s.io/apimachinery/pkg/util/framer/framer.go:150 +0x1a1
volcano.sh/volcano/vendor/k8s.io/apimachinery/pkg/runtime/serializer/streaming.(*decoder).Decode(0xc00010e190, 0x0, 0x23a32e0, 0xc0008ddc80, 0x0, 0x0, 0x0, 0xc000114118, 0x105aca0)
	/Users/yuan.chen/GolandProjects/src/volcano.sh/volcano/vendor/k8s.io/apimachinery/pkg/runtime/serializer/streaming/streaming.go:77 +0x89
volcano.sh/volcano/vendor/k8s.io/client-go/rest/watch.(*Decoder).Decode(0xc0008ee000, 0xc000723fa8, 0x8, 0x23a16e0, 0xc000102000, 0x0, 0x0)
	/Users/yuan.chen/GolandProjects/src/volcano.sh/volcano/vendor/k8s.io/client-go/rest/watch/decoder.go:49 +0x7c
volcano.sh/volcano/vendor/k8s.io/apimachinery/pkg/watch.(*StreamWatcher).receive(0xc0008ea030)
	/Users/yuan.chen/GolandProjects/src/volcano.sh/volcano/vendor/k8s.io/apimachinery/pkg/watch/streamwatcher.go:93 +0x175
created by volcano.sh/volcano/vendor/k8s.io/apimachinery/pkg/watch.NewStreamWatcher
	/Users/yuan.chen/GolandProjects/src/volcano.sh/volcano/vendor/k8s.io/apimachinery/pkg/watch/streamwatcher.go:60 +0x9f

goroutine 214 [sync.Cond.Wait]:
runtime.goparkunlock(...)
	/usr/local/opt/go/libexec/src/runtime/proc.go:310
sync.runtime_notifyListWait(0xc0001242c0, 0x0)
	/usr/local/opt/go/libexec/src/runtime/sema.go:510 +0xf8
sync.(*Cond).Wait(0xc0001242b0)
	/usr/local/opt/go/libexec/src/sync/cond.go:56 +0x9d
volcano.sh/volcano/vendor/golang.org/x/net/http2.(*pipe).Read(0xc0001242a8, 0xc0008ce400, 0x200, 0x200, 0x0, 0x0, 0x0)
	/Users/yuan.chen/GolandProjects/src/volcano.sh/volcano/vendor/golang.org/x/net/http2/pipe.go:64 +0xa6
volcano.sh/volcano/vendor/golang.org/x/net/http2.transportResponseBody.Read(0xc000124280, 0xc0008ce400, 0x200, 0x200, 0x0, 0x0, 0x0)
	/Users/yuan.chen/GolandProjects/src/volcano.sh/volcano/vendor/golang.org/x/net/http2/transport.go:1952 +0xac
encoding/json.(*Decoder).refill(0xc0001786e0, 0xc0009e4120, 0x0)
	/usr/local/opt/go/libexec/src/encoding/json/stream.go:161 +0xeb
encoding/json.(*Decoder).readValue(0xc0001786e0, 0x0, 0x0, 0x1fbf8c0)
	/usr/local/opt/go/libexec/src/encoding/json/stream.go:136 +0x1dc
encoding/json.(*Decoder).Decode(0xc0001786e0, 0x1fd7a80, 0xc0009e4120, 0x0, 0x0)
	/usr/local/opt/go/libexec/src/encoding/json/stream.go:63 +0x79
volcano.sh/volcano/vendor/k8s.io/apimachinery/pkg/util/framer.(*jsonFrameReader).Read(0xc0009d6b10, 0xc0008c6400, 0x400, 0x400, 0x0, 0x0, 0x38)
	/Users/yuan.chen/GolandProjects/src/volcano.sh/volcano/vendor/k8s.io/apimachinery/pkg/util/framer/framer.go:150 +0x1a1
volcano.sh/volcano/vendor/k8s.io/apimachinery/pkg/runtime/serializer/streaming.(*decoder).Decode(0xc000164820, 0x0, 0x23a32e0, 0xc0000bd640, 0x0, 0x0, 0x0, 0x0, 0x0)
	/Users/yuan.chen/GolandProjects/src/volcano.sh/volcano/vendor/k8s.io/apimachinery/pkg/runtime/serializer/streaming/streaming.go:77 +0x89
volcano.sh/volcano/vendor/k8s.io/client-go/rest/watch.(*Decoder).Decode(0xc0009e4100, 0x0, 0x0, 0x0, 0x0, 0x0, 0x14eab96)
	/Users/yuan.chen/GolandProjects/src/volcano.sh/volcano/vendor/k8s.io/client-go/rest/watch/decoder.go:49 +0x7c
volcano.sh/volcano/vendor/k8s.io/apimachinery/pkg/watch.(*StreamWatcher).receive(0xc0009d6b40)
	/Users/yuan.chen/GolandProjects/src/volcano.sh/volcano/vendor/k8s.io/apimachinery/pkg/watch/streamwatcher.go:93 +0x175
created by volcano.sh/volcano/vendor/k8s.io/apimachinery/pkg/watch.NewStreamWatcher
	/Users/yuan.chen/GolandProjects/src/volcano.sh/volcano/vendor/k8s.io/apimachinery/pkg/watch/streamwatcher.go:60 +0x9f

goroutine 127 [select]:
volcano.sh/volcano/vendor/k8s.io/client-go/tools/cache.(*Reflector).ListAndWatch.func1(0xc0003e8000, 0x0, 0xc0000c1140, 0xc0000eb1a0)
	/Users/yuan.chen/GolandProjects/src/volcano.sh/volcano/vendor/k8s.io/client-go/tools/cache/reflector.go:194 +0x178
created by volcano.sh/volcano/vendor/k8s.io/client-go/tools/cache.(*Reflector).ListAndWatch
	/Users/yuan.chen/GolandProjects/src/volcano.sh/volcano/vendor/k8s.io/client-go/tools/cache/reflector.go:188 +0x6fb

goroutine 169 [select]:
volcano.sh/volcano/vendor/k8s.io/client-go/tools/cache.(*Reflector).ListAndWatch.func1(0xc0000fa000, 0x0, 0xc0003e6b40, 0xc000446900)
	/Users/yuan.chen/GolandProjects/src/volcano.sh/volcano/vendor/k8s.io/client-go/tools/cache/reflector.go:194 +0x178
created by volcano.sh/volcano/vendor/k8s.io/client-go/tools/cache.(*Reflector).ListAndWatch
	/Users/yuan.chen/GolandProjects/src/volcano.sh/volcano/vendor/k8s.io/client-go/tools/cache/reflector.go:188 +0x6fb

goroutine 201 [select]:
volcano.sh/volcano/vendor/k8s.io/client-go/tools/cache.(*Reflector).ListAndWatch.func1(0xc0003e80a0, 0x0, 0xc0003b6780, 0xc0000ecf60)
	/Users/yuan.chen/GolandProjects/src/volcano.sh/volcano/vendor/k8s.io/client-go/tools/cache/reflector.go:194 +0x178
created by volcano.sh/volcano/vendor/k8s.io/client-go/tools/cache.(*Reflector).ListAndWatch
	/Users/yuan.chen/GolandProjects/src/volcano.sh/volcano/vendor/k8s.io/client-go/tools/cache/reflector.go:188 +0x6fb

goroutine 170 [sync.Cond.Wait]:
runtime.goparkunlock(...)
	/usr/local/opt/go/libexec/src/runtime/proc.go:310
sync.runtime_notifyListWait(0xc000472180, 0x0)
	/usr/local/opt/go/libexec/src/runtime/sema.go:510 +0xf8
sync.(*Cond).Wait(0xc000472170)
	/usr/local/opt/go/libexec/src/sync/cond.go:56 +0x9d
volcano.sh/volcano/vendor/golang.org/x/net/http2.(*pipe).Read(0xc000472168, 0xc0009ce000, 0x200, 0x200, 0x0, 0x0, 0x0)
	/Users/yuan.chen/GolandProjects/src/volcano.sh/volcano/vendor/golang.org/x/net/http2/pipe.go:64 +0xa6
volcano.sh/volcano/vendor/golang.org/x/net/http2.transportResponseBody.Read(0xc000472140, 0xc0009ce000, 0x200, 0x200, 0x0, 0x0, 0x0)
	/Users/yuan.chen/GolandProjects/src/volcano.sh/volcano/vendor/golang.org/x/net/http2/transport.go:1952 +0xac
encoding/json.(*Decoder).refill(0xc00070f340, 0xc000940d60, 0x0)
	/usr/local/opt/go/libexec/src/encoding/json/stream.go:161 +0xeb
encoding/json.(*Decoder).readValue(0xc00070f340, 0x0, 0x0, 0x1fbf8c0)
	/usr/local/opt/go/libexec/src/encoding/json/stream.go:136 +0x1dc
encoding/json.(*Decoder).Decode(0xc00070f340, 0x1fd7a80, 0xc000940d60, 0x0, 0x0)
	/usr/local/opt/go/libexec/src/encoding/json/stream.go:63 +0x79
volcano.sh/volcano/vendor/k8s.io/apimachinery/pkg/util/framer.(*jsonFrameReader).Read(0xc000931c80, 0xc0009ca000, 0x400, 0x400, 0x0, 0x0, 0x38)
	/Users/yuan.chen/GolandProjects/src/volcano.sh/volcano/vendor/k8s.io/apimachinery/pkg/util/framer/framer.go:150 +0x1a1
volcano.sh/volcano/vendor/k8s.io/apimachinery/pkg/runtime/serializer/streaming.(*decoder).Decode(0xc0006aa410, 0x0, 0x23a32e0, 0xc0005beec0, 0x0, 0x0, 0x0, 0x0, 0x0)
	/Users/yuan.chen/GolandProjects/src/volcano.sh/volcano/vendor/k8s.io/apimachinery/pkg/runtime/serializer/streaming/streaming.go:77 +0x89
volcano.sh/volcano/vendor/k8s.io/client-go/rest/watch.(*Decoder).Decode(0xc000940d40, 0x0, 0x0, 0x0, 0x0, 0x0, 0x0)
	/Users/yuan.chen/GolandProjects/src/volcano.sh/volcano/vendor/k8s.io/client-go/rest/watch/decoder.go:49 +0x7c
volcano.sh/volcano/vendor/k8s.io/apimachinery/pkg/watch.(*StreamWatcher).receive(0xc000931cb0)
	/Users/yuan.chen/GolandProjects/src/volcano.sh/volcano/vendor/k8s.io/apimachinery/pkg/watch/streamwatcher.go:93 +0x175
created by volcano.sh/volcano/vendor/k8s.io/apimachinery/pkg/watch.NewStreamWatcher
	/Users/yuan.chen/GolandProjects/src/volcano.sh/volcano/vendor/k8s.io/apimachinery/pkg/watch/streamwatcher.go:60 +0x9f

goroutine 203 [select]:
volcano.sh/volcano/vendor/k8s.io/client-go/tools/cache.(*Reflector).ListAndWatch.func1(0xc0005c0000, 0x0, 0xc000115140, 0xc0000ecba0)
	/Users/yuan.chen/GolandProjects/src/volcano.sh/volcano/vendor/k8s.io/client-go/tools/cache/reflector.go:194 +0x178
created by volcano.sh/volcano/vendor/k8s.io/client-go/tools/cache.(*Reflector).ListAndWatch
	/Users/yuan.chen/GolandProjects/src/volcano.sh/volcano/vendor/k8s.io/client-go/tools/cache/reflector.go:188 +0x6fb

goroutine 109 [sync.Cond.Wait]:
runtime.goparkunlock(...)
	/usr/local/opt/go/libexec/src/runtime/proc.go:310
sync.runtime_notifyListWait(0xc0001ccf40, 0x0)
	/usr/local/opt/go/libexec/src/runtime/sema.go:510 +0xf8
sync.(*Cond).Wait(0xc0001ccf30)
	/usr/local/opt/go/libexec/src/sync/cond.go:56 +0x9d
volcano.sh/volcano/vendor/golang.org/x/net/http2.(*pipe).Read(0xc0001ccf28, 0xc000a4e000, 0x200, 0x200, 0x0, 0x0, 0x0)
	/Users/yuan.chen/GolandProjects/src/volcano.sh/volcano/vendor/golang.org/x/net/http2/pipe.go:64 +0xa6
volcano.sh/volcano/vendor/golang.org/x/net/http2.transportResponseBody.Read(0xc0001ccf00, 0xc000a4e000, 0x200, 0x200, 0x0, 0x0, 0x0)
	/Users/yuan.chen/GolandProjects/src/volcano.sh/volcano/vendor/golang.org/x/net/http2/transport.go:1952 +0xac
encoding/json.(*Decoder).refill(0xc0005786e0, 0xc0009aac20, 0x4948546833336d51)
	/usr/local/opt/go/libexec/src/encoding/json/stream.go:161 +0xeb
encoding/json.(*Decoder).readValue(0xc0005786e0, 0x0, 0x0, 0x1fbf8c0)
	/usr/local/opt/go/libexec/src/encoding/json/stream.go:136 +0x1dc
encoding/json.(*Decoder).Decode(0xc0005786e0, 0x1fd7a80, 0xc0009aac20, 0x10233e5, 0xc00014bc00)
	/usr/local/opt/go/libexec/src/encoding/json/stream.go:63 +0x79
volcano.sh/volcano/vendor/k8s.io/apimachinery/pkg/util/framer.(*jsonFrameReader).Read(0xc0009b6b70, 0xc000a44000, 0x400, 0x400, 0x716b67424e416a41, 0x773947696b68, 0x38)
	/Users/yuan.chen/GolandProjects/src/volcano.sh/volcano/vendor/k8s.io/apimachinery/pkg/util/framer/framer.go:150 +0x1a1
volcano.sh/volcano/vendor/k8s.io/apimachinery/pkg/runtime/serializer/streaming.(*decoder).Decode(0xc0002fe280, 0x0, 0x23a32e0, 0xc00014bc00, 0x6a53386c76414451, 0x4c31796c31774142, 0x514b456c58524735, 0xa776f4837304b63, 0x555055476d625235)
	/Users/yuan.chen/GolandProjects/src/volcano.sh/volcano/vendor/k8s.io/apimachinery/pkg/runtime/serializer/streaming/streaming.go:77 +0x89
volcano.sh/volcano/vendor/k8s.io/client-go/rest/watch.(*Decoder).Decode(0xc0009aac00, 0x4d334e5a526e4a6a, 0x4163307562547338, 0x507a515a416d4175, 0x4b724d7166677470, 0x51666f50335a0a33, 0x5279634a46465948)
	/Users/yuan.chen/GolandProjects/src/volcano.sh/volcano/vendor/k8s.io/client-go/rest/watch/decoder.go:49 +0x7c
volcano.sh/volcano/vendor/k8s.io/apimachinery/pkg/watch.(*StreamWatcher).receive(0xc0009b6ba0)
	/Users/yuan.chen/GolandProjects/src/volcano.sh/volcano/vendor/k8s.io/apimachinery/pkg/watch/streamwatcher.go:93 +0x175
created by volcano.sh/volcano/vendor/k8s.io/apimachinery/pkg/watch.NewStreamWatcher
	/Users/yuan.chen/GolandProjects/src/volcano.sh/volcano/vendor/k8s.io/apimachinery/pkg/watch/streamwatcher.go:60 +0x9f

goroutine 216 [sync.Cond.Wait]:
runtime.goparkunlock(...)
	/usr/local/opt/go/libexec/src/runtime/proc.go:310
sync.runtime_notifyListWait(0xc000464180, 0x0)
	/usr/local/opt/go/libexec/src/runtime/sema.go:510 +0xf8
sync.(*Cond).Wait(0xc000464170)
	/usr/local/opt/go/libexec/src/sync/cond.go:56 +0x9d
volcano.sh/volcano/vendor/golang.org/x/net/http2.(*pipe).Read(0xc000464168, 0xc000468200, 0x200, 0x200, 0x0, 0x0, 0x0)
	/Users/yuan.chen/GolandProjects/src/volcano.sh/volcano/vendor/golang.org/x/net/http2/pipe.go:64 +0xa6
volcano.sh/volcano/vendor/golang.org/x/net/http2.transportResponseBody.Read(0xc000464140, 0xc000468200, 0x200, 0x200, 0x0, 0x0, 0x0)
	/Users/yuan.chen/GolandProjects/src/volcano.sh/volcano/vendor/golang.org/x/net/http2/transport.go:1952 +0xac
encoding/json.(*Decoder).refill(0xc000648000, 0xc000546040, 0x0)
	/usr/local/opt/go/libexec/src/encoding/json/stream.go:161 +0xeb
encoding/json.(*Decoder).readValue(0xc000648000, 0x0, 0x0, 0x1fbf8c0)
	/usr/local/opt/go/libexec/src/encoding/json/stream.go:136 +0x1dc
encoding/json.(*Decoder).Decode(0xc000648000, 0x1fd7a80, 0xc000546040, 0x339d280, 0xf)
	/usr/local/opt/go/libexec/src/encoding/json/stream.go:63 +0x79
volcano.sh/volcano/vendor/k8s.io/apimachinery/pkg/util/framer.(*jsonFrameReader).Read(0xc000214990, 0xc000460400, 0x400, 0x400, 0x1, 0x1000000000000, 0x38)
	/Users/yuan.chen/GolandProjects/src/volcano.sh/volcano/vendor/k8s.io/apimachinery/pkg/util/framer/framer.go:150 +0x1a1
volcano.sh/volcano/vendor/k8s.io/apimachinery/pkg/runtime/serializer/streaming.(*decoder).Decode(0xc0002fe2d0, 0x0, 0x23a32e0, 0xc00014a3c0, 0x10, 0xc0000d04b0, 0x18, 0xc00006cdf8, 0x13a6000)
	/Users/yuan.chen/GolandProjects/src/volcano.sh/volcano/vendor/k8s.io/apimachinery/pkg/runtime/serializer/streaming/streaming.go:77 +0x89
volcano.sh/volcano/vendor/k8s.io/client-go/rest/watch.(*Decoder).Decode(0xc000546020, 0xc0000d04b0, 0xc000599400, 0x3393f80, 0x0, 0xdf8475800, 0x14eab96)
	/Users/yuan.chen/GolandProjects/src/volcano.sh/volcano/vendor/k8s.io/client-go/rest/watch/decoder.go:49 +0x7c
volcano.sh/volcano/vendor/k8s.io/apimachinery/pkg/watch.(*StreamWatcher).receive(0xc000214ae0)
	/Users/yuan.chen/GolandProjects/src/volcano.sh/volcano/vendor/k8s.io/apimachinery/pkg/watch/streamwatcher.go:93 +0x175
created by volcano.sh/volcano/vendor/k8s.io/apimachinery/pkg/watch.NewStreamWatcher
	/Users/yuan.chen/GolandProjects/src/volcano.sh/volcano/vendor/k8s.io/apimachinery/pkg/watch/streamwatcher.go:60 +0x9f

goroutine 205 [sync.Cond.Wait]:
runtime.goparkunlock(...)
	/usr/local/opt/go/libexec/src/runtime/proc.go:310
sync.runtime_notifyListWait(0xc000472540, 0x0)
	/usr/local/opt/go/libexec/src/runtime/sema.go:510 +0xf8
sync.(*Cond).Wait(0xc000472530)
	/usr/local/opt/go/libexec/src/sync/cond.go:56 +0x9d
volcano.sh/volcano/vendor/golang.org/x/net/http2.(*pipe).Read(0xc000472528, 0xc00073c000, 0x200, 0x200, 0x0, 0x0, 0x0)
	/Users/yuan.chen/GolandProjects/src/volcano.sh/volcano/vendor/golang.org/x/net/http2/pipe.go:64 +0xa6
volcano.sh/volcano/vendor/golang.org/x/net/http2.transportResponseBody.Read(0xc000472500, 0xc00073c000, 0x200, 0x200, 0x0, 0x0, 0x0)
	/Users/yuan.chen/GolandProjects/src/volcano.sh/volcano/vendor/golang.org/x/net/http2/transport.go:1952 +0xac
encoding/json.(*Decoder).refill(0xc0005c89a0, 0xc0007ec960, 0x2b446c614b7a352b)
	/usr/local/opt/go/libexec/src/encoding/json/stream.go:161 +0xeb
encoding/json.(*Decoder).readValue(0xc0005c89a0, 0x0, 0x0, 0x1fbf8c0)
	/usr/local/opt/go/libexec/src/encoding/json/stream.go:136 +0x1dc
encoding/json.(*Decoder).Decode(0xc0005c89a0, 0x1fd7a80, 0xc0007ec960, 0x51796e6b672f6870, 0x78686d766c593771)
	/usr/local/opt/go/libexec/src/encoding/json/stream.go:63 +0x79
volcano.sh/volcano/vendor/k8s.io/apimachinery/pkg/util/framer.(*jsonFrameReader).Read(0xc0007d5530, 0xc000121000, 0x400, 0x400, 0x5838614c796e6851, 0x37474e616856, 0x38)
	/Users/yuan.chen/GolandProjects/src/volcano.sh/volcano/vendor/k8s.io/apimachinery/pkg/util/framer/framer.go:150 +0x1a1
volcano.sh/volcano/vendor/k8s.io/apimachinery/pkg/runtime/serializer/streaming.(*decoder).Decode(0xc00015e500, 0x0, 0x23a32e0, 0xc0008dd0c0, 0x795538766f766859, 0x4a59544435373733, 0x706f4b3452693145, 0x7439546544384a56, 0x49456e5044337a34)
	/Users/yuan.chen/GolandProjects/src/volcano.sh/volcano/vendor/k8s.io/apimachinery/pkg/runtime/serializer/streaming/streaming.go:77 +0x89
volcano.sh/volcano/vendor/k8s.io/client-go/rest/watch.(*Decoder).Decode(0xc0007ec940, 0x633438674f7a527a, 0x73325579466c5165, 0x4f5a7a536c624648, 0x6c7a6c3751523365, 0x73494f6b586f376b, 0x526d64646b375554)
	/Users/yuan.chen/GolandProjects/src/volcano.sh/volcano/vendor/k8s.io/client-go/rest/watch/decoder.go:49 +0x7c
volcano.sh/volcano/vendor/k8s.io/apimachinery/pkg/watch.(*StreamWatcher).receive(0xc0007d55f0)
	/Users/yuan.chen/GolandProjects/src/volcano.sh/volcano/vendor/k8s.io/apimachinery/pkg/watch/streamwatcher.go:93 +0x175
created by volcano.sh/volcano/vendor/k8s.io/apimachinery/pkg/watch.NewStreamWatcher
	/Users/yuan.chen/GolandProjects/src/volcano.sh/volcano/vendor/k8s.io/apimachinery/pkg/watch/streamwatcher.go:60 +0x9f

goroutine 94 [select]:
volcano.sh/volcano/vendor/k8s.io/client-go/tools/cache.(*Reflector).ListAndWatch.func1(0xc000310000, 0x0, 0xc00038a660, 0xc0006a75c0)
	/Users/yuan.chen/GolandProjects/src/volcano.sh/volcano/vendor/k8s.io/client-go/tools/cache/reflector.go:194 +0x178
created by volcano.sh/volcano/vendor/k8s.io/client-go/tools/cache.(*Reflector).ListAndWatch
	/Users/yuan.chen/GolandProjects/src/volcano.sh/volcano/vendor/k8s.io/client-go/tools/cache/reflector.go:188 +0x6fb

goroutine 95 [sync.Cond.Wait]:
runtime.goparkunlock(...)
	/usr/local/opt/go/libexec/src/runtime/proc.go:310
sync.runtime_notifyListWait(0xc000821080, 0xc000000007)
	/usr/local/opt/go/libexec/src/runtime/sema.go:510 +0xf8
sync.(*Cond).Wait(0xc000821070)
	/usr/local/opt/go/libexec/src/sync/cond.go:56 +0x9d
volcano.sh/volcano/vendor/golang.org/x/net/http2.(*pipe).Read(0xc000821068, 0xc000542001, 0xdff, 0xdff, 0x0, 0x0, 0x0)
	/Users/yuan.chen/GolandProjects/src/volcano.sh/volcano/vendor/golang.org/x/net/http2/pipe.go:64 +0xa6
volcano.sh/volcano/vendor/golang.org/x/net/http2.transportResponseBody.Read(0xc000821040, 0xc000542001, 0xdff, 0xdff, 0x0, 0x0, 0x0)
	/Users/yuan.chen/GolandProjects/src/volcano.sh/volcano/vendor/golang.org/x/net/http2/transport.go:1952 +0xac
encoding/json.(*Decoder).refill(0xc0001c71e0, 0xc0009b420a, 0x9)
	/usr/local/opt/go/libexec/src/encoding/json/stream.go:161 +0xeb
encoding/json.(*Decoder).readValue(0xc0001c71e0, 0x0, 0x0, 0x1fbf8c0)
	/usr/local/opt/go/libexec/src/encoding/json/stream.go:136 +0x1dc
encoding/json.(*Decoder).Decode(0xc0001c71e0, 0x1fd7a80, 0xc0009b4220, 0x0, 0x0)
	/usr/local/opt/go/libexec/src/encoding/json/stream.go:63 +0x79
volcano.sh/volcano/vendor/k8s.io/apimachinery/pkg/util/framer.(*jsonFrameReader).Read(0xc0005a1ad0, 0xc000560a80, 0x800, 0xa80, 0x23a1920, 0x0, 0x38)
	/Users/yuan.chen/GolandProjects/src/volcano.sh/volcano/vendor/k8s.io/apimachinery/pkg/util/framer/framer.go:150 +0x1a1
volcano.sh/volcano/vendor/k8s.io/apimachinery/pkg/runtime/serializer/streaming.(*decoder).Decode(0xc000165270, 0x0, 0x23a32e0, 0xc000907e40, 0x0, 0x0, 0x0, 0xc00038a9b8, 0x105aca0)
	/Users/yuan.chen/GolandProjects/src/volcano.sh/volcano/vendor/k8s.io/apimachinery/pkg/runtime/serializer/streaming/streaming.go:77 +0x89
volcano.sh/volcano/vendor/k8s.io/client-go/rest/watch.(*Decoder).Decode(0xc0008fc2e0, 0xc00065ffa8, 0x7, 0x23a1920, 0xc000283500, 0x0, 0x0)
	/Users/yuan.chen/GolandProjects/src/volcano.sh/volcano/vendor/k8s.io/client-go/rest/watch/decoder.go:49 +0x7c
volcano.sh/volcano/vendor/k8s.io/apimachinery/pkg/watch.(*StreamWatcher).receive(0xc0005a1b30)
	/Users/yuan.chen/GolandProjects/src/volcano.sh/volcano/vendor/k8s.io/apimachinery/pkg/watch/streamwatcher.go:93 +0x175
created by volcano.sh/volcano/vendor/k8s.io/apimachinery/pkg/watch.NewStreamWatcher
	/Users/yuan.chen/GolandProjects/src/volcano.sh/volcano/vendor/k8s.io/apimachinery/pkg/watch/streamwatcher.go:60 +0x9f

goroutine 96 [select]:
volcano.sh/volcano/vendor/k8s.io/apimachinery/pkg/util/wait.JitterUntil(0xc000771660, 0x12a05f200, 0x0, 0x7570306577514501, 0x0)
	/Users/yuan.chen/GolandProjects/src/volcano.sh/volcano/vendor/k8s.io/apimachinery/pkg/util/wait/wait.go:145 +0x181
volcano.sh/volcano/vendor/k8s.io/apimachinery/pkg/util/wait.Until(0xc000771660, 0x12a05f200, 0x0)
	/Users/yuan.chen/GolandProjects/src/volcano.sh/volcano/vendor/k8s.io/apimachinery/pkg/util/wait/wait.go:88 +0x4d
created by volcano.sh/volcano/pkg/scheduler.(*Scheduler).Run
	/Users/yuan.chen/GolandProjects/src/volcano.sh/volcano/pkg/scheduler/scheduler.go:68 +0xd4
