Log file created at: 2019/11/04 15:51:17
Running on machine: SVMAC-C02T6AMCGTFL
Binary: Built with gc go1.13 for darwin/amd64
Log line format: [IWEF]mmdd hh:mm:ss.uuuuuu threadid file:line] msg
I1104 15:51:17.592490   66853 event_handlers.go:729] Add Queue(default) into cache, spec(v1alpha2.QueueSpec{Weight:1, Capability:v1.ResourceList(nil)})
I1104 15:51:17.600621   66853 event_handlers.go:709] Add Queue(default) into cache, spec(v1alpha1.QueueSpec{Weight:1, Capability:v1.ResourceList(nil)})
I1104 15:51:17.605957   66853 event_handlers.go:48] Pod kube-system/coredns-fb8b8dccf-xfpnf will not not scheduled by jdos-batch, skip creating PodGroup and Job for it
I1104 15:51:17.605974   66853 event_handlers.go:189] Added pod <kube-system/coredns-fb8b8dccf-xfpnf> into cache.
I1104 15:51:17.605981   66853 event_handlers.go:48] Pod kube-system/etcd-minikube will not not scheduled by jdos-batch, skip creating PodGroup and Job for it
I1104 15:51:17.605985   66853 event_handlers.go:189] Added pod <kube-system/etcd-minikube> into cache.
I1104 15:51:17.605991   66853 event_handlers.go:48] Pod kube-system/kube-addon-manager-minikube will not not scheduled by jdos-batch, skip creating PodGroup and Job for it
I1104 15:51:17.605994   66853 event_handlers.go:189] Added pod <kube-system/kube-addon-manager-minikube> into cache.
I1104 15:51:17.606000   66853 event_handlers.go:48] Pod kube-system/kube-apiserver-minikube will not not scheduled by jdos-batch, skip creating PodGroup and Job for it
I1104 15:51:17.606003   66853 event_handlers.go:189] Added pod <kube-system/kube-apiserver-minikube> into cache.
I1104 15:51:17.606006   66853 event_handlers.go:48] Pod kube-system/kube-controller-manager-minikube will not not scheduled by jdos-batch, skip creating PodGroup and Job for it
I1104 15:51:17.606009   66853 event_handlers.go:189] Added pod <kube-system/kube-controller-manager-minikube> into cache.
I1104 15:51:17.606021   66853 event_handlers.go:48] Pod kube-system/kube-proxy-kc6f7 will not not scheduled by jdos-batch, skip creating PodGroup and Job for it
I1104 15:51:17.606024   66853 event_handlers.go:189] Added pod <kube-system/kube-proxy-kc6f7> into cache.
I1104 15:51:17.606028   66853 event_handlers.go:48] Pod kube-system/storage-provisioner will not not scheduled by jdos-batch, skip creating PodGroup and Job for it
I1104 15:51:17.606030   66853 event_handlers.go:189] Added pod <kube-system/storage-provisioner> into cache.
I1104 15:51:17.606035   66853 event_handlers.go:48] Pod kube-system/coredns-fb8b8dccf-cm54h will not not scheduled by jdos-batch, skip creating PodGroup and Job for it
I1104 15:51:17.606038   66853 event_handlers.go:189] Added pod <kube-system/coredns-fb8b8dccf-cm54h> into cache.
I1104 15:51:17.606042   66853 event_handlers.go:48] Pod kube-system/kube-scheduler-minikube will not not scheduled by jdos-batch, skip creating PodGroup and Job for it
I1104 15:51:17.606046   66853 event_handlers.go:189] Added pod <kube-system/kube-scheduler-minikube> into cache.
I1104 15:51:17.606049   66853 event_handlers.go:48] Pod kube-system/kubernetes-dashboard-d7c9687c7-tkc82 will not not scheduled by jdos-batch, skip creating PodGroup and Job for it
I1104 15:51:17.606052   66853 event_handlers.go:189] Added pod <kube-system/kubernetes-dashboard-d7c9687c7-tkc82> into cache.
I1104 15:51:17.606055   66853 event_handlers.go:48] Pod kube-system/registry-f4x5r will not not scheduled by jdos-batch, skip creating PodGroup and Job for it
I1104 15:51:17.606057   66853 event_handlers.go:189] Added pod <kube-system/registry-f4x5r> into cache.
I1104 15:51:17.687261   66853 scheduler.go:72] Start scheduling ...
I1104 15:51:17.687618   66853 cache.go:771] There are <0> Jobs, <1> Queues and <1> Nodes in total for scheduling.
I1104 15:51:17.687634   66853 session.go:135] Open Session fe697282-ff5d-11e9-99a6-784f43775513 with <0> Job and <1> Queues
I1104 15:51:17.687715   66853 proportion.go:67] The total resource is <cpu 4000.00, memory 4959854592.00, hugepages-2Mi 0.00>
I1104 15:51:17.687743   66853 proportion.go:117] Exiting when total weight is 0
I1104 15:51:17.687770   66853 enqueue.go:43] Enter Enqueue ...
I1104 15:51:17.687775   66853 enqueue.go:75] Try to enqueue PodGroup to 0 Queues
I1104 15:51:17.687783   66853 enqueue.go:122] Leaving Enqueue ...
I1104 15:51:17.687800   66853 allocate.go:43] Enter Allocate ...
I1104 15:51:17.687808   66853 allocate.go:94] Try to allocate resource to 0 Namespaces
I1104 15:51:17.687821   66853 allocate.go:253] Leaving Allocate ...
I1104 15:51:17.687826   66853 backfill.go:42] Enter Backfill ...
I1104 15:51:17.687830   66853 backfill.go:91] Leaving Backfill ...
I1104 15:51:17.687852   66853 session.go:154] Close Session fe697282-ff5d-11e9-99a6-784f43775513
I1104 15:51:17.687856   66853 scheduler.go:87] End scheduling ...
I1104 15:51:22.688067   66853 scheduler.go:72] Start scheduling ...
I1104 15:51:22.688222   66853 cache.go:771] There are <0> Jobs, <1> Queues and <1> Nodes in total for scheduling.
I1104 15:51:22.688228   66853 session.go:135] Open Session 01647b12-ff5e-11e9-99a6-784f43775513 with <0> Job and <1> Queues
I1104 15:51:22.688292   66853 proportion.go:67] The total resource is <cpu 4000.00, memory 4959854592.00, hugepages-2Mi 0.00>
I1104 15:51:22.688308   66853 proportion.go:117] Exiting when total weight is 0
I1104 15:51:22.688324   66853 enqueue.go:43] Enter Enqueue ...
I1104 15:51:22.688328   66853 enqueue.go:75] Try to enqueue PodGroup to 0 Queues
I1104 15:51:22.688334   66853 enqueue.go:122] Leaving Enqueue ...
I1104 15:51:22.688340   66853 allocate.go:43] Enter Allocate ...
I1104 15:51:22.688345   66853 allocate.go:94] Try to allocate resource to 0 Namespaces
I1104 15:51:22.688356   66853 allocate.go:253] Leaving Allocate ...
I1104 15:51:22.688360   66853 backfill.go:42] Enter Backfill ...
I1104 15:51:22.688363   66853 backfill.go:91] Leaving Backfill ...
I1104 15:51:22.688374   66853 session.go:154] Close Session 01647b12-ff5e-11e9-99a6-784f43775513
I1104 15:51:22.688377   66853 scheduler.go:87] End scheduling ...
I1104 15:51:27.691277   66853 scheduler.go:72] Start scheduling ...
I1104 15:51:27.691425   66853 cache.go:771] There are <0> Jobs, <1> Queues and <1> Nodes in total for scheduling.
I1104 15:51:27.691432   66853 session.go:135] Open Session 045fe874-ff5e-11e9-99a6-784f43775513 with <0> Job and <1> Queues
I1104 15:51:27.691468   66853 proportion.go:67] The total resource is <cpu 4000.00, memory 4959854592.00, hugepages-2Mi 0.00>
I1104 15:51:27.691485   66853 proportion.go:117] Exiting when total weight is 0
I1104 15:51:27.691502   66853 enqueue.go:43] Enter Enqueue ...
I1104 15:51:27.691506   66853 enqueue.go:75] Try to enqueue PodGroup to 0 Queues
I1104 15:51:27.691512   66853 enqueue.go:122] Leaving Enqueue ...
I1104 15:51:27.691518   66853 allocate.go:43] Enter Allocate ...
I1104 15:51:27.691523   66853 allocate.go:94] Try to allocate resource to 0 Namespaces
I1104 15:51:27.691533   66853 allocate.go:253] Leaving Allocate ...
I1104 15:51:27.691537   66853 backfill.go:42] Enter Backfill ...
I1104 15:51:27.691540   66853 backfill.go:91] Leaving Backfill ...
I1104 15:51:27.691550   66853 session.go:154] Close Session 045fe874-ff5e-11e9-99a6-784f43775513
I1104 15:51:27.691553   66853 scheduler.go:87] End scheduling ...
I1104 15:51:32.693213   66853 scheduler.go:72] Start scheduling ...
I1104 15:51:32.693363   66853 cache.go:771] There are <0> Jobs, <1> Queues and <1> Nodes in total for scheduling.
I1104 15:51:32.693370   66853 session.go:135] Open Session 075b24da-ff5e-11e9-99a6-784f43775513 with <0> Job and <1> Queues
I1104 15:51:32.693406   66853 proportion.go:67] The total resource is <cpu 4000.00, memory 4959854592.00, hugepages-2Mi 0.00>
I1104 15:51:32.693423   66853 proportion.go:117] Exiting when total weight is 0
I1104 15:51:32.693439   66853 enqueue.go:43] Enter Enqueue ...
I1104 15:51:32.693443   66853 enqueue.go:75] Try to enqueue PodGroup to 0 Queues
I1104 15:51:32.693450   66853 enqueue.go:122] Leaving Enqueue ...
I1104 15:51:32.693456   66853 allocate.go:43] Enter Allocate ...
I1104 15:51:32.693461   66853 allocate.go:94] Try to allocate resource to 0 Namespaces
I1104 15:51:32.693472   66853 allocate.go:253] Leaving Allocate ...
I1104 15:51:32.693476   66853 backfill.go:42] Enter Backfill ...
I1104 15:51:32.693479   66853 backfill.go:91] Leaving Backfill ...
I1104 15:51:32.693491   66853 session.go:154] Close Session 075b24da-ff5e-11e9-99a6-784f43775513
I1104 15:51:32.693494   66853 scheduler.go:87] End scheduling ...
I1104 15:51:37.697680   66853 scheduler.go:72] Start scheduling ...
I1104 15:51:37.697821   66853 cache.go:771] There are <0> Jobs, <1> Queues and <1> Nodes in total for scheduling.
I1104 15:51:37.697827   66853 session.go:135] Open Session 0a56c2d4-ff5e-11e9-99a6-784f43775513 with <0> Job and <1> Queues
I1104 15:51:37.697860   66853 proportion.go:67] The total resource is <cpu 4000.00, memory 4959854592.00, hugepages-2Mi 0.00>
I1104 15:51:37.697877   66853 proportion.go:117] Exiting when total weight is 0
I1104 15:51:37.697898   66853 enqueue.go:43] Enter Enqueue ...
I1104 15:51:37.697902   66853 enqueue.go:75] Try to enqueue PodGroup to 0 Queues
I1104 15:51:37.697908   66853 enqueue.go:122] Leaving Enqueue ...
I1104 15:51:37.697914   66853 allocate.go:43] Enter Allocate ...
I1104 15:51:37.697918   66853 allocate.go:94] Try to allocate resource to 0 Namespaces
I1104 15:51:37.697929   66853 allocate.go:253] Leaving Allocate ...
I1104 15:51:37.697933   66853 backfill.go:42] Enter Backfill ...
I1104 15:51:37.697936   66853 backfill.go:91] Leaving Backfill ...
I1104 15:51:37.697952   66853 session.go:154] Close Session 0a56c2d4-ff5e-11e9-99a6-784f43775513
I1104 15:51:37.697955   66853 scheduler.go:87] End scheduling ...
I1104 15:51:39.992705   66853 event_handlers.go:189] Added pod <default/qj-1-csdn6> into cache.
I1104 15:51:39.994241   66853 event_handlers.go:189] Added pod <default/qj-1-7bpz7> into cache.
I1104 15:51:39.998699   66853 event_handlers.go:409] Add PodGroup(qj-1) into cache, spec(v1alpha1.PodGroupSpec{MinMember:2, Queue:"default", PriorityClassName:"", MinResources:(*v1.ResourceList)(nil)})
I1104 15:51:42.698168   66853 scheduler.go:72] Start scheduling ...
I1104 15:51:42.698381   66853 cache.go:732] The priority of job <default/qj-1> is </0>
I1104 15:51:42.698406   66853 cache.go:771] There are <1> Jobs, <1> Queues and <1> Nodes in total for scheduling.
I1104 15:51:42.698415   66853 session.go:135] Open Session 0d51c768-ff5e-11e9-99a6-784f43775513 with <1> Job and <1> Queues
I1104 15:51:42.698475   66853 proportion.go:67] The total resource is <cpu 4000.00, memory 4959854592.00, hugepages-2Mi 0.00>
I1104 15:51:42.698513   66853 proportion.go:71] Considering Job <default/qj-1>.
I1104 15:51:42.698522   66853 proportion.go:85] Added Queue <default> attributes.
I1104 15:51:42.698535   66853 proportion.go:127] Considering Queue <default>: weight <1>, total weight <1>.
I1104 15:51:42.698546   66853 proportion.go:144] The attributes of queue <default> in proportion: deserved <cpu 4000.00, memory 4959854592.00, hugepages-2Mi 0.00>, allocate <cpu 0.00, memory 0.00>, request <cpu 2000.00, memory 1073741824.00>, share <0.00>
I1104 15:51:42.698585   66853 proportion.go:154] Exiting when remaining is empty:  <cpu 0.00, memory 0.00, hugepages-2Mi 0.00>
I1104 15:51:42.698623   66853 enqueue.go:43] Enter Enqueue ...
I1104 15:51:42.698627   66853 enqueue.go:58] Added Queue <default> for Job <default/qj-1>
I1104 15:51:42.698636   66853 enqueue.go:75] Try to enqueue PodGroup to 0 Queues
I1104 15:51:42.698643   66853 enqueue.go:122] Leaving Enqueue ...
I1104 15:51:42.698648   66853 allocate.go:43] Enter Allocate ...
I1104 15:51:42.698656   66853 allocate.go:90] Added Job <default/qj-1> into Queue <default>
I1104 15:51:42.698661   66853 allocate.go:94] Try to allocate resource to 1 Namespaces
I1104 15:51:42.698670   66853 allocate.go:153] Try to allocate resource to Jobs in Namespace <default> Queue <default>
I1104 15:51:42.698682   66853 priority.go:47] Priority TaskOrder: <default/qj-1-7bpz7> priority is 0, <default/qj-1-csdn6> priority is 0
I1104 15:51:42.698689   66853 allocate.go:178] Try to allocate resource to 2 tasks of Job <default/qj-1>
I1104 15:51:42.698708   66853 allocate.go:186] There are <1> nodes for Job <default/qj-1>
I1104 15:51:42.698737   66853 scheduler_helper.go:84] Considering Task <default/qj-1-csdn6> on node <minikube>: <cpu 1000.00, memory 536870912.00> vs. <cpu 3245.00, memory 4760625152.00, hugepages-2Mi 0.00>
I1104 15:51:42.698820   66853 predicates.go:177] CheckNodeCondition predicates Task <default/qj-1-csdn6> on Node <minikube>: fit true, err <nil>
I1104 15:51:42.698828   66853 predicates.go:190] CheckNodeUnschedulable Predicate Task <default/qj-1-csdn6> on Node <minikube>: fit true, err <nil>
I1104 15:51:42.698835   66853 predicates.go:203] NodeSelect predicates Task <default/qj-1-csdn6> on Node <minikube>: fit true, err <nil>
I1104 15:51:42.698843   66853 predicates.go:216] HostPorts predicates Task <default/qj-1-csdn6> on Node <minikube>: fit true, err <nil>
I1104 15:51:42.698848   66853 predicates.go:229] Toleration/Taint predicates Task <default/qj-1-csdn6> on Node <minikube>: fit true, err <nil>
I1104 15:51:42.698861   66853 predicates.go:294] Pod Affinity/Anti-Affinity predicates Task <default/qj-1-csdn6> on Node <minikube>: fit true, err <nil>
I1104 15:51:42.698898   66853 nodeorder.go:197] Total Score for task default/qj-1-csdn6 on node minikube is: 13.000000
I1104 15:51:42.698920   66853 nodeorder.go:217] Batch Total Score for task default/qj-1-csdn6 is: map[minikube:0]
I1104 15:51:42.698941   66853 allocate.go:210] Binding Task <default/qj-1-csdn6> to node <minikube>
I1104 15:51:42.698973   66853 statement.go:226] After allocated Task <default/qj-1-csdn6> to Node <minikube>: idle <cpu 2245.00, memory 4223754240.00, hugepages-2Mi 0.00>, used <cpu 1755.00, memory 736100352.00>, releasing <cpu 0.00, memory 0.00>
I1104 15:51:42.699022   66853 predicates.go:134] predicates, update pod default/qj-1-csdn6 allocate to node [minikube]
I1104 15:51:42.699027   66853 proportion.go:247] Proportion AllocateFunc: task <default/qj-1-csdn6>, resreq <cpu 1000.00, memory 536870912.00>,  share <0.25>
I1104 15:51:42.699070   66853 nodeorder.go:144] node order, update pod default/qj-1-csdn6 allocate to node [minikube]
I1104 15:51:42.699080   66853 drf.go:271] DRF AllocateFunc: task <default/qj-1-csdn6>, resreq <cpu 1000.00, memory 536870912.00>,  share <0.25>, namespace share <0.25>
I1104 15:51:42.699085   66853 statement.go:244] Allocating operations ...
I1104 15:51:42.699093   66853 allocate.go:186] There are <1> nodes for Job <default/qj-1>
I1104 15:51:42.699110   66853 scheduler_helper.go:84] Considering Task <default/qj-1-7bpz7> on node <minikube>: <cpu 1000.00, memory 536870912.00> vs. <cpu 2245.00, memory 4223754240.00, hugepages-2Mi 0.00>
I1104 15:51:42.699127   66853 predicates.go:177] CheckNodeCondition predicates Task <default/qj-1-7bpz7> on Node <minikube>: fit true, err <nil>
I1104 15:51:42.699132   66853 predicates.go:190] CheckNodeUnschedulable Predicate Task <default/qj-1-7bpz7> on Node <minikube>: fit true, err <nil>
I1104 15:51:42.699137   66853 predicates.go:203] NodeSelect predicates Task <default/qj-1-7bpz7> on Node <minikube>: fit true, err <nil>
I1104 15:51:42.699142   66853 predicates.go:216] HostPorts predicates Task <default/qj-1-7bpz7> on Node <minikube>: fit true, err <nil>
I1104 15:51:42.699147   66853 predicates.go:229] Toleration/Taint predicates Task <default/qj-1-7bpz7> on Node <minikube>: fit true, err <nil>
I1104 15:51:42.699155   66853 predicates.go:294] Pod Affinity/Anti-Affinity predicates Task <default/qj-1-7bpz7> on Node <minikube>: fit true, err <nil>
I1104 15:51:42.699172   66853 nodeorder.go:197] Total Score for task default/qj-1-7bpz7 on node minikube is: 9.000000
I1104 15:51:42.699188   66853 nodeorder.go:217] Batch Total Score for task default/qj-1-7bpz7 is: map[minikube:0]
I1104 15:51:42.699200   66853 allocate.go:210] Binding Task <default/qj-1-7bpz7> to node <minikube>
I1104 15:51:42.699208   66853 statement.go:226] After allocated Task <default/qj-1-7bpz7> to Node <minikube>: idle <cpu 1245.00, memory 3686883328.00, hugepages-2Mi 0.00>, used <cpu 2755.00, memory 1272971264.00>, releasing <cpu 0.00, memory 0.00>
I1104 15:51:42.699221   66853 predicates.go:134] predicates, update pod default/qj-1-7bpz7 allocate to node [minikube]
I1104 15:51:42.699224   66853 proportion.go:247] Proportion AllocateFunc: task <default/qj-1-7bpz7>, resreq <cpu 1000.00, memory 536870912.00>,  share <0.5>
I1104 15:51:42.699232   66853 nodeorder.go:144] node order, update pod default/qj-1-7bpz7 allocate to node [minikube]
I1104 15:51:42.699236   66853 drf.go:271] DRF AllocateFunc: task <default/qj-1-7bpz7>, resreq <cpu 1000.00, memory 536870912.00>,  share <0.5>, namespace share <0.5>
I1104 15:51:42.699240   66853 statement.go:244] Allocating operations ...
I1104 15:51:42.699252   66853 statement.go:326] Committing operations ...
I1104 15:51:42.699275   66853 allocate.go:153] Try to allocate resource to Jobs in Namespace <default> Queue <default>
I1104 15:51:42.699281   66853 allocate.go:157] Can not find jobs for queue default.
I1104 15:51:42.699290   66853 allocate.go:253] Leaving Allocate ...
I1104 15:51:42.699295   66853 backfill.go:42] Enter Backfill ...
I1104 15:51:42.699300   66853 backfill.go:91] Leaving Backfill ...
I1104 15:51:42.707005   66853 event_handlers.go:215] Updated pod <default/qj-1-7bpz7> in cache.
I1104 15:51:42.710886   66853 event_handlers.go:215] Updated pod <default/qj-1-csdn6> in cache.
I1104 15:51:42.713836   66853 session.go:154] Close Session 0d51c768-ff5e-11e9-99a6-784f43775513
I1104 15:51:42.713848   66853 scheduler.go:87] End scheduling ...
I1104 15:51:42.734016   66853 event_handlers.go:215] Updated pod <default/qj-1-7bpz7> in cache.
I1104 15:51:42.745807   66853 event_handlers.go:215] Updated pod <default/qj-1-csdn6> in cache.
I1104 15:51:46.046348   66853 event_handlers.go:215] Updated pod <default/qj-1-csdn6> in cache.
I1104 15:51:47.066469   66853 event_handlers.go:215] Updated pod <default/qj-1-7bpz7> in cache.
I1104 15:51:47.717308   66853 scheduler.go:72] Start scheduling ...
I1104 15:51:47.717426   66853 cache.go:732] The priority of job <default/qj-1> is </0>
I1104 15:51:47.717441   66853 cache.go:771] There are <1> Jobs, <1> Queues and <1> Nodes in total for scheduling.
I1104 15:51:47.717445   66853 session.go:135] Open Session 104fa21e-ff5e-11e9-99a6-784f43775513 with <1> Job and <1> Queues
I1104 15:51:47.717481   66853 proportion.go:67] The total resource is <cpu 4000.00, memory 4959854592.00, hugepages-2Mi 0.00>
I1104 15:51:47.717492   66853 proportion.go:71] Considering Job <default/qj-1>.
I1104 15:51:47.717496   66853 proportion.go:85] Added Queue <default> attributes.
I1104 15:51:47.717502   66853 proportion.go:127] Considering Queue <default>: weight <1>, total weight <1>.
I1104 15:51:47.717507   66853 proportion.go:144] The attributes of queue <default> in proportion: deserved <cpu 4000.00, memory 4959854592.00, hugepages-2Mi 0.00>, allocate <cpu 2000.00, memory 1073741824.00>, request <cpu 2000.00, memory 1073741824.00>, share <0.50>
I1104 15:51:47.717519   66853 proportion.go:154] Exiting when remaining is empty:  <cpu 0.00, memory 0.00, hugepages-2Mi 0.00>
I1104 15:51:47.717535   66853 enqueue.go:43] Enter Enqueue ...
I1104 15:51:47.717539   66853 enqueue.go:58] Added Queue <default> for Job <default/qj-1>
I1104 15:51:47.717543   66853 enqueue.go:75] Try to enqueue PodGroup to 0 Queues
I1104 15:51:47.717548   66853 enqueue.go:122] Leaving Enqueue ...
I1104 15:51:47.717553   66853 allocate.go:43] Enter Allocate ...
I1104 15:51:47.717557   66853 allocate.go:90] Added Job <default/qj-1> into Queue <default>
I1104 15:51:47.717561   66853 allocate.go:94] Try to allocate resource to 1 Namespaces
I1104 15:51:47.717567   66853 allocate.go:153] Try to allocate resource to Jobs in Namespace <default> Queue <default>
I1104 15:51:47.717572   66853 allocate.go:178] Try to allocate resource to 0 tasks of Job <default/qj-1>
I1104 15:51:47.717576   66853 statement.go:326] Committing operations ...
I1104 15:51:47.717580   66853 allocate.go:153] Try to allocate resource to Jobs in Namespace <default> Queue <default>
I1104 15:51:47.717584   66853 allocate.go:157] Can not find jobs for queue default.
I1104 15:51:47.717591   66853 allocate.go:253] Leaving Allocate ...
I1104 15:51:47.717595   66853 backfill.go:42] Enter Backfill ...
I1104 15:51:47.717598   66853 backfill.go:91] Leaving Backfill ...
I1104 15:51:47.722702   66853 session.go:154] Close Session 104fa21e-ff5e-11e9-99a6-784f43775513
I1104 15:51:47.722713   66853 scheduler.go:87] End scheduling ...
I1104 15:51:52.727294   66853 scheduler.go:72] Start scheduling ...
I1104 15:51:52.727448   66853 cache.go:732] The priority of job <default/qj-1> is </0>
I1104 15:51:52.727463   66853 cache.go:771] There are <1> Jobs, <1> Queues and <1> Nodes in total for scheduling.
I1104 15:51:52.727469   66853 session.go:135] Open Session 134c19de-ff5e-11e9-99a6-784f43775513 with <1> Job and <1> Queues
I1104 15:51:52.727507   66853 proportion.go:67] The total resource is <cpu 4000.00, memory 4959854592.00, hugepages-2Mi 0.00>
I1104 15:51:52.727551   66853 proportion.go:71] Considering Job <default/qj-1>.
I1104 15:51:52.727555   66853 proportion.go:85] Added Queue <default> attributes.
I1104 15:51:52.727575   66853 proportion.go:127] Considering Queue <default>: weight <1>, total weight <1>.
I1104 15:51:52.727581   66853 proportion.go:144] The attributes of queue <default> in proportion: deserved <cpu 4000.00, memory 4959854592.00, hugepages-2Mi 0.00>, allocate <cpu 2000.00, memory 1073741824.00>, request <cpu 2000.00, memory 1073741824.00>, share <0.50>
I1104 15:51:52.727595   66853 proportion.go:154] Exiting when remaining is empty:  <cpu 0.00, memory 0.00, hugepages-2Mi 0.00>
I1104 15:51:52.727614   66853 enqueue.go:43] Enter Enqueue ...
I1104 15:51:52.727618   66853 enqueue.go:58] Added Queue <default> for Job <default/qj-1>
I1104 15:51:52.727622   66853 enqueue.go:75] Try to enqueue PodGroup to 0 Queues
I1104 15:51:52.727627   66853 enqueue.go:122] Leaving Enqueue ...
I1104 15:51:52.727633   66853 allocate.go:43] Enter Allocate ...
I1104 15:51:52.727636   66853 allocate.go:90] Added Job <default/qj-1> into Queue <default>
I1104 15:51:52.727641   66853 allocate.go:94] Try to allocate resource to 1 Namespaces
I1104 15:51:52.727646   66853 allocate.go:153] Try to allocate resource to Jobs in Namespace <default> Queue <default>
I1104 15:51:52.727652   66853 allocate.go:178] Try to allocate resource to 0 tasks of Job <default/qj-1>
I1104 15:51:52.727656   66853 statement.go:326] Committing operations ...
I1104 15:51:52.727660   66853 allocate.go:153] Try to allocate resource to Jobs in Namespace <default> Queue <default>
I1104 15:51:52.727664   66853 allocate.go:157] Can not find jobs for queue default.
I1104 15:51:52.727672   66853 allocate.go:253] Leaving Allocate ...
I1104 15:51:52.727675   66853 backfill.go:42] Enter Backfill ...
I1104 15:51:52.727678   66853 backfill.go:91] Leaving Backfill ...
I1104 15:51:52.730988   66853 session.go:154] Close Session 134c19de-ff5e-11e9-99a6-784f43775513
I1104 15:51:52.730998   66853 scheduler.go:87] End scheduling ...
I1104 15:51:57.731981   66853 scheduler.go:72] Start scheduling ...
I1104 15:51:57.732126   66853 cache.go:732] The priority of job <default/qj-1> is </0>
I1104 15:51:57.732147   66853 cache.go:771] There are <1> Jobs, <1> Queues and <1> Nodes in total for scheduling.
I1104 15:51:57.732152   66853 session.go:135] Open Session 1647c084-ff5e-11e9-99a6-784f43775513 with <1> Job and <1> Queues
I1104 15:51:57.732191   66853 proportion.go:67] The total resource is <cpu 4000.00, memory 4959854592.00, hugepages-2Mi 0.00>
I1104 15:51:57.732202   66853 proportion.go:71] Considering Job <default/qj-1>.
I1104 15:51:57.732206   66853 proportion.go:85] Added Queue <default> attributes.
I1104 15:51:57.732212   66853 proportion.go:127] Considering Queue <default>: weight <1>, total weight <1>.
I1104 15:51:57.732217   66853 proportion.go:144] The attributes of queue <default> in proportion: deserved <cpu 4000.00, memory 4959854592.00, hugepages-2Mi 0.00>, allocate <cpu 2000.00, memory 1073741824.00>, request <cpu 2000.00, memory 1073741824.00>, share <0.50>
I1104 15:51:57.732230   66853 proportion.go:154] Exiting when remaining is empty:  <cpu 0.00, memory 0.00, hugepages-2Mi 0.00>
I1104 15:51:57.732249   66853 enqueue.go:43] Enter Enqueue ...
I1104 15:51:57.732253   66853 enqueue.go:58] Added Queue <default> for Job <default/qj-1>
I1104 15:51:57.732258   66853 enqueue.go:75] Try to enqueue PodGroup to 0 Queues
I1104 15:51:57.732263   66853 enqueue.go:122] Leaving Enqueue ...
I1104 15:51:57.732268   66853 allocate.go:43] Enter Allocate ...
I1104 15:51:57.732272   66853 allocate.go:90] Added Job <default/qj-1> into Queue <default>
I1104 15:51:57.732276   66853 allocate.go:94] Try to allocate resource to 1 Namespaces
I1104 15:51:57.732282   66853 allocate.go:153] Try to allocate resource to Jobs in Namespace <default> Queue <default>
I1104 15:51:57.732288   66853 allocate.go:178] Try to allocate resource to 0 tasks of Job <default/qj-1>
I1104 15:51:57.732291   66853 statement.go:326] Committing operations ...
I1104 15:51:57.732296   66853 allocate.go:153] Try to allocate resource to Jobs in Namespace <default> Queue <default>
I1104 15:51:57.732299   66853 allocate.go:157] Can not find jobs for queue default.
I1104 15:51:57.732307   66853 allocate.go:253] Leaving Allocate ...
I1104 15:51:57.732310   66853 backfill.go:42] Enter Backfill ...
I1104 15:51:57.732314   66853 backfill.go:91] Leaving Backfill ...
I1104 15:51:57.735789   66853 session.go:154] Close Session 1647c084-ff5e-11e9-99a6-784f43775513
I1104 15:51:57.735798   66853 scheduler.go:87] End scheduling ...
I1104 15:52:02.737082   66853 scheduler.go:72] Start scheduling ...
I1104 15:52:02.737207   66853 cache.go:732] The priority of job <default/qj-1> is </0>
I1104 15:52:02.737223   66853 cache.go:771] There are <1> Jobs, <1> Queues and <1> Nodes in total for scheduling.
I1104 15:52:02.737228   66853 session.go:135] Open Session 19437828-ff5e-11e9-99a6-784f43775513 with <1> Job and <1> Queues
I1104 15:52:02.737262   66853 proportion.go:67] The total resource is <cpu 4000.00, memory 4959854592.00, hugepages-2Mi 0.00>
I1104 15:52:02.737272   66853 proportion.go:71] Considering Job <default/qj-1>.
I1104 15:52:02.737276   66853 proportion.go:85] Added Queue <default> attributes.
I1104 15:52:02.737284   66853 proportion.go:127] Considering Queue <default>: weight <1>, total weight <1>.
I1104 15:52:02.737290   66853 proportion.go:144] The attributes of queue <default> in proportion: deserved <cpu 4000.00, memory 4959854592.00, hugepages-2Mi 0.00>, allocate <cpu 2000.00, memory 1073741824.00>, request <cpu 2000.00, memory 1073741824.00>, share <0.50>
I1104 15:52:02.737302   66853 proportion.go:154] Exiting when remaining is empty:  <cpu 0.00, memory 0.00, hugepages-2Mi 0.00>
I1104 15:52:02.737327   66853 enqueue.go:43] Enter Enqueue ...
I1104 15:52:02.737330   66853 enqueue.go:58] Added Queue <default> for Job <default/qj-1>
I1104 15:52:02.737334   66853 enqueue.go:75] Try to enqueue PodGroup to 0 Queues
I1104 15:52:02.737341   66853 enqueue.go:122] Leaving Enqueue ...
I1104 15:52:02.737346   66853 allocate.go:43] Enter Allocate ...
I1104 15:52:02.737350   66853 allocate.go:90] Added Job <default/qj-1> into Queue <default>
I1104 15:52:02.737355   66853 allocate.go:94] Try to allocate resource to 1 Namespaces
I1104 15:52:02.737360   66853 allocate.go:153] Try to allocate resource to Jobs in Namespace <default> Queue <default>
I1104 15:52:02.737366   66853 allocate.go:178] Try to allocate resource to 0 tasks of Job <default/qj-1>
I1104 15:52:02.737370   66853 statement.go:326] Committing operations ...
I1104 15:52:02.737375   66853 allocate.go:153] Try to allocate resource to Jobs in Namespace <default> Queue <default>
I1104 15:52:02.737379   66853 allocate.go:157] Can not find jobs for queue default.
I1104 15:52:02.737387   66853 allocate.go:253] Leaving Allocate ...
I1104 15:52:02.737390   66853 backfill.go:42] Enter Backfill ...
I1104 15:52:02.737394   66853 backfill.go:91] Leaving Backfill ...
I1104 15:52:02.740734   66853 session.go:154] Close Session 19437828-ff5e-11e9-99a6-784f43775513
I1104 15:52:02.740746   66853 scheduler.go:87] End scheduling ...
I1104 15:52:07.742774   66853 scheduler.go:72] Start scheduling ...
I1104 15:52:07.742926   66853 cache.go:732] The priority of job <default/qj-1> is </0>
I1104 15:52:07.742945   66853 cache.go:771] There are <1> Jobs, <1> Queues and <1> Nodes in total for scheduling.
I1104 15:52:07.742949   66853 session.go:135] Open Session 1c3f47b4-ff5e-11e9-99a6-784f43775513 with <1> Job and <1> Queues
I1104 15:52:07.742985   66853 proportion.go:67] The total resource is <cpu 4000.00, memory 4959854592.00, hugepages-2Mi 0.00>
I1104 15:52:07.742995   66853 proportion.go:71] Considering Job <default/qj-1>.
I1104 15:52:07.742999   66853 proportion.go:85] Added Queue <default> attributes.
I1104 15:52:07.743005   66853 proportion.go:127] Considering Queue <default>: weight <1>, total weight <1>.
I1104 15:52:07.743012   66853 proportion.go:144] The attributes of queue <default> in proportion: deserved <cpu 4000.00, memory 4959854592.00, hugepages-2Mi 0.00>, allocate <cpu 2000.00, memory 1073741824.00>, request <cpu 2000.00, memory 1073741824.00>, share <0.50>
I1104 15:52:07.743025   66853 proportion.go:154] Exiting when remaining is empty:  <cpu 0.00, memory 0.00, hugepages-2Mi 0.00>
I1104 15:52:07.743043   66853 enqueue.go:43] Enter Enqueue ...
I1104 15:52:07.743046   66853 enqueue.go:58] Added Queue <default> for Job <default/qj-1>
I1104 15:52:07.743051   66853 enqueue.go:75] Try to enqueue PodGroup to 0 Queues
I1104 15:52:07.743056   66853 enqueue.go:122] Leaving Enqueue ...
I1104 15:52:07.743061   66853 allocate.go:43] Enter Allocate ...
I1104 15:52:07.743065   66853 allocate.go:90] Added Job <default/qj-1> into Queue <default>
I1104 15:52:07.743069   66853 allocate.go:94] Try to allocate resource to 1 Namespaces
I1104 15:52:07.743075   66853 allocate.go:153] Try to allocate resource to Jobs in Namespace <default> Queue <default>
I1104 15:52:07.743081   66853 allocate.go:178] Try to allocate resource to 0 tasks of Job <default/qj-1>
I1104 15:52:07.743084   66853 statement.go:326] Committing operations ...
I1104 15:52:07.743088   66853 allocate.go:153] Try to allocate resource to Jobs in Namespace <default> Queue <default>
I1104 15:52:07.743092   66853 allocate.go:157] Can not find jobs for queue default.
I1104 15:52:07.743100   66853 allocate.go:253] Leaving Allocate ...
I1104 15:52:07.743103   66853 backfill.go:42] Enter Backfill ...
I1104 15:52:07.743106   66853 backfill.go:91] Leaving Backfill ...
I1104 15:52:07.746284   66853 session.go:154] Close Session 1c3f47b4-ff5e-11e9-99a6-784f43775513
I1104 15:52:07.746294   66853 scheduler.go:87] End scheduling ...
I1104 15:52:12.750913   66853 scheduler.go:72] Start scheduling ...
I1104 15:52:12.751040   66853 cache.go:732] The priority of job <default/qj-1> is </0>
I1104 15:52:12.751056   66853 cache.go:771] There are <1> Jobs, <1> Queues and <1> Nodes in total for scheduling.
I1104 15:52:12.751060   66853 session.go:135] Open Session 1f3b758c-ff5e-11e9-99a6-784f43775513 with <1> Job and <1> Queues
I1104 15:52:12.751071   66853 proportion.go:67] The total resource is <cpu 4000.00, memory 4959854592.00, hugepages-2Mi 0.00>
I1104 15:52:12.751080   66853 proportion.go:71] Considering Job <default/qj-1>.
I1104 15:52:12.751084   66853 proportion.go:85] Added Queue <default> attributes.
I1104 15:52:12.751091   66853 proportion.go:127] Considering Queue <default>: weight <1>, total weight <1>.
I1104 15:52:12.751096   66853 proportion.go:144] The attributes of queue <default> in proportion: deserved <cpu 4000.00, memory 4959854592.00, hugepages-2Mi 0.00>, allocate <cpu 2000.00, memory 1073741824.00>, request <cpu 2000.00, memory 1073741824.00>, share <0.50>
I1104 15:52:12.751108   66853 proportion.go:154] Exiting when remaining is empty:  <cpu 0.00, memory 0.00, hugepages-2Mi 0.00>
I1104 15:52:12.751161   66853 enqueue.go:43] Enter Enqueue ...
I1104 15:52:12.751164   66853 enqueue.go:58] Added Queue <default> for Job <default/qj-1>
I1104 15:52:12.751168   66853 enqueue.go:75] Try to enqueue PodGroup to 0 Queues
I1104 15:52:12.751174   66853 enqueue.go:122] Leaving Enqueue ...
I1104 15:52:12.751179   66853 allocate.go:43] Enter Allocate ...
I1104 15:52:12.751183   66853 allocate.go:90] Added Job <default/qj-1> into Queue <default>
I1104 15:52:12.751187   66853 allocate.go:94] Try to allocate resource to 1 Namespaces
I1104 15:52:12.751193   66853 allocate.go:153] Try to allocate resource to Jobs in Namespace <default> Queue <default>
I1104 15:52:12.751199   66853 allocate.go:178] Try to allocate resource to 0 tasks of Job <default/qj-1>
I1104 15:52:12.751202   66853 statement.go:326] Committing operations ...
I1104 15:52:12.751207   66853 allocate.go:153] Try to allocate resource to Jobs in Namespace <default> Queue <default>
I1104 15:52:12.751210   66853 allocate.go:157] Can not find jobs for queue default.
I1104 15:52:12.751218   66853 allocate.go:253] Leaving Allocate ...
I1104 15:52:12.751221   66853 backfill.go:42] Enter Backfill ...
I1104 15:52:12.751229   66853 backfill.go:91] Leaving Backfill ...
I1104 15:52:12.755654   66853 session.go:154] Close Session 1f3b758c-ff5e-11e9-99a6-784f43775513
I1104 15:52:12.755664   66853 scheduler.go:87] End scheduling ...
I1104 15:52:17.755874   66853 scheduler.go:72] Start scheduling ...
I1104 15:52:17.756061   66853 cache.go:732] The priority of job <default/qj-1> is </0>
I1104 15:52:17.756082   66853 cache.go:771] There are <1> Jobs, <1> Queues and <1> Nodes in total for scheduling.
I1104 15:52:17.756087   66853 session.go:135] Open Session 223728e4-ff5e-11e9-99a6-784f43775513 with <1> Job and <1> Queues
I1104 15:52:17.756188   66853 proportion.go:67] The total resource is <cpu 4000.00, memory 4959854592.00, hugepages-2Mi 0.00>
I1104 15:52:17.756205   66853 proportion.go:71] Considering Job <default/qj-1>.
I1104 15:52:17.756211   66853 proportion.go:85] Added Queue <default> attributes.
I1104 15:52:17.756221   66853 proportion.go:127] Considering Queue <default>: weight <1>, total weight <1>.
I1104 15:52:17.756231   66853 proportion.go:144] The attributes of queue <default> in proportion: deserved <cpu 4000.00, memory 4959854592.00, hugepages-2Mi 0.00>, allocate <cpu 2000.00, memory 1073741824.00>, request <cpu 2000.00, memory 1073741824.00>, share <0.50>
I1104 15:52:17.756256   66853 proportion.go:154] Exiting when remaining is empty:  <cpu 0.00, memory 0.00, hugepages-2Mi 0.00>
I1104 15:52:17.756300   66853 enqueue.go:43] Enter Enqueue ...
I1104 15:52:17.756307   66853 enqueue.go:58] Added Queue <default> for Job <default/qj-1>
I1104 15:52:17.756315   66853 enqueue.go:75] Try to enqueue PodGroup to 0 Queues
I1104 15:52:17.756325   66853 enqueue.go:122] Leaving Enqueue ...
I1104 15:52:17.756332   66853 allocate.go:43] Enter Allocate ...
I1104 15:52:17.756339   66853 allocate.go:90] Added Job <default/qj-1> into Queue <default>
I1104 15:52:17.756347   66853 allocate.go:94] Try to allocate resource to 1 Namespaces
I1104 15:52:17.756356   66853 allocate.go:153] Try to allocate resource to Jobs in Namespace <default> Queue <default>
I1104 15:52:17.756366   66853 allocate.go:178] Try to allocate resource to 0 tasks of Job <default/qj-1>
I1104 15:52:17.756371   66853 statement.go:326] Committing operations ...
I1104 15:52:17.756379   66853 allocate.go:153] Try to allocate resource to Jobs in Namespace <default> Queue <default>
I1104 15:52:17.756385   66853 allocate.go:157] Can not find jobs for queue default.
I1104 15:52:17.756398   66853 allocate.go:253] Leaving Allocate ...
I1104 15:52:17.756403   66853 backfill.go:42] Enter Backfill ...
I1104 15:52:17.756409   66853 backfill.go:91] Leaving Backfill ...
I1104 15:52:17.765704   66853 session.go:154] Close Session 223728e4-ff5e-11e9-99a6-784f43775513
I1104 15:52:17.765717   66853 scheduler.go:87] End scheduling ...
I1104 15:52:22.768220   66853 scheduler.go:72] Start scheduling ...
I1104 15:52:22.768359   66853 cache.go:732] The priority of job <default/qj-1> is </0>
I1104 15:52:22.768389   66853 cache.go:771] There are <1> Jobs, <1> Queues and <1> Nodes in total for scheduling.
I1104 15:52:22.768393   66853 session.go:135] Open Session 2533fafe-ff5e-11e9-99a6-784f43775513 with <1> Job and <1> Queues
I1104 15:52:22.768427   66853 proportion.go:67] The total resource is <cpu 4000.00, memory 4959854592.00, hugepages-2Mi 0.00>
I1104 15:52:22.768437   66853 proportion.go:71] Considering Job <default/qj-1>.
I1104 15:52:22.768441   66853 proportion.go:85] Added Queue <default> attributes.
I1104 15:52:22.768447   66853 proportion.go:127] Considering Queue <default>: weight <1>, total weight <1>.
I1104 15:52:22.768452   66853 proportion.go:144] The attributes of queue <default> in proportion: deserved <cpu 4000.00, memory 4959854592.00, hugepages-2Mi 0.00>, allocate <cpu 2000.00, memory 1073741824.00>, request <cpu 2000.00, memory 1073741824.00>, share <0.50>
I1104 15:52:22.768463   66853 proportion.go:154] Exiting when remaining is empty:  <cpu 0.00, memory 0.00, hugepages-2Mi 0.00>
I1104 15:52:22.768484   66853 enqueue.go:43] Enter Enqueue ...
I1104 15:52:22.768488   66853 enqueue.go:58] Added Queue <default> for Job <default/qj-1>
I1104 15:52:22.768492   66853 enqueue.go:75] Try to enqueue PodGroup to 0 Queues
I1104 15:52:22.768497   66853 enqueue.go:122] Leaving Enqueue ...
I1104 15:52:22.768502   66853 allocate.go:43] Enter Allocate ...
I1104 15:52:22.768506   66853 allocate.go:90] Added Job <default/qj-1> into Queue <default>
I1104 15:52:22.768511   66853 allocate.go:94] Try to allocate resource to 1 Namespaces
I1104 15:52:22.768516   66853 allocate.go:153] Try to allocate resource to Jobs in Namespace <default> Queue <default>
I1104 15:52:22.768522   66853 allocate.go:178] Try to allocate resource to 0 tasks of Job <default/qj-1>
I1104 15:52:22.768526   66853 statement.go:326] Committing operations ...
I1104 15:52:22.768530   66853 allocate.go:153] Try to allocate resource to Jobs in Namespace <default> Queue <default>
I1104 15:52:22.768534   66853 allocate.go:157] Can not find jobs for queue default.
I1104 15:52:22.768541   66853 allocate.go:253] Leaving Allocate ...
I1104 15:52:22.768544   66853 backfill.go:42] Enter Backfill ...
I1104 15:52:22.768548   66853 backfill.go:91] Leaving Backfill ...
I1104 15:52:22.792863   66853 session.go:154] Close Session 2533fafe-ff5e-11e9-99a6-784f43775513
I1104 15:52:22.792903   66853 scheduler.go:87] End scheduling ...
I1104 15:52:27.794955   66853 scheduler.go:72] Start scheduling ...
I1104 15:52:27.795085   66853 cache.go:732] The priority of job <default/qj-1> is </0>
I1104 15:52:27.795124   66853 cache.go:771] There are <1> Jobs, <1> Queues and <1> Nodes in total for scheduling.
I1104 15:52:27.795129   66853 session.go:135] Open Session 2832ff3e-ff5e-11e9-99a6-784f43775513 with <1> Job and <1> Queues
I1104 15:52:27.795178   66853 proportion.go:67] The total resource is <cpu 4000.00, memory 4959854592.00, hugepages-2Mi 0.00>
I1104 15:52:27.795189   66853 proportion.go:71] Considering Job <default/qj-1>.
I1104 15:52:27.795192   66853 proportion.go:85] Added Queue <default> attributes.
I1104 15:52:27.795198   66853 proportion.go:127] Considering Queue <default>: weight <1>, total weight <1>.
I1104 15:52:27.795204   66853 proportion.go:144] The attributes of queue <default> in proportion: deserved <cpu 4000.00, memory 4959854592.00, hugepages-2Mi 0.00>, allocate <cpu 2000.00, memory 1073741824.00>, request <cpu 2000.00, memory 1073741824.00>, share <0.50>
I1104 15:52:27.795214   66853 proportion.go:154] Exiting when remaining is empty:  <cpu 0.00, memory 0.00, hugepages-2Mi 0.00>
I1104 15:52:27.795226   66853 enqueue.go:43] Enter Enqueue ...
I1104 15:52:27.795229   66853 enqueue.go:58] Added Queue <default> for Job <default/qj-1>
I1104 15:52:27.795234   66853 enqueue.go:75] Try to enqueue PodGroup to 0 Queues
I1104 15:52:27.795239   66853 enqueue.go:122] Leaving Enqueue ...
I1104 15:52:27.795244   66853 allocate.go:43] Enter Allocate ...
I1104 15:52:27.795248   66853 allocate.go:90] Added Job <default/qj-1> into Queue <default>
I1104 15:52:27.795252   66853 allocate.go:94] Try to allocate resource to 1 Namespaces
I1104 15:52:27.795258   66853 allocate.go:153] Try to allocate resource to Jobs in Namespace <default> Queue <default>
I1104 15:52:27.795264   66853 allocate.go:178] Try to allocate resource to 0 tasks of Job <default/qj-1>
I1104 15:52:27.795267   66853 statement.go:326] Committing operations ...
I1104 15:52:27.795272   66853 allocate.go:153] Try to allocate resource to Jobs in Namespace <default> Queue <default>
I1104 15:52:27.795275   66853 allocate.go:157] Can not find jobs for queue default.
I1104 15:52:27.795283   66853 allocate.go:253] Leaving Allocate ...
I1104 15:52:27.795286   66853 backfill.go:42] Enter Backfill ...
I1104 15:52:27.795290   66853 backfill.go:91] Leaving Backfill ...
I1104 15:52:27.799407   66853 session.go:154] Close Session 2832ff3e-ff5e-11e9-99a6-784f43775513
I1104 15:52:27.799430   66853 scheduler.go:87] End scheduling ...
I1104 15:52:28.750769   66853 event_handlers.go:215] Updated pod <default/qj-1-7bpz7> in cache.
I1104 15:52:28.773379   66853 event_handlers.go:215] Updated pod <default/qj-1-csdn6> in cache.
I1104 15:52:32.801347   66853 scheduler.go:72] Start scheduling ...
I1104 15:52:32.801486   66853 cache.go:732] The priority of job <default/qj-1> is </0>
I1104 15:52:32.801502   66853 cache.go:771] There are <1> Jobs, <1> Queues and <1> Nodes in total for scheduling.
I1104 15:52:32.801507   66853 session.go:135] Open Session 2b2ee98c-ff5e-11e9-99a6-784f43775513 with <1> Job and <1> Queues
I1104 15:52:32.801559   66853 proportion.go:67] The total resource is <cpu 4000.00, memory 4959854592.00, hugepages-2Mi 0.00>
I1104 15:52:32.801572   66853 proportion.go:71] Considering Job <default/qj-1>.
I1104 15:52:32.801576   66853 proportion.go:85] Added Queue <default> attributes.
I1104 15:52:32.801583   66853 proportion.go:127] Considering Queue <default>: weight <1>, total weight <1>.
I1104 15:52:32.801589   66853 proportion.go:144] The attributes of queue <default> in proportion: deserved <cpu 4000.00, memory 4959854592.00, hugepages-2Mi 0.00>, allocate <cpu 0.00, memory 0.00>, request <cpu 0.00, memory 0.00>, share <0.00>
I1104 15:52:32.801601   66853 proportion.go:154] Exiting when remaining is empty:  <cpu 0.00, memory 0.00, hugepages-2Mi 0.00>
I1104 15:52:32.801627   66853 enqueue.go:43] Enter Enqueue ...
I1104 15:52:32.801630   66853 enqueue.go:58] Added Queue <default> for Job <default/qj-1>
I1104 15:52:32.801635   66853 enqueue.go:75] Try to enqueue PodGroup to 0 Queues
I1104 15:52:32.801641   66853 enqueue.go:122] Leaving Enqueue ...
I1104 15:52:32.801646   66853 allocate.go:43] Enter Allocate ...
I1104 15:52:32.801651   66853 allocate.go:90] Added Job <default/qj-1> into Queue <default>
I1104 15:52:32.801656   66853 allocate.go:94] Try to allocate resource to 1 Namespaces
I1104 15:52:32.801662   66853 allocate.go:153] Try to allocate resource to Jobs in Namespace <default> Queue <default>
I1104 15:52:32.801669   66853 allocate.go:178] Try to allocate resource to 0 tasks of Job <default/qj-1>
I1104 15:52:32.801672   66853 statement.go:326] Committing operations ...
I1104 15:52:32.801677   66853 allocate.go:153] Try to allocate resource to Jobs in Namespace <default> Queue <default>
I1104 15:52:32.801681   66853 allocate.go:157] Can not find jobs for queue default.
I1104 15:52:32.801690   66853 allocate.go:253] Leaving Allocate ...
I1104 15:52:32.801694   66853 backfill.go:42] Enter Backfill ...
I1104 15:52:32.801698   66853 backfill.go:91] Leaving Backfill ...
I1104 15:52:32.809411   66853 session.go:154] Close Session 2b2ee98c-ff5e-11e9-99a6-784f43775513
I1104 15:52:32.809422   66853 scheduler.go:87] End scheduling ...
I1104 15:52:37.812398   66853 scheduler.go:72] Start scheduling ...
I1104 15:52:37.816301   66853 cache.go:732] The priority of job <default/qj-1> is </0>
I1104 15:52:37.816323   66853 cache.go:771] There are <1> Jobs, <1> Queues and <1> Nodes in total for scheduling.
I1104 15:52:37.816330   66853 session.go:135] Open Session 2e2c1cc2-ff5e-11e9-99a6-784f43775513 with <1> Job and <1> Queues
I1104 15:52:37.816373   66853 proportion.go:67] The total resource is <cpu 4000.00, memory 4959854592.00, hugepages-2Mi 0.00>
I1104 15:52:37.816386   66853 proportion.go:71] Considering Job <default/qj-1>.
I1104 15:52:37.816391   66853 proportion.go:85] Added Queue <default> attributes.
I1104 15:52:37.816403   66853 proportion.go:127] Considering Queue <default>: weight <1>, total weight <1>.
I1104 15:52:37.816411   66853 proportion.go:144] The attributes of queue <default> in proportion: deserved <cpu 4000.00, memory 4959854592.00, hugepages-2Mi 0.00>, allocate <cpu 0.00, memory 0.00>, request <cpu 0.00, memory 0.00>, share <0.00>
I1104 15:52:37.816427   66853 proportion.go:154] Exiting when remaining is empty:  <cpu 0.00, memory 0.00, hugepages-2Mi 0.00>
I1104 15:52:37.816457   66853 enqueue.go:43] Enter Enqueue ...
I1104 15:52:37.816465   66853 enqueue.go:58] Added Queue <default> for Job <default/qj-1>
I1104 15:52:37.816471   66853 enqueue.go:70] Added Job <default/qj-1> into Queue <default>
I1104 15:52:37.816478   66853 enqueue.go:75] Try to enqueue PodGroup to 1 Queues
I1104 15:52:37.816511   66853 enqueue.go:122] Leaving Enqueue ...
I1104 15:52:37.816526   66853 allocate.go:43] Enter Allocate ...
I1104 15:52:37.816538   66853 allocate.go:90] Added Job <default/qj-1> into Queue <default>
I1104 15:52:37.816550   66853 allocate.go:94] Try to allocate resource to 1 Namespaces
I1104 15:52:37.816562   66853 allocate.go:153] Try to allocate resource to Jobs in Namespace <default> Queue <default>
I1104 15:52:37.816573   66853 allocate.go:178] Try to allocate resource to 0 tasks of Job <default/qj-1>
I1104 15:52:37.816580   66853 statement.go:326] Committing operations ...
I1104 15:52:37.816589   66853 allocate.go:153] Try to allocate resource to Jobs in Namespace <default> Queue <default>
I1104 15:52:37.816595   66853 allocate.go:157] Can not find jobs for queue default.
I1104 15:52:37.816606   66853 allocate.go:253] Leaving Allocate ...
I1104 15:52:37.816611   66853 backfill.go:42] Enter Backfill ...
I1104 15:52:37.816619   66853 backfill.go:91] Leaving Backfill ...
I1104 15:52:37.823294   66853 session.go:154] Close Session 2e2c1cc2-ff5e-11e9-99a6-784f43775513
I1104 15:52:37.823305   66853 scheduler.go:87] End scheduling ...
I1104 15:52:42.823749   66853 scheduler.go:72] Start scheduling ...
I1104 15:52:42.832555   66853 cache.go:732] The priority of job <default/qj-1> is </0>
I1104 15:52:42.832605   66853 cache.go:771] There are <1> Jobs, <1> Queues and <1> Nodes in total for scheduling.
I1104 15:52:42.832615   66853 session.go:135] Open Session 31298720-ff5e-11e9-99a6-784f43775513 with <1> Job and <1> Queues
I1104 15:52:42.832631   66853 proportion.go:67] The total resource is <cpu 4000.00, memory 4959854592.00, hugepages-2Mi 0.00>
I1104 15:52:42.832647   66853 proportion.go:71] Considering Job <default/qj-1>.
I1104 15:52:42.832654   66853 proportion.go:85] Added Queue <default> attributes.
I1104 15:52:42.832663   66853 proportion.go:127] Considering Queue <default>: weight <1>, total weight <1>.
I1104 15:52:42.832674   66853 proportion.go:144] The attributes of queue <default> in proportion: deserved <cpu 4000.00, memory 4959854592.00, hugepages-2Mi 0.00>, allocate <cpu 0.00, memory 0.00>, request <cpu 0.00, memory 0.00>, share <0.00>
I1104 15:52:42.832692   66853 proportion.go:154] Exiting when remaining is empty:  <cpu 0.00, memory 0.00, hugepages-2Mi 0.00>
I1104 15:52:42.832789   66853 enqueue.go:43] Enter Enqueue ...
I1104 15:52:42.832795   66853 enqueue.go:58] Added Queue <default> for Job <default/qj-1>
I1104 15:52:42.832801   66853 enqueue.go:75] Try to enqueue PodGroup to 0 Queues
I1104 15:52:42.832809   66853 enqueue.go:122] Leaving Enqueue ...
I1104 15:52:42.832817   66853 allocate.go:43] Enter Allocate ...
I1104 15:52:42.832822   66853 allocate.go:90] Added Job <default/qj-1> into Queue <default>
I1104 15:52:42.832828   66853 allocate.go:94] Try to allocate resource to 1 Namespaces
I1104 15:52:42.832835   66853 allocate.go:153] Try to allocate resource to Jobs in Namespace <default> Queue <default>
I1104 15:52:42.832844   66853 allocate.go:178] Try to allocate resource to 0 tasks of Job <default/qj-1>
I1104 15:52:42.832849   66853 statement.go:326] Committing operations ...
I1104 15:52:42.832855   66853 allocate.go:153] Try to allocate resource to Jobs in Namespace <default> Queue <default>
I1104 15:52:42.832859   66853 allocate.go:157] Can not find jobs for queue default.
I1104 15:52:42.832868   66853 allocate.go:253] Leaving Allocate ...
I1104 15:52:42.832873   66853 backfill.go:42] Enter Backfill ...
I1104 15:52:42.832877   66853 backfill.go:91] Leaving Backfill ...
I1104 15:52:42.838772   66853 session.go:154] Close Session 31298720-ff5e-11e9-99a6-784f43775513
I1104 15:52:42.838785   66853 scheduler.go:87] End scheduling ...
I1104 15:52:47.841397   66853 scheduler.go:72] Start scheduling ...
I1104 15:52:47.847584   66853 cache.go:732] The priority of job <default/qj-1> is </0>
I1104 15:52:47.847603   66853 cache.go:771] There are <1> Jobs, <1> Queues and <1> Nodes in total for scheduling.
I1104 15:52:47.847608   66853 session.go:135] Open Session 3426c424-ff5e-11e9-99a6-784f43775513 with <1> Job and <1> Queues
I1104 15:52:47.847650   66853 proportion.go:67] The total resource is <cpu 4000.00, memory 4959854592.00, hugepages-2Mi 0.00>
I1104 15:52:47.847661   66853 proportion.go:71] Considering Job <default/qj-1>.
I1104 15:52:47.847666   66853 proportion.go:85] Added Queue <default> attributes.
I1104 15:52:47.847673   66853 proportion.go:127] Considering Queue <default>: weight <1>, total weight <1>.
I1104 15:52:47.847679   66853 proportion.go:144] The attributes of queue <default> in proportion: deserved <cpu 4000.00, memory 4959854592.00, hugepages-2Mi 0.00>, allocate <cpu 0.00, memory 0.00>, request <cpu 0.00, memory 0.00>, share <0.00>
I1104 15:52:47.847690   66853 proportion.go:154] Exiting when remaining is empty:  <cpu 0.00, memory 0.00, hugepages-2Mi 0.00>
I1104 15:52:47.847708   66853 enqueue.go:43] Enter Enqueue ...
I1104 15:52:47.847712   66853 enqueue.go:58] Added Queue <default> for Job <default/qj-1>
I1104 15:52:47.847717   66853 enqueue.go:75] Try to enqueue PodGroup to 0 Queues
I1104 15:52:47.847723   66853 enqueue.go:122] Leaving Enqueue ...
I1104 15:52:47.847736   66853 allocate.go:43] Enter Allocate ...
I1104 15:52:47.847741   66853 allocate.go:90] Added Job <default/qj-1> into Queue <default>
I1104 15:52:47.847746   66853 allocate.go:94] Try to allocate resource to 1 Namespaces
I1104 15:52:47.847753   66853 allocate.go:153] Try to allocate resource to Jobs in Namespace <default> Queue <default>
I1104 15:52:47.847760   66853 allocate.go:178] Try to allocate resource to 0 tasks of Job <default/qj-1>
I1104 15:52:47.847764   66853 statement.go:326] Committing operations ...
I1104 15:52:47.847769   66853 allocate.go:153] Try to allocate resource to Jobs in Namespace <default> Queue <default>
I1104 15:52:47.847773   66853 allocate.go:157] Can not find jobs for queue default.
I1104 15:52:47.847782   66853 allocate.go:253] Leaving Allocate ...
I1104 15:52:47.847786   66853 backfill.go:42] Enter Backfill ...
I1104 15:52:47.847790   66853 backfill.go:91] Leaving Backfill ...
I1104 15:52:47.852434   66853 session.go:154] Close Session 3426c424-ff5e-11e9-99a6-784f43775513
I1104 15:52:47.852444   66853 scheduler.go:87] End scheduling ...
I1104 15:52:52.853922   66853 scheduler.go:72] Start scheduling ...
I1104 15:52:52.862914   66853 cache.go:732] The priority of job <default/qj-1> is </0>
I1104 15:52:52.862936   66853 cache.go:771] There are <1> Jobs, <1> Queues and <1> Nodes in total for scheduling.
I1104 15:52:52.862941   66853 session.go:135] Open Session 37240b6e-ff5e-11e9-99a6-784f43775513 with <1> Job and <1> Queues
I1104 15:52:52.862984   66853 proportion.go:67] The total resource is <cpu 4000.00, memory 4959854592.00, hugepages-2Mi 0.00>
I1104 15:52:52.862995   66853 proportion.go:71] Considering Job <default/qj-1>.
I1104 15:52:52.862999   66853 proportion.go:85] Added Queue <default> attributes.
I1104 15:52:52.863006   66853 proportion.go:127] Considering Queue <default>: weight <1>, total weight <1>.
I1104 15:52:52.863013   66853 proportion.go:144] The attributes of queue <default> in proportion: deserved <cpu 4000.00, memory 4959854592.00, hugepages-2Mi 0.00>, allocate <cpu 0.00, memory 0.00>, request <cpu 0.00, memory 0.00>, share <0.00>
I1104 15:52:52.863024   66853 proportion.go:154] Exiting when remaining is empty:  <cpu 0.00, memory 0.00, hugepages-2Mi 0.00>
I1104 15:52:52.863042   66853 enqueue.go:43] Enter Enqueue ...
I1104 15:52:52.863046   66853 enqueue.go:58] Added Queue <default> for Job <default/qj-1>
I1104 15:52:52.863051   66853 enqueue.go:75] Try to enqueue PodGroup to 0 Queues
I1104 15:52:52.863057   66853 enqueue.go:122] Leaving Enqueue ...
I1104 15:52:52.863063   66853 allocate.go:43] Enter Allocate ...
I1104 15:52:52.863067   66853 allocate.go:90] Added Job <default/qj-1> into Queue <default>
I1104 15:52:52.863072   66853 allocate.go:94] Try to allocate resource to 1 Namespaces
I1104 15:52:52.863079   66853 allocate.go:153] Try to allocate resource to Jobs in Namespace <default> Queue <default>
I1104 15:52:52.863086   66853 allocate.go:178] Try to allocate resource to 0 tasks of Job <default/qj-1>
I1104 15:52:52.863090   66853 statement.go:326] Committing operations ...
I1104 15:52:52.863099   66853 allocate.go:153] Try to allocate resource to Jobs in Namespace <default> Queue <default>
I1104 15:52:52.863104   66853 allocate.go:157] Can not find jobs for queue default.
I1104 15:52:52.863113   66853 allocate.go:253] Leaving Allocate ...
I1104 15:52:52.863117   66853 backfill.go:42] Enter Backfill ...
I1104 15:52:52.863121   66853 backfill.go:91] Leaving Backfill ...
I1104 15:52:52.866813   66853 session.go:154] Close Session 37240b6e-ff5e-11e9-99a6-784f43775513
I1104 15:52:52.866826   66853 scheduler.go:87] End scheduling ...
I1104 15:52:57.869025   66853 scheduler.go:72] Start scheduling ...
I1104 15:52:57.884913   66853 cache.go:732] The priority of job <default/qj-1> is </0>
I1104 15:52:57.884933   66853 cache.go:771] There are <1> Jobs, <1> Queues and <1> Nodes in total for scheduling.
I1104 15:52:57.884937   66853 session.go:135] Open Session 3a2256b8-ff5e-11e9-99a6-784f43775513 with <1> Job and <1> Queues
I1104 15:52:57.884984   66853 proportion.go:67] The total resource is <cpu 4000.00, memory 4959854592.00, hugepages-2Mi 0.00>
I1104 15:52:57.884996   66853 proportion.go:71] Considering Job <default/qj-1>.
I1104 15:52:57.885000   66853 proportion.go:85] Added Queue <default> attributes.
I1104 15:52:57.885007   66853 proportion.go:127] Considering Queue <default>: weight <1>, total weight <1>.
I1104 15:52:57.885016   66853 proportion.go:144] The attributes of queue <default> in proportion: deserved <cpu 4000.00, memory 4959854592.00, hugepages-2Mi 0.00>, allocate <cpu 0.00, memory 0.00>, request <cpu 0.00, memory 0.00>, share <0.00>
I1104 15:52:57.885027   66853 proportion.go:154] Exiting when remaining is empty:  <cpu 0.00, memory 0.00, hugepages-2Mi 0.00>
I1104 15:52:57.885035   66853 enqueue.go:43] Enter Enqueue ...
I1104 15:52:57.885039   66853 enqueue.go:58] Added Queue <default> for Job <default/qj-1>
I1104 15:52:57.885044   66853 enqueue.go:75] Try to enqueue PodGroup to 0 Queues
I1104 15:52:57.885050   66853 enqueue.go:122] Leaving Enqueue ...
I1104 15:52:57.885056   66853 allocate.go:43] Enter Allocate ...
I1104 15:52:57.885061   66853 allocate.go:90] Added Job <default/qj-1> into Queue <default>
I1104 15:52:57.885066   66853 allocate.go:94] Try to allocate resource to 1 Namespaces
I1104 15:52:57.885073   66853 allocate.go:153] Try to allocate resource to Jobs in Namespace <default> Queue <default>
I1104 15:52:57.885080   66853 allocate.go:178] Try to allocate resource to 0 tasks of Job <default/qj-1>
I1104 15:52:57.885084   66853 statement.go:326] Committing operations ...
I1104 15:52:57.885089   66853 allocate.go:153] Try to allocate resource to Jobs in Namespace <default> Queue <default>
I1104 15:52:57.885093   66853 allocate.go:157] Can not find jobs for queue default.
I1104 15:52:57.885103   66853 allocate.go:253] Leaving Allocate ...
I1104 15:52:57.885106   66853 backfill.go:42] Enter Backfill ...
I1104 15:52:57.885110   66853 backfill.go:91] Leaving Backfill ...
I1104 15:52:57.897222   66853 session.go:154] Close Session 3a2256b8-ff5e-11e9-99a6-784f43775513
I1104 15:52:57.897239   66853 scheduler.go:87] End scheduling ...
I1104 15:53:02.899040   66853 scheduler.go:72] Start scheduling ...
I1104 15:53:02.903767   66853 cache.go:732] The priority of job <default/qj-1> is </0>
I1104 15:53:02.903815   66853 cache.go:771] There are <1> Jobs, <1> Queues and <1> Nodes in total for scheduling.
I1104 15:53:02.903820   66853 session.go:135] Open Session 3d20280e-ff5e-11e9-99a6-784f43775513 with <1> Job and <1> Queues
I1104 15:53:02.903832   66853 proportion.go:67] The total resource is <cpu 4000.00, memory 4959854592.00, hugepages-2Mi 0.00>
I1104 15:53:02.903842   66853 proportion.go:71] Considering Job <default/qj-1>.
I1104 15:53:02.903846   66853 proportion.go:85] Added Queue <default> attributes.
I1104 15:53:02.903853   66853 proportion.go:127] Considering Queue <default>: weight <1>, total weight <1>.
I1104 15:53:02.903860   66853 proportion.go:144] The attributes of queue <default> in proportion: deserved <cpu 4000.00, memory 4959854592.00, hugepages-2Mi 0.00>, allocate <cpu 0.00, memory 0.00>, request <cpu 0.00, memory 0.00>, share <0.00>
I1104 15:53:02.903871   66853 proportion.go:154] Exiting when remaining is empty:  <cpu 0.00, memory 0.00, hugepages-2Mi 0.00>
I1104 15:53:02.903917   66853 enqueue.go:43] Enter Enqueue ...
I1104 15:53:02.903921   66853 enqueue.go:58] Added Queue <default> for Job <default/qj-1>
I1104 15:53:02.903926   66853 enqueue.go:75] Try to enqueue PodGroup to 0 Queues
I1104 15:53:02.903933   66853 enqueue.go:122] Leaving Enqueue ...
I1104 15:53:02.903939   66853 allocate.go:43] Enter Allocate ...
I1104 15:53:02.903944   66853 allocate.go:90] Added Job <default/qj-1> into Queue <default>
I1104 15:53:02.903949   66853 allocate.go:94] Try to allocate resource to 1 Namespaces
I1104 15:53:02.903956   66853 allocate.go:153] Try to allocate resource to Jobs in Namespace <default> Queue <default>
I1104 15:53:02.903963   66853 allocate.go:178] Try to allocate resource to 0 tasks of Job <default/qj-1>
I1104 15:53:02.903967   66853 statement.go:326] Committing operations ...
I1104 15:53:02.903972   66853 allocate.go:153] Try to allocate resource to Jobs in Namespace <default> Queue <default>
I1104 15:53:02.903976   66853 allocate.go:157] Can not find jobs for queue default.
I1104 15:53:02.903986   66853 allocate.go:253] Leaving Allocate ...
I1104 15:53:02.903989   66853 backfill.go:42] Enter Backfill ...
I1104 15:53:02.903994   66853 backfill.go:91] Leaving Backfill ...
I1104 15:53:02.908122   66853 session.go:154] Close Session 3d20280e-ff5e-11e9-99a6-784f43775513
I1104 15:53:02.908131   66853 scheduler.go:87] End scheduling ...
I1104 15:53:07.911757   66853 scheduler.go:72] Start scheduling ...
I1104 15:53:07.922586   66853 cache.go:732] The priority of job <default/qj-1> is </0>
I1104 15:53:07.922607   66853 cache.go:771] There are <1> Jobs, <1> Queues and <1> Nodes in total for scheduling.
I1104 15:53:07.922612   66853 session.go:135] Open Session 401df7a2-ff5e-11e9-99a6-784f43775513 with <1> Job and <1> Queues
I1104 15:53:07.922665   66853 proportion.go:67] The total resource is <cpu 4000.00, memory 4959854592.00, hugepages-2Mi 0.00>
I1104 15:53:07.922679   66853 proportion.go:71] Considering Job <default/qj-1>.
I1104 15:53:07.922684   66853 proportion.go:85] Added Queue <default> attributes.
I1104 15:53:07.922692   66853 proportion.go:127] Considering Queue <default>: weight <1>, total weight <1>.
I1104 15:53:07.922700   66853 proportion.go:144] The attributes of queue <default> in proportion: deserved <cpu 4000.00, memory 4959854592.00, hugepages-2Mi 0.00>, allocate <cpu 0.00, memory 0.00>, request <cpu 0.00, memory 0.00>, share <0.00>
I1104 15:53:07.922715   66853 proportion.go:154] Exiting when remaining is empty:  <cpu 0.00, memory 0.00, hugepages-2Mi 0.00>
I1104 15:53:07.922745   66853 enqueue.go:43] Enter Enqueue ...
I1104 15:53:07.922750   66853 enqueue.go:58] Added Queue <default> for Job <default/qj-1>
I1104 15:53:07.922756   66853 enqueue.go:75] Try to enqueue PodGroup to 0 Queues
I1104 15:53:07.922763   66853 enqueue.go:122] Leaving Enqueue ...
I1104 15:53:07.922786   66853 allocate.go:43] Enter Allocate ...
I1104 15:53:07.922793   66853 allocate.go:90] Added Job <default/qj-1> into Queue <default>
I1104 15:53:07.922800   66853 allocate.go:94] Try to allocate resource to 1 Namespaces
I1104 15:53:07.922808   66853 allocate.go:153] Try to allocate resource to Jobs in Namespace <default> Queue <default>
I1104 15:53:07.922816   66853 allocate.go:178] Try to allocate resource to 0 tasks of Job <default/qj-1>
I1104 15:53:07.922820   66853 statement.go:326] Committing operations ...
I1104 15:53:07.922827   66853 allocate.go:153] Try to allocate resource to Jobs in Namespace <default> Queue <default>
I1104 15:53:07.922832   66853 allocate.go:157] Can not find jobs for queue default.
I1104 15:53:07.922843   66853 allocate.go:253] Leaving Allocate ...
I1104 15:53:07.922847   66853 backfill.go:42] Enter Backfill ...
I1104 15:53:07.922852   66853 backfill.go:91] Leaving Backfill ...
I1104 15:53:07.927037   66853 session.go:154] Close Session 401df7a2-ff5e-11e9-99a6-784f43775513
I1104 15:53:07.927047   66853 scheduler.go:87] End scheduling ...
I1104 15:53:12.928231   66853 scheduler.go:72] Start scheduling ...
I1104 15:53:12.940398   66853 cache.go:732] The priority of job <default/qj-1> is </0>
I1104 15:53:12.940416   66853 cache.go:771] There are <1> Jobs, <1> Queues and <1> Nodes in total for scheduling.
I1104 15:53:12.940421   66853 session.go:135] Open Session 431ba03a-ff5e-11e9-99a6-784f43775513 with <1> Job and <1> Queues
I1104 15:53:12.940473   66853 proportion.go:67] The total resource is <cpu 4000.00, memory 4959854592.00, hugepages-2Mi 0.00>
I1104 15:53:12.940484   66853 proportion.go:71] Considering Job <default/qj-1>.
I1104 15:53:12.940489   66853 proportion.go:85] Added Queue <default> attributes.
I1104 15:53:12.940496   66853 proportion.go:127] Considering Queue <default>: weight <1>, total weight <1>.
I1104 15:53:12.940502   66853 proportion.go:144] The attributes of queue <default> in proportion: deserved <cpu 4000.00, memory 4959854592.00, hugepages-2Mi 0.00>, allocate <cpu 0.00, memory 0.00>, request <cpu 0.00, memory 0.00>, share <0.00>
I1104 15:53:12.940513   66853 proportion.go:154] Exiting when remaining is empty:  <cpu 0.00, memory 0.00, hugepages-2Mi 0.00>
I1104 15:53:12.940534   66853 enqueue.go:43] Enter Enqueue ...
I1104 15:53:12.940538   66853 enqueue.go:58] Added Queue <default> for Job <default/qj-1>
I1104 15:53:12.940543   66853 enqueue.go:75] Try to enqueue PodGroup to 0 Queues
I1104 15:53:12.940549   66853 enqueue.go:122] Leaving Enqueue ...
I1104 15:53:12.940554   66853 allocate.go:43] Enter Allocate ...
I1104 15:53:12.940559   66853 allocate.go:90] Added Job <default/qj-1> into Queue <default>
I1104 15:53:12.940564   66853 allocate.go:94] Try to allocate resource to 1 Namespaces
I1104 15:53:12.940575   66853 allocate.go:153] Try to allocate resource to Jobs in Namespace <default> Queue <default>
I1104 15:53:12.940582   66853 allocate.go:178] Try to allocate resource to 0 tasks of Job <default/qj-1>
I1104 15:53:12.940586   66853 statement.go:326] Committing operations ...
I1104 15:53:12.940592   66853 allocate.go:153] Try to allocate resource to Jobs in Namespace <default> Queue <default>
I1104 15:53:12.940596   66853 allocate.go:157] Can not find jobs for queue default.
I1104 15:53:12.940605   66853 allocate.go:253] Leaving Allocate ...
I1104 15:53:12.940609   66853 backfill.go:42] Enter Backfill ...
I1104 15:53:12.940613   66853 backfill.go:91] Leaving Backfill ...
I1104 15:53:12.944337   66853 session.go:154] Close Session 431ba03a-ff5e-11e9-99a6-784f43775513
I1104 15:53:12.944348   66853 scheduler.go:87] End scheduling ...
I1104 15:53:17.945374   66853 scheduler.go:72] Start scheduling ...
I1104 15:53:17.945630   66853 cache.go:732] The priority of job <default/qj-1> is </0>
I1104 15:53:17.945659   66853 cache.go:771] There are <1> Jobs, <1> Queues and <1> Nodes in total for scheduling.
I1104 15:53:17.945666   66853 session.go:135] Open Session 46175c0c-ff5e-11e9-99a6-784f43775513 with <1> Job and <1> Queues
I1104 15:53:17.945718   66853 proportion.go:67] The total resource is <cpu 4000.00, memory 4959854592.00, hugepages-2Mi 0.00>
I1104 15:53:17.945735   66853 proportion.go:71] Considering Job <default/qj-1>.
I1104 15:53:17.945741   66853 proportion.go:85] Added Queue <default> attributes.
I1104 15:53:17.945751   66853 proportion.go:127] Considering Queue <default>: weight <1>, total weight <1>.
I1104 15:53:17.945761   66853 proportion.go:144] The attributes of queue <default> in proportion: deserved <cpu 4000.00, memory 4959854592.00, hugepages-2Mi 0.00>, allocate <cpu 0.00, memory 0.00>, request <cpu 0.00, memory 0.00>, share <0.00>
I1104 15:53:17.945779   66853 proportion.go:154] Exiting when remaining is empty:  <cpu 0.00, memory 0.00, hugepages-2Mi 0.00>
I1104 15:53:17.945810   66853 enqueue.go:43] Enter Enqueue ...
I1104 15:53:17.945816   66853 enqueue.go:58] Added Queue <default> for Job <default/qj-1>
I1104 15:53:17.945823   66853 enqueue.go:75] Try to enqueue PodGroup to 0 Queues
I1104 15:53:17.945832   66853 enqueue.go:122] Leaving Enqueue ...
I1104 15:53:17.945840   66853 allocate.go:43] Enter Allocate ...
I1104 15:53:17.945846   66853 allocate.go:90] Added Job <default/qj-1> into Queue <default>
I1104 15:53:17.945855   66853 allocate.go:94] Try to allocate resource to 1 Namespaces
I1104 15:53:17.945865   66853 allocate.go:153] Try to allocate resource to Jobs in Namespace <default> Queue <default>
I1104 15:53:17.945875   66853 allocate.go:178] Try to allocate resource to 0 tasks of Job <default/qj-1>
I1104 15:53:17.945880   66853 statement.go:326] Committing operations ...
I1104 15:53:17.945888   66853 allocate.go:153] Try to allocate resource to Jobs in Namespace <default> Queue <default>
I1104 15:53:17.945894   66853 allocate.go:157] Can not find jobs for queue default.
I1104 15:53:17.945908   66853 allocate.go:253] Leaving Allocate ...
I1104 15:53:17.945913   66853 backfill.go:42] Enter Backfill ...
I1104 15:53:17.945919   66853 backfill.go:91] Leaving Backfill ...
I1104 15:53:17.950292   66853 session.go:154] Close Session 46175c0c-ff5e-11e9-99a6-784f43775513
I1104 15:53:17.950303   66853 scheduler.go:87] End scheduling ...
I1104 15:53:22.952439   66853 scheduler.go:72] Start scheduling ...
I1104 15:53:22.964225   66853 cache.go:732] The priority of job <default/qj-1> is </0>
I1104 15:53:22.964246   66853 cache.go:771] There are <1> Jobs, <1> Queues and <1> Nodes in total for scheduling.
I1104 15:53:22.964251   66853 session.go:135] Open Session 491523bc-ff5e-11e9-99a6-784f43775513 with <1> Job and <1> Queues
I1104 15:53:22.964299   66853 proportion.go:67] The total resource is <cpu 4000.00, memory 4959854592.00, hugepages-2Mi 0.00>
I1104 15:53:22.964317   66853 proportion.go:71] Considering Job <default/qj-1>.
I1104 15:53:22.964322   66853 proportion.go:85] Added Queue <default> attributes.
I1104 15:53:22.964330   66853 proportion.go:127] Considering Queue <default>: weight <1>, total weight <1>.
I1104 15:53:22.964338   66853 proportion.go:144] The attributes of queue <default> in proportion: deserved <cpu 4000.00, memory 4959854592.00, hugepages-2Mi 0.00>, allocate <cpu 0.00, memory 0.00>, request <cpu 0.00, memory 0.00>, share <0.00>
I1104 15:53:22.964352   66853 proportion.go:154] Exiting when remaining is empty:  <cpu 0.00, memory 0.00, hugepages-2Mi 0.00>
I1104 15:53:22.964375   66853 enqueue.go:43] Enter Enqueue ...
I1104 15:53:22.964381   66853 enqueue.go:58] Added Queue <default> for Job <default/qj-1>
I1104 15:53:22.964387   66853 enqueue.go:75] Try to enqueue PodGroup to 0 Queues
I1104 15:53:22.964395   66853 enqueue.go:122] Leaving Enqueue ...
I1104 15:53:22.964402   66853 allocate.go:43] Enter Allocate ...
I1104 15:53:22.964407   66853 allocate.go:90] Added Job <default/qj-1> into Queue <default>
I1104 15:53:22.964414   66853 allocate.go:94] Try to allocate resource to 1 Namespaces
I1104 15:53:22.964422   66853 allocate.go:153] Try to allocate resource to Jobs in Namespace <default> Queue <default>
I1104 15:53:22.964430   66853 allocate.go:178] Try to allocate resource to 0 tasks of Job <default/qj-1>
I1104 15:53:22.964435   66853 statement.go:326] Committing operations ...
I1104 15:53:22.964442   66853 allocate.go:153] Try to allocate resource to Jobs in Namespace <default> Queue <default>
I1104 15:53:22.964447   66853 allocate.go:157] Can not find jobs for queue default.
I1104 15:53:22.964459   66853 allocate.go:253] Leaving Allocate ...
I1104 15:53:22.964464   66853 backfill.go:42] Enter Backfill ...
I1104 15:53:22.964470   66853 backfill.go:91] Leaving Backfill ...
I1104 15:53:22.968646   66853 session.go:154] Close Session 491523bc-ff5e-11e9-99a6-784f43775513
I1104 15:53:22.968656   66853 scheduler.go:87] End scheduling ...
I1104 15:53:27.969288   66853 scheduler.go:72] Start scheduling ...
I1104 15:53:27.981967   66853 cache.go:732] The priority of job <default/qj-1> is </0>
I1104 15:53:27.981987   66853 cache.go:771] There are <1> Jobs, <1> Queues and <1> Nodes in total for scheduling.
I1104 15:53:27.981992   66853 session.go:135] Open Session 4c12c948-ff5e-11e9-99a6-784f43775513 with <1> Job and <1> Queues
I1104 15:53:27.982032   66853 proportion.go:67] The total resource is <cpu 4000.00, memory 4959854592.00, hugepages-2Mi 0.00>
I1104 15:53:27.982044   66853 proportion.go:71] Considering Job <default/qj-1>.
I1104 15:53:27.982049   66853 proportion.go:85] Added Queue <default> attributes.
I1104 15:53:27.982065   66853 proportion.go:127] Considering Queue <default>: weight <1>, total weight <1>.
I1104 15:53:27.982073   66853 proportion.go:144] The attributes of queue <default> in proportion: deserved <cpu 4000.00, memory 4959854592.00, hugepages-2Mi 0.00>, allocate <cpu 0.00, memory 0.00>, request <cpu 0.00, memory 0.00>, share <0.00>
I1104 15:53:27.982085   66853 proportion.go:154] Exiting when remaining is empty:  <cpu 0.00, memory 0.00, hugepages-2Mi 0.00>
I1104 15:53:27.982102   66853 enqueue.go:43] Enter Enqueue ...
I1104 15:53:27.982106   66853 enqueue.go:58] Added Queue <default> for Job <default/qj-1>
I1104 15:53:27.982111   66853 enqueue.go:75] Try to enqueue PodGroup to 0 Queues
I1104 15:53:27.982117   66853 enqueue.go:122] Leaving Enqueue ...
I1104 15:53:27.982123   66853 allocate.go:43] Enter Allocate ...
I1104 15:53:27.982127   66853 allocate.go:90] Added Job <default/qj-1> into Queue <default>
I1104 15:53:27.982133   66853 allocate.go:94] Try to allocate resource to 1 Namespaces
I1104 15:53:27.982139   66853 allocate.go:153] Try to allocate resource to Jobs in Namespace <default> Queue <default>
I1104 15:53:27.982146   66853 allocate.go:178] Try to allocate resource to 0 tasks of Job <default/qj-1>
I1104 15:53:27.982150   66853 statement.go:326] Committing operations ...
I1104 15:53:27.982155   66853 allocate.go:153] Try to allocate resource to Jobs in Namespace <default> Queue <default>
I1104 15:53:27.982159   66853 allocate.go:157] Can not find jobs for queue default.
I1104 15:53:27.982169   66853 allocate.go:253] Leaving Allocate ...
I1104 15:53:27.982173   66853 backfill.go:42] Enter Backfill ...
I1104 15:53:27.982177   66853 backfill.go:91] Leaving Backfill ...
I1104 15:53:27.986571   66853 session.go:154] Close Session 4c12c948-ff5e-11e9-99a6-784f43775513
I1104 15:53:27.986582   66853 scheduler.go:87] End scheduling ...
I1104 15:53:32.986738   66853 scheduler.go:72] Start scheduling ...
I1104 15:53:32.997925   66853 cache.go:732] The priority of job <default/qj-1> is </0>
I1104 15:53:32.997941   66853 cache.go:771] There are <1> Jobs, <1> Queues and <1> Nodes in total for scheduling.
I1104 15:53:32.997945   66853 session.go:135] Open Session 4f102960-ff5e-11e9-99a6-784f43775513 with <1> Job and <1> Queues
I1104 15:53:32.997993   66853 proportion.go:67] The total resource is <cpu 4000.00, memory 4959854592.00, hugepages-2Mi 0.00>
I1104 15:53:32.998006   66853 proportion.go:71] Considering Job <default/qj-1>.
I1104 15:53:32.998010   66853 proportion.go:85] Added Queue <default> attributes.
I1104 15:53:32.998017   66853 proportion.go:127] Considering Queue <default>: weight <1>, total weight <1>.
I1104 15:53:32.998023   66853 proportion.go:144] The attributes of queue <default> in proportion: deserved <cpu 4000.00, memory 4959854592.00, hugepages-2Mi 0.00>, allocate <cpu 0.00, memory 0.00>, request <cpu 0.00, memory 0.00>, share <0.00>
I1104 15:53:32.998035   66853 proportion.go:154] Exiting when remaining is empty:  <cpu 0.00, memory 0.00, hugepages-2Mi 0.00>
I1104 15:53:32.998052   66853 enqueue.go:43] Enter Enqueue ...
I1104 15:53:32.998055   66853 enqueue.go:58] Added Queue <default> for Job <default/qj-1>
I1104 15:53:32.998060   66853 enqueue.go:75] Try to enqueue PodGroup to 0 Queues
I1104 15:53:32.998067   66853 enqueue.go:122] Leaving Enqueue ...
I1104 15:53:32.998072   66853 allocate.go:43] Enter Allocate ...
I1104 15:53:32.998077   66853 allocate.go:90] Added Job <default/qj-1> into Queue <default>
I1104 15:53:32.998082   66853 allocate.go:94] Try to allocate resource to 1 Namespaces
I1104 15:53:32.998088   66853 allocate.go:153] Try to allocate resource to Jobs in Namespace <default> Queue <default>
I1104 15:53:32.998096   66853 allocate.go:178] Try to allocate resource to 0 tasks of Job <default/qj-1>
I1104 15:53:32.998100   66853 statement.go:326] Committing operations ...
I1104 15:53:32.998105   66853 allocate.go:153] Try to allocate resource to Jobs in Namespace <default> Queue <default>
I1104 15:53:32.998109   66853 allocate.go:157] Can not find jobs for queue default.
I1104 15:53:32.998122   66853 allocate.go:253] Leaving Allocate ...
I1104 15:53:32.998126   66853 backfill.go:42] Enter Backfill ...
I1104 15:53:32.998130   66853 backfill.go:91] Leaving Backfill ...
I1104 15:53:33.003133   66853 session.go:154] Close Session 4f102960-ff5e-11e9-99a6-784f43775513
I1104 15:53:33.003144   66853 scheduler.go:87] End scheduling ...
I1104 15:53:38.003320   66853 scheduler.go:72] Start scheduling ...
I1104 15:53:38.017142   66853 cache.go:732] The priority of job <default/qj-1> is </0>
I1104 15:53:38.017206   66853 cache.go:771] There are <1> Jobs, <1> Queues and <1> Nodes in total for scheduling.
I1104 15:53:38.017219   66853 session.go:135] Open Session 520e04fc-ff5e-11e9-99a6-784f43775513 with <1> Job and <1> Queues
I1104 15:53:38.017292   66853 proportion.go:67] The total resource is <cpu 4000.00, memory 4959854592.00, hugepages-2Mi 0.00>
I1104 15:53:38.017312   66853 proportion.go:71] Considering Job <default/qj-1>.
I1104 15:53:38.017319   66853 proportion.go:85] Added Queue <default> attributes.
I1104 15:53:38.017335   66853 proportion.go:127] Considering Queue <default>: weight <1>, total weight <1>.
I1104 15:53:38.017354   66853 proportion.go:144] The attributes of queue <default> in proportion: deserved <cpu 4000.00, memory 4959854592.00, hugepages-2Mi 0.00>, allocate <cpu 0.00, memory 0.00>, request <cpu 0.00, memory 0.00>, share <0.00>
I1104 15:53:38.017386   66853 proportion.go:154] Exiting when remaining is empty:  <cpu 0.00, memory 0.00, hugepages-2Mi 0.00>
I1104 15:53:38.017441   66853 enqueue.go:43] Enter Enqueue ...
I1104 15:53:38.017451   66853 enqueue.go:58] Added Queue <default> for Job <default/qj-1>
I1104 15:53:38.017460   66853 enqueue.go:75] Try to enqueue PodGroup to 0 Queues
I1104 15:53:38.017471   66853 enqueue.go:122] Leaving Enqueue ...
I1104 15:53:38.017490   66853 allocate.go:43] Enter Allocate ...
I1104 15:53:38.017500   66853 allocate.go:90] Added Job <default/qj-1> into Queue <default>
I1104 15:53:38.017510   66853 allocate.go:94] Try to allocate resource to 1 Namespaces
I1104 15:53:38.017520   66853 allocate.go:153] Try to allocate resource to Jobs in Namespace <default> Queue <default>
I1104 15:53:38.017531   66853 allocate.go:178] Try to allocate resource to 0 tasks of Job <default/qj-1>
I1104 15:53:38.017540   66853 statement.go:326] Committing operations ...
I1104 15:53:38.017549   66853 allocate.go:153] Try to allocate resource to Jobs in Namespace <default> Queue <default>
I1104 15:53:38.017556   66853 allocate.go:157] Can not find jobs for queue default.
I1104 15:53:38.017571   66853 allocate.go:253] Leaving Allocate ...
I1104 15:53:38.017577   66853 backfill.go:42] Enter Backfill ...
I1104 15:53:38.017584   66853 backfill.go:91] Leaving Backfill ...
I1104 15:53:38.022177   66853 session.go:154] Close Session 520e04fc-ff5e-11e9-99a6-784f43775513
I1104 15:53:38.022188   66853 scheduler.go:87] End scheduling ...
I1104 15:53:43.022347   66853 scheduler.go:72] Start scheduling ...
I1104 15:53:43.036787   66853 cache.go:732] The priority of job <default/qj-1> is </0>
I1104 15:53:43.036814   66853 cache.go:771] There are <1> Jobs, <1> Queues and <1> Nodes in total for scheduling.
I1104 15:53:43.036821   66853 session.go:135] Open Session 550bf81c-ff5e-11e9-99a6-784f43775513 with <1> Job and <1> Queues
I1104 15:53:43.036861   66853 proportion.go:67] The total resource is <cpu 4000.00, memory 4959854592.00, hugepages-2Mi 0.00>
I1104 15:53:43.036874   66853 proportion.go:71] Considering Job <default/qj-1>.
I1104 15:53:43.036879   66853 proportion.go:85] Added Queue <default> attributes.
I1104 15:53:43.036886   66853 proportion.go:127] Considering Queue <default>: weight <1>, total weight <1>.
I1104 15:53:43.036892   66853 proportion.go:144] The attributes of queue <default> in proportion: deserved <cpu 4000.00, memory 4959854592.00, hugepages-2Mi 0.00>, allocate <cpu 0.00, memory 0.00>, request <cpu 0.00, memory 0.00>, share <0.00>
I1104 15:53:43.036903   66853 proportion.go:154] Exiting when remaining is empty:  <cpu 0.00, memory 0.00, hugepages-2Mi 0.00>
I1104 15:53:43.036920   66853 enqueue.go:43] Enter Enqueue ...
I1104 15:53:43.036924   66853 enqueue.go:58] Added Queue <default> for Job <default/qj-1>
I1104 15:53:43.036929   66853 enqueue.go:75] Try to enqueue PodGroup to 0 Queues
I1104 15:53:43.036935   66853 enqueue.go:122] Leaving Enqueue ...
I1104 15:53:43.036941   66853 allocate.go:43] Enter Allocate ...
I1104 15:53:43.036945   66853 allocate.go:90] Added Job <default/qj-1> into Queue <default>
I1104 15:53:43.036952   66853 allocate.go:94] Try to allocate resource to 1 Namespaces
I1104 15:53:43.036962   66853 allocate.go:153] Try to allocate resource to Jobs in Namespace <default> Queue <default>
I1104 15:53:43.036973   66853 allocate.go:178] Try to allocate resource to 0 tasks of Job <default/qj-1>
I1104 15:53:43.036980   66853 statement.go:326] Committing operations ...
I1104 15:53:43.036988   66853 allocate.go:153] Try to allocate resource to Jobs in Namespace <default> Queue <default>
I1104 15:53:43.036996   66853 allocate.go:157] Can not find jobs for queue default.
I1104 15:53:43.037006   66853 allocate.go:253] Leaving Allocate ...
I1104 15:53:43.037010   66853 backfill.go:42] Enter Backfill ...
I1104 15:53:43.037014   66853 backfill.go:91] Leaving Backfill ...
I1104 15:53:43.044435   66853 session.go:154] Close Session 550bf81c-ff5e-11e9-99a6-784f43775513
I1104 15:53:43.044445   66853 scheduler.go:87] End scheduling ...
I1104 15:53:48.044699   66853 scheduler.go:72] Start scheduling ...
I1104 15:53:48.052456   66853 cache.go:732] The priority of job <default/qj-1> is </0>
I1104 15:53:48.052475   66853 cache.go:771] There are <1> Jobs, <1> Queues and <1> Nodes in total for scheduling.
I1104 15:53:48.052480   66853 session.go:135] Open Session 58094cfe-ff5e-11e9-99a6-784f43775513 with <1> Job and <1> Queues
I1104 15:53:48.052492   66853 proportion.go:67] The total resource is <cpu 4000.00, memory 4959854592.00, hugepages-2Mi 0.00>
I1104 15:53:48.052505   66853 proportion.go:71] Considering Job <default/qj-1>.
I1104 15:53:48.052509   66853 proportion.go:85] Added Queue <default> attributes.
I1104 15:53:48.052516   66853 proportion.go:127] Considering Queue <default>: weight <1>, total weight <1>.
I1104 15:53:48.052523   66853 proportion.go:144] The attributes of queue <default> in proportion: deserved <cpu 4000.00, memory 4959854592.00, hugepages-2Mi 0.00>, allocate <cpu 0.00, memory 0.00>, request <cpu 0.00, memory 0.00>, share <0.00>
I1104 15:53:48.052535   66853 proportion.go:154] Exiting when remaining is empty:  <cpu 0.00, memory 0.00, hugepages-2Mi 0.00>
I1104 15:53:48.052579   66853 enqueue.go:43] Enter Enqueue ...
I1104 15:53:48.052583   66853 enqueue.go:58] Added Queue <default> for Job <default/qj-1>
I1104 15:53:48.052588   66853 enqueue.go:75] Try to enqueue PodGroup to 0 Queues
I1104 15:53:48.052594   66853 enqueue.go:122] Leaving Enqueue ...
I1104 15:53:48.052599   66853 allocate.go:43] Enter Allocate ...
I1104 15:53:48.052604   66853 allocate.go:90] Added Job <default/qj-1> into Queue <default>
I1104 15:53:48.052610   66853 allocate.go:94] Try to allocate resource to 1 Namespaces
I1104 15:53:48.052617   66853 allocate.go:153] Try to allocate resource to Jobs in Namespace <default> Queue <default>
I1104 15:53:48.052624   66853 allocate.go:178] Try to allocate resource to 0 tasks of Job <default/qj-1>
I1104 15:53:48.052628   66853 statement.go:326] Committing operations ...
I1104 15:53:48.052633   66853 allocate.go:153] Try to allocate resource to Jobs in Namespace <default> Queue <default>
I1104 15:53:48.052638   66853 allocate.go:157] Can not find jobs for queue default.
I1104 15:53:48.052647   66853 allocate.go:253] Leaving Allocate ...
I1104 15:53:48.052650   66853 backfill.go:42] Enter Backfill ...
I1104 15:53:48.052655   66853 backfill.go:91] Leaving Backfill ...
I1104 15:53:48.056554   66853 session.go:154] Close Session 58094cfe-ff5e-11e9-99a6-784f43775513
I1104 15:53:48.056567   66853 scheduler.go:87] End scheduling ...
I1104 15:53:53.061610   66853 scheduler.go:72] Start scheduling ...
I1104 15:53:53.071054   66853 cache.go:732] The priority of job <default/qj-1> is </0>
I1104 15:53:53.071072   66853 cache.go:771] There are <1> Jobs, <1> Queues and <1> Nodes in total for scheduling.
I1104 15:53:53.071078   66853 session.go:135] Open Session 5b0713e6-ff5e-11e9-99a6-784f43775513 with <1> Job and <1> Queues
I1104 15:53:53.071115   66853 proportion.go:67] The total resource is <cpu 4000.00, memory 4959854592.00, hugepages-2Mi 0.00>
I1104 15:53:53.071127   66853 proportion.go:71] Considering Job <default/qj-1>.
I1104 15:53:53.071132   66853 proportion.go:85] Added Queue <default> attributes.
I1104 15:53:53.071139   66853 proportion.go:127] Considering Queue <default>: weight <1>, total weight <1>.
I1104 15:53:53.071145   66853 proportion.go:144] The attributes of queue <default> in proportion: deserved <cpu 4000.00, memory 4959854592.00, hugepages-2Mi 0.00>, allocate <cpu 0.00, memory 0.00>, request <cpu 0.00, memory 0.00>, share <0.00>
I1104 15:53:53.071158   66853 proportion.go:154] Exiting when remaining is empty:  <cpu 0.00, memory 0.00, hugepages-2Mi 0.00>
I1104 15:53:53.071175   66853 enqueue.go:43] Enter Enqueue ...
I1104 15:53:53.071179   66853 enqueue.go:58] Added Queue <default> for Job <default/qj-1>
I1104 15:53:53.071184   66853 enqueue.go:75] Try to enqueue PodGroup to 0 Queues
I1104 15:53:53.071191   66853 enqueue.go:122] Leaving Enqueue ...
I1104 15:53:53.071196   66853 allocate.go:43] Enter Allocate ...
I1104 15:53:53.071201   66853 allocate.go:90] Added Job <default/qj-1> into Queue <default>
I1104 15:53:53.071206   66853 allocate.go:94] Try to allocate resource to 1 Namespaces
I1104 15:53:53.071213   66853 allocate.go:153] Try to allocate resource to Jobs in Namespace <default> Queue <default>
I1104 15:53:53.071220   66853 allocate.go:178] Try to allocate resource to 0 tasks of Job <default/qj-1>
I1104 15:53:53.071224   66853 statement.go:326] Committing operations ...
I1104 15:53:53.071229   66853 allocate.go:153] Try to allocate resource to Jobs in Namespace <default> Queue <default>
I1104 15:53:53.071233   66853 allocate.go:157] Can not find jobs for queue default.
I1104 15:53:53.071242   66853 allocate.go:253] Leaving Allocate ...
I1104 15:53:53.071246   66853 backfill.go:42] Enter Backfill ...
I1104 15:53:53.071250   66853 backfill.go:91] Leaving Backfill ...
I1104 15:53:53.075397   66853 session.go:154] Close Session 5b0713e6-ff5e-11e9-99a6-784f43775513
I1104 15:53:53.075407   66853 scheduler.go:87] End scheduling ...
I1104 15:53:58.079678   66853 scheduler.go:72] Start scheduling ...
I1104 15:53:58.092588   66853 cache.go:732] The priority of job <default/qj-1> is </0>
I1104 15:53:58.092627   66853 cache.go:771] There are <1> Jobs, <1> Queues and <1> Nodes in total for scheduling.
I1104 15:53:58.092635   66853 session.go:135] Open Session 5e054ce8-ff5e-11e9-99a6-784f43775513 with <1> Job and <1> Queues
I1104 15:53:58.092699   66853 proportion.go:67] The total resource is <cpu 4000.00, memory 4959854592.00, hugepages-2Mi 0.00>
I1104 15:53:58.092715   66853 proportion.go:71] Considering Job <default/qj-1>.
I1104 15:53:58.092721   66853 proportion.go:85] Added Queue <default> attributes.
I1104 15:53:58.092728   66853 proportion.go:127] Considering Queue <default>: weight <1>, total weight <1>.
I1104 15:53:58.092739   66853 proportion.go:144] The attributes of queue <default> in proportion: deserved <cpu 4000.00, memory 4959854592.00, hugepages-2Mi 0.00>, allocate <cpu 0.00, memory 0.00>, request <cpu 0.00, memory 0.00>, share <0.00>
I1104 15:53:58.092756   66853 proportion.go:154] Exiting when remaining is empty:  <cpu 0.00, memory 0.00, hugepages-2Mi 0.00>
I1104 15:53:58.092784   66853 enqueue.go:43] Enter Enqueue ...
I1104 15:53:58.092788   66853 enqueue.go:58] Added Queue <default> for Job <default/qj-1>
I1104 15:53:58.092794   66853 enqueue.go:75] Try to enqueue PodGroup to 0 Queues
I1104 15:53:58.092804   66853 enqueue.go:122] Leaving Enqueue ...
I1104 15:53:58.092812   66853 allocate.go:43] Enter Allocate ...
I1104 15:53:58.092825   66853 allocate.go:90] Added Job <default/qj-1> into Queue <default>
I1104 15:53:58.092842   66853 allocate.go:94] Try to allocate resource to 1 Namespaces
I1104 15:53:58.092855   66853 allocate.go:153] Try to allocate resource to Jobs in Namespace <default> Queue <default>
I1104 15:53:58.092865   66853 allocate.go:178] Try to allocate resource to 0 tasks of Job <default/qj-1>
I1104 15:53:58.092871   66853 statement.go:326] Committing operations ...
I1104 15:53:58.092881   66853 allocate.go:153] Try to allocate resource to Jobs in Namespace <default> Queue <default>
I1104 15:53:58.092888   66853 allocate.go:157] Can not find jobs for queue default.
I1104 15:53:58.092907   66853 allocate.go:253] Leaving Allocate ...
I1104 15:53:58.092914   66853 backfill.go:42] Enter Backfill ...
I1104 15:53:58.092920   66853 backfill.go:91] Leaving Backfill ...
I1104 15:53:58.096933   66853 session.go:154] Close Session 5e054ce8-ff5e-11e9-99a6-784f43775513
I1104 15:53:58.096943   66853 scheduler.go:87] End scheduling ...
I1104 15:54:03.101460   66853 scheduler.go:72] Start scheduling ...
I1104 15:54:03.108672   66853 cache.go:732] The priority of job <default/qj-1> is </0>
I1104 15:54:03.108703   66853 cache.go:771] There are <1> Jobs, <1> Queues and <1> Nodes in total for scheduling.
I1104 15:54:03.108711   66853 session.go:135] Open Session 6102b156-ff5e-11e9-99a6-784f43775513 with <1> Job and <1> Queues
I1104 15:54:03.108752   66853 proportion.go:67] The total resource is <cpu 4000.00, memory 4959854592.00, hugepages-2Mi 0.00>
I1104 15:54:03.108769   66853 proportion.go:71] Considering Job <default/qj-1>.
I1104 15:54:03.108776   66853 proportion.go:85] Added Queue <default> attributes.
I1104 15:54:03.108786   66853 proportion.go:127] Considering Queue <default>: weight <1>, total weight <1>.
I1104 15:54:03.108796   66853 proportion.go:144] The attributes of queue <default> in proportion: deserved <cpu 4000.00, memory 4959854592.00, hugepages-2Mi 0.00>, allocate <cpu 0.00, memory 0.00>, request <cpu 0.00, memory 0.00>, share <0.00>
I1104 15:54:03.108814   66853 proportion.go:154] Exiting when remaining is empty:  <cpu 0.00, memory 0.00, hugepages-2Mi 0.00>
I1104 15:54:03.108852   66853 enqueue.go:43] Enter Enqueue ...
I1104 15:54:03.108858   66853 enqueue.go:58] Added Queue <default> for Job <default/qj-1>
I1104 15:54:03.108865   66853 enqueue.go:75] Try to enqueue PodGroup to 0 Queues
I1104 15:54:03.108874   66853 enqueue.go:122] Leaving Enqueue ...
I1104 15:54:03.108882   66853 allocate.go:43] Enter Allocate ...
I1104 15:54:03.108888   66853 allocate.go:90] Added Job <default/qj-1> into Queue <default>
I1104 15:54:03.108896   66853 allocate.go:94] Try to allocate resource to 1 Namespaces
I1104 15:54:03.108906   66853 allocate.go:153] Try to allocate resource to Jobs in Namespace <default> Queue <default>
I1104 15:54:03.108917   66853 allocate.go:178] Try to allocate resource to 0 tasks of Job <default/qj-1>
I1104 15:54:03.108922   66853 statement.go:326] Committing operations ...
I1104 15:54:03.108930   66853 allocate.go:153] Try to allocate resource to Jobs in Namespace <default> Queue <default>
I1104 15:54:03.108936   66853 allocate.go:157] Can not find jobs for queue default.
I1104 15:54:03.108950   66853 allocate.go:253] Leaving Allocate ...
I1104 15:54:03.108956   66853 backfill.go:42] Enter Backfill ...
I1104 15:54:03.108962   66853 backfill.go:91] Leaving Backfill ...
I1104 15:54:03.112959   66853 session.go:154] Close Session 6102b156-ff5e-11e9-99a6-784f43775513
I1104 15:54:03.112969   66853 scheduler.go:87] End scheduling ...
I1104 15:54:08.114310   66853 scheduler.go:72] Start scheduling ...
I1104 15:54:08.118656   66853 cache.go:732] The priority of job <default/qj-1> is </0>
I1104 15:54:08.118689   66853 cache.go:771] There are <1> Jobs, <1> Queues and <1> Nodes in total for scheduling.
I1104 15:54:08.118698   66853 session.go:135] Open Session 63ff27ae-ff5e-11e9-99a6-784f43775513 with <1> Job and <1> Queues
I1104 15:54:08.118776   66853 proportion.go:67] The total resource is <cpu 4000.00, memory 4959854592.00, hugepages-2Mi 0.00>
I1104 15:54:08.118792   66853 proportion.go:71] Considering Job <default/qj-1>.
I1104 15:54:08.118799   66853 proportion.go:85] Added Queue <default> attributes.
I1104 15:54:08.118808   66853 proportion.go:127] Considering Queue <default>: weight <1>, total weight <1>.
I1104 15:54:08.118818   66853 proportion.go:144] The attributes of queue <default> in proportion: deserved <cpu 4000.00, memory 4959854592.00, hugepages-2Mi 0.00>, allocate <cpu 0.00, memory 0.00>, request <cpu 0.00, memory 0.00>, share <0.00>
I1104 15:54:08.118836   66853 proportion.go:154] Exiting when remaining is empty:  <cpu 0.00, memory 0.00, hugepages-2Mi 0.00>
I1104 15:54:08.118847   66853 enqueue.go:43] Enter Enqueue ...
I1104 15:54:08.118852   66853 enqueue.go:58] Added Queue <default> for Job <default/qj-1>
I1104 15:54:08.118860   66853 enqueue.go:75] Try to enqueue PodGroup to 0 Queues
I1104 15:54:08.118869   66853 enqueue.go:122] Leaving Enqueue ...
I1104 15:54:08.118877   66853 allocate.go:43] Enter Allocate ...
I1104 15:54:08.118884   66853 allocate.go:90] Added Job <default/qj-1> into Queue <default>
I1104 15:54:08.118892   66853 allocate.go:94] Try to allocate resource to 1 Namespaces
I1104 15:54:08.118902   66853 allocate.go:153] Try to allocate resource to Jobs in Namespace <default> Queue <default>
I1104 15:54:08.118912   66853 allocate.go:178] Try to allocate resource to 0 tasks of Job <default/qj-1>
I1104 15:54:08.118918   66853 statement.go:326] Committing operations ...
I1104 15:54:08.118932   66853 allocate.go:153] Try to allocate resource to Jobs in Namespace <default> Queue <default>
I1104 15:54:08.118939   66853 allocate.go:157] Can not find jobs for queue default.
I1104 15:54:08.118953   66853 allocate.go:253] Leaving Allocate ...
I1104 15:54:08.118959   66853 backfill.go:42] Enter Backfill ...
I1104 15:54:08.118966   66853 backfill.go:91] Leaving Backfill ...
I1104 15:54:08.122930   66853 session.go:154] Close Session 63ff27ae-ff5e-11e9-99a6-784f43775513
I1104 15:54:08.122941   66853 scheduler.go:87] End scheduling ...
I1104 15:54:13.124814   66853 scheduler.go:72] Start scheduling ...
I1104 15:54:13.137321   66853 cache.go:732] The priority of job <default/qj-1> is </0>
I1104 15:54:13.137347   66853 cache.go:771] There are <1> Jobs, <1> Queues and <1> Nodes in total for scheduling.
I1104 15:54:13.137353   66853 session.go:135] Open Session 66fcf1f2-ff5e-11e9-99a6-784f43775513 with <1> Job and <1> Queues
I1104 15:54:13.137367   66853 proportion.go:67] The total resource is <cpu 4000.00, memory 4959854592.00, hugepages-2Mi 0.00>
I1104 15:54:13.137380   66853 proportion.go:71] Considering Job <default/qj-1>.
I1104 15:54:13.137384   66853 proportion.go:85] Added Queue <default> attributes.
I1104 15:54:13.137392   66853 proportion.go:127] Considering Queue <default>: weight <1>, total weight <1>.
I1104 15:54:13.137400   66853 proportion.go:144] The attributes of queue <default> in proportion: deserved <cpu 4000.00, memory 4959854592.00, hugepages-2Mi 0.00>, allocate <cpu 0.00, memory 0.00>, request <cpu 0.00, memory 0.00>, share <0.00>
I1104 15:54:13.137414   66853 proportion.go:154] Exiting when remaining is empty:  <cpu 0.00, memory 0.00, hugepages-2Mi 0.00>
I1104 15:54:13.137484   66853 enqueue.go:43] Enter Enqueue ...
I1104 15:54:13.137507   66853 enqueue.go:58] Added Queue <default> for Job <default/qj-1>
I1104 15:54:13.137517   66853 enqueue.go:75] Try to enqueue PodGroup to 0 Queues
I1104 15:54:13.137526   66853 enqueue.go:122] Leaving Enqueue ...
I1104 15:54:13.137534   66853 allocate.go:43] Enter Allocate ...
I1104 15:54:13.137540   66853 allocate.go:90] Added Job <default/qj-1> into Queue <default>
I1104 15:54:13.137547   66853 allocate.go:94] Try to allocate resource to 1 Namespaces
I1104 15:54:13.137556   66853 allocate.go:153] Try to allocate resource to Jobs in Namespace <default> Queue <default>
I1104 15:54:13.137563   66853 allocate.go:178] Try to allocate resource to 0 tasks of Job <default/qj-1>
I1104 15:54:13.137568   66853 statement.go:326] Committing operations ...
I1104 15:54:13.137575   66853 allocate.go:153] Try to allocate resource to Jobs in Namespace <default> Queue <default>
I1104 15:54:13.137580   66853 allocate.go:157] Can not find jobs for queue default.
I1104 15:54:13.137594   66853 allocate.go:253] Leaving Allocate ...
I1104 15:54:13.137598   66853 backfill.go:42] Enter Backfill ...
I1104 15:54:13.137617   66853 backfill.go:91] Leaving Backfill ...
I1104 15:54:13.143160   66853 session.go:154] Close Session 66fcf1f2-ff5e-11e9-99a6-784f43775513
I1104 15:54:13.143173   66853 scheduler.go:87] End scheduling ...
I1104 15:54:18.144050   66853 scheduler.go:72] Start scheduling ...
I1104 15:54:18.151799   66853 cache.go:732] The priority of job <default/qj-1> is </0>
I1104 15:54:18.151818   66853 cache.go:771] There are <1> Jobs, <1> Queues and <1> Nodes in total for scheduling.
I1104 15:54:18.151823   66853 session.go:135] Open Session 69fa186c-ff5e-11e9-99a6-784f43775513 with <1> Job and <1> Queues
I1104 15:54:18.151863   66853 proportion.go:67] The total resource is <cpu 4000.00, memory 4959854592.00, hugepages-2Mi 0.00>
I1104 15:54:18.151876   66853 proportion.go:71] Considering Job <default/qj-1>.
I1104 15:54:18.151880   66853 proportion.go:85] Added Queue <default> attributes.
I1104 15:54:18.151892   66853 proportion.go:127] Considering Queue <default>: weight <1>, total weight <1>.
I1104 15:54:18.151899   66853 proportion.go:144] The attributes of queue <default> in proportion: deserved <cpu 4000.00, memory 4959854592.00, hugepages-2Mi 0.00>, allocate <cpu 0.00, memory 0.00>, request <cpu 0.00, memory 0.00>, share <0.00>
I1104 15:54:18.151912   66853 proportion.go:154] Exiting when remaining is empty:  <cpu 0.00, memory 0.00, hugepages-2Mi 0.00>
I1104 15:54:18.151933   66853 enqueue.go:43] Enter Enqueue ...
I1104 15:54:18.151937   66853 enqueue.go:58] Added Queue <default> for Job <default/qj-1>
I1104 15:54:18.151943   66853 enqueue.go:75] Try to enqueue PodGroup to 0 Queues
I1104 15:54:18.151949   66853 enqueue.go:122] Leaving Enqueue ...
I1104 15:54:18.151955   66853 allocate.go:43] Enter Allocate ...
I1104 15:54:18.151959   66853 allocate.go:90] Added Job <default/qj-1> into Queue <default>
I1104 15:54:18.151965   66853 allocate.go:94] Try to allocate resource to 1 Namespaces
I1104 15:54:18.151972   66853 allocate.go:153] Try to allocate resource to Jobs in Namespace <default> Queue <default>
I1104 15:54:18.151979   66853 allocate.go:178] Try to allocate resource to 0 tasks of Job <default/qj-1>
I1104 15:54:18.151982   66853 statement.go:326] Committing operations ...
I1104 15:54:18.151988   66853 allocate.go:153] Try to allocate resource to Jobs in Namespace <default> Queue <default>
I1104 15:54:18.151992   66853 allocate.go:157] Can not find jobs for queue default.
I1104 15:54:18.152001   66853 allocate.go:253] Leaving Allocate ...
I1104 15:54:18.152005   66853 backfill.go:42] Enter Backfill ...
I1104 15:54:18.152009   66853 backfill.go:91] Leaving Backfill ...
I1104 15:54:18.155884   66853 session.go:154] Close Session 69fa186c-ff5e-11e9-99a6-784f43775513
I1104 15:54:18.155895   66853 scheduler.go:87] End scheduling ...
I1104 15:54:23.156171   66853 scheduler.go:72] Start scheduling ...
I1104 15:54:23.165389   66853 cache.go:732] The priority of job <default/qj-1> is </0>
I1104 15:54:23.165415   66853 cache.go:771] There are <1> Jobs, <1> Queues and <1> Nodes in total for scheduling.
I1104 15:54:23.165422   66853 session.go:135] Open Session 6cf71b1e-ff5e-11e9-99a6-784f43775513 with <1> Job and <1> Queues
I1104 15:54:23.165476   66853 proportion.go:67] The total resource is <cpu 4000.00, memory 4959854592.00, hugepages-2Mi 0.00>
I1104 15:54:23.165492   66853 proportion.go:71] Considering Job <default/qj-1>.
I1104 15:54:23.165498   66853 proportion.go:85] Added Queue <default> attributes.
I1104 15:54:23.165508   66853 proportion.go:127] Considering Queue <default>: weight <1>, total weight <1>.
I1104 15:54:23.165523   66853 proportion.go:144] The attributes of queue <default> in proportion: deserved <cpu 4000.00, memory 4959854592.00, hugepages-2Mi 0.00>, allocate <cpu 0.00, memory 0.00>, request <cpu 0.00, memory 0.00>, share <0.00>
I1104 15:54:23.165542   66853 proportion.go:154] Exiting when remaining is empty:  <cpu 0.00, memory 0.00, hugepages-2Mi 0.00>
I1104 15:54:23.165568   66853 enqueue.go:43] Enter Enqueue ...
I1104 15:54:23.165574   66853 enqueue.go:58] Added Queue <default> for Job <default/qj-1>
I1104 15:54:23.165582   66853 enqueue.go:75] Try to enqueue PodGroup to 0 Queues
I1104 15:54:23.165591   66853 enqueue.go:122] Leaving Enqueue ...
I1104 15:54:23.165600   66853 allocate.go:43] Enter Allocate ...
I1104 15:54:23.165606   66853 allocate.go:90] Added Job <default/qj-1> into Queue <default>
I1104 15:54:23.165614   66853 allocate.go:94] Try to allocate resource to 1 Namespaces
I1104 15:54:23.165624   66853 allocate.go:153] Try to allocate resource to Jobs in Namespace <default> Queue <default>
I1104 15:54:23.165634   66853 allocate.go:178] Try to allocate resource to 0 tasks of Job <default/qj-1>
I1104 15:54:23.165640   66853 statement.go:326] Committing operations ...
I1104 15:54:23.165648   66853 allocate.go:153] Try to allocate resource to Jobs in Namespace <default> Queue <default>
I1104 15:54:23.165655   66853 allocate.go:157] Can not find jobs for queue default.
I1104 15:54:23.165669   66853 allocate.go:253] Leaving Allocate ...
I1104 15:54:23.165675   66853 backfill.go:42] Enter Backfill ...
I1104 15:54:23.165681   66853 backfill.go:91] Leaving Backfill ...
I1104 15:54:23.170470   66853 session.go:154] Close Session 6cf71b1e-ff5e-11e9-99a6-784f43775513
I1104 15:54:23.170481   66853 scheduler.go:87] End scheduling ...
I1104 15:54:28.170663   66853 scheduler.go:72] Start scheduling ...
I1104 15:54:28.182235   66853 cache.go:732] The priority of job <default/qj-1> is </0>
I1104 15:54:28.182261   66853 cache.go:771] There are <1> Jobs, <1> Queues and <1> Nodes in total for scheduling.
I1104 15:54:28.182268   66853 session.go:135] Open Session 6ff49d82-ff5e-11e9-99a6-784f43775513 with <1> Job and <1> Queues
I1104 15:54:28.182326   66853 proportion.go:67] The total resource is <cpu 4000.00, memory 4959854592.00, hugepages-2Mi 0.00>
I1104 15:54:28.182356   66853 proportion.go:71] Considering Job <default/qj-1>.
I1104 15:54:28.182362   66853 proportion.go:85] Added Queue <default> attributes.
I1104 15:54:28.182370   66853 proportion.go:127] Considering Queue <default>: weight <1>, total weight <1>.
I1104 15:54:28.182377   66853 proportion.go:144] The attributes of queue <default> in proportion: deserved <cpu 4000.00, memory 4959854592.00, hugepages-2Mi 0.00>, allocate <cpu 0.00, memory 0.00>, request <cpu 0.00, memory 0.00>, share <0.00>
I1104 15:54:28.182395   66853 proportion.go:154] Exiting when remaining is empty:  <cpu 0.00, memory 0.00, hugepages-2Mi 0.00>
I1104 15:54:28.182421   66853 enqueue.go:43] Enter Enqueue ...
I1104 15:54:28.182425   66853 enqueue.go:58] Added Queue <default> for Job <default/qj-1>
I1104 15:54:28.182431   66853 enqueue.go:75] Try to enqueue PodGroup to 0 Queues
I1104 15:54:28.182438   66853 enqueue.go:122] Leaving Enqueue ...
I1104 15:54:28.182447   66853 allocate.go:43] Enter Allocate ...
I1104 15:54:28.182452   66853 allocate.go:90] Added Job <default/qj-1> into Queue <default>
I1104 15:54:28.182458   66853 allocate.go:94] Try to allocate resource to 1 Namespaces
I1104 15:54:28.182466   66853 allocate.go:153] Try to allocate resource to Jobs in Namespace <default> Queue <default>
I1104 15:54:28.182477   66853 allocate.go:178] Try to allocate resource to 0 tasks of Job <default/qj-1>
I1104 15:54:28.182481   66853 statement.go:326] Committing operations ...
I1104 15:54:28.182487   66853 allocate.go:153] Try to allocate resource to Jobs in Namespace <default> Queue <default>
I1104 15:54:28.182492   66853 allocate.go:157] Can not find jobs for queue default.
I1104 15:54:28.182504   66853 allocate.go:253] Leaving Allocate ...
I1104 15:54:28.182509   66853 backfill.go:42] Enter Backfill ...
I1104 15:54:28.182514   66853 backfill.go:91] Leaving Backfill ...
I1104 15:54:28.186785   66853 session.go:154] Close Session 6ff49d82-ff5e-11e9-99a6-784f43775513
I1104 15:54:28.186795   66853 scheduler.go:87] End scheduling ...
I1104 15:54:33.186953   66853 scheduler.go:72] Start scheduling ...
I1104 15:54:33.201301   66853 cache.go:732] The priority of job <default/qj-1> is </0>
I1104 15:54:33.201318   66853 cache.go:771] There are <1> Jobs, <1> Queues and <1> Nodes in total for scheduling.
I1104 15:54:33.201322   66853 session.go:135] Open Session 72f277b6-ff5e-11e9-99a6-784f43775513 with <1> Job and <1> Queues
I1104 15:54:33.201355   66853 proportion.go:67] The total resource is <cpu 4000.00, memory 4959854592.00, hugepages-2Mi 0.00>
I1104 15:54:33.201365   66853 proportion.go:71] Considering Job <default/qj-1>.
I1104 15:54:33.201369   66853 proportion.go:85] Added Queue <default> attributes.
I1104 15:54:33.201375   66853 proportion.go:127] Considering Queue <default>: weight <1>, total weight <1>.
I1104 15:54:33.201381   66853 proportion.go:144] The attributes of queue <default> in proportion: deserved <cpu 4000.00, memory 4959854592.00, hugepages-2Mi 0.00>, allocate <cpu 0.00, memory 0.00>, request <cpu 0.00, memory 0.00>, share <0.00>
I1104 15:54:33.201391   66853 proportion.go:154] Exiting when remaining is empty:  <cpu 0.00, memory 0.00, hugepages-2Mi 0.00>
I1104 15:54:33.201412   66853 enqueue.go:43] Enter Enqueue ...
I1104 15:54:33.201416   66853 enqueue.go:58] Added Queue <default> for Job <default/qj-1>
I1104 15:54:33.201420   66853 enqueue.go:75] Try to enqueue PodGroup to 0 Queues
I1104 15:54:33.201426   66853 enqueue.go:122] Leaving Enqueue ...
I1104 15:54:33.201431   66853 allocate.go:43] Enter Allocate ...
I1104 15:54:33.201435   66853 allocate.go:90] Added Job <default/qj-1> into Queue <default>
I1104 15:54:33.201440   66853 allocate.go:94] Try to allocate resource to 1 Namespaces
I1104 15:54:33.201446   66853 allocate.go:153] Try to allocate resource to Jobs in Namespace <default> Queue <default>
I1104 15:54:33.201452   66853 allocate.go:178] Try to allocate resource to 0 tasks of Job <default/qj-1>
I1104 15:54:33.201455   66853 statement.go:326] Committing operations ...
I1104 15:54:33.201460   66853 allocate.go:153] Try to allocate resource to Jobs in Namespace <default> Queue <default>
I1104 15:54:33.201463   66853 allocate.go:157] Can not find jobs for queue default.
I1104 15:54:33.201472   66853 allocate.go:253] Leaving Allocate ...
I1104 15:54:33.201475   66853 backfill.go:42] Enter Backfill ...
I1104 15:54:33.201479   66853 backfill.go:91] Leaving Backfill ...
I1104 15:54:33.206935   66853 session.go:154] Close Session 72f277b6-ff5e-11e9-99a6-784f43775513
I1104 15:54:33.206945   66853 scheduler.go:87] End scheduling ...
I1104 15:54:38.207608   66853 scheduler.go:72] Start scheduling ...
I1104 15:54:38.219448   66853 cache.go:732] The priority of job <default/qj-1> is </0>
I1104 15:54:38.219475   66853 cache.go:771] There are <1> Jobs, <1> Queues and <1> Nodes in total for scheduling.
I1104 15:54:38.219482   66853 session.go:135] Open Session 75f02c2e-ff5e-11e9-99a6-784f43775513 with <1> Job and <1> Queues
I1104 15:54:38.219534   66853 proportion.go:67] The total resource is <cpu 4000.00, memory 4959854592.00, hugepages-2Mi 0.00>
I1104 15:54:38.219550   66853 proportion.go:71] Considering Job <default/qj-1>.
I1104 15:54:38.219557   66853 proportion.go:85] Added Queue <default> attributes.
I1104 15:54:38.219567   66853 proportion.go:127] Considering Queue <default>: weight <1>, total weight <1>.
I1104 15:54:38.219576   66853 proportion.go:144] The attributes of queue <default> in proportion: deserved <cpu 4000.00, memory 4959854592.00, hugepages-2Mi 0.00>, allocate <cpu 0.00, memory 0.00>, request <cpu 0.00, memory 0.00>, share <0.00>
I1104 15:54:38.219594   66853 proportion.go:154] Exiting when remaining is empty:  <cpu 0.00, memory 0.00, hugepages-2Mi 0.00>
I1104 15:54:38.219624   66853 enqueue.go:43] Enter Enqueue ...
I1104 15:54:38.219630   66853 enqueue.go:58] Added Queue <default> for Job <default/qj-1>
I1104 15:54:38.219637   66853 enqueue.go:75] Try to enqueue PodGroup to 0 Queues
I1104 15:54:38.219647   66853 enqueue.go:122] Leaving Enqueue ...
I1104 15:54:38.219654   66853 allocate.go:43] Enter Allocate ...
I1104 15:54:38.219661   66853 allocate.go:90] Added Job <default/qj-1> into Queue <default>
I1104 15:54:38.219669   66853 allocate.go:94] Try to allocate resource to 1 Namespaces
I1104 15:54:38.219679   66853 allocate.go:153] Try to allocate resource to Jobs in Namespace <default> Queue <default>
I1104 15:54:38.219689   66853 allocate.go:178] Try to allocate resource to 0 tasks of Job <default/qj-1>
I1104 15:54:38.219694   66853 statement.go:326] Committing operations ...
I1104 15:54:38.219702   66853 allocate.go:153] Try to allocate resource to Jobs in Namespace <default> Queue <default>
I1104 15:54:38.219709   66853 allocate.go:157] Can not find jobs for queue default.
I1104 15:54:38.219722   66853 allocate.go:253] Leaving Allocate ...
I1104 15:54:38.219728   66853 backfill.go:42] Enter Backfill ...
I1104 15:54:38.219734   66853 backfill.go:91] Leaving Backfill ...
I1104 15:54:38.224228   66853 session.go:154] Close Session 75f02c2e-ff5e-11e9-99a6-784f43775513
I1104 15:54:38.224238   66853 scheduler.go:87] End scheduling ...
I1104 15:54:43.226424   66853 scheduler.go:72] Start scheduling ...
I1104 15:54:43.234762   66853 cache.go:732] The priority of job <default/qj-1> is </0>
I1104 15:54:43.234783   66853 cache.go:771] There are <1> Jobs, <1> Queues and <1> Nodes in total for scheduling.
I1104 15:54:43.234788   66853 session.go:135] Open Session 78ed73c8-ff5e-11e9-99a6-784f43775513 with <1> Job and <1> Queues
I1104 15:54:43.234799   66853 proportion.go:67] The total resource is <cpu 4000.00, memory 4959854592.00, hugepages-2Mi 0.00>
I1104 15:54:43.234810   66853 proportion.go:71] Considering Job <default/qj-1>.
I1104 15:54:43.234815   66853 proportion.go:85] Added Queue <default> attributes.
I1104 15:54:43.234821   66853 proportion.go:127] Considering Queue <default>: weight <1>, total weight <1>.
I1104 15:54:43.234829   66853 proportion.go:144] The attributes of queue <default> in proportion: deserved <cpu 4000.00, memory 4959854592.00, hugepages-2Mi 0.00>, allocate <cpu 0.00, memory 0.00>, request <cpu 0.00, memory 0.00>, share <0.00>
I1104 15:54:43.234840   66853 proportion.go:154] Exiting when remaining is empty:  <cpu 0.00, memory 0.00, hugepages-2Mi 0.00>
I1104 15:54:43.234883   66853 enqueue.go:43] Enter Enqueue ...
I1104 15:54:43.234888   66853 enqueue.go:58] Added Queue <default> for Job <default/qj-1>
I1104 15:54:43.234893   66853 enqueue.go:75] Try to enqueue PodGroup to 0 Queues
I1104 15:54:43.234900   66853 enqueue.go:122] Leaving Enqueue ...
I1104 15:54:43.234905   66853 allocate.go:43] Enter Allocate ...
I1104 15:54:43.234909   66853 allocate.go:90] Added Job <default/qj-1> into Queue <default>
I1104 15:54:43.234915   66853 allocate.go:94] Try to allocate resource to 1 Namespaces
I1104 15:54:43.234922   66853 allocate.go:153] Try to allocate resource to Jobs in Namespace <default> Queue <default>
I1104 15:54:43.234929   66853 allocate.go:178] Try to allocate resource to 0 tasks of Job <default/qj-1>
I1104 15:54:43.234933   66853 statement.go:326] Committing operations ...
I1104 15:54:43.234938   66853 allocate.go:153] Try to allocate resource to Jobs in Namespace <default> Queue <default>
I1104 15:54:43.234942   66853 allocate.go:157] Can not find jobs for queue default.
I1104 15:54:43.234951   66853 allocate.go:253] Leaving Allocate ...
I1104 15:54:43.234955   66853 backfill.go:42] Enter Backfill ...
I1104 15:54:43.234959   66853 backfill.go:91] Leaving Backfill ...
I1104 15:54:43.238774   66853 session.go:154] Close Session 78ed73c8-ff5e-11e9-99a6-784f43775513
I1104 15:54:43.238785   66853 scheduler.go:87] End scheduling ...
I1104 15:54:48.242464   66853 scheduler.go:72] Start scheduling ...
I1104 15:54:48.251813   66853 cache.go:732] The priority of job <default/qj-1> is </0>
I1104 15:54:48.251837   66853 cache.go:771] There are <1> Jobs, <1> Queues and <1> Nodes in total for scheduling.
I1104 15:54:48.251850   66853 session.go:135] Open Session 7beafe06-ff5e-11e9-99a6-784f43775513 with <1> Job and <1> Queues
I1104 15:54:48.251909   66853 proportion.go:67] The total resource is <cpu 4000.00, memory 4959854592.00, hugepages-2Mi 0.00>
I1104 15:54:48.251927   66853 proportion.go:71] Considering Job <default/qj-1>.
I1104 15:54:48.251935   66853 proportion.go:85] Added Queue <default> attributes.
I1104 15:54:48.251943   66853 proportion.go:127] Considering Queue <default>: weight <1>, total weight <1>.
I1104 15:54:48.251949   66853 proportion.go:144] The attributes of queue <default> in proportion: deserved <cpu 4000.00, memory 4959854592.00, hugepages-2Mi 0.00>, allocate <cpu 0.00, memory 0.00>, request <cpu 0.00, memory 0.00>, share <0.00>
I1104 15:54:48.251964   66853 proportion.go:154] Exiting when remaining is empty:  <cpu 0.00, memory 0.00, hugepages-2Mi 0.00>
I1104 15:54:48.251995   66853 enqueue.go:43] Enter Enqueue ...
I1104 15:54:48.252002   66853 enqueue.go:58] Added Queue <default> for Job <default/qj-1>
I1104 15:54:48.252014   66853 enqueue.go:75] Try to enqueue PodGroup to 0 Queues
I1104 15:54:48.252024   66853 enqueue.go:122] Leaving Enqueue ...
I1104 15:54:48.252031   66853 allocate.go:43] Enter Allocate ...
I1104 15:54:48.252036   66853 allocate.go:90] Added Job <default/qj-1> into Queue <default>
I1104 15:54:48.252046   66853 allocate.go:94] Try to allocate resource to 1 Namespaces
I1104 15:54:48.252054   66853 allocate.go:153] Try to allocate resource to Jobs in Namespace <default> Queue <default>
I1104 15:54:48.252066   66853 allocate.go:178] Try to allocate resource to 0 tasks of Job <default/qj-1>
I1104 15:54:48.252075   66853 statement.go:326] Committing operations ...
I1104 15:54:48.252087   66853 allocate.go:153] Try to allocate resource to Jobs in Namespace <default> Queue <default>
I1104 15:54:48.252097   66853 allocate.go:157] Can not find jobs for queue default.
I1104 15:54:48.252110   66853 allocate.go:253] Leaving Allocate ...
I1104 15:54:48.252116   66853 backfill.go:42] Enter Backfill ...
I1104 15:54:48.252122   66853 backfill.go:91] Leaving Backfill ...
I1104 15:54:48.255496   66853 session.go:154] Close Session 7beafe06-ff5e-11e9-99a6-784f43775513
I1104 15:54:48.255507   66853 scheduler.go:87] End scheduling ...
I1104 15:54:53.257977   66853 scheduler.go:72] Start scheduling ...
I1104 15:54:53.268299   66853 cache.go:732] The priority of job <default/qj-1> is </0>
I1104 15:54:53.268327   66853 cache.go:771] There are <1> Jobs, <1> Queues and <1> Nodes in total for scheduling.
I1104 15:54:53.268334   66853 session.go:135] Open Session 7ee871ec-ff5e-11e9-99a6-784f43775513 with <1> Job and <1> Queues
I1104 15:54:53.268395   66853 proportion.go:67] The total resource is <cpu 4000.00, memory 4959854592.00, hugepages-2Mi 0.00>
I1104 15:54:53.268413   66853 proportion.go:71] Considering Job <default/qj-1>.
I1104 15:54:53.268420   66853 proportion.go:85] Added Queue <default> attributes.
I1104 15:54:53.268430   66853 proportion.go:127] Considering Queue <default>: weight <1>, total weight <1>.
I1104 15:54:53.268440   66853 proportion.go:144] The attributes of queue <default> in proportion: deserved <cpu 4000.00, memory 4959854592.00, hugepages-2Mi 0.00>, allocate <cpu 0.00, memory 0.00>, request <cpu 0.00, memory 0.00>, share <0.00>
I1104 15:54:53.268457   66853 proportion.go:154] Exiting when remaining is empty:  <cpu 0.00, memory 0.00, hugepages-2Mi 0.00>
I1104 15:54:53.268483   66853 enqueue.go:43] Enter Enqueue ...
I1104 15:54:53.268490   66853 enqueue.go:58] Added Queue <default> for Job <default/qj-1>
I1104 15:54:53.268497   66853 enqueue.go:75] Try to enqueue PodGroup to 0 Queues
I1104 15:54:53.268508   66853 enqueue.go:122] Leaving Enqueue ...
I1104 15:54:53.268516   66853 allocate.go:43] Enter Allocate ...
I1104 15:54:53.268523   66853 allocate.go:90] Added Job <default/qj-1> into Queue <default>
I1104 15:54:53.268532   66853 allocate.go:94] Try to allocate resource to 1 Namespaces
I1104 15:54:53.268545   66853 allocate.go:153] Try to allocate resource to Jobs in Namespace <default> Queue <default>
I1104 15:54:53.268555   66853 allocate.go:178] Try to allocate resource to 0 tasks of Job <default/qj-1>
I1104 15:54:53.268561   66853 statement.go:326] Committing operations ...
I1104 15:54:53.268569   66853 allocate.go:153] Try to allocate resource to Jobs in Namespace <default> Queue <default>
I1104 15:54:53.268575   66853 allocate.go:157] Can not find jobs for queue default.
I1104 15:54:53.268589   66853 allocate.go:253] Leaving Allocate ...
I1104 15:54:53.268595   66853 backfill.go:42] Enter Backfill ...
I1104 15:54:53.268601   66853 backfill.go:91] Leaving Backfill ...
I1104 15:54:53.272891   66853 session.go:154] Close Session 7ee871ec-ff5e-11e9-99a6-784f43775513
I1104 15:54:53.272904   66853 scheduler.go:87] End scheduling ...
I1104 15:54:58.273478   66853 scheduler.go:72] Start scheduling ...
I1104 15:54:58.287621   66853 cache.go:732] The priority of job <default/qj-1> is </0>
I1104 15:54:58.287640   66853 cache.go:771] There are <1> Jobs, <1> Queues and <1> Nodes in total for scheduling.
I1104 15:54:58.287646   66853 session.go:135] Open Session 81e655da-ff5e-11e9-99a6-784f43775513 with <1> Job and <1> Queues
I1104 15:54:58.287700   66853 proportion.go:67] The total resource is <cpu 4000.00, memory 4959854592.00, hugepages-2Mi 0.00>
I1104 15:54:58.287714   66853 proportion.go:71] Considering Job <default/qj-1>.
I1104 15:54:58.287719   66853 proportion.go:85] Added Queue <default> attributes.
I1104 15:54:58.287746   66853 proportion.go:127] Considering Queue <default>: weight <1>, total weight <1>.
I1104 15:54:58.287752   66853 proportion.go:144] The attributes of queue <default> in proportion: deserved <cpu 4000.00, memory 4959854592.00, hugepages-2Mi 0.00>, allocate <cpu 0.00, memory 0.00>, request <cpu 0.00, memory 0.00>, share <0.00>
I1104 15:54:58.287764   66853 proportion.go:154] Exiting when remaining is empty:  <cpu 0.00, memory 0.00, hugepages-2Mi 0.00>
I1104 15:54:58.287783   66853 enqueue.go:43] Enter Enqueue ...
I1104 15:54:58.287787   66853 enqueue.go:58] Added Queue <default> for Job <default/qj-1>
I1104 15:54:58.287792   66853 enqueue.go:75] Try to enqueue PodGroup to 0 Queues
I1104 15:54:58.287798   66853 enqueue.go:122] Leaving Enqueue ...
I1104 15:54:58.287804   66853 allocate.go:43] Enter Allocate ...
I1104 15:54:58.287808   66853 allocate.go:90] Added Job <default/qj-1> into Queue <default>
I1104 15:54:58.287814   66853 allocate.go:94] Try to allocate resource to 1 Namespaces
I1104 15:54:58.287821   66853 allocate.go:153] Try to allocate resource to Jobs in Namespace <default> Queue <default>
I1104 15:54:58.287829   66853 allocate.go:178] Try to allocate resource to 0 tasks of Job <default/qj-1>
I1104 15:54:58.287834   66853 statement.go:326] Committing operations ...
I1104 15:54:58.287839   66853 allocate.go:153] Try to allocate resource to Jobs in Namespace <default> Queue <default>
I1104 15:54:58.287843   66853 allocate.go:157] Can not find jobs for queue default.
I1104 15:54:58.287852   66853 allocate.go:253] Leaving Allocate ...
I1104 15:54:58.287856   66853 backfill.go:42] Enter Backfill ...
I1104 15:54:58.287860   66853 backfill.go:91] Leaving Backfill ...
I1104 15:54:58.291928   66853 session.go:154] Close Session 81e655da-ff5e-11e9-99a6-784f43775513
I1104 15:54:58.291941   66853 scheduler.go:87] End scheduling ...
I1104 15:55:03.293064   66853 scheduler.go:72] Start scheduling ...
I1104 15:55:03.299336   66853 cache.go:732] The priority of job <default/qj-1> is </0>
I1104 15:55:03.299361   66853 cache.go:771] There are <1> Jobs, <1> Queues and <1> Nodes in total for scheduling.
I1104 15:55:03.299368   66853 session.go:135] Open Session 84e30f6c-ff5e-11e9-99a6-784f43775513 with <1> Job and <1> Queues
I1104 15:55:03.299450   66853 proportion.go:67] The total resource is <cpu 4000.00, memory 4959854592.00, hugepages-2Mi 0.00>
I1104 15:55:03.299471   66853 proportion.go:71] Considering Job <default/qj-1>.
I1104 15:55:03.299479   66853 proportion.go:85] Added Queue <default> attributes.
I1104 15:55:03.299492   66853 proportion.go:127] Considering Queue <default>: weight <1>, total weight <1>.
I1104 15:55:03.299504   66853 proportion.go:144] The attributes of queue <default> in proportion: deserved <cpu 4000.00, memory 4959854592.00, hugepages-2Mi 0.00>, allocate <cpu 0.00, memory 0.00>, request <cpu 0.00, memory 0.00>, share <0.00>
I1104 15:55:03.299527   66853 proportion.go:154] Exiting when remaining is empty:  <cpu 0.00, memory 0.00, hugepages-2Mi 0.00>
I1104 15:55:03.299560   66853 enqueue.go:43] Enter Enqueue ...
I1104 15:55:03.299567   66853 enqueue.go:58] Added Queue <default> for Job <default/qj-1>
I1104 15:55:03.299576   66853 enqueue.go:75] Try to enqueue PodGroup to 0 Queues
I1104 15:55:03.299588   66853 enqueue.go:122] Leaving Enqueue ...
I1104 15:55:03.299598   66853 allocate.go:43] Enter Allocate ...
I1104 15:55:03.299613   66853 allocate.go:90] Added Job <default/qj-1> into Queue <default>
I1104 15:55:03.299639   66853 allocate.go:94] Try to allocate resource to 1 Namespaces
I1104 15:55:03.299649   66853 allocate.go:153] Try to allocate resource to Jobs in Namespace <default> Queue <default>
I1104 15:55:03.299660   66853 allocate.go:178] Try to allocate resource to 0 tasks of Job <default/qj-1>
I1104 15:55:03.299665   66853 statement.go:326] Committing operations ...
I1104 15:55:03.299673   66853 allocate.go:153] Try to allocate resource to Jobs in Namespace <default> Queue <default>
I1104 15:55:03.299679   66853 allocate.go:157] Can not find jobs for queue default.
I1104 15:55:03.299696   66853 allocate.go:253] Leaving Allocate ...
I1104 15:55:03.299701   66853 backfill.go:42] Enter Backfill ...
I1104 15:55:03.299707   66853 backfill.go:91] Leaving Backfill ...
I1104 15:55:03.303410   66853 session.go:154] Close Session 84e30f6c-ff5e-11e9-99a6-784f43775513
I1104 15:55:03.303421   66853 scheduler.go:87] End scheduling ...
I1104 15:55:08.305957   66853 scheduler.go:72] Start scheduling ...
I1104 15:55:08.315522   66853 cache.go:732] The priority of job <default/qj-1> is </0>
I1104 15:55:08.315541   66853 cache.go:771] There are <1> Jobs, <1> Queues and <1> Nodes in total for scheduling.
I1104 15:55:08.315546   66853 session.go:135] Open Session 87e078d0-ff5e-11e9-99a6-784f43775513 with <1> Job and <1> Queues
I1104 15:55:08.315578   66853 proportion.go:67] The total resource is <cpu 4000.00, memory 4959854592.00, hugepages-2Mi 0.00>
I1104 15:55:08.315590   66853 proportion.go:71] Considering Job <default/qj-1>.
I1104 15:55:08.315594   66853 proportion.go:85] Added Queue <default> attributes.
I1104 15:55:08.315601   66853 proportion.go:127] Considering Queue <default>: weight <1>, total weight <1>.
I1104 15:55:08.315607   66853 proportion.go:144] The attributes of queue <default> in proportion: deserved <cpu 4000.00, memory 4959854592.00, hugepages-2Mi 0.00>, allocate <cpu 0.00, memory 0.00>, request <cpu 0.00, memory 0.00>, share <0.00>
I1104 15:55:08.315619   66853 proportion.go:154] Exiting when remaining is empty:  <cpu 0.00, memory 0.00, hugepages-2Mi 0.00>
I1104 15:55:08.315645   66853 enqueue.go:43] Enter Enqueue ...
I1104 15:55:08.315649   66853 enqueue.go:58] Added Queue <default> for Job <default/qj-1>
I1104 15:55:08.315654   66853 enqueue.go:75] Try to enqueue PodGroup to 0 Queues
I1104 15:55:08.315662   66853 enqueue.go:122] Leaving Enqueue ...
I1104 15:55:08.315668   66853 allocate.go:43] Enter Allocate ...
I1104 15:55:08.315672   66853 allocate.go:90] Added Job <default/qj-1> into Queue <default>
I1104 15:55:08.315677   66853 allocate.go:94] Try to allocate resource to 1 Namespaces
I1104 15:55:08.315684   66853 allocate.go:153] Try to allocate resource to Jobs in Namespace <default> Queue <default>
I1104 15:55:08.315691   66853 allocate.go:178] Try to allocate resource to 0 tasks of Job <default/qj-1>
I1104 15:55:08.315695   66853 statement.go:326] Committing operations ...
I1104 15:55:08.315700   66853 allocate.go:153] Try to allocate resource to Jobs in Namespace <default> Queue <default>
I1104 15:55:08.315704   66853 allocate.go:157] Can not find jobs for queue default.
I1104 15:55:08.315714   66853 allocate.go:253] Leaving Allocate ...
I1104 15:55:08.315717   66853 backfill.go:42] Enter Backfill ...
I1104 15:55:08.315721   66853 backfill.go:91] Leaving Backfill ...
I1104 15:55:08.319795   66853 session.go:154] Close Session 87e078d0-ff5e-11e9-99a6-784f43775513
I1104 15:55:08.319805   66853 scheduler.go:87] End scheduling ...
I1104 15:55:13.320591   66853 scheduler.go:72] Start scheduling ...
I1104 15:55:13.331850   66853 cache.go:732] The priority of job <default/qj-1> is </0>
I1104 15:55:13.331876   66853 cache.go:771] There are <1> Jobs, <1> Queues and <1> Nodes in total for scheduling.
I1104 15:55:13.331881   66853 session.go:135] Open Session 8adde6bc-ff5e-11e9-99a6-784f43775513 with <1> Job and <1> Queues
I1104 15:55:13.331924   66853 proportion.go:67] The total resource is <cpu 4000.00, memory 4959854592.00, hugepages-2Mi 0.00>
I1104 15:55:13.331938   66853 proportion.go:71] Considering Job <default/qj-1>.
I1104 15:55:13.331943   66853 proportion.go:85] Added Queue <default> attributes.
I1104 15:55:13.331950   66853 proportion.go:127] Considering Queue <default>: weight <1>, total weight <1>.
I1104 15:55:13.331957   66853 proportion.go:144] The attributes of queue <default> in proportion: deserved <cpu 4000.00, memory 4959854592.00, hugepages-2Mi 0.00>, allocate <cpu 0.00, memory 0.00>, request <cpu 0.00, memory 0.00>, share <0.00>
I1104 15:55:13.331969   66853 proportion.go:154] Exiting when remaining is empty:  <cpu 0.00, memory 0.00, hugepages-2Mi 0.00>
I1104 15:55:13.331990   66853 enqueue.go:43] Enter Enqueue ...
I1104 15:55:13.331995   66853 enqueue.go:58] Added Queue <default> for Job <default/qj-1>
I1104 15:55:13.332001   66853 enqueue.go:75] Try to enqueue PodGroup to 0 Queues
I1104 15:55:13.332010   66853 enqueue.go:122] Leaving Enqueue ...
I1104 15:55:13.332016   66853 allocate.go:43] Enter Allocate ...
I1104 15:55:13.332021   66853 allocate.go:90] Added Job <default/qj-1> into Queue <default>
I1104 15:55:13.332028   66853 allocate.go:94] Try to allocate resource to 1 Namespaces
I1104 15:55:13.332035   66853 allocate.go:153] Try to allocate resource to Jobs in Namespace <default> Queue <default>
I1104 15:55:13.332043   66853 allocate.go:178] Try to allocate resource to 0 tasks of Job <default/qj-1>
I1104 15:55:13.332048   66853 statement.go:326] Committing operations ...
I1104 15:55:13.332054   66853 allocate.go:153] Try to allocate resource to Jobs in Namespace <default> Queue <default>
I1104 15:55:13.332059   66853 allocate.go:157] Can not find jobs for queue default.
I1104 15:55:13.332070   66853 allocate.go:253] Leaving Allocate ...
I1104 15:55:13.332075   66853 backfill.go:42] Enter Backfill ...
I1104 15:55:13.332080   66853 backfill.go:91] Leaving Backfill ...
I1104 15:55:13.337753   66853 session.go:154] Close Session 8adde6bc-ff5e-11e9-99a6-784f43775513
I1104 15:55:13.337764   66853 scheduler.go:87] End scheduling ...
I1104 15:55:18.340416   66853 scheduler.go:72] Start scheduling ...
I1104 15:55:18.340559   66853 cache.go:732] The priority of job <default/qj-1> is </0>
I1104 15:55:18.340577   66853 cache.go:771] There are <1> Jobs, <1> Queues and <1> Nodes in total for scheduling.
I1104 15:55:18.340582   66853 session.go:135] Open Session 8dda2c04-ff5e-11e9-99a6-784f43775513 with <1> Job and <1> Queues
I1104 15:55:18.340621   66853 proportion.go:67] The total resource is <cpu 4000.00, memory 4959854592.00, hugepages-2Mi 0.00>
I1104 15:55:18.340632   66853 proportion.go:71] Considering Job <default/qj-1>.
I1104 15:55:18.340636   66853 proportion.go:85] Added Queue <default> attributes.
I1104 15:55:18.340646   66853 proportion.go:127] Considering Queue <default>: weight <1>, total weight <1>.
I1104 15:55:18.340654   66853 proportion.go:144] The attributes of queue <default> in proportion: deserved <cpu 4000.00, memory 4959854592.00, hugepages-2Mi 0.00>, allocate <cpu 0.00, memory 0.00>, request <cpu 0.00, memory 0.00>, share <0.00>
I1104 15:55:18.340666   66853 proportion.go:154] Exiting when remaining is empty:  <cpu 0.00, memory 0.00, hugepages-2Mi 0.00>
I1104 15:55:18.340695   66853 enqueue.go:43] Enter Enqueue ...
I1104 15:55:18.340699   66853 enqueue.go:58] Added Queue <default> for Job <default/qj-1>
I1104 15:55:18.340704   66853 enqueue.go:75] Try to enqueue PodGroup to 0 Queues
I1104 15:55:18.340710   66853 enqueue.go:122] Leaving Enqueue ...
I1104 15:55:18.340716   66853 allocate.go:43] Enter Allocate ...
I1104 15:55:18.340720   66853 allocate.go:90] Added Job <default/qj-1> into Queue <default>
I1104 15:55:18.340726   66853 allocate.go:94] Try to allocate resource to 1 Namespaces
I1104 15:55:18.340732   66853 allocate.go:153] Try to allocate resource to Jobs in Namespace <default> Queue <default>
I1104 15:55:18.340739   66853 allocate.go:178] Try to allocate resource to 0 tasks of Job <default/qj-1>
I1104 15:55:18.340742   66853 statement.go:326] Committing operations ...
I1104 15:55:18.340749   66853 allocate.go:153] Try to allocate resource to Jobs in Namespace <default> Queue <default>
I1104 15:55:18.340754   66853 allocate.go:157] Can not find jobs for queue default.
I1104 15:55:18.340763   66853 allocate.go:253] Leaving Allocate ...
I1104 15:55:18.340766   66853 backfill.go:42] Enter Backfill ...
I1104 15:55:18.340770   66853 backfill.go:91] Leaving Backfill ...
I1104 15:55:18.344815   66853 session.go:154] Close Session 8dda2c04-ff5e-11e9-99a6-784f43775513
I1104 15:55:18.344825   66853 scheduler.go:87] End scheduling ...
I1104 15:55:23.348548   66853 scheduler.go:72] Start scheduling ...
I1104 15:55:23.351012   66853 cache.go:732] The priority of job <default/qj-1> is </0>
I1104 15:55:23.351030   66853 cache.go:771] There are <1> Jobs, <1> Queues and <1> Nodes in total for scheduling.
I1104 15:55:23.351035   66853 session.go:135] Open Session 90d6b4d6-ff5e-11e9-99a6-784f43775513 with <1> Job and <1> Queues
I1104 15:55:23.351083   66853 proportion.go:67] The total resource is <cpu 4000.00, memory 4959854592.00, hugepages-2Mi 0.00>
I1104 15:55:23.351095   66853 proportion.go:71] Considering Job <default/qj-1>.
I1104 15:55:23.351099   66853 proportion.go:85] Added Queue <default> attributes.
I1104 15:55:23.351105   66853 proportion.go:127] Considering Queue <default>: weight <1>, total weight <1>.
I1104 15:55:23.351112   66853 proportion.go:144] The attributes of queue <default> in proportion: deserved <cpu 4000.00, memory 4959854592.00, hugepages-2Mi 0.00>, allocate <cpu 0.00, memory 0.00>, request <cpu 0.00, memory 0.00>, share <0.00>
I1104 15:55:23.351123   66853 proportion.go:154] Exiting when remaining is empty:  <cpu 0.00, memory 0.00, hugepages-2Mi 0.00>
I1104 15:55:23.351130   66853 enqueue.go:43] Enter Enqueue ...
I1104 15:55:23.351134   66853 enqueue.go:58] Added Queue <default> for Job <default/qj-1>
I1104 15:55:23.351139   66853 enqueue.go:75] Try to enqueue PodGroup to 0 Queues
I1104 15:55:23.351146   66853 enqueue.go:122] Leaving Enqueue ...
I1104 15:55:23.351151   66853 allocate.go:43] Enter Allocate ...
I1104 15:55:23.351155   66853 allocate.go:90] Added Job <default/qj-1> into Queue <default>
I1104 15:55:23.351160   66853 allocate.go:94] Try to allocate resource to 1 Namespaces
I1104 15:55:23.351167   66853 allocate.go:153] Try to allocate resource to Jobs in Namespace <default> Queue <default>
I1104 15:55:23.351174   66853 allocate.go:178] Try to allocate resource to 0 tasks of Job <default/qj-1>
I1104 15:55:23.351178   66853 statement.go:326] Committing operations ...
I1104 15:55:23.351183   66853 allocate.go:153] Try to allocate resource to Jobs in Namespace <default> Queue <default>
I1104 15:55:23.351187   66853 allocate.go:157] Can not find jobs for queue default.
I1104 15:55:23.351197   66853 allocate.go:253] Leaving Allocate ...
I1104 15:55:23.351200   66853 backfill.go:42] Enter Backfill ...
I1104 15:55:23.351204   66853 backfill.go:91] Leaving Backfill ...
I1104 15:55:23.355498   66853 session.go:154] Close Session 90d6b4d6-ff5e-11e9-99a6-784f43775513
I1104 15:55:23.355509   66853 scheduler.go:87] End scheduling ...
I1104 15:55:28.359494   66853 scheduler.go:72] Start scheduling ...
I1104 15:55:28.368918   66853 cache.go:732] The priority of job <default/qj-1> is </0>
I1104 15:55:28.368947   66853 cache.go:771] There are <1> Jobs, <1> Queues and <1> Nodes in total for scheduling.
I1104 15:55:28.368955   66853 session.go:135] Open Session 93d45fe4-ff5e-11e9-99a6-784f43775513 with <1> Job and <1> Queues
I1104 15:55:28.368970   66853 proportion.go:67] The total resource is <cpu 4000.00, memory 4959854592.00, hugepages-2Mi 0.00>
I1104 15:55:28.368984   66853 proportion.go:71] Considering Job <default/qj-1>.
I1104 15:55:28.368991   66853 proportion.go:85] Added Queue <default> attributes.
I1104 15:55:28.369001   66853 proportion.go:127] Considering Queue <default>: weight <1>, total weight <1>.
I1104 15:55:28.369010   66853 proportion.go:144] The attributes of queue <default> in proportion: deserved <cpu 4000.00, memory 4959854592.00, hugepages-2Mi 0.00>, allocate <cpu 0.00, memory 0.00>, request <cpu 0.00, memory 0.00>, share <0.00>
I1104 15:55:28.369031   66853 proportion.go:154] Exiting when remaining is empty:  <cpu 0.00, memory 0.00, hugepages-2Mi 0.00>
I1104 15:55:28.369094   66853 enqueue.go:43] Enter Enqueue ...
I1104 15:55:28.369100   66853 enqueue.go:58] Added Queue <default> for Job <default/qj-1>
I1104 15:55:28.369107   66853 enqueue.go:75] Try to enqueue PodGroup to 0 Queues
I1104 15:55:28.369116   66853 enqueue.go:122] Leaving Enqueue ...
I1104 15:55:28.369124   66853 allocate.go:43] Enter Allocate ...
I1104 15:55:28.369131   66853 allocate.go:90] Added Job <default/qj-1> into Queue <default>
I1104 15:55:28.369139   66853 allocate.go:94] Try to allocate resource to 1 Namespaces
I1104 15:55:28.369148   66853 allocate.go:153] Try to allocate resource to Jobs in Namespace <default> Queue <default>
I1104 15:55:28.369159   66853 allocate.go:178] Try to allocate resource to 0 tasks of Job <default/qj-1>
I1104 15:55:28.369164   66853 statement.go:326] Committing operations ...
I1104 15:55:28.369172   66853 allocate.go:153] Try to allocate resource to Jobs in Namespace <default> Queue <default>
I1104 15:55:28.369178   66853 allocate.go:157] Can not find jobs for queue default.
I1104 15:55:28.369192   66853 allocate.go:253] Leaving Allocate ...
I1104 15:55:28.369197   66853 backfill.go:42] Enter Backfill ...
I1104 15:55:28.369203   66853 backfill.go:91] Leaving Backfill ...
I1104 15:55:28.373687   66853 session.go:154] Close Session 93d45fe4-ff5e-11e9-99a6-784f43775513
I1104 15:55:28.373696   66853 scheduler.go:87] End scheduling ...
I1104 15:55:33.377566   66853 scheduler.go:72] Start scheduling ...
I1104 15:55:33.389249   66853 cache.go:732] The priority of job <default/qj-1> is </0>
I1104 15:55:33.389281   66853 cache.go:771] There are <1> Jobs, <1> Queues and <1> Nodes in total for scheduling.
I1104 15:55:33.389288   66853 session.go:135] Open Session 96d26a24-ff5e-11e9-99a6-784f43775513 with <1> Job and <1> Queues
I1104 15:55:33.389325   66853 proportion.go:67] The total resource is <cpu 4000.00, memory 4959854592.00, hugepages-2Mi 0.00>
I1104 15:55:33.389340   66853 proportion.go:71] Considering Job <default/qj-1>.
I1104 15:55:33.389345   66853 proportion.go:85] Added Queue <default> attributes.
I1104 15:55:33.389353   66853 proportion.go:127] Considering Queue <default>: weight <1>, total weight <1>.
I1104 15:55:33.389360   66853 proportion.go:144] The attributes of queue <default> in proportion: deserved <cpu 4000.00, memory 4959854592.00, hugepages-2Mi 0.00>, allocate <cpu 0.00, memory 0.00>, request <cpu 0.00, memory 0.00>, share <0.00>
I1104 15:55:33.389379   66853 proportion.go:154] Exiting when remaining is empty:  <cpu 0.00, memory 0.00, hugepages-2Mi 0.00>
I1104 15:55:33.389411   66853 enqueue.go:43] Enter Enqueue ...
I1104 15:55:33.389416   66853 enqueue.go:58] Added Queue <default> for Job <default/qj-1>
I1104 15:55:33.389421   66853 enqueue.go:75] Try to enqueue PodGroup to 0 Queues
I1104 15:55:33.389429   66853 enqueue.go:122] Leaving Enqueue ...
I1104 15:55:33.389435   66853 allocate.go:43] Enter Allocate ...
I1104 15:55:33.389441   66853 allocate.go:90] Added Job <default/qj-1> into Queue <default>
I1104 15:55:33.389448   66853 allocate.go:94] Try to allocate resource to 1 Namespaces
I1104 15:55:33.389456   66853 allocate.go:153] Try to allocate resource to Jobs in Namespace <default> Queue <default>
I1104 15:55:33.389464   66853 allocate.go:178] Try to allocate resource to 0 tasks of Job <default/qj-1>
I1104 15:55:33.389469   66853 statement.go:326] Committing operations ...
I1104 15:55:33.389476   66853 allocate.go:153] Try to allocate resource to Jobs in Namespace <default> Queue <default>
I1104 15:55:33.389481   66853 allocate.go:157] Can not find jobs for queue default.
I1104 15:55:33.389493   66853 allocate.go:253] Leaving Allocate ...
I1104 15:55:33.389498   66853 backfill.go:42] Enter Backfill ...
I1104 15:55:33.389503   66853 backfill.go:91] Leaving Backfill ...
I1104 15:55:33.393945   66853 session.go:154] Close Session 96d26a24-ff5e-11e9-99a6-784f43775513
I1104 15:55:33.393956   66853 scheduler.go:87] End scheduling ...
I1104 15:55:38.397729   66853 scheduler.go:72] Start scheduling ...
I1104 15:55:38.408223   66853 cache.go:732] The priority of job <default/qj-1> is </0>
I1104 15:55:38.408289   66853 cache.go:771] There are <1> Jobs, <1> Queues and <1> Nodes in total for scheduling.
I1104 15:55:38.408297   66853 session.go:135] Open Session 99d03fd0-ff5e-11e9-99a6-784f43775513 with <1> Job and <1> Queues
I1104 15:55:38.408352   66853 proportion.go:67] The total resource is <cpu 4000.00, memory 4959854592.00, hugepages-2Mi 0.00>
I1104 15:55:38.408367   66853 proportion.go:71] Considering Job <default/qj-1>.
I1104 15:55:38.408373   66853 proportion.go:85] Added Queue <default> attributes.
I1104 15:55:38.408383   66853 proportion.go:127] Considering Queue <default>: weight <1>, total weight <1>.
I1104 15:55:38.408398   66853 proportion.go:144] The attributes of queue <default> in proportion: deserved <cpu 4000.00, memory 4959854592.00, hugepages-2Mi 0.00>, allocate <cpu 0.00, memory 0.00>, request <cpu 0.00, memory 0.00>, share <0.00>
I1104 15:55:38.408416   66853 proportion.go:154] Exiting when remaining is empty:  <cpu 0.00, memory 0.00, hugepages-2Mi 0.00>
I1104 15:55:38.408444   66853 enqueue.go:43] Enter Enqueue ...
I1104 15:55:38.408450   66853 enqueue.go:58] Added Queue <default> for Job <default/qj-1>
I1104 15:55:38.408457   66853 enqueue.go:75] Try to enqueue PodGroup to 0 Queues
I1104 15:55:38.408466   66853 enqueue.go:122] Leaving Enqueue ...
I1104 15:55:38.408474   66853 allocate.go:43] Enter Allocate ...
I1104 15:55:38.408481   66853 allocate.go:90] Added Job <default/qj-1> into Queue <default>
I1104 15:55:38.408489   66853 allocate.go:94] Try to allocate resource to 1 Namespaces
I1104 15:55:38.408499   66853 allocate.go:153] Try to allocate resource to Jobs in Namespace <default> Queue <default>
I1104 15:55:38.408509   66853 allocate.go:178] Try to allocate resource to 0 tasks of Job <default/qj-1>
I1104 15:55:38.408514   66853 statement.go:326] Committing operations ...
I1104 15:55:38.408522   66853 allocate.go:153] Try to allocate resource to Jobs in Namespace <default> Queue <default>
I1104 15:55:38.408528   66853 allocate.go:157] Can not find jobs for queue default.
I1104 15:55:38.408542   66853 allocate.go:253] Leaving Allocate ...
I1104 15:55:38.408547   66853 backfill.go:42] Enter Backfill ...
I1104 15:55:38.408553   66853 backfill.go:91] Leaving Backfill ...
I1104 15:55:38.412674   66853 session.go:154] Close Session 99d03fd0-ff5e-11e9-99a6-784f43775513
I1104 15:55:38.412684   66853 scheduler.go:87] End scheduling ...
I1104 15:55:43.417632   66853 scheduler.go:72] Start scheduling ...
I1104 15:55:43.427216   66853 cache.go:732] The priority of job <default/qj-1> is </0>
I1104 15:55:43.427268   66853 cache.go:771] There are <1> Jobs, <1> Queues and <1> Nodes in total for scheduling.
I1104 15:55:43.427278   66853 session.go:135] Open Session 9cce15ae-ff5e-11e9-99a6-784f43775513 with <1> Job and <1> Queues
I1104 15:55:43.427336   66853 proportion.go:67] The total resource is <cpu 4000.00, memory 4959854592.00, hugepages-2Mi 0.00>
I1104 15:55:43.427355   66853 proportion.go:71] Considering Job <default/qj-1>.
I1104 15:55:43.427364   66853 proportion.go:85] Added Queue <default> attributes.
I1104 15:55:43.427379   66853 proportion.go:127] Considering Queue <default>: weight <1>, total weight <1>.
I1104 15:55:43.427393   66853 proportion.go:144] The attributes of queue <default> in proportion: deserved <cpu 4000.00, memory 4959854592.00, hugepages-2Mi 0.00>, allocate <cpu 0.00, memory 0.00>, request <cpu 0.00, memory 0.00>, share <0.00>
I1104 15:55:43.427414   66853 proportion.go:154] Exiting when remaining is empty:  <cpu 0.00, memory 0.00, hugepages-2Mi 0.00>
I1104 15:55:43.427452   66853 enqueue.go:43] Enter Enqueue ...
I1104 15:55:43.427459   66853 enqueue.go:58] Added Queue <default> for Job <default/qj-1>
I1104 15:55:43.427471   66853 enqueue.go:75] Try to enqueue PodGroup to 0 Queues
I1104 15:55:43.427483   66853 enqueue.go:122] Leaving Enqueue ...
I1104 15:55:43.427495   66853 allocate.go:43] Enter Allocate ...
I1104 15:55:43.427505   66853 allocate.go:90] Added Job <default/qj-1> into Queue <default>
I1104 15:55:43.427514   66853 allocate.go:94] Try to allocate resource to 1 Namespaces
I1104 15:55:43.427527   66853 allocate.go:153] Try to allocate resource to Jobs in Namespace <default> Queue <default>
I1104 15:55:43.427538   66853 allocate.go:178] Try to allocate resource to 0 tasks of Job <default/qj-1>
I1104 15:55:43.427544   66853 statement.go:326] Committing operations ...
I1104 15:55:43.427552   66853 allocate.go:153] Try to allocate resource to Jobs in Namespace <default> Queue <default>
I1104 15:55:43.427564   66853 allocate.go:157] Can not find jobs for queue default.
I1104 15:55:43.427579   66853 allocate.go:253] Leaving Allocate ...
I1104 15:55:43.427585   66853 backfill.go:42] Enter Backfill ...
I1104 15:55:43.427592   66853 backfill.go:91] Leaving Backfill ...
I1104 15:55:43.434540   66853 session.go:154] Close Session 9cce15ae-ff5e-11e9-99a6-784f43775513
I1104 15:55:43.434551   66853 scheduler.go:87] End scheduling ...
I1104 15:55:48.437089   66853 scheduler.go:72] Start scheduling ...
I1104 15:55:48.446601   66853 cache.go:732] The priority of job <default/qj-1> is </0>
I1104 15:55:48.446621   66853 cache.go:771] There are <1> Jobs, <1> Queues and <1> Nodes in total for scheduling.
I1104 15:55:48.446627   66853 session.go:135] Open Session 9fcbfd02-ff5e-11e9-99a6-784f43775513 with <1> Job and <1> Queues
I1104 15:55:48.446639   66853 proportion.go:67] The total resource is <cpu 4000.00, memory 4959854592.00, hugepages-2Mi 0.00>
I1104 15:55:48.446653   66853 proportion.go:71] Considering Job <default/qj-1>.
I1104 15:55:48.446658   66853 proportion.go:85] Added Queue <default> attributes.
I1104 15:55:48.446667   66853 proportion.go:127] Considering Queue <default>: weight <1>, total weight <1>.
I1104 15:55:48.446675   66853 proportion.go:144] The attributes of queue <default> in proportion: deserved <cpu 4000.00, memory 4959854592.00, hugepages-2Mi 0.00>, allocate <cpu 0.00, memory 0.00>, request <cpu 0.00, memory 0.00>, share <0.00>
I1104 15:55:48.446689   66853 proportion.go:154] Exiting when remaining is empty:  <cpu 0.00, memory 0.00, hugepages-2Mi 0.00>
I1104 15:55:48.446738   66853 enqueue.go:43] Enter Enqueue ...
I1104 15:55:48.446743   66853 enqueue.go:58] Added Queue <default> for Job <default/qj-1>
I1104 15:55:48.446748   66853 enqueue.go:75] Try to enqueue PodGroup to 0 Queues
I1104 15:55:48.446756   66853 enqueue.go:122] Leaving Enqueue ...
I1104 15:55:48.446762   66853 allocate.go:43] Enter Allocate ...
I1104 15:55:48.446767   66853 allocate.go:90] Added Job <default/qj-1> into Queue <default>
I1104 15:55:48.446774   66853 allocate.go:94] Try to allocate resource to 1 Namespaces
I1104 15:55:48.446781   66853 allocate.go:153] Try to allocate resource to Jobs in Namespace <default> Queue <default>
I1104 15:55:48.446791   66853 allocate.go:178] Try to allocate resource to 0 tasks of Job <default/qj-1>
I1104 15:55:48.446795   66853 statement.go:326] Committing operations ...
I1104 15:55:48.446801   66853 allocate.go:153] Try to allocate resource to Jobs in Namespace <default> Queue <default>
I1104 15:55:48.446806   66853 allocate.go:157] Can not find jobs for queue default.
I1104 15:55:48.446817   66853 allocate.go:253] Leaving Allocate ...
I1104 15:55:48.446821   66853 backfill.go:42] Enter Backfill ...
I1104 15:55:48.446826   66853 backfill.go:91] Leaving Backfill ...
I1104 15:55:48.459144   66853 session.go:154] Close Session 9fcbfd02-ff5e-11e9-99a6-784f43775513
I1104 15:55:48.459157   66853 scheduler.go:87] End scheduling ...
I1104 15:55:53.461155   66853 scheduler.go:72] Start scheduling ...
I1104 15:55:53.466647   66853 cache.go:732] The priority of job <default/qj-1> is </0>
I1104 15:55:53.466671   66853 cache.go:771] There are <1> Jobs, <1> Queues and <1> Nodes in total for scheduling.
I1104 15:55:53.466679   66853 session.go:135] Open Session a2c9fc34-ff5e-11e9-99a6-784f43775513 with <1> Job and <1> Queues
I1104 15:55:53.466742   66853 proportion.go:67] The total resource is <cpu 4000.00, memory 4959854592.00, hugepages-2Mi 0.00>
I1104 15:55:53.466766   66853 proportion.go:71] Considering Job <default/qj-1>.
I1104 15:55:53.466776   66853 proportion.go:85] Added Queue <default> attributes.
I1104 15:55:53.466787   66853 proportion.go:127] Considering Queue <default>: weight <1>, total weight <1>.
I1104 15:55:53.466795   66853 proportion.go:144] The attributes of queue <default> in proportion: deserved <cpu 4000.00, memory 4959854592.00, hugepages-2Mi 0.00>, allocate <cpu 0.00, memory 0.00>, request <cpu 0.00, memory 0.00>, share <0.00>
I1104 15:55:53.466818   66853 proportion.go:154] Exiting when remaining is empty:  <cpu 0.00, memory 0.00, hugepages-2Mi 0.00>
I1104 15:55:53.466854   66853 enqueue.go:43] Enter Enqueue ...
I1104 15:55:53.466858   66853 enqueue.go:58] Added Queue <default> for Job <default/qj-1>
I1104 15:55:53.466863   66853 enqueue.go:75] Try to enqueue PodGroup to 0 Queues
I1104 15:55:53.466871   66853 enqueue.go:122] Leaving Enqueue ...
I1104 15:55:53.466877   66853 allocate.go:43] Enter Allocate ...
I1104 15:55:53.466883   66853 allocate.go:90] Added Job <default/qj-1> into Queue <default>
I1104 15:55:53.466890   66853 allocate.go:94] Try to allocate resource to 1 Namespaces
I1104 15:55:53.466897   66853 allocate.go:153] Try to allocate resource to Jobs in Namespace <default> Queue <default>
I1104 15:55:53.466905   66853 allocate.go:178] Try to allocate resource to 0 tasks of Job <default/qj-1>
I1104 15:55:53.466909   66853 statement.go:326] Committing operations ...
I1104 15:55:53.466916   66853 allocate.go:153] Try to allocate resource to Jobs in Namespace <default> Queue <default>
I1104 15:55:53.466920   66853 allocate.go:157] Can not find jobs for queue default.
I1104 15:55:53.466931   66853 allocate.go:253] Leaving Allocate ...
I1104 15:55:53.466935   66853 backfill.go:42] Enter Backfill ...
I1104 15:55:53.466940   66853 backfill.go:91] Leaving Backfill ...
I1104 15:55:53.470897   66853 session.go:154] Close Session a2c9fc34-ff5e-11e9-99a6-784f43775513
I1104 15:55:53.470908   66853 scheduler.go:87] End scheduling ...
I1104 15:55:58.471109   66853 scheduler.go:72] Start scheduling ...
I1104 15:55:58.481925   66853 cache.go:732] The priority of job <default/qj-1> is </0>
I1104 15:55:58.481945   66853 cache.go:771] There are <1> Jobs, <1> Queues and <1> Nodes in total for scheduling.
I1104 15:55:58.481950   66853 session.go:135] Open Session a5c7420c-ff5e-11e9-99a6-784f43775513 with <1> Job and <1> Queues
I1104 15:55:58.482005   66853 proportion.go:67] The total resource is <cpu 4000.00, memory 4959854592.00, hugepages-2Mi 0.00>
I1104 15:55:58.482018   66853 proportion.go:71] Considering Job <default/qj-1>.
I1104 15:55:58.482022   66853 proportion.go:85] Added Queue <default> attributes.
I1104 15:55:58.482029   66853 proportion.go:127] Considering Queue <default>: weight <1>, total weight <1>.
I1104 15:55:58.482035   66853 proportion.go:144] The attributes of queue <default> in proportion: deserved <cpu 4000.00, memory 4959854592.00, hugepages-2Mi 0.00>, allocate <cpu 0.00, memory 0.00>, request <cpu 0.00, memory 0.00>, share <0.00>
I1104 15:55:58.482047   66853 proportion.go:154] Exiting when remaining is empty:  <cpu 0.00, memory 0.00, hugepages-2Mi 0.00>
I1104 15:55:58.482065   66853 enqueue.go:43] Enter Enqueue ...
I1104 15:55:58.482069   66853 enqueue.go:58] Added Queue <default> for Job <default/qj-1>
I1104 15:55:58.482074   66853 enqueue.go:75] Try to enqueue PodGroup to 0 Queues
I1104 15:55:58.482080   66853 enqueue.go:122] Leaving Enqueue ...
I1104 15:55:58.482086   66853 allocate.go:43] Enter Allocate ...
I1104 15:55:58.482090   66853 allocate.go:90] Added Job <default/qj-1> into Queue <default>
I1104 15:55:58.482095   66853 allocate.go:94] Try to allocate resource to 1 Namespaces
I1104 15:55:58.482102   66853 allocate.go:153] Try to allocate resource to Jobs in Namespace <default> Queue <default>
I1104 15:55:58.482109   66853 allocate.go:178] Try to allocate resource to 0 tasks of Job <default/qj-1>
I1104 15:55:58.482113   66853 statement.go:326] Committing operations ...
I1104 15:55:58.482119   66853 allocate.go:153] Try to allocate resource to Jobs in Namespace <default> Queue <default>
I1104 15:55:58.482123   66853 allocate.go:157] Can not find jobs for queue default.
I1104 15:55:58.482132   66853 allocate.go:253] Leaving Allocate ...
I1104 15:55:58.482136   66853 backfill.go:42] Enter Backfill ...
I1104 15:55:58.482140   66853 backfill.go:91] Leaving Backfill ...
I1104 15:55:58.487481   66853 session.go:154] Close Session a5c7420c-ff5e-11e9-99a6-784f43775513
I1104 15:55:58.487494   66853 scheduler.go:87] End scheduling ...
I1104 15:56:03.490324   66853 scheduler.go:72] Start scheduling ...
I1104 15:56:03.504761   66853 cache.go:732] The priority of job <default/qj-1> is </0>
I1104 15:56:03.504782   66853 cache.go:771] There are <1> Jobs, <1> Queues and <1> Nodes in total for scheduling.
I1104 15:56:03.504788   66853 session.go:135] Open Session a8c5ae30-ff5e-11e9-99a6-784f43775513 with <1> Job and <1> Queues
I1104 15:56:03.504848   66853 proportion.go:67] The total resource is <cpu 4000.00, memory 4959854592.00, hugepages-2Mi 0.00>
I1104 15:56:03.504864   66853 proportion.go:71] Considering Job <default/qj-1>.
I1104 15:56:03.504869   66853 proportion.go:85] Added Queue <default> attributes.
I1104 15:56:03.504877   66853 proportion.go:127] Considering Queue <default>: weight <1>, total weight <1>.
I1104 15:56:03.504884   66853 proportion.go:144] The attributes of queue <default> in proportion: deserved <cpu 4000.00, memory 4959854592.00, hugepages-2Mi 0.00>, allocate <cpu 0.00, memory 0.00>, request <cpu 0.00, memory 0.00>, share <0.00>
I1104 15:56:03.504901   66853 proportion.go:154] Exiting when remaining is empty:  <cpu 0.00, memory 0.00, hugepages-2Mi 0.00>
I1104 15:56:03.504911   66853 enqueue.go:43] Enter Enqueue ...
I1104 15:56:03.504916   66853 enqueue.go:58] Added Queue <default> for Job <default/qj-1>
I1104 15:56:03.504923   66853 enqueue.go:75] Try to enqueue PodGroup to 0 Queues
I1104 15:56:03.504930   66853 enqueue.go:122] Leaving Enqueue ...
I1104 15:56:03.504937   66853 allocate.go:43] Enter Allocate ...
I1104 15:56:03.504942   66853 allocate.go:90] Added Job <default/qj-1> into Queue <default>
I1104 15:56:03.504948   66853 allocate.go:94] Try to allocate resource to 1 Namespaces
I1104 15:56:03.504956   66853 allocate.go:153] Try to allocate resource to Jobs in Namespace <default> Queue <default>
I1104 15:56:03.504964   66853 allocate.go:178] Try to allocate resource to 0 tasks of Job <default/qj-1>
I1104 15:56:03.504968   66853 statement.go:326] Committing operations ...
I1104 15:56:03.504976   66853 allocate.go:153] Try to allocate resource to Jobs in Namespace <default> Queue <default>
I1104 15:56:03.504982   66853 allocate.go:157] Can not find jobs for queue default.
I1104 15:56:03.504992   66853 allocate.go:253] Leaving Allocate ...
I1104 15:56:03.504998   66853 backfill.go:42] Enter Backfill ...
I1104 15:56:03.505003   66853 backfill.go:91] Leaving Backfill ...
I1104 15:56:03.508827   66853 session.go:154] Close Session a8c5ae30-ff5e-11e9-99a6-784f43775513
I1104 15:56:03.508838   66853 scheduler.go:87] End scheduling ...
I1104 15:56:08.509894   66853 scheduler.go:72] Start scheduling ...
I1104 15:56:08.520238   66853 cache.go:732] The priority of job <default/qj-1> is </0>
I1104 15:56:08.520266   66853 cache.go:771] There are <1> Jobs, <1> Queues and <1> Nodes in total for scheduling.
I1104 15:56:08.520274   66853 session.go:135] Open Session abc2f980-ff5e-11e9-99a6-784f43775513 with <1> Job and <1> Queues
I1104 15:56:08.520329   66853 proportion.go:67] The total resource is <cpu 4000.00, memory 4959854592.00, hugepages-2Mi 0.00>
I1104 15:56:08.520346   66853 proportion.go:71] Considering Job <default/qj-1>.
I1104 15:56:08.520353   66853 proportion.go:85] Added Queue <default> attributes.
I1104 15:56:08.520364   66853 proportion.go:127] Considering Queue <default>: weight <1>, total weight <1>.
I1104 15:56:08.520374   66853 proportion.go:144] The attributes of queue <default> in proportion: deserved <cpu 4000.00, memory 4959854592.00, hugepages-2Mi 0.00>, allocate <cpu 0.00, memory 0.00>, request <cpu 0.00, memory 0.00>, share <0.00>
I1104 15:56:08.520391   66853 proportion.go:154] Exiting when remaining is empty:  <cpu 0.00, memory 0.00, hugepages-2Mi 0.00>
I1104 15:56:08.520417   66853 enqueue.go:43] Enter Enqueue ...
I1104 15:56:08.520423   66853 enqueue.go:58] Added Queue <default> for Job <default/qj-1>
I1104 15:56:08.520430   66853 enqueue.go:75] Try to enqueue PodGroup to 0 Queues
I1104 15:56:08.520439   66853 enqueue.go:122] Leaving Enqueue ...
I1104 15:56:08.520447   66853 allocate.go:43] Enter Allocate ...
I1104 15:56:08.520454   66853 allocate.go:90] Added Job <default/qj-1> into Queue <default>
I1104 15:56:08.520462   66853 allocate.go:94] Try to allocate resource to 1 Namespaces
I1104 15:56:08.520473   66853 allocate.go:153] Try to allocate resource to Jobs in Namespace <default> Queue <default>
I1104 15:56:08.520483   66853 allocate.go:178] Try to allocate resource to 0 tasks of Job <default/qj-1>
I1104 15:56:08.520488   66853 statement.go:326] Committing operations ...
I1104 15:56:08.520496   66853 allocate.go:153] Try to allocate resource to Jobs in Namespace <default> Queue <default>
I1104 15:56:08.520503   66853 allocate.go:157] Can not find jobs for queue default.
I1104 15:56:08.520517   66853 allocate.go:253] Leaving Allocate ...
I1104 15:56:08.520522   66853 backfill.go:42] Enter Backfill ...
I1104 15:56:08.520529   66853 backfill.go:91] Leaving Backfill ...
I1104 15:56:08.525331   66853 session.go:154] Close Session abc2f980-ff5e-11e9-99a6-784f43775513
I1104 15:56:08.525352   66853 scheduler.go:87] End scheduling ...
I1104 15:56:13.525695   66853 scheduler.go:72] Start scheduling ...
I1104 15:56:13.536322   66853 cache.go:732] The priority of job <default/qj-1> is </0>
I1104 15:56:13.536343   66853 cache.go:771] There are <1> Jobs, <1> Queues and <1> Nodes in total for scheduling.
I1104 15:56:13.536350   66853 session.go:135] Open Session aec06032-ff5e-11e9-99a6-784f43775513 with <1> Job and <1> Queues
I1104 15:56:13.536392   66853 proportion.go:67] The total resource is <cpu 4000.00, memory 4959854592.00, hugepages-2Mi 0.00>
I1104 15:56:13.536404   66853 proportion.go:71] Considering Job <default/qj-1>.
I1104 15:56:13.536410   66853 proportion.go:85] Added Queue <default> attributes.
I1104 15:56:13.536418   66853 proportion.go:127] Considering Queue <default>: weight <1>, total weight <1>.
I1104 15:56:13.536424   66853 proportion.go:144] The attributes of queue <default> in proportion: deserved <cpu 4000.00, memory 4959854592.00, hugepages-2Mi 0.00>, allocate <cpu 0.00, memory 0.00>, request <cpu 0.00, memory 0.00>, share <0.00>
I1104 15:56:13.536435   66853 proportion.go:154] Exiting when remaining is empty:  <cpu 0.00, memory 0.00, hugepages-2Mi 0.00>
I1104 15:56:13.536452   66853 enqueue.go:43] Enter Enqueue ...
I1104 15:56:13.536456   66853 enqueue.go:58] Added Queue <default> for Job <default/qj-1>
I1104 15:56:13.536462   66853 enqueue.go:75] Try to enqueue PodGroup to 0 Queues
I1104 15:56:13.536468   66853 enqueue.go:122] Leaving Enqueue ...
I1104 15:56:13.536474   66853 allocate.go:43] Enter Allocate ...
I1104 15:56:13.536478   66853 allocate.go:90] Added Job <default/qj-1> into Queue <default>
I1104 15:56:13.536484   66853 allocate.go:94] Try to allocate resource to 1 Namespaces
I1104 15:56:13.536490   66853 allocate.go:153] Try to allocate resource to Jobs in Namespace <default> Queue <default>
I1104 15:56:13.536497   66853 allocate.go:178] Try to allocate resource to 0 tasks of Job <default/qj-1>
I1104 15:56:13.536501   66853 statement.go:326] Committing operations ...
I1104 15:56:13.536506   66853 allocate.go:153] Try to allocate resource to Jobs in Namespace <default> Queue <default>
I1104 15:56:13.536511   66853 allocate.go:157] Can not find jobs for queue default.
I1104 15:56:13.536520   66853 allocate.go:253] Leaving Allocate ...
I1104 15:56:13.536523   66853 backfill.go:42] Enter Backfill ...
I1104 15:56:13.536528   66853 backfill.go:91] Leaving Backfill ...
I1104 15:56:13.540926   66853 session.go:154] Close Session aec06032-ff5e-11e9-99a6-784f43775513
I1104 15:56:13.540940   66853 scheduler.go:87] End scheduling ...
I1104 15:56:18.541150   66853 scheduler.go:72] Start scheduling ...
I1104 15:56:18.541310   66853 cache.go:732] The priority of job <default/qj-1> is </0>
I1104 15:56:18.557809   66853 cache.go:771] There are <1> Jobs, <1> Queues and <1> Nodes in total for scheduling.
I1104 15:56:18.557820   66853 session.go:135] Open Session b1bc134e-ff5e-11e9-99a6-784f43775513 with <1> Job and <1> Queues
I1104 15:56:18.557855   66853 proportion.go:67] The total resource is <cpu 4000.00, memory 4959854592.00, hugepages-2Mi 0.00>
I1104 15:56:18.557868   66853 proportion.go:71] Considering Job <default/qj-1>.
I1104 15:56:18.557873   66853 proportion.go:85] Added Queue <default> attributes.
I1104 15:56:18.557879   66853 proportion.go:127] Considering Queue <default>: weight <1>, total weight <1>.
I1104 15:56:18.557886   66853 proportion.go:144] The attributes of queue <default> in proportion: deserved <cpu 4000.00, memory 4959854592.00, hugepages-2Mi 0.00>, allocate <cpu 0.00, memory 0.00>, request <cpu 0.00, memory 0.00>, share <0.00>
I1104 15:56:18.557899   66853 proportion.go:154] Exiting when remaining is empty:  <cpu 0.00, memory 0.00, hugepages-2Mi 0.00>
I1104 15:56:18.557926   66853 enqueue.go:43] Enter Enqueue ...
I1104 15:56:18.557930   66853 enqueue.go:58] Added Queue <default> for Job <default/qj-1>
I1104 15:56:18.557935   66853 enqueue.go:75] Try to enqueue PodGroup to 0 Queues
I1104 15:56:18.557941   66853 enqueue.go:122] Leaving Enqueue ...
I1104 15:56:18.557946   66853 allocate.go:43] Enter Allocate ...
I1104 15:56:18.557950   66853 allocate.go:90] Added Job <default/qj-1> into Queue <default>
I1104 15:56:18.557956   66853 allocate.go:94] Try to allocate resource to 1 Namespaces
I1104 15:56:18.557962   66853 allocate.go:153] Try to allocate resource to Jobs in Namespace <default> Queue <default>
I1104 15:56:18.557969   66853 allocate.go:178] Try to allocate resource to 0 tasks of Job <default/qj-1>
I1104 15:56:18.557973   66853 statement.go:326] Committing operations ...
I1104 15:56:18.557979   66853 allocate.go:153] Try to allocate resource to Jobs in Namespace <default> Queue <default>
I1104 15:56:18.557983   66853 allocate.go:157] Can not find jobs for queue default.
I1104 15:56:18.557992   66853 allocate.go:253] Leaving Allocate ...
I1104 15:56:18.557996   66853 backfill.go:42] Enter Backfill ...
I1104 15:56:18.558000   66853 backfill.go:91] Leaving Backfill ...
I1104 15:56:18.562904   66853 session.go:154] Close Session b1bc134e-ff5e-11e9-99a6-784f43775513
I1104 15:56:18.562915   66853 scheduler.go:87] End scheduling ...
I1104 15:56:23.566502   66853 scheduler.go:72] Start scheduling ...
I1104 15:56:23.579583   66853 cache.go:732] The priority of job <default/qj-1> is </0>
I1104 15:56:23.579608   66853 cache.go:771] There are <1> Jobs, <1> Queues and <1> Nodes in total for scheduling.
I1104 15:56:23.579615   66853 session.go:135] Open Session b4bcda7e-ff5e-11e9-99a6-784f43775513 with <1> Job and <1> Queues
I1104 15:56:23.579690   66853 proportion.go:67] The total resource is <cpu 4000.00, memory 4959854592.00, hugepages-2Mi 0.00>
I1104 15:56:23.579706   66853 proportion.go:71] Considering Job <default/qj-1>.
I1104 15:56:23.579712   66853 proportion.go:85] Added Queue <default> attributes.
I1104 15:56:23.579722   66853 proportion.go:127] Considering Queue <default>: weight <1>, total weight <1>.
I1104 15:56:23.579731   66853 proportion.go:144] The attributes of queue <default> in proportion: deserved <cpu 4000.00, memory 4959854592.00, hugepages-2Mi 0.00>, allocate <cpu 0.00, memory 0.00>, request <cpu 0.00, memory 0.00>, share <0.00>
I1104 15:56:23.579748   66853 proportion.go:154] Exiting when remaining is empty:  <cpu 0.00, memory 0.00, hugepages-2Mi 0.00>
I1104 15:56:23.579759   66853 enqueue.go:43] Enter Enqueue ...
I1104 15:56:23.579765   66853 enqueue.go:58] Added Queue <default> for Job <default/qj-1>
I1104 15:56:23.579773   66853 enqueue.go:75] Try to enqueue PodGroup to 0 Queues
I1104 15:56:23.579782   66853 enqueue.go:122] Leaving Enqueue ...
I1104 15:56:23.579790   66853 allocate.go:43] Enter Allocate ...
I1104 15:56:23.579797   66853 allocate.go:90] Added Job <default/qj-1> into Queue <default>
I1104 15:56:23.579805   66853 allocate.go:94] Try to allocate resource to 1 Namespaces
I1104 15:56:23.579814   66853 allocate.go:153] Try to allocate resource to Jobs in Namespace <default> Queue <default>
I1104 15:56:23.579824   66853 allocate.go:178] Try to allocate resource to 0 tasks of Job <default/qj-1>
I1104 15:56:23.579830   66853 statement.go:326] Committing operations ...
I1104 15:56:23.579838   66853 allocate.go:153] Try to allocate resource to Jobs in Namespace <default> Queue <default>
I1104 15:56:23.579844   66853 allocate.go:157] Can not find jobs for queue default.
I1104 15:56:23.579858   66853 allocate.go:253] Leaving Allocate ...
I1104 15:56:23.579863   66853 backfill.go:42] Enter Backfill ...
I1104 15:56:23.579869   66853 backfill.go:91] Leaving Backfill ...
I1104 15:56:23.584754   66853 session.go:154] Close Session b4bcda7e-ff5e-11e9-99a6-784f43775513
I1104 15:56:23.584765   66853 scheduler.go:87] End scheduling ...
I1104 15:56:28.589123   66853 scheduler.go:72] Start scheduling ...
I1104 15:56:28.597433   66853 cache.go:732] The priority of job <default/qj-1> is </0>
I1104 15:56:28.597455   66853 cache.go:771] There are <1> Jobs, <1> Queues and <1> Nodes in total for scheduling.
I1104 15:56:28.597461   66853 session.go:135] Open Session b7ba84d8-ff5e-11e9-99a6-784f43775513 with <1> Job and <1> Queues
I1104 15:56:28.597506   66853 proportion.go:67] The total resource is <cpu 4000.00, memory 4959854592.00, hugepages-2Mi 0.00>
I1104 15:56:28.597520   66853 proportion.go:71] Considering Job <default/qj-1>.
I1104 15:56:28.597526   66853 proportion.go:85] Added Queue <default> attributes.
I1104 15:56:28.597534   66853 proportion.go:127] Considering Queue <default>: weight <1>, total weight <1>.
I1104 15:56:28.597542   66853 proportion.go:144] The attributes of queue <default> in proportion: deserved <cpu 4000.00, memory 4959854592.00, hugepages-2Mi 0.00>, allocate <cpu 0.00, memory 0.00>, request <cpu 0.00, memory 0.00>, share <0.00>
I1104 15:56:28.597555   66853 proportion.go:154] Exiting when remaining is empty:  <cpu 0.00, memory 0.00, hugepages-2Mi 0.00>
I1104 15:56:28.597578   66853 enqueue.go:43] Enter Enqueue ...
I1104 15:56:28.597582   66853 enqueue.go:58] Added Queue <default> for Job <default/qj-1>
I1104 15:56:28.597588   66853 enqueue.go:75] Try to enqueue PodGroup to 0 Queues
I1104 15:56:28.597595   66853 enqueue.go:122] Leaving Enqueue ...
I1104 15:56:28.597602   66853 allocate.go:43] Enter Allocate ...
I1104 15:56:28.597607   66853 allocate.go:90] Added Job <default/qj-1> into Queue <default>
I1104 15:56:28.597614   66853 allocate.go:94] Try to allocate resource to 1 Namespaces
I1104 15:56:28.597622   66853 allocate.go:153] Try to allocate resource to Jobs in Namespace <default> Queue <default>
I1104 15:56:28.597630   66853 allocate.go:178] Try to allocate resource to 0 tasks of Job <default/qj-1>
I1104 15:56:28.597634   66853 statement.go:326] Committing operations ...
I1104 15:56:28.597641   66853 allocate.go:153] Try to allocate resource to Jobs in Namespace <default> Queue <default>
I1104 15:56:28.597646   66853 allocate.go:157] Can not find jobs for queue default.
I1104 15:56:28.597656   66853 allocate.go:253] Leaving Allocate ...
I1104 15:56:28.597661   66853 backfill.go:42] Enter Backfill ...
I1104 15:56:28.597667   66853 backfill.go:91] Leaving Backfill ...
I1104 15:56:28.601603   66853 session.go:154] Close Session b7ba84d8-ff5e-11e9-99a6-784f43775513
I1104 15:56:28.601613   66853 scheduler.go:87] End scheduling ...
I1104 15:56:33.604380   66853 scheduler.go:72] Start scheduling ...
I1104 15:56:33.610561   66853 cache.go:732] The priority of job <default/qj-1> is </0>
I1104 15:56:33.610578   66853 cache.go:771] There are <1> Jobs, <1> Queues and <1> Nodes in total for scheduling.
I1104 15:56:33.610582   66853 session.go:135] Open Session bab77678-ff5e-11e9-99a6-784f43775513 with <1> Job and <1> Queues
I1104 15:56:33.610621   66853 proportion.go:67] The total resource is <cpu 4000.00, memory 4959854592.00, hugepages-2Mi 0.00>
I1104 15:56:33.610632   66853 proportion.go:71] Considering Job <default/qj-1>.
I1104 15:56:33.610637   66853 proportion.go:85] Added Queue <default> attributes.
I1104 15:56:33.610643   66853 proportion.go:127] Considering Queue <default>: weight <1>, total weight <1>.
I1104 15:56:33.610649   66853 proportion.go:144] The attributes of queue <default> in proportion: deserved <cpu 4000.00, memory 4959854592.00, hugepages-2Mi 0.00>, allocate <cpu 0.00, memory 0.00>, request <cpu 0.00, memory 0.00>, share <0.00>
I1104 15:56:33.610659   66853 proportion.go:154] Exiting when remaining is empty:  <cpu 0.00, memory 0.00, hugepages-2Mi 0.00>
I1104 15:56:33.610675   66853 enqueue.go:43] Enter Enqueue ...
I1104 15:56:33.610679   66853 enqueue.go:58] Added Queue <default> for Job <default/qj-1>
I1104 15:56:33.610683   66853 enqueue.go:75] Try to enqueue PodGroup to 0 Queues
I1104 15:56:33.610689   66853 enqueue.go:122] Leaving Enqueue ...
I1104 15:56:33.610694   66853 allocate.go:43] Enter Allocate ...
I1104 15:56:33.610698   66853 allocate.go:90] Added Job <default/qj-1> into Queue <default>
I1104 15:56:33.610703   66853 allocate.go:94] Try to allocate resource to 1 Namespaces
I1104 15:56:33.610709   66853 allocate.go:153] Try to allocate resource to Jobs in Namespace <default> Queue <default>
I1104 15:56:33.610715   66853 allocate.go:178] Try to allocate resource to 0 tasks of Job <default/qj-1>
I1104 15:56:33.610718   66853 statement.go:326] Committing operations ...
I1104 15:56:33.610723   66853 allocate.go:153] Try to allocate resource to Jobs in Namespace <default> Queue <default>
I1104 15:56:33.610729   66853 allocate.go:157] Can not find jobs for queue default.
I1104 15:56:33.610737   66853 allocate.go:253] Leaving Allocate ...
I1104 15:56:33.610741   66853 backfill.go:42] Enter Backfill ...
I1104 15:56:33.610744   66853 backfill.go:91] Leaving Backfill ...
I1104 15:56:33.624780   66853 session.go:154] Close Session bab77678-ff5e-11e9-99a6-784f43775513
I1104 15:56:33.624791   66853 scheduler.go:87] End scheduling ...
I1104 15:56:38.629764   66853 scheduler.go:72] Start scheduling ...
I1104 15:56:38.629901   66853 cache.go:732] The priority of job <default/qj-1> is </0>
I1104 15:56:38.629920   66853 cache.go:771] There are <1> Jobs, <1> Queues and <1> Nodes in total for scheduling.
I1104 15:56:38.629925   66853 session.go:135] Open Session bdb55a7a-ff5e-11e9-99a6-784f43775513 with <1> Job and <1> Queues
I1104 15:56:38.629968   66853 proportion.go:67] The total resource is <cpu 4000.00, memory 4959854592.00, hugepages-2Mi 0.00>
I1104 15:56:38.629980   66853 proportion.go:71] Considering Job <default/qj-1>.
I1104 15:56:38.629985   66853 proportion.go:85] Added Queue <default> attributes.
I1104 15:56:38.629993   66853 proportion.go:127] Considering Queue <default>: weight <1>, total weight <1>.
I1104 15:56:38.630000   66853 proportion.go:144] The attributes of queue <default> in proportion: deserved <cpu 4000.00, memory 4959854592.00, hugepages-2Mi 0.00>, allocate <cpu 0.00, memory 0.00>, request <cpu 0.00, memory 0.00>, share <0.00>
I1104 15:56:38.630013   66853 proportion.go:154] Exiting when remaining is empty:  <cpu 0.00, memory 0.00, hugepages-2Mi 0.00>
I1104 15:56:38.630034   66853 enqueue.go:43] Enter Enqueue ...
I1104 15:56:38.630039   66853 enqueue.go:58] Added Queue <default> for Job <default/qj-1>
I1104 15:56:38.630044   66853 enqueue.go:75] Try to enqueue PodGroup to 0 Queues
I1104 15:56:38.630054   66853 enqueue.go:122] Leaving Enqueue ...
I1104 15:56:38.630060   66853 allocate.go:43] Enter Allocate ...
I1104 15:56:38.630066   66853 allocate.go:90] Added Job <default/qj-1> into Queue <default>
I1104 15:56:38.630073   66853 allocate.go:94] Try to allocate resource to 1 Namespaces
I1104 15:56:38.630081   66853 allocate.go:153] Try to allocate resource to Jobs in Namespace <default> Queue <default>
I1104 15:56:38.630089   66853 allocate.go:178] Try to allocate resource to 0 tasks of Job <default/qj-1>
I1104 15:56:38.630094   66853 statement.go:326] Committing operations ...
I1104 15:56:38.630100   66853 allocate.go:153] Try to allocate resource to Jobs in Namespace <default> Queue <default>
I1104 15:56:38.630105   66853 allocate.go:157] Can not find jobs for queue default.
I1104 15:56:38.630119   66853 allocate.go:253] Leaving Allocate ...
I1104 15:56:38.630123   66853 backfill.go:42] Enter Backfill ...
I1104 15:56:38.630128   66853 backfill.go:91] Leaving Backfill ...
I1104 15:56:38.633902   66853 session.go:154] Close Session bdb55a7a-ff5e-11e9-99a6-784f43775513
I1104 15:56:38.633913   66853 scheduler.go:87] End scheduling ...
I1104 15:56:43.635231   66853 scheduler.go:72] Start scheduling ...
I1104 15:56:43.643657   66853 cache.go:732] The priority of job <default/qj-1> is </0>
I1104 15:56:43.643677   66853 cache.go:771] There are <1> Jobs, <1> Queues and <1> Nodes in total for scheduling.
I1104 15:56:43.643683   66853 session.go:135] Open Session c0b26402-ff5e-11e9-99a6-784f43775513 with <1> Job and <1> Queues
I1104 15:56:43.643720   66853 proportion.go:67] The total resource is <cpu 4000.00, memory 4959854592.00, hugepages-2Mi 0.00>
I1104 15:56:43.643731   66853 proportion.go:71] Considering Job <default/qj-1>.
I1104 15:56:43.643736   66853 proportion.go:85] Added Queue <default> attributes.
I1104 15:56:43.643746   66853 proportion.go:127] Considering Queue <default>: weight <1>, total weight <1>.
I1104 15:56:43.643753   66853 proportion.go:144] The attributes of queue <default> in proportion: deserved <cpu 4000.00, memory 4959854592.00, hugepages-2Mi 0.00>, allocate <cpu 0.00, memory 0.00>, request <cpu 0.00, memory 0.00>, share <0.00>
I1104 15:56:43.643764   66853 proportion.go:154] Exiting when remaining is empty:  <cpu 0.00, memory 0.00, hugepages-2Mi 0.00>
I1104 15:56:43.643783   66853 enqueue.go:43] Enter Enqueue ...
I1104 15:56:43.643787   66853 enqueue.go:58] Added Queue <default> for Job <default/qj-1>
I1104 15:56:43.643792   66853 enqueue.go:75] Try to enqueue PodGroup to 0 Queues
I1104 15:56:43.643798   66853 enqueue.go:122] Leaving Enqueue ...
I1104 15:56:43.643803   66853 allocate.go:43] Enter Allocate ...
I1104 15:56:43.643808   66853 allocate.go:90] Added Job <default/qj-1> into Queue <default>
I1104 15:56:43.643813   66853 allocate.go:94] Try to allocate resource to 1 Namespaces
I1104 15:56:43.643820   66853 allocate.go:153] Try to allocate resource to Jobs in Namespace <default> Queue <default>
I1104 15:56:43.643826   66853 allocate.go:178] Try to allocate resource to 0 tasks of Job <default/qj-1>
I1104 15:56:43.643830   66853 statement.go:326] Committing operations ...
I1104 15:56:43.643835   66853 allocate.go:153] Try to allocate resource to Jobs in Namespace <default> Queue <default>
I1104 15:56:43.643840   66853 allocate.go:157] Can not find jobs for queue default.
I1104 15:56:43.643849   66853 allocate.go:253] Leaving Allocate ...
I1104 15:56:43.643852   66853 backfill.go:42] Enter Backfill ...
I1104 15:56:43.643857   66853 backfill.go:91] Leaving Backfill ...
I1104 15:56:43.648567   66853 session.go:154] Close Session c0b26402-ff5e-11e9-99a6-784f43775513
I1104 15:56:43.648579   66853 scheduler.go:87] End scheduling ...
I1104 15:56:48.652197   66853 scheduler.go:72] Start scheduling ...
I1104 15:56:48.659312   66853 cache.go:732] The priority of job <default/qj-1> is </0>
I1104 15:56:48.659340   66853 cache.go:771] There are <1> Jobs, <1> Queues and <1> Nodes in total for scheduling.
I1104 15:56:48.659347   66853 session.go:135] Open Session c3afb790-ff5e-11e9-99a6-784f43775513 with <1> Job and <1> Queues
I1104 15:56:48.659405   66853 proportion.go:67] The total resource is <cpu 4000.00, memory 4959854592.00, hugepages-2Mi 0.00>
I1104 15:56:48.659473   66853 proportion.go:71] Considering Job <default/qj-1>.
I1104 15:56:48.659483   66853 proportion.go:85] Added Queue <default> attributes.
I1104 15:56:48.659493   66853 proportion.go:127] Considering Queue <default>: weight <1>, total weight <1>.
I1104 15:56:48.659504   66853 proportion.go:144] The attributes of queue <default> in proportion: deserved <cpu 4000.00, memory 4959854592.00, hugepages-2Mi 0.00>, allocate <cpu 0.00, memory 0.00>, request <cpu 0.00, memory 0.00>, share <0.00>
I1104 15:56:48.659530   66853 proportion.go:154] Exiting when remaining is empty:  <cpu 0.00, memory 0.00, hugepages-2Mi 0.00>
I1104 15:56:48.659574   66853 enqueue.go:43] Enter Enqueue ...
I1104 15:56:48.659580   66853 enqueue.go:58] Added Queue <default> for Job <default/qj-1>
I1104 15:56:48.659588   66853 enqueue.go:75] Try to enqueue PodGroup to 0 Queues
I1104 15:56:48.659599   66853 enqueue.go:122] Leaving Enqueue ...
I1104 15:56:48.659608   66853 allocate.go:43] Enter Allocate ...
I1104 15:56:48.659615   66853 allocate.go:90] Added Job <default/qj-1> into Queue <default>
I1104 15:56:48.659624   66853 allocate.go:94] Try to allocate resource to 1 Namespaces
I1104 15:56:48.659635   66853 allocate.go:153] Try to allocate resource to Jobs in Namespace <default> Queue <default>
I1104 15:56:48.659647   66853 allocate.go:178] Try to allocate resource to 0 tasks of Job <default/qj-1>
I1104 15:56:48.659654   66853 statement.go:326] Committing operations ...
I1104 15:56:48.659663   66853 allocate.go:153] Try to allocate resource to Jobs in Namespace <default> Queue <default>
I1104 15:56:48.659671   66853 allocate.go:157] Can not find jobs for queue default.
I1104 15:56:48.659687   66853 allocate.go:253] Leaving Allocate ...
I1104 15:56:48.659694   66853 backfill.go:42] Enter Backfill ...
I1104 15:56:48.659701   66853 backfill.go:91] Leaving Backfill ...
I1104 15:56:48.663367   66853 session.go:154] Close Session c3afb790-ff5e-11e9-99a6-784f43775513
I1104 15:56:48.663377   66853 scheduler.go:87] End scheduling ...
I1104 15:56:53.663761   66853 scheduler.go:72] Start scheduling ...
I1104 15:56:53.674608   66853 cache.go:732] The priority of job <default/qj-1> is </0>
I1104 15:56:53.674627   66853 cache.go:771] There are <1> Jobs, <1> Queues and <1> Nodes in total for scheduling.
I1104 15:56:53.674632   66853 session.go:135] Open Session c6acfe44-ff5e-11e9-99a6-784f43775513 with <1> Job and <1> Queues
I1104 15:56:53.674670   66853 proportion.go:67] The total resource is <cpu 4000.00, memory 4959854592.00, hugepages-2Mi 0.00>
I1104 15:56:53.674681   66853 proportion.go:71] Considering Job <default/qj-1>.
I1104 15:56:53.674685   66853 proportion.go:85] Added Queue <default> attributes.
I1104 15:56:53.674692   66853 proportion.go:127] Considering Queue <default>: weight <1>, total weight <1>.
I1104 15:56:53.674698   66853 proportion.go:144] The attributes of queue <default> in proportion: deserved <cpu 4000.00, memory 4959854592.00, hugepages-2Mi 0.00>, allocate <cpu 0.00, memory 0.00>, request <cpu 0.00, memory 0.00>, share <0.00>
I1104 15:56:53.674709   66853 proportion.go:154] Exiting when remaining is empty:  <cpu 0.00, memory 0.00, hugepages-2Mi 0.00>
I1104 15:56:53.674729   66853 enqueue.go:43] Enter Enqueue ...
I1104 15:56:53.674733   66853 enqueue.go:58] Added Queue <default> for Job <default/qj-1>
I1104 15:56:53.674738   66853 enqueue.go:75] Try to enqueue PodGroup to 0 Queues
I1104 15:56:53.674745   66853 enqueue.go:122] Leaving Enqueue ...
I1104 15:56:53.674750   66853 allocate.go:43] Enter Allocate ...
I1104 15:56:53.674755   66853 allocate.go:90] Added Job <default/qj-1> into Queue <default>
I1104 15:56:53.674761   66853 allocate.go:94] Try to allocate resource to 1 Namespaces
I1104 15:56:53.674767   66853 allocate.go:153] Try to allocate resource to Jobs in Namespace <default> Queue <default>
I1104 15:56:53.674774   66853 allocate.go:178] Try to allocate resource to 0 tasks of Job <default/qj-1>
I1104 15:56:53.674780   66853 statement.go:326] Committing operations ...
I1104 15:56:53.674785   66853 allocate.go:153] Try to allocate resource to Jobs in Namespace <default> Queue <default>
I1104 15:56:53.674789   66853 allocate.go:157] Can not find jobs for queue default.
I1104 15:56:53.674799   66853 allocate.go:253] Leaving Allocate ...
I1104 15:56:53.674802   66853 backfill.go:42] Enter Backfill ...
I1104 15:56:53.674806   66853 backfill.go:91] Leaving Backfill ...
I1104 15:56:53.678674   66853 session.go:154] Close Session c6acfe44-ff5e-11e9-99a6-784f43775513
I1104 15:56:53.678684   66853 scheduler.go:87] End scheduling ...
I1104 15:56:58.680878   66853 scheduler.go:72] Start scheduling ...
I1104 15:56:58.693596   66853 cache.go:732] The priority of job <default/qj-1> is </0>
I1104 15:56:58.693614   66853 cache.go:771] There are <1> Jobs, <1> Queues and <1> Nodes in total for scheduling.
I1104 15:56:58.693618   66853 session.go:135] Open Session c9aad472-ff5e-11e9-99a6-784f43775513 with <1> Job and <1> Queues
I1104 15:56:58.693654   66853 proportion.go:67] The total resource is <cpu 4000.00, memory 4959854592.00, hugepages-2Mi 0.00>
I1104 15:56:58.693665   66853 proportion.go:71] Considering Job <default/qj-1>.
I1104 15:56:58.693670   66853 proportion.go:85] Added Queue <default> attributes.
I1104 15:56:58.693676   66853 proportion.go:127] Considering Queue <default>: weight <1>, total weight <1>.
I1104 15:56:58.693683   66853 proportion.go:144] The attributes of queue <default> in proportion: deserved <cpu 4000.00, memory 4959854592.00, hugepages-2Mi 0.00>, allocate <cpu 0.00, memory 0.00>, request <cpu 0.00, memory 0.00>, share <0.00>
I1104 15:56:58.693696   66853 proportion.go:154] Exiting when remaining is empty:  <cpu 0.00, memory 0.00, hugepages-2Mi 0.00>
I1104 15:56:58.693714   66853 enqueue.go:43] Enter Enqueue ...
I1104 15:56:58.693718   66853 enqueue.go:58] Added Queue <default> for Job <default/qj-1>
I1104 15:56:58.693722   66853 enqueue.go:75] Try to enqueue PodGroup to 0 Queues
I1104 15:56:58.693729   66853 enqueue.go:122] Leaving Enqueue ...
I1104 15:56:58.693734   66853 allocate.go:43] Enter Allocate ...
I1104 15:56:58.693738   66853 allocate.go:90] Added Job <default/qj-1> into Queue <default>
I1104 15:56:58.693743   66853 allocate.go:94] Try to allocate resource to 1 Namespaces
I1104 15:56:58.693750   66853 allocate.go:153] Try to allocate resource to Jobs in Namespace <default> Queue <default>
I1104 15:56:58.693757   66853 allocate.go:178] Try to allocate resource to 0 tasks of Job <default/qj-1>
I1104 15:56:58.693760   66853 statement.go:326] Committing operations ...
I1104 15:56:58.693765   66853 allocate.go:153] Try to allocate resource to Jobs in Namespace <default> Queue <default>
I1104 15:56:58.693769   66853 allocate.go:157] Can not find jobs for queue default.
I1104 15:56:58.693778   66853 allocate.go:253] Leaving Allocate ...
I1104 15:56:58.693781   66853 backfill.go:42] Enter Backfill ...
I1104 15:56:58.693786   66853 backfill.go:91] Leaving Backfill ...
I1104 15:56:58.700886   66853 session.go:154] Close Session c9aad472-ff5e-11e9-99a6-784f43775513
I1104 15:56:58.700897   66853 scheduler.go:87] End scheduling ...
I1104 15:57:03.704893   66853 scheduler.go:72] Start scheduling ...
I1104 15:57:03.706830   66853 cache.go:732] The priority of job <default/qj-1> is </0>
I1104 15:57:03.706859   66853 cache.go:771] There are <1> Jobs, <1> Queues and <1> Nodes in total for scheduling.
I1104 15:57:03.706866   66853 session.go:135] Open Session cca7c93c-ff5e-11e9-99a6-784f43775513 with <1> Job and <1> Queues
I1104 15:57:03.706918   66853 proportion.go:67] The total resource is <cpu 4000.00, memory 4959854592.00, hugepages-2Mi 0.00>
I1104 15:57:03.706933   66853 proportion.go:71] Considering Job <default/qj-1>.
I1104 15:57:03.706939   66853 proportion.go:85] Added Queue <default> attributes.
I1104 15:57:03.706949   66853 proportion.go:127] Considering Queue <default>: weight <1>, total weight <1>.
I1104 15:57:03.706959   66853 proportion.go:144] The attributes of queue <default> in proportion: deserved <cpu 4000.00, memory 4959854592.00, hugepages-2Mi 0.00>, allocate <cpu 0.00, memory 0.00>, request <cpu 0.00, memory 0.00>, share <0.00>
I1104 15:57:03.706976   66853 proportion.go:154] Exiting when remaining is empty:  <cpu 0.00, memory 0.00, hugepages-2Mi 0.00>
I1104 15:57:03.707006   66853 enqueue.go:43] Enter Enqueue ...
I1104 15:57:03.707012   66853 enqueue.go:58] Added Queue <default> for Job <default/qj-1>
I1104 15:57:03.707019   66853 enqueue.go:75] Try to enqueue PodGroup to 0 Queues
I1104 15:57:03.707030   66853 enqueue.go:122] Leaving Enqueue ...
I1104 15:57:03.707038   66853 allocate.go:43] Enter Allocate ...
I1104 15:57:03.707045   66853 allocate.go:90] Added Job <default/qj-1> into Queue <default>
I1104 15:57:03.707054   66853 allocate.go:94] Try to allocate resource to 1 Namespaces
I1104 15:57:03.707064   66853 allocate.go:153] Try to allocate resource to Jobs in Namespace <default> Queue <default>
I1104 15:57:03.707075   66853 allocate.go:178] Try to allocate resource to 0 tasks of Job <default/qj-1>
I1104 15:57:03.707081   66853 statement.go:326] Committing operations ...
I1104 15:57:03.707088   66853 allocate.go:153] Try to allocate resource to Jobs in Namespace <default> Queue <default>
I1104 15:57:03.707095   66853 allocate.go:157] Can not find jobs for queue default.
I1104 15:57:03.707109   66853 allocate.go:253] Leaving Allocate ...
I1104 15:57:03.707114   66853 backfill.go:42] Enter Backfill ...
I1104 15:57:03.707120   66853 backfill.go:91] Leaving Backfill ...
I1104 15:57:03.711103   66853 session.go:154] Close Session cca7c93c-ff5e-11e9-99a6-784f43775513
I1104 15:57:03.711114   66853 scheduler.go:87] End scheduling ...
I1104 15:57:08.713340   66853 scheduler.go:72] Start scheduling ...
I1104 15:57:08.725047   66853 cache.go:732] The priority of job <default/qj-1> is </0>
I1104 15:57:08.725091   66853 cache.go:771] There are <1> Jobs, <1> Queues and <1> Nodes in total for scheduling.
I1104 15:57:08.725099   66853 session.go:135] Open Session cfa5808e-ff5e-11e9-99a6-784f43775513 with <1> Job and <1> Queues
I1104 15:57:08.725170   66853 proportion.go:67] The total resource is <cpu 4000.00, memory 4959854592.00, hugepages-2Mi 0.00>
I1104 15:57:08.725183   66853 proportion.go:71] Considering Job <default/qj-1>.
I1104 15:57:08.725188   66853 proportion.go:85] Added Queue <default> attributes.
I1104 15:57:08.725195   66853 proportion.go:127] Considering Queue <default>: weight <1>, total weight <1>.
I1104 15:57:08.725202   66853 proportion.go:144] The attributes of queue <default> in proportion: deserved <cpu 4000.00, memory 4959854592.00, hugepages-2Mi 0.00>, allocate <cpu 0.00, memory 0.00>, request <cpu 0.00, memory 0.00>, share <0.00>
I1104 15:57:08.725213   66853 proportion.go:154] Exiting when remaining is empty:  <cpu 0.00, memory 0.00, hugepages-2Mi 0.00>
I1104 15:57:08.725233   66853 enqueue.go:43] Enter Enqueue ...
I1104 15:57:08.725237   66853 enqueue.go:58] Added Queue <default> for Job <default/qj-1>
I1104 15:57:08.725242   66853 enqueue.go:75] Try to enqueue PodGroup to 0 Queues
I1104 15:57:08.725248   66853 enqueue.go:122] Leaving Enqueue ...
I1104 15:57:08.725254   66853 allocate.go:43] Enter Allocate ...
I1104 15:57:08.725258   66853 allocate.go:90] Added Job <default/qj-1> into Queue <default>
I1104 15:57:08.725264   66853 allocate.go:94] Try to allocate resource to 1 Namespaces
I1104 15:57:08.725270   66853 allocate.go:153] Try to allocate resource to Jobs in Namespace <default> Queue <default>
I1104 15:57:08.725277   66853 allocate.go:178] Try to allocate resource to 0 tasks of Job <default/qj-1>
I1104 15:57:08.725281   66853 statement.go:326] Committing operations ...
I1104 15:57:08.725287   66853 allocate.go:153] Try to allocate resource to Jobs in Namespace <default> Queue <default>
I1104 15:57:08.725291   66853 allocate.go:157] Can not find jobs for queue default.
I1104 15:57:08.725300   66853 allocate.go:253] Leaving Allocate ...
I1104 15:57:08.725304   66853 backfill.go:42] Enter Backfill ...
I1104 15:57:08.725308   66853 backfill.go:91] Leaving Backfill ...
I1104 15:57:08.729087   66853 session.go:154] Close Session cfa5808e-ff5e-11e9-99a6-784f43775513
I1104 15:57:08.729098   66853 scheduler.go:87] End scheduling ...
I1104 15:57:13.731682   66853 scheduler.go:72] Start scheduling ...
I1104 15:57:13.744463   66853 cache.go:732] The priority of job <default/qj-1> is </0>
I1104 15:57:13.744481   66853 cache.go:771] There are <1> Jobs, <1> Queues and <1> Nodes in total for scheduling.
I1104 15:57:13.744486   66853 session.go:135] Open Session d2a368c8-ff5e-11e9-99a6-784f43775513 with <1> Job and <1> Queues
I1104 15:57:13.744526   66853 proportion.go:67] The total resource is <cpu 4000.00, memory 4959854592.00, hugepages-2Mi 0.00>
I1104 15:57:13.744537   66853 proportion.go:71] Considering Job <default/qj-1>.
I1104 15:57:13.744542   66853 proportion.go:85] Added Queue <default> attributes.
I1104 15:57:13.744548   66853 proportion.go:127] Considering Queue <default>: weight <1>, total weight <1>.
I1104 15:57:13.744555   66853 proportion.go:144] The attributes of queue <default> in proportion: deserved <cpu 4000.00, memory 4959854592.00, hugepages-2Mi 0.00>, allocate <cpu 0.00, memory 0.00>, request <cpu 0.00, memory 0.00>, share <0.00>
I1104 15:57:13.744566   66853 proportion.go:154] Exiting when remaining is empty:  <cpu 0.00, memory 0.00, hugepages-2Mi 0.00>
I1104 15:57:13.744584   66853 enqueue.go:43] Enter Enqueue ...
I1104 15:57:13.744588   66853 enqueue.go:58] Added Queue <default> for Job <default/qj-1>
I1104 15:57:13.744593   66853 enqueue.go:75] Try to enqueue PodGroup to 0 Queues
I1104 15:57:13.744599   66853 enqueue.go:122] Leaving Enqueue ...
I1104 15:57:13.744604   66853 allocate.go:43] Enter Allocate ...
I1104 15:57:13.744609   66853 allocate.go:90] Added Job <default/qj-1> into Queue <default>
I1104 15:57:13.744616   66853 allocate.go:94] Try to allocate resource to 1 Namespaces
I1104 15:57:13.744623   66853 allocate.go:153] Try to allocate resource to Jobs in Namespace <default> Queue <default>
I1104 15:57:13.744629   66853 allocate.go:178] Try to allocate resource to 0 tasks of Job <default/qj-1>
I1104 15:57:13.744634   66853 statement.go:326] Committing operations ...
I1104 15:57:13.744639   66853 allocate.go:153] Try to allocate resource to Jobs in Namespace <default> Queue <default>
I1104 15:57:13.744643   66853 allocate.go:157] Can not find jobs for queue default.
I1104 15:57:13.744668   66853 allocate.go:253] Leaving Allocate ...
I1104 15:57:13.744677   66853 backfill.go:42] Enter Backfill ...
I1104 15:57:13.744684   66853 backfill.go:91] Leaving Backfill ...
I1104 15:57:13.748530   66853 session.go:154] Close Session d2a368c8-ff5e-11e9-99a6-784f43775513
I1104 15:57:13.748541   66853 scheduler.go:87] End scheduling ...
I1104 15:57:18.751173   66853 scheduler.go:72] Start scheduling ...
I1104 15:57:18.761202   66853 cache.go:732] The priority of job <default/qj-1> is </0>
I1104 15:57:18.761229   66853 cache.go:771] There are <1> Jobs, <1> Queues and <1> Nodes in total for scheduling.
I1104 15:57:18.761236   66853 session.go:135] Open Session d5a0e5e6-ff5e-11e9-99a6-784f43775513 with <1> Job and <1> Queues
I1104 15:57:18.761286   66853 proportion.go:67] The total resource is <cpu 4000.00, memory 4959854592.00, hugepages-2Mi 0.00>
I1104 15:57:18.761303   66853 proportion.go:71] Considering Job <default/qj-1>.
I1104 15:57:18.761310   66853 proportion.go:85] Added Queue <default> attributes.
I1104 15:57:18.761319   66853 proportion.go:127] Considering Queue <default>: weight <1>, total weight <1>.
I1104 15:57:18.761329   66853 proportion.go:144] The attributes of queue <default> in proportion: deserved <cpu 4000.00, memory 4959854592.00, hugepages-2Mi 0.00>, allocate <cpu 0.00, memory 0.00>, request <cpu 0.00, memory 0.00>, share <0.00>
I1104 15:57:18.761346   66853 proportion.go:154] Exiting when remaining is empty:  <cpu 0.00, memory 0.00, hugepages-2Mi 0.00>
I1104 15:57:18.761378   66853 enqueue.go:43] Enter Enqueue ...
I1104 15:57:18.761384   66853 enqueue.go:58] Added Queue <default> for Job <default/qj-1>
I1104 15:57:18.761392   66853 enqueue.go:75] Try to enqueue PodGroup to 0 Queues
I1104 15:57:18.761401   66853 enqueue.go:122] Leaving Enqueue ...
I1104 15:57:18.761409   66853 allocate.go:43] Enter Allocate ...
I1104 15:57:18.761415   66853 allocate.go:90] Added Job <default/qj-1> into Queue <default>
I1104 15:57:18.761423   66853 allocate.go:94] Try to allocate resource to 1 Namespaces
I1104 15:57:18.761433   66853 allocate.go:153] Try to allocate resource to Jobs in Namespace <default> Queue <default>
I1104 15:57:18.761443   66853 allocate.go:178] Try to allocate resource to 0 tasks of Job <default/qj-1>
I1104 15:57:18.761448   66853 statement.go:326] Committing operations ...
I1104 15:57:18.761456   66853 allocate.go:153] Try to allocate resource to Jobs in Namespace <default> Queue <default>
I1104 15:57:18.761463   66853 allocate.go:157] Can not find jobs for queue default.
I1104 15:57:18.761476   66853 allocate.go:253] Leaving Allocate ...
I1104 15:57:18.761482   66853 backfill.go:42] Enter Backfill ...
I1104 15:57:18.761488   66853 backfill.go:91] Leaving Backfill ...
I1104 15:57:18.766099   66853 session.go:154] Close Session d5a0e5e6-ff5e-11e9-99a6-784f43775513
I1104 15:57:18.766109   66853 scheduler.go:87] End scheduling ...
I1104 15:57:23.766382   66853 scheduler.go:72] Start scheduling ...
I1104 15:57:23.777631   66853 cache.go:732] The priority of job <default/qj-1> is </0>
I1104 15:57:23.777654   66853 cache.go:771] There are <1> Jobs, <1> Queues and <1> Nodes in total for scheduling.
I1104 15:57:23.777660   66853 session.go:135] Open Session d89e5936-ff5e-11e9-99a6-784f43775513 with <1> Job and <1> Queues
I1104 15:57:23.777708   66853 proportion.go:67] The total resource is <cpu 4000.00, memory 4959854592.00, hugepages-2Mi 0.00>
I1104 15:57:23.777722   66853 proportion.go:71] Considering Job <default/qj-1>.
I1104 15:57:23.777727   66853 proportion.go:85] Added Queue <default> attributes.
I1104 15:57:23.777735   66853 proportion.go:127] Considering Queue <default>: weight <1>, total weight <1>.
I1104 15:57:23.777742   66853 proportion.go:144] The attributes of queue <default> in proportion: deserved <cpu 4000.00, memory 4959854592.00, hugepages-2Mi 0.00>, allocate <cpu 0.00, memory 0.00>, request <cpu 0.00, memory 0.00>, share <0.00>
I1104 15:57:23.777756   66853 proportion.go:154] Exiting when remaining is empty:  <cpu 0.00, memory 0.00, hugepages-2Mi 0.00>
I1104 15:57:23.777777   66853 enqueue.go:43] Enter Enqueue ...
I1104 15:57:23.777782   66853 enqueue.go:58] Added Queue <default> for Job <default/qj-1>
I1104 15:57:23.777788   66853 enqueue.go:75] Try to enqueue PodGroup to 0 Queues
I1104 15:57:23.777795   66853 enqueue.go:122] Leaving Enqueue ...
I1104 15:57:23.777802   66853 allocate.go:43] Enter Allocate ...
I1104 15:57:23.777807   66853 allocate.go:90] Added Job <default/qj-1> into Queue <default>
I1104 15:57:23.777813   66853 allocate.go:94] Try to allocate resource to 1 Namespaces
I1104 15:57:23.777821   66853 allocate.go:153] Try to allocate resource to Jobs in Namespace <default> Queue <default>
I1104 15:57:23.777829   66853 allocate.go:178] Try to allocate resource to 0 tasks of Job <default/qj-1>
I1104 15:57:23.777834   66853 statement.go:326] Committing operations ...
I1104 15:57:23.777840   66853 allocate.go:153] Try to allocate resource to Jobs in Namespace <default> Queue <default>
I1104 15:57:23.777845   66853 allocate.go:157] Can not find jobs for queue default.
I1104 15:57:23.777856   66853 allocate.go:253] Leaving Allocate ...
I1104 15:57:23.777860   66853 backfill.go:42] Enter Backfill ...
I1104 15:57:23.777865   66853 backfill.go:91] Leaving Backfill ...
I1104 15:57:23.781714   66853 session.go:154] Close Session d89e5936-ff5e-11e9-99a6-784f43775513
I1104 15:57:23.781724   66853 scheduler.go:87] End scheduling ...
I1104 15:57:28.782061   66853 scheduler.go:72] Start scheduling ...
I1104 15:57:28.792937   66853 cache.go:732] The priority of job <default/qj-1> is </0>
I1104 15:57:28.792957   66853 cache.go:771] There are <1> Jobs, <1> Queues and <1> Nodes in total for scheduling.
I1104 15:57:28.792962   66853 session.go:135] Open Session db9b9ffe-ff5e-11e9-99a6-784f43775513 with <1> Job and <1> Queues
I1104 15:57:28.792999   66853 proportion.go:67] The total resource is <cpu 4000.00, memory 4959854592.00, hugepages-2Mi 0.00>
I1104 15:57:28.793012   66853 proportion.go:71] Considering Job <default/qj-1>.
I1104 15:57:28.793017   66853 proportion.go:85] Added Queue <default> attributes.
I1104 15:57:28.793024   66853 proportion.go:127] Considering Queue <default>: weight <1>, total weight <1>.
I1104 15:57:28.793030   66853 proportion.go:144] The attributes of queue <default> in proportion: deserved <cpu 4000.00, memory 4959854592.00, hugepages-2Mi 0.00>, allocate <cpu 0.00, memory 0.00>, request <cpu 0.00, memory 0.00>, share <0.00>
I1104 15:57:28.793043   66853 proportion.go:154] Exiting when remaining is empty:  <cpu 0.00, memory 0.00, hugepages-2Mi 0.00>
I1104 15:57:28.793065   66853 enqueue.go:43] Enter Enqueue ...
I1104 15:57:28.793070   66853 enqueue.go:58] Added Queue <default> for Job <default/qj-1>
I1104 15:57:28.793076   66853 enqueue.go:75] Try to enqueue PodGroup to 0 Queues
I1104 15:57:28.793082   66853 enqueue.go:122] Leaving Enqueue ...
I1104 15:57:28.793088   66853 allocate.go:43] Enter Allocate ...
I1104 15:57:28.793092   66853 allocate.go:90] Added Job <default/qj-1> into Queue <default>
I1104 15:57:28.793098   66853 allocate.go:94] Try to allocate resource to 1 Namespaces
I1104 15:57:28.793106   66853 allocate.go:153] Try to allocate resource to Jobs in Namespace <default> Queue <default>
I1104 15:57:28.793112   66853 allocate.go:178] Try to allocate resource to 0 tasks of Job <default/qj-1>
I1104 15:57:28.793116   66853 statement.go:326] Committing operations ...
I1104 15:57:28.793121   66853 allocate.go:153] Try to allocate resource to Jobs in Namespace <default> Queue <default>
I1104 15:57:28.793127   66853 allocate.go:157] Can not find jobs for queue default.
I1104 15:57:28.793137   66853 allocate.go:253] Leaving Allocate ...
I1104 15:57:28.793140   66853 backfill.go:42] Enter Backfill ...
I1104 15:57:28.793145   66853 backfill.go:91] Leaving Backfill ...
I1104 15:57:28.797833   66853 session.go:154] Close Session db9b9ffe-ff5e-11e9-99a6-784f43775513
I1104 15:57:28.797843   66853 scheduler.go:87] End scheduling ...
I1104 15:57:33.798117   66853 scheduler.go:72] Start scheduling ...
I1104 15:57:33.809471   66853 cache.go:732] The priority of job <default/qj-1> is </0>
I1104 15:57:33.809497   66853 cache.go:771] There are <1> Jobs, <1> Queues and <1> Nodes in total for scheduling.
I1104 15:57:33.809504   66853 session.go:135] Open Session de99159c-ff5e-11e9-99a6-784f43775513 with <1> Job and <1> Queues
I1104 15:57:33.809557   66853 proportion.go:67] The total resource is <cpu 4000.00, memory 4959854592.00, hugepages-2Mi 0.00>
I1104 15:57:33.809573   66853 proportion.go:71] Considering Job <default/qj-1>.
I1104 15:57:33.809580   66853 proportion.go:85] Added Queue <default> attributes.
I1104 15:57:33.809594   66853 proportion.go:127] Considering Queue <default>: weight <1>, total weight <1>.
I1104 15:57:33.809604   66853 proportion.go:144] The attributes of queue <default> in proportion: deserved <cpu 4000.00, memory 4959854592.00, hugepages-2Mi 0.00>, allocate <cpu 0.00, memory 0.00>, request <cpu 0.00, memory 0.00>, share <0.00>
I1104 15:57:33.809622   66853 proportion.go:154] Exiting when remaining is empty:  <cpu 0.00, memory 0.00, hugepages-2Mi 0.00>
I1104 15:57:33.809647   66853 enqueue.go:43] Enter Enqueue ...
I1104 15:57:33.809652   66853 enqueue.go:58] Added Queue <default> for Job <default/qj-1>
I1104 15:57:33.809660   66853 enqueue.go:75] Try to enqueue PodGroup to 0 Queues
I1104 15:57:33.809669   66853 enqueue.go:122] Leaving Enqueue ...
I1104 15:57:33.809677   66853 allocate.go:43] Enter Allocate ...
I1104 15:57:33.809684   66853 allocate.go:90] Added Job <default/qj-1> into Queue <default>
I1104 15:57:33.809692   66853 allocate.go:94] Try to allocate resource to 1 Namespaces
I1104 15:57:33.809701   66853 allocate.go:153] Try to allocate resource to Jobs in Namespace <default> Queue <default>
I1104 15:57:33.809711   66853 allocate.go:178] Try to allocate resource to 0 tasks of Job <default/qj-1>
I1104 15:57:33.809717   66853 statement.go:326] Committing operations ...
I1104 15:57:33.809725   66853 allocate.go:153] Try to allocate resource to Jobs in Namespace <default> Queue <default>
I1104 15:57:33.809731   66853 allocate.go:157] Can not find jobs for queue default.
I1104 15:57:33.809745   66853 allocate.go:253] Leaving Allocate ...
I1104 15:57:33.809750   66853 backfill.go:42] Enter Backfill ...
I1104 15:57:33.809757   66853 backfill.go:91] Leaving Backfill ...
I1104 15:57:33.815311   66853 session.go:154] Close Session de99159c-ff5e-11e9-99a6-784f43775513
I1104 15:57:33.815321   66853 scheduler.go:87] End scheduling ...
I1104 15:57:38.816291   66853 scheduler.go:72] Start scheduling ...
I1104 15:57:38.828283   66853 cache.go:732] The priority of job <default/qj-1> is </0>
I1104 15:57:38.828310   66853 cache.go:771] There are <1> Jobs, <1> Queues and <1> Nodes in total for scheduling.
I1104 15:57:38.828317   66853 session.go:135] Open Session e196e4c2-ff5e-11e9-99a6-784f43775513 with <1> Job and <1> Queues
I1104 15:57:38.828374   66853 proportion.go:67] The total resource is <cpu 4000.00, memory 4959854592.00, hugepages-2Mi 0.00>
I1104 15:57:38.828392   66853 proportion.go:71] Considering Job <default/qj-1>.
I1104 15:57:38.828399   66853 proportion.go:85] Added Queue <default> attributes.
I1104 15:57:38.828409   66853 proportion.go:127] Considering Queue <default>: weight <1>, total weight <1>.
I1104 15:57:38.828418   66853 proportion.go:144] The attributes of queue <default> in proportion: deserved <cpu 4000.00, memory 4959854592.00, hugepages-2Mi 0.00>, allocate <cpu 0.00, memory 0.00>, request <cpu 0.00, memory 0.00>, share <0.00>
I1104 15:57:38.828436   66853 proportion.go:154] Exiting when remaining is empty:  <cpu 0.00, memory 0.00, hugepages-2Mi 0.00>
I1104 15:57:38.828461   66853 enqueue.go:43] Enter Enqueue ...
I1104 15:57:38.828467   66853 enqueue.go:58] Added Queue <default> for Job <default/qj-1>
I1104 15:57:38.828474   66853 enqueue.go:75] Try to enqueue PodGroup to 0 Queues
I1104 15:57:38.828484   66853 enqueue.go:122] Leaving Enqueue ...
I1104 15:57:38.828492   66853 allocate.go:43] Enter Allocate ...
I1104 15:57:38.828498   66853 allocate.go:90] Added Job <default/qj-1> into Queue <default>
I1104 15:57:38.828508   66853 allocate.go:94] Try to allocate resource to 1 Namespaces
I1104 15:57:38.828518   66853 allocate.go:153] Try to allocate resource to Jobs in Namespace <default> Queue <default>
I1104 15:57:38.828529   66853 allocate.go:178] Try to allocate resource to 0 tasks of Job <default/qj-1>
I1104 15:57:38.828535   66853 statement.go:326] Committing operations ...
I1104 15:57:38.828542   66853 allocate.go:153] Try to allocate resource to Jobs in Namespace <default> Queue <default>
I1104 15:57:38.828549   66853 allocate.go:157] Can not find jobs for queue default.
I1104 15:57:38.828563   66853 allocate.go:253] Leaving Allocate ...
I1104 15:57:38.828568   66853 backfill.go:42] Enter Backfill ...
I1104 15:57:38.828575   66853 backfill.go:91] Leaving Backfill ...
I1104 15:57:38.833356   66853 session.go:154] Close Session e196e4c2-ff5e-11e9-99a6-784f43775513
I1104 15:57:38.833367   66853 scheduler.go:87] End scheduling ...
I1104 15:57:43.833702   66853 scheduler.go:72] Start scheduling ...
I1104 15:57:43.846759   66853 cache.go:732] The priority of job <default/qj-1> is </0>
I1104 15:57:43.846777   66853 cache.go:771] There are <1> Jobs, <1> Queues and <1> Nodes in total for scheduling.
I1104 15:57:43.846781   66853 session.go:135] Open Session e494a808-ff5e-11e9-99a6-784f43775513 with <1> Job and <1> Queues
I1104 15:57:43.846827   66853 proportion.go:67] The total resource is <cpu 4000.00, memory 4959854592.00, hugepages-2Mi 0.00>
I1104 15:57:43.846838   66853 proportion.go:71] Considering Job <default/qj-1>.
I1104 15:57:43.846843   66853 proportion.go:85] Added Queue <default> attributes.
I1104 15:57:43.846850   66853 proportion.go:127] Considering Queue <default>: weight <1>, total weight <1>.
I1104 15:57:43.846856   66853 proportion.go:144] The attributes of queue <default> in proportion: deserved <cpu 4000.00, memory 4959854592.00, hugepages-2Mi 0.00>, allocate <cpu 0.00, memory 0.00>, request <cpu 0.00, memory 0.00>, share <0.00>
I1104 15:57:43.846867   66853 proportion.go:154] Exiting when remaining is empty:  <cpu 0.00, memory 0.00, hugepages-2Mi 0.00>
I1104 15:57:43.846874   66853 enqueue.go:43] Enter Enqueue ...
I1104 15:57:43.846878   66853 enqueue.go:58] Added Queue <default> for Job <default/qj-1>
I1104 15:57:43.846883   66853 enqueue.go:75] Try to enqueue PodGroup to 0 Queues
I1104 15:57:43.846889   66853 enqueue.go:122] Leaving Enqueue ...
I1104 15:57:43.846895   66853 allocate.go:43] Enter Allocate ...
I1104 15:57:43.846899   66853 allocate.go:90] Added Job <default/qj-1> into Queue <default>
I1104 15:57:43.846904   66853 allocate.go:94] Try to allocate resource to 1 Namespaces
I1104 15:57:43.846911   66853 allocate.go:153] Try to allocate resource to Jobs in Namespace <default> Queue <default>
I1104 15:57:43.846917   66853 allocate.go:178] Try to allocate resource to 0 tasks of Job <default/qj-1>
I1104 15:57:43.846921   66853 statement.go:326] Committing operations ...
I1104 15:57:43.846926   66853 allocate.go:153] Try to allocate resource to Jobs in Namespace <default> Queue <default>
I1104 15:57:43.846930   66853 allocate.go:157] Can not find jobs for queue default.
I1104 15:57:43.846939   66853 allocate.go:253] Leaving Allocate ...
I1104 15:57:43.846942   66853 backfill.go:42] Enter Backfill ...
I1104 15:57:43.846946   66853 backfill.go:91] Leaving Backfill ...
I1104 15:57:43.850851   66853 session.go:154] Close Session e494a808-ff5e-11e9-99a6-784f43775513
I1104 15:57:43.850862   66853 scheduler.go:87] End scheduling ...
I1104 15:57:48.855467   66853 scheduler.go:72] Start scheduling ...
I1104 15:57:48.863029   66853 cache.go:732] The priority of job <default/qj-1> is </0>
I1104 15:57:48.863049   66853 cache.go:771] There are <1> Jobs, <1> Queues and <1> Nodes in total for scheduling.
I1104 15:57:48.863054   66853 session.go:135] Open Session e79213f6-ff5e-11e9-99a6-784f43775513 with <1> Job and <1> Queues
I1104 15:57:48.863093   66853 proportion.go:67] The total resource is <cpu 4000.00, memory 4959854592.00, hugepages-2Mi 0.00>
I1104 15:57:48.863106   66853 proportion.go:71] Considering Job <default/qj-1>.
I1104 15:57:48.863111   66853 proportion.go:85] Added Queue <default> attributes.
I1104 15:57:48.863118   66853 proportion.go:127] Considering Queue <default>: weight <1>, total weight <1>.
I1104 15:57:48.863125   66853 proportion.go:144] The attributes of queue <default> in proportion: deserved <cpu 4000.00, memory 4959854592.00, hugepages-2Mi 0.00>, allocate <cpu 0.00, memory 0.00>, request <cpu 0.00, memory 0.00>, share <0.00>
I1104 15:57:48.863137   66853 proportion.go:154] Exiting when remaining is empty:  <cpu 0.00, memory 0.00, hugepages-2Mi 0.00>
I1104 15:57:48.863155   66853 enqueue.go:43] Enter Enqueue ...
I1104 15:57:48.863159   66853 enqueue.go:58] Added Queue <default> for Job <default/qj-1>
I1104 15:57:48.863164   66853 enqueue.go:75] Try to enqueue PodGroup to 0 Queues
I1104 15:57:48.863170   66853 enqueue.go:122] Leaving Enqueue ...
I1104 15:57:48.863176   66853 allocate.go:43] Enter Allocate ...
I1104 15:57:48.863180   66853 allocate.go:90] Added Job <default/qj-1> into Queue <default>
I1104 15:57:48.863186   66853 allocate.go:94] Try to allocate resource to 1 Namespaces
I1104 15:57:48.863193   66853 allocate.go:153] Try to allocate resource to Jobs in Namespace <default> Queue <default>
I1104 15:57:48.863218   66853 allocate.go:178] Try to allocate resource to 0 tasks of Job <default/qj-1>
I1104 15:57:48.863222   66853 statement.go:326] Committing operations ...
I1104 15:57:48.863228   66853 allocate.go:153] Try to allocate resource to Jobs in Namespace <default> Queue <default>
I1104 15:57:48.863232   66853 allocate.go:157] Can not find jobs for queue default.
I1104 15:57:48.863242   66853 allocate.go:253] Leaving Allocate ...
I1104 15:57:48.863246   66853 backfill.go:42] Enter Backfill ...
I1104 15:57:48.863250   66853 backfill.go:91] Leaving Backfill ...
I1104 15:57:48.867683   66853 session.go:154] Close Session e79213f6-ff5e-11e9-99a6-784f43775513
I1104 15:57:48.867694   66853 scheduler.go:87] End scheduling ...
I1104 15:57:53.870647   66853 scheduler.go:72] Start scheduling ...
I1104 15:57:53.874624   66853 cache.go:732] The priority of job <default/qj-1> is </0>
I1104 15:57:53.874643   66853 cache.go:771] There are <1> Jobs, <1> Queues and <1> Nodes in total for scheduling.
I1104 15:57:53.874649   66853 session.go:135] Open Session ea8ec950-ff5e-11e9-99a6-784f43775513 with <1> Job and <1> Queues
I1104 15:57:53.874698   66853 proportion.go:67] The total resource is <cpu 4000.00, memory 4959854592.00, hugepages-2Mi 0.00>
I1104 15:57:53.874711   66853 proportion.go:71] Considering Job <default/qj-1>.
I1104 15:57:53.874716   66853 proportion.go:85] Added Queue <default> attributes.
I1104 15:57:53.874723   66853 proportion.go:127] Considering Queue <default>: weight <1>, total weight <1>.
I1104 15:57:53.874729   66853 proportion.go:144] The attributes of queue <default> in proportion: deserved <cpu 4000.00, memory 4959854592.00, hugepages-2Mi 0.00>, allocate <cpu 0.00, memory 0.00>, request <cpu 0.00, memory 0.00>, share <0.00>
I1104 15:57:53.874743   66853 proportion.go:154] Exiting when remaining is empty:  <cpu 0.00, memory 0.00, hugepages-2Mi 0.00>
I1104 15:57:53.874751   66853 enqueue.go:43] Enter Enqueue ...
I1104 15:57:53.874755   66853 enqueue.go:58] Added Queue <default> for Job <default/qj-1>
I1104 15:57:53.874760   66853 enqueue.go:75] Try to enqueue PodGroup to 0 Queues
I1104 15:57:53.874767   66853 enqueue.go:122] Leaving Enqueue ...
I1104 15:57:53.874772   66853 allocate.go:43] Enter Allocate ...
I1104 15:57:53.874777   66853 allocate.go:90] Added Job <default/qj-1> into Queue <default>
I1104 15:57:53.874782   66853 allocate.go:94] Try to allocate resource to 1 Namespaces
I1104 15:57:53.874789   66853 allocate.go:153] Try to allocate resource to Jobs in Namespace <default> Queue <default>
I1104 15:57:53.874796   66853 allocate.go:178] Try to allocate resource to 0 tasks of Job <default/qj-1>
I1104 15:57:53.874801   66853 statement.go:326] Committing operations ...
I1104 15:57:53.874806   66853 allocate.go:153] Try to allocate resource to Jobs in Namespace <default> Queue <default>
I1104 15:57:53.874811   66853 allocate.go:157] Can not find jobs for queue default.
I1104 15:57:53.874820   66853 allocate.go:253] Leaving Allocate ...
I1104 15:57:53.874824   66853 backfill.go:42] Enter Backfill ...
I1104 15:57:53.874828   66853 backfill.go:91] Leaving Backfill ...
I1104 15:57:53.880154   66853 session.go:154] Close Session ea8ec950-ff5e-11e9-99a6-784f43775513
I1104 15:57:53.880166   66853 scheduler.go:87] End scheduling ...
I1104 15:57:58.882409   66853 scheduler.go:72] Start scheduling ...
I1104 15:57:58.893123   66853 cache.go:732] The priority of job <default/qj-1> is </0>
I1104 15:57:58.893142   66853 cache.go:771] There are <1> Jobs, <1> Queues and <1> Nodes in total for scheduling.
I1104 15:57:58.893146   66853 session.go:135] Open Session ed8c8c82-ff5e-11e9-99a6-784f43775513 with <1> Job and <1> Queues
I1104 15:57:58.893182   66853 proportion.go:67] The total resource is <cpu 4000.00, memory 4959854592.00, hugepages-2Mi 0.00>
I1104 15:57:58.893193   66853 proportion.go:71] Considering Job <default/qj-1>.
I1104 15:57:58.893198   66853 proportion.go:85] Added Queue <default> attributes.
I1104 15:57:58.893204   66853 proportion.go:127] Considering Queue <default>: weight <1>, total weight <1>.
I1104 15:57:58.893210   66853 proportion.go:144] The attributes of queue <default> in proportion: deserved <cpu 4000.00, memory 4959854592.00, hugepages-2Mi 0.00>, allocate <cpu 0.00, memory 0.00>, request <cpu 0.00, memory 0.00>, share <0.00>
I1104 15:57:58.893221   66853 proportion.go:154] Exiting when remaining is empty:  <cpu 0.00, memory 0.00, hugepages-2Mi 0.00>
I1104 15:57:58.893241   66853 enqueue.go:43] Enter Enqueue ...
I1104 15:57:58.893245   66853 enqueue.go:58] Added Queue <default> for Job <default/qj-1>
I1104 15:57:58.893251   66853 enqueue.go:75] Try to enqueue PodGroup to 0 Queues
I1104 15:57:58.893257   66853 enqueue.go:122] Leaving Enqueue ...
I1104 15:57:58.893264   66853 allocate.go:43] Enter Allocate ...
I1104 15:57:58.893268   66853 allocate.go:90] Added Job <default/qj-1> into Queue <default>
I1104 15:57:58.893273   66853 allocate.go:94] Try to allocate resource to 1 Namespaces
I1104 15:57:58.893280   66853 allocate.go:153] Try to allocate resource to Jobs in Namespace <default> Queue <default>
I1104 15:57:58.893287   66853 allocate.go:178] Try to allocate resource to 0 tasks of Job <default/qj-1>
I1104 15:57:58.893291   66853 statement.go:326] Committing operations ...
I1104 15:57:58.893297   66853 allocate.go:153] Try to allocate resource to Jobs in Namespace <default> Queue <default>
I1104 15:57:58.893301   66853 allocate.go:157] Can not find jobs for queue default.
I1104 15:57:58.893310   66853 allocate.go:253] Leaving Allocate ...
I1104 15:57:58.893314   66853 backfill.go:42] Enter Backfill ...
I1104 15:57:58.893318   66853 backfill.go:91] Leaving Backfill ...
I1104 15:57:58.898452   66853 session.go:154] Close Session ed8c8c82-ff5e-11e9-99a6-784f43775513
I1104 15:57:58.898461   66853 scheduler.go:87] End scheduling ...
I1104 15:58:03.902224   66853 scheduler.go:72] Start scheduling ...
I1104 15:58:03.908109   66853 cache.go:732] The priority of job <default/qj-1> is </0>
I1104 15:58:03.908134   66853 cache.go:771] There are <1> Jobs, <1> Queues and <1> Nodes in total for scheduling.
I1104 15:58:03.908141   66853 session.go:135] Open Session f089c5a8-ff5e-11e9-99a6-784f43775513 with <1> Job and <1> Queues
I1104 15:58:03.908193   66853 proportion.go:67] The total resource is <cpu 4000.00, memory 4959854592.00, hugepages-2Mi 0.00>
I1104 15:58:03.908211   66853 proportion.go:71] Considering Job <default/qj-1>.
I1104 15:58:03.908218   66853 proportion.go:85] Added Queue <default> attributes.
I1104 15:58:03.908229   66853 proportion.go:127] Considering Queue <default>: weight <1>, total weight <1>.
I1104 15:58:03.908251   66853 proportion.go:144] The attributes of queue <default> in proportion: deserved <cpu 4000.00, memory 4959854592.00, hugepages-2Mi 0.00>, allocate <cpu 0.00, memory 0.00>, request <cpu 0.00, memory 0.00>, share <0.00>
I1104 15:58:03.908264   66853 proportion.go:154] Exiting when remaining is empty:  <cpu 0.00, memory 0.00, hugepages-2Mi 0.00>
I1104 15:58:03.908286   66853 enqueue.go:43] Enter Enqueue ...
I1104 15:58:03.908290   66853 enqueue.go:58] Added Queue <default> for Job <default/qj-1>
I1104 15:58:03.908295   66853 enqueue.go:75] Try to enqueue PodGroup to 0 Queues
I1104 15:58:03.908302   66853 enqueue.go:122] Leaving Enqueue ...
I1104 15:58:03.908308   66853 allocate.go:43] Enter Allocate ...
I1104 15:58:03.908312   66853 allocate.go:90] Added Job <default/qj-1> into Queue <default>
I1104 15:58:03.908318   66853 allocate.go:94] Try to allocate resource to 1 Namespaces
I1104 15:58:03.908325   66853 allocate.go:153] Try to allocate resource to Jobs in Namespace <default> Queue <default>
I1104 15:58:03.908332   66853 allocate.go:178] Try to allocate resource to 0 tasks of Job <default/qj-1>
I1104 15:58:03.908336   66853 statement.go:326] Committing operations ...
I1104 15:58:03.908341   66853 allocate.go:153] Try to allocate resource to Jobs in Namespace <default> Queue <default>
I1104 15:58:03.908345   66853 allocate.go:157] Can not find jobs for queue default.
I1104 15:58:03.908354   66853 allocate.go:253] Leaving Allocate ...
I1104 15:58:03.908358   66853 backfill.go:42] Enter Backfill ...
I1104 15:58:03.908362   66853 backfill.go:91] Leaving Backfill ...
I1104 15:58:03.913205   66853 session.go:154] Close Session f089c5a8-ff5e-11e9-99a6-784f43775513
I1104 15:58:03.913216   66853 scheduler.go:87] End scheduling ...
I1104 15:58:08.914116   66853 scheduler.go:72] Start scheduling ...
I1104 15:58:08.916442   66853 cache.go:732] The priority of job <default/qj-1> is </0>
I1104 15:58:08.916460   66853 cache.go:771] There are <1> Jobs, <1> Queues and <1> Nodes in total for scheduling.
I1104 15:58:08.916464   66853 session.go:135] Open Session f385fc7c-ff5e-11e9-99a6-784f43775513 with <1> Job and <1> Queues
I1104 15:58:08.916475   66853 proportion.go:67] The total resource is <cpu 4000.00, memory 4959854592.00, hugepages-2Mi 0.00>
I1104 15:58:08.916487   66853 proportion.go:71] Considering Job <default/qj-1>.
I1104 15:58:08.916491   66853 proportion.go:85] Added Queue <default> attributes.
I1104 15:58:08.916498   66853 proportion.go:127] Considering Queue <default>: weight <1>, total weight <1>.
I1104 15:58:08.916505   66853 proportion.go:144] The attributes of queue <default> in proportion: deserved <cpu 4000.00, memory 4959854592.00, hugepages-2Mi 0.00>, allocate <cpu 0.00, memory 0.00>, request <cpu 0.00, memory 0.00>, share <0.00>
I1104 15:58:08.916516   66853 proportion.go:154] Exiting when remaining is empty:  <cpu 0.00, memory 0.00, hugepages-2Mi 0.00>
I1104 15:58:08.916559   66853 enqueue.go:43] Enter Enqueue ...
I1104 15:58:08.916562   66853 enqueue.go:58] Added Queue <default> for Job <default/qj-1>
I1104 15:58:08.916567   66853 enqueue.go:75] Try to enqueue PodGroup to 0 Queues
I1104 15:58:08.916574   66853 enqueue.go:122] Leaving Enqueue ...
I1104 15:58:08.916579   66853 allocate.go:43] Enter Allocate ...
I1104 15:58:08.916583   66853 allocate.go:90] Added Job <default/qj-1> into Queue <default>
I1104 15:58:08.916588   66853 allocate.go:94] Try to allocate resource to 1 Namespaces
I1104 15:58:08.916595   66853 allocate.go:153] Try to allocate resource to Jobs in Namespace <default> Queue <default>
I1104 15:58:08.916602   66853 allocate.go:178] Try to allocate resource to 0 tasks of Job <default/qj-1>
I1104 15:58:08.916606   66853 statement.go:326] Committing operations ...
I1104 15:58:08.916611   66853 allocate.go:153] Try to allocate resource to Jobs in Namespace <default> Queue <default>
I1104 15:58:08.916615   66853 allocate.go:157] Can not find jobs for queue default.
I1104 15:58:08.916624   66853 allocate.go:253] Leaving Allocate ...
I1104 15:58:08.916627   66853 backfill.go:42] Enter Backfill ...
I1104 15:58:08.916631   66853 backfill.go:91] Leaving Backfill ...
I1104 15:58:08.921410   66853 session.go:154] Close Session f385fc7c-ff5e-11e9-99a6-784f43775513
I1104 15:58:08.921424   66853 scheduler.go:87] End scheduling ...
I1104 15:58:13.921947   66853 scheduler.go:72] Start scheduling ...
I1104 15:58:13.935528   66853 cache.go:732] The priority of job <default/qj-1> is </0>
I1104 15:58:13.935558   66853 cache.go:771] There are <1> Jobs, <1> Queues and <1> Nodes in total for scheduling.
I1104 15:58:13.935565   66853 session.go:135] Open Session f683d5b6-ff5e-11e9-99a6-784f43775513 with <1> Job and <1> Queues
I1104 15:58:13.935631   66853 proportion.go:67] The total resource is <cpu 4000.00, memory 4959854592.00, hugepages-2Mi 0.00>
I1104 15:58:13.935646   66853 proportion.go:71] Considering Job <default/qj-1>.
I1104 15:58:13.935651   66853 proportion.go:85] Added Queue <default> attributes.
I1104 15:58:13.935659   66853 proportion.go:127] Considering Queue <default>: weight <1>, total weight <1>.
I1104 15:58:13.935667   66853 proportion.go:144] The attributes of queue <default> in proportion: deserved <cpu 4000.00, memory 4959854592.00, hugepages-2Mi 0.00>, allocate <cpu 0.00, memory 0.00>, request <cpu 0.00, memory 0.00>, share <0.00>
I1104 15:58:13.935680   66853 proportion.go:154] Exiting when remaining is empty:  <cpu 0.00, memory 0.00, hugepages-2Mi 0.00>
I1104 15:58:13.935703   66853 enqueue.go:43] Enter Enqueue ...
I1104 15:58:13.935708   66853 enqueue.go:58] Added Queue <default> for Job <default/qj-1>
I1104 15:58:13.935714   66853 enqueue.go:75] Try to enqueue PodGroup to 0 Queues
I1104 15:58:13.935722   66853 enqueue.go:122] Leaving Enqueue ...
I1104 15:58:13.935729   66853 allocate.go:43] Enter Allocate ...
I1104 15:58:13.935734   66853 allocate.go:90] Added Job <default/qj-1> into Queue <default>
I1104 15:58:13.935740   66853 allocate.go:94] Try to allocate resource to 1 Namespaces
I1104 15:58:13.935748   66853 allocate.go:153] Try to allocate resource to Jobs in Namespace <default> Queue <default>
I1104 15:58:13.935756   66853 allocate.go:178] Try to allocate resource to 0 tasks of Job <default/qj-1>
I1104 15:58:13.935761   66853 statement.go:326] Committing operations ...
I1104 15:58:13.935767   66853 allocate.go:153] Try to allocate resource to Jobs in Namespace <default> Queue <default>
I1104 15:58:13.935772   66853 allocate.go:157] Can not find jobs for queue default.
I1104 15:58:13.935785   66853 allocate.go:253] Leaving Allocate ...
I1104 15:58:13.935790   66853 backfill.go:42] Enter Backfill ...
I1104 15:58:13.935795   66853 backfill.go:91] Leaving Backfill ...
I1104 15:58:13.940086   66853 session.go:154] Close Session f683d5b6-ff5e-11e9-99a6-784f43775513
I1104 15:58:13.940098   66853 scheduler.go:87] End scheduling ...
I1104 15:58:18.940710   66853 scheduler.go:72] Start scheduling ...
I1104 15:58:18.947428   66853 cache.go:732] The priority of job <default/qj-1> is </0>
I1104 15:58:18.947448   66853 cache.go:771] There are <1> Jobs, <1> Queues and <1> Nodes in total for scheduling.
I1104 15:58:18.947454   66853 session.go:135] Open Session f9809772-ff5e-11e9-99a6-784f43775513 with <1> Job and <1> Queues
I1104 15:58:18.947467   66853 proportion.go:67] The total resource is <cpu 4000.00, memory 4959854592.00, hugepages-2Mi 0.00>
I1104 15:58:18.947479   66853 proportion.go:71] Considering Job <default/qj-1>.
I1104 15:58:18.947484   66853 proportion.go:85] Added Queue <default> attributes.
I1104 15:58:18.947492   66853 proportion.go:127] Considering Queue <default>: weight <1>, total weight <1>.
I1104 15:58:18.947499   66853 proportion.go:144] The attributes of queue <default> in proportion: deserved <cpu 4000.00, memory 4959854592.00, hugepages-2Mi 0.00>, allocate <cpu 0.00, memory 0.00>, request <cpu 0.00, memory 0.00>, share <0.00>
I1104 15:58:18.947512   66853 proportion.go:154] Exiting when remaining is empty:  <cpu 0.00, memory 0.00, hugepages-2Mi 0.00>
I1104 15:58:18.947563   66853 enqueue.go:43] Enter Enqueue ...
I1104 15:58:18.947568   66853 enqueue.go:58] Added Queue <default> for Job <default/qj-1>
I1104 15:58:18.947573   66853 enqueue.go:75] Try to enqueue PodGroup to 0 Queues
I1104 15:58:18.947581   66853 enqueue.go:122] Leaving Enqueue ...
I1104 15:58:18.947587   66853 allocate.go:43] Enter Allocate ...
I1104 15:58:18.947592   66853 allocate.go:90] Added Job <default/qj-1> into Queue <default>
I1104 15:58:18.947598   66853 allocate.go:94] Try to allocate resource to 1 Namespaces
I1104 15:58:18.947606   66853 allocate.go:153] Try to allocate resource to Jobs in Namespace <default> Queue <default>
I1104 15:58:18.947614   66853 allocate.go:178] Try to allocate resource to 0 tasks of Job <default/qj-1>
I1104 15:58:18.947618   66853 statement.go:326] Committing operations ...
I1104 15:58:18.947625   66853 allocate.go:153] Try to allocate resource to Jobs in Namespace <default> Queue <default>
I1104 15:58:18.947629   66853 allocate.go:157] Can not find jobs for queue default.
I1104 15:58:18.947640   66853 allocate.go:253] Leaving Allocate ...
I1104 15:58:18.947644   66853 backfill.go:42] Enter Backfill ...
I1104 15:58:18.947649   66853 backfill.go:91] Leaving Backfill ...
I1104 15:58:18.952347   66853 session.go:154] Close Session f9809772-ff5e-11e9-99a6-784f43775513
I1104 15:58:18.952357   66853 scheduler.go:87] End scheduling ...
I1104 15:58:23.956705   66853 scheduler.go:72] Start scheduling ...
I1104 15:58:23.966409   66853 cache.go:732] The priority of job <default/qj-1> is </0>
I1104 15:58:23.966434   66853 cache.go:771] There are <1> Jobs, <1> Queues and <1> Nodes in total for scheduling.
I1104 15:58:23.966441   66853 session.go:135] Open Session fc7e6d00-ff5e-11e9-99a6-784f43775513 with <1> Job and <1> Queues
I1104 15:58:23.966498   66853 proportion.go:67] The total resource is <cpu 4000.00, memory 4959854592.00, hugepages-2Mi 0.00>
I1104 15:58:23.966513   66853 proportion.go:71] Considering Job <default/qj-1>.
I1104 15:58:23.966520   66853 proportion.go:85] Added Queue <default> attributes.
I1104 15:58:23.966529   66853 proportion.go:127] Considering Queue <default>: weight <1>, total weight <1>.
I1104 15:58:23.966539   66853 proportion.go:144] The attributes of queue <default> in proportion: deserved <cpu 4000.00, memory 4959854592.00, hugepages-2Mi 0.00>, allocate <cpu 0.00, memory 0.00>, request <cpu 0.00, memory 0.00>, share <0.00>
I1104 15:58:23.966556   66853 proportion.go:154] Exiting when remaining is empty:  <cpu 0.00, memory 0.00, hugepages-2Mi 0.00>
I1104 15:58:23.966582   66853 enqueue.go:43] Enter Enqueue ...
I1104 15:58:23.966587   66853 enqueue.go:58] Added Queue <default> for Job <default/qj-1>
I1104 15:58:23.966595   66853 enqueue.go:75] Try to enqueue PodGroup to 0 Queues
I1104 15:58:23.966607   66853 enqueue.go:122] Leaving Enqueue ...
I1104 15:58:23.966615   66853 allocate.go:43] Enter Allocate ...
I1104 15:58:23.966621   66853 allocate.go:90] Added Job <default/qj-1> into Queue <default>
I1104 15:58:23.966630   66853 allocate.go:94] Try to allocate resource to 1 Namespaces
I1104 15:58:23.966639   66853 allocate.go:153] Try to allocate resource to Jobs in Namespace <default> Queue <default>
I1104 15:58:23.966650   66853 allocate.go:178] Try to allocate resource to 0 tasks of Job <default/qj-1>
I1104 15:58:23.966655   66853 statement.go:326] Committing operations ...
I1104 15:58:23.966663   66853 allocate.go:153] Try to allocate resource to Jobs in Namespace <default> Queue <default>
I1104 15:58:23.966669   66853 allocate.go:157] Can not find jobs for queue default.
I1104 15:58:23.966683   66853 allocate.go:253] Leaving Allocate ...
I1104 15:58:23.966688   66853 backfill.go:42] Enter Backfill ...
I1104 15:58:23.966695   66853 backfill.go:91] Leaving Backfill ...
I1104 15:58:23.971091   66853 session.go:154] Close Session fc7e6d00-ff5e-11e9-99a6-784f43775513
I1104 15:58:23.971101   66853 scheduler.go:87] End scheduling ...
I1104 15:58:28.971273   66853 scheduler.go:72] Start scheduling ...
I1104 15:58:28.988929   66853 cache.go:732] The priority of job <default/qj-1> is </0>
I1104 15:58:28.988950   66853 cache.go:771] There are <1> Jobs, <1> Queues and <1> Nodes in total for scheduling.
I1104 15:58:28.988955   66853 session.go:135] Open Session ff7ccd9e-ff5e-11e9-99a6-784f43775513 with <1> Job and <1> Queues
I1104 15:58:28.989014   66853 proportion.go:67] The total resource is <cpu 4000.00, memory 4959854592.00, hugepages-2Mi 0.00>
I1104 15:58:28.989028   66853 proportion.go:71] Considering Job <default/qj-1>.
I1104 15:58:28.989033   66853 proportion.go:85] Added Queue <default> attributes.
I1104 15:58:28.989041   66853 proportion.go:127] Considering Queue <default>: weight <1>, total weight <1>.
I1104 15:58:28.989048   66853 proportion.go:144] The attributes of queue <default> in proportion: deserved <cpu 4000.00, memory 4959854592.00, hugepages-2Mi 0.00>, allocate <cpu 0.00, memory 0.00>, request <cpu 0.00, memory 0.00>, share <0.00>
I1104 15:58:28.989061   66853 proportion.go:154] Exiting when remaining is empty:  <cpu 0.00, memory 0.00, hugepages-2Mi 0.00>
I1104 15:58:28.989070   66853 enqueue.go:43] Enter Enqueue ...
I1104 15:58:28.989075   66853 enqueue.go:58] Added Queue <default> for Job <default/qj-1>
I1104 15:58:28.989080   66853 enqueue.go:75] Try to enqueue PodGroup to 0 Queues
I1104 15:58:28.989087   66853 enqueue.go:122] Leaving Enqueue ...
I1104 15:58:28.989093   66853 allocate.go:43] Enter Allocate ...
I1104 15:58:28.989101   66853 allocate.go:90] Added Job <default/qj-1> into Queue <default>
I1104 15:58:28.989107   66853 allocate.go:94] Try to allocate resource to 1 Namespaces
I1104 15:58:28.989115   66853 allocate.go:153] Try to allocate resource to Jobs in Namespace <default> Queue <default>
I1104 15:58:28.989123   66853 allocate.go:178] Try to allocate resource to 0 tasks of Job <default/qj-1>
I1104 15:58:28.989127   66853 statement.go:326] Committing operations ...
I1104 15:58:28.989134   66853 allocate.go:153] Try to allocate resource to Jobs in Namespace <default> Queue <default>
I1104 15:58:28.989139   66853 allocate.go:157] Can not find jobs for queue default.
I1104 15:58:28.989150   66853 allocate.go:253] Leaving Allocate ...
I1104 15:58:28.989155   66853 backfill.go:42] Enter Backfill ...
I1104 15:58:28.989160   66853 backfill.go:91] Leaving Backfill ...
I1104 15:58:28.994128   66853 session.go:154] Close Session ff7ccd9e-ff5e-11e9-99a6-784f43775513
I1104 15:58:28.994138   66853 scheduler.go:87] End scheduling ...
I1104 15:58:33.997374   66853 scheduler.go:72] Start scheduling ...
I1104 15:58:34.006461   66853 cache.go:732] The priority of job <default/qj-1> is </0>
I1104 15:58:34.006478   66853 cache.go:771] There are <1> Jobs, <1> Queues and <1> Nodes in total for scheduling.
I1104 15:58:34.006482   66853 session.go:135] Open Session 027a6b64-ff5f-11e9-99a6-784f43775513 with <1> Job and <1> Queues
I1104 15:58:34.006520   66853 proportion.go:67] The total resource is <cpu 4000.00, memory 4959854592.00, hugepages-2Mi 0.00>
I1104 15:58:34.006532   66853 proportion.go:71] Considering Job <default/qj-1>.
I1104 15:58:34.006536   66853 proportion.go:85] Added Queue <default> attributes.
I1104 15:58:34.006542   66853 proportion.go:127] Considering Queue <default>: weight <1>, total weight <1>.
I1104 15:58:34.006549   66853 proportion.go:144] The attributes of queue <default> in proportion: deserved <cpu 4000.00, memory 4959854592.00, hugepages-2Mi 0.00>, allocate <cpu 0.00, memory 0.00>, request <cpu 0.00, memory 0.00>, share <0.00>
I1104 15:58:34.006560   66853 proportion.go:154] Exiting when remaining is empty:  <cpu 0.00, memory 0.00, hugepages-2Mi 0.00>
I1104 15:58:34.006576   66853 enqueue.go:43] Enter Enqueue ...
I1104 15:58:34.006580   66853 enqueue.go:58] Added Queue <default> for Job <default/qj-1>
I1104 15:58:34.006585   66853 enqueue.go:75] Try to enqueue PodGroup to 0 Queues
I1104 15:58:34.006591   66853 enqueue.go:122] Leaving Enqueue ...
I1104 15:58:34.006596   66853 allocate.go:43] Enter Allocate ...
I1104 15:58:34.006600   66853 allocate.go:90] Added Job <default/qj-1> into Queue <default>
I1104 15:58:34.006605   66853 allocate.go:94] Try to allocate resource to 1 Namespaces
I1104 15:58:34.006611   66853 allocate.go:153] Try to allocate resource to Jobs in Namespace <default> Queue <default>
I1104 15:58:34.006618   66853 allocate.go:178] Try to allocate resource to 0 tasks of Job <default/qj-1>
I1104 15:58:34.006623   66853 statement.go:326] Committing operations ...
I1104 15:58:34.006628   66853 allocate.go:153] Try to allocate resource to Jobs in Namespace <default> Queue <default>
I1104 15:58:34.006632   66853 allocate.go:157] Can not find jobs for queue default.
I1104 15:58:34.006640   66853 allocate.go:253] Leaving Allocate ...
I1104 15:58:34.006644   66853 backfill.go:42] Enter Backfill ...
I1104 15:58:34.006648   66853 backfill.go:91] Leaving Backfill ...
I1104 15:58:34.010795   66853 session.go:154] Close Session 027a6b64-ff5f-11e9-99a6-784f43775513
I1104 15:58:34.010805   66853 scheduler.go:87] End scheduling ...
I1104 15:58:39.014159   66853 scheduler.go:72] Start scheduling ...
I1104 15:58:39.023174   66853 cache.go:732] The priority of job <default/qj-1> is </0>
I1104 15:58:39.023202   66853 cache.go:771] There are <1> Jobs, <1> Queues and <1> Nodes in total for scheduling.
I1104 15:58:39.023209   66853 session.go:135] Open Session 0577e788-ff5f-11e9-99a6-784f43775513 with <1> Job and <1> Queues
I1104 15:58:39.023224   66853 proportion.go:67] The total resource is <cpu 4000.00, memory 4959854592.00, hugepages-2Mi 0.00>
I1104 15:58:39.023249   66853 proportion.go:71] Considering Job <default/qj-1>.
I1104 15:58:39.023256   66853 proportion.go:85] Added Queue <default> attributes.
I1104 15:58:39.023268   66853 proportion.go:127] Considering Queue <default>: weight <1>, total weight <1>.
I1104 15:58:39.023295   66853 proportion.go:144] The attributes of queue <default> in proportion: deserved <cpu 4000.00, memory 4959854592.00, hugepages-2Mi 0.00>, allocate <cpu 0.00, memory 0.00>, request <cpu 0.00, memory 0.00>, share <0.00>
I1104 15:58:39.023313   66853 proportion.go:154] Exiting when remaining is empty:  <cpu 0.00, memory 0.00, hugepages-2Mi 0.00>
I1104 15:58:39.023372   66853 enqueue.go:43] Enter Enqueue ...
I1104 15:58:39.023377   66853 enqueue.go:58] Added Queue <default> for Job <default/qj-1>
I1104 15:58:39.023382   66853 enqueue.go:75] Try to enqueue PodGroup to 0 Queues
I1104 15:58:39.023388   66853 enqueue.go:122] Leaving Enqueue ...
I1104 15:58:39.023394   66853 allocate.go:43] Enter Allocate ...
I1104 15:58:39.023398   66853 allocate.go:90] Added Job <default/qj-1> into Queue <default>
I1104 15:58:39.023404   66853 allocate.go:94] Try to allocate resource to 1 Namespaces
I1104 15:58:39.023410   66853 allocate.go:153] Try to allocate resource to Jobs in Namespace <default> Queue <default>
I1104 15:58:39.023417   66853 allocate.go:178] Try to allocate resource to 0 tasks of Job <default/qj-1>
I1104 15:58:39.023421   66853 statement.go:326] Committing operations ...
I1104 15:58:39.023427   66853 allocate.go:153] Try to allocate resource to Jobs in Namespace <default> Queue <default>
I1104 15:58:39.023431   66853 allocate.go:157] Can not find jobs for queue default.
I1104 15:58:39.023440   66853 allocate.go:253] Leaving Allocate ...
I1104 15:58:39.023444   66853 backfill.go:42] Enter Backfill ...
I1104 15:58:39.023448   66853 backfill.go:91] Leaving Backfill ...
I1104 15:58:39.028699   66853 session.go:154] Close Session 0577e788-ff5f-11e9-99a6-784f43775513
I1104 15:58:39.028710   66853 scheduler.go:87] End scheduling ...
I1104 15:58:44.030042   66853 scheduler.go:72] Start scheduling ...
I1104 15:58:44.038903   66853 cache.go:732] The priority of job <default/qj-1> is </0>
I1104 15:58:44.038926   66853 cache.go:771] There are <1> Jobs, <1> Queues and <1> Nodes in total for scheduling.
I1104 15:58:44.038932   66853 session.go:135] Open Session 08753f44-ff5f-11e9-99a6-784f43775513 with <1> Job and <1> Queues
I1104 15:58:44.038997   66853 proportion.go:67] The total resource is <cpu 4000.00, memory 4959854592.00, hugepages-2Mi 0.00>
I1104 15:58:44.039008   66853 proportion.go:71] Considering Job <default/qj-1>.
I1104 15:58:44.039015   66853 proportion.go:85] Added Queue <default> attributes.
I1104 15:58:44.039023   66853 proportion.go:127] Considering Queue <default>: weight <1>, total weight <1>.
I1104 15:58:44.039030   66853 proportion.go:144] The attributes of queue <default> in proportion: deserved <cpu 4000.00, memory 4959854592.00, hugepages-2Mi 0.00>, allocate <cpu 0.00, memory 0.00>, request <cpu 0.00, memory 0.00>, share <0.00>
I1104 15:58:44.039041   66853 proportion.go:154] Exiting when remaining is empty:  <cpu 0.00, memory 0.00, hugepages-2Mi 0.00>
I1104 15:58:44.039061   66853 enqueue.go:43] Enter Enqueue ...
I1104 15:58:44.039065   66853 enqueue.go:58] Added Queue <default> for Job <default/qj-1>
I1104 15:58:44.039071   66853 enqueue.go:75] Try to enqueue PodGroup to 0 Queues
I1104 15:58:44.039077   66853 enqueue.go:122] Leaving Enqueue ...
I1104 15:58:44.039083   66853 allocate.go:43] Enter Allocate ...
I1104 15:58:44.039088   66853 allocate.go:90] Added Job <default/qj-1> into Queue <default>
I1104 15:58:44.039094   66853 allocate.go:94] Try to allocate resource to 1 Namespaces
I1104 15:58:44.039101   66853 allocate.go:153] Try to allocate resource to Jobs in Namespace <default> Queue <default>
I1104 15:58:44.039109   66853 allocate.go:178] Try to allocate resource to 0 tasks of Job <default/qj-1>
I1104 15:58:44.039113   66853 statement.go:326] Committing operations ...
I1104 15:58:44.039120   66853 allocate.go:153] Try to allocate resource to Jobs in Namespace <default> Queue <default>
I1104 15:58:44.039124   66853 allocate.go:157] Can not find jobs for queue default.
I1104 15:58:44.039135   66853 allocate.go:253] Leaving Allocate ...
I1104 15:58:44.039140   66853 backfill.go:42] Enter Backfill ...
I1104 15:58:44.039145   66853 backfill.go:91] Leaving Backfill ...
I1104 15:58:44.046716   66853 session.go:154] Close Session 08753f44-ff5f-11e9-99a6-784f43775513
I1104 15:58:44.046728   66853 scheduler.go:87] End scheduling ...
I1104 15:58:49.047896   66853 scheduler.go:72] Start scheduling ...
I1104 15:58:49.057469   66853 cache.go:732] The priority of job <default/qj-1> is </0>
I1104 15:58:49.057495   66853 cache.go:771] There are <1> Jobs, <1> Queues and <1> Nodes in total for scheduling.
I1104 15:58:49.057502   66853 session.go:135] Open Session 0b73049c-ff5f-11e9-99a6-784f43775513 with <1> Job and <1> Queues
I1104 15:58:49.057541   66853 proportion.go:67] The total resource is <cpu 4000.00, memory 4959854592.00, hugepages-2Mi 0.00>
I1104 15:58:49.057556   66853 proportion.go:71] Considering Job <default/qj-1>.
I1104 15:58:49.057563   66853 proportion.go:85] Added Queue <default> attributes.
I1104 15:58:49.057572   66853 proportion.go:127] Considering Queue <default>: weight <1>, total weight <1>.
I1104 15:58:49.057585   66853 proportion.go:144] The attributes of queue <default> in proportion: deserved <cpu 4000.00, memory 4959854592.00, hugepages-2Mi 0.00>, allocate <cpu 0.00, memory 0.00>, request <cpu 0.00, memory 0.00>, share <0.00>
I1104 15:58:49.057602   66853 proportion.go:154] Exiting when remaining is empty:  <cpu 0.00, memory 0.00, hugepages-2Mi 0.00>
I1104 15:58:49.057639   66853 enqueue.go:43] Enter Enqueue ...
I1104 15:58:49.057645   66853 enqueue.go:58] Added Queue <default> for Job <default/qj-1>
I1104 15:58:49.057652   66853 enqueue.go:75] Try to enqueue PodGroup to 0 Queues
I1104 15:58:49.057661   66853 enqueue.go:122] Leaving Enqueue ...
I1104 15:58:49.057669   66853 allocate.go:43] Enter Allocate ...
I1104 15:58:49.057675   66853 allocate.go:90] Added Job <default/qj-1> into Queue <default>
I1104 15:58:49.057683   66853 allocate.go:94] Try to allocate resource to 1 Namespaces
I1104 15:58:49.057693   66853 allocate.go:153] Try to allocate resource to Jobs in Namespace <default> Queue <default>
I1104 15:58:49.057704   66853 allocate.go:178] Try to allocate resource to 0 tasks of Job <default/qj-1>
I1104 15:58:49.057709   66853 statement.go:326] Committing operations ...
I1104 15:58:49.057717   66853 allocate.go:153] Try to allocate resource to Jobs in Namespace <default> Queue <default>
I1104 15:58:49.057725   66853 allocate.go:157] Can not find jobs for queue default.
I1104 15:58:49.057739   66853 allocate.go:253] Leaving Allocate ...
I1104 15:58:49.057744   66853 backfill.go:42] Enter Backfill ...
I1104 15:58:49.057750   66853 backfill.go:91] Leaving Backfill ...
I1104 15:58:49.061766   66853 session.go:154] Close Session 0b73049c-ff5f-11e9-99a6-784f43775513
I1104 15:58:49.061777   66853 scheduler.go:87] End scheduling ...
I1104 15:58:54.062820   66853 scheduler.go:72] Start scheduling ...
I1104 15:58:54.074983   66853 cache.go:732] The priority of job <default/qj-1> is </0>
I1104 15:58:54.075012   66853 cache.go:771] There are <1> Jobs, <1> Queues and <1> Nodes in total for scheduling.
I1104 15:58:54.075019   66853 session.go:135] Open Session 0e70a10e-ff5f-11e9-99a6-784f43775513 with <1> Job and <1> Queues
I1104 15:58:54.075035   66853 proportion.go:67] The total resource is <cpu 4000.00, memory 4959854592.00, hugepages-2Mi 0.00>
I1104 15:58:54.075051   66853 proportion.go:71] Considering Job <default/qj-1>.
I1104 15:58:54.075060   66853 proportion.go:85] Added Queue <default> attributes.
I1104 15:58:54.075070   66853 proportion.go:127] Considering Queue <default>: weight <1>, total weight <1>.
I1104 15:58:54.075079   66853 proportion.go:144] The attributes of queue <default> in proportion: deserved <cpu 4000.00, memory 4959854592.00, hugepages-2Mi 0.00>, allocate <cpu 0.00, memory 0.00>, request <cpu 0.00, memory 0.00>, share <0.00>
I1104 15:58:54.075097   66853 proportion.go:154] Exiting when remaining is empty:  <cpu 0.00, memory 0.00, hugepages-2Mi 0.00>
I1104 15:58:54.075161   66853 enqueue.go:43] Enter Enqueue ...
I1104 15:58:54.075167   66853 enqueue.go:58] Added Queue <default> for Job <default/qj-1>
I1104 15:58:54.075174   66853 enqueue.go:75] Try to enqueue PodGroup to 0 Queues
I1104 15:58:54.075183   66853 enqueue.go:122] Leaving Enqueue ...
I1104 15:58:54.075191   66853 allocate.go:43] Enter Allocate ...
I1104 15:58:54.075198   66853 allocate.go:90] Added Job <default/qj-1> into Queue <default>
I1104 15:58:54.075206   66853 allocate.go:94] Try to allocate resource to 1 Namespaces
I1104 15:58:54.075216   66853 allocate.go:153] Try to allocate resource to Jobs in Namespace <default> Queue <default>
I1104 15:58:54.075227   66853 allocate.go:178] Try to allocate resource to 0 tasks of Job <default/qj-1>
I1104 15:58:54.075232   66853 statement.go:326] Committing operations ...
I1104 15:58:54.075240   66853 allocate.go:153] Try to allocate resource to Jobs in Namespace <default> Queue <default>
I1104 15:58:54.075246   66853 allocate.go:157] Can not find jobs for queue default.
I1104 15:58:54.075260   66853 allocate.go:253] Leaving Allocate ...
I1104 15:58:54.075265   66853 backfill.go:42] Enter Backfill ...
I1104 15:58:54.075271   66853 backfill.go:91] Leaving Backfill ...
I1104 15:58:54.079170   66853 session.go:154] Close Session 0e70a10e-ff5f-11e9-99a6-784f43775513
I1104 15:58:54.079182   66853 scheduler.go:87] End scheduling ...
I1104 15:58:59.081050   66853 scheduler.go:72] Start scheduling ...
I1104 15:58:59.095004   66853 cache.go:732] The priority of job <default/qj-1> is </0>
I1104 15:58:59.095030   66853 cache.go:771] There are <1> Jobs, <1> Queues and <1> Nodes in total for scheduling.
I1104 15:58:59.095037   66853 session.go:135] Open Session 116e9fa0-ff5f-11e9-99a6-784f43775513 with <1> Job and <1> Queues
I1104 15:58:59.095090   66853 proportion.go:67] The total resource is <cpu 4000.00, memory 4959854592.00, hugepages-2Mi 0.00>
I1104 15:58:59.095106   66853 proportion.go:71] Considering Job <default/qj-1>.
I1104 15:58:59.095112   66853 proportion.go:85] Added Queue <default> attributes.
I1104 15:58:59.095122   66853 proportion.go:127] Considering Queue <default>: weight <1>, total weight <1>.
I1104 15:58:59.095136   66853 proportion.go:144] The attributes of queue <default> in proportion: deserved <cpu 4000.00, memory 4959854592.00, hugepages-2Mi 0.00>, allocate <cpu 0.00, memory 0.00>, request <cpu 0.00, memory 0.00>, share <0.00>
I1104 15:58:59.095154   66853 proportion.go:154] Exiting when remaining is empty:  <cpu 0.00, memory 0.00, hugepages-2Mi 0.00>
I1104 15:58:59.095179   66853 enqueue.go:43] Enter Enqueue ...
I1104 15:58:59.095185   66853 enqueue.go:58] Added Queue <default> for Job <default/qj-1>
I1104 15:58:59.095198   66853 enqueue.go:75] Try to enqueue PodGroup to 0 Queues
I1104 15:58:59.095208   66853 enqueue.go:122] Leaving Enqueue ...
I1104 15:58:59.095215   66853 allocate.go:43] Enter Allocate ...
I1104 15:58:59.095222   66853 allocate.go:90] Added Job <default/qj-1> into Queue <default>
I1104 15:58:59.095231   66853 allocate.go:94] Try to allocate resource to 1 Namespaces
I1104 15:58:59.095241   66853 allocate.go:153] Try to allocate resource to Jobs in Namespace <default> Queue <default>
I1104 15:58:59.095252   66853 allocate.go:178] Try to allocate resource to 0 tasks of Job <default/qj-1>
I1104 15:58:59.095258   66853 statement.go:326] Committing operations ...
I1104 15:58:59.095281   66853 allocate.go:153] Try to allocate resource to Jobs in Namespace <default> Queue <default>
I1104 15:58:59.095285   66853 allocate.go:157] Can not find jobs for queue default.
I1104 15:58:59.095295   66853 allocate.go:253] Leaving Allocate ...
I1104 15:58:59.095299   66853 backfill.go:42] Enter Backfill ...
I1104 15:58:59.095303   66853 backfill.go:91] Leaving Backfill ...
I1104 15:58:59.099630   66853 session.go:154] Close Session 116e9fa0-ff5f-11e9-99a6-784f43775513
I1104 15:58:59.099643   66853 scheduler.go:87] End scheduling ...
I1104 15:59:04.100327   66853 scheduler.go:72] Start scheduling ...
I1104 15:59:04.111528   66853 cache.go:732] The priority of job <default/qj-1> is </0>
I1104 15:59:04.111548   66853 cache.go:771] There are <1> Jobs, <1> Queues and <1> Nodes in total for scheduling.
I1104 15:59:04.111552   66853 session.go:135] Open Session 146c167e-ff5f-11e9-99a6-784f43775513 with <1> Job and <1> Queues
I1104 15:59:04.111603   66853 proportion.go:67] The total resource is <cpu 4000.00, memory 4959854592.00, hugepages-2Mi 0.00>
I1104 15:59:04.111614   66853 proportion.go:71] Considering Job <default/qj-1>.
I1104 15:59:04.111618   66853 proportion.go:85] Added Queue <default> attributes.
I1104 15:59:04.111625   66853 proportion.go:127] Considering Queue <default>: weight <1>, total weight <1>.
I1104 15:59:04.111631   66853 proportion.go:144] The attributes of queue <default> in proportion: deserved <cpu 4000.00, memory 4959854592.00, hugepages-2Mi 0.00>, allocate <cpu 0.00, memory 0.00>, request <cpu 0.00, memory 0.00>, share <0.00>
I1104 15:59:04.111642   66853 proportion.go:154] Exiting when remaining is empty:  <cpu 0.00, memory 0.00, hugepages-2Mi 0.00>
I1104 15:59:04.111650   66853 enqueue.go:43] Enter Enqueue ...
I1104 15:59:04.111654   66853 enqueue.go:58] Added Queue <default> for Job <default/qj-1>
I1104 15:59:04.111659   66853 enqueue.go:75] Try to enqueue PodGroup to 0 Queues
I1104 15:59:04.111665   66853 enqueue.go:122] Leaving Enqueue ...
I1104 15:59:04.111670   66853 allocate.go:43] Enter Allocate ...
I1104 15:59:04.111675   66853 allocate.go:90] Added Job <default/qj-1> into Queue <default>
I1104 15:59:04.111680   66853 allocate.go:94] Try to allocate resource to 1 Namespaces
I1104 15:59:04.111687   66853 allocate.go:153] Try to allocate resource to Jobs in Namespace <default> Queue <default>
I1104 15:59:04.111694   66853 allocate.go:178] Try to allocate resource to 0 tasks of Job <default/qj-1>
I1104 15:59:04.111699   66853 statement.go:326] Committing operations ...
I1104 15:59:04.111705   66853 allocate.go:153] Try to allocate resource to Jobs in Namespace <default> Queue <default>
I1104 15:59:04.111709   66853 allocate.go:157] Can not find jobs for queue default.
I1104 15:59:04.111718   66853 allocate.go:253] Leaving Allocate ...
I1104 15:59:04.111722   66853 backfill.go:42] Enter Backfill ...
I1104 15:59:04.111726   66853 backfill.go:91] Leaving Backfill ...
I1104 15:59:04.115897   66853 session.go:154] Close Session 146c167e-ff5f-11e9-99a6-784f43775513
I1104 15:59:04.115907   66853 scheduler.go:87] End scheduling ...
I1104 15:59:09.116073   66853 scheduler.go:72] Start scheduling ...
I1104 15:59:09.130478   66853 cache.go:732] The priority of job <default/qj-1> is </0>
I1104 15:59:09.130509   66853 cache.go:771] There are <1> Jobs, <1> Queues and <1> Nodes in total for scheduling.
I1104 15:59:09.130517   66853 session.go:135] Open Session 1769ea9a-ff5f-11e9-99a6-784f43775513 with <1> Job and <1> Queues
I1104 15:59:09.130569   66853 proportion.go:67] The total resource is <cpu 4000.00, memory 4959854592.00, hugepages-2Mi 0.00>
I1104 15:59:09.130587   66853 proportion.go:71] Considering Job <default/qj-1>.
I1104 15:59:09.130597   66853 proportion.go:85] Added Queue <default> attributes.
I1104 15:59:09.130606   66853 proportion.go:127] Considering Queue <default>: weight <1>, total weight <1>.
I1104 15:59:09.130614   66853 proportion.go:144] The attributes of queue <default> in proportion: deserved <cpu 4000.00, memory 4959854592.00, hugepages-2Mi 0.00>, allocate <cpu 0.00, memory 0.00>, request <cpu 0.00, memory 0.00>, share <0.00>
I1104 15:59:09.130632   66853 proportion.go:154] Exiting when remaining is empty:  <cpu 0.00, memory 0.00, hugepages-2Mi 0.00>
I1104 15:59:09.130661   66853 enqueue.go:43] Enter Enqueue ...
I1104 15:59:09.130666   66853 enqueue.go:58] Added Queue <default> for Job <default/qj-1>
I1104 15:59:09.130673   66853 enqueue.go:75] Try to enqueue PodGroup to 0 Queues
I1104 15:59:09.130681   66853 enqueue.go:122] Leaving Enqueue ...
I1104 15:59:09.130688   66853 allocate.go:43] Enter Allocate ...
I1104 15:59:09.130694   66853 allocate.go:90] Added Job <default/qj-1> into Queue <default>
I1104 15:59:09.130701   66853 allocate.go:94] Try to allocate resource to 1 Namespaces
I1104 15:59:09.130709   66853 allocate.go:153] Try to allocate resource to Jobs in Namespace <default> Queue <default>
I1104 15:59:09.130719   66853 allocate.go:178] Try to allocate resource to 0 tasks of Job <default/qj-1>
I1104 15:59:09.130725   66853 statement.go:326] Committing operations ...
I1104 15:59:09.130732   66853 allocate.go:153] Try to allocate resource to Jobs in Namespace <default> Queue <default>
I1104 15:59:09.130738   66853 allocate.go:157] Can not find jobs for queue default.
I1104 15:59:09.130749   66853 allocate.go:253] Leaving Allocate ...
I1104 15:59:09.130754   66853 backfill.go:42] Enter Backfill ...
I1104 15:59:09.130759   66853 backfill.go:91] Leaving Backfill ...
I1104 15:59:09.134443   66853 session.go:154] Close Session 1769ea9a-ff5f-11e9-99a6-784f43775513
I1104 15:59:09.134453   66853 scheduler.go:87] End scheduling ...
I1104 15:59:14.135050   66853 scheduler.go:72] Start scheduling ...
I1104 15:59:14.145034   66853 cache.go:732] The priority of job <default/qj-1> is </0>
I1104 15:59:14.145055   66853 cache.go:771] There are <1> Jobs, <1> Queues and <1> Nodes in total for scheduling.
I1104 15:59:14.145060   66853 session.go:135] Open Session 1a67142a-ff5f-11e9-99a6-784f43775513 with <1> Job and <1> Queues
I1104 15:59:14.145073   66853 proportion.go:67] The total resource is <cpu 4000.00, memory 4959854592.00, hugepages-2Mi 0.00>
I1104 15:59:14.145085   66853 proportion.go:71] Considering Job <default/qj-1>.
I1104 15:59:14.145090   66853 proportion.go:85] Added Queue <default> attributes.
I1104 15:59:14.145097   66853 proportion.go:127] Considering Queue <default>: weight <1>, total weight <1>.
I1104 15:59:14.145105   66853 proportion.go:144] The attributes of queue <default> in proportion: deserved <cpu 4000.00, memory 4959854592.00, hugepages-2Mi 0.00>, allocate <cpu 0.00, memory 0.00>, request <cpu 0.00, memory 0.00>, share <0.00>
I1104 15:59:14.145117   66853 proportion.go:154] Exiting when remaining is empty:  <cpu 0.00, memory 0.00, hugepages-2Mi 0.00>
I1104 15:59:14.145165   66853 enqueue.go:43] Enter Enqueue ...
I1104 15:59:14.145169   66853 enqueue.go:58] Added Queue <default> for Job <default/qj-1>
I1104 15:59:14.145175   66853 enqueue.go:75] Try to enqueue PodGroup to 0 Queues
I1104 15:59:14.145181   66853 enqueue.go:122] Leaving Enqueue ...
I1104 15:59:14.145188   66853 allocate.go:43] Enter Allocate ...
I1104 15:59:14.145193   66853 allocate.go:90] Added Job <default/qj-1> into Queue <default>
I1104 15:59:14.145200   66853 allocate.go:94] Try to allocate resource to 1 Namespaces
I1104 15:59:14.145207   66853 allocate.go:153] Try to allocate resource to Jobs in Namespace <default> Queue <default>
I1104 15:59:14.145215   66853 allocate.go:178] Try to allocate resource to 0 tasks of Job <default/qj-1>
I1104 15:59:14.145219   66853 statement.go:326] Committing operations ...
I1104 15:59:14.145226   66853 allocate.go:153] Try to allocate resource to Jobs in Namespace <default> Queue <default>
I1104 15:59:14.145232   66853 allocate.go:157] Can not find jobs for queue default.
I1104 15:59:14.145241   66853 allocate.go:253] Leaving Allocate ...
I1104 15:59:14.145247   66853 backfill.go:42] Enter Backfill ...
I1104 15:59:14.145251   66853 backfill.go:91] Leaving Backfill ...
I1104 15:59:14.149498   66853 session.go:154] Close Session 1a67142a-ff5f-11e9-99a6-784f43775513
I1104 15:59:14.149509   66853 scheduler.go:87] End scheduling ...
I1104 15:59:19.153314   66853 scheduler.go:72] Start scheduling ...
I1104 15:59:19.159499   66853 cache.go:732] The priority of job <default/qj-1> is </0>
I1104 15:59:19.159516   66853 cache.go:771] There are <1> Jobs, <1> Queues and <1> Nodes in total for scheduling.
I1104 15:59:19.159520   66853 session.go:135] Open Session 1d6439f0-ff5f-11e9-99a6-784f43775513 with <1> Job and <1> Queues
I1104 15:59:19.159558   66853 proportion.go:67] The total resource is <cpu 4000.00, memory 4959854592.00, hugepages-2Mi 0.00>
I1104 15:59:19.159569   66853 proportion.go:71] Considering Job <default/qj-1>.
I1104 15:59:19.159573   66853 proportion.go:85] Added Queue <default> attributes.
I1104 15:59:19.159579   66853 proportion.go:127] Considering Queue <default>: weight <1>, total weight <1>.
I1104 15:59:19.159586   66853 proportion.go:144] The attributes of queue <default> in proportion: deserved <cpu 4000.00, memory 4959854592.00, hugepages-2Mi 0.00>, allocate <cpu 0.00, memory 0.00>, request <cpu 0.00, memory 0.00>, share <0.00>
I1104 15:59:19.159597   66853 proportion.go:154] Exiting when remaining is empty:  <cpu 0.00, memory 0.00, hugepages-2Mi 0.00>
I1104 15:59:19.159614   66853 enqueue.go:43] Enter Enqueue ...
I1104 15:59:19.159618   66853 enqueue.go:58] Added Queue <default> for Job <default/qj-1>
I1104 15:59:19.159626   66853 enqueue.go:75] Try to enqueue PodGroup to 0 Queues
I1104 15:59:19.159633   66853 enqueue.go:122] Leaving Enqueue ...
I1104 15:59:19.159639   66853 allocate.go:43] Enter Allocate ...
I1104 15:59:19.159643   66853 allocate.go:90] Added Job <default/qj-1> into Queue <default>
I1104 15:59:19.159649   66853 allocate.go:94] Try to allocate resource to 1 Namespaces
I1104 15:59:19.159657   66853 allocate.go:153] Try to allocate resource to Jobs in Namespace <default> Queue <default>
I1104 15:59:19.159663   66853 allocate.go:178] Try to allocate resource to 0 tasks of Job <default/qj-1>
I1104 15:59:19.159667   66853 statement.go:326] Committing operations ...
I1104 15:59:19.159672   66853 allocate.go:153] Try to allocate resource to Jobs in Namespace <default> Queue <default>
I1104 15:59:19.159677   66853 allocate.go:157] Can not find jobs for queue default.
I1104 15:59:19.159686   66853 allocate.go:253] Leaving Allocate ...
I1104 15:59:19.159690   66853 backfill.go:42] Enter Backfill ...
I1104 15:59:19.159694   66853 backfill.go:91] Leaving Backfill ...
I1104 15:59:19.164104   66853 session.go:154] Close Session 1d6439f0-ff5f-11e9-99a6-784f43775513
I1104 15:59:19.164114   66853 scheduler.go:87] End scheduling ...
I1104 15:59:24.166119   66853 scheduler.go:72] Start scheduling ...
I1104 15:59:24.177489   66853 cache.go:732] The priority of job <default/qj-1> is </0>
I1104 15:59:24.177510   66853 cache.go:771] There are <1> Jobs, <1> Queues and <1> Nodes in total for scheduling.
I1104 15:59:24.177515   66853 session.go:135] Open Session 2061e8d2-ff5f-11e9-99a6-784f43775513 with <1> Job and <1> Queues
I1104 15:59:24.177555   66853 proportion.go:67] The total resource is <cpu 4000.00, memory 4959854592.00, hugepages-2Mi 0.00>
I1104 15:59:24.177569   66853 proportion.go:71] Considering Job <default/qj-1>.
I1104 15:59:24.177574   66853 proportion.go:85] Added Queue <default> attributes.
I1104 15:59:24.177581   66853 proportion.go:127] Considering Queue <default>: weight <1>, total weight <1>.
I1104 15:59:24.177591   66853 proportion.go:144] The attributes of queue <default> in proportion: deserved <cpu 4000.00, memory 4959854592.00, hugepages-2Mi 0.00>, allocate <cpu 0.00, memory 0.00>, request <cpu 0.00, memory 0.00>, share <0.00>
I1104 15:59:24.177607   66853 proportion.go:154] Exiting when remaining is empty:  <cpu 0.00, memory 0.00, hugepages-2Mi 0.00>
I1104 15:59:24.177631   66853 enqueue.go:43] Enter Enqueue ...
I1104 15:59:24.177635   66853 enqueue.go:58] Added Queue <default> for Job <default/qj-1>
I1104 15:59:24.177641   66853 enqueue.go:75] Try to enqueue PodGroup to 0 Queues
I1104 15:59:24.177648   66853 enqueue.go:122] Leaving Enqueue ...
I1104 15:59:24.177654   66853 allocate.go:43] Enter Allocate ...
I1104 15:59:24.177659   66853 allocate.go:90] Added Job <default/qj-1> into Queue <default>
I1104 15:59:24.177665   66853 allocate.go:94] Try to allocate resource to 1 Namespaces
I1104 15:59:24.177673   66853 allocate.go:153] Try to allocate resource to Jobs in Namespace <default> Queue <default>
I1104 15:59:24.177680   66853 allocate.go:178] Try to allocate resource to 0 tasks of Job <default/qj-1>
I1104 15:59:24.177685   66853 statement.go:326] Committing operations ...
I1104 15:59:24.177691   66853 allocate.go:153] Try to allocate resource to Jobs in Namespace <default> Queue <default>
I1104 15:59:24.177696   66853 allocate.go:157] Can not find jobs for queue default.
I1104 15:59:24.177707   66853 allocate.go:253] Leaving Allocate ...
I1104 15:59:24.177711   66853 backfill.go:42] Enter Backfill ...
I1104 15:59:24.177716   66853 backfill.go:91] Leaving Backfill ...
I1104 15:59:24.182328   66853 session.go:154] Close Session 2061e8d2-ff5f-11e9-99a6-784f43775513
I1104 15:59:24.182338   66853 scheduler.go:87] End scheduling ...
I1104 15:59:29.183098   66853 scheduler.go:72] Start scheduling ...
I1104 15:59:29.196742   66853 cache.go:732] The priority of job <default/qj-1> is </0>
I1104 15:59:29.196771   66853 cache.go:771] There are <1> Jobs, <1> Queues and <1> Nodes in total for scheduling.
I1104 15:59:29.196779   66853 session.go:135] Open Session 235fc8a6-ff5f-11e9-99a6-784f43775513 with <1> Job and <1> Queues
I1104 15:59:29.196849   66853 proportion.go:67] The total resource is <cpu 4000.00, memory 4959854592.00, hugepages-2Mi 0.00>
I1104 15:59:29.196863   66853 proportion.go:71] Considering Job <default/qj-1>.
I1104 15:59:29.196868   66853 proportion.go:85] Added Queue <default> attributes.
I1104 15:59:29.196875   66853 proportion.go:127] Considering Queue <default>: weight <1>, total weight <1>.
I1104 15:59:29.196886   66853 proportion.go:144] The attributes of queue <default> in proportion: deserved <cpu 4000.00, memory 4959854592.00, hugepages-2Mi 0.00>, allocate <cpu 0.00, memory 0.00>, request <cpu 0.00, memory 0.00>, share <0.00>
I1104 15:59:29.196900   66853 proportion.go:154] Exiting when remaining is empty:  <cpu 0.00, memory 0.00, hugepages-2Mi 0.00>
I1104 15:59:29.196933   66853 enqueue.go:43] Enter Enqueue ...
I1104 15:59:29.196937   66853 enqueue.go:58] Added Queue <default> for Job <default/qj-1>
I1104 15:59:29.196942   66853 enqueue.go:75] Try to enqueue PodGroup to 0 Queues
I1104 15:59:29.196950   66853 enqueue.go:122] Leaving Enqueue ...
I1104 15:59:29.196957   66853 allocate.go:43] Enter Allocate ...
I1104 15:59:29.196961   66853 allocate.go:90] Added Job <default/qj-1> into Queue <default>
I1104 15:59:29.196966   66853 allocate.go:94] Try to allocate resource to 1 Namespaces
I1104 15:59:29.196973   66853 allocate.go:153] Try to allocate resource to Jobs in Namespace <default> Queue <default>
I1104 15:59:29.196982   66853 allocate.go:178] Try to allocate resource to 0 tasks of Job <default/qj-1>
I1104 15:59:29.196986   66853 statement.go:326] Committing operations ...
I1104 15:59:29.196991   66853 allocate.go:153] Try to allocate resource to Jobs in Namespace <default> Queue <default>
I1104 15:59:29.196998   66853 allocate.go:157] Can not find jobs for queue default.
I1104 15:59:29.197007   66853 allocate.go:253] Leaving Allocate ...
I1104 15:59:29.197010   66853 backfill.go:42] Enter Backfill ...
I1104 15:59:29.197014   66853 backfill.go:91] Leaving Backfill ...
I1104 15:59:29.211035   66853 session.go:154] Close Session 235fc8a6-ff5f-11e9-99a6-784f43775513
I1104 15:59:29.211046   66853 scheduler.go:87] End scheduling ...
I1104 15:59:34.211391   66853 scheduler.go:72] Start scheduling ...
I1104 15:59:34.211568   66853 cache.go:732] The priority of job <default/qj-1> is </0>
I1104 15:59:34.211588   66853 cache.go:771] There are <1> Jobs, <1> Queues and <1> Nodes in total for scheduling.
I1104 15:59:34.211593   66853 session.go:135] Open Session 265cfd3a-ff5f-11e9-99a6-784f43775513 with <1> Job and <1> Queues
I1104 15:59:34.211634   66853 proportion.go:67] The total resource is <cpu 4000.00, memory 4959854592.00, hugepages-2Mi 0.00>
I1104 15:59:34.211646   66853 proportion.go:71] Considering Job <default/qj-1>.
I1104 15:59:34.211650   66853 proportion.go:85] Added Queue <default> attributes.
I1104 15:59:34.211659   66853 proportion.go:127] Considering Queue <default>: weight <1>, total weight <1>.
I1104 15:59:34.211665   66853 proportion.go:144] The attributes of queue <default> in proportion: deserved <cpu 4000.00, memory 4959854592.00, hugepages-2Mi 0.00>, allocate <cpu 0.00, memory 0.00>, request <cpu 0.00, memory 0.00>, share <0.00>
I1104 15:59:34.211676   66853 proportion.go:154] Exiting when remaining is empty:  <cpu 0.00, memory 0.00, hugepages-2Mi 0.00>
I1104 15:59:34.211693   66853 enqueue.go:43] Enter Enqueue ...
I1104 15:59:34.211697   66853 enqueue.go:58] Added Queue <default> for Job <default/qj-1>
I1104 15:59:34.211702   66853 enqueue.go:75] Try to enqueue PodGroup to 0 Queues
I1104 15:59:34.211708   66853 enqueue.go:122] Leaving Enqueue ...
I1104 15:59:34.211714   66853 allocate.go:43] Enter Allocate ...
I1104 15:59:34.211719   66853 allocate.go:90] Added Job <default/qj-1> into Queue <default>
I1104 15:59:34.211724   66853 allocate.go:94] Try to allocate resource to 1 Namespaces
I1104 15:59:34.211731   66853 allocate.go:153] Try to allocate resource to Jobs in Namespace <default> Queue <default>
I1104 15:59:34.211737   66853 allocate.go:178] Try to allocate resource to 0 tasks of Job <default/qj-1>
I1104 15:59:34.211742   66853 statement.go:326] Committing operations ...
I1104 15:59:34.211747   66853 allocate.go:153] Try to allocate resource to Jobs in Namespace <default> Queue <default>
I1104 15:59:34.211751   66853 allocate.go:157] Can not find jobs for queue default.
I1104 15:59:34.211760   66853 allocate.go:253] Leaving Allocate ...
I1104 15:59:34.211763   66853 backfill.go:42] Enter Backfill ...
I1104 15:59:34.211767   66853 backfill.go:91] Leaving Backfill ...
I1104 15:59:34.216551   66853 session.go:154] Close Session 265cfd3a-ff5f-11e9-99a6-784f43775513
I1104 15:59:34.216562   66853 scheduler.go:87] End scheduling ...
I1104 15:59:39.216890   66853 scheduler.go:72] Start scheduling ...
I1104 15:59:39.220361   66853 cache.go:732] The priority of job <default/qj-1> is </0>
I1104 15:59:39.220377   66853 cache.go:771] There are <1> Jobs, <1> Queues and <1> Nodes in total for scheduling.
I1104 15:59:39.220382   66853 session.go:135] Open Session 2959452a-ff5f-11e9-99a6-784f43775513 with <1> Job and <1> Queues
I1104 15:59:39.220417   66853 proportion.go:67] The total resource is <cpu 4000.00, memory 4959854592.00, hugepages-2Mi 0.00>
I1104 15:59:39.220429   66853 proportion.go:71] Considering Job <default/qj-1>.
I1104 15:59:39.220433   66853 proportion.go:85] Added Queue <default> attributes.
I1104 15:59:39.220440   66853 proportion.go:127] Considering Queue <default>: weight <1>, total weight <1>.
I1104 15:59:39.220446   66853 proportion.go:144] The attributes of queue <default> in proportion: deserved <cpu 4000.00, memory 4959854592.00, hugepages-2Mi 0.00>, allocate <cpu 0.00, memory 0.00>, request <cpu 0.00, memory 0.00>, share <0.00>
I1104 15:59:39.220458   66853 proportion.go:154] Exiting when remaining is empty:  <cpu 0.00, memory 0.00, hugepages-2Mi 0.00>
I1104 15:59:39.220481   66853 enqueue.go:43] Enter Enqueue ...
I1104 15:59:39.220484   66853 enqueue.go:58] Added Queue <default> for Job <default/qj-1>
I1104 15:59:39.220489   66853 enqueue.go:75] Try to enqueue PodGroup to 0 Queues
I1104 15:59:39.220495   66853 enqueue.go:122] Leaving Enqueue ...
I1104 15:59:39.220502   66853 allocate.go:43] Enter Allocate ...
I1104 15:59:39.220507   66853 allocate.go:90] Added Job <default/qj-1> into Queue <default>
I1104 15:59:39.220512   66853 allocate.go:94] Try to allocate resource to 1 Namespaces
I1104 15:59:39.220519   66853 allocate.go:153] Try to allocate resource to Jobs in Namespace <default> Queue <default>
I1104 15:59:39.220526   66853 allocate.go:178] Try to allocate resource to 0 tasks of Job <default/qj-1>
I1104 15:59:39.220530   66853 statement.go:326] Committing operations ...
I1104 15:59:39.220535   66853 allocate.go:153] Try to allocate resource to Jobs in Namespace <default> Queue <default>
I1104 15:59:39.220539   66853 allocate.go:157] Can not find jobs for queue default.
I1104 15:59:39.220548   66853 allocate.go:253] Leaving Allocate ...
I1104 15:59:39.220552   66853 backfill.go:42] Enter Backfill ...
I1104 15:59:39.220556   66853 backfill.go:91] Leaving Backfill ...
I1104 15:59:39.224749   66853 session.go:154] Close Session 2959452a-ff5f-11e9-99a6-784f43775513
I1104 15:59:39.224760   66853 scheduler.go:87] End scheduling ...
I1104 15:59:44.227548   66853 scheduler.go:72] Start scheduling ...
I1104 15:59:44.236768   66853 cache.go:732] The priority of job <default/qj-1> is </0>
I1104 15:59:44.236787   66853 cache.go:771] There are <1> Jobs, <1> Queues and <1> Nodes in total for scheduling.
I1104 15:59:44.236792   66853 session.go:135] Open Session 2c56b6cc-ff5f-11e9-99a6-784f43775513 with <1> Job and <1> Queues
I1104 15:59:44.236828   66853 proportion.go:67] The total resource is <cpu 4000.00, memory 4959854592.00, hugepages-2Mi 0.00>
I1104 15:59:44.236840   66853 proportion.go:71] Considering Job <default/qj-1>.
I1104 15:59:44.236844   66853 proportion.go:85] Added Queue <default> attributes.
I1104 15:59:44.236851   66853 proportion.go:127] Considering Queue <default>: weight <1>, total weight <1>.
I1104 15:59:44.236858   66853 proportion.go:144] The attributes of queue <default> in proportion: deserved <cpu 4000.00, memory 4959854592.00, hugepages-2Mi 0.00>, allocate <cpu 0.00, memory 0.00>, request <cpu 0.00, memory 0.00>, share <0.00>
I1104 15:59:44.236870   66853 proportion.go:154] Exiting when remaining is empty:  <cpu 0.00, memory 0.00, hugepages-2Mi 0.00>
I1104 15:59:44.236891   66853 enqueue.go:43] Enter Enqueue ...
I1104 15:59:44.236894   66853 enqueue.go:58] Added Queue <default> for Job <default/qj-1>
I1104 15:59:44.236899   66853 enqueue.go:75] Try to enqueue PodGroup to 0 Queues
I1104 15:59:44.236906   66853 enqueue.go:122] Leaving Enqueue ...
I1104 15:59:44.236911   66853 allocate.go:43] Enter Allocate ...
I1104 15:59:44.236916   66853 allocate.go:90] Added Job <default/qj-1> into Queue <default>
I1104 15:59:44.236921   66853 allocate.go:94] Try to allocate resource to 1 Namespaces
I1104 15:59:44.236928   66853 allocate.go:153] Try to allocate resource to Jobs in Namespace <default> Queue <default>
I1104 15:59:44.236935   66853 allocate.go:178] Try to allocate resource to 0 tasks of Job <default/qj-1>
I1104 15:59:44.236939   66853 statement.go:326] Committing operations ...
I1104 15:59:44.236944   66853 allocate.go:153] Try to allocate resource to Jobs in Namespace <default> Queue <default>
I1104 15:59:44.236948   66853 allocate.go:157] Can not find jobs for queue default.
I1104 15:59:44.236958   66853 allocate.go:253] Leaving Allocate ...
I1104 15:59:44.236961   66853 backfill.go:42] Enter Backfill ...
I1104 15:59:44.236966   66853 backfill.go:91] Leaving Backfill ...
I1104 15:59:44.240649   66853 session.go:154] Close Session 2c56b6cc-ff5f-11e9-99a6-784f43775513
I1104 15:59:44.240663   66853 scheduler.go:87] End scheduling ...
I1104 15:59:49.242605   66853 scheduler.go:72] Start scheduling ...
I1104 15:59:49.251670   66853 cache.go:732] The priority of job <default/qj-1> is </0>
I1104 15:59:49.251697   66853 cache.go:771] There are <1> Jobs, <1> Queues and <1> Nodes in total for scheduling.
I1104 15:59:49.251704   66853 session.go:135] Open Session 2f53ec96-ff5f-11e9-99a6-784f43775513 with <1> Job and <1> Queues
I1104 15:59:49.251719   66853 proportion.go:67] The total resource is <cpu 4000.00, memory 4959854592.00, hugepages-2Mi 0.00>
I1104 15:59:49.251735   66853 proportion.go:71] Considering Job <default/qj-1>.
I1104 15:59:49.251742   66853 proportion.go:85] Added Queue <default> attributes.
I1104 15:59:49.251751   66853 proportion.go:127] Considering Queue <default>: weight <1>, total weight <1>.
I1104 15:59:49.251761   66853 proportion.go:144] The attributes of queue <default> in proportion: deserved <cpu 4000.00, memory 4959854592.00, hugepages-2Mi 0.00>, allocate <cpu 0.00, memory 0.00>, request <cpu 0.00, memory 0.00>, share <0.00>
I1104 15:59:49.251779   66853 proportion.go:154] Exiting when remaining is empty:  <cpu 0.00, memory 0.00, hugepages-2Mi 0.00>
I1104 15:59:49.251840   66853 enqueue.go:43] Enter Enqueue ...
I1104 15:59:49.251846   66853 enqueue.go:58] Added Queue <default> for Job <default/qj-1>
I1104 15:59:49.251853   66853 enqueue.go:75] Try to enqueue PodGroup to 0 Queues
I1104 15:59:49.251863   66853 enqueue.go:122] Leaving Enqueue ...
I1104 15:59:49.251871   66853 allocate.go:43] Enter Allocate ...
I1104 15:59:49.251877   66853 allocate.go:90] Added Job <default/qj-1> into Queue <default>
I1104 15:59:49.251886   66853 allocate.go:94] Try to allocate resource to 1 Namespaces
I1104 15:59:49.251896   66853 allocate.go:153] Try to allocate resource to Jobs in Namespace <default> Queue <default>
I1104 15:59:49.251906   66853 allocate.go:178] Try to allocate resource to 0 tasks of Job <default/qj-1>
I1104 15:59:49.251912   66853 statement.go:326] Committing operations ...
I1104 15:59:49.251920   66853 allocate.go:153] Try to allocate resource to Jobs in Namespace <default> Queue <default>
I1104 15:59:49.251927   66853 allocate.go:157] Can not find jobs for queue default.
I1104 15:59:49.251941   66853 allocate.go:253] Leaving Allocate ...
I1104 15:59:49.251946   66853 backfill.go:42] Enter Backfill ...
I1104 15:59:49.251952   66853 backfill.go:91] Leaving Backfill ...
I1104 15:59:49.256679   66853 session.go:154] Close Session 2f53ec96-ff5f-11e9-99a6-784f43775513
I1104 15:59:49.256691   66853 scheduler.go:87] End scheduling ...
I1104 15:59:54.256942   66853 scheduler.go:72] Start scheduling ...
I1104 15:59:54.270969   66853 cache.go:732] The priority of job <default/qj-1> is </0>
I1104 15:59:54.270997   66853 cache.go:771] There are <1> Jobs, <1> Queues and <1> Nodes in total for scheduling.
I1104 15:59:54.271005   66853 session.go:135] Open Session 3251ced6-ff5f-11e9-99a6-784f43775513 with <1> Job and <1> Queues
I1104 15:59:54.271058   66853 proportion.go:67] The total resource is <cpu 4000.00, memory 4959854592.00, hugepages-2Mi 0.00>
I1104 15:59:54.271076   66853 proportion.go:71] Considering Job <default/qj-1>.
I1104 15:59:54.271082   66853 proportion.go:85] Added Queue <default> attributes.
I1104 15:59:54.271093   66853 proportion.go:127] Considering Queue <default>: weight <1>, total weight <1>.
I1104 15:59:54.271102   66853 proportion.go:144] The attributes of queue <default> in proportion: deserved <cpu 4000.00, memory 4959854592.00, hugepages-2Mi 0.00>, allocate <cpu 0.00, memory 0.00>, request <cpu 0.00, memory 0.00>, share <0.00>
I1104 15:59:54.271120   66853 proportion.go:154] Exiting when remaining is empty:  <cpu 0.00, memory 0.00, hugepages-2Mi 0.00>
I1104 15:59:54.271149   66853 enqueue.go:43] Enter Enqueue ...
I1104 15:59:54.271155   66853 enqueue.go:58] Added Queue <default> for Job <default/qj-1>
I1104 15:59:54.271162   66853 enqueue.go:75] Try to enqueue PodGroup to 0 Queues
I1104 15:59:54.271171   66853 enqueue.go:122] Leaving Enqueue ...
I1104 15:59:54.271180   66853 allocate.go:43] Enter Allocate ...
I1104 15:59:54.271186   66853 allocate.go:90] Added Job <default/qj-1> into Queue <default>
I1104 15:59:54.271195   66853 allocate.go:94] Try to allocate resource to 1 Namespaces
I1104 15:59:54.271205   66853 allocate.go:153] Try to allocate resource to Jobs in Namespace <default> Queue <default>
I1104 15:59:54.271215   66853 allocate.go:178] Try to allocate resource to 0 tasks of Job <default/qj-1>
I1104 15:59:54.271221   66853 statement.go:326] Committing operations ...
I1104 15:59:54.271229   66853 allocate.go:153] Try to allocate resource to Jobs in Namespace <default> Queue <default>
I1104 15:59:54.271235   66853 allocate.go:157] Can not find jobs for queue default.
I1104 15:59:54.271249   66853 allocate.go:253] Leaving Allocate ...
I1104 15:59:54.271254   66853 backfill.go:42] Enter Backfill ...
I1104 15:59:54.271261   66853 backfill.go:91] Leaving Backfill ...
I1104 15:59:54.275514   66853 session.go:154] Close Session 3251ced6-ff5f-11e9-99a6-784f43775513
I1104 15:59:54.275525   66853 scheduler.go:87] End scheduling ...
I1104 15:59:59.276397   66853 scheduler.go:72] Start scheduling ...
I1104 15:59:59.287958   66853 cache.go:732] The priority of job <default/qj-1> is </0>
I1104 15:59:59.287977   66853 cache.go:771] There are <1> Jobs, <1> Queues and <1> Nodes in total for scheduling.
I1104 15:59:59.287981   66853 session.go:135] Open Session 354f5680-ff5f-11e9-99a6-784f43775513 with <1> Job and <1> Queues
I1104 15:59:59.288012   66853 proportion.go:67] The total resource is <cpu 4000.00, memory 4959854592.00, hugepages-2Mi 0.00>
I1104 15:59:59.288026   66853 proportion.go:71] Considering Job <default/qj-1>.
I1104 15:59:59.288030   66853 proportion.go:85] Added Queue <default> attributes.
I1104 15:59:59.288038   66853 proportion.go:127] Considering Queue <default>: weight <1>, total weight <1>.
I1104 15:59:59.288044   66853 proportion.go:144] The attributes of queue <default> in proportion: deserved <cpu 4000.00, memory 4959854592.00, hugepages-2Mi 0.00>, allocate <cpu 0.00, memory 0.00>, request <cpu 0.00, memory 0.00>, share <0.00>
I1104 15:59:59.288056   66853 proportion.go:154] Exiting when remaining is empty:  <cpu 0.00, memory 0.00, hugepages-2Mi 0.00>
I1104 15:59:59.288083   66853 enqueue.go:43] Enter Enqueue ...
I1104 15:59:59.288087   66853 enqueue.go:58] Added Queue <default> for Job <default/qj-1>
I1104 15:59:59.288091   66853 enqueue.go:75] Try to enqueue PodGroup to 0 Queues
I1104 15:59:59.288098   66853 enqueue.go:122] Leaving Enqueue ...
I1104 15:59:59.288103   66853 allocate.go:43] Enter Allocate ...
I1104 15:59:59.288108   66853 allocate.go:90] Added Job <default/qj-1> into Queue <default>
I1104 15:59:59.288114   66853 allocate.go:94] Try to allocate resource to 1 Namespaces
I1104 15:59:59.288120   66853 allocate.go:153] Try to allocate resource to Jobs in Namespace <default> Queue <default>
I1104 15:59:59.288127   66853 allocate.go:178] Try to allocate resource to 0 tasks of Job <default/qj-1>
I1104 15:59:59.288131   66853 statement.go:326] Committing operations ...
I1104 15:59:59.288136   66853 allocate.go:153] Try to allocate resource to Jobs in Namespace <default> Queue <default>
I1104 15:59:59.288141   66853 allocate.go:157] Can not find jobs for queue default.
I1104 15:59:59.288150   66853 allocate.go:253] Leaving Allocate ...
I1104 15:59:59.288154   66853 backfill.go:42] Enter Backfill ...
I1104 15:59:59.288158   66853 backfill.go:91] Leaving Backfill ...
I1104 15:59:59.291904   66853 session.go:154] Close Session 354f5680-ff5f-11e9-99a6-784f43775513
I1104 15:59:59.291925   66853 scheduler.go:87] End scheduling ...
I1104 16:00:04.292936   66853 scheduler.go:72] Start scheduling ...
I1104 16:00:04.300512   66853 cache.go:732] The priority of job <default/qj-1> is </0>
I1104 16:00:04.300533   66853 cache.go:771] There are <1> Jobs, <1> Queues and <1> Nodes in total for scheduling.
I1104 16:00:04.300538   66853 session.go:135] Open Session 384c32a4-ff5f-11e9-99a6-784f43775513 with <1> Job and <1> Queues
I1104 16:00:04.300576   66853 proportion.go:67] The total resource is <cpu 4000.00, memory 4959854592.00, hugepages-2Mi 0.00>
I1104 16:00:04.300588   66853 proportion.go:71] Considering Job <default/qj-1>.
I1104 16:00:04.300593   66853 proportion.go:85] Added Queue <default> attributes.
I1104 16:00:04.300601   66853 proportion.go:127] Considering Queue <default>: weight <1>, total weight <1>.
I1104 16:00:04.300607   66853 proportion.go:144] The attributes of queue <default> in proportion: deserved <cpu 4000.00, memory 4959854592.00, hugepages-2Mi 0.00>, allocate <cpu 0.00, memory 0.00>, request <cpu 0.00, memory 0.00>, share <0.00>
I1104 16:00:04.300619   66853 proportion.go:154] Exiting when remaining is empty:  <cpu 0.00, memory 0.00, hugepages-2Mi 0.00>
I1104 16:00:04.300637   66853 enqueue.go:43] Enter Enqueue ...
I1104 16:00:04.300641   66853 enqueue.go:58] Added Queue <default> for Job <default/qj-1>
I1104 16:00:04.300646   66853 enqueue.go:75] Try to enqueue PodGroup to 0 Queues
I1104 16:00:04.300653   66853 enqueue.go:122] Leaving Enqueue ...
I1104 16:00:04.300658   66853 allocate.go:43] Enter Allocate ...
I1104 16:00:04.300663   66853 allocate.go:90] Added Job <default/qj-1> into Queue <default>
I1104 16:00:04.300668   66853 allocate.go:94] Try to allocate resource to 1 Namespaces
I1104 16:00:04.300675   66853 allocate.go:153] Try to allocate resource to Jobs in Namespace <default> Queue <default>
I1104 16:00:04.300682   66853 allocate.go:178] Try to allocate resource to 0 tasks of Job <default/qj-1>
I1104 16:00:04.300686   66853 statement.go:326] Committing operations ...
I1104 16:00:04.300691   66853 allocate.go:153] Try to allocate resource to Jobs in Namespace <default> Queue <default>
I1104 16:00:04.300695   66853 allocate.go:157] Can not find jobs for queue default.
I1104 16:00:04.300705   66853 allocate.go:253] Leaving Allocate ...
I1104 16:00:04.300708   66853 backfill.go:42] Enter Backfill ...
I1104 16:00:04.300712   66853 backfill.go:91] Leaving Backfill ...
I1104 16:00:04.304622   66853 session.go:154] Close Session 384c32a4-ff5f-11e9-99a6-784f43775513
I1104 16:00:04.304632   66853 scheduler.go:87] End scheduling ...
I1104 16:00:09.307286   66853 scheduler.go:72] Start scheduling ...
I1104 16:00:09.316001   66853 cache.go:732] The priority of job <default/qj-1> is </0>
I1104 16:00:09.316019   66853 cache.go:771] There are <1> Jobs, <1> Queues and <1> Nodes in total for scheduling.
I1104 16:00:09.316024   66853 session.go:135] Open Session 3b498024-ff5f-11e9-99a6-784f43775513 with <1> Job and <1> Queues
I1104 16:00:09.316062   66853 proportion.go:67] The total resource is <cpu 4000.00, memory 4959854592.00, hugepages-2Mi 0.00>
I1104 16:00:09.316073   66853 proportion.go:71] Considering Job <default/qj-1>.
I1104 16:00:09.316077   66853 proportion.go:85] Added Queue <default> attributes.
I1104 16:00:09.316084   66853 proportion.go:127] Considering Queue <default>: weight <1>, total weight <1>.
I1104 16:00:09.316090   66853 proportion.go:144] The attributes of queue <default> in proportion: deserved <cpu 4000.00, memory 4959854592.00, hugepages-2Mi 0.00>, allocate <cpu 0.00, memory 0.00>, request <cpu 0.00, memory 0.00>, share <0.00>
I1104 16:00:09.316105   66853 proportion.go:154] Exiting when remaining is empty:  <cpu 0.00, memory 0.00, hugepages-2Mi 0.00>
I1104 16:00:09.316123   66853 enqueue.go:43] Enter Enqueue ...
I1104 16:00:09.316127   66853 enqueue.go:58] Added Queue <default> for Job <default/qj-1>
I1104 16:00:09.316132   66853 enqueue.go:75] Try to enqueue PodGroup to 0 Queues
I1104 16:00:09.316138   66853 enqueue.go:122] Leaving Enqueue ...
I1104 16:00:09.316143   66853 allocate.go:43] Enter Allocate ...
I1104 16:00:09.316148   66853 allocate.go:90] Added Job <default/qj-1> into Queue <default>
I1104 16:00:09.316153   66853 allocate.go:94] Try to allocate resource to 1 Namespaces
I1104 16:00:09.316160   66853 allocate.go:153] Try to allocate resource to Jobs in Namespace <default> Queue <default>
I1104 16:00:09.316167   66853 allocate.go:178] Try to allocate resource to 0 tasks of Job <default/qj-1>
I1104 16:00:09.316171   66853 statement.go:326] Committing operations ...
I1104 16:00:09.316176   66853 allocate.go:153] Try to allocate resource to Jobs in Namespace <default> Queue <default>
I1104 16:00:09.316180   66853 allocate.go:157] Can not find jobs for queue default.
I1104 16:00:09.316189   66853 allocate.go:253] Leaving Allocate ...
I1104 16:00:09.316193   66853 backfill.go:42] Enter Backfill ...
I1104 16:00:09.316197   66853 backfill.go:91] Leaving Backfill ...
I1104 16:00:09.320157   66853 session.go:154] Close Session 3b498024-ff5f-11e9-99a6-784f43775513
I1104 16:00:09.320168   66853 scheduler.go:87] End scheduling ...
I1104 16:00:14.323569   66853 scheduler.go:72] Start scheduling ...
I1104 16:00:14.334337   66853 cache.go:732] The priority of job <default/qj-1> is </0>
I1104 16:00:14.334366   66853 cache.go:771] There are <1> Jobs, <1> Queues and <1> Nodes in total for scheduling.
I1104 16:00:14.334371   66853 session.go:135] Open Session 3e473ce4-ff5f-11e9-99a6-784f43775513 with <1> Job and <1> Queues
I1104 16:00:14.334382   66853 proportion.go:67] The total resource is <cpu 4000.00, memory 4959854592.00, hugepages-2Mi 0.00>
I1104 16:00:14.334394   66853 proportion.go:71] Considering Job <default/qj-1>.
I1104 16:00:14.334398   66853 proportion.go:85] Added Queue <default> attributes.
I1104 16:00:14.334405   66853 proportion.go:127] Considering Queue <default>: weight <1>, total weight <1>.
I1104 16:00:14.334411   66853 proportion.go:144] The attributes of queue <default> in proportion: deserved <cpu 4000.00, memory 4959854592.00, hugepages-2Mi 0.00>, allocate <cpu 0.00, memory 0.00>, request <cpu 0.00, memory 0.00>, share <0.00>
I1104 16:00:14.334424   66853 proportion.go:154] Exiting when remaining is empty:  <cpu 0.00, memory 0.00, hugepages-2Mi 0.00>
I1104 16:00:14.334469   66853 enqueue.go:43] Enter Enqueue ...
I1104 16:00:14.334473   66853 enqueue.go:58] Added Queue <default> for Job <default/qj-1>
I1104 16:00:14.334478   66853 enqueue.go:75] Try to enqueue PodGroup to 0 Queues
I1104 16:00:14.334485   66853 enqueue.go:122] Leaving Enqueue ...
I1104 16:00:14.334490   66853 allocate.go:43] Enter Allocate ...
I1104 16:00:14.334494   66853 allocate.go:90] Added Job <default/qj-1> into Queue <default>
I1104 16:00:14.334500   66853 allocate.go:94] Try to allocate resource to 1 Namespaces
I1104 16:00:14.334507   66853 allocate.go:153] Try to allocate resource to Jobs in Namespace <default> Queue <default>
I1104 16:00:14.334514   66853 allocate.go:178] Try to allocate resource to 0 tasks of Job <default/qj-1>
I1104 16:00:14.334517   66853 statement.go:326] Committing operations ...
I1104 16:00:14.334522   66853 allocate.go:153] Try to allocate resource to Jobs in Namespace <default> Queue <default>
I1104 16:00:14.334527   66853 allocate.go:157] Can not find jobs for queue default.
I1104 16:00:14.334536   66853 allocate.go:253] Leaving Allocate ...
I1104 16:00:14.334540   66853 backfill.go:42] Enter Backfill ...
I1104 16:00:14.334544   66853 backfill.go:91] Leaving Backfill ...
I1104 16:00:14.342845   66853 session.go:154] Close Session 3e473ce4-ff5f-11e9-99a6-784f43775513
I1104 16:00:14.342856   66853 scheduler.go:87] End scheduling ...
I1104 16:00:19.343209   66853 scheduler.go:72] Start scheduling ...
I1104 16:00:19.348537   66853 cache.go:732] The priority of job <default/qj-1> is </0>
I1104 16:00:19.348556   66853 cache.go:771] There are <1> Jobs, <1> Queues and <1> Nodes in total for scheduling.
I1104 16:00:19.348561   66853 session.go:135] Open Session 41445724-ff5f-11e9-99a6-784f43775513 with <1> Job and <1> Queues
I1104 16:00:19.348608   66853 proportion.go:67] The total resource is <cpu 4000.00, memory 4959854592.00, hugepages-2Mi 0.00>
I1104 16:00:19.348620   66853 proportion.go:71] Considering Job <default/qj-1>.
I1104 16:00:19.348624   66853 proportion.go:85] Added Queue <default> attributes.
I1104 16:00:19.348632   66853 proportion.go:127] Considering Queue <default>: weight <1>, total weight <1>.
I1104 16:00:19.348640   66853 proportion.go:144] The attributes of queue <default> in proportion: deserved <cpu 4000.00, memory 4959854592.00, hugepages-2Mi 0.00>, allocate <cpu 0.00, memory 0.00>, request <cpu 0.00, memory 0.00>, share <0.00>
I1104 16:00:19.348651   66853 proportion.go:154] Exiting when remaining is empty:  <cpu 0.00, memory 0.00, hugepages-2Mi 0.00>
I1104 16:00:19.348669   66853 enqueue.go:43] Enter Enqueue ...
I1104 16:00:19.348673   66853 enqueue.go:58] Added Queue <default> for Job <default/qj-1>
I1104 16:00:19.348678   66853 enqueue.go:75] Try to enqueue PodGroup to 0 Queues
I1104 16:00:19.348685   66853 enqueue.go:122] Leaving Enqueue ...
I1104 16:00:19.348691   66853 allocate.go:43] Enter Allocate ...
I1104 16:00:19.348697   66853 allocate.go:90] Added Job <default/qj-1> into Queue <default>
I1104 16:00:19.348702   66853 allocate.go:94] Try to allocate resource to 1 Namespaces
I1104 16:00:19.348708   66853 allocate.go:153] Try to allocate resource to Jobs in Namespace <default> Queue <default>
I1104 16:00:19.348715   66853 allocate.go:178] Try to allocate resource to 0 tasks of Job <default/qj-1>
I1104 16:00:19.348720   66853 statement.go:326] Committing operations ...
I1104 16:00:19.348725   66853 allocate.go:153] Try to allocate resource to Jobs in Namespace <default> Queue <default>
I1104 16:00:19.348758   66853 allocate.go:157] Can not find jobs for queue default.
I1104 16:00:19.348772   66853 allocate.go:253] Leaving Allocate ...
I1104 16:00:19.348782   66853 backfill.go:42] Enter Backfill ...
I1104 16:00:19.348788   66853 backfill.go:91] Leaving Backfill ...
I1104 16:00:19.355164   66853 session.go:154] Close Session 41445724-ff5f-11e9-99a6-784f43775513
I1104 16:00:19.355175   66853 scheduler.go:87] End scheduling ...
I1104 16:00:24.360528   66853 scheduler.go:72] Start scheduling ...
I1104 16:00:24.363028   66853 cache.go:732] The priority of job <default/qj-1> is </0>
I1104 16:00:24.363056   66853 cache.go:771] There are <1> Jobs, <1> Queues and <1> Nodes in total for scheduling.
I1104 16:00:24.363063   66853 session.go:135] Open Session 44417df8-ff5f-11e9-99a6-784f43775513 with <1> Job and <1> Queues
I1104 16:00:24.363114   66853 proportion.go:67] The total resource is <cpu 4000.00, memory 4959854592.00, hugepages-2Mi 0.00>
I1104 16:00:24.363130   66853 proportion.go:71] Considering Job <default/qj-1>.
I1104 16:00:24.363137   66853 proportion.go:85] Added Queue <default> attributes.
I1104 16:00:24.363152   66853 proportion.go:127] Considering Queue <default>: weight <1>, total weight <1>.
I1104 16:00:24.363162   66853 proportion.go:144] The attributes of queue <default> in proportion: deserved <cpu 4000.00, memory 4959854592.00, hugepages-2Mi 0.00>, allocate <cpu 0.00, memory 0.00>, request <cpu 0.00, memory 0.00>, share <0.00>
I1104 16:00:24.363181   66853 proportion.go:154] Exiting when remaining is empty:  <cpu 0.00, memory 0.00, hugepages-2Mi 0.00>
I1104 16:00:24.363215   66853 enqueue.go:43] Enter Enqueue ...
I1104 16:00:24.363221   66853 enqueue.go:58] Added Queue <default> for Job <default/qj-1>
I1104 16:00:24.363230   66853 enqueue.go:75] Try to enqueue PodGroup to 0 Queues
I1104 16:00:24.363240   66853 enqueue.go:122] Leaving Enqueue ...
I1104 16:00:24.363249   66853 allocate.go:43] Enter Allocate ...
I1104 16:00:24.363257   66853 allocate.go:90] Added Job <default/qj-1> into Queue <default>
I1104 16:00:24.363265   66853 allocate.go:94] Try to allocate resource to 1 Namespaces
I1104 16:00:24.363275   66853 allocate.go:153] Try to allocate resource to Jobs in Namespace <default> Queue <default>
I1104 16:00:24.363286   66853 allocate.go:178] Try to allocate resource to 0 tasks of Job <default/qj-1>
I1104 16:00:24.363293   66853 statement.go:326] Committing operations ...
I1104 16:00:24.363301   66853 allocate.go:153] Try to allocate resource to Jobs in Namespace <default> Queue <default>
I1104 16:00:24.363308   66853 allocate.go:157] Can not find jobs for queue default.
I1104 16:00:24.363322   66853 allocate.go:253] Leaving Allocate ...
I1104 16:00:24.363327   66853 backfill.go:42] Enter Backfill ...
I1104 16:00:24.363333   66853 backfill.go:91] Leaving Backfill ...
I1104 16:00:24.367922   66853 session.go:154] Close Session 44417df8-ff5f-11e9-99a6-784f43775513
I1104 16:00:24.367933   66853 scheduler.go:87] End scheduling ...
I1104 16:00:29.370781   66853 scheduler.go:72] Start scheduling ...
I1104 16:00:29.374831   66853 cache.go:732] The priority of job <default/qj-1> is </0>
I1104 16:00:29.374850   66853 cache.go:771] There are <1> Jobs, <1> Queues and <1> Nodes in total for scheduling.
I1104 16:00:29.374855   66853 session.go:135] Open Session 473e3c30-ff5f-11e9-99a6-784f43775513 with <1> Job and <1> Queues
I1104 16:00:29.374886   66853 proportion.go:67] The total resource is <cpu 4000.00, memory 4959854592.00, hugepages-2Mi 0.00>
I1104 16:00:29.374897   66853 proportion.go:71] Considering Job <default/qj-1>.
I1104 16:00:29.374901   66853 proportion.go:85] Added Queue <default> attributes.
I1104 16:00:29.374908   66853 proportion.go:127] Considering Queue <default>: weight <1>, total weight <1>.
I1104 16:00:29.374914   66853 proportion.go:144] The attributes of queue <default> in proportion: deserved <cpu 4000.00, memory 4959854592.00, hugepages-2Mi 0.00>, allocate <cpu 0.00, memory 0.00>, request <cpu 0.00, memory 0.00>, share <0.00>
I1104 16:00:29.374929   66853 proportion.go:154] Exiting when remaining is empty:  <cpu 0.00, memory 0.00, hugepages-2Mi 0.00>
I1104 16:00:29.374955   66853 enqueue.go:43] Enter Enqueue ...
I1104 16:00:29.374959   66853 enqueue.go:58] Added Queue <default> for Job <default/qj-1>
I1104 16:00:29.374964   66853 enqueue.go:75] Try to enqueue PodGroup to 0 Queues
I1104 16:00:29.374970   66853 enqueue.go:122] Leaving Enqueue ...
I1104 16:00:29.374975   66853 allocate.go:43] Enter Allocate ...
I1104 16:00:29.374979   66853 allocate.go:90] Added Job <default/qj-1> into Queue <default>
I1104 16:00:29.374985   66853 allocate.go:94] Try to allocate resource to 1 Namespaces
I1104 16:00:29.374992   66853 allocate.go:153] Try to allocate resource to Jobs in Namespace <default> Queue <default>
I1104 16:00:29.374999   66853 allocate.go:178] Try to allocate resource to 0 tasks of Job <default/qj-1>
I1104 16:00:29.375002   66853 statement.go:326] Committing operations ...
I1104 16:00:29.375007   66853 allocate.go:153] Try to allocate resource to Jobs in Namespace <default> Queue <default>
I1104 16:00:29.375011   66853 allocate.go:157] Can not find jobs for queue default.
I1104 16:00:29.375020   66853 allocate.go:253] Leaving Allocate ...
I1104 16:00:29.375024   66853 backfill.go:42] Enter Backfill ...
I1104 16:00:29.375029   66853 backfill.go:91] Leaving Backfill ...
I1104 16:00:29.378764   66853 session.go:154] Close Session 473e3c30-ff5f-11e9-99a6-784f43775513
I1104 16:00:29.378774   66853 scheduler.go:87] End scheduling ...
I1104 16:00:34.379932   66853 scheduler.go:72] Start scheduling ...
I1104 16:00:34.390242   66853 cache.go:732] The priority of job <default/qj-1> is </0>
I1104 16:00:34.390260   66853 cache.go:771] There are <1> Jobs, <1> Queues and <1> Nodes in total for scheduling.
I1104 16:00:34.390265   66853 session.go:135] Open Session 4a3b865e-ff5f-11e9-99a6-784f43775513 with <1> Job and <1> Queues
I1104 16:00:34.390302   66853 proportion.go:67] The total resource is <cpu 4000.00, memory 4959854592.00, hugepages-2Mi 0.00>
I1104 16:00:34.390315   66853 proportion.go:71] Considering Job <default/qj-1>.
I1104 16:00:34.390319   66853 proportion.go:85] Added Queue <default> attributes.
I1104 16:00:34.390326   66853 proportion.go:127] Considering Queue <default>: weight <1>, total weight <1>.
I1104 16:00:34.390333   66853 proportion.go:144] The attributes of queue <default> in proportion: deserved <cpu 4000.00, memory 4959854592.00, hugepages-2Mi 0.00>, allocate <cpu 0.00, memory 0.00>, request <cpu 0.00, memory 0.00>, share <0.00>
I1104 16:00:34.390344   66853 proportion.go:154] Exiting when remaining is empty:  <cpu 0.00, memory 0.00, hugepages-2Mi 0.00>
I1104 16:00:34.390367   66853 enqueue.go:43] Enter Enqueue ...
I1104 16:00:34.390371   66853 enqueue.go:58] Added Queue <default> for Job <default/qj-1>
I1104 16:00:34.390376   66853 enqueue.go:75] Try to enqueue PodGroup to 0 Queues
I1104 16:00:34.390382   66853 enqueue.go:122] Leaving Enqueue ...
I1104 16:00:34.390387   66853 allocate.go:43] Enter Allocate ...
I1104 16:00:34.390392   66853 allocate.go:90] Added Job <default/qj-1> into Queue <default>
I1104 16:00:34.390397   66853 allocate.go:94] Try to allocate resource to 1 Namespaces
I1104 16:00:34.390404   66853 allocate.go:153] Try to allocate resource to Jobs in Namespace <default> Queue <default>
I1104 16:00:34.390411   66853 allocate.go:178] Try to allocate resource to 0 tasks of Job <default/qj-1>
I1104 16:00:34.390415   66853 statement.go:326] Committing operations ...
I1104 16:00:34.390420   66853 allocate.go:153] Try to allocate resource to Jobs in Namespace <default> Queue <default>
I1104 16:00:34.390424   66853 allocate.go:157] Can not find jobs for queue default.
I1104 16:00:34.390433   66853 allocate.go:253] Leaving Allocate ...
I1104 16:00:34.390437   66853 backfill.go:42] Enter Backfill ...
I1104 16:00:34.390441   66853 backfill.go:91] Leaving Backfill ...
I1104 16:00:34.394660   66853 session.go:154] Close Session 4a3b865e-ff5f-11e9-99a6-784f43775513
I1104 16:00:34.394671   66853 scheduler.go:87] End scheduling ...
I1104 16:00:39.395043   66853 scheduler.go:72] Start scheduling ...
I1104 16:00:39.404937   66853 cache.go:732] The priority of job <default/qj-1> is </0>
I1104 16:00:39.404955   66853 cache.go:771] There are <1> Jobs, <1> Queues and <1> Nodes in total for scheduling.
I1104 16:00:39.404959   66853 session.go:135] Open Session 4d38b548-ff5f-11e9-99a6-784f43775513 with <1> Job and <1> Queues
I1104 16:00:39.404970   66853 proportion.go:67] The total resource is <cpu 4000.00, memory 4959854592.00, hugepages-2Mi 0.00>
I1104 16:00:39.404982   66853 proportion.go:71] Considering Job <default/qj-1>.
I1104 16:00:39.404986   66853 proportion.go:85] Added Queue <default> attributes.
I1104 16:00:39.404993   66853 proportion.go:127] Considering Queue <default>: weight <1>, total weight <1>.
I1104 16:00:39.404999   66853 proportion.go:144] The attributes of queue <default> in proportion: deserved <cpu 4000.00, memory 4959854592.00, hugepages-2Mi 0.00>, allocate <cpu 0.00, memory 0.00>, request <cpu 0.00, memory 0.00>, share <0.00>
I1104 16:00:39.405010   66853 proportion.go:154] Exiting when remaining is empty:  <cpu 0.00, memory 0.00, hugepages-2Mi 0.00>
I1104 16:00:39.405059   66853 enqueue.go:43] Enter Enqueue ...
I1104 16:00:39.405064   66853 enqueue.go:58] Added Queue <default> for Job <default/qj-1>
I1104 16:00:39.405069   66853 enqueue.go:75] Try to enqueue PodGroup to 0 Queues
I1104 16:00:39.405075   66853 enqueue.go:122] Leaving Enqueue ...
I1104 16:00:39.405081   66853 allocate.go:43] Enter Allocate ...
I1104 16:00:39.405085   66853 allocate.go:90] Added Job <default/qj-1> into Queue <default>
I1104 16:00:39.405091   66853 allocate.go:94] Try to allocate resource to 1 Namespaces
I1104 16:00:39.405097   66853 allocate.go:153] Try to allocate resource to Jobs in Namespace <default> Queue <default>
I1104 16:00:39.405104   66853 allocate.go:178] Try to allocate resource to 0 tasks of Job <default/qj-1>
I1104 16:00:39.405108   66853 statement.go:326] Committing operations ...
I1104 16:00:39.405114   66853 allocate.go:153] Try to allocate resource to Jobs in Namespace <default> Queue <default>
I1104 16:00:39.405118   66853 allocate.go:157] Can not find jobs for queue default.
I1104 16:00:39.405128   66853 allocate.go:253] Leaving Allocate ...
I1104 16:00:39.405132   66853 backfill.go:42] Enter Backfill ...
I1104 16:00:39.405137   66853 backfill.go:91] Leaving Backfill ...
I1104 16:00:39.409600   66853 session.go:154] Close Session 4d38b548-ff5f-11e9-99a6-784f43775513
I1104 16:00:39.409610   66853 scheduler.go:87] End scheduling ...
I1104 16:00:44.410252   66853 scheduler.go:72] Start scheduling ...
I1104 16:00:44.422838   66853 cache.go:732] The priority of job <default/qj-1> is </0>
I1104 16:00:44.422866   66853 cache.go:771] There are <1> Jobs, <1> Queues and <1> Nodes in total for scheduling.
I1104 16:00:44.422873   66853 session.go:135] Open Session 50366060-ff5f-11e9-99a6-784f43775513 with <1> Job and <1> Queues
I1104 16:00:44.422913   66853 proportion.go:67] The total resource is <cpu 4000.00, memory 4959854592.00, hugepages-2Mi 0.00>
I1104 16:00:44.422938   66853 proportion.go:71] Considering Job <default/qj-1>.
I1104 16:00:44.422945   66853 proportion.go:85] Added Queue <default> attributes.
I1104 16:00:44.422955   66853 proportion.go:127] Considering Queue <default>: weight <1>, total weight <1>.
I1104 16:00:44.422965   66853 proportion.go:144] The attributes of queue <default> in proportion: deserved <cpu 4000.00, memory 4959854592.00, hugepages-2Mi 0.00>, allocate <cpu 0.00, memory 0.00>, request <cpu 0.00, memory 0.00>, share <0.00>
I1104 16:00:44.422988   66853 proportion.go:154] Exiting when remaining is empty:  <cpu 0.00, memory 0.00, hugepages-2Mi 0.00>
I1104 16:00:44.423033   66853 enqueue.go:43] Enter Enqueue ...
I1104 16:00:44.423039   66853 enqueue.go:58] Added Queue <default> for Job <default/qj-1>
I1104 16:00:44.423047   66853 enqueue.go:75] Try to enqueue PodGroup to 0 Queues
I1104 16:00:44.423057   66853 enqueue.go:122] Leaving Enqueue ...
I1104 16:00:44.423065   66853 allocate.go:43] Enter Allocate ...
I1104 16:00:44.423072   66853 allocate.go:90] Added Job <default/qj-1> into Queue <default>
I1104 16:00:44.423080   66853 allocate.go:94] Try to allocate resource to 1 Namespaces
I1104 16:00:44.423090   66853 allocate.go:153] Try to allocate resource to Jobs in Namespace <default> Queue <default>
I1104 16:00:44.423101   66853 allocate.go:178] Try to allocate resource to 0 tasks of Job <default/qj-1>
I1104 16:00:44.423106   66853 statement.go:326] Committing operations ...
I1104 16:00:44.423115   66853 allocate.go:153] Try to allocate resource to Jobs in Namespace <default> Queue <default>
I1104 16:00:44.423122   66853 allocate.go:157] Can not find jobs for queue default.
I1104 16:00:44.423137   66853 allocate.go:253] Leaving Allocate ...
I1104 16:00:44.423143   66853 backfill.go:42] Enter Backfill ...
I1104 16:00:44.423149   66853 backfill.go:91] Leaving Backfill ...
I1104 16:00:44.427254   66853 session.go:154] Close Session 50366060-ff5f-11e9-99a6-784f43775513
I1104 16:00:44.427265   66853 scheduler.go:87] End scheduling ...
I1104 16:00:49.431322   66853 scheduler.go:72] Start scheduling ...
I1104 16:00:49.437255   66853 cache.go:732] The priority of job <default/qj-1> is </0>
I1104 16:00:49.437273   66853 cache.go:771] There are <1> Jobs, <1> Queues and <1> Nodes in total for scheduling.
I1104 16:00:49.437277   66853 session.go:135] Open Session 533384be-ff5f-11e9-99a6-784f43775513 with <1> Job and <1> Queues
I1104 16:00:49.437314   66853 proportion.go:67] The total resource is <cpu 4000.00, memory 4959854592.00, hugepages-2Mi 0.00>
I1104 16:00:49.437324   66853 proportion.go:71] Considering Job <default/qj-1>.
I1104 16:00:49.437328   66853 proportion.go:85] Added Queue <default> attributes.
I1104 16:00:49.437335   66853 proportion.go:127] Considering Queue <default>: weight <1>, total weight <1>.
I1104 16:00:49.437341   66853 proportion.go:144] The attributes of queue <default> in proportion: deserved <cpu 4000.00, memory 4959854592.00, hugepages-2Mi 0.00>, allocate <cpu 0.00, memory 0.00>, request <cpu 0.00, memory 0.00>, share <0.00>
I1104 16:00:49.437355   66853 proportion.go:154] Exiting when remaining is empty:  <cpu 0.00, memory 0.00, hugepages-2Mi 0.00>
I1104 16:00:49.437372   66853 enqueue.go:43] Enter Enqueue ...
I1104 16:00:49.437375   66853 enqueue.go:58] Added Queue <default> for Job <default/qj-1>
I1104 16:00:49.437380   66853 enqueue.go:75] Try to enqueue PodGroup to 0 Queues
I1104 16:00:49.437386   66853 enqueue.go:122] Leaving Enqueue ...
I1104 16:00:49.437391   66853 allocate.go:43] Enter Allocate ...
I1104 16:00:49.437395   66853 allocate.go:90] Added Job <default/qj-1> into Queue <default>
I1104 16:00:49.437400   66853 allocate.go:94] Try to allocate resource to 1 Namespaces
I1104 16:00:49.437407   66853 allocate.go:153] Try to allocate resource to Jobs in Namespace <default> Queue <default>
I1104 16:00:49.437413   66853 allocate.go:178] Try to allocate resource to 0 tasks of Job <default/qj-1>
I1104 16:00:49.437417   66853 statement.go:326] Committing operations ...
I1104 16:00:49.437422   66853 allocate.go:153] Try to allocate resource to Jobs in Namespace <default> Queue <default>
I1104 16:00:49.437426   66853 allocate.go:157] Can not find jobs for queue default.
I1104 16:00:49.437436   66853 allocate.go:253] Leaving Allocate ...
I1104 16:00:49.437441   66853 backfill.go:42] Enter Backfill ...
I1104 16:00:49.437447   66853 backfill.go:91] Leaving Backfill ...
I1104 16:00:49.441271   66853 session.go:154] Close Session 533384be-ff5f-11e9-99a6-784f43775513
I1104 16:00:49.441284   66853 scheduler.go:87] End scheduling ...
I1104 16:00:54.445842   66853 scheduler.go:72] Start scheduling ...
I1104 16:00:54.457192   66853 cache.go:732] The priority of job <default/qj-1> is </0>
I1104 16:00:54.457210   66853 cache.go:771] There are <1> Jobs, <1> Queues and <1> Nodes in total for scheduling.
I1104 16:00:54.457214   66853 session.go:135] Open Session 56317ffe-ff5f-11e9-99a6-784f43775513 with <1> Job and <1> Queues
I1104 16:00:54.457252   66853 proportion.go:67] The total resource is <cpu 4000.00, memory 4959854592.00, hugepages-2Mi 0.00>
I1104 16:00:54.457263   66853 proportion.go:71] Considering Job <default/qj-1>.
I1104 16:00:54.457268   66853 proportion.go:85] Added Queue <default> attributes.
I1104 16:00:54.457275   66853 proportion.go:127] Considering Queue <default>: weight <1>, total weight <1>.
I1104 16:00:54.457281   66853 proportion.go:144] The attributes of queue <default> in proportion: deserved <cpu 4000.00, memory 4959854592.00, hugepages-2Mi 0.00>, allocate <cpu 0.00, memory 0.00>, request <cpu 0.00, memory 0.00>, share <0.00>
I1104 16:00:54.457293   66853 proportion.go:154] Exiting when remaining is empty:  <cpu 0.00, memory 0.00, hugepages-2Mi 0.00>
I1104 16:00:54.457311   66853 enqueue.go:43] Enter Enqueue ...
I1104 16:00:54.457315   66853 enqueue.go:58] Added Queue <default> for Job <default/qj-1>
I1104 16:00:54.457320   66853 enqueue.go:75] Try to enqueue PodGroup to 0 Queues
I1104 16:00:54.457326   66853 enqueue.go:122] Leaving Enqueue ...
I1104 16:00:54.457332   66853 allocate.go:43] Enter Allocate ...
I1104 16:00:54.457336   66853 allocate.go:90] Added Job <default/qj-1> into Queue <default>
I1104 16:00:54.457341   66853 allocate.go:94] Try to allocate resource to 1 Namespaces
I1104 16:00:54.457348   66853 allocate.go:153] Try to allocate resource to Jobs in Namespace <default> Queue <default>
I1104 16:00:54.457355   66853 allocate.go:178] Try to allocate resource to 0 tasks of Job <default/qj-1>
I1104 16:00:54.457359   66853 statement.go:326] Committing operations ...
I1104 16:00:54.457364   66853 allocate.go:153] Try to allocate resource to Jobs in Namespace <default> Queue <default>
I1104 16:00:54.457368   66853 allocate.go:157] Can not find jobs for queue default.
I1104 16:00:54.457377   66853 allocate.go:253] Leaving Allocate ...
I1104 16:00:54.457381   66853 backfill.go:42] Enter Backfill ...
I1104 16:00:54.457385   66853 backfill.go:91] Leaving Backfill ...
I1104 16:00:54.460639   66853 session.go:154] Close Session 56317ffe-ff5f-11e9-99a6-784f43775513
I1104 16:00:54.460650   66853 scheduler.go:87] End scheduling ...
I1104 16:00:59.462431   66853 scheduler.go:72] Start scheduling ...
I1104 16:00:59.472372   66853 cache.go:732] The priority of job <default/qj-1> is </0>
I1104 16:00:59.472390   66853 cache.go:771] There are <1> Jobs, <1> Queues and <1> Nodes in total for scheduling.
I1104 16:00:59.472394   66853 session.go:135] Open Session 592ec1a8-ff5f-11e9-99a6-784f43775513 with <1> Job and <1> Queues
I1104 16:00:59.472444   66853 proportion.go:67] The total resource is <cpu 4000.00, memory 4959854592.00, hugepages-2Mi 0.00>
I1104 16:00:59.472456   66853 proportion.go:71] Considering Job <default/qj-1>.
I1104 16:00:59.472461   66853 proportion.go:85] Added Queue <default> attributes.
I1104 16:00:59.472470   66853 proportion.go:127] Considering Queue <default>: weight <1>, total weight <1>.
I1104 16:00:59.472477   66853 proportion.go:144] The attributes of queue <default> in proportion: deserved <cpu 4000.00, memory 4959854592.00, hugepages-2Mi 0.00>, allocate <cpu 0.00, memory 0.00>, request <cpu 0.00, memory 0.00>, share <0.00>
I1104 16:00:59.472488   66853 proportion.go:154] Exiting when remaining is empty:  <cpu 0.00, memory 0.00, hugepages-2Mi 0.00>
I1104 16:00:59.472496   66853 enqueue.go:43] Enter Enqueue ...
I1104 16:00:59.472501   66853 enqueue.go:58] Added Queue <default> for Job <default/qj-1>
I1104 16:00:59.472506   66853 enqueue.go:75] Try to enqueue PodGroup to 0 Queues
I1104 16:00:59.472513   66853 enqueue.go:122] Leaving Enqueue ...
I1104 16:00:59.472519   66853 allocate.go:43] Enter Allocate ...
I1104 16:00:59.472523   66853 allocate.go:90] Added Job <default/qj-1> into Queue <default>
I1104 16:00:59.472529   66853 allocate.go:94] Try to allocate resource to 1 Namespaces
I1104 16:00:59.472538   66853 allocate.go:153] Try to allocate resource to Jobs in Namespace <default> Queue <default>
I1104 16:00:59.472545   66853 allocate.go:178] Try to allocate resource to 0 tasks of Job <default/qj-1>
I1104 16:00:59.472549   66853 statement.go:326] Committing operations ...
I1104 16:00:59.472555   66853 allocate.go:153] Try to allocate resource to Jobs in Namespace <default> Queue <default>
I1104 16:00:59.472561   66853 allocate.go:157] Can not find jobs for queue default.
I1104 16:00:59.472569   66853 allocate.go:253] Leaving Allocate ...
I1104 16:00:59.472574   66853 backfill.go:42] Enter Backfill ...
I1104 16:00:59.472579   66853 backfill.go:91] Leaving Backfill ...
I1104 16:00:59.476103   66853 session.go:154] Close Session 592ec1a8-ff5f-11e9-99a6-784f43775513
I1104 16:00:59.476114   66853 scheduler.go:87] End scheduling ...
I1104 16:01:04.476404   66853 scheduler.go:72] Start scheduling ...
I1104 16:01:04.491004   66853 cache.go:732] The priority of job <default/qj-1> is </0>
I1104 16:01:04.491045   66853 cache.go:771] There are <1> Jobs, <1> Queues and <1> Nodes in total for scheduling.
I1104 16:01:04.491050   66853 session.go:135] Open Session 5c2c8868-ff5f-11e9-99a6-784f43775513 with <1> Job and <1> Queues
I1104 16:01:04.491062   66853 proportion.go:67] The total resource is <cpu 4000.00, memory 4959854592.00, hugepages-2Mi 0.00>
I1104 16:01:04.491075   66853 proportion.go:71] Considering Job <default/qj-1>.
I1104 16:01:04.491079   66853 proportion.go:85] Added Queue <default> attributes.
I1104 16:01:04.491085   66853 proportion.go:127] Considering Queue <default>: weight <1>, total weight <1>.
I1104 16:01:04.491092   66853 proportion.go:144] The attributes of queue <default> in proportion: deserved <cpu 4000.00, memory 4959854592.00, hugepages-2Mi 0.00>, allocate <cpu 0.00, memory 0.00>, request <cpu 0.00, memory 0.00>, share <0.00>
I1104 16:01:04.491104   66853 proportion.go:154] Exiting when remaining is empty:  <cpu 0.00, memory 0.00, hugepages-2Mi 0.00>
I1104 16:01:04.491166   66853 enqueue.go:43] Enter Enqueue ...
I1104 16:01:04.491170   66853 enqueue.go:58] Added Queue <default> for Job <default/qj-1>
I1104 16:01:04.491175   66853 enqueue.go:75] Try to enqueue PodGroup to 0 Queues
I1104 16:01:04.491181   66853 enqueue.go:122] Leaving Enqueue ...
I1104 16:01:04.491188   66853 allocate.go:43] Enter Allocate ...
I1104 16:01:04.491192   66853 allocate.go:90] Added Job <default/qj-1> into Queue <default>
I1104 16:01:04.491198   66853 allocate.go:94] Try to allocate resource to 1 Namespaces
I1104 16:01:04.491204   66853 allocate.go:153] Try to allocate resource to Jobs in Namespace <default> Queue <default>
I1104 16:01:04.491211   66853 allocate.go:178] Try to allocate resource to 0 tasks of Job <default/qj-1>
I1104 16:01:04.491215   66853 statement.go:326] Committing operations ...
I1104 16:01:04.491221   66853 allocate.go:153] Try to allocate resource to Jobs in Namespace <default> Queue <default>
I1104 16:01:04.491225   66853 allocate.go:157] Can not find jobs for queue default.
I1104 16:01:04.491234   66853 allocate.go:253] Leaving Allocate ...
I1104 16:01:04.491238   66853 backfill.go:42] Enter Backfill ...
I1104 16:01:04.491243   66853 backfill.go:91] Leaving Backfill ...
I1104 16:01:04.495164   66853 session.go:154] Close Session 5c2c8868-ff5f-11e9-99a6-784f43775513
I1104 16:01:04.495174   66853 scheduler.go:87] End scheduling ...
I1104 16:01:09.495599   66853 scheduler.go:72] Start scheduling ...
I1104 16:01:09.506885   66853 cache.go:732] The priority of job <default/qj-1> is </0>
I1104 16:01:09.506904   66853 cache.go:771] There are <1> Jobs, <1> Queues and <1> Nodes in total for scheduling.
I1104 16:01:09.506908   66853 session.go:135] Open Session 5f29e6be-ff5f-11e9-99a6-784f43775513 with <1> Job and <1> Queues
I1104 16:01:09.506919   66853 proportion.go:67] The total resource is <cpu 4000.00, memory 4959854592.00, hugepages-2Mi 0.00>
I1104 16:01:09.506929   66853 proportion.go:71] Considering Job <default/qj-1>.
I1104 16:01:09.506932   66853 proportion.go:85] Added Queue <default> attributes.
I1104 16:01:09.506938   66853 proportion.go:127] Considering Queue <default>: weight <1>, total weight <1>.
I1104 16:01:09.506944   66853 proportion.go:144] The attributes of queue <default> in proportion: deserved <cpu 4000.00, memory 4959854592.00, hugepages-2Mi 0.00>, allocate <cpu 0.00, memory 0.00>, request <cpu 0.00, memory 0.00>, share <0.00>
I1104 16:01:09.506953   66853 proportion.go:154] Exiting when remaining is empty:  <cpu 0.00, memory 0.00, hugepages-2Mi 0.00>
I1104 16:01:09.506994   66853 enqueue.go:43] Enter Enqueue ...
I1104 16:01:09.506998   66853 enqueue.go:58] Added Queue <default> for Job <default/qj-1>
I1104 16:01:09.507002   66853 enqueue.go:75] Try to enqueue PodGroup to 0 Queues
I1104 16:01:09.507008   66853 enqueue.go:122] Leaving Enqueue ...
I1104 16:01:09.507013   66853 allocate.go:43] Enter Allocate ...
I1104 16:01:09.507017   66853 allocate.go:90] Added Job <default/qj-1> into Queue <default>
I1104 16:01:09.507022   66853 allocate.go:94] Try to allocate resource to 1 Namespaces
I1104 16:01:09.507027   66853 allocate.go:153] Try to allocate resource to Jobs in Namespace <default> Queue <default>
I1104 16:01:09.507033   66853 allocate.go:178] Try to allocate resource to 0 tasks of Job <default/qj-1>
I1104 16:01:09.507037   66853 statement.go:326] Committing operations ...
I1104 16:01:09.507041   66853 allocate.go:153] Try to allocate resource to Jobs in Namespace <default> Queue <default>
I1104 16:01:09.507045   66853 allocate.go:157] Can not find jobs for queue default.
I1104 16:01:09.507053   66853 allocate.go:253] Leaving Allocate ...
I1104 16:01:09.507056   66853 backfill.go:42] Enter Backfill ...
I1104 16:01:09.507059   66853 backfill.go:91] Leaving Backfill ...
I1104 16:01:09.511093   66853 session.go:154] Close Session 5f29e6be-ff5f-11e9-99a6-784f43775513
I1104 16:01:09.511106   66853 scheduler.go:87] End scheduling ...
I1104 16:01:14.514772   66853 scheduler.go:72] Start scheduling ...
I1104 16:01:14.521571   66853 cache.go:732] The priority of job <default/qj-1> is </0>
I1104 16:01:14.521596   66853 cache.go:771] There are <1> Jobs, <1> Queues and <1> Nodes in total for scheduling.
I1104 16:01:14.521603   66853 session.go:135] Open Session 6227140e-ff5f-11e9-99a6-784f43775513 with <1> Job and <1> Queues
I1104 16:01:14.521653   66853 proportion.go:67] The total resource is <cpu 4000.00, memory 4959854592.00, hugepages-2Mi 0.00>
I1104 16:01:14.521673   66853 proportion.go:71] Considering Job <default/qj-1>.
I1104 16:01:14.521680   66853 proportion.go:85] Added Queue <default> attributes.
I1104 16:01:14.521690   66853 proportion.go:127] Considering Queue <default>: weight <1>, total weight <1>.
I1104 16:01:14.521700   66853 proportion.go:144] The attributes of queue <default> in proportion: deserved <cpu 4000.00, memory 4959854592.00, hugepages-2Mi 0.00>, allocate <cpu 0.00, memory 0.00>, request <cpu 0.00, memory 0.00>, share <0.00>
I1104 16:01:14.521717   66853 proportion.go:154] Exiting when remaining is empty:  <cpu 0.00, memory 0.00, hugepages-2Mi 0.00>
I1104 16:01:14.521748   66853 enqueue.go:43] Enter Enqueue ...
I1104 16:01:14.521753   66853 enqueue.go:58] Added Queue <default> for Job <default/qj-1>
I1104 16:01:14.521760   66853 enqueue.go:75] Try to enqueue PodGroup to 0 Queues
I1104 16:01:14.521770   66853 enqueue.go:122] Leaving Enqueue ...
I1104 16:01:14.521777   66853 allocate.go:43] Enter Allocate ...
I1104 16:01:14.521784   66853 allocate.go:90] Added Job <default/qj-1> into Queue <default>
I1104 16:01:14.521792   66853 allocate.go:94] Try to allocate resource to 1 Namespaces
I1104 16:01:14.521802   66853 allocate.go:153] Try to allocate resource to Jobs in Namespace <default> Queue <default>
I1104 16:01:14.521812   66853 allocate.go:178] Try to allocate resource to 0 tasks of Job <default/qj-1>
I1104 16:01:14.521817   66853 statement.go:326] Committing operations ...
I1104 16:01:14.521825   66853 allocate.go:153] Try to allocate resource to Jobs in Namespace <default> Queue <default>
I1104 16:01:14.521832   66853 allocate.go:157] Can not find jobs for queue default.
I1104 16:01:14.521848   66853 allocate.go:253] Leaving Allocate ...
I1104 16:01:14.521853   66853 backfill.go:42] Enter Backfill ...
I1104 16:01:14.521860   66853 backfill.go:91] Leaving Backfill ...
I1104 16:01:14.526823   66853 session.go:154] Close Session 6227140e-ff5f-11e9-99a6-784f43775513
I1104 16:01:14.526834   66853 scheduler.go:87] End scheduling ...
I1104 16:01:19.530428   66853 scheduler.go:72] Start scheduling ...
I1104 16:01:19.535542   66853 cache.go:732] The priority of job <default/qj-1> is </0>
I1104 16:01:19.535558   66853 cache.go:771] There are <1> Jobs, <1> Queues and <1> Nodes in total for scheduling.
I1104 16:01:19.535562   66853 session.go:135] Open Session 6524273c-ff5f-11e9-99a6-784f43775513 with <1> Job and <1> Queues
I1104 16:01:19.535597   66853 proportion.go:67] The total resource is <cpu 4000.00, memory 4959854592.00, hugepages-2Mi 0.00>
I1104 16:01:19.535606   66853 proportion.go:71] Considering Job <default/qj-1>.
I1104 16:01:19.535610   66853 proportion.go:85] Added Queue <default> attributes.
I1104 16:01:19.535616   66853 proportion.go:127] Considering Queue <default>: weight <1>, total weight <1>.
I1104 16:01:19.535624   66853 proportion.go:144] The attributes of queue <default> in proportion: deserved <cpu 4000.00, memory 4959854592.00, hugepages-2Mi 0.00>, allocate <cpu 0.00, memory 0.00>, request <cpu 0.00, memory 0.00>, share <0.00>
I1104 16:01:19.535634   66853 proportion.go:154] Exiting when remaining is empty:  <cpu 0.00, memory 0.00, hugepages-2Mi 0.00>
I1104 16:01:19.535650   66853 enqueue.go:43] Enter Enqueue ...
I1104 16:01:19.535654   66853 enqueue.go:58] Added Queue <default> for Job <default/qj-1>
I1104 16:01:19.535658   66853 enqueue.go:75] Try to enqueue PodGroup to 0 Queues
I1104 16:01:19.535664   66853 enqueue.go:122] Leaving Enqueue ...
I1104 16:01:19.535669   66853 allocate.go:43] Enter Allocate ...
I1104 16:01:19.535673   66853 allocate.go:90] Added Job <default/qj-1> into Queue <default>
I1104 16:01:19.535678   66853 allocate.go:94] Try to allocate resource to 1 Namespaces
I1104 16:01:19.535683   66853 allocate.go:153] Try to allocate resource to Jobs in Namespace <default> Queue <default>
I1104 16:01:19.535690   66853 allocate.go:178] Try to allocate resource to 0 tasks of Job <default/qj-1>
I1104 16:01:19.535693   66853 statement.go:326] Committing operations ...
I1104 16:01:19.535698   66853 allocate.go:153] Try to allocate resource to Jobs in Namespace <default> Queue <default>
I1104 16:01:19.535701   66853 allocate.go:157] Can not find jobs for queue default.
I1104 16:01:19.535710   66853 allocate.go:253] Leaving Allocate ...
I1104 16:01:19.535713   66853 backfill.go:42] Enter Backfill ...
I1104 16:01:19.535717   66853 backfill.go:91] Leaving Backfill ...
I1104 16:01:19.540207   66853 session.go:154] Close Session 6524273c-ff5f-11e9-99a6-784f43775513
I1104 16:01:19.540217   66853 scheduler.go:87] End scheduling ...
I1104 16:01:24.545504   66853 scheduler.go:72] Start scheduling ...
I1104 16:01:24.547267   66853 cache.go:732] The priority of job <default/qj-1> is </0>
I1104 16:01:24.547286   66853 cache.go:771] There are <1> Jobs, <1> Queues and <1> Nodes in total for scheduling.
I1104 16:01:24.547291   66853 session.go:135] Open Session 6820e164-ff5f-11e9-99a6-784f43775513 with <1> Job and <1> Queues
I1104 16:01:24.547327   66853 proportion.go:67] The total resource is <cpu 4000.00, memory 4959854592.00, hugepages-2Mi 0.00>
I1104 16:01:24.547338   66853 proportion.go:71] Considering Job <default/qj-1>.
I1104 16:01:24.547342   66853 proportion.go:85] Added Queue <default> attributes.
I1104 16:01:24.547349   66853 proportion.go:127] Considering Queue <default>: weight <1>, total weight <1>.
I1104 16:01:24.547355   66853 proportion.go:144] The attributes of queue <default> in proportion: deserved <cpu 4000.00, memory 4959854592.00, hugepages-2Mi 0.00>, allocate <cpu 0.00, memory 0.00>, request <cpu 0.00, memory 0.00>, share <0.00>
I1104 16:01:24.547366   66853 proportion.go:154] Exiting when remaining is empty:  <cpu 0.00, memory 0.00, hugepages-2Mi 0.00>
I1104 16:01:24.547388   66853 enqueue.go:43] Enter Enqueue ...
I1104 16:01:24.547392   66853 enqueue.go:58] Added Queue <default> for Job <default/qj-1>
I1104 16:01:24.547397   66853 enqueue.go:75] Try to enqueue PodGroup to 0 Queues
I1104 16:01:24.547403   66853 enqueue.go:122] Leaving Enqueue ...
I1104 16:01:24.547409   66853 allocate.go:43] Enter Allocate ...
I1104 16:01:24.547414   66853 allocate.go:90] Added Job <default/qj-1> into Queue <default>
I1104 16:01:24.547419   66853 allocate.go:94] Try to allocate resource to 1 Namespaces
I1104 16:01:24.547426   66853 allocate.go:153] Try to allocate resource to Jobs in Namespace <default> Queue <default>
I1104 16:01:24.547433   66853 allocate.go:178] Try to allocate resource to 0 tasks of Job <default/qj-1>
I1104 16:01:24.547437   66853 statement.go:326] Committing operations ...
I1104 16:01:24.547442   66853 allocate.go:153] Try to allocate resource to Jobs in Namespace <default> Queue <default>
I1104 16:01:24.547446   66853 allocate.go:157] Can not find jobs for queue default.
I1104 16:01:24.547455   66853 allocate.go:253] Leaving Allocate ...
I1104 16:01:24.547459   66853 backfill.go:42] Enter Backfill ...
I1104 16:01:24.547463   66853 backfill.go:91] Leaving Backfill ...
I1104 16:01:24.550825   66853 session.go:154] Close Session 6820e164-ff5f-11e9-99a6-784f43775513
I1104 16:01:24.550836   66853 scheduler.go:87] End scheduling ...
I1104 16:01:29.555262   66853 scheduler.go:72] Start scheduling ...
I1104 16:01:29.566481   66853 cache.go:732] The priority of job <default/qj-1> is </0>
I1104 16:01:29.566499   66853 cache.go:771] There are <1> Jobs, <1> Queues and <1> Nodes in total for scheduling.
I1104 16:01:29.566506   66853 session.go:135] Open Session 6b1ec098-ff5f-11e9-99a6-784f43775513 with <1> Job and <1> Queues
I1104 16:01:29.566517   66853 proportion.go:67] The total resource is <cpu 4000.00, memory 4959854592.00, hugepages-2Mi 0.00>
I1104 16:01:29.566527   66853 proportion.go:71] Considering Job <default/qj-1>.
I1104 16:01:29.566531   66853 proportion.go:85] Added Queue <default> attributes.
I1104 16:01:29.566537   66853 proportion.go:127] Considering Queue <default>: weight <1>, total weight <1>.
I1104 16:01:29.566544   66853 proportion.go:144] The attributes of queue <default> in proportion: deserved <cpu 4000.00, memory 4959854592.00, hugepages-2Mi 0.00>, allocate <cpu 0.00, memory 0.00>, request <cpu 0.00, memory 0.00>, share <0.00>
I1104 16:01:29.566554   66853 proportion.go:154] Exiting when remaining is empty:  <cpu 0.00, memory 0.00, hugepages-2Mi 0.00>
I1104 16:01:29.566596   66853 enqueue.go:43] Enter Enqueue ...
I1104 16:01:29.566600   66853 enqueue.go:58] Added Queue <default> for Job <default/qj-1>
I1104 16:01:29.566606   66853 enqueue.go:75] Try to enqueue PodGroup to 0 Queues
I1104 16:01:29.566613   66853 enqueue.go:122] Leaving Enqueue ...
I1104 16:01:29.566618   66853 allocate.go:43] Enter Allocate ...
I1104 16:01:29.566622   66853 allocate.go:90] Added Job <default/qj-1> into Queue <default>
I1104 16:01:29.566627   66853 allocate.go:94] Try to allocate resource to 1 Namespaces
I1104 16:01:29.566634   66853 allocate.go:153] Try to allocate resource to Jobs in Namespace <default> Queue <default>
I1104 16:01:29.566640   66853 allocate.go:178] Try to allocate resource to 0 tasks of Job <default/qj-1>
I1104 16:01:29.566644   66853 statement.go:326] Committing operations ...
I1104 16:01:29.566649   66853 allocate.go:153] Try to allocate resource to Jobs in Namespace <default> Queue <default>
I1104 16:01:29.566652   66853 allocate.go:157] Can not find jobs for queue default.
I1104 16:01:29.566661   66853 allocate.go:253] Leaving Allocate ...
I1104 16:01:29.566665   66853 backfill.go:42] Enter Backfill ...
I1104 16:01:29.566669   66853 backfill.go:91] Leaving Backfill ...
I1104 16:01:29.571651   66853 session.go:154] Close Session 6b1ec098-ff5f-11e9-99a6-784f43775513
I1104 16:01:29.571662   66853 scheduler.go:87] End scheduling ...
I1104 16:01:34.575828   66853 scheduler.go:72] Start scheduling ...
I1104 16:01:34.582883   66853 cache.go:732] The priority of job <default/qj-1> is </0>
I1104 16:01:34.582904   66853 cache.go:771] There are <1> Jobs, <1> Queues and <1> Nodes in total for scheduling.
I1104 16:01:34.582910   66853 session.go:135] Open Session 6e1c3168-ff5f-11e9-99a6-784f43775513 with <1> Job and <1> Queues
I1104 16:01:34.582955   66853 proportion.go:67] The total resource is <cpu 4000.00, memory 4959854592.00, hugepages-2Mi 0.00>
I1104 16:01:34.582968   66853 proportion.go:71] Considering Job <default/qj-1>.
I1104 16:01:34.582973   66853 proportion.go:85] Added Queue <default> attributes.
I1104 16:01:34.582981   66853 proportion.go:127] Considering Queue <default>: weight <1>, total weight <1>.
I1104 16:01:34.582988   66853 proportion.go:144] The attributes of queue <default> in proportion: deserved <cpu 4000.00, memory 4959854592.00, hugepages-2Mi 0.00>, allocate <cpu 0.00, memory 0.00>, request <cpu 0.00, memory 0.00>, share <0.00>
I1104 16:01:34.583002   66853 proportion.go:154] Exiting when remaining is empty:  <cpu 0.00, memory 0.00, hugepages-2Mi 0.00>
I1104 16:01:34.583021   66853 enqueue.go:43] Enter Enqueue ...
I1104 16:01:34.583025   66853 enqueue.go:58] Added Queue <default> for Job <default/qj-1>
I1104 16:01:34.583031   66853 enqueue.go:75] Try to enqueue PodGroup to 0 Queues
I1104 16:01:34.583038   66853 enqueue.go:122] Leaving Enqueue ...
I1104 16:01:34.583045   66853 allocate.go:43] Enter Allocate ...
I1104 16:01:34.583050   66853 allocate.go:90] Added Job <default/qj-1> into Queue <default>
I1104 16:01:34.583056   66853 allocate.go:94] Try to allocate resource to 1 Namespaces
I1104 16:01:34.583063   66853 allocate.go:153] Try to allocate resource to Jobs in Namespace <default> Queue <default>
I1104 16:01:34.583071   66853 allocate.go:178] Try to allocate resource to 0 tasks of Job <default/qj-1>
I1104 16:01:34.583077   66853 statement.go:326] Committing operations ...
I1104 16:01:34.583083   66853 allocate.go:153] Try to allocate resource to Jobs in Namespace <default> Queue <default>
I1104 16:01:34.583088   66853 allocate.go:157] Can not find jobs for queue default.
I1104 16:01:34.583099   66853 allocate.go:253] Leaving Allocate ...
I1104 16:01:34.583104   66853 backfill.go:42] Enter Backfill ...
I1104 16:01:34.583108   66853 backfill.go:91] Leaving Backfill ...
I1104 16:01:34.587719   66853 session.go:154] Close Session 6e1c3168-ff5f-11e9-99a6-784f43775513
I1104 16:01:34.587730   66853 scheduler.go:87] End scheduling ...
I1104 16:01:39.587887   66853 scheduler.go:72] Start scheduling ...
I1104 16:01:39.599404   66853 cache.go:732] The priority of job <default/qj-1> is </0>
I1104 16:01:39.599422   66853 cache.go:771] There are <1> Jobs, <1> Queues and <1> Nodes in total for scheduling.
I1104 16:01:39.599427   66853 session.go:135] Open Session 7119a76a-ff5f-11e9-99a6-784f43775513 with <1> Job and <1> Queues
I1104 16:01:39.599462   66853 proportion.go:67] The total resource is <cpu 4000.00, memory 4959854592.00, hugepages-2Mi 0.00>
I1104 16:01:39.599473   66853 proportion.go:71] Considering Job <default/qj-1>.
I1104 16:01:39.599478   66853 proportion.go:85] Added Queue <default> attributes.
I1104 16:01:39.599485   66853 proportion.go:127] Considering Queue <default>: weight <1>, total weight <1>.
I1104 16:01:39.599493   66853 proportion.go:144] The attributes of queue <default> in proportion: deserved <cpu 4000.00, memory 4959854592.00, hugepages-2Mi 0.00>, allocate <cpu 0.00, memory 0.00>, request <cpu 0.00, memory 0.00>, share <0.00>
I1104 16:01:39.599504   66853 proportion.go:154] Exiting when remaining is empty:  <cpu 0.00, memory 0.00, hugepages-2Mi 0.00>
I1104 16:01:39.599521   66853 enqueue.go:43] Enter Enqueue ...
I1104 16:01:39.599525   66853 enqueue.go:58] Added Queue <default> for Job <default/qj-1>
I1104 16:01:39.599530   66853 enqueue.go:75] Try to enqueue PodGroup to 0 Queues
I1104 16:01:39.599536   66853 enqueue.go:122] Leaving Enqueue ...
I1104 16:01:39.599541   66853 allocate.go:43] Enter Allocate ...
I1104 16:01:39.599545   66853 allocate.go:90] Added Job <default/qj-1> into Queue <default>
I1104 16:01:39.599551   66853 allocate.go:94] Try to allocate resource to 1 Namespaces
I1104 16:01:39.599557   66853 allocate.go:153] Try to allocate resource to Jobs in Namespace <default> Queue <default>
I1104 16:01:39.599563   66853 allocate.go:178] Try to allocate resource to 0 tasks of Job <default/qj-1>
I1104 16:01:39.599567   66853 statement.go:326] Committing operations ...
I1104 16:01:39.599572   66853 allocate.go:153] Try to allocate resource to Jobs in Namespace <default> Queue <default>
I1104 16:01:39.599576   66853 allocate.go:157] Can not find jobs for queue default.
I1104 16:01:39.599585   66853 allocate.go:253] Leaving Allocate ...
I1104 16:01:39.599588   66853 backfill.go:42] Enter Backfill ...
I1104 16:01:39.599592   66853 backfill.go:91] Leaving Backfill ...
I1104 16:01:39.604821   66853 session.go:154] Close Session 7119a76a-ff5f-11e9-99a6-784f43775513
I1104 16:01:39.604831   66853 scheduler.go:87] End scheduling ...
I1104 16:01:44.605944   66853 scheduler.go:72] Start scheduling ...
I1104 16:01:44.616795   66853 cache.go:732] The priority of job <default/qj-1> is </0>
I1104 16:01:44.616814   66853 cache.go:771] There are <1> Jobs, <1> Queues and <1> Nodes in total for scheduling.
I1104 16:01:44.616819   66853 session.go:135] Open Session 74173f9a-ff5f-11e9-99a6-784f43775513 with <1> Job and <1> Queues
I1104 16:01:44.616865   66853 proportion.go:67] The total resource is <cpu 4000.00, memory 4959854592.00, hugepages-2Mi 0.00>
I1104 16:01:44.616877   66853 proportion.go:71] Considering Job <default/qj-1>.
I1104 16:01:44.616882   66853 proportion.go:85] Added Queue <default> attributes.
I1104 16:01:44.616889   66853 proportion.go:127] Considering Queue <default>: weight <1>, total weight <1>.
I1104 16:01:44.616895   66853 proportion.go:144] The attributes of queue <default> in proportion: deserved <cpu 4000.00, memory 4959854592.00, hugepages-2Mi 0.00>, allocate <cpu 0.00, memory 0.00>, request <cpu 0.00, memory 0.00>, share <0.00>
I1104 16:01:44.616906   66853 proportion.go:154] Exiting when remaining is empty:  <cpu 0.00, memory 0.00, hugepages-2Mi 0.00>
I1104 16:01:44.616914   66853 enqueue.go:43] Enter Enqueue ...
I1104 16:01:44.616917   66853 enqueue.go:58] Added Queue <default> for Job <default/qj-1>
I1104 16:01:44.616922   66853 enqueue.go:75] Try to enqueue PodGroup to 0 Queues
I1104 16:01:44.616928   66853 enqueue.go:122] Leaving Enqueue ...
I1104 16:01:44.616934   66853 allocate.go:43] Enter Allocate ...
I1104 16:01:44.616938   66853 allocate.go:90] Added Job <default/qj-1> into Queue <default>
I1104 16:01:44.616944   66853 allocate.go:94] Try to allocate resource to 1 Namespaces
I1104 16:01:44.616950   66853 allocate.go:153] Try to allocate resource to Jobs in Namespace <default> Queue <default>
I1104 16:01:44.616957   66853 allocate.go:178] Try to allocate resource to 0 tasks of Job <default/qj-1>
I1104 16:01:44.616961   66853 statement.go:326] Committing operations ...
I1104 16:01:44.616966   66853 allocate.go:153] Try to allocate resource to Jobs in Namespace <default> Queue <default>
I1104 16:01:44.616970   66853 allocate.go:157] Can not find jobs for queue default.
I1104 16:01:44.616979   66853 allocate.go:253] Leaving Allocate ...
I1104 16:01:44.616983   66853 backfill.go:42] Enter Backfill ...
I1104 16:01:44.616987   66853 backfill.go:91] Leaving Backfill ...
I1104 16:01:44.620640   66853 session.go:154] Close Session 74173f9a-ff5f-11e9-99a6-784f43775513
I1104 16:01:44.620652   66853 scheduler.go:87] End scheduling ...
I1104 16:01:49.624636   66853 scheduler.go:72] Start scheduling ...
I1104 16:01:49.631608   66853 cache.go:732] The priority of job <default/qj-1> is </0>
I1104 16:01:49.631630   66853 cache.go:771] There are <1> Jobs, <1> Queues and <1> Nodes in total for scheduling.
I1104 16:01:49.631635   66853 session.go:135] Open Session 771471a4-ff5f-11e9-99a6-784f43775513 with <1> Job and <1> Queues
I1104 16:01:49.631678   66853 proportion.go:67] The total resource is <cpu 4000.00, memory 4959854592.00, hugepages-2Mi 0.00>
I1104 16:01:49.631692   66853 proportion.go:71] Considering Job <default/qj-1>.
I1104 16:01:49.631698   66853 proportion.go:85] Added Queue <default> attributes.
I1104 16:01:49.631706   66853 proportion.go:127] Considering Queue <default>: weight <1>, total weight <1>.
I1104 16:01:49.631714   66853 proportion.go:144] The attributes of queue <default> in proportion: deserved <cpu 4000.00, memory 4959854592.00, hugepages-2Mi 0.00>, allocate <cpu 0.00, memory 0.00>, request <cpu 0.00, memory 0.00>, share <0.00>
I1104 16:01:49.631728   66853 proportion.go:154] Exiting when remaining is empty:  <cpu 0.00, memory 0.00, hugepages-2Mi 0.00>
I1104 16:01:49.631750   66853 enqueue.go:43] Enter Enqueue ...
I1104 16:01:49.631755   66853 enqueue.go:58] Added Queue <default> for Job <default/qj-1>
I1104 16:01:49.631761   66853 enqueue.go:75] Try to enqueue PodGroup to 0 Queues
I1104 16:01:49.631768   66853 enqueue.go:122] Leaving Enqueue ...
I1104 16:01:49.631775   66853 allocate.go:43] Enter Allocate ...
I1104 16:01:49.631781   66853 allocate.go:90] Added Job <default/qj-1> into Queue <default>
I1104 16:01:49.631787   66853 allocate.go:94] Try to allocate resource to 1 Namespaces
I1104 16:01:49.631795   66853 allocate.go:153] Try to allocate resource to Jobs in Namespace <default> Queue <default>
I1104 16:01:49.631803   66853 allocate.go:178] Try to allocate resource to 0 tasks of Job <default/qj-1>
I1104 16:01:49.631808   66853 statement.go:326] Committing operations ...
I1104 16:01:49.631814   66853 allocate.go:153] Try to allocate resource to Jobs in Namespace <default> Queue <default>
I1104 16:01:49.631819   66853 allocate.go:157] Can not find jobs for queue default.
I1104 16:01:49.631830   66853 allocate.go:253] Leaving Allocate ...
I1104 16:01:49.631834   66853 backfill.go:42] Enter Backfill ...
I1104 16:01:49.631839   66853 backfill.go:91] Leaving Backfill ...
I1104 16:01:49.636125   66853 session.go:154] Close Session 771471a4-ff5f-11e9-99a6-784f43775513
I1104 16:01:49.636136   66853 scheduler.go:87] End scheduling ...
I1104 16:01:54.636664   66853 scheduler.go:72] Start scheduling ...
I1104 16:01:54.651390   66853 cache.go:732] The priority of job <default/qj-1> is </0>
I1104 16:01:54.651412   66853 cache.go:771] There are <1> Jobs, <1> Queues and <1> Nodes in total for scheduling.
I1104 16:01:54.651418   66853 session.go:135] Open Session 7a126762-ff5f-11e9-99a6-784f43775513 with <1> Job and <1> Queues
I1104 16:01:54.651457   66853 proportion.go:67] The total resource is <cpu 4000.00, memory 4959854592.00, hugepages-2Mi 0.00>
I1104 16:01:54.651472   66853 proportion.go:71] Considering Job <default/qj-1>.
I1104 16:01:54.651478   66853 proportion.go:85] Added Queue <default> attributes.
I1104 16:01:54.651486   66853 proportion.go:127] Considering Queue <default>: weight <1>, total weight <1>.
I1104 16:01:54.651494   66853 proportion.go:144] The attributes of queue <default> in proportion: deserved <cpu 4000.00, memory 4959854592.00, hugepages-2Mi 0.00>, allocate <cpu 0.00, memory 0.00>, request <cpu 0.00, memory 0.00>, share <0.00>
I1104 16:01:54.651509   66853 proportion.go:154] Exiting when remaining is empty:  <cpu 0.00, memory 0.00, hugepages-2Mi 0.00>
I1104 16:01:54.651532   66853 enqueue.go:43] Enter Enqueue ...
I1104 16:01:54.651536   66853 enqueue.go:58] Added Queue <default> for Job <default/qj-1>
I1104 16:01:54.651542   66853 enqueue.go:75] Try to enqueue PodGroup to 0 Queues
I1104 16:01:54.651549   66853 enqueue.go:122] Leaving Enqueue ...
I1104 16:01:54.651555   66853 allocate.go:43] Enter Allocate ...
I1104 16:01:54.651560   66853 allocate.go:90] Added Job <default/qj-1> into Queue <default>
I1104 16:01:54.651567   66853 allocate.go:94] Try to allocate resource to 1 Namespaces
I1104 16:01:54.651574   66853 allocate.go:153] Try to allocate resource to Jobs in Namespace <default> Queue <default>
I1104 16:01:54.651582   66853 allocate.go:178] Try to allocate resource to 0 tasks of Job <default/qj-1>
I1104 16:01:54.651587   66853 statement.go:326] Committing operations ...
I1104 16:01:54.651593   66853 allocate.go:153] Try to allocate resource to Jobs in Namespace <default> Queue <default>
I1104 16:01:54.651598   66853 allocate.go:157] Can not find jobs for queue default.
I1104 16:01:54.651609   66853 allocate.go:253] Leaving Allocate ...
I1104 16:01:54.651613   66853 backfill.go:42] Enter Backfill ...
I1104 16:01:54.651618   66853 backfill.go:91] Leaving Backfill ...
I1104 16:01:54.656165   66853 session.go:154] Close Session 7a126762-ff5f-11e9-99a6-784f43775513
I1104 16:01:54.656177   66853 scheduler.go:87] End scheduling ...
I1104 16:01:59.657217   66853 scheduler.go:72] Start scheduling ...
I1104 16:01:59.669651   66853 cache.go:732] The priority of job <default/qj-1> is </0>
I1104 16:01:59.669668   66853 cache.go:771] There are <1> Jobs, <1> Queues and <1> Nodes in total for scheduling.
I1104 16:01:59.669672   66853 session.go:135] Open Session 7d1021c0-ff5f-11e9-99a6-784f43775513 with <1> Job and <1> Queues
I1104 16:01:59.669706   66853 proportion.go:67] The total resource is <cpu 4000.00, memory 4959854592.00, hugepages-2Mi 0.00>
I1104 16:01:59.669716   66853 proportion.go:71] Considering Job <default/qj-1>.
I1104 16:01:59.669721   66853 proportion.go:85] Added Queue <default> attributes.
I1104 16:01:59.669727   66853 proportion.go:127] Considering Queue <default>: weight <1>, total weight <1>.
I1104 16:01:59.669733   66853 proportion.go:144] The attributes of queue <default> in proportion: deserved <cpu 4000.00, memory 4959854592.00, hugepages-2Mi 0.00>, allocate <cpu 0.00, memory 0.00>, request <cpu 0.00, memory 0.00>, share <0.00>
I1104 16:01:59.669743   66853 proportion.go:154] Exiting when remaining is empty:  <cpu 0.00, memory 0.00, hugepages-2Mi 0.00>
I1104 16:01:59.669761   66853 enqueue.go:43] Enter Enqueue ...
I1104 16:01:59.669765   66853 enqueue.go:58] Added Queue <default> for Job <default/qj-1>
I1104 16:01:59.669769   66853 enqueue.go:75] Try to enqueue PodGroup to 0 Queues
I1104 16:01:59.669775   66853 enqueue.go:122] Leaving Enqueue ...
I1104 16:01:59.669780   66853 allocate.go:43] Enter Allocate ...
I1104 16:01:59.669798   66853 allocate.go:90] Added Job <default/qj-1> into Queue <default>
I1104 16:01:59.669803   66853 allocate.go:94] Try to allocate resource to 1 Namespaces
I1104 16:01:59.669809   66853 allocate.go:153] Try to allocate resource to Jobs in Namespace <default> Queue <default>
I1104 16:01:59.669816   66853 allocate.go:178] Try to allocate resource to 0 tasks of Job <default/qj-1>
I1104 16:01:59.669820   66853 statement.go:326] Committing operations ...
I1104 16:01:59.669825   66853 allocate.go:153] Try to allocate resource to Jobs in Namespace <default> Queue <default>
I1104 16:01:59.669828   66853 allocate.go:157] Can not find jobs for queue default.
I1104 16:01:59.669837   66853 allocate.go:253] Leaving Allocate ...
I1104 16:01:59.669840   66853 backfill.go:42] Enter Backfill ...
I1104 16:01:59.669844   66853 backfill.go:91] Leaving Backfill ...
I1104 16:01:59.676057   66853 session.go:154] Close Session 7d1021c0-ff5f-11e9-99a6-784f43775513
I1104 16:01:59.676070   66853 scheduler.go:87] End scheduling ...
I1104 16:02:04.681290   66853 scheduler.go:72] Start scheduling ...
I1104 16:02:04.688117   66853 cache.go:732] The priority of job <default/qj-1> is </0>
I1104 16:02:04.688143   66853 cache.go:771] There are <1> Jobs, <1> Queues and <1> Nodes in total for scheduling.
I1104 16:02:04.688149   66853 session.go:135] Open Session 800de2b8-ff5f-11e9-99a6-784f43775513 with <1> Job and <1> Queues
I1104 16:02:04.688218   66853 proportion.go:67] The total resource is <cpu 4000.00, memory 4959854592.00, hugepages-2Mi 0.00>
I1104 16:02:04.688234   66853 proportion.go:71] Considering Job <default/qj-1>.
I1104 16:02:04.688240   66853 proportion.go:85] Added Queue <default> attributes.
I1104 16:02:04.688250   66853 proportion.go:127] Considering Queue <default>: weight <1>, total weight <1>.
I1104 16:02:04.688259   66853 proportion.go:144] The attributes of queue <default> in proportion: deserved <cpu 4000.00, memory 4959854592.00, hugepages-2Mi 0.00>, allocate <cpu 0.00, memory 0.00>, request <cpu 0.00, memory 0.00>, share <0.00>
I1104 16:02:04.688277   66853 proportion.go:154] Exiting when remaining is empty:  <cpu 0.00, memory 0.00, hugepages-2Mi 0.00>
I1104 16:02:04.688287   66853 enqueue.go:43] Enter Enqueue ...
I1104 16:02:04.688293   66853 enqueue.go:58] Added Queue <default> for Job <default/qj-1>
I1104 16:02:04.688300   66853 enqueue.go:75] Try to enqueue PodGroup to 0 Queues
I1104 16:02:04.688310   66853 enqueue.go:122] Leaving Enqueue ...
I1104 16:02:04.688317   66853 allocate.go:43] Enter Allocate ...
I1104 16:02:04.688324   66853 allocate.go:90] Added Job <default/qj-1> into Queue <default>
I1104 16:02:04.688332   66853 allocate.go:94] Try to allocate resource to 1 Namespaces
I1104 16:02:04.688342   66853 allocate.go:153] Try to allocate resource to Jobs in Namespace <default> Queue <default>
I1104 16:02:04.688352   66853 allocate.go:178] Try to allocate resource to 0 tasks of Job <default/qj-1>
I1104 16:02:04.688357   66853 statement.go:326] Committing operations ...
I1104 16:02:04.688365   66853 allocate.go:153] Try to allocate resource to Jobs in Namespace <default> Queue <default>
I1104 16:02:04.688371   66853 allocate.go:157] Can not find jobs for queue default.
I1104 16:02:04.688385   66853 allocate.go:253] Leaving Allocate ...
I1104 16:02:04.688390   66853 backfill.go:42] Enter Backfill ...
I1104 16:02:04.688397   66853 backfill.go:91] Leaving Backfill ...
I1104 16:02:04.692025   66853 session.go:154] Close Session 800de2b8-ff5f-11e9-99a6-784f43775513
I1104 16:02:04.692035   66853 scheduler.go:87] End scheduling ...
I1104 16:02:09.695517   66853 scheduler.go:72] Start scheduling ...
I1104 16:02:09.721098   66853 cache.go:732] The priority of job <default/qj-1> is </0>
I1104 16:02:09.721121   66853 cache.go:771] There are <1> Jobs, <1> Queues and <1> Nodes in total for scheduling.
I1104 16:02:09.721127   66853 session.go:135] Open Session 830ddbee-ff5f-11e9-99a6-784f43775513 with <1> Job and <1> Queues
I1104 16:02:09.721167   66853 proportion.go:67] The total resource is <cpu 4000.00, memory 4959854592.00, hugepages-2Mi 0.00>
I1104 16:02:09.721179   66853 proportion.go:71] Considering Job <default/qj-1>.
I1104 16:02:09.721184   66853 proportion.go:85] Added Queue <default> attributes.
I1104 16:02:09.721191   66853 proportion.go:127] Considering Queue <default>: weight <1>, total weight <1>.
I1104 16:02:09.721198   66853 proportion.go:144] The attributes of queue <default> in proportion: deserved <cpu 4000.00, memory 4959854592.00, hugepages-2Mi 0.00>, allocate <cpu 0.00, memory 0.00>, request <cpu 0.00, memory 0.00>, share <0.00>
I1104 16:02:09.721212   66853 proportion.go:154] Exiting when remaining is empty:  <cpu 0.00, memory 0.00, hugepages-2Mi 0.00>
I1104 16:02:09.721236   66853 enqueue.go:43] Enter Enqueue ...
I1104 16:02:09.721240   66853 enqueue.go:58] Added Queue <default> for Job <default/qj-1>
I1104 16:02:09.721246   66853 enqueue.go:75] Try to enqueue PodGroup to 0 Queues
I1104 16:02:09.721253   66853 enqueue.go:122] Leaving Enqueue ...
I1104 16:02:09.721259   66853 allocate.go:43] Enter Allocate ...
I1104 16:02:09.721264   66853 allocate.go:90] Added Job <default/qj-1> into Queue <default>
I1104 16:02:09.721271   66853 allocate.go:94] Try to allocate resource to 1 Namespaces
I1104 16:02:09.721278   66853 allocate.go:153] Try to allocate resource to Jobs in Namespace <default> Queue <default>
I1104 16:02:09.721286   66853 allocate.go:178] Try to allocate resource to 0 tasks of Job <default/qj-1>
I1104 16:02:09.721291   66853 statement.go:326] Committing operations ...
I1104 16:02:09.721297   66853 allocate.go:153] Try to allocate resource to Jobs in Namespace <default> Queue <default>
I1104 16:02:09.721301   66853 allocate.go:157] Can not find jobs for queue default.
I1104 16:02:09.721312   66853 allocate.go:253] Leaving Allocate ...
I1104 16:02:09.721316   66853 backfill.go:42] Enter Backfill ...
I1104 16:02:09.721321   66853 backfill.go:91] Leaving Backfill ...
I1104 16:02:09.725491   66853 session.go:154] Close Session 830ddbee-ff5f-11e9-99a6-784f43775513
I1104 16:02:09.725503   66853 scheduler.go:87] End scheduling ...
I1104 16:02:14.726342   66853 scheduler.go:72] Start scheduling ...
I1104 16:02:14.739540   66853 cache.go:732] The priority of job <default/qj-1> is </0>
I1104 16:02:14.739564   66853 cache.go:771] There are <1> Jobs, <1> Queues and <1> Nodes in total for scheduling.
I1104 16:02:14.739571   66853 session.go:135] Open Session 860b9cd2-ff5f-11e9-99a6-784f43775513 with <1> Job and <1> Queues
I1104 16:02:14.739615   66853 proportion.go:67] The total resource is <cpu 4000.00, memory 4959854592.00, hugepages-2Mi 0.00>
I1104 16:02:14.739635   66853 proportion.go:71] Considering Job <default/qj-1>.
I1104 16:02:14.739641   66853 proportion.go:85] Added Queue <default> attributes.
I1104 16:02:14.739649   66853 proportion.go:127] Considering Queue <default>: weight <1>, total weight <1>.
I1104 16:02:14.739656   66853 proportion.go:144] The attributes of queue <default> in proportion: deserved <cpu 4000.00, memory 4959854592.00, hugepages-2Mi 0.00>, allocate <cpu 0.00, memory 0.00>, request <cpu 0.00, memory 0.00>, share <0.00>
I1104 16:02:14.739671   66853 proportion.go:154] Exiting when remaining is empty:  <cpu 0.00, memory 0.00, hugepages-2Mi 0.00>
I1104 16:02:14.739694   66853 enqueue.go:43] Enter Enqueue ...
I1104 16:02:14.739698   66853 enqueue.go:58] Added Queue <default> for Job <default/qj-1>
I1104 16:02:14.739703   66853 enqueue.go:75] Try to enqueue PodGroup to 0 Queues
I1104 16:02:14.739711   66853 enqueue.go:122] Leaving Enqueue ...
I1104 16:02:14.739717   66853 allocate.go:43] Enter Allocate ...
I1104 16:02:14.739722   66853 allocate.go:90] Added Job <default/qj-1> into Queue <default>
I1104 16:02:14.739727   66853 allocate.go:94] Try to allocate resource to 1 Namespaces
I1104 16:02:14.739734   66853 allocate.go:153] Try to allocate resource to Jobs in Namespace <default> Queue <default>
I1104 16:02:14.739741   66853 allocate.go:178] Try to allocate resource to 0 tasks of Job <default/qj-1>
I1104 16:02:14.739745   66853 statement.go:326] Committing operations ...
I1104 16:02:14.739750   66853 allocate.go:153] Try to allocate resource to Jobs in Namespace <default> Queue <default>
I1104 16:02:14.739754   66853 allocate.go:157] Can not find jobs for queue default.
I1104 16:02:14.739764   66853 allocate.go:253] Leaving Allocate ...
I1104 16:02:14.739768   66853 backfill.go:42] Enter Backfill ...
I1104 16:02:14.739772   66853 backfill.go:91] Leaving Backfill ...
I1104 16:02:14.743488   66853 session.go:154] Close Session 860b9cd2-ff5f-11e9-99a6-784f43775513
I1104 16:02:14.743506   66853 scheduler.go:87] End scheduling ...
I1104 16:02:19.744864   66853 scheduler.go:72] Start scheduling ...
I1104 16:02:19.753128   66853 cache.go:732] The priority of job <default/qj-1> is </0>
I1104 16:02:19.753154   66853 cache.go:771] There are <1> Jobs, <1> Queues and <1> Nodes in total for scheduling.
I1104 16:02:19.753161   66853 session.go:135] Open Session 89089ff2-ff5f-11e9-99a6-784f43775513 with <1> Job and <1> Queues
I1104 16:02:19.753206   66853 proportion.go:67] The total resource is <cpu 4000.00, memory 4959854592.00, hugepages-2Mi 0.00>
I1104 16:02:19.753221   66853 proportion.go:71] Considering Job <default/qj-1>.
I1104 16:02:19.753226   66853 proportion.go:85] Added Queue <default> attributes.
I1104 16:02:19.753234   66853 proportion.go:127] Considering Queue <default>: weight <1>, total weight <1>.
I1104 16:02:19.753242   66853 proportion.go:144] The attributes of queue <default> in proportion: deserved <cpu 4000.00, memory 4959854592.00, hugepages-2Mi 0.00>, allocate <cpu 0.00, memory 0.00>, request <cpu 0.00, memory 0.00>, share <0.00>
I1104 16:02:19.753265   66853 proportion.go:154] Exiting when remaining is empty:  <cpu 0.00, memory 0.00, hugepages-2Mi 0.00>
I1104 16:02:19.753331   66853 enqueue.go:43] Enter Enqueue ...
I1104 16:02:19.753338   66853 enqueue.go:58] Added Queue <default> for Job <default/qj-1>
I1104 16:02:19.753345   66853 enqueue.go:75] Try to enqueue PodGroup to 0 Queues
I1104 16:02:19.753353   66853 enqueue.go:122] Leaving Enqueue ...
I1104 16:02:19.753360   66853 allocate.go:43] Enter Allocate ...
I1104 16:02:19.753365   66853 allocate.go:90] Added Job <default/qj-1> into Queue <default>
I1104 16:02:19.753372   66853 allocate.go:94] Try to allocate resource to 1 Namespaces
I1104 16:02:19.753380   66853 allocate.go:153] Try to allocate resource to Jobs in Namespace <default> Queue <default>
I1104 16:02:19.753388   66853 allocate.go:178] Try to allocate resource to 0 tasks of Job <default/qj-1>
I1104 16:02:19.753393   66853 statement.go:326] Committing operations ...
I1104 16:02:19.753399   66853 allocate.go:153] Try to allocate resource to Jobs in Namespace <default> Queue <default>
I1104 16:02:19.753404   66853 allocate.go:157] Can not find jobs for queue default.
I1104 16:02:19.753418   66853 allocate.go:253] Leaving Allocate ...
I1104 16:02:19.753423   66853 backfill.go:42] Enter Backfill ...
I1104 16:02:19.753428   66853 backfill.go:91] Leaving Backfill ...
I1104 16:02:19.757043   66853 session.go:154] Close Session 89089ff2-ff5f-11e9-99a6-784f43775513
I1104 16:02:19.757053   66853 scheduler.go:87] End scheduling ...
I1104 16:02:24.757212   66853 scheduler.go:72] Start scheduling ...
I1104 16:02:24.769758   66853 cache.go:732] The priority of job <default/qj-1> is </0>
I1104 16:02:24.769778   66853 cache.go:771] There are <1> Jobs, <1> Queues and <1> Nodes in total for scheduling.
I1104 16:02:24.769783   66853 session.go:135] Open Session 8c061a9a-ff5f-11e9-99a6-784f43775513 with <1> Job and <1> Queues
I1104 16:02:24.769823   66853 proportion.go:67] The total resource is <cpu 4000.00, memory 4959854592.00, hugepages-2Mi 0.00>
I1104 16:02:24.769834   66853 proportion.go:71] Considering Job <default/qj-1>.
I1104 16:02:24.769838   66853 proportion.go:85] Added Queue <default> attributes.
I1104 16:02:24.769845   66853 proportion.go:127] Considering Queue <default>: weight <1>, total weight <1>.
I1104 16:02:24.769851   66853 proportion.go:144] The attributes of queue <default> in proportion: deserved <cpu 4000.00, memory 4959854592.00, hugepages-2Mi 0.00>, allocate <cpu 0.00, memory 0.00>, request <cpu 0.00, memory 0.00>, share <0.00>
I1104 16:02:24.769862   66853 proportion.go:154] Exiting when remaining is empty:  <cpu 0.00, memory 0.00, hugepages-2Mi 0.00>
I1104 16:02:24.769879   66853 enqueue.go:43] Enter Enqueue ...
I1104 16:02:24.769883   66853 enqueue.go:58] Added Queue <default> for Job <default/qj-1>
I1104 16:02:24.769887   66853 enqueue.go:75] Try to enqueue PodGroup to 0 Queues
I1104 16:02:24.769894   66853 enqueue.go:122] Leaving Enqueue ...
I1104 16:02:24.769900   66853 allocate.go:43] Enter Allocate ...
I1104 16:02:24.769904   66853 allocate.go:90] Added Job <default/qj-1> into Queue <default>
I1104 16:02:24.769909   66853 allocate.go:94] Try to allocate resource to 1 Namespaces
I1104 16:02:24.769916   66853 allocate.go:153] Try to allocate resource to Jobs in Namespace <default> Queue <default>
I1104 16:02:24.769925   66853 allocate.go:178] Try to allocate resource to 0 tasks of Job <default/qj-1>
I1104 16:02:24.769929   66853 statement.go:326] Committing operations ...
I1104 16:02:24.769934   66853 allocate.go:153] Try to allocate resource to Jobs in Namespace <default> Queue <default>
I1104 16:02:24.769938   66853 allocate.go:157] Can not find jobs for queue default.
I1104 16:02:24.769948   66853 allocate.go:253] Leaving Allocate ...
I1104 16:02:24.769952   66853 backfill.go:42] Enter Backfill ...
I1104 16:02:24.769956   66853 backfill.go:91] Leaving Backfill ...
I1104 16:02:24.773974   66853 session.go:154] Close Session 8c061a9a-ff5f-11e9-99a6-784f43775513
I1104 16:02:24.773984   66853 scheduler.go:87] End scheduling ...
I1104 16:02:29.774926   66853 scheduler.go:72] Start scheduling ...
I1104 16:02:29.787287   66853 cache.go:732] The priority of job <default/qj-1> is </0>
I1104 16:02:29.787309   66853 cache.go:771] There are <1> Jobs, <1> Queues and <1> Nodes in total for scheduling.
I1104 16:02:29.787314   66853 session.go:135] Open Session 8f03b7d4-ff5f-11e9-99a6-784f43775513 with <1> Job and <1> Queues
I1104 16:02:29.787325   66853 proportion.go:67] The total resource is <cpu 4000.00, memory 4959854592.00, hugepages-2Mi 0.00>
I1104 16:02:29.787337   66853 proportion.go:71] Considering Job <default/qj-1>.
I1104 16:02:29.787342   66853 proportion.go:85] Added Queue <default> attributes.
I1104 16:02:29.787348   66853 proportion.go:127] Considering Queue <default>: weight <1>, total weight <1>.
I1104 16:02:29.787355   66853 proportion.go:144] The attributes of queue <default> in proportion: deserved <cpu 4000.00, memory 4959854592.00, hugepages-2Mi 0.00>, allocate <cpu 0.00, memory 0.00>, request <cpu 0.00, memory 0.00>, share <0.00>
I1104 16:02:29.787366   66853 proportion.go:154] Exiting when remaining is empty:  <cpu 0.00, memory 0.00, hugepages-2Mi 0.00>
I1104 16:02:29.787415   66853 enqueue.go:43] Enter Enqueue ...
I1104 16:02:29.787419   66853 enqueue.go:58] Added Queue <default> for Job <default/qj-1>
I1104 16:02:29.787424   66853 enqueue.go:75] Try to enqueue PodGroup to 0 Queues
I1104 16:02:29.787430   66853 enqueue.go:122] Leaving Enqueue ...
I1104 16:02:29.787436   66853 allocate.go:43] Enter Allocate ...
I1104 16:02:29.787440   66853 allocate.go:90] Added Job <default/qj-1> into Queue <default>
I1104 16:02:29.787446   66853 allocate.go:94] Try to allocate resource to 1 Namespaces
I1104 16:02:29.787452   66853 allocate.go:153] Try to allocate resource to Jobs in Namespace <default> Queue <default>
I1104 16:02:29.787459   66853 allocate.go:178] Try to allocate resource to 0 tasks of Job <default/qj-1>
I1104 16:02:29.787463   66853 statement.go:326] Committing operations ...
I1104 16:02:29.787468   66853 allocate.go:153] Try to allocate resource to Jobs in Namespace <default> Queue <default>
I1104 16:02:29.787473   66853 allocate.go:157] Can not find jobs for queue default.
I1104 16:02:29.787482   66853 allocate.go:253] Leaving Allocate ...
I1104 16:02:29.787485   66853 backfill.go:42] Enter Backfill ...
I1104 16:02:29.787489   66853 backfill.go:91] Leaving Backfill ...
I1104 16:02:29.791572   66853 session.go:154] Close Session 8f03b7d4-ff5f-11e9-99a6-784f43775513
I1104 16:02:29.791584   66853 scheduler.go:87] End scheduling ...
I1104 16:02:34.796539   66853 scheduler.go:72] Start scheduling ...
I1104 16:02:34.803853   66853 cache.go:732] The priority of job <default/qj-1> is </0>
I1104 16:02:34.803882   66853 cache.go:771] There are <1> Jobs, <1> Queues and <1> Nodes in total for scheduling.
I1104 16:02:34.803893   66853 session.go:135] Open Session 92012e76-ff5f-11e9-99a6-784f43775513 with <1> Job and <1> Queues
I1104 16:02:34.803956   66853 proportion.go:67] The total resource is <cpu 4000.00, memory 4959854592.00, hugepages-2Mi 0.00>
I1104 16:02:34.803972   66853 proportion.go:71] Considering Job <default/qj-1>.
I1104 16:02:34.803978   66853 proportion.go:85] Added Queue <default> attributes.
I1104 16:02:34.803988   66853 proportion.go:127] Considering Queue <default>: weight <1>, total weight <1>.
I1104 16:02:34.803999   66853 proportion.go:144] The attributes of queue <default> in proportion: deserved <cpu 4000.00, memory 4959854592.00, hugepages-2Mi 0.00>, allocate <cpu 0.00, memory 0.00>, request <cpu 0.00, memory 0.00>, share <0.00>
I1104 16:02:34.804019   66853 proportion.go:154] Exiting when remaining is empty:  <cpu 0.00, memory 0.00, hugepages-2Mi 0.00>
I1104 16:02:34.804052   66853 enqueue.go:43] Enter Enqueue ...
I1104 16:02:34.804059   66853 enqueue.go:58] Added Queue <default> for Job <default/qj-1>
I1104 16:02:34.804068   66853 enqueue.go:75] Try to enqueue PodGroup to 0 Queues
I1104 16:02:34.804079   66853 enqueue.go:122] Leaving Enqueue ...
I1104 16:02:34.804088   66853 allocate.go:43] Enter Allocate ...
I1104 16:02:34.804100   66853 allocate.go:90] Added Job <default/qj-1> into Queue <default>
I1104 16:02:34.804109   66853 allocate.go:94] Try to allocate resource to 1 Namespaces
I1104 16:02:34.804121   66853 allocate.go:153] Try to allocate resource to Jobs in Namespace <default> Queue <default>
I1104 16:02:34.804133   66853 allocate.go:178] Try to allocate resource to 0 tasks of Job <default/qj-1>
I1104 16:02:34.804140   66853 statement.go:326] Committing operations ...
I1104 16:02:34.804149   66853 allocate.go:153] Try to allocate resource to Jobs in Namespace <default> Queue <default>
I1104 16:02:34.804156   66853 allocate.go:157] Can not find jobs for queue default.
I1104 16:02:34.804172   66853 allocate.go:253] Leaving Allocate ...
I1104 16:02:34.804178   66853 backfill.go:42] Enter Backfill ...
I1104 16:02:34.804185   66853 backfill.go:91] Leaving Backfill ...
I1104 16:02:34.808391   66853 session.go:154] Close Session 92012e76-ff5f-11e9-99a6-784f43775513
I1104 16:02:34.808402   66853 scheduler.go:87] End scheduling ...
I1104 16:02:39.809070   66853 scheduler.go:72] Start scheduling ...
I1104 16:02:39.817953   66853 cache.go:732] The priority of job <default/qj-1> is </0>
I1104 16:02:39.817972   66853 cache.go:771] There are <1> Jobs, <1> Queues and <1> Nodes in total for scheduling.
I1104 16:02:39.817978   66853 session.go:135] Open Session 94fe4690-ff5f-11e9-99a6-784f43775513 with <1> Job and <1> Queues
I1104 16:02:39.818019   66853 proportion.go:67] The total resource is <cpu 4000.00, memory 4959854592.00, hugepages-2Mi 0.00>
I1104 16:02:39.818030   66853 proportion.go:71] Considering Job <default/qj-1>.
I1104 16:02:39.818035   66853 proportion.go:85] Added Queue <default> attributes.
I1104 16:02:39.818042   66853 proportion.go:127] Considering Queue <default>: weight <1>, total weight <1>.
I1104 16:02:39.818048   66853 proportion.go:144] The attributes of queue <default> in proportion: deserved <cpu 4000.00, memory 4959854592.00, hugepages-2Mi 0.00>, allocate <cpu 0.00, memory 0.00>, request <cpu 0.00, memory 0.00>, share <0.00>
I1104 16:02:39.818060   66853 proportion.go:154] Exiting when remaining is empty:  <cpu 0.00, memory 0.00, hugepages-2Mi 0.00>
I1104 16:02:39.818078   66853 enqueue.go:43] Enter Enqueue ...
I1104 16:02:39.818082   66853 enqueue.go:58] Added Queue <default> for Job <default/qj-1>
I1104 16:02:39.818087   66853 enqueue.go:75] Try to enqueue PodGroup to 0 Queues
I1104 16:02:39.818094   66853 enqueue.go:122] Leaving Enqueue ...
I1104 16:02:39.818099   66853 allocate.go:43] Enter Allocate ...
I1104 16:02:39.818104   66853 allocate.go:90] Added Job <default/qj-1> into Queue <default>
I1104 16:02:39.818110   66853 allocate.go:94] Try to allocate resource to 1 Namespaces
I1104 16:02:39.818118   66853 allocate.go:153] Try to allocate resource to Jobs in Namespace <default> Queue <default>
I1104 16:02:39.818126   66853 allocate.go:178] Try to allocate resource to 0 tasks of Job <default/qj-1>
I1104 16:02:39.818130   66853 statement.go:326] Committing operations ...
I1104 16:02:39.818135   66853 allocate.go:153] Try to allocate resource to Jobs in Namespace <default> Queue <default>
I1104 16:02:39.818140   66853 allocate.go:157] Can not find jobs for queue default.
I1104 16:02:39.818150   66853 allocate.go:253] Leaving Allocate ...
I1104 16:02:39.818153   66853 backfill.go:42] Enter Backfill ...
I1104 16:02:39.818157   66853 backfill.go:91] Leaving Backfill ...
I1104 16:02:39.822545   66853 session.go:154] Close Session 94fe4690-ff5f-11e9-99a6-784f43775513
I1104 16:02:39.822555   66853 scheduler.go:87] End scheduling ...
I1104 16:02:44.825440   66853 scheduler.go:72] Start scheduling ...
I1104 16:02:44.840321   66853 cache.go:732] The priority of job <default/qj-1> is </0>
I1104 16:02:44.840354   66853 cache.go:771] There are <1> Jobs, <1> Queues and <1> Nodes in total for scheduling.
I1104 16:02:44.840361   66853 session.go:135] Open Session 97fc9f7c-ff5f-11e9-99a6-784f43775513 with <1> Job and <1> Queues
I1104 16:02:44.840435   66853 proportion.go:67] The total resource is <cpu 4000.00, memory 4959854592.00, hugepages-2Mi 0.00>
I1104 16:02:44.840451   66853 proportion.go:71] Considering Job <default/qj-1>.
I1104 16:02:44.840458   66853 proportion.go:85] Added Queue <default> attributes.
I1104 16:02:44.840467   66853 proportion.go:127] Considering Queue <default>: weight <1>, total weight <1>.
I1104 16:02:44.840477   66853 proportion.go:144] The attributes of queue <default> in proportion: deserved <cpu 4000.00, memory 4959854592.00, hugepages-2Mi 0.00>, allocate <cpu 0.00, memory 0.00>, request <cpu 0.00, memory 0.00>, share <0.00>
I1104 16:02:44.840495   66853 proportion.go:154] Exiting when remaining is empty:  <cpu 0.00, memory 0.00, hugepages-2Mi 0.00>
I1104 16:02:44.840506   66853 enqueue.go:43] Enter Enqueue ...
I1104 16:02:44.840511   66853 enqueue.go:58] Added Queue <default> for Job <default/qj-1>
I1104 16:02:44.840520   66853 enqueue.go:75] Try to enqueue PodGroup to 0 Queues
I1104 16:02:44.840531   66853 enqueue.go:122] Leaving Enqueue ...
I1104 16:02:44.840539   66853 allocate.go:43] Enter Allocate ...
I1104 16:02:44.840546   66853 allocate.go:90] Added Job <default/qj-1> into Queue <default>
I1104 16:02:44.840556   66853 allocate.go:94] Try to allocate resource to 1 Namespaces
I1104 16:02:44.840566   66853 allocate.go:153] Try to allocate resource to Jobs in Namespace <default> Queue <default>
I1104 16:02:44.840577   66853 allocate.go:178] Try to allocate resource to 0 tasks of Job <default/qj-1>
I1104 16:02:44.840585   66853 statement.go:326] Committing operations ...
I1104 16:02:44.840594   66853 allocate.go:153] Try to allocate resource to Jobs in Namespace <default> Queue <default>
I1104 16:02:44.840600   66853 allocate.go:157] Can not find jobs for queue default.
I1104 16:02:44.840616   66853 allocate.go:253] Leaving Allocate ...
I1104 16:02:44.840622   66853 backfill.go:42] Enter Backfill ...
I1104 16:02:44.840628   66853 backfill.go:91] Leaving Backfill ...
I1104 16:02:44.845784   66853 session.go:154] Close Session 97fc9f7c-ff5f-11e9-99a6-784f43775513
I1104 16:02:44.845795   66853 scheduler.go:87] End scheduling ...
I1104 16:02:49.846335   66853 scheduler.go:72] Start scheduling ...
I1104 16:02:49.850264   66853 cache.go:732] The priority of job <default/qj-1> is </0>
I1104 16:02:49.850283   66853 cache.go:771] There are <1> Jobs, <1> Queues and <1> Nodes in total for scheduling.
I1104 16:02:49.850288   66853 session.go:135] Open Session 9af915d4-ff5f-11e9-99a6-784f43775513 with <1> Job and <1> Queues
I1104 16:02:49.850340   66853 proportion.go:67] The total resource is <cpu 4000.00, memory 4959854592.00, hugepages-2Mi 0.00>
I1104 16:02:49.850352   66853 proportion.go:71] Considering Job <default/qj-1>.
I1104 16:02:49.850356   66853 proportion.go:85] Added Queue <default> attributes.
I1104 16:02:49.850366   66853 proportion.go:127] Considering Queue <default>: weight <1>, total weight <1>.
I1104 16:02:49.850375   66853 proportion.go:144] The attributes of queue <default> in proportion: deserved <cpu 4000.00, memory 4959854592.00, hugepages-2Mi 0.00>, allocate <cpu 0.00, memory 0.00>, request <cpu 0.00, memory 0.00>, share <0.00>
I1104 16:02:49.850406   66853 proportion.go:154] Exiting when remaining is empty:  <cpu 0.00, memory 0.00, hugepages-2Mi 0.00>
I1104 16:02:49.850434   66853 enqueue.go:43] Enter Enqueue ...
I1104 16:02:49.850440   66853 enqueue.go:58] Added Queue <default> for Job <default/qj-1>
I1104 16:02:49.850448   66853 enqueue.go:75] Try to enqueue PodGroup to 0 Queues
I1104 16:02:49.850457   66853 enqueue.go:122] Leaving Enqueue ...
I1104 16:02:49.850465   66853 allocate.go:43] Enter Allocate ...
I1104 16:02:49.850472   66853 allocate.go:90] Added Job <default/qj-1> into Queue <default>
I1104 16:02:49.850480   66853 allocate.go:94] Try to allocate resource to 1 Namespaces
I1104 16:02:49.850490   66853 allocate.go:153] Try to allocate resource to Jobs in Namespace <default> Queue <default>
I1104 16:02:49.850500   66853 allocate.go:178] Try to allocate resource to 0 tasks of Job <default/qj-1>
I1104 16:02:49.850506   66853 statement.go:326] Committing operations ...
I1104 16:02:49.850514   66853 allocate.go:153] Try to allocate resource to Jobs in Namespace <default> Queue <default>
I1104 16:02:49.850520   66853 allocate.go:157] Can not find jobs for queue default.
I1104 16:02:49.850534   66853 allocate.go:253] Leaving Allocate ...
I1104 16:02:49.850542   66853 backfill.go:42] Enter Backfill ...
I1104 16:02:49.850549   66853 backfill.go:91] Leaving Backfill ...
I1104 16:02:49.855848   66853 session.go:154] Close Session 9af915d4-ff5f-11e9-99a6-784f43775513
I1104 16:02:49.855859   66853 scheduler.go:87] End scheduling ...
I1104 16:02:54.856125   66853 scheduler.go:72] Start scheduling ...
I1104 16:02:54.865169   66853 cache.go:732] The priority of job <default/qj-1> is </0>
I1104 16:02:54.865189   66853 cache.go:771] There are <1> Jobs, <1> Queues and <1> Nodes in total for scheduling.
I1104 16:02:54.865194   66853 session.go:135] Open Session 9df64ad6-ff5f-11e9-99a6-784f43775513 with <1> Job and <1> Queues
I1104 16:02:54.865242   66853 proportion.go:67] The total resource is <cpu 4000.00, memory 4959854592.00, hugepages-2Mi 0.00>
I1104 16:02:54.865254   66853 proportion.go:71] Considering Job <default/qj-1>.
I1104 16:02:54.865261   66853 proportion.go:85] Added Queue <default> attributes.
I1104 16:02:54.865268   66853 proportion.go:127] Considering Queue <default>: weight <1>, total weight <1>.
I1104 16:02:54.865275   66853 proportion.go:144] The attributes of queue <default> in proportion: deserved <cpu 4000.00, memory 4959854592.00, hugepages-2Mi 0.00>, allocate <cpu 0.00, memory 0.00>, request <cpu 0.00, memory 0.00>, share <0.00>
I1104 16:02:54.865287   66853 proportion.go:154] Exiting when remaining is empty:  <cpu 0.00, memory 0.00, hugepages-2Mi 0.00>
I1104 16:02:54.865295   66853 enqueue.go:43] Enter Enqueue ...
I1104 16:02:54.865299   66853 enqueue.go:58] Added Queue <default> for Job <default/qj-1>
I1104 16:02:54.865304   66853 enqueue.go:75] Try to enqueue PodGroup to 0 Queues
I1104 16:02:54.865311   66853 enqueue.go:122] Leaving Enqueue ...
I1104 16:02:54.865316   66853 allocate.go:43] Enter Allocate ...
I1104 16:02:54.865321   66853 allocate.go:90] Added Job <default/qj-1> into Queue <default>
I1104 16:02:54.865326   66853 allocate.go:94] Try to allocate resource to 1 Namespaces
I1104 16:02:54.865333   66853 allocate.go:153] Try to allocate resource to Jobs in Namespace <default> Queue <default>
I1104 16:02:54.865340   66853 allocate.go:178] Try to allocate resource to 0 tasks of Job <default/qj-1>
I1104 16:02:54.865344   66853 statement.go:326] Committing operations ...
I1104 16:02:54.865350   66853 allocate.go:153] Try to allocate resource to Jobs in Namespace <default> Queue <default>
I1104 16:02:54.865354   66853 allocate.go:157] Can not find jobs for queue default.
I1104 16:02:54.865363   66853 allocate.go:253] Leaving Allocate ...
I1104 16:02:54.865367   66853 backfill.go:42] Enter Backfill ...
I1104 16:02:54.865371   66853 backfill.go:91] Leaving Backfill ...
I1104 16:02:54.869414   66853 session.go:154] Close Session 9df64ad6-ff5f-11e9-99a6-784f43775513
I1104 16:02:54.869425   66853 scheduler.go:87] End scheduling ...
I1104 16:02:59.873888   66853 scheduler.go:72] Start scheduling ...
I1104 16:02:59.887433   66853 cache.go:732] The priority of job <default/qj-1> is </0>
I1104 16:02:59.887454   66853 cache.go:771] There are <1> Jobs, <1> Queues and <1> Nodes in total for scheduling.
I1104 16:02:59.887460   66853 session.go:135] Open Session a0f4a25a-ff5f-11e9-99a6-784f43775513 with <1> Job and <1> Queues
I1104 16:02:59.887504   66853 proportion.go:67] The total resource is <cpu 4000.00, memory 4959854592.00, hugepages-2Mi 0.00>
I1104 16:02:59.887517   66853 proportion.go:71] Considering Job <default/qj-1>.
I1104 16:02:59.887521   66853 proportion.go:85] Added Queue <default> attributes.
I1104 16:02:59.887528   66853 proportion.go:127] Considering Queue <default>: weight <1>, total weight <1>.
I1104 16:02:59.887534   66853 proportion.go:144] The attributes of queue <default> in proportion: deserved <cpu 4000.00, memory 4959854592.00, hugepages-2Mi 0.00>, allocate <cpu 0.00, memory 0.00>, request <cpu 0.00, memory 0.00>, share <0.00>
I1104 16:02:59.887546   66853 proportion.go:154] Exiting when remaining is empty:  <cpu 0.00, memory 0.00, hugepages-2Mi 0.00>
I1104 16:02:59.887564   66853 enqueue.go:43] Enter Enqueue ...
I1104 16:02:59.887568   66853 enqueue.go:58] Added Queue <default> for Job <default/qj-1>
I1104 16:02:59.887574   66853 enqueue.go:75] Try to enqueue PodGroup to 0 Queues
I1104 16:02:59.887580   66853 enqueue.go:122] Leaving Enqueue ...
I1104 16:02:59.887585   66853 allocate.go:43] Enter Allocate ...
I1104 16:02:59.887590   66853 allocate.go:90] Added Job <default/qj-1> into Queue <default>
I1104 16:02:59.887595   66853 allocate.go:94] Try to allocate resource to 1 Namespaces
I1104 16:02:59.887602   66853 allocate.go:153] Try to allocate resource to Jobs in Namespace <default> Queue <default>
I1104 16:02:59.887609   66853 allocate.go:178] Try to allocate resource to 0 tasks of Job <default/qj-1>
I1104 16:02:59.887613   66853 statement.go:326] Committing operations ...
I1104 16:02:59.887618   66853 allocate.go:153] Try to allocate resource to Jobs in Namespace <default> Queue <default>
I1104 16:02:59.887623   66853 allocate.go:157] Can not find jobs for queue default.
I1104 16:02:59.887632   66853 allocate.go:253] Leaving Allocate ...
I1104 16:02:59.887636   66853 backfill.go:42] Enter Backfill ...
I1104 16:02:59.887640   66853 backfill.go:91] Leaving Backfill ...
I1104 16:02:59.892233   66853 session.go:154] Close Session a0f4a25a-ff5f-11e9-99a6-784f43775513
I1104 16:02:59.892263   66853 scheduler.go:87] End scheduling ...
I1104 16:03:04.892480   66853 scheduler.go:72] Start scheduling ...
I1104 16:03:04.908428   66853 cache.go:732] The priority of job <default/qj-1> is </0>
I1104 16:03:04.908453   66853 cache.go:771] There are <1> Jobs, <1> Queues and <1> Nodes in total for scheduling.
I1104 16:03:04.908460   66853 session.go:135] Open Session a3f2c6a8-ff5f-11e9-99a6-784f43775513 with <1> Job and <1> Queues
I1104 16:03:04.908542   66853 proportion.go:67] The total resource is <cpu 4000.00, memory 4959854592.00, hugepages-2Mi 0.00>
I1104 16:03:04.908558   66853 proportion.go:71] Considering Job <default/qj-1>.
I1104 16:03:04.908564   66853 proportion.go:85] Added Queue <default> attributes.
I1104 16:03:04.908574   66853 proportion.go:127] Considering Queue <default>: weight <1>, total weight <1>.
I1104 16:03:04.908584   66853 proportion.go:144] The attributes of queue <default> in proportion: deserved <cpu 4000.00, memory 4959854592.00, hugepages-2Mi 0.00>, allocate <cpu 0.00, memory 0.00>, request <cpu 0.00, memory 0.00>, share <0.00>
I1104 16:03:04.908616   66853 proportion.go:154] Exiting when remaining is empty:  <cpu 0.00, memory 0.00, hugepages-2Mi 0.00>
I1104 16:03:04.908643   66853 enqueue.go:43] Enter Enqueue ...
I1104 16:03:04.908649   66853 enqueue.go:58] Added Queue <default> for Job <default/qj-1>
I1104 16:03:04.908656   66853 enqueue.go:75] Try to enqueue PodGroup to 0 Queues
I1104 16:03:04.908665   66853 enqueue.go:122] Leaving Enqueue ...
I1104 16:03:04.908673   66853 allocate.go:43] Enter Allocate ...
I1104 16:03:04.908679   66853 allocate.go:90] Added Job <default/qj-1> into Queue <default>
I1104 16:03:04.908687   66853 allocate.go:94] Try to allocate resource to 1 Namespaces
I1104 16:03:04.908697   66853 allocate.go:153] Try to allocate resource to Jobs in Namespace <default> Queue <default>
I1104 16:03:04.908707   66853 allocate.go:178] Try to allocate resource to 0 tasks of Job <default/qj-1>
I1104 16:03:04.908713   66853 statement.go:326] Committing operations ...
I1104 16:03:04.908721   66853 allocate.go:153] Try to allocate resource to Jobs in Namespace <default> Queue <default>
I1104 16:03:04.908728   66853 allocate.go:157] Can not find jobs for queue default.
I1104 16:03:04.908742   66853 allocate.go:253] Leaving Allocate ...
I1104 16:03:04.908747   66853 backfill.go:42] Enter Backfill ...
I1104 16:03:04.908753   66853 backfill.go:91] Leaving Backfill ...
I1104 16:03:04.913182   66853 session.go:154] Close Session a3f2c6a8-ff5f-11e9-99a6-784f43775513
I1104 16:03:04.913192   66853 scheduler.go:87] End scheduling ...
I1104 16:03:09.913461   66853 scheduler.go:72] Start scheduling ...
I1104 16:03:09.922799   66853 cache.go:732] The priority of job <default/qj-1> is </0>
I1104 16:03:09.922818   66853 cache.go:771] There are <1> Jobs, <1> Queues and <1> Nodes in total for scheduling.
I1104 16:03:09.922823   66853 session.go:135] Open Session a6efe926-ff5f-11e9-99a6-784f43775513 with <1> Job and <1> Queues
I1104 16:03:09.922862   66853 proportion.go:67] The total resource is <cpu 4000.00, memory 4959854592.00, hugepages-2Mi 0.00>
I1104 16:03:09.922874   66853 proportion.go:71] Considering Job <default/qj-1>.
I1104 16:03:09.922878   66853 proportion.go:85] Added Queue <default> attributes.
I1104 16:03:09.922890   66853 proportion.go:127] Considering Queue <default>: weight <1>, total weight <1>.
I1104 16:03:09.922896   66853 proportion.go:144] The attributes of queue <default> in proportion: deserved <cpu 4000.00, memory 4959854592.00, hugepages-2Mi 0.00>, allocate <cpu 0.00, memory 0.00>, request <cpu 0.00, memory 0.00>, share <0.00>
I1104 16:03:09.922907   66853 proportion.go:154] Exiting when remaining is empty:  <cpu 0.00, memory 0.00, hugepages-2Mi 0.00>
I1104 16:03:09.922925   66853 enqueue.go:43] Enter Enqueue ...
I1104 16:03:09.922929   66853 enqueue.go:58] Added Queue <default> for Job <default/qj-1>
I1104 16:03:09.922933   66853 enqueue.go:75] Try to enqueue PodGroup to 0 Queues
I1104 16:03:09.922940   66853 enqueue.go:122] Leaving Enqueue ...
I1104 16:03:09.922945   66853 allocate.go:43] Enter Allocate ...
I1104 16:03:09.922949   66853 allocate.go:90] Added Job <default/qj-1> into Queue <default>
I1104 16:03:09.922954   66853 allocate.go:94] Try to allocate resource to 1 Namespaces
I1104 16:03:09.922961   66853 allocate.go:153] Try to allocate resource to Jobs in Namespace <default> Queue <default>
I1104 16:03:09.922968   66853 allocate.go:178] Try to allocate resource to 0 tasks of Job <default/qj-1>
I1104 16:03:09.922971   66853 statement.go:326] Committing operations ...
I1104 16:03:09.922976   66853 allocate.go:153] Try to allocate resource to Jobs in Namespace <default> Queue <default>
I1104 16:03:09.922980   66853 allocate.go:157] Can not find jobs for queue default.
I1104 16:03:09.922989   66853 allocate.go:253] Leaving Allocate ...
I1104 16:03:09.922993   66853 backfill.go:42] Enter Backfill ...
I1104 16:03:09.922996   66853 backfill.go:91] Leaving Backfill ...
I1104 16:03:09.927195   66853 session.go:154] Close Session a6efe926-ff5f-11e9-99a6-784f43775513
I1104 16:03:09.927206   66853 scheduler.go:87] End scheduling ...
I1104 16:03:14.927783   66853 scheduler.go:72] Start scheduling ...
I1104 16:03:14.939103   66853 cache.go:732] The priority of job <default/qj-1> is </0>
I1104 16:03:14.939119   66853 cache.go:771] There are <1> Jobs, <1> Queues and <1> Nodes in total for scheduling.
I1104 16:03:14.939125   66853 session.go:135] Open Session a9ed567c-ff5f-11e9-99a6-784f43775513 with <1> Job and <1> Queues
I1104 16:03:14.939175   66853 proportion.go:67] The total resource is <cpu 4000.00, memory 4959854592.00, hugepages-2Mi 0.00>
I1104 16:03:14.939189   66853 proportion.go:71] Considering Job <default/qj-1>.
I1104 16:03:14.939196   66853 proportion.go:85] Added Queue <default> attributes.
I1104 16:03:14.939203   66853 proportion.go:127] Considering Queue <default>: weight <1>, total weight <1>.
I1104 16:03:14.939211   66853 proportion.go:144] The attributes of queue <default> in proportion: deserved <cpu 4000.00, memory 4959854592.00, hugepages-2Mi 0.00>, allocate <cpu 0.00, memory 0.00>, request <cpu 0.00, memory 0.00>, share <0.00>
I1104 16:03:14.939225   66853 proportion.go:154] Exiting when remaining is empty:  <cpu 0.00, memory 0.00, hugepages-2Mi 0.00>
I1104 16:03:14.939233   66853 enqueue.go:43] Enter Enqueue ...
I1104 16:03:14.939238   66853 enqueue.go:58] Added Queue <default> for Job <default/qj-1>
I1104 16:03:14.939244   66853 enqueue.go:75] Try to enqueue PodGroup to 0 Queues
I1104 16:03:14.939251   66853 enqueue.go:122] Leaving Enqueue ...
I1104 16:03:14.939257   66853 allocate.go:43] Enter Allocate ...
I1104 16:03:14.939262   66853 allocate.go:90] Added Job <default/qj-1> into Queue <default>
I1104 16:03:14.939268   66853 allocate.go:94] Try to allocate resource to 1 Namespaces
I1104 16:03:14.939276   66853 allocate.go:153] Try to allocate resource to Jobs in Namespace <default> Queue <default>
I1104 16:03:14.939284   66853 allocate.go:178] Try to allocate resource to 0 tasks of Job <default/qj-1>
I1104 16:03:14.939288   66853 statement.go:326] Committing operations ...
I1104 16:03:14.939294   66853 allocate.go:153] Try to allocate resource to Jobs in Namespace <default> Queue <default>
I1104 16:03:14.939299   66853 allocate.go:157] Can not find jobs for queue default.
I1104 16:03:14.939310   66853 allocate.go:253] Leaving Allocate ...
I1104 16:03:14.939315   66853 backfill.go:42] Enter Backfill ...
I1104 16:03:14.939319   66853 backfill.go:91] Leaving Backfill ...
I1104 16:03:14.943290   66853 session.go:154] Close Session a9ed567c-ff5f-11e9-99a6-784f43775513
I1104 16:03:14.943301   66853 scheduler.go:87] End scheduling ...
I1104 16:03:19.943472   66853 scheduler.go:72] Start scheduling ...
I1104 16:03:19.952931   66853 cache.go:732] The priority of job <default/qj-1> is </0>
I1104 16:03:19.952964   66853 cache.go:771] There are <1> Jobs, <1> Queues and <1> Nodes in total for scheduling.
I1104 16:03:19.952973   66853 session.go:135] Open Session acea6194-ff5f-11e9-99a6-784f43775513 with <1> Job and <1> Queues
I1104 16:03:19.953024   66853 proportion.go:67] The total resource is <cpu 4000.00, memory 4959854592.00, hugepages-2Mi 0.00>
I1104 16:03:19.953045   66853 proportion.go:71] Considering Job <default/qj-1>.
I1104 16:03:19.953053   66853 proportion.go:85] Added Queue <default> attributes.
I1104 16:03:19.953066   66853 proportion.go:127] Considering Queue <default>: weight <1>, total weight <1>.
I1104 16:03:19.953079   66853 proportion.go:144] The attributes of queue <default> in proportion: deserved <cpu 4000.00, memory 4959854592.00, hugepages-2Mi 0.00>, allocate <cpu 0.00, memory 0.00>, request <cpu 0.00, memory 0.00>, share <0.00>
I1104 16:03:19.953101   66853 proportion.go:154] Exiting when remaining is empty:  <cpu 0.00, memory 0.00, hugepages-2Mi 0.00>
I1104 16:03:19.953153   66853 enqueue.go:43] Enter Enqueue ...
I1104 16:03:19.953160   66853 enqueue.go:58] Added Queue <default> for Job <default/qj-1>
I1104 16:03:19.953170   66853 enqueue.go:75] Try to enqueue PodGroup to 0 Queues
I1104 16:03:19.953182   66853 enqueue.go:122] Leaving Enqueue ...
I1104 16:03:19.953192   66853 allocate.go:43] Enter Allocate ...
I1104 16:03:19.953201   66853 allocate.go:90] Added Job <default/qj-1> into Queue <default>
I1104 16:03:19.953212   66853 allocate.go:94] Try to allocate resource to 1 Namespaces
I1104 16:03:19.953224   66853 allocate.go:153] Try to allocate resource to Jobs in Namespace <default> Queue <default>
I1104 16:03:19.953237   66853 allocate.go:178] Try to allocate resource to 0 tasks of Job <default/qj-1>
I1104 16:03:19.953245   66853 statement.go:326] Committing operations ...
I1104 16:03:19.953255   66853 allocate.go:153] Try to allocate resource to Jobs in Namespace <default> Queue <default>
I1104 16:03:19.953263   66853 allocate.go:157] Can not find jobs for queue default.
I1104 16:03:19.953281   66853 allocate.go:253] Leaving Allocate ...
I1104 16:03:19.953288   66853 backfill.go:42] Enter Backfill ...
I1104 16:03:19.953296   66853 backfill.go:91] Leaving Backfill ...
I1104 16:03:19.958030   66853 session.go:154] Close Session acea6194-ff5f-11e9-99a6-784f43775513
I1104 16:03:19.958041   66853 scheduler.go:87] End scheduling ...
I1104 16:03:24.958244   66853 scheduler.go:72] Start scheduling ...
I1104 16:03:24.972070   66853 cache.go:732] The priority of job <default/qj-1> is </0>
I1104 16:03:24.972089   66853 cache.go:771] There are <1> Jobs, <1> Queues and <1> Nodes in total for scheduling.
I1104 16:03:24.972095   66853 session.go:135] Open Session afe83f56-ff5f-11e9-99a6-784f43775513 with <1> Job and <1> Queues
I1104 16:03:24.972126   66853 proportion.go:67] The total resource is <cpu 4000.00, memory 4959854592.00, hugepages-2Mi 0.00>
I1104 16:03:24.972138   66853 proportion.go:71] Considering Job <default/qj-1>.
I1104 16:03:24.972142   66853 proportion.go:85] Added Queue <default> attributes.
I1104 16:03:24.972149   66853 proportion.go:127] Considering Queue <default>: weight <1>, total weight <1>.
I1104 16:03:24.972158   66853 proportion.go:144] The attributes of queue <default> in proportion: deserved <cpu 4000.00, memory 4959854592.00, hugepages-2Mi 0.00>, allocate <cpu 0.00, memory 0.00>, request <cpu 0.00, memory 0.00>, share <0.00>
I1104 16:03:24.972170   66853 proportion.go:154] Exiting when remaining is empty:  <cpu 0.00, memory 0.00, hugepages-2Mi 0.00>
I1104 16:03:24.972198   66853 enqueue.go:43] Enter Enqueue ...
I1104 16:03:24.972202   66853 enqueue.go:58] Added Queue <default> for Job <default/qj-1>
I1104 16:03:24.972207   66853 enqueue.go:75] Try to enqueue PodGroup to 0 Queues
I1104 16:03:24.972213   66853 enqueue.go:122] Leaving Enqueue ...
I1104 16:03:24.972218   66853 allocate.go:43] Enter Allocate ...
I1104 16:03:24.972222   66853 allocate.go:90] Added Job <default/qj-1> into Queue <default>
I1104 16:03:24.972228   66853 allocate.go:94] Try to allocate resource to 1 Namespaces
I1104 16:03:24.972234   66853 allocate.go:153] Try to allocate resource to Jobs in Namespace <default> Queue <default>
I1104 16:03:24.972241   66853 allocate.go:178] Try to allocate resource to 0 tasks of Job <default/qj-1>
I1104 16:03:24.972244   66853 statement.go:326] Committing operations ...
I1104 16:03:24.972250   66853 allocate.go:153] Try to allocate resource to Jobs in Namespace <default> Queue <default>
I1104 16:03:24.972254   66853 allocate.go:157] Can not find jobs for queue default.
I1104 16:03:24.972262   66853 allocate.go:253] Leaving Allocate ...
I1104 16:03:24.972266   66853 backfill.go:42] Enter Backfill ...
I1104 16:03:24.972270   66853 backfill.go:91] Leaving Backfill ...
I1104 16:03:24.976127   66853 session.go:154] Close Session afe83f56-ff5f-11e9-99a6-784f43775513
I1104 16:03:24.976137   66853 scheduler.go:87] End scheduling ...
I1104 16:03:29.976252   66853 scheduler.go:72] Start scheduling ...
I1104 16:03:29.976452   66853 cache.go:732] The priority of job <default/qj-1> is </0>
I1104 16:03:29.990561   66853 cache.go:771] There are <1> Jobs, <1> Queues and <1> Nodes in total for scheduling.
I1104 16:03:29.990570   66853 session.go:135] Open Session b2e3da08-ff5f-11e9-99a6-784f43775513 with <1> Job and <1> Queues
I1104 16:03:29.990605   66853 proportion.go:67] The total resource is <cpu 4000.00, memory 4959854592.00, hugepages-2Mi 0.00>
I1104 16:03:29.990618   66853 proportion.go:71] Considering Job <default/qj-1>.
I1104 16:03:29.990623   66853 proportion.go:85] Added Queue <default> attributes.
I1104 16:03:29.990630   66853 proportion.go:127] Considering Queue <default>: weight <1>, total weight <1>.
I1104 16:03:29.990637   66853 proportion.go:144] The attributes of queue <default> in proportion: deserved <cpu 4000.00, memory 4959854592.00, hugepages-2Mi 0.00>, allocate <cpu 0.00, memory 0.00>, request <cpu 0.00, memory 0.00>, share <0.00>
I1104 16:03:29.990648   66853 proportion.go:154] Exiting when remaining is empty:  <cpu 0.00, memory 0.00, hugepages-2Mi 0.00>
I1104 16:03:29.990678   66853 enqueue.go:43] Enter Enqueue ...
I1104 16:03:29.990682   66853 enqueue.go:58] Added Queue <default> for Job <default/qj-1>
I1104 16:03:29.990687   66853 enqueue.go:75] Try to enqueue PodGroup to 0 Queues
I1104 16:03:29.990693   66853 enqueue.go:122] Leaving Enqueue ...
I1104 16:03:29.990699   66853 allocate.go:43] Enter Allocate ...
I1104 16:03:29.990703   66853 allocate.go:90] Added Job <default/qj-1> into Queue <default>
I1104 16:03:29.990708   66853 allocate.go:94] Try to allocate resource to 1 Namespaces
I1104 16:03:29.990715   66853 allocate.go:153] Try to allocate resource to Jobs in Namespace <default> Queue <default>
I1104 16:03:29.990721   66853 allocate.go:178] Try to allocate resource to 0 tasks of Job <default/qj-1>
I1104 16:03:29.990725   66853 statement.go:326] Committing operations ...
I1104 16:03:29.990731   66853 allocate.go:153] Try to allocate resource to Jobs in Namespace <default> Queue <default>
I1104 16:03:29.990734   66853 allocate.go:157] Can not find jobs for queue default.
I1104 16:03:29.990743   66853 allocate.go:253] Leaving Allocate ...
I1104 16:03:29.990747   66853 backfill.go:42] Enter Backfill ...
I1104 16:03:29.990751   66853 backfill.go:91] Leaving Backfill ...
I1104 16:03:29.995054   66853 session.go:154] Close Session b2e3da08-ff5f-11e9-99a6-784f43775513
I1104 16:03:29.995064   66853 scheduler.go:87] End scheduling ...
I1104 16:03:34.996615   66853 scheduler.go:72] Start scheduling ...
I1104 16:03:35.010189   66853 cache.go:732] The priority of job <default/qj-1> is </0>
I1104 16:03:35.010212   66853 cache.go:771] There are <1> Jobs, <1> Queues and <1> Nodes in total for scheduling.
I1104 16:03:35.010218   66853 session.go:135] Open Session b5e3f170-ff5f-11e9-99a6-784f43775513 with <1> Job and <1> Queues
I1104 16:03:35.010259   66853 proportion.go:67] The total resource is <cpu 4000.00, memory 4959854592.00, hugepages-2Mi 0.00>
I1104 16:03:35.010271   66853 proportion.go:71] Considering Job <default/qj-1>.
I1104 16:03:35.010276   66853 proportion.go:85] Added Queue <default> attributes.
I1104 16:03:35.010283   66853 proportion.go:127] Considering Queue <default>: weight <1>, total weight <1>.
I1104 16:03:35.010289   66853 proportion.go:144] The attributes of queue <default> in proportion: deserved <cpu 4000.00, memory 4959854592.00, hugepages-2Mi 0.00>, allocate <cpu 0.00, memory 0.00>, request <cpu 0.00, memory 0.00>, share <0.00>
I1104 16:03:35.010301   66853 proportion.go:154] Exiting when remaining is empty:  <cpu 0.00, memory 0.00, hugepages-2Mi 0.00>
I1104 16:03:35.010321   66853 enqueue.go:43] Enter Enqueue ...
I1104 16:03:35.010325   66853 enqueue.go:58] Added Queue <default> for Job <default/qj-1>
I1104 16:03:35.010330   66853 enqueue.go:75] Try to enqueue PodGroup to 0 Queues
I1104 16:03:35.010337   66853 enqueue.go:122] Leaving Enqueue ...
I1104 16:03:35.010343   66853 allocate.go:43] Enter Allocate ...
I1104 16:03:35.010348   66853 allocate.go:90] Added Job <default/qj-1> into Queue <default>
I1104 16:03:35.010355   66853 allocate.go:94] Try to allocate resource to 1 Namespaces
I1104 16:03:35.010362   66853 allocate.go:153] Try to allocate resource to Jobs in Namespace <default> Queue <default>
I1104 16:03:35.010369   66853 allocate.go:178] Try to allocate resource to 0 tasks of Job <default/qj-1>
I1104 16:03:35.010373   66853 statement.go:326] Committing operations ...
I1104 16:03:35.010379   66853 allocate.go:153] Try to allocate resource to Jobs in Namespace <default> Queue <default>
I1104 16:03:35.010384   66853 allocate.go:157] Can not find jobs for queue default.
I1104 16:03:35.010395   66853 allocate.go:253] Leaving Allocate ...
I1104 16:03:35.010400   66853 backfill.go:42] Enter Backfill ...
I1104 16:03:35.010404   66853 backfill.go:91] Leaving Backfill ...
I1104 16:03:35.014691   66853 session.go:154] Close Session b5e3f170-ff5f-11e9-99a6-784f43775513
I1104 16:03:35.014701   66853 scheduler.go:87] End scheduling ...
I1104 16:03:40.016592   66853 scheduler.go:72] Start scheduling ...
I1104 16:03:40.030397   66853 cache.go:732] The priority of job <default/qj-1> is </0>
I1104 16:03:40.030416   66853 cache.go:771] There are <1> Jobs, <1> Queues and <1> Nodes in total for scheduling.
I1104 16:03:40.030423   66853 session.go:135] Open Session b8e1f746-ff5f-11e9-99a6-784f43775513 with <1> Job and <1> Queues
I1104 16:03:40.030458   66853 proportion.go:67] The total resource is <cpu 4000.00, memory 4959854592.00, hugepages-2Mi 0.00>
I1104 16:03:40.030469   66853 proportion.go:71] Considering Job <default/qj-1>.
I1104 16:03:40.030474   66853 proportion.go:85] Added Queue <default> attributes.
I1104 16:03:40.030481   66853 proportion.go:127] Considering Queue <default>: weight <1>, total weight <1>.
I1104 16:03:40.030487   66853 proportion.go:144] The attributes of queue <default> in proportion: deserved <cpu 4000.00, memory 4959854592.00, hugepages-2Mi 0.00>, allocate <cpu 0.00, memory 0.00>, request <cpu 0.00, memory 0.00>, share <0.00>
I1104 16:03:40.030499   66853 proportion.go:154] Exiting when remaining is empty:  <cpu 0.00, memory 0.00, hugepages-2Mi 0.00>
I1104 16:03:40.030519   66853 enqueue.go:43] Enter Enqueue ...
I1104 16:03:40.030523   66853 enqueue.go:58] Added Queue <default> for Job <default/qj-1>
I1104 16:03:40.030529   66853 enqueue.go:75] Try to enqueue PodGroup to 0 Queues
I1104 16:03:40.030536   66853 enqueue.go:122] Leaving Enqueue ...
I1104 16:03:40.030541   66853 allocate.go:43] Enter Allocate ...
I1104 16:03:40.030546   66853 allocate.go:90] Added Job <default/qj-1> into Queue <default>
I1104 16:03:40.030551   66853 allocate.go:94] Try to allocate resource to 1 Namespaces
I1104 16:03:40.030557   66853 allocate.go:153] Try to allocate resource to Jobs in Namespace <default> Queue <default>
I1104 16:03:40.030564   66853 allocate.go:178] Try to allocate resource to 0 tasks of Job <default/qj-1>
I1104 16:03:40.030568   66853 statement.go:326] Committing operations ...
I1104 16:03:40.030573   66853 allocate.go:153] Try to allocate resource to Jobs in Namespace <default> Queue <default>
I1104 16:03:40.030577   66853 allocate.go:157] Can not find jobs for queue default.
I1104 16:03:40.030587   66853 allocate.go:253] Leaving Allocate ...
I1104 16:03:40.030591   66853 backfill.go:42] Enter Backfill ...
I1104 16:03:40.030595   66853 backfill.go:91] Leaving Backfill ...
I1104 16:03:40.034699   66853 session.go:154] Close Session b8e1f746-ff5f-11e9-99a6-784f43775513
I1104 16:03:40.034713   66853 scheduler.go:87] End scheduling ...
I1104 16:03:45.034929   66853 scheduler.go:72] Start scheduling ...
I1104 16:03:45.048587   66853 cache.go:732] The priority of job <default/qj-1> is </0>
I1104 16:03:45.048609   66853 cache.go:771] There are <1> Jobs, <1> Queues and <1> Nodes in total for scheduling.
I1104 16:03:45.048614   66853 session.go:135] Open Session bbdfae48-ff5f-11e9-99a6-784f43775513 with <1> Job and <1> Queues
I1104 16:03:45.048652   66853 proportion.go:67] The total resource is <cpu 4000.00, memory 4959854592.00, hugepages-2Mi 0.00>
I1104 16:03:45.048667   66853 proportion.go:71] Considering Job <default/qj-1>.
I1104 16:03:45.048674   66853 proportion.go:85] Added Queue <default> attributes.
I1104 16:03:45.048684   66853 proportion.go:127] Considering Queue <default>: weight <1>, total weight <1>.
I1104 16:03:45.048695   66853 proportion.go:144] The attributes of queue <default> in proportion: deserved <cpu 4000.00, memory 4959854592.00, hugepages-2Mi 0.00>, allocate <cpu 0.00, memory 0.00>, request <cpu 0.00, memory 0.00>, share <0.00>
I1104 16:03:45.048709   66853 proportion.go:154] Exiting when remaining is empty:  <cpu 0.00, memory 0.00, hugepages-2Mi 0.00>
I1104 16:03:45.048731   66853 enqueue.go:43] Enter Enqueue ...
I1104 16:03:45.048735   66853 enqueue.go:58] Added Queue <default> for Job <default/qj-1>
I1104 16:03:45.048739   66853 enqueue.go:75] Try to enqueue PodGroup to 0 Queues
I1104 16:03:45.048746   66853 enqueue.go:122] Leaving Enqueue ...
I1104 16:03:45.048753   66853 allocate.go:43] Enter Allocate ...
I1104 16:03:45.048758   66853 allocate.go:90] Added Job <default/qj-1> into Queue <default>
I1104 16:03:45.048763   66853 allocate.go:94] Try to allocate resource to 1 Namespaces
I1104 16:03:45.048770   66853 allocate.go:153] Try to allocate resource to Jobs in Namespace <default> Queue <default>
I1104 16:03:45.048776   66853 allocate.go:178] Try to allocate resource to 0 tasks of Job <default/qj-1>
I1104 16:03:45.048782   66853 statement.go:326] Committing operations ...
I1104 16:03:45.048788   66853 allocate.go:153] Try to allocate resource to Jobs in Namespace <default> Queue <default>
I1104 16:03:45.048792   66853 allocate.go:157] Can not find jobs for queue default.
I1104 16:03:45.048801   66853 allocate.go:253] Leaving Allocate ...
I1104 16:03:45.048805   66853 backfill.go:42] Enter Backfill ...
I1104 16:03:45.048810   66853 backfill.go:91] Leaving Backfill ...
I1104 16:03:45.053519   66853 session.go:154] Close Session bbdfae48-ff5f-11e9-99a6-784f43775513
I1104 16:03:45.053529   66853 scheduler.go:87] End scheduling ...
I1104 16:03:50.056659   66853 scheduler.go:72] Start scheduling ...
I1104 16:03:50.066374   66853 cache.go:732] The priority of job <default/qj-1> is </0>
I1104 16:03:50.066408   66853 cache.go:771] There are <1> Jobs, <1> Queues and <1> Nodes in total for scheduling.
I1104 16:03:50.066415   66853 session.go:135] Open Session bedd54a6-ff5f-11e9-99a6-784f43775513 with <1> Job and <1> Queues
I1104 16:03:50.066458   66853 proportion.go:67] The total resource is <cpu 4000.00, memory 4959854592.00, hugepages-2Mi 0.00>
I1104 16:03:50.066479   66853 proportion.go:71] Considering Job <default/qj-1>.
I1104 16:03:50.066488   66853 proportion.go:85] Added Queue <default> attributes.
I1104 16:03:50.066498   66853 proportion.go:127] Considering Queue <default>: weight <1>, total weight <1>.
I1104 16:03:50.066509   66853 proportion.go:144] The attributes of queue <default> in proportion: deserved <cpu 4000.00, memory 4959854592.00, hugepages-2Mi 0.00>, allocate <cpu 0.00, memory 0.00>, request <cpu 0.00, memory 0.00>, share <0.00>
I1104 16:03:50.066530   66853 proportion.go:154] Exiting when remaining is empty:  <cpu 0.00, memory 0.00, hugepages-2Mi 0.00>
I1104 16:03:50.066572   66853 enqueue.go:43] Enter Enqueue ...
I1104 16:03:50.066579   66853 enqueue.go:58] Added Queue <default> for Job <default/qj-1>
I1104 16:03:50.066587   66853 enqueue.go:75] Try to enqueue PodGroup to 0 Queues
I1104 16:03:50.066598   66853 enqueue.go:122] Leaving Enqueue ...
I1104 16:03:50.066607   66853 allocate.go:43] Enter Allocate ...
I1104 16:03:50.066615   66853 allocate.go:90] Added Job <default/qj-1> into Queue <default>
I1104 16:03:50.066626   66853 allocate.go:94] Try to allocate resource to 1 Namespaces
I1104 16:03:50.066637   66853 allocate.go:153] Try to allocate resource to Jobs in Namespace <default> Queue <default>
I1104 16:03:50.066648   66853 allocate.go:178] Try to allocate resource to 0 tasks of Job <default/qj-1>
I1104 16:03:50.066655   66853 statement.go:326] Committing operations ...
I1104 16:03:50.066663   66853 allocate.go:153] Try to allocate resource to Jobs in Namespace <default> Queue <default>
I1104 16:03:50.066671   66853 allocate.go:157] Can not find jobs for queue default.
I1104 16:03:50.066687   66853 allocate.go:253] Leaving Allocate ...
I1104 16:03:50.066694   66853 backfill.go:42] Enter Backfill ...
I1104 16:03:50.066701   66853 backfill.go:91] Leaving Backfill ...
I1104 16:03:50.071496   66853 session.go:154] Close Session bedd54a6-ff5f-11e9-99a6-784f43775513
I1104 16:03:50.071507   66853 scheduler.go:87] End scheduling ...
I1104 16:03:55.072789   66853 scheduler.go:72] Start scheduling ...
I1104 16:03:55.081523   66853 cache.go:732] The priority of job <default/qj-1> is </0>
I1104 16:03:55.081553   66853 cache.go:771] There are <1> Jobs, <1> Queues and <1> Nodes in total for scheduling.
I1104 16:03:55.081561   66853 session.go:135] Open Session c1da94e8-ff5f-11e9-99a6-784f43775513 with <1> Job and <1> Queues
I1104 16:03:55.081618   66853 proportion.go:67] The total resource is <cpu 4000.00, memory 4959854592.00, hugepages-2Mi 0.00>
I1104 16:03:55.081635   66853 proportion.go:71] Considering Job <default/qj-1>.
I1104 16:03:55.081641   66853 proportion.go:85] Added Queue <default> attributes.
I1104 16:03:55.081651   66853 proportion.go:127] Considering Queue <default>: weight <1>, total weight <1>.
I1104 16:03:55.081662   66853 proportion.go:144] The attributes of queue <default> in proportion: deserved <cpu 4000.00, memory 4959854592.00, hugepages-2Mi 0.00>, allocate <cpu 0.00, memory 0.00>, request <cpu 0.00, memory 0.00>, share <0.00>
I1104 16:03:55.081679   66853 proportion.go:154] Exiting when remaining is empty:  <cpu 0.00, memory 0.00, hugepages-2Mi 0.00>
I1104 16:03:55.081706   66853 enqueue.go:43] Enter Enqueue ...
I1104 16:03:55.081712   66853 enqueue.go:58] Added Queue <default> for Job <default/qj-1>
I1104 16:03:55.081719   66853 enqueue.go:75] Try to enqueue PodGroup to 0 Queues
I1104 16:03:55.081729   66853 enqueue.go:122] Leaving Enqueue ...
I1104 16:03:55.081736   66853 allocate.go:43] Enter Allocate ...
I1104 16:03:55.081743   66853 allocate.go:90] Added Job <default/qj-1> into Queue <default>
I1104 16:03:55.081752   66853 allocate.go:94] Try to allocate resource to 1 Namespaces
I1104 16:03:55.081761   66853 allocate.go:153] Try to allocate resource to Jobs in Namespace <default> Queue <default>
I1104 16:03:55.081771   66853 allocate.go:178] Try to allocate resource to 0 tasks of Job <default/qj-1>
I1104 16:03:55.081777   66853 statement.go:326] Committing operations ...
I1104 16:03:55.081785   66853 allocate.go:153] Try to allocate resource to Jobs in Namespace <default> Queue <default>
I1104 16:03:55.081791   66853 allocate.go:157] Can not find jobs for queue default.
I1104 16:03:55.081805   66853 allocate.go:253] Leaving Allocate ...
I1104 16:03:55.081810   66853 backfill.go:42] Enter Backfill ...
I1104 16:03:55.081817   66853 backfill.go:91] Leaving Backfill ...
I1104 16:03:55.085995   66853 session.go:154] Close Session c1da94e8-ff5f-11e9-99a6-784f43775513
I1104 16:03:55.086006   66853 scheduler.go:87] End scheduling ...
I1104 16:04:00.087441   66853 scheduler.go:72] Start scheduling ...
I1104 16:04:00.095222   66853 cache.go:732] The priority of job <default/qj-1> is </0>
I1104 16:04:00.095247   66853 cache.go:771] There are <1> Jobs, <1> Queues and <1> Nodes in total for scheduling.
I1104 16:04:00.095254   66853 session.go:135] Open Session c4d79c7c-ff5f-11e9-99a6-784f43775513 with <1> Job and <1> Queues
I1104 16:04:00.095303   66853 proportion.go:67] The total resource is <cpu 4000.00, memory 4959854592.00, hugepages-2Mi 0.00>
I1104 16:04:00.095319   66853 proportion.go:71] Considering Job <default/qj-1>.
I1104 16:04:00.095325   66853 proportion.go:85] Added Queue <default> attributes.
I1104 16:04:00.095336   66853 proportion.go:127] Considering Queue <default>: weight <1>, total weight <1>.
I1104 16:04:00.095347   66853 proportion.go:144] The attributes of queue <default> in proportion: deserved <cpu 4000.00, memory 4959854592.00, hugepages-2Mi 0.00>, allocate <cpu 0.00, memory 0.00>, request <cpu 0.00, memory 0.00>, share <0.00>
I1104 16:04:00.095364   66853 proportion.go:154] Exiting when remaining is empty:  <cpu 0.00, memory 0.00, hugepages-2Mi 0.00>
I1104 16:04:00.095397   66853 enqueue.go:43] Enter Enqueue ...
I1104 16:04:00.095405   66853 enqueue.go:58] Added Queue <default> for Job <default/qj-1>
I1104 16:04:00.095412   66853 enqueue.go:75] Try to enqueue PodGroup to 0 Queues
I1104 16:04:00.095422   66853 enqueue.go:122] Leaving Enqueue ...
I1104 16:04:00.095430   66853 allocate.go:43] Enter Allocate ...
I1104 16:04:00.095437   66853 allocate.go:90] Added Job <default/qj-1> into Queue <default>
I1104 16:04:00.095446   66853 allocate.go:94] Try to allocate resource to 1 Namespaces
I1104 16:04:00.095456   66853 allocate.go:153] Try to allocate resource to Jobs in Namespace <default> Queue <default>
I1104 16:04:00.095468   66853 allocate.go:178] Try to allocate resource to 0 tasks of Job <default/qj-1>
I1104 16:04:00.095474   66853 statement.go:326] Committing operations ...
I1104 16:04:00.095482   66853 allocate.go:153] Try to allocate resource to Jobs in Namespace <default> Queue <default>
I1104 16:04:00.095489   66853 allocate.go:157] Can not find jobs for queue default.
I1104 16:04:00.095506   66853 allocate.go:253] Leaving Allocate ...
I1104 16:04:00.095511   66853 backfill.go:42] Enter Backfill ...
I1104 16:04:00.095517   66853 backfill.go:91] Leaving Backfill ...
I1104 16:04:00.100839   66853 session.go:154] Close Session c4d79c7c-ff5f-11e9-99a6-784f43775513
I1104 16:04:00.100850   66853 scheduler.go:87] End scheduling ...
I1104 16:04:05.101775   66853 scheduler.go:72] Start scheduling ...
I1104 16:04:05.113824   66853 cache.go:732] The priority of job <default/qj-1> is </0>
I1104 16:04:05.113844   66853 cache.go:771] There are <1> Jobs, <1> Queues and <1> Nodes in total for scheduling.
I1104 16:04:05.113850   66853 session.go:135] Open Session c7d56472-ff5f-11e9-99a6-784f43775513 with <1> Job and <1> Queues
I1104 16:04:05.113883   66853 proportion.go:67] The total resource is <cpu 4000.00, memory 4959854592.00, hugepages-2Mi 0.00>
I1104 16:04:05.113897   66853 proportion.go:71] Considering Job <default/qj-1>.
I1104 16:04:05.113902   66853 proportion.go:85] Added Queue <default> attributes.
I1104 16:04:05.113910   66853 proportion.go:127] Considering Queue <default>: weight <1>, total weight <1>.
I1104 16:04:05.113918   66853 proportion.go:144] The attributes of queue <default> in proportion: deserved <cpu 4000.00, memory 4959854592.00, hugepages-2Mi 0.00>, allocate <cpu 0.00, memory 0.00>, request <cpu 0.00, memory 0.00>, share <0.00>
I1104 16:04:05.113932   66853 proportion.go:154] Exiting when remaining is empty:  <cpu 0.00, memory 0.00, hugepages-2Mi 0.00>
I1104 16:04:05.113962   66853 enqueue.go:43] Enter Enqueue ...
I1104 16:04:05.113967   66853 enqueue.go:58] Added Queue <default> for Job <default/qj-1>
I1104 16:04:05.113973   66853 enqueue.go:75] Try to enqueue PodGroup to 0 Queues
I1104 16:04:05.113980   66853 enqueue.go:122] Leaving Enqueue ...
I1104 16:04:05.113986   66853 allocate.go:43] Enter Allocate ...
I1104 16:04:05.113991   66853 allocate.go:90] Added Job <default/qj-1> into Queue <default>
I1104 16:04:05.113998   66853 allocate.go:94] Try to allocate resource to 1 Namespaces
I1104 16:04:05.114005   66853 allocate.go:153] Try to allocate resource to Jobs in Namespace <default> Queue <default>
I1104 16:04:05.114013   66853 allocate.go:178] Try to allocate resource to 0 tasks of Job <default/qj-1>
I1104 16:04:05.114018   66853 statement.go:326] Committing operations ...
I1104 16:04:05.114024   66853 allocate.go:153] Try to allocate resource to Jobs in Namespace <default> Queue <default>
I1104 16:04:05.114029   66853 allocate.go:157] Can not find jobs for queue default.
I1104 16:04:05.114040   66853 allocate.go:253] Leaving Allocate ...
I1104 16:04:05.114044   66853 backfill.go:42] Enter Backfill ...
I1104 16:04:05.114049   66853 backfill.go:91] Leaving Backfill ...
I1104 16:04:05.119007   66853 session.go:154] Close Session c7d56472-ff5f-11e9-99a6-784f43775513
I1104 16:04:05.119019   66853 scheduler.go:87] End scheduling ...
I1104 16:04:10.123817   66853 scheduler.go:72] Start scheduling ...
I1104 16:04:10.128023   66853 cache.go:732] The priority of job <default/qj-1> is </0>
I1104 16:04:10.128044   66853 cache.go:771] There are <1> Jobs, <1> Queues and <1> Nodes in total for scheduling.
I1104 16:04:10.128049   66853 session.go:135] Open Session cad27fac-ff5f-11e9-99a6-784f43775513 with <1> Job and <1> Queues
I1104 16:04:10.128097   66853 proportion.go:67] The total resource is <cpu 4000.00, memory 4959854592.00, hugepages-2Mi 0.00>
I1104 16:04:10.128112   66853 proportion.go:71] Considering Job <default/qj-1>.
I1104 16:04:10.128117   66853 proportion.go:85] Added Queue <default> attributes.
I1104 16:04:10.128123   66853 proportion.go:127] Considering Queue <default>: weight <1>, total weight <1>.
I1104 16:04:10.128130   66853 proportion.go:144] The attributes of queue <default> in proportion: deserved <cpu 4000.00, memory 4959854592.00, hugepages-2Mi 0.00>, allocate <cpu 0.00, memory 0.00>, request <cpu 0.00, memory 0.00>, share <0.00>
I1104 16:04:10.128143   66853 proportion.go:154] Exiting when remaining is empty:  <cpu 0.00, memory 0.00, hugepages-2Mi 0.00>
I1104 16:04:10.128151   66853 enqueue.go:43] Enter Enqueue ...
